2025-04-11 14:50:58,029 INFO    StreamThr :17843 [internal.py:wandb_internal():86] W&B internal server running at pid: 17843, started at: 2025-04-11 14:50:58.026067
2025-04-11 14:50:58,035 DEBUG   HandlerThread:17843 [handler.py:handle_request():146] handle_request: status
2025-04-11 14:50:58,037 INFO    WriterThread:17843 [datastore.py:open_for_write():85] open: /root/ltu-main/ltu-main/src/ltu_as/train_scripts/wandb/run-20250411_145058-mlm5cp60/run-mlm5cp60.wandb
2025-04-11 14:50:58,038 DEBUG   SenderThread:17843 [sender.py:send():380] send: header
2025-04-11 14:50:58,038 DEBUG   SenderThread:17843 [sender.py:send():380] send: run
2025-04-11 14:50:58,843 INFO    SenderThread:17843 [dir_watcher.py:__init__():211] watching files in: /root/ltu-main/ltu-main/src/ltu_as/train_scripts/wandb/run-20250411_145058-mlm5cp60/files
2025-04-11 14:50:58,844 DEBUG   HandlerThread:17843 [handler.py:handle_request():146] handle_request: check_version
2025-04-11 14:50:58,844 INFO    SenderThread:17843 [sender.py:_start_run_threads():1122] run started: mlm5cp60 with start time 1744383058.026119
2025-04-11 14:50:58,845 DEBUG   SenderThread:17843 [sender.py:send_request():407] send_request: check_version
2025-04-11 14:50:59,432 DEBUG   HandlerThread:17843 [handler.py:handle_request():146] handle_request: run_start
2025-04-11 14:50:59,447 DEBUG   HandlerThread:17843 [system_info.py:__init__():32] System info init
2025-04-11 14:50:59,447 DEBUG   HandlerThread:17843 [system_info.py:__init__():47] System info init done
2025-04-11 14:50:59,447 INFO    HandlerThread:17843 [system_monitor.py:start():194] Starting system monitor
2025-04-11 14:50:59,447 INFO    SystemMonitor:17843 [system_monitor.py:_start():158] Starting system asset monitoring threads
2025-04-11 14:50:59,448 INFO    HandlerThread:17843 [system_monitor.py:probe():214] Collecting system info
2025-04-11 14:50:59,448 INFO    SystemMonitor:17843 [interfaces.py:start():190] Started cpu monitoring
2025-04-11 14:50:59,449 INFO    SystemMonitor:17843 [interfaces.py:start():190] Started disk monitoring
2025-04-11 14:50:59,451 INFO    SystemMonitor:17843 [interfaces.py:start():190] Started gpu monitoring
2025-04-11 14:50:59,452 INFO    SystemMonitor:17843 [interfaces.py:start():190] Started memory monitoring
2025-04-11 14:50:59,454 INFO    SystemMonitor:17843 [interfaces.py:start():190] Started network monitoring
2025-04-11 14:50:59,463 DEBUG   HandlerThread:17843 [system_info.py:probe():196] Probing system
2025-04-11 14:50:59,464 DEBUG   HandlerThread:17843 [gitlib.py:_init_repo():53] git repository is invalid
2025-04-11 14:50:59,464 DEBUG   HandlerThread:17843 [system_info.py:probe():244] Probing system done
2025-04-11 14:50:59,464 DEBUG   HandlerThread:17843 [system_monitor.py:probe():223] {'os': 'Linux-4.15.0-213-generic-x86_64-with-glibc2.27', 'python': '3.10.15', 'heartbeatAt': '2025-04-11T14:50:59.463498', 'startedAt': '2025-04-11T14:50:58.008078', 'docker': None, 'cuda': None, 'args': ('--base_model', '../../../pretrained_mdls/ltuas_long_noqa_a6.bin', '--data_path', '../../../openasqa/data/iemocap_preprocess_with_answers_updated.json', '--output_dir', '../exp/ltuas_ft_meld/', '--batch_size', '256', '--micro_batch_size', '1', '--num_epochs', '1', '--learning_rate', '2e-4', '--cutoff_len', '100', '--val_set_size', '0', '--lora_r', '8', '--lora_alpha', '16', '--lora_dropout', '0.05', '--lora_target_modules', '[q_proj,v_proj]', '--group_by_length', '--wandb_run_name', '../exp/ltuas_ft_meld/', '--save_steps', '30', '--trainable_params', 'all'), 'state': 'running', 'program': '/root/ltu-main/ltu-main/src/ltu_as/train_scripts/../finetune_low_resource.py', 'codePathLocal': None, 'host': 'ubuntu', 'username': 'root', 'executable': '/root/anaconda3/envs/venv_ltu/bin/python', 'cpu_count': 4, 'cpu_count_logical': 4, 'cpu_freq': {'current': 2294.598, 'min': 0.0, 'max': 0.0}, 'cpu_freq_per_core': [{'current': 2294.598, 'min': 0.0, 'max': 0.0}, {'current': 2294.598, 'min': 0.0, 'max': 0.0}, {'current': 2294.598, 'min': 0.0, 'max': 0.0}, {'current': 2294.598, 'min': 0.0, 'max': 0.0}], 'disk': {'/': {'total': 499.9882621765137, 'used': 333.58660888671875}}, 'gpu': 'NVIDIA A100-PCIE-40GB', 'gpu_count': 1, 'gpu_devices': [{'name': 'NVIDIA A100-PCIE-40GB', 'memory_total': 42949672960}], 'memory': {'total': 19.60204315185547}}
2025-04-11 14:50:59,465 INFO    HandlerThread:17843 [system_monitor.py:probe():224] Finished collecting system info
2025-04-11 14:50:59,465 INFO    HandlerThread:17843 [system_monitor.py:probe():227] Publishing system info
2025-04-11 14:50:59,465 DEBUG   HandlerThread:17843 [system_info.py:_save_pip():52] Saving list of pip packages installed into the current environment
2025-04-11 14:50:59,465 DEBUG   HandlerThread:17843 [system_info.py:_save_pip():68] Saving pip packages done
2025-04-11 14:50:59,465 DEBUG   HandlerThread:17843 [system_info.py:_save_conda():75] Saving list of conda packages installed into the current environment
2025-04-11 14:50:59,840 INFO    Thread-12 :17843 [dir_watcher.py:_on_file_created():271] file/dir created: /root/ltu-main/ltu-main/src/ltu_as/train_scripts/wandb/run-20250411_145058-mlm5cp60/files/requirements.txt
2025-04-11 14:50:59,840 INFO    Thread-12 :17843 [dir_watcher.py:_on_file_created():271] file/dir created: /root/ltu-main/ltu-main/src/ltu_as/train_scripts/wandb/run-20250411_145058-mlm5cp60/files/conda-environment.yaml
2025-04-11 14:51:06,112 DEBUG   HandlerThread:17843 [system_info.py:_save_conda():87] Saving conda packages done
2025-04-11 14:51:06,113 INFO    HandlerThread:17843 [system_monitor.py:probe():229] Finished publishing system info
2025-04-11 14:51:06,121 DEBUG   HandlerThread:17843 [handler.py:handle_request():146] handle_request: status_report
2025-04-11 14:51:06,122 DEBUG   HandlerThread:17843 [handler.py:handle_request():146] handle_request: keepalive
2025-04-11 14:51:06,123 DEBUG   SenderThread:17843 [sender.py:send():380] send: files
2025-04-11 14:51:06,123 INFO    SenderThread:17843 [sender.py:_save_file():1378] saving file wandb-metadata.json with policy now
2025-04-11 14:51:06,131 DEBUG   SenderThread:17843 [sender.py:send():380] send: telemetry
2025-04-11 14:51:06,134 DEBUG   SenderThread:17843 [sender.py:send():380] send: config
2025-04-11 14:51:06,136 DEBUG   HandlerThread:17843 [handler.py:handle_request():146] handle_request: stop_status
2025-04-11 14:51:06,136 DEBUG   HandlerThread:17843 [handler.py:handle_request():146] handle_request: internal_messages
2025-04-11 14:51:06,136 DEBUG   SenderThread:17843 [sender.py:send_request():407] send_request: stop_status
2025-04-11 14:51:06,585 DEBUG   SenderThread:17843 [sender.py:send():380] send: metric
2025-04-11 14:51:06,586 DEBUG   SenderThread:17843 [sender.py:send():380] send: telemetry
2025-04-11 14:51:06,586 DEBUG   SenderThread:17843 [sender.py:send():380] send: metric
2025-04-11 14:51:06,586 WARNING SenderThread:17843 [sender.py:send_metric():1329] Seen metric with glob (shouldn't happen)
2025-04-11 14:51:06,653 ERROR   wandb-upload_0:17843 [internal_api.py:upload_file():2556] upload_file exception https://storage.googleapis.com/wandb-production.appspot.com/2931823730-harbin-institute-of-technology/ltu-as/mlm5cp60/wandb-metadata.json?X-Goog-Algorithm=GOOG4-RSA-SHA256&X-Goog-Credential=gorilla-files-url-signer-man%40wandb-production.iam.gserviceaccount.com%2F20250411%2Fauto%2Fstorage%2Fgoog4_request&X-Goog-Date=20250411T145106Z&X-Goog-Expires=86399&X-Goog-Signature=5e61366a9cdba14e9366e693773cc7799673c98fe4965f87dc63e9596d3f0187754b4e166d7560ee536e464deebf60499d155fae33d314f1b808bc2ccf04fe2c2b6efba6d43259562807703d0c11efadf701d1f3e05abb6b0468adf02bd6951f959adbbc65e0e0d573f6077508150688e50412733d3f1fd1d82b1064ce9849427b169d276ec4abcb3c6ad012ae7b83463f0f43df52a7831651905f2c417198214e2d77562e52239192e58ea0c1a2ffac95120c36d81ee751e5ad5f0567ad413c9810baa3cdbf48f97d70e2753cf600570333d0c31fed9fdb63c272a974ee3c1de0d894e1ac50b3735ef19c262cef60219e3f1c55b31dfe63d31aed27b25d009c&X-Goog-SignedHeaders=host&X-User=2931823730: HTTPSConnectionPool(host='storage.googleapis.com', port=443): Max retries exceeded with url: /wandb-production.appspot.com/2931823730-harbin-institute-of-technology/ltu-as/mlm5cp60/wandb-metadata.json?X-Goog-Algorithm=GOOG4-RSA-SHA256&X-Goog-Credential=gorilla-files-url-signer-man%40wandb-production.iam.gserviceaccount.com%2F20250411%2Fauto%2Fstorage%2Fgoog4_request&X-Goog-Date=20250411T145106Z&X-Goog-Expires=86399&X-Goog-Signature=5e61366a9cdba14e9366e693773cc7799673c98fe4965f87dc63e9596d3f0187754b4e166d7560ee536e464deebf60499d155fae33d314f1b808bc2ccf04fe2c2b6efba6d43259562807703d0c11efadf701d1f3e05abb6b0468adf02bd6951f959adbbc65e0e0d573f6077508150688e50412733d3f1fd1d82b1064ce9849427b169d276ec4abcb3c6ad012ae7b83463f0f43df52a7831651905f2c417198214e2d77562e52239192e58ea0c1a2ffac95120c36d81ee751e5ad5f0567ad413c9810baa3cdbf48f97d70e2753cf600570333d0c31fed9fdb63c272a974ee3c1de0d894e1ac50b3735ef19c262cef60219e3f1c55b31dfe63d31aed27b25d009c&X-Goog-SignedHeaders=host&X-User=2931823730 (Caused by NewConnectionError('<urllib3.connection.HTTPSConnection object at 0x7f464c195420>: Failed to establish a new connection: [Errno 101] Network is unreachable'))
2025-04-11 14:51:06,653 ERROR   wandb-upload_0:17843 [internal_api.py:upload_file():2558] upload_file request headers: {'User-Agent': 'python-requests/2.32.3', 'Accept-Encoding': 'gzip, deflate, br', 'Accept': '*/*', 'Connection': 'keep-alive', 'Content-Length': '2274'}
2025-04-11 14:51:06,653 ERROR   wandb-upload_0:17843 [internal_api.py:upload_file():2560] upload_file response body: 
2025-04-11 14:51:06,839 INFO    Thread-12 :17843 [dir_watcher.py:_on_file_modified():288] file/dir modified: /root/ltu-main/ltu-main/src/ltu_as/train_scripts/wandb/run-20250411_145058-mlm5cp60/files/conda-environment.yaml
2025-04-11 14:51:06,840 INFO    Thread-12 :17843 [dir_watcher.py:_on_file_created():271] file/dir created: /root/ltu-main/ltu-main/src/ltu_as/train_scripts/wandb/run-20250411_145058-mlm5cp60/files/wandb-metadata.json
2025-04-11 14:51:06,840 INFO    Thread-12 :17843 [dir_watcher.py:_on_file_created():271] file/dir created: /root/ltu-main/ltu-main/src/ltu_as/train_scripts/wandb/run-20250411_145058-mlm5cp60/files/output.log
2025-04-11 14:51:07,721 ERROR   wandb-upload_0:17843 [internal_api.py:upload_file():2556] upload_file exception https://storage.googleapis.com/wandb-production.appspot.com/2931823730-harbin-institute-of-technology/ltu-as/mlm5cp60/wandb-metadata.json?X-Goog-Algorithm=GOOG4-RSA-SHA256&X-Goog-Credential=gorilla-files-url-signer-man%40wandb-production.iam.gserviceaccount.com%2F20250411%2Fauto%2Fstorage%2Fgoog4_request&X-Goog-Date=20250411T145106Z&X-Goog-Expires=86399&X-Goog-Signature=5e61366a9cdba14e9366e693773cc7799673c98fe4965f87dc63e9596d3f0187754b4e166d7560ee536e464deebf60499d155fae33d314f1b808bc2ccf04fe2c2b6efba6d43259562807703d0c11efadf701d1f3e05abb6b0468adf02bd6951f959adbbc65e0e0d573f6077508150688e50412733d3f1fd1d82b1064ce9849427b169d276ec4abcb3c6ad012ae7b83463f0f43df52a7831651905f2c417198214e2d77562e52239192e58ea0c1a2ffac95120c36d81ee751e5ad5f0567ad413c9810baa3cdbf48f97d70e2753cf600570333d0c31fed9fdb63c272a974ee3c1de0d894e1ac50b3735ef19c262cef60219e3f1c55b31dfe63d31aed27b25d009c&X-Goog-SignedHeaders=host&X-User=2931823730: HTTPSConnectionPool(host='storage.googleapis.com', port=443): Max retries exceeded with url: /wandb-production.appspot.com/2931823730-harbin-institute-of-technology/ltu-as/mlm5cp60/wandb-metadata.json?X-Goog-Algorithm=GOOG4-RSA-SHA256&X-Goog-Credential=gorilla-files-url-signer-man%40wandb-production.iam.gserviceaccount.com%2F20250411%2Fauto%2Fstorage%2Fgoog4_request&X-Goog-Date=20250411T145106Z&X-Goog-Expires=86399&X-Goog-Signature=5e61366a9cdba14e9366e693773cc7799673c98fe4965f87dc63e9596d3f0187754b4e166d7560ee536e464deebf60499d155fae33d314f1b808bc2ccf04fe2c2b6efba6d43259562807703d0c11efadf701d1f3e05abb6b0468adf02bd6951f959adbbc65e0e0d573f6077508150688e50412733d3f1fd1d82b1064ce9849427b169d276ec4abcb3c6ad012ae7b83463f0f43df52a7831651905f2c417198214e2d77562e52239192e58ea0c1a2ffac95120c36d81ee751e5ad5f0567ad413c9810baa3cdbf48f97d70e2753cf600570333d0c31fed9fdb63c272a974ee3c1de0d894e1ac50b3735ef19c262cef60219e3f1c55b31dfe63d31aed27b25d009c&X-Goog-SignedHeaders=host&X-User=2931823730 (Caused by NewConnectionError('<urllib3.connection.HTTPSConnection object at 0x7f464c196020>: Failed to establish a new connection: [Errno 101] Network is unreachable'))
2025-04-11 14:51:07,721 ERROR   wandb-upload_0:17843 [internal_api.py:upload_file():2558] upload_file request headers: {'User-Agent': 'python-requests/2.32.3', 'Accept-Encoding': 'gzip, deflate, br', 'Accept': '*/*', 'Connection': 'keep-alive', 'Content-Length': '2274'}
2025-04-11 14:51:07,721 ERROR   wandb-upload_0:17843 [internal_api.py:upload_file():2560] upload_file response body: 
2025-04-11 14:51:08,588 DEBUG   HandlerThread:17843 [handler.py:handle_request():146] handle_request: status_report
2025-04-11 14:51:08,840 INFO    Thread-12 :17843 [dir_watcher.py:_on_file_modified():288] file/dir modified: /root/ltu-main/ltu-main/src/ltu_as/train_scripts/wandb/run-20250411_145058-mlm5cp60/files/output.log
2025-04-11 14:51:09,796 ERROR   wandb-upload_0:17843 [internal_api.py:upload_file():2556] upload_file exception https://storage.googleapis.com/wandb-production.appspot.com/2931823730-harbin-institute-of-technology/ltu-as/mlm5cp60/wandb-metadata.json?X-Goog-Algorithm=GOOG4-RSA-SHA256&X-Goog-Credential=gorilla-files-url-signer-man%40wandb-production.iam.gserviceaccount.com%2F20250411%2Fauto%2Fstorage%2Fgoog4_request&X-Goog-Date=20250411T145106Z&X-Goog-Expires=86399&X-Goog-Signature=5e61366a9cdba14e9366e693773cc7799673c98fe4965f87dc63e9596d3f0187754b4e166d7560ee536e464deebf60499d155fae33d314f1b808bc2ccf04fe2c2b6efba6d43259562807703d0c11efadf701d1f3e05abb6b0468adf02bd6951f959adbbc65e0e0d573f6077508150688e50412733d3f1fd1d82b1064ce9849427b169d276ec4abcb3c6ad012ae7b83463f0f43df52a7831651905f2c417198214e2d77562e52239192e58ea0c1a2ffac95120c36d81ee751e5ad5f0567ad413c9810baa3cdbf48f97d70e2753cf600570333d0c31fed9fdb63c272a974ee3c1de0d894e1ac50b3735ef19c262cef60219e3f1c55b31dfe63d31aed27b25d009c&X-Goog-SignedHeaders=host&X-User=2931823730: HTTPSConnectionPool(host='storage.googleapis.com', port=443): Max retries exceeded with url: /wandb-production.appspot.com/2931823730-harbin-institute-of-technology/ltu-as/mlm5cp60/wandb-metadata.json?X-Goog-Algorithm=GOOG4-RSA-SHA256&X-Goog-Credential=gorilla-files-url-signer-man%40wandb-production.iam.gserviceaccount.com%2F20250411%2Fauto%2Fstorage%2Fgoog4_request&X-Goog-Date=20250411T145106Z&X-Goog-Expires=86399&X-Goog-Signature=5e61366a9cdba14e9366e693773cc7799673c98fe4965f87dc63e9596d3f0187754b4e166d7560ee536e464deebf60499d155fae33d314f1b808bc2ccf04fe2c2b6efba6d43259562807703d0c11efadf701d1f3e05abb6b0468adf02bd6951f959adbbc65e0e0d573f6077508150688e50412733d3f1fd1d82b1064ce9849427b169d276ec4abcb3c6ad012ae7b83463f0f43df52a7831651905f2c417198214e2d77562e52239192e58ea0c1a2ffac95120c36d81ee751e5ad5f0567ad413c9810baa3cdbf48f97d70e2753cf600570333d0c31fed9fdb63c272a974ee3c1de0d894e1ac50b3735ef19c262cef60219e3f1c55b31dfe63d31aed27b25d009c&X-Goog-SignedHeaders=host&X-User=2931823730 (Caused by NewConnectionError('<urllib3.connection.HTTPSConnection object at 0x7f464c1962f0>: Failed to establish a new connection: [Errno 101] Network is unreachable'))
2025-04-11 14:51:09,796 ERROR   wandb-upload_0:17843 [internal_api.py:upload_file():2558] upload_file request headers: {'User-Agent': 'python-requests/2.32.3', 'Accept-Encoding': 'gzip, deflate, br', 'Accept': '*/*', 'Connection': 'keep-alive', 'Content-Length': '2274'}
2025-04-11 14:51:09,796 ERROR   wandb-upload_0:17843 [internal_api.py:upload_file():2560] upload_file response body: 
2025-04-11 14:51:09,797 INFO    wandb-upload_0:17843 [retry.py:__call__():172] Retry attempt failed:
Traceback (most recent call last):
  File "/root/anaconda3/envs/venv_ltu/lib/python3.10/site-packages/urllib3/connection.py", line 198, in _new_conn
    sock = connection.create_connection(
  File "/root/anaconda3/envs/venv_ltu/lib/python3.10/site-packages/urllib3/util/connection.py", line 85, in create_connection
    raise err
  File "/root/anaconda3/envs/venv_ltu/lib/python3.10/site-packages/urllib3/util/connection.py", line 73, in create_connection
    sock.connect(sa)
OSError: [Errno 101] Network is unreachable

The above exception was the direct cause of the following exception:

Traceback (most recent call last):
  File "/root/anaconda3/envs/venv_ltu/lib/python3.10/site-packages/urllib3/connectionpool.py", line 793, in urlopen
    response = self._make_request(
  File "/root/anaconda3/envs/venv_ltu/lib/python3.10/site-packages/urllib3/connectionpool.py", line 491, in _make_request
    raise new_e
  File "/root/anaconda3/envs/venv_ltu/lib/python3.10/site-packages/urllib3/connectionpool.py", line 467, in _make_request
    self._validate_conn(conn)
  File "/root/anaconda3/envs/venv_ltu/lib/python3.10/site-packages/urllib3/connectionpool.py", line 1099, in _validate_conn
    conn.connect()
  File "/root/anaconda3/envs/venv_ltu/lib/python3.10/site-packages/urllib3/connection.py", line 616, in connect
    self.sock = sock = self._new_conn()
  File "/root/anaconda3/envs/venv_ltu/lib/python3.10/site-packages/urllib3/connection.py", line 213, in _new_conn
    raise NewConnectionError(
urllib3.exceptions.NewConnectionError: <urllib3.connection.HTTPSConnection object at 0x7f464c1962f0>: Failed to establish a new connection: [Errno 101] Network is unreachable

The above exception was the direct cause of the following exception:

Traceback (most recent call last):
  File "/root/anaconda3/envs/venv_ltu/lib/python3.10/site-packages/requests/adapters.py", line 667, in send
    resp = conn.urlopen(
  File "/root/anaconda3/envs/venv_ltu/lib/python3.10/site-packages/urllib3/connectionpool.py", line 847, in urlopen
    retries = retries.increment(
  File "/root/anaconda3/envs/venv_ltu/lib/python3.10/site-packages/urllib3/util/retry.py", line 515, in increment
    raise MaxRetryError(_pool, url, reason) from reason  # type: ignore[arg-type]
urllib3.exceptions.MaxRetryError: HTTPSConnectionPool(host='storage.googleapis.com', port=443): Max retries exceeded with url: /wandb-production.appspot.com/2931823730-harbin-institute-of-technology/ltu-as/mlm5cp60/wandb-metadata.json?X-Goog-Algorithm=GOOG4-RSA-SHA256&X-Goog-Credential=gorilla-files-url-signer-man%40wandb-production.iam.gserviceaccount.com%2F20250411%2Fauto%2Fstorage%2Fgoog4_request&X-Goog-Date=20250411T145106Z&X-Goog-Expires=86399&X-Goog-Signature=5e61366a9cdba14e9366e693773cc7799673c98fe4965f87dc63e9596d3f0187754b4e166d7560ee536e464deebf60499d155fae33d314f1b808bc2ccf04fe2c2b6efba6d43259562807703d0c11efadf701d1f3e05abb6b0468adf02bd6951f959adbbc65e0e0d573f6077508150688e50412733d3f1fd1d82b1064ce9849427b169d276ec4abcb3c6ad012ae7b83463f0f43df52a7831651905f2c417198214e2d77562e52239192e58ea0c1a2ffac95120c36d81ee751e5ad5f0567ad413c9810baa3cdbf48f97d70e2753cf600570333d0c31fed9fdb63c272a974ee3c1de0d894e1ac50b3735ef19c262cef60219e3f1c55b31dfe63d31aed27b25d009c&X-Goog-SignedHeaders=host&X-User=2931823730 (Caused by NewConnectionError('<urllib3.connection.HTTPSConnection object at 0x7f464c1962f0>: Failed to establish a new connection: [Errno 101] Network is unreachable'))

During handling of the above exception, another exception occurred:

Traceback (most recent call last):
  File "/root/anaconda3/envs/venv_ltu/lib/python3.10/site-packages/wandb/sdk/internal/internal_api.py", line 2549, in upload_file
    response = self._upload_file_session.put(
  File "/root/anaconda3/envs/venv_ltu/lib/python3.10/site-packages/requests/sessions.py", line 649, in put
    return self.request("PUT", url, data=data, **kwargs)
  File "/root/anaconda3/envs/venv_ltu/lib/python3.10/site-packages/requests/sessions.py", line 589, in request
    resp = self.send(prep, **send_kwargs)
  File "/root/anaconda3/envs/venv_ltu/lib/python3.10/site-packages/requests/sessions.py", line 703, in send
    r = adapter.send(request, **kwargs)
  File "/root/anaconda3/envs/venv_ltu/lib/python3.10/site-packages/requests/adapters.py", line 700, in send
    raise ConnectionError(e, request=request)
requests.exceptions.ConnectionError: HTTPSConnectionPool(host='storage.googleapis.com', port=443): Max retries exceeded with url: /wandb-production.appspot.com/2931823730-harbin-institute-of-technology/ltu-as/mlm5cp60/wandb-metadata.json?X-Goog-Algorithm=GOOG4-RSA-SHA256&X-Goog-Credential=gorilla-files-url-signer-man%40wandb-production.iam.gserviceaccount.com%2F20250411%2Fauto%2Fstorage%2Fgoog4_request&X-Goog-Date=20250411T145106Z&X-Goog-Expires=86399&X-Goog-Signature=5e61366a9cdba14e9366e693773cc7799673c98fe4965f87dc63e9596d3f0187754b4e166d7560ee536e464deebf60499d155fae33d314f1b808bc2ccf04fe2c2b6efba6d43259562807703d0c11efadf701d1f3e05abb6b0468adf02bd6951f959adbbc65e0e0d573f6077508150688e50412733d3f1fd1d82b1064ce9849427b169d276ec4abcb3c6ad012ae7b83463f0f43df52a7831651905f2c417198214e2d77562e52239192e58ea0c1a2ffac95120c36d81ee751e5ad5f0567ad413c9810baa3cdbf48f97d70e2753cf600570333d0c31fed9fdb63c272a974ee3c1de0d894e1ac50b3735ef19c262cef60219e3f1c55b31dfe63d31aed27b25d009c&X-Goog-SignedHeaders=host&X-User=2931823730 (Caused by NewConnectionError('<urllib3.connection.HTTPSConnection object at 0x7f464c1962f0>: Failed to establish a new connection: [Errno 101] Network is unreachable'))

During handling of the above exception, another exception occurred:

Traceback (most recent call last):
  File "/root/anaconda3/envs/venv_ltu/lib/python3.10/site-packages/wandb/sdk/lib/retry.py", line 131, in __call__
    result = self._call_fn(*args, **kwargs)
  File "/root/anaconda3/envs/venv_ltu/lib/python3.10/site-packages/wandb/sdk/internal/internal_api.py", line 2580, in upload_file
    raise _e.with_traceback(sys.exc_info()[2])
  File "/root/anaconda3/envs/venv_ltu/lib/python3.10/site-packages/wandb/sdk/internal/internal_api.py", line 2549, in upload_file
    response = self._upload_file_session.put(
  File "/root/anaconda3/envs/venv_ltu/lib/python3.10/site-packages/requests/sessions.py", line 649, in put
    return self.request("PUT", url, data=data, **kwargs)
  File "/root/anaconda3/envs/venv_ltu/lib/python3.10/site-packages/requests/sessions.py", line 589, in request
    resp = self.send(prep, **send_kwargs)
  File "/root/anaconda3/envs/venv_ltu/lib/python3.10/site-packages/requests/sessions.py", line 703, in send
    r = adapter.send(request, **kwargs)
  File "/root/anaconda3/envs/venv_ltu/lib/python3.10/site-packages/requests/adapters.py", line 700, in send
    raise ConnectionError(e, request=request)
wandb.sdk.lib.retry.TransientError: None
2025-04-11 14:51:12,290 DEBUG   SenderThread:17843 [sender.py:send():380] send: exit
2025-04-11 14:51:12,290 INFO    SenderThread:17843 [sender.py:send_exit():585] handling exit code: 1
2025-04-11 14:51:12,290 INFO    SenderThread:17843 [sender.py:send_exit():587] handling runtime: 12
2025-04-11 14:51:12,293 INFO    SenderThread:17843 [sender.py:_save_file():1378] saving file wandb-summary.json with policy end
2025-04-11 14:51:12,293 INFO    SenderThread:17843 [sender.py:send_exit():593] send defer
2025-04-11 14:51:12,294 DEBUG   HandlerThread:17843 [handler.py:handle_request():146] handle_request: defer
2025-04-11 14:51:12,294 INFO    HandlerThread:17843 [handler.py:handle_request_defer():172] handle defer: 0
2025-04-11 14:51:12,294 DEBUG   SenderThread:17843 [sender.py:send_request():407] send_request: defer
2025-04-11 14:51:12,294 INFO    SenderThread:17843 [sender.py:send_request_defer():609] handle sender defer: 0
2025-04-11 14:51:12,294 INFO    SenderThread:17843 [sender.py:transition_state():613] send defer: 1
2025-04-11 14:51:12,295 DEBUG   HandlerThread:17843 [handler.py:handle_request():146] handle_request: defer
2025-04-11 14:51:12,295 INFO    HandlerThread:17843 [handler.py:handle_request_defer():172] handle defer: 1
2025-04-11 14:51:12,295 DEBUG   SenderThread:17843 [sender.py:send_request():407] send_request: defer
2025-04-11 14:51:12,295 INFO    SenderThread:17843 [sender.py:send_request_defer():609] handle sender defer: 1
2025-04-11 14:51:12,295 INFO    SenderThread:17843 [sender.py:transition_state():613] send defer: 2
2025-04-11 14:51:12,295 DEBUG   HandlerThread:17843 [handler.py:handle_request():146] handle_request: defer
2025-04-11 14:51:12,295 INFO    HandlerThread:17843 [handler.py:handle_request_defer():172] handle defer: 2
2025-04-11 14:51:12,296 INFO    HandlerThread:17843 [system_monitor.py:finish():203] Stopping system monitor
2025-04-11 14:51:12,296 DEBUG   SystemMonitor:17843 [system_monitor.py:_start():172] Starting system metrics aggregation loop
2025-04-11 14:51:12,296 INFO    HandlerThread:17843 [interfaces.py:finish():202] Joined cpu monitor
2025-04-11 14:51:12,297 DEBUG   SystemMonitor:17843 [system_monitor.py:_start():179] Finished system metrics aggregation loop
2025-04-11 14:51:12,297 INFO    HandlerThread:17843 [interfaces.py:finish():202] Joined disk monitor
2025-04-11 14:51:12,298 DEBUG   SystemMonitor:17843 [system_monitor.py:_start():183] Publishing last batch of metrics
2025-04-11 14:51:12,319 INFO    HandlerThread:17843 [interfaces.py:finish():202] Joined gpu monitor
2025-04-11 14:51:12,319 INFO    HandlerThread:17843 [interfaces.py:finish():202] Joined memory monitor
2025-04-11 14:51:12,319 INFO    HandlerThread:17843 [interfaces.py:finish():202] Joined network monitor
2025-04-11 14:51:12,320 DEBUG   SenderThread:17843 [sender.py:send_request():407] send_request: defer
2025-04-11 14:51:12,320 INFO    SenderThread:17843 [sender.py:send_request_defer():609] handle sender defer: 2
2025-04-11 14:51:12,320 INFO    SenderThread:17843 [sender.py:transition_state():613] send defer: 3
2025-04-11 14:51:12,320 DEBUG   SenderThread:17843 [sender.py:send():380] send: stats
2025-04-11 14:51:12,320 DEBUG   HandlerThread:17843 [handler.py:handle_request():146] handle_request: defer
2025-04-11 14:51:12,320 INFO    HandlerThread:17843 [handler.py:handle_request_defer():172] handle defer: 3
2025-04-11 14:51:12,321 DEBUG   SenderThread:17843 [sender.py:send_request():407] send_request: defer
2025-04-11 14:51:12,321 INFO    SenderThread:17843 [sender.py:send_request_defer():609] handle sender defer: 3
2025-04-11 14:51:12,321 INFO    SenderThread:17843 [sender.py:transition_state():613] send defer: 4
2025-04-11 14:51:12,321 DEBUG   HandlerThread:17843 [handler.py:handle_request():146] handle_request: defer
2025-04-11 14:51:12,321 INFO    HandlerThread:17843 [handler.py:handle_request_defer():172] handle defer: 4
2025-04-11 14:51:12,321 DEBUG   SenderThread:17843 [sender.py:send_request():407] send_request: defer
2025-04-11 14:51:12,321 INFO    SenderThread:17843 [sender.py:send_request_defer():609] handle sender defer: 4
2025-04-11 14:51:12,321 INFO    SenderThread:17843 [sender.py:transition_state():613] send defer: 5
2025-04-11 14:51:12,322 DEBUG   HandlerThread:17843 [handler.py:handle_request():146] handle_request: defer
2025-04-11 14:51:12,322 INFO    HandlerThread:17843 [handler.py:handle_request_defer():172] handle defer: 5
2025-04-11 14:51:12,322 DEBUG   SenderThread:17843 [sender.py:send():380] send: summary
2025-04-11 14:51:12,326 INFO    SenderThread:17843 [sender.py:_save_file():1378] saving file wandb-summary.json with policy end
2025-04-11 14:51:12,326 DEBUG   SenderThread:17843 [sender.py:send_request():407] send_request: defer
2025-04-11 14:51:12,326 INFO    SenderThread:17843 [sender.py:send_request_defer():609] handle sender defer: 5
2025-04-11 14:51:12,326 INFO    SenderThread:17843 [sender.py:transition_state():613] send defer: 6
2025-04-11 14:51:12,326 DEBUG   HandlerThread:17843 [handler.py:handle_request():146] handle_request: defer
2025-04-11 14:51:12,326 INFO    HandlerThread:17843 [handler.py:handle_request_defer():172] handle defer: 6
2025-04-11 14:51:12,327 DEBUG   SenderThread:17843 [sender.py:send_request():407] send_request: defer
2025-04-11 14:51:12,327 INFO    SenderThread:17843 [sender.py:send_request_defer():609] handle sender defer: 6
2025-04-11 14:51:12,331 DEBUG   HandlerThread:17843 [handler.py:handle_request():146] handle_request: status_report
2025-04-11 14:51:12,671 INFO    SenderThread:17843 [sender.py:transition_state():613] send defer: 7
2025-04-11 14:51:12,671 DEBUG   HandlerThread:17843 [handler.py:handle_request():146] handle_request: defer
2025-04-11 14:51:12,672 INFO    HandlerThread:17843 [handler.py:handle_request_defer():172] handle defer: 7
2025-04-11 14:51:12,672 DEBUG   SenderThread:17843 [sender.py:send_request():407] send_request: defer
2025-04-11 14:51:12,672 INFO    SenderThread:17843 [sender.py:send_request_defer():609] handle sender defer: 7
2025-04-11 14:51:12,842 INFO    Thread-12 :17843 [dir_watcher.py:_on_file_modified():288] file/dir modified: /root/ltu-main/ltu-main/src/ltu_as/train_scripts/wandb/run-20250411_145058-mlm5cp60/files/config.yaml
2025-04-11 14:51:12,843 INFO    Thread-12 :17843 [dir_watcher.py:_on_file_created():271] file/dir created: /root/ltu-main/ltu-main/src/ltu_as/train_scripts/wandb/run-20250411_145058-mlm5cp60/files/wandb-summary.json
2025-04-11 14:51:13,289 DEBUG   HandlerThread:17843 [handler.py:handle_request():146] handle_request: poll_exit
2025-04-11 14:51:14,615 INFO    SenderThread:17843 [sender.py:transition_state():613] send defer: 8
2025-04-11 14:51:14,615 DEBUG   SenderThread:17843 [sender.py:send_request():407] send_request: poll_exit
2025-04-11 14:51:14,615 DEBUG   HandlerThread:17843 [handler.py:handle_request():146] handle_request: defer
2025-04-11 14:51:14,615 INFO    HandlerThread:17843 [handler.py:handle_request_defer():172] handle defer: 8
2025-04-11 14:51:14,616 DEBUG   SenderThread:17843 [sender.py:send_request():407] send_request: defer
2025-04-11 14:51:14,616 INFO    SenderThread:17843 [sender.py:send_request_defer():609] handle sender defer: 8
2025-04-11 14:51:14,616 INFO    SenderThread:17843 [job_builder.py:build():281] Attempting to build job artifact
2025-04-11 14:51:14,619 INFO    SenderThread:17843 [job_builder.py:_get_source_type():404] no source found
2025-04-11 14:51:14,619 INFO    SenderThread:17843 [sender.py:transition_state():613] send defer: 9
2025-04-11 14:51:14,619 DEBUG   HandlerThread:17843 [handler.py:handle_request():146] handle_request: defer
2025-04-11 14:51:14,620 INFO    HandlerThread:17843 [handler.py:handle_request_defer():172] handle defer: 9
2025-04-11 14:51:14,620 DEBUG   SenderThread:17843 [sender.py:send_request():407] send_request: defer
2025-04-11 14:51:14,620 INFO    SenderThread:17843 [sender.py:send_request_defer():609] handle sender defer: 9
2025-04-11 14:51:14,620 INFO    SenderThread:17843 [dir_watcher.py:finish():358] shutting down directory watcher
2025-04-11 14:51:14,727 ERROR   wandb-upload_0:17843 [internal_api.py:upload_file():2556] upload_file exception https://storage.googleapis.com/wandb-production.appspot.com/2931823730-harbin-institute-of-technology/ltu-as/mlm5cp60/wandb-metadata.json?X-Goog-Algorithm=GOOG4-RSA-SHA256&X-Goog-Credential=gorilla-files-url-signer-man%40wandb-production.iam.gserviceaccount.com%2F20250411%2Fauto%2Fstorage%2Fgoog4_request&X-Goog-Date=20250411T145106Z&X-Goog-Expires=86399&X-Goog-Signature=5e61366a9cdba14e9366e693773cc7799673c98fe4965f87dc63e9596d3f0187754b4e166d7560ee536e464deebf60499d155fae33d314f1b808bc2ccf04fe2c2b6efba6d43259562807703d0c11efadf701d1f3e05abb6b0468adf02bd6951f959adbbc65e0e0d573f6077508150688e50412733d3f1fd1d82b1064ce9849427b169d276ec4abcb3c6ad012ae7b83463f0f43df52a7831651905f2c417198214e2d77562e52239192e58ea0c1a2ffac95120c36d81ee751e5ad5f0567ad413c9810baa3cdbf48f97d70e2753cf600570333d0c31fed9fdb63c272a974ee3c1de0d894e1ac50b3735ef19c262cef60219e3f1c55b31dfe63d31aed27b25d009c&X-Goog-SignedHeaders=host&X-User=2931823730: HTTPSConnectionPool(host='storage.googleapis.com', port=443): Max retries exceeded with url: /wandb-production.appspot.com/2931823730-harbin-institute-of-technology/ltu-as/mlm5cp60/wandb-metadata.json?X-Goog-Algorithm=GOOG4-RSA-SHA256&X-Goog-Credential=gorilla-files-url-signer-man%40wandb-production.iam.gserviceaccount.com%2F20250411%2Fauto%2Fstorage%2Fgoog4_request&X-Goog-Date=20250411T145106Z&X-Goog-Expires=86399&X-Goog-Signature=5e61366a9cdba14e9366e693773cc7799673c98fe4965f87dc63e9596d3f0187754b4e166d7560ee536e464deebf60499d155fae33d314f1b808bc2ccf04fe2c2b6efba6d43259562807703d0c11efadf701d1f3e05abb6b0468adf02bd6951f959adbbc65e0e0d573f6077508150688e50412733d3f1fd1d82b1064ce9849427b169d276ec4abcb3c6ad012ae7b83463f0f43df52a7831651905f2c417198214e2d77562e52239192e58ea0c1a2ffac95120c36d81ee751e5ad5f0567ad413c9810baa3cdbf48f97d70e2753cf600570333d0c31fed9fdb63c272a974ee3c1de0d894e1ac50b3735ef19c262cef60219e3f1c55b31dfe63d31aed27b25d009c&X-Goog-SignedHeaders=host&X-User=2931823730 (Caused by NewConnectionError('<urllib3.connection.HTTPSConnection object at 0x7f464c197dc0>: Failed to establish a new connection: [Errno 101] Network is unreachable'))
2025-04-11 14:51:14,727 ERROR   wandb-upload_0:17843 [internal_api.py:upload_file():2558] upload_file request headers: {'User-Agent': 'python-requests/2.32.3', 'Accept-Encoding': 'gzip, deflate, br', 'Accept': '*/*', 'Connection': 'keep-alive', 'Content-Length': '2274'}
2025-04-11 14:51:14,727 ERROR   wandb-upload_0:17843 [internal_api.py:upload_file():2560] upload_file response body: 
2025-04-11 14:51:14,843 INFO    Thread-12 :17843 [dir_watcher.py:_on_file_modified():288] file/dir modified: /root/ltu-main/ltu-main/src/ltu_as/train_scripts/wandb/run-20250411_145058-mlm5cp60/files/output.log
2025-04-11 14:51:14,844 INFO    SenderThread:17843 [dir_watcher.py:finish():388] scan: /root/ltu-main/ltu-main/src/ltu_as/train_scripts/wandb/run-20250411_145058-mlm5cp60/files
2025-04-11 14:51:14,845 INFO    SenderThread:17843 [dir_watcher.py:finish():402] scan save: /root/ltu-main/ltu-main/src/ltu_as/train_scripts/wandb/run-20250411_145058-mlm5cp60/files/config.yaml config.yaml
2025-04-11 14:51:14,845 INFO    SenderThread:17843 [dir_watcher.py:finish():402] scan save: /root/ltu-main/ltu-main/src/ltu_as/train_scripts/wandb/run-20250411_145058-mlm5cp60/files/requirements.txt requirements.txt
2025-04-11 14:51:14,850 INFO    SenderThread:17843 [dir_watcher.py:finish():402] scan save: /root/ltu-main/ltu-main/src/ltu_as/train_scripts/wandb/run-20250411_145058-mlm5cp60/files/conda-environment.yaml conda-environment.yaml
2025-04-11 14:51:14,850 INFO    SenderThread:17843 [dir_watcher.py:finish():402] scan save: /root/ltu-main/ltu-main/src/ltu_as/train_scripts/wandb/run-20250411_145058-mlm5cp60/files/wandb-metadata.json wandb-metadata.json
2025-04-11 14:51:14,851 INFO    SenderThread:17843 [dir_watcher.py:finish():402] scan save: /root/ltu-main/ltu-main/src/ltu_as/train_scripts/wandb/run-20250411_145058-mlm5cp60/files/output.log output.log
2025-04-11 14:51:14,851 INFO    SenderThread:17843 [dir_watcher.py:finish():402] scan save: /root/ltu-main/ltu-main/src/ltu_as/train_scripts/wandb/run-20250411_145058-mlm5cp60/files/wandb-summary.json wandb-summary.json
2025-04-11 14:51:14,851 INFO    SenderThread:17843 [sender.py:transition_state():613] send defer: 10
2025-04-11 14:51:14,856 DEBUG   HandlerThread:17843 [handler.py:handle_request():146] handle_request: defer
2025-04-11 14:51:14,856 INFO    HandlerThread:17843 [handler.py:handle_request_defer():172] handle defer: 10
2025-04-11 14:51:14,863 DEBUG   SenderThread:17843 [sender.py:send_request():407] send_request: defer
2025-04-11 14:51:14,863 INFO    SenderThread:17843 [sender.py:send_request_defer():609] handle sender defer: 10
2025-04-11 14:51:14,863 INFO    SenderThread:17843 [file_pusher.py:finish():175] shutting down file pusher
2025-04-11 14:51:15,117 ERROR   wandb-upload_1:17843 [internal_api.py:upload_file():2556] upload_file exception https://storage.googleapis.com/wandb-production.appspot.com/2931823730-harbin-institute-of-technology/ltu-as/mlm5cp60/config.yaml?X-Goog-Algorithm=GOOG4-RSA-SHA256&X-Goog-Credential=gorilla-files-url-signer-man%40wandb-production.iam.gserviceaccount.com%2F20250411%2Fauto%2Fstorage%2Fgoog4_request&X-Goog-Date=20250411T145114Z&X-Goog-Expires=86399&X-Goog-Signature=944235794937f5025098c1ad39eaa00481a836c99c5822829b310120eb7d5a4666982e0e334a9357d37d9b7e4cb8fd4f3724f2d49c298240333fb06ed6be1b75da245bf972b74d0764218fb8da8150e6196b47290b328b850073b184f52a618c71c6fc15b6faa23f42ea4f43733bcf9b72a4ffce6124a6fabb01094b60566df348dc4ffb6145b7e1b56d8870304b0db1439adbc5d7d36e9dbedcb04ed306c15ea7e5660dd3c1a459a318151493ddac525b223c64c1c3acd07b1074ffb2bae2a2c5748e1ccfa4dba073a06ddff15af3a314e16ae4a851154ac4a30a6b911fdd8835407050fbc7b5592ead92e01e0d5bee0d8d8fcb5b9ea7d5b9b626f96466baed&X-Goog-SignedHeaders=host&X-User=2931823730: HTTPSConnectionPool(host='storage.googleapis.com', port=443): Max retries exceeded with url: /wandb-production.appspot.com/2931823730-harbin-institute-of-technology/ltu-as/mlm5cp60/config.yaml?X-Goog-Algorithm=GOOG4-RSA-SHA256&X-Goog-Credential=gorilla-files-url-signer-man%40wandb-production.iam.gserviceaccount.com%2F20250411%2Fauto%2Fstorage%2Fgoog4_request&X-Goog-Date=20250411T145114Z&X-Goog-Expires=86399&X-Goog-Signature=944235794937f5025098c1ad39eaa00481a836c99c5822829b310120eb7d5a4666982e0e334a9357d37d9b7e4cb8fd4f3724f2d49c298240333fb06ed6be1b75da245bf972b74d0764218fb8da8150e6196b47290b328b850073b184f52a618c71c6fc15b6faa23f42ea4f43733bcf9b72a4ffce6124a6fabb01094b60566df348dc4ffb6145b7e1b56d8870304b0db1439adbc5d7d36e9dbedcb04ed306c15ea7e5660dd3c1a459a318151493ddac525b223c64c1c3acd07b1074ffb2bae2a2c5748e1ccfa4dba073a06ddff15af3a314e16ae4a851154ac4a30a6b911fdd8835407050fbc7b5592ead92e01e0d5bee0d8d8fcb5b9ea7d5b9b626f96466baed&X-Goog-SignedHeaders=host&X-User=2931823730 (Caused by NewConnectionError('<urllib3.connection.HTTPSConnection object at 0x7f464c197250>: Failed to establish a new connection: [Errno 101] Network is unreachable'))
2025-04-11 14:51:15,117 ERROR   wandb-upload_1:17843 [internal_api.py:upload_file():2558] upload_file request headers: {'User-Agent': 'python-requests/2.32.3', 'Accept-Encoding': 'gzip, deflate, br', 'Accept': '*/*', 'Connection': 'keep-alive', 'Content-Length': '8685'}
2025-04-11 14:51:15,117 ERROR   wandb-upload_1:17843 [internal_api.py:upload_file():2560] upload_file response body: 
2025-04-11 14:51:15,133 ERROR   wandb-upload_2:17843 [internal_api.py:upload_file():2556] upload_file exception https://storage.googleapis.com/wandb-production.appspot.com/2931823730-harbin-institute-of-technology/ltu-as/mlm5cp60/requirements.txt?X-Goog-Algorithm=GOOG4-RSA-SHA256&X-Goog-Credential=gorilla-files-url-signer-man%40wandb-production.iam.gserviceaccount.com%2F20250411%2Fauto%2Fstorage%2Fgoog4_request&X-Goog-Date=20250411T145114Z&X-Goog-Expires=86399&X-Goog-Signature=acbd028386bc03d94948aaf65bc53bf77977ac5585e79ea0716ec007860ef39ea96f93094178bbe53396288150856563223a0e942bd376af8b161d4d58a6cf0e9dbea71fc7a9410c6f71628492009b7953de41033e7b38937eb708bfb6ada10c77ca0870f3d12be57f6d029ecfb8822e7dc5a62df88082610c8fc02b7aa861cee7e448378ac9d23208529f4a5e6344e6123aa73d657af02d72994735111ae518708f803b7f58dec8713f9eceb068ad7513a1b67628cc6fcf386e87c1a6dad3ca8abbf5fe3d3e33a074098ac226b071cc8aec87b300c8c753ac0940760332a70b2be12d9199bfeb835e45ee4c7766e2aaeab19a9da94cb9c52d45ad6563a0c27f&X-Goog-SignedHeaders=host&X-User=2931823730: HTTPSConnectionPool(host='storage.googleapis.com', port=443): Max retries exceeded with url: /wandb-production.appspot.com/2931823730-harbin-institute-of-technology/ltu-as/mlm5cp60/requirements.txt?X-Goog-Algorithm=GOOG4-RSA-SHA256&X-Goog-Credential=gorilla-files-url-signer-man%40wandb-production.iam.gserviceaccount.com%2F20250411%2Fauto%2Fstorage%2Fgoog4_request&X-Goog-Date=20250411T145114Z&X-Goog-Expires=86399&X-Goog-Signature=acbd028386bc03d94948aaf65bc53bf77977ac5585e79ea0716ec007860ef39ea96f93094178bbe53396288150856563223a0e942bd376af8b161d4d58a6cf0e9dbea71fc7a9410c6f71628492009b7953de41033e7b38937eb708bfb6ada10c77ca0870f3d12be57f6d029ecfb8822e7dc5a62df88082610c8fc02b7aa861cee7e448378ac9d23208529f4a5e6344e6123aa73d657af02d72994735111ae518708f803b7f58dec8713f9eceb068ad7513a1b67628cc6fcf386e87c1a6dad3ca8abbf5fe3d3e33a074098ac226b071cc8aec87b300c8c753ac0940760332a70b2be12d9199bfeb835e45ee4c7766e2aaeab19a9da94cb9c52d45ad6563a0c27f&X-Goog-SignedHeaders=host&X-User=2931823730 (Caused by NewConnectionError('<urllib3.connection.HTTPSConnection object at 0x7f464c1976d0>: Failed to establish a new connection: [Errno 101] Network is unreachable'))
2025-04-11 14:51:15,133 ERROR   wandb-upload_2:17843 [internal_api.py:upload_file():2558] upload_file request headers: {'User-Agent': 'python-requests/2.32.3', 'Accept-Encoding': 'gzip, deflate, br', 'Accept': '*/*', 'Connection': 'keep-alive', 'Content-Length': '4212'}
2025-04-11 14:51:15,133 ERROR   wandb-upload_2:17843 [internal_api.py:upload_file():2560] upload_file response body: 
2025-04-11 14:51:15,327 ERROR   wandb-upload_5:17843 [internal_api.py:upload_file():2556] upload_file exception https://storage.googleapis.com/wandb-production.appspot.com/2931823730-harbin-institute-of-technology/ltu-as/mlm5cp60/wandb-summary.json?X-Goog-Algorithm=GOOG4-RSA-SHA256&X-Goog-Credential=gorilla-files-url-signer-man%40wandb-production.iam.gserviceaccount.com%2F20250411%2Fauto%2Fstorage%2Fgoog4_request&X-Goog-Date=20250411T145115Z&X-Goog-Expires=86399&X-Goog-Signature=9df2087e11492ad178d77d9e9fab97630232b0a4f96a431148e4daf3a3ffb76f141a6acc698d2740403fe5d6787ed13f31ea70b94181a053e6e9bfe3b29b740f760a5a90f424f03e99c5b223fc30b089129e72948a62f1760c560b7f1eb6038148a7932d92a6c49a8613d4c7c04501f90b05b4395abd8bec4475d17d5fb0c4f0abdc39833cf913bd4da65c1c091140821a3269fc0d9ca812c0aaaceb66744bedabc6e1cc1b30e8946fc2d71819ae2467e1b4a3a0776572ba1fab93fa95fd681e3209826ea4ec41e0cdd752b417e53356fffd31afc35e8b7c23e46b68c60bd862806ba43d57d1fb048b5ba045a2b204376bd24fe7b11077307f2a2ccff7f3704e&X-Goog-SignedHeaders=host&X-User=2931823730: HTTPSConnectionPool(host='storage.googleapis.com', port=443): Max retries exceeded with url: /wandb-production.appspot.com/2931823730-harbin-institute-of-technology/ltu-as/mlm5cp60/wandb-summary.json?X-Goog-Algorithm=GOOG4-RSA-SHA256&X-Goog-Credential=gorilla-files-url-signer-man%40wandb-production.iam.gserviceaccount.com%2F20250411%2Fauto%2Fstorage%2Fgoog4_request&X-Goog-Date=20250411T145115Z&X-Goog-Expires=86399&X-Goog-Signature=9df2087e11492ad178d77d9e9fab97630232b0a4f96a431148e4daf3a3ffb76f141a6acc698d2740403fe5d6787ed13f31ea70b94181a053e6e9bfe3b29b740f760a5a90f424f03e99c5b223fc30b089129e72948a62f1760c560b7f1eb6038148a7932d92a6c49a8613d4c7c04501f90b05b4395abd8bec4475d17d5fb0c4f0abdc39833cf913bd4da65c1c091140821a3269fc0d9ca812c0aaaceb66744bedabc6e1cc1b30e8946fc2d71819ae2467e1b4a3a0776572ba1fab93fa95fd681e3209826ea4ec41e0cdd752b417e53356fffd31afc35e8b7c23e46b68c60bd862806ba43d57d1fb048b5ba045a2b204376bd24fe7b11077307f2a2ccff7f3704e&X-Goog-SignedHeaders=host&X-User=2931823730 (Caused by NewConnectionError('<urllib3.connection.HTTPSConnection object at 0x7f464c196170>: Failed to establish a new connection: [Errno 101] Network is unreachable'))
2025-04-11 14:51:15,327 ERROR   wandb-upload_5:17843 [internal_api.py:upload_file():2558] upload_file request headers: {'User-Agent': 'python-requests/2.32.3', 'Accept-Encoding': 'gzip, deflate, br', 'Accept': '*/*', 'Connection': 'keep-alive', 'Content-Length': '27'}
2025-04-11 14:51:15,327 ERROR   wandb-upload_5:17843 [internal_api.py:upload_file():2560] upload_file response body: 
2025-04-11 14:51:15,328 ERROR   wandb-upload_4:17843 [internal_api.py:upload_file():2556] upload_file exception https://storage.googleapis.com/wandb-production.appspot.com/2931823730-harbin-institute-of-technology/ltu-as/mlm5cp60/output.log?X-Goog-Algorithm=GOOG4-RSA-SHA256&X-Goog-Credential=gorilla-files-url-signer-man%40wandb-production.iam.gserviceaccount.com%2F20250411%2Fauto%2Fstorage%2Fgoog4_request&X-Goog-Date=20250411T145115Z&X-Goog-Expires=86399&X-Goog-Signature=66829b877c42ca303b639780fff7bf88cbb60209259c7dc6d23083a84ea8a96b64d71ff0c30cfcd6586ba916252610aa15480efdf90421949aa85f951f9b619e468eda017b8e55a28c0dd8aa6f99210f3f778f8a86e71dc469c624bf57498806db03fe0da4046f07d2c7f46ebf78d08027dddd14f7a09c4e83545aa9466da1eb6bbcaa07656e8c5098eb49767523418a66675017d803a591dae803119383f64fd0a7046d0036e02ac698d4dae626392e5291c9836cbd2eaea947ec9227980072d7bf72433004230cc067028ae4702b9478433d2bac33dd2edcdea1ff05ace0e6798c3b76707a6db65d093dae199f68cfbd61847341fb284cad3d6d9cc1489b0e&X-Goog-SignedHeaders=host&X-User=2931823730: HTTPSConnectionPool(host='storage.googleapis.com', port=443): Max retries exceeded with url: /wandb-production.appspot.com/2931823730-harbin-institute-of-technology/ltu-as/mlm5cp60/output.log?X-Goog-Algorithm=GOOG4-RSA-SHA256&X-Goog-Credential=gorilla-files-url-signer-man%40wandb-production.iam.gserviceaccount.com%2F20250411%2Fauto%2Fstorage%2Fgoog4_request&X-Goog-Date=20250411T145115Z&X-Goog-Expires=86399&X-Goog-Signature=66829b877c42ca303b639780fff7bf88cbb60209259c7dc6d23083a84ea8a96b64d71ff0c30cfcd6586ba916252610aa15480efdf90421949aa85f951f9b619e468eda017b8e55a28c0dd8aa6f99210f3f778f8a86e71dc469c624bf57498806db03fe0da4046f07d2c7f46ebf78d08027dddd14f7a09c4e83545aa9466da1eb6bbcaa07656e8c5098eb49767523418a66675017d803a591dae803119383f64fd0a7046d0036e02ac698d4dae626392e5291c9836cbd2eaea947ec9227980072d7bf72433004230cc067028ae4702b9478433d2bac33dd2edcdea1ff05ace0e6798c3b76707a6db65d093dae199f68cfbd61847341fb284cad3d6d9cc1489b0e&X-Goog-SignedHeaders=host&X-User=2931823730 (Caused by NewConnectionError('<urllib3.connection.HTTPSConnection object at 0x7f464c197640>: Failed to establish a new connection: [Errno 101] Network is unreachable'))
2025-04-11 14:51:15,328 ERROR   wandb-upload_4:17843 [internal_api.py:upload_file():2558] upload_file request headers: {'User-Agent': 'python-requests/2.32.3', 'Accept-Encoding': 'gzip, deflate, br', 'Accept': '*/*', 'Connection': 'keep-alive', 'Content-Length': '4566'}
2025-04-11 14:51:15,328 ERROR   wandb-upload_4:17843 [internal_api.py:upload_file():2560] upload_file response body: 
2025-04-11 14:51:15,400 ERROR   wandb-upload_3:17843 [internal_api.py:upload_file():2556] upload_file exception https://storage.googleapis.com/wandb-production.appspot.com/2931823730-harbin-institute-of-technology/ltu-as/mlm5cp60/conda-environment.yaml?X-Goog-Algorithm=GOOG4-RSA-SHA256&X-Goog-Credential=gorilla-files-url-signer-man%40wandb-production.iam.gserviceaccount.com%2F20250411%2Fauto%2Fstorage%2Fgoog4_request&X-Goog-Date=20250411T145115Z&X-Goog-Expires=86399&X-Goog-Signature=18c9185561c0e38a4095f6492f7ba3109bb74b7ca241ce5eba7e7367298010776513c088c54a371846d5c60ffa97e1926acad93ddaeb7f1e863a32adfdbd3ffc7bd69000bb824d131ffd311a667fb373a02ed98fdde3d3caad24788ea1354f96c4dc5978d4dd03d993fdc19d79c0bbe55b08cbcf76dd3880dac13b40fb199889896f2944e570131678d4e0919686f72ab8a582d56638e963c3f9f8381660cc5a8e5124ccfb7760a0091bef421e6d0f0d3730b307cd29f88f8c5494dac201cc0a86ef0c41611677a875a6db0e8bddf08d412fb945a3c2ad3f19455ce2420ce93516e3e900072ff66ab558af6cd2677815e466cfd6ffe2abe2071b697185a279bd&X-Goog-SignedHeaders=host&X-User=2931823730: HTTPSConnectionPool(host='storage.googleapis.com', port=443): Max retries exceeded with url: /wandb-production.appspot.com/2931823730-harbin-institute-of-technology/ltu-as/mlm5cp60/conda-environment.yaml?X-Goog-Algorithm=GOOG4-RSA-SHA256&X-Goog-Credential=gorilla-files-url-signer-man%40wandb-production.iam.gserviceaccount.com%2F20250411%2Fauto%2Fstorage%2Fgoog4_request&X-Goog-Date=20250411T145115Z&X-Goog-Expires=86399&X-Goog-Signature=18c9185561c0e38a4095f6492f7ba3109bb74b7ca241ce5eba7e7367298010776513c088c54a371846d5c60ffa97e1926acad93ddaeb7f1e863a32adfdbd3ffc7bd69000bb824d131ffd311a667fb373a02ed98fdde3d3caad24788ea1354f96c4dc5978d4dd03d993fdc19d79c0bbe55b08cbcf76dd3880dac13b40fb199889896f2944e570131678d4e0919686f72ab8a582d56638e963c3f9f8381660cc5a8e5124ccfb7760a0091bef421e6d0f0d3730b307cd29f88f8c5494dac201cc0a86ef0c41611677a875a6db0e8bddf08d412fb945a3c2ad3f19455ce2420ce93516e3e900072ff66ab558af6cd2677815e466cfd6ffe2abe2071b697185a279bd&X-Goog-SignedHeaders=host&X-User=2931823730 (Caused by NewConnectionError('<urllib3.connection.HTTPSConnection object at 0x7f464c197e50>: Failed to establish a new connection: [Errno 101] Network is unreachable'))
2025-04-11 14:51:15,400 ERROR   wandb-upload_3:17843 [internal_api.py:upload_file():2558] upload_file request headers: {'User-Agent': 'python-requests/2.32.3', 'Accept-Encoding': 'gzip, deflate, br', 'Accept': '*/*', 'Connection': 'keep-alive', 'Content-Length': '8281'}
2025-04-11 14:51:15,401 ERROR   wandb-upload_3:17843 [internal_api.py:upload_file():2560] upload_file response body: 
2025-04-11 14:51:16,150 ERROR   wandb-upload_2:17843 [internal_api.py:upload_file():2556] upload_file exception https://storage.googleapis.com/wandb-production.appspot.com/2931823730-harbin-institute-of-technology/ltu-as/mlm5cp60/requirements.txt?X-Goog-Algorithm=GOOG4-RSA-SHA256&X-Goog-Credential=gorilla-files-url-signer-man%40wandb-production.iam.gserviceaccount.com%2F20250411%2Fauto%2Fstorage%2Fgoog4_request&X-Goog-Date=20250411T145114Z&X-Goog-Expires=86399&X-Goog-Signature=acbd028386bc03d94948aaf65bc53bf77977ac5585e79ea0716ec007860ef39ea96f93094178bbe53396288150856563223a0e942bd376af8b161d4d58a6cf0e9dbea71fc7a9410c6f71628492009b7953de41033e7b38937eb708bfb6ada10c77ca0870f3d12be57f6d029ecfb8822e7dc5a62df88082610c8fc02b7aa861cee7e448378ac9d23208529f4a5e6344e6123aa73d657af02d72994735111ae518708f803b7f58dec8713f9eceb068ad7513a1b67628cc6fcf386e87c1a6dad3ca8abbf5fe3d3e33a074098ac226b071cc8aec87b300c8c753ac0940760332a70b2be12d9199bfeb835e45ee4c7766e2aaeab19a9da94cb9c52d45ad6563a0c27f&X-Goog-SignedHeaders=host&X-User=2931823730: HTTPSConnectionPool(host='storage.googleapis.com', port=443): Max retries exceeded with url: /wandb-production.appspot.com/2931823730-harbin-institute-of-technology/ltu-as/mlm5cp60/requirements.txt?X-Goog-Algorithm=GOOG4-RSA-SHA256&X-Goog-Credential=gorilla-files-url-signer-man%40wandb-production.iam.gserviceaccount.com%2F20250411%2Fauto%2Fstorage%2Fgoog4_request&X-Goog-Date=20250411T145114Z&X-Goog-Expires=86399&X-Goog-Signature=acbd028386bc03d94948aaf65bc53bf77977ac5585e79ea0716ec007860ef39ea96f93094178bbe53396288150856563223a0e942bd376af8b161d4d58a6cf0e9dbea71fc7a9410c6f71628492009b7953de41033e7b38937eb708bfb6ada10c77ca0870f3d12be57f6d029ecfb8822e7dc5a62df88082610c8fc02b7aa861cee7e448378ac9d23208529f4a5e6344e6123aa73d657af02d72994735111ae518708f803b7f58dec8713f9eceb068ad7513a1b67628cc6fcf386e87c1a6dad3ca8abbf5fe3d3e33a074098ac226b071cc8aec87b300c8c753ac0940760332a70b2be12d9199bfeb835e45ee4c7766e2aaeab19a9da94cb9c52d45ad6563a0c27f&X-Goog-SignedHeaders=host&X-User=2931823730 (Caused by NewConnectionError('<urllib3.connection.HTTPSConnection object at 0x7f462ce1e050>: Failed to establish a new connection: [Errno 101] Network is unreachable'))
2025-04-11 14:51:16,150 ERROR   wandb-upload_2:17843 [internal_api.py:upload_file():2558] upload_file request headers: {'User-Agent': 'python-requests/2.32.3', 'Accept-Encoding': 'gzip, deflate, br', 'Accept': '*/*', 'Connection': 'keep-alive', 'Content-Length': '4212'}
2025-04-11 14:51:16,150 ERROR   wandb-upload_2:17843 [internal_api.py:upload_file():2560] upload_file response body: 
2025-04-11 14:51:16,225 ERROR   wandb-upload_1:17843 [internal_api.py:upload_file():2556] upload_file exception https://storage.googleapis.com/wandb-production.appspot.com/2931823730-harbin-institute-of-technology/ltu-as/mlm5cp60/config.yaml?X-Goog-Algorithm=GOOG4-RSA-SHA256&X-Goog-Credential=gorilla-files-url-signer-man%40wandb-production.iam.gserviceaccount.com%2F20250411%2Fauto%2Fstorage%2Fgoog4_request&X-Goog-Date=20250411T145114Z&X-Goog-Expires=86399&X-Goog-Signature=944235794937f5025098c1ad39eaa00481a836c99c5822829b310120eb7d5a4666982e0e334a9357d37d9b7e4cb8fd4f3724f2d49c298240333fb06ed6be1b75da245bf972b74d0764218fb8da8150e6196b47290b328b850073b184f52a618c71c6fc15b6faa23f42ea4f43733bcf9b72a4ffce6124a6fabb01094b60566df348dc4ffb6145b7e1b56d8870304b0db1439adbc5d7d36e9dbedcb04ed306c15ea7e5660dd3c1a459a318151493ddac525b223c64c1c3acd07b1074ffb2bae2a2c5748e1ccfa4dba073a06ddff15af3a314e16ae4a851154ac4a30a6b911fdd8835407050fbc7b5592ead92e01e0d5bee0d8d8fcb5b9ea7d5b9b626f96466baed&X-Goog-SignedHeaders=host&X-User=2931823730: HTTPSConnectionPool(host='storage.googleapis.com', port=443): Max retries exceeded with url: /wandb-production.appspot.com/2931823730-harbin-institute-of-technology/ltu-as/mlm5cp60/config.yaml?X-Goog-Algorithm=GOOG4-RSA-SHA256&X-Goog-Credential=gorilla-files-url-signer-man%40wandb-production.iam.gserviceaccount.com%2F20250411%2Fauto%2Fstorage%2Fgoog4_request&X-Goog-Date=20250411T145114Z&X-Goog-Expires=86399&X-Goog-Signature=944235794937f5025098c1ad39eaa00481a836c99c5822829b310120eb7d5a4666982e0e334a9357d37d9b7e4cb8fd4f3724f2d49c298240333fb06ed6be1b75da245bf972b74d0764218fb8da8150e6196b47290b328b850073b184f52a618c71c6fc15b6faa23f42ea4f43733bcf9b72a4ffce6124a6fabb01094b60566df348dc4ffb6145b7e1b56d8870304b0db1439adbc5d7d36e9dbedcb04ed306c15ea7e5660dd3c1a459a318151493ddac525b223c64c1c3acd07b1074ffb2bae2a2c5748e1ccfa4dba073a06ddff15af3a314e16ae4a851154ac4a30a6b911fdd8835407050fbc7b5592ead92e01e0d5bee0d8d8fcb5b9ea7d5b9b626f96466baed&X-Goog-SignedHeaders=host&X-User=2931823730 (Caused by NewConnectionError('<urllib3.connection.HTTPSConnection object at 0x7f462ce1d720>: Failed to establish a new connection: [Errno 101] Network is unreachable'))
2025-04-11 14:51:16,225 ERROR   wandb-upload_1:17843 [internal_api.py:upload_file():2558] upload_file request headers: {'User-Agent': 'python-requests/2.32.3', 'Accept-Encoding': 'gzip, deflate, br', 'Accept': '*/*', 'Connection': 'keep-alive', 'Content-Length': '8685'}
2025-04-11 14:51:16,226 ERROR   wandb-upload_1:17843 [internal_api.py:upload_file():2560] upload_file response body: 
2025-04-11 14:51:16,226 INFO    wandb-upload_1:17843 [retry.py:__call__():172] Retry attempt failed:
Traceback (most recent call last):
  File "/root/anaconda3/envs/venv_ltu/lib/python3.10/site-packages/urllib3/connection.py", line 198, in _new_conn
    sock = connection.create_connection(
  File "/root/anaconda3/envs/venv_ltu/lib/python3.10/site-packages/urllib3/util/connection.py", line 85, in create_connection
    raise err
  File "/root/anaconda3/envs/venv_ltu/lib/python3.10/site-packages/urllib3/util/connection.py", line 73, in create_connection
    sock.connect(sa)
OSError: [Errno 101] Network is unreachable

The above exception was the direct cause of the following exception:

Traceback (most recent call last):
  File "/root/anaconda3/envs/venv_ltu/lib/python3.10/site-packages/urllib3/connectionpool.py", line 793, in urlopen
    response = self._make_request(
  File "/root/anaconda3/envs/venv_ltu/lib/python3.10/site-packages/urllib3/connectionpool.py", line 491, in _make_request
    raise new_e
  File "/root/anaconda3/envs/venv_ltu/lib/python3.10/site-packages/urllib3/connectionpool.py", line 467, in _make_request
    self._validate_conn(conn)
  File "/root/anaconda3/envs/venv_ltu/lib/python3.10/site-packages/urllib3/connectionpool.py", line 1099, in _validate_conn
    conn.connect()
  File "/root/anaconda3/envs/venv_ltu/lib/python3.10/site-packages/urllib3/connection.py", line 616, in connect
    self.sock = sock = self._new_conn()
  File "/root/anaconda3/envs/venv_ltu/lib/python3.10/site-packages/urllib3/connection.py", line 213, in _new_conn
    raise NewConnectionError(
urllib3.exceptions.NewConnectionError: <urllib3.connection.HTTPSConnection object at 0x7f462ce1d720>: Failed to establish a new connection: [Errno 101] Network is unreachable

The above exception was the direct cause of the following exception:

Traceback (most recent call last):
  File "/root/anaconda3/envs/venv_ltu/lib/python3.10/site-packages/requests/adapters.py", line 667, in send
    resp = conn.urlopen(
  File "/root/anaconda3/envs/venv_ltu/lib/python3.10/site-packages/urllib3/connectionpool.py", line 847, in urlopen
    retries = retries.increment(
  File "/root/anaconda3/envs/venv_ltu/lib/python3.10/site-packages/urllib3/util/retry.py", line 515, in increment
    raise MaxRetryError(_pool, url, reason) from reason  # type: ignore[arg-type]
urllib3.exceptions.MaxRetryError: HTTPSConnectionPool(host='storage.googleapis.com', port=443): Max retries exceeded with url: /wandb-production.appspot.com/2931823730-harbin-institute-of-technology/ltu-as/mlm5cp60/config.yaml?X-Goog-Algorithm=GOOG4-RSA-SHA256&X-Goog-Credential=gorilla-files-url-signer-man%40wandb-production.iam.gserviceaccount.com%2F20250411%2Fauto%2Fstorage%2Fgoog4_request&X-Goog-Date=20250411T145114Z&X-Goog-Expires=86399&X-Goog-Signature=944235794937f5025098c1ad39eaa00481a836c99c5822829b310120eb7d5a4666982e0e334a9357d37d9b7e4cb8fd4f3724f2d49c298240333fb06ed6be1b75da245bf972b74d0764218fb8da8150e6196b47290b328b850073b184f52a618c71c6fc15b6faa23f42ea4f43733bcf9b72a4ffce6124a6fabb01094b60566df348dc4ffb6145b7e1b56d8870304b0db1439adbc5d7d36e9dbedcb04ed306c15ea7e5660dd3c1a459a318151493ddac525b223c64c1c3acd07b1074ffb2bae2a2c5748e1ccfa4dba073a06ddff15af3a314e16ae4a851154ac4a30a6b911fdd8835407050fbc7b5592ead92e01e0d5bee0d8d8fcb5b9ea7d5b9b626f96466baed&X-Goog-SignedHeaders=host&X-User=2931823730 (Caused by NewConnectionError('<urllib3.connection.HTTPSConnection object at 0x7f462ce1d720>: Failed to establish a new connection: [Errno 101] Network is unreachable'))

During handling of the above exception, another exception occurred:

Traceback (most recent call last):
  File "/root/anaconda3/envs/venv_ltu/lib/python3.10/site-packages/wandb/sdk/internal/internal_api.py", line 2549, in upload_file
    response = self._upload_file_session.put(
  File "/root/anaconda3/envs/venv_ltu/lib/python3.10/site-packages/requests/sessions.py", line 649, in put
    return self.request("PUT", url, data=data, **kwargs)
  File "/root/anaconda3/envs/venv_ltu/lib/python3.10/site-packages/requests/sessions.py", line 589, in request
    resp = self.send(prep, **send_kwargs)
  File "/root/anaconda3/envs/venv_ltu/lib/python3.10/site-packages/requests/sessions.py", line 703, in send
    r = adapter.send(request, **kwargs)
  File "/root/anaconda3/envs/venv_ltu/lib/python3.10/site-packages/requests/adapters.py", line 700, in send
    raise ConnectionError(e, request=request)
requests.exceptions.ConnectionError: HTTPSConnectionPool(host='storage.googleapis.com', port=443): Max retries exceeded with url: /wandb-production.appspot.com/2931823730-harbin-institute-of-technology/ltu-as/mlm5cp60/config.yaml?X-Goog-Algorithm=GOOG4-RSA-SHA256&X-Goog-Credential=gorilla-files-url-signer-man%40wandb-production.iam.gserviceaccount.com%2F20250411%2Fauto%2Fstorage%2Fgoog4_request&X-Goog-Date=20250411T145114Z&X-Goog-Expires=86399&X-Goog-Signature=944235794937f5025098c1ad39eaa00481a836c99c5822829b310120eb7d5a4666982e0e334a9357d37d9b7e4cb8fd4f3724f2d49c298240333fb06ed6be1b75da245bf972b74d0764218fb8da8150e6196b47290b328b850073b184f52a618c71c6fc15b6faa23f42ea4f43733bcf9b72a4ffce6124a6fabb01094b60566df348dc4ffb6145b7e1b56d8870304b0db1439adbc5d7d36e9dbedcb04ed306c15ea7e5660dd3c1a459a318151493ddac525b223c64c1c3acd07b1074ffb2bae2a2c5748e1ccfa4dba073a06ddff15af3a314e16ae4a851154ac4a30a6b911fdd8835407050fbc7b5592ead92e01e0d5bee0d8d8fcb5b9ea7d5b9b626f96466baed&X-Goog-SignedHeaders=host&X-User=2931823730 (Caused by NewConnectionError('<urllib3.connection.HTTPSConnection object at 0x7f462ce1d720>: Failed to establish a new connection: [Errno 101] Network is unreachable'))

During handling of the above exception, another exception occurred:

Traceback (most recent call last):
  File "/root/anaconda3/envs/venv_ltu/lib/python3.10/site-packages/wandb/sdk/lib/retry.py", line 131, in __call__
    result = self._call_fn(*args, **kwargs)
  File "/root/anaconda3/envs/venv_ltu/lib/python3.10/site-packages/wandb/sdk/internal/internal_api.py", line 2580, in upload_file
    raise _e.with_traceback(sys.exc_info()[2])
  File "/root/anaconda3/envs/venv_ltu/lib/python3.10/site-packages/wandb/sdk/internal/internal_api.py", line 2549, in upload_file
    response = self._upload_file_session.put(
  File "/root/anaconda3/envs/venv_ltu/lib/python3.10/site-packages/requests/sessions.py", line 649, in put
    return self.request("PUT", url, data=data, **kwargs)
  File "/root/anaconda3/envs/venv_ltu/lib/python3.10/site-packages/requests/sessions.py", line 589, in request
    resp = self.send(prep, **send_kwargs)
  File "/root/anaconda3/envs/venv_ltu/lib/python3.10/site-packages/requests/sessions.py", line 703, in send
    r = adapter.send(request, **kwargs)
  File "/root/anaconda3/envs/venv_ltu/lib/python3.10/site-packages/requests/adapters.py", line 700, in send
    raise ConnectionError(e, request=request)
wandb.sdk.lib.retry.TransientError: None
2025-04-11 14:51:16,426 ERROR   wandb-upload_3:17843 [internal_api.py:upload_file():2556] upload_file exception https://storage.googleapis.com/wandb-production.appspot.com/2931823730-harbin-institute-of-technology/ltu-as/mlm5cp60/conda-environment.yaml?X-Goog-Algorithm=GOOG4-RSA-SHA256&X-Goog-Credential=gorilla-files-url-signer-man%40wandb-production.iam.gserviceaccount.com%2F20250411%2Fauto%2Fstorage%2Fgoog4_request&X-Goog-Date=20250411T145115Z&X-Goog-Expires=86399&X-Goog-Signature=18c9185561c0e38a4095f6492f7ba3109bb74b7ca241ce5eba7e7367298010776513c088c54a371846d5c60ffa97e1926acad93ddaeb7f1e863a32adfdbd3ffc7bd69000bb824d131ffd311a667fb373a02ed98fdde3d3caad24788ea1354f96c4dc5978d4dd03d993fdc19d79c0bbe55b08cbcf76dd3880dac13b40fb199889896f2944e570131678d4e0919686f72ab8a582d56638e963c3f9f8381660cc5a8e5124ccfb7760a0091bef421e6d0f0d3730b307cd29f88f8c5494dac201cc0a86ef0c41611677a875a6db0e8bddf08d412fb945a3c2ad3f19455ce2420ce93516e3e900072ff66ab558af6cd2677815e466cfd6ffe2abe2071b697185a279bd&X-Goog-SignedHeaders=host&X-User=2931823730: HTTPSConnectionPool(host='storage.googleapis.com', port=443): Max retries exceeded with url: /wandb-production.appspot.com/2931823730-harbin-institute-of-technology/ltu-as/mlm5cp60/conda-environment.yaml?X-Goog-Algorithm=GOOG4-RSA-SHA256&X-Goog-Credential=gorilla-files-url-signer-man%40wandb-production.iam.gserviceaccount.com%2F20250411%2Fauto%2Fstorage%2Fgoog4_request&X-Goog-Date=20250411T145115Z&X-Goog-Expires=86399&X-Goog-Signature=18c9185561c0e38a4095f6492f7ba3109bb74b7ca241ce5eba7e7367298010776513c088c54a371846d5c60ffa97e1926acad93ddaeb7f1e863a32adfdbd3ffc7bd69000bb824d131ffd311a667fb373a02ed98fdde3d3caad24788ea1354f96c4dc5978d4dd03d993fdc19d79c0bbe55b08cbcf76dd3880dac13b40fb199889896f2944e570131678d4e0919686f72ab8a582d56638e963c3f9f8381660cc5a8e5124ccfb7760a0091bef421e6d0f0d3730b307cd29f88f8c5494dac201cc0a86ef0c41611677a875a6db0e8bddf08d412fb945a3c2ad3f19455ce2420ce93516e3e900072ff66ab558af6cd2677815e466cfd6ffe2abe2071b697185a279bd&X-Goog-SignedHeaders=host&X-User=2931823730 (Caused by NewConnectionError('<urllib3.connection.HTTPSConnection object at 0x7f462ce1cf10>: Failed to establish a new connection: [Errno 101] Network is unreachable'))
2025-04-11 14:51:16,426 ERROR   wandb-upload_3:17843 [internal_api.py:upload_file():2558] upload_file request headers: {'User-Agent': 'python-requests/2.32.3', 'Accept-Encoding': 'gzip, deflate, br', 'Accept': '*/*', 'Connection': 'keep-alive', 'Content-Length': '8281'}
2025-04-11 14:51:16,426 ERROR   wandb-upload_3:17843 [internal_api.py:upload_file():2560] upload_file response body: 
2025-04-11 14:51:16,513 ERROR   wandb-upload_5:17843 [internal_api.py:upload_file():2556] upload_file exception https://storage.googleapis.com/wandb-production.appspot.com/2931823730-harbin-institute-of-technology/ltu-as/mlm5cp60/wandb-summary.json?X-Goog-Algorithm=GOOG4-RSA-SHA256&X-Goog-Credential=gorilla-files-url-signer-man%40wandb-production.iam.gserviceaccount.com%2F20250411%2Fauto%2Fstorage%2Fgoog4_request&X-Goog-Date=20250411T145115Z&X-Goog-Expires=86399&X-Goog-Signature=9df2087e11492ad178d77d9e9fab97630232b0a4f96a431148e4daf3a3ffb76f141a6acc698d2740403fe5d6787ed13f31ea70b94181a053e6e9bfe3b29b740f760a5a90f424f03e99c5b223fc30b089129e72948a62f1760c560b7f1eb6038148a7932d92a6c49a8613d4c7c04501f90b05b4395abd8bec4475d17d5fb0c4f0abdc39833cf913bd4da65c1c091140821a3269fc0d9ca812c0aaaceb66744bedabc6e1cc1b30e8946fc2d71819ae2467e1b4a3a0776572ba1fab93fa95fd681e3209826ea4ec41e0cdd752b417e53356fffd31afc35e8b7c23e46b68c60bd862806ba43d57d1fb048b5ba045a2b204376bd24fe7b11077307f2a2ccff7f3704e&X-Goog-SignedHeaders=host&X-User=2931823730: HTTPSConnectionPool(host='storage.googleapis.com', port=443): Max retries exceeded with url: /wandb-production.appspot.com/2931823730-harbin-institute-of-technology/ltu-as/mlm5cp60/wandb-summary.json?X-Goog-Algorithm=GOOG4-RSA-SHA256&X-Goog-Credential=gorilla-files-url-signer-man%40wandb-production.iam.gserviceaccount.com%2F20250411%2Fauto%2Fstorage%2Fgoog4_request&X-Goog-Date=20250411T145115Z&X-Goog-Expires=86399&X-Goog-Signature=9df2087e11492ad178d77d9e9fab97630232b0a4f96a431148e4daf3a3ffb76f141a6acc698d2740403fe5d6787ed13f31ea70b94181a053e6e9bfe3b29b740f760a5a90f424f03e99c5b223fc30b089129e72948a62f1760c560b7f1eb6038148a7932d92a6c49a8613d4c7c04501f90b05b4395abd8bec4475d17d5fb0c4f0abdc39833cf913bd4da65c1c091140821a3269fc0d9ca812c0aaaceb66744bedabc6e1cc1b30e8946fc2d71819ae2467e1b4a3a0776572ba1fab93fa95fd681e3209826ea4ec41e0cdd752b417e53356fffd31afc35e8b7c23e46b68c60bd862806ba43d57d1fb048b5ba045a2b204376bd24fe7b11077307f2a2ccff7f3704e&X-Goog-SignedHeaders=host&X-User=2931823730 (Caused by NewConnectionError('<urllib3.connection.HTTPSConnection object at 0x7f462ce1d7b0>: Failed to establish a new connection: [Errno 101] Network is unreachable'))
2025-04-11 14:51:16,513 ERROR   wandb-upload_5:17843 [internal_api.py:upload_file():2558] upload_file request headers: {'User-Agent': 'python-requests/2.32.3', 'Accept-Encoding': 'gzip, deflate, br', 'Accept': '*/*', 'Connection': 'keep-alive', 'Content-Length': '27'}
2025-04-11 14:51:16,513 ERROR   wandb-upload_5:17843 [internal_api.py:upload_file():2560] upload_file response body: 
2025-04-11 14:51:16,559 ERROR   wandb-upload_4:17843 [internal_api.py:upload_file():2556] upload_file exception https://storage.googleapis.com/wandb-production.appspot.com/2931823730-harbin-institute-of-technology/ltu-as/mlm5cp60/output.log?X-Goog-Algorithm=GOOG4-RSA-SHA256&X-Goog-Credential=gorilla-files-url-signer-man%40wandb-production.iam.gserviceaccount.com%2F20250411%2Fauto%2Fstorage%2Fgoog4_request&X-Goog-Date=20250411T145115Z&X-Goog-Expires=86399&X-Goog-Signature=66829b877c42ca303b639780fff7bf88cbb60209259c7dc6d23083a84ea8a96b64d71ff0c30cfcd6586ba916252610aa15480efdf90421949aa85f951f9b619e468eda017b8e55a28c0dd8aa6f99210f3f778f8a86e71dc469c624bf57498806db03fe0da4046f07d2c7f46ebf78d08027dddd14f7a09c4e83545aa9466da1eb6bbcaa07656e8c5098eb49767523418a66675017d803a591dae803119383f64fd0a7046d0036e02ac698d4dae626392e5291c9836cbd2eaea947ec9227980072d7bf72433004230cc067028ae4702b9478433d2bac33dd2edcdea1ff05ace0e6798c3b76707a6db65d093dae199f68cfbd61847341fb284cad3d6d9cc1489b0e&X-Goog-SignedHeaders=host&X-User=2931823730: HTTPSConnectionPool(host='storage.googleapis.com', port=443): Max retries exceeded with url: /wandb-production.appspot.com/2931823730-harbin-institute-of-technology/ltu-as/mlm5cp60/output.log?X-Goog-Algorithm=GOOG4-RSA-SHA256&X-Goog-Credential=gorilla-files-url-signer-man%40wandb-production.iam.gserviceaccount.com%2F20250411%2Fauto%2Fstorage%2Fgoog4_request&X-Goog-Date=20250411T145115Z&X-Goog-Expires=86399&X-Goog-Signature=66829b877c42ca303b639780fff7bf88cbb60209259c7dc6d23083a84ea8a96b64d71ff0c30cfcd6586ba916252610aa15480efdf90421949aa85f951f9b619e468eda017b8e55a28c0dd8aa6f99210f3f778f8a86e71dc469c624bf57498806db03fe0da4046f07d2c7f46ebf78d08027dddd14f7a09c4e83545aa9466da1eb6bbcaa07656e8c5098eb49767523418a66675017d803a591dae803119383f64fd0a7046d0036e02ac698d4dae626392e5291c9836cbd2eaea947ec9227980072d7bf72433004230cc067028ae4702b9478433d2bac33dd2edcdea1ff05ace0e6798c3b76707a6db65d093dae199f68cfbd61847341fb284cad3d6d9cc1489b0e&X-Goog-SignedHeaders=host&X-User=2931823730 (Caused by NewConnectionError('<urllib3.connection.HTTPSConnection object at 0x7f462ce1ee90>: Failed to establish a new connection: [Errno 101] Network is unreachable'))
2025-04-11 14:51:16,559 ERROR   wandb-upload_4:17843 [internal_api.py:upload_file():2558] upload_file request headers: {'User-Agent': 'python-requests/2.32.3', 'Accept-Encoding': 'gzip, deflate, br', 'Accept': '*/*', 'Connection': 'keep-alive', 'Content-Length': '4566'}
2025-04-11 14:51:16,559 ERROR   wandb-upload_4:17843 [internal_api.py:upload_file():2560] upload_file response body: 
2025-04-11 14:51:18,291 DEBUG   HandlerThread:17843 [handler.py:handle_request():146] handle_request: keepalive
2025-04-11 14:51:18,491 ERROR   wandb-upload_1:17843 [internal_api.py:upload_file():2556] upload_file exception https://storage.googleapis.com/wandb-production.appspot.com/2931823730-harbin-institute-of-technology/ltu-as/mlm5cp60/config.yaml?X-Goog-Algorithm=GOOG4-RSA-SHA256&X-Goog-Credential=gorilla-files-url-signer-man%40wandb-production.iam.gserviceaccount.com%2F20250411%2Fauto%2Fstorage%2Fgoog4_request&X-Goog-Date=20250411T145114Z&X-Goog-Expires=86399&X-Goog-Signature=944235794937f5025098c1ad39eaa00481a836c99c5822829b310120eb7d5a4666982e0e334a9357d37d9b7e4cb8fd4f3724f2d49c298240333fb06ed6be1b75da245bf972b74d0764218fb8da8150e6196b47290b328b850073b184f52a618c71c6fc15b6faa23f42ea4f43733bcf9b72a4ffce6124a6fabb01094b60566df348dc4ffb6145b7e1b56d8870304b0db1439adbc5d7d36e9dbedcb04ed306c15ea7e5660dd3c1a459a318151493ddac525b223c64c1c3acd07b1074ffb2bae2a2c5748e1ccfa4dba073a06ddff15af3a314e16ae4a851154ac4a30a6b911fdd8835407050fbc7b5592ead92e01e0d5bee0d8d8fcb5b9ea7d5b9b626f96466baed&X-Goog-SignedHeaders=host&X-User=2931823730: HTTPSConnectionPool(host='storage.googleapis.com', port=443): Max retries exceeded with url: /wandb-production.appspot.com/2931823730-harbin-institute-of-technology/ltu-as/mlm5cp60/config.yaml?X-Goog-Algorithm=GOOG4-RSA-SHA256&X-Goog-Credential=gorilla-files-url-signer-man%40wandb-production.iam.gserviceaccount.com%2F20250411%2Fauto%2Fstorage%2Fgoog4_request&X-Goog-Date=20250411T145114Z&X-Goog-Expires=86399&X-Goog-Signature=944235794937f5025098c1ad39eaa00481a836c99c5822829b310120eb7d5a4666982e0e334a9357d37d9b7e4cb8fd4f3724f2d49c298240333fb06ed6be1b75da245bf972b74d0764218fb8da8150e6196b47290b328b850073b184f52a618c71c6fc15b6faa23f42ea4f43733bcf9b72a4ffce6124a6fabb01094b60566df348dc4ffb6145b7e1b56d8870304b0db1439adbc5d7d36e9dbedcb04ed306c15ea7e5660dd3c1a459a318151493ddac525b223c64c1c3acd07b1074ffb2bae2a2c5748e1ccfa4dba073a06ddff15af3a314e16ae4a851154ac4a30a6b911fdd8835407050fbc7b5592ead92e01e0d5bee0d8d8fcb5b9ea7d5b9b626f96466baed&X-Goog-SignedHeaders=host&X-User=2931823730 (Caused by NewConnectionError('<urllib3.connection.HTTPSConnection object at 0x7f462ce1f490>: Failed to establish a new connection: [Errno 101] Network is unreachable'))
2025-04-11 14:51:18,491 ERROR   wandb-upload_1:17843 [internal_api.py:upload_file():2558] upload_file request headers: {'User-Agent': 'python-requests/2.32.3', 'Accept-Encoding': 'gzip, deflate, br', 'Accept': '*/*', 'Connection': 'keep-alive', 'Content-Length': '8685'}
2025-04-11 14:51:18,492 ERROR   wandb-upload_1:17843 [internal_api.py:upload_file():2560] upload_file response body: 
2025-04-11 14:51:18,570 ERROR   wandb-upload_2:17843 [internal_api.py:upload_file():2556] upload_file exception https://storage.googleapis.com/wandb-production.appspot.com/2931823730-harbin-institute-of-technology/ltu-as/mlm5cp60/requirements.txt?X-Goog-Algorithm=GOOG4-RSA-SHA256&X-Goog-Credential=gorilla-files-url-signer-man%40wandb-production.iam.gserviceaccount.com%2F20250411%2Fauto%2Fstorage%2Fgoog4_request&X-Goog-Date=20250411T145114Z&X-Goog-Expires=86399&X-Goog-Signature=acbd028386bc03d94948aaf65bc53bf77977ac5585e79ea0716ec007860ef39ea96f93094178bbe53396288150856563223a0e942bd376af8b161d4d58a6cf0e9dbea71fc7a9410c6f71628492009b7953de41033e7b38937eb708bfb6ada10c77ca0870f3d12be57f6d029ecfb8822e7dc5a62df88082610c8fc02b7aa861cee7e448378ac9d23208529f4a5e6344e6123aa73d657af02d72994735111ae518708f803b7f58dec8713f9eceb068ad7513a1b67628cc6fcf386e87c1a6dad3ca8abbf5fe3d3e33a074098ac226b071cc8aec87b300c8c753ac0940760332a70b2be12d9199bfeb835e45ee4c7766e2aaeab19a9da94cb9c52d45ad6563a0c27f&X-Goog-SignedHeaders=host&X-User=2931823730: HTTPSConnectionPool(host='storage.googleapis.com', port=443): Max retries exceeded with url: /wandb-production.appspot.com/2931823730-harbin-institute-of-technology/ltu-as/mlm5cp60/requirements.txt?X-Goog-Algorithm=GOOG4-RSA-SHA256&X-Goog-Credential=gorilla-files-url-signer-man%40wandb-production.iam.gserviceaccount.com%2F20250411%2Fauto%2Fstorage%2Fgoog4_request&X-Goog-Date=20250411T145114Z&X-Goog-Expires=86399&X-Goog-Signature=acbd028386bc03d94948aaf65bc53bf77977ac5585e79ea0716ec007860ef39ea96f93094178bbe53396288150856563223a0e942bd376af8b161d4d58a6cf0e9dbea71fc7a9410c6f71628492009b7953de41033e7b38937eb708bfb6ada10c77ca0870f3d12be57f6d029ecfb8822e7dc5a62df88082610c8fc02b7aa861cee7e448378ac9d23208529f4a5e6344e6123aa73d657af02d72994735111ae518708f803b7f58dec8713f9eceb068ad7513a1b67628cc6fcf386e87c1a6dad3ca8abbf5fe3d3e33a074098ac226b071cc8aec87b300c8c753ac0940760332a70b2be12d9199bfeb835e45ee4c7766e2aaeab19a9da94cb9c52d45ad6563a0c27f&X-Goog-SignedHeaders=host&X-User=2931823730 (Caused by NewConnectionError('<urllib3.connection.HTTPSConnection object at 0x7f462ce1cb20>: Failed to establish a new connection: [Errno 101] Network is unreachable'))
2025-04-11 14:51:18,570 ERROR   wandb-upload_2:17843 [internal_api.py:upload_file():2558] upload_file request headers: {'User-Agent': 'python-requests/2.32.3', 'Accept-Encoding': 'gzip, deflate, br', 'Accept': '*/*', 'Connection': 'keep-alive', 'Content-Length': '4212'}
2025-04-11 14:51:18,570 ERROR   wandb-upload_2:17843 [internal_api.py:upload_file():2560] upload_file response body: 
2025-04-11 14:51:18,616 ERROR   wandb-upload_3:17843 [internal_api.py:upload_file():2556] upload_file exception https://storage.googleapis.com/wandb-production.appspot.com/2931823730-harbin-institute-of-technology/ltu-as/mlm5cp60/conda-environment.yaml?X-Goog-Algorithm=GOOG4-RSA-SHA256&X-Goog-Credential=gorilla-files-url-signer-man%40wandb-production.iam.gserviceaccount.com%2F20250411%2Fauto%2Fstorage%2Fgoog4_request&X-Goog-Date=20250411T145115Z&X-Goog-Expires=86399&X-Goog-Signature=18c9185561c0e38a4095f6492f7ba3109bb74b7ca241ce5eba7e7367298010776513c088c54a371846d5c60ffa97e1926acad93ddaeb7f1e863a32adfdbd3ffc7bd69000bb824d131ffd311a667fb373a02ed98fdde3d3caad24788ea1354f96c4dc5978d4dd03d993fdc19d79c0bbe55b08cbcf76dd3880dac13b40fb199889896f2944e570131678d4e0919686f72ab8a582d56638e963c3f9f8381660cc5a8e5124ccfb7760a0091bef421e6d0f0d3730b307cd29f88f8c5494dac201cc0a86ef0c41611677a875a6db0e8bddf08d412fb945a3c2ad3f19455ce2420ce93516e3e900072ff66ab558af6cd2677815e466cfd6ffe2abe2071b697185a279bd&X-Goog-SignedHeaders=host&X-User=2931823730: HTTPSConnectionPool(host='storage.googleapis.com', port=443): Max retries exceeded with url: /wandb-production.appspot.com/2931823730-harbin-institute-of-technology/ltu-as/mlm5cp60/conda-environment.yaml?X-Goog-Algorithm=GOOG4-RSA-SHA256&X-Goog-Credential=gorilla-files-url-signer-man%40wandb-production.iam.gserviceaccount.com%2F20250411%2Fauto%2Fstorage%2Fgoog4_request&X-Goog-Date=20250411T145115Z&X-Goog-Expires=86399&X-Goog-Signature=18c9185561c0e38a4095f6492f7ba3109bb74b7ca241ce5eba7e7367298010776513c088c54a371846d5c60ffa97e1926acad93ddaeb7f1e863a32adfdbd3ffc7bd69000bb824d131ffd311a667fb373a02ed98fdde3d3caad24788ea1354f96c4dc5978d4dd03d993fdc19d79c0bbe55b08cbcf76dd3880dac13b40fb199889896f2944e570131678d4e0919686f72ab8a582d56638e963c3f9f8381660cc5a8e5124ccfb7760a0091bef421e6d0f0d3730b307cd29f88f8c5494dac201cc0a86ef0c41611677a875a6db0e8bddf08d412fb945a3c2ad3f19455ce2420ce93516e3e900072ff66ab558af6cd2677815e466cfd6ffe2abe2071b697185a279bd&X-Goog-SignedHeaders=host&X-User=2931823730 (Caused by NewConnectionError('<urllib3.connection.HTTPSConnection object at 0x7f464c197e50>: Failed to establish a new connection: [Errno 101] Network is unreachable'))
2025-04-11 14:51:18,616 ERROR   wandb-upload_3:17843 [internal_api.py:upload_file():2558] upload_file request headers: {'User-Agent': 'python-requests/2.32.3', 'Accept-Encoding': 'gzip, deflate, br', 'Accept': '*/*', 'Connection': 'keep-alive', 'Content-Length': '8281'}
2025-04-11 14:51:18,616 ERROR   wandb-upload_3:17843 [internal_api.py:upload_file():2560] upload_file response body: 
2025-04-11 14:51:18,646 ERROR   wandb-upload_5:17843 [internal_api.py:upload_file():2556] upload_file exception https://storage.googleapis.com/wandb-production.appspot.com/2931823730-harbin-institute-of-technology/ltu-as/mlm5cp60/wandb-summary.json?X-Goog-Algorithm=GOOG4-RSA-SHA256&X-Goog-Credential=gorilla-files-url-signer-man%40wandb-production.iam.gserviceaccount.com%2F20250411%2Fauto%2Fstorage%2Fgoog4_request&X-Goog-Date=20250411T145115Z&X-Goog-Expires=86399&X-Goog-Signature=9df2087e11492ad178d77d9e9fab97630232b0a4f96a431148e4daf3a3ffb76f141a6acc698d2740403fe5d6787ed13f31ea70b94181a053e6e9bfe3b29b740f760a5a90f424f03e99c5b223fc30b089129e72948a62f1760c560b7f1eb6038148a7932d92a6c49a8613d4c7c04501f90b05b4395abd8bec4475d17d5fb0c4f0abdc39833cf913bd4da65c1c091140821a3269fc0d9ca812c0aaaceb66744bedabc6e1cc1b30e8946fc2d71819ae2467e1b4a3a0776572ba1fab93fa95fd681e3209826ea4ec41e0cdd752b417e53356fffd31afc35e8b7c23e46b68c60bd862806ba43d57d1fb048b5ba045a2b204376bd24fe7b11077307f2a2ccff7f3704e&X-Goog-SignedHeaders=host&X-User=2931823730: HTTPSConnectionPool(host='storage.googleapis.com', port=443): Max retries exceeded with url: /wandb-production.appspot.com/2931823730-harbin-institute-of-technology/ltu-as/mlm5cp60/wandb-summary.json?X-Goog-Algorithm=GOOG4-RSA-SHA256&X-Goog-Credential=gorilla-files-url-signer-man%40wandb-production.iam.gserviceaccount.com%2F20250411%2Fauto%2Fstorage%2Fgoog4_request&X-Goog-Date=20250411T145115Z&X-Goog-Expires=86399&X-Goog-Signature=9df2087e11492ad178d77d9e9fab97630232b0a4f96a431148e4daf3a3ffb76f141a6acc698d2740403fe5d6787ed13f31ea70b94181a053e6e9bfe3b29b740f760a5a90f424f03e99c5b223fc30b089129e72948a62f1760c560b7f1eb6038148a7932d92a6c49a8613d4c7c04501f90b05b4395abd8bec4475d17d5fb0c4f0abdc39833cf913bd4da65c1c091140821a3269fc0d9ca812c0aaaceb66744bedabc6e1cc1b30e8946fc2d71819ae2467e1b4a3a0776572ba1fab93fa95fd681e3209826ea4ec41e0cdd752b417e53356fffd31afc35e8b7c23e46b68c60bd862806ba43d57d1fb048b5ba045a2b204376bd24fe7b11077307f2a2ccff7f3704e&X-Goog-SignedHeaders=host&X-User=2931823730 (Caused by NewConnectionError('<urllib3.connection.HTTPSConnection object at 0x7f464c197340>: Failed to establish a new connection: [Errno 101] Network is unreachable'))
2025-04-11 14:51:18,646 ERROR   wandb-upload_5:17843 [internal_api.py:upload_file():2558] upload_file request headers: {'User-Agent': 'python-requests/2.32.3', 'Accept-Encoding': 'gzip, deflate, br', 'Accept': '*/*', 'Connection': 'keep-alive', 'Content-Length': '27'}
2025-04-11 14:51:18,646 ERROR   wandb-upload_5:17843 [internal_api.py:upload_file():2560] upload_file response body: 
2025-04-11 14:51:18,980 ERROR   wandb-upload_4:17843 [internal_api.py:upload_file():2556] upload_file exception https://storage.googleapis.com/wandb-production.appspot.com/2931823730-harbin-institute-of-technology/ltu-as/mlm5cp60/output.log?X-Goog-Algorithm=GOOG4-RSA-SHA256&X-Goog-Credential=gorilla-files-url-signer-man%40wandb-production.iam.gserviceaccount.com%2F20250411%2Fauto%2Fstorage%2Fgoog4_request&X-Goog-Date=20250411T145115Z&X-Goog-Expires=86399&X-Goog-Signature=66829b877c42ca303b639780fff7bf88cbb60209259c7dc6d23083a84ea8a96b64d71ff0c30cfcd6586ba916252610aa15480efdf90421949aa85f951f9b619e468eda017b8e55a28c0dd8aa6f99210f3f778f8a86e71dc469c624bf57498806db03fe0da4046f07d2c7f46ebf78d08027dddd14f7a09c4e83545aa9466da1eb6bbcaa07656e8c5098eb49767523418a66675017d803a591dae803119383f64fd0a7046d0036e02ac698d4dae626392e5291c9836cbd2eaea947ec9227980072d7bf72433004230cc067028ae4702b9478433d2bac33dd2edcdea1ff05ace0e6798c3b76707a6db65d093dae199f68cfbd61847341fb284cad3d6d9cc1489b0e&X-Goog-SignedHeaders=host&X-User=2931823730: HTTPSConnectionPool(host='storage.googleapis.com', port=443): Max retries exceeded with url: /wandb-production.appspot.com/2931823730-harbin-institute-of-technology/ltu-as/mlm5cp60/output.log?X-Goog-Algorithm=GOOG4-RSA-SHA256&X-Goog-Credential=gorilla-files-url-signer-man%40wandb-production.iam.gserviceaccount.com%2F20250411%2Fauto%2Fstorage%2Fgoog4_request&X-Goog-Date=20250411T145115Z&X-Goog-Expires=86399&X-Goog-Signature=66829b877c42ca303b639780fff7bf88cbb60209259c7dc6d23083a84ea8a96b64d71ff0c30cfcd6586ba916252610aa15480efdf90421949aa85f951f9b619e468eda017b8e55a28c0dd8aa6f99210f3f778f8a86e71dc469c624bf57498806db03fe0da4046f07d2c7f46ebf78d08027dddd14f7a09c4e83545aa9466da1eb6bbcaa07656e8c5098eb49767523418a66675017d803a591dae803119383f64fd0a7046d0036e02ac698d4dae626392e5291c9836cbd2eaea947ec9227980072d7bf72433004230cc067028ae4702b9478433d2bac33dd2edcdea1ff05ace0e6798c3b76707a6db65d093dae199f68cfbd61847341fb284cad3d6d9cc1489b0e&X-Goog-SignedHeaders=host&X-User=2931823730 (Caused by NewConnectionError('<urllib3.connection.HTTPSConnection object at 0x7f464c197580>: Failed to establish a new connection: [Errno 101] Network is unreachable'))
2025-04-11 14:51:18,980 ERROR   wandb-upload_4:17843 [internal_api.py:upload_file():2558] upload_file request headers: {'User-Agent': 'python-requests/2.32.3', 'Accept-Encoding': 'gzip, deflate, br', 'Accept': '*/*', 'Connection': 'keep-alive', 'Content-Length': '4566'}
2025-04-11 14:51:18,980 ERROR   wandb-upload_4:17843 [internal_api.py:upload_file():2560] upload_file response body: 
2025-04-11 14:51:19,864 DEBUG   HandlerThread:17843 [handler.py:handle_request():146] handle_request: status_report
2025-04-11 14:51:22,842 ERROR   wandb-upload_2:17843 [internal_api.py:upload_file():2556] upload_file exception https://storage.googleapis.com/wandb-production.appspot.com/2931823730-harbin-institute-of-technology/ltu-as/mlm5cp60/requirements.txt?X-Goog-Algorithm=GOOG4-RSA-SHA256&X-Goog-Credential=gorilla-files-url-signer-man%40wandb-production.iam.gserviceaccount.com%2F20250411%2Fauto%2Fstorage%2Fgoog4_request&X-Goog-Date=20250411T145114Z&X-Goog-Expires=86399&X-Goog-Signature=acbd028386bc03d94948aaf65bc53bf77977ac5585e79ea0716ec007860ef39ea96f93094178bbe53396288150856563223a0e942bd376af8b161d4d58a6cf0e9dbea71fc7a9410c6f71628492009b7953de41033e7b38937eb708bfb6ada10c77ca0870f3d12be57f6d029ecfb8822e7dc5a62df88082610c8fc02b7aa861cee7e448378ac9d23208529f4a5e6344e6123aa73d657af02d72994735111ae518708f803b7f58dec8713f9eceb068ad7513a1b67628cc6fcf386e87c1a6dad3ca8abbf5fe3d3e33a074098ac226b071cc8aec87b300c8c753ac0940760332a70b2be12d9199bfeb835e45ee4c7766e2aaeab19a9da94cb9c52d45ad6563a0c27f&X-Goog-SignedHeaders=host&X-User=2931823730: HTTPSConnectionPool(host='storage.googleapis.com', port=443): Max retries exceeded with url: /wandb-production.appspot.com/2931823730-harbin-institute-of-technology/ltu-as/mlm5cp60/requirements.txt?X-Goog-Algorithm=GOOG4-RSA-SHA256&X-Goog-Credential=gorilla-files-url-signer-man%40wandb-production.iam.gserviceaccount.com%2F20250411%2Fauto%2Fstorage%2Fgoog4_request&X-Goog-Date=20250411T145114Z&X-Goog-Expires=86399&X-Goog-Signature=acbd028386bc03d94948aaf65bc53bf77977ac5585e79ea0716ec007860ef39ea96f93094178bbe53396288150856563223a0e942bd376af8b161d4d58a6cf0e9dbea71fc7a9410c6f71628492009b7953de41033e7b38937eb708bfb6ada10c77ca0870f3d12be57f6d029ecfb8822e7dc5a62df88082610c8fc02b7aa861cee7e448378ac9d23208529f4a5e6344e6123aa73d657af02d72994735111ae518708f803b7f58dec8713f9eceb068ad7513a1b67628cc6fcf386e87c1a6dad3ca8abbf5fe3d3e33a074098ac226b071cc8aec87b300c8c753ac0940760332a70b2be12d9199bfeb835e45ee4c7766e2aaeab19a9da94cb9c52d45ad6563a0c27f&X-Goog-SignedHeaders=host&X-User=2931823730 (Caused by NewConnectionError('<urllib3.connection.HTTPSConnection object at 0x7f464c1967a0>: Failed to establish a new connection: [Errno 101] Network is unreachable'))
2025-04-11 14:51:22,843 ERROR   wandb-upload_2:17843 [internal_api.py:upload_file():2558] upload_file request headers: {'User-Agent': 'python-requests/2.32.3', 'Accept-Encoding': 'gzip, deflate, br', 'Accept': '*/*', 'Connection': 'keep-alive', 'Content-Length': '4212'}
2025-04-11 14:51:22,843 ERROR   wandb-upload_2:17843 [internal_api.py:upload_file():2560] upload_file response body: 
2025-04-11 14:51:23,087 ERROR   wandb-upload_1:17843 [internal_api.py:upload_file():2556] upload_file exception https://storage.googleapis.com/wandb-production.appspot.com/2931823730-harbin-institute-of-technology/ltu-as/mlm5cp60/config.yaml?X-Goog-Algorithm=GOOG4-RSA-SHA256&X-Goog-Credential=gorilla-files-url-signer-man%40wandb-production.iam.gserviceaccount.com%2F20250411%2Fauto%2Fstorage%2Fgoog4_request&X-Goog-Date=20250411T145114Z&X-Goog-Expires=86399&X-Goog-Signature=944235794937f5025098c1ad39eaa00481a836c99c5822829b310120eb7d5a4666982e0e334a9357d37d9b7e4cb8fd4f3724f2d49c298240333fb06ed6be1b75da245bf972b74d0764218fb8da8150e6196b47290b328b850073b184f52a618c71c6fc15b6faa23f42ea4f43733bcf9b72a4ffce6124a6fabb01094b60566df348dc4ffb6145b7e1b56d8870304b0db1439adbc5d7d36e9dbedcb04ed306c15ea7e5660dd3c1a459a318151493ddac525b223c64c1c3acd07b1074ffb2bae2a2c5748e1ccfa4dba073a06ddff15af3a314e16ae4a851154ac4a30a6b911fdd8835407050fbc7b5592ead92e01e0d5bee0d8d8fcb5b9ea7d5b9b626f96466baed&X-Goog-SignedHeaders=host&X-User=2931823730: HTTPSConnectionPool(host='storage.googleapis.com', port=443): Max retries exceeded with url: /wandb-production.appspot.com/2931823730-harbin-institute-of-technology/ltu-as/mlm5cp60/config.yaml?X-Goog-Algorithm=GOOG4-RSA-SHA256&X-Goog-Credential=gorilla-files-url-signer-man%40wandb-production.iam.gserviceaccount.com%2F20250411%2Fauto%2Fstorage%2Fgoog4_request&X-Goog-Date=20250411T145114Z&X-Goog-Expires=86399&X-Goog-Signature=944235794937f5025098c1ad39eaa00481a836c99c5822829b310120eb7d5a4666982e0e334a9357d37d9b7e4cb8fd4f3724f2d49c298240333fb06ed6be1b75da245bf972b74d0764218fb8da8150e6196b47290b328b850073b184f52a618c71c6fc15b6faa23f42ea4f43733bcf9b72a4ffce6124a6fabb01094b60566df348dc4ffb6145b7e1b56d8870304b0db1439adbc5d7d36e9dbedcb04ed306c15ea7e5660dd3c1a459a318151493ddac525b223c64c1c3acd07b1074ffb2bae2a2c5748e1ccfa4dba073a06ddff15af3a314e16ae4a851154ac4a30a6b911fdd8835407050fbc7b5592ead92e01e0d5bee0d8d8fcb5b9ea7d5b9b626f96466baed&X-Goog-SignedHeaders=host&X-User=2931823730 (Caused by NewConnectionError('<urllib3.connection.HTTPSConnection object at 0x7f464c195420>: Failed to establish a new connection: [Errno 101] Network is unreachable'))
2025-04-11 14:51:23,088 ERROR   wandb-upload_1:17843 [internal_api.py:upload_file():2558] upload_file request headers: {'User-Agent': 'python-requests/2.32.3', 'Accept-Encoding': 'gzip, deflate, br', 'Accept': '*/*', 'Connection': 'keep-alive', 'Content-Length': '8685'}
2025-04-11 14:51:23,088 ERROR   wandb-upload_1:17843 [internal_api.py:upload_file():2560] upload_file response body: 
2025-04-11 14:51:23,293 DEBUG   HandlerThread:17843 [handler.py:handle_request():146] handle_request: keepalive
2025-04-11 14:51:23,362 ERROR   wandb-upload_0:17843 [internal_api.py:upload_file():2556] upload_file exception https://storage.googleapis.com/wandb-production.appspot.com/2931823730-harbin-institute-of-technology/ltu-as/mlm5cp60/wandb-metadata.json?X-Goog-Algorithm=GOOG4-RSA-SHA256&X-Goog-Credential=gorilla-files-url-signer-man%40wandb-production.iam.gserviceaccount.com%2F20250411%2Fauto%2Fstorage%2Fgoog4_request&X-Goog-Date=20250411T145106Z&X-Goog-Expires=86399&X-Goog-Signature=5e61366a9cdba14e9366e693773cc7799673c98fe4965f87dc63e9596d3f0187754b4e166d7560ee536e464deebf60499d155fae33d314f1b808bc2ccf04fe2c2b6efba6d43259562807703d0c11efadf701d1f3e05abb6b0468adf02bd6951f959adbbc65e0e0d573f6077508150688e50412733d3f1fd1d82b1064ce9849427b169d276ec4abcb3c6ad012ae7b83463f0f43df52a7831651905f2c417198214e2d77562e52239192e58ea0c1a2ffac95120c36d81ee751e5ad5f0567ad413c9810baa3cdbf48f97d70e2753cf600570333d0c31fed9fdb63c272a974ee3c1de0d894e1ac50b3735ef19c262cef60219e3f1c55b31dfe63d31aed27b25d009c&X-Goog-SignedHeaders=host&X-User=2931823730: HTTPSConnectionPool(host='storage.googleapis.com', port=443): Max retries exceeded with url: /wandb-production.appspot.com/2931823730-harbin-institute-of-technology/ltu-as/mlm5cp60/wandb-metadata.json?X-Goog-Algorithm=GOOG4-RSA-SHA256&X-Goog-Credential=gorilla-files-url-signer-man%40wandb-production.iam.gserviceaccount.com%2F20250411%2Fauto%2Fstorage%2Fgoog4_request&X-Goog-Date=20250411T145106Z&X-Goog-Expires=86399&X-Goog-Signature=5e61366a9cdba14e9366e693773cc7799673c98fe4965f87dc63e9596d3f0187754b4e166d7560ee536e464deebf60499d155fae33d314f1b808bc2ccf04fe2c2b6efba6d43259562807703d0c11efadf701d1f3e05abb6b0468adf02bd6951f959adbbc65e0e0d573f6077508150688e50412733d3f1fd1d82b1064ce9849427b169d276ec4abcb3c6ad012ae7b83463f0f43df52a7831651905f2c417198214e2d77562e52239192e58ea0c1a2ffac95120c36d81ee751e5ad5f0567ad413c9810baa3cdbf48f97d70e2753cf600570333d0c31fed9fdb63c272a974ee3c1de0d894e1ac50b3735ef19c262cef60219e3f1c55b31dfe63d31aed27b25d009c&X-Goog-SignedHeaders=host&X-User=2931823730 (Caused by NewConnectionError('<urllib3.connection.HTTPSConnection object at 0x7f462ce1f3d0>: Failed to establish a new connection: [Errno 101] Network is unreachable'))
2025-04-11 14:51:23,362 ERROR   wandb-upload_0:17843 [internal_api.py:upload_file():2558] upload_file request headers: {'User-Agent': 'python-requests/2.32.3', 'Accept-Encoding': 'gzip, deflate, br', 'Accept': '*/*', 'Connection': 'keep-alive', 'Content-Length': '2274'}
2025-04-11 14:51:23,362 ERROR   wandb-upload_0:17843 [internal_api.py:upload_file():2560] upload_file response body: 
2025-04-11 14:51:23,399 ERROR   wandb-upload_3:17843 [internal_api.py:upload_file():2556] upload_file exception https://storage.googleapis.com/wandb-production.appspot.com/2931823730-harbin-institute-of-technology/ltu-as/mlm5cp60/conda-environment.yaml?X-Goog-Algorithm=GOOG4-RSA-SHA256&X-Goog-Credential=gorilla-files-url-signer-man%40wandb-production.iam.gserviceaccount.com%2F20250411%2Fauto%2Fstorage%2Fgoog4_request&X-Goog-Date=20250411T145115Z&X-Goog-Expires=86399&X-Goog-Signature=18c9185561c0e38a4095f6492f7ba3109bb74b7ca241ce5eba7e7367298010776513c088c54a371846d5c60ffa97e1926acad93ddaeb7f1e863a32adfdbd3ffc7bd69000bb824d131ffd311a667fb373a02ed98fdde3d3caad24788ea1354f96c4dc5978d4dd03d993fdc19d79c0bbe55b08cbcf76dd3880dac13b40fb199889896f2944e570131678d4e0919686f72ab8a582d56638e963c3f9f8381660cc5a8e5124ccfb7760a0091bef421e6d0f0d3730b307cd29f88f8c5494dac201cc0a86ef0c41611677a875a6db0e8bddf08d412fb945a3c2ad3f19455ce2420ce93516e3e900072ff66ab558af6cd2677815e466cfd6ffe2abe2071b697185a279bd&X-Goog-SignedHeaders=host&X-User=2931823730: HTTPSConnectionPool(host='storage.googleapis.com', port=443): Max retries exceeded with url: /wandb-production.appspot.com/2931823730-harbin-institute-of-technology/ltu-as/mlm5cp60/conda-environment.yaml?X-Goog-Algorithm=GOOG4-RSA-SHA256&X-Goog-Credential=gorilla-files-url-signer-man%40wandb-production.iam.gserviceaccount.com%2F20250411%2Fauto%2Fstorage%2Fgoog4_request&X-Goog-Date=20250411T145115Z&X-Goog-Expires=86399&X-Goog-Signature=18c9185561c0e38a4095f6492f7ba3109bb74b7ca241ce5eba7e7367298010776513c088c54a371846d5c60ffa97e1926acad93ddaeb7f1e863a32adfdbd3ffc7bd69000bb824d131ffd311a667fb373a02ed98fdde3d3caad24788ea1354f96c4dc5978d4dd03d993fdc19d79c0bbe55b08cbcf76dd3880dac13b40fb199889896f2944e570131678d4e0919686f72ab8a582d56638e963c3f9f8381660cc5a8e5124ccfb7760a0091bef421e6d0f0d3730b307cd29f88f8c5494dac201cc0a86ef0c41611677a875a6db0e8bddf08d412fb945a3c2ad3f19455ce2420ce93516e3e900072ff66ab558af6cd2677815e466cfd6ffe2abe2071b697185a279bd&X-Goog-SignedHeaders=host&X-User=2931823730 (Caused by NewConnectionError('<urllib3.connection.HTTPSConnection object at 0x7f462ce1efe0>: Failed to establish a new connection: [Errno 101] Network is unreachable'))
2025-04-11 14:51:23,399 ERROR   wandb-upload_3:17843 [internal_api.py:upload_file():2558] upload_file request headers: {'User-Agent': 'python-requests/2.32.3', 'Accept-Encoding': 'gzip, deflate, br', 'Accept': '*/*', 'Connection': 'keep-alive', 'Content-Length': '8281'}
2025-04-11 14:51:23,400 ERROR   wandb-upload_3:17843 [internal_api.py:upload_file():2560] upload_file response body: 
2025-04-11 14:51:23,473 ERROR   wandb-upload_5:17843 [internal_api.py:upload_file():2556] upload_file exception https://storage.googleapis.com/wandb-production.appspot.com/2931823730-harbin-institute-of-technology/ltu-as/mlm5cp60/wandb-summary.json?X-Goog-Algorithm=GOOG4-RSA-SHA256&X-Goog-Credential=gorilla-files-url-signer-man%40wandb-production.iam.gserviceaccount.com%2F20250411%2Fauto%2Fstorage%2Fgoog4_request&X-Goog-Date=20250411T145115Z&X-Goog-Expires=86399&X-Goog-Signature=9df2087e11492ad178d77d9e9fab97630232b0a4f96a431148e4daf3a3ffb76f141a6acc698d2740403fe5d6787ed13f31ea70b94181a053e6e9bfe3b29b740f760a5a90f424f03e99c5b223fc30b089129e72948a62f1760c560b7f1eb6038148a7932d92a6c49a8613d4c7c04501f90b05b4395abd8bec4475d17d5fb0c4f0abdc39833cf913bd4da65c1c091140821a3269fc0d9ca812c0aaaceb66744bedabc6e1cc1b30e8946fc2d71819ae2467e1b4a3a0776572ba1fab93fa95fd681e3209826ea4ec41e0cdd752b417e53356fffd31afc35e8b7c23e46b68c60bd862806ba43d57d1fb048b5ba045a2b204376bd24fe7b11077307f2a2ccff7f3704e&X-Goog-SignedHeaders=host&X-User=2931823730: HTTPSConnectionPool(host='storage.googleapis.com', port=443): Max retries exceeded with url: /wandb-production.appspot.com/2931823730-harbin-institute-of-technology/ltu-as/mlm5cp60/wandb-summary.json?X-Goog-Algorithm=GOOG4-RSA-SHA256&X-Goog-Credential=gorilla-files-url-signer-man%40wandb-production.iam.gserviceaccount.com%2F20250411%2Fauto%2Fstorage%2Fgoog4_request&X-Goog-Date=20250411T145115Z&X-Goog-Expires=86399&X-Goog-Signature=9df2087e11492ad178d77d9e9fab97630232b0a4f96a431148e4daf3a3ffb76f141a6acc698d2740403fe5d6787ed13f31ea70b94181a053e6e9bfe3b29b740f760a5a90f424f03e99c5b223fc30b089129e72948a62f1760c560b7f1eb6038148a7932d92a6c49a8613d4c7c04501f90b05b4395abd8bec4475d17d5fb0c4f0abdc39833cf913bd4da65c1c091140821a3269fc0d9ca812c0aaaceb66744bedabc6e1cc1b30e8946fc2d71819ae2467e1b4a3a0776572ba1fab93fa95fd681e3209826ea4ec41e0cdd752b417e53356fffd31afc35e8b7c23e46b68c60bd862806ba43d57d1fb048b5ba045a2b204376bd24fe7b11077307f2a2ccff7f3704e&X-Goog-SignedHeaders=host&X-User=2931823730 (Caused by NewConnectionError('<urllib3.connection.HTTPSConnection object at 0x7f462ce1d3c0>: Failed to establish a new connection: [Errno 101] Network is unreachable'))
2025-04-11 14:51:23,473 ERROR   wandb-upload_5:17843 [internal_api.py:upload_file():2558] upload_file request headers: {'User-Agent': 'python-requests/2.32.3', 'Accept-Encoding': 'gzip, deflate, br', 'Accept': '*/*', 'Connection': 'keep-alive', 'Content-Length': '27'}
2025-04-11 14:51:23,474 ERROR   wandb-upload_5:17843 [internal_api.py:upload_file():2560] upload_file response body: 
2025-04-11 14:51:23,954 ERROR   wandb-upload_4:17843 [internal_api.py:upload_file():2556] upload_file exception https://storage.googleapis.com/wandb-production.appspot.com/2931823730-harbin-institute-of-technology/ltu-as/mlm5cp60/output.log?X-Goog-Algorithm=GOOG4-RSA-SHA256&X-Goog-Credential=gorilla-files-url-signer-man%40wandb-production.iam.gserviceaccount.com%2F20250411%2Fauto%2Fstorage%2Fgoog4_request&X-Goog-Date=20250411T145115Z&X-Goog-Expires=86399&X-Goog-Signature=66829b877c42ca303b639780fff7bf88cbb60209259c7dc6d23083a84ea8a96b64d71ff0c30cfcd6586ba916252610aa15480efdf90421949aa85f951f9b619e468eda017b8e55a28c0dd8aa6f99210f3f778f8a86e71dc469c624bf57498806db03fe0da4046f07d2c7f46ebf78d08027dddd14f7a09c4e83545aa9466da1eb6bbcaa07656e8c5098eb49767523418a66675017d803a591dae803119383f64fd0a7046d0036e02ac698d4dae626392e5291c9836cbd2eaea947ec9227980072d7bf72433004230cc067028ae4702b9478433d2bac33dd2edcdea1ff05ace0e6798c3b76707a6db65d093dae199f68cfbd61847341fb284cad3d6d9cc1489b0e&X-Goog-SignedHeaders=host&X-User=2931823730: HTTPSConnectionPool(host='storage.googleapis.com', port=443): Max retries exceeded with url: /wandb-production.appspot.com/2931823730-harbin-institute-of-technology/ltu-as/mlm5cp60/output.log?X-Goog-Algorithm=GOOG4-RSA-SHA256&X-Goog-Credential=gorilla-files-url-signer-man%40wandb-production.iam.gserviceaccount.com%2F20250411%2Fauto%2Fstorage%2Fgoog4_request&X-Goog-Date=20250411T145115Z&X-Goog-Expires=86399&X-Goog-Signature=66829b877c42ca303b639780fff7bf88cbb60209259c7dc6d23083a84ea8a96b64d71ff0c30cfcd6586ba916252610aa15480efdf90421949aa85f951f9b619e468eda017b8e55a28c0dd8aa6f99210f3f778f8a86e71dc469c624bf57498806db03fe0da4046f07d2c7f46ebf78d08027dddd14f7a09c4e83545aa9466da1eb6bbcaa07656e8c5098eb49767523418a66675017d803a591dae803119383f64fd0a7046d0036e02ac698d4dae626392e5291c9836cbd2eaea947ec9227980072d7bf72433004230cc067028ae4702b9478433d2bac33dd2edcdea1ff05ace0e6798c3b76707a6db65d093dae199f68cfbd61847341fb284cad3d6d9cc1489b0e&X-Goog-SignedHeaders=host&X-User=2931823730 (Caused by NewConnectionError('<urllib3.connection.HTTPSConnection object at 0x7f462ce1d4e0>: Failed to establish a new connection: [Errno 101] Network is unreachable'))
2025-04-11 14:51:23,954 ERROR   wandb-upload_4:17843 [internal_api.py:upload_file():2558] upload_file request headers: {'User-Agent': 'python-requests/2.32.3', 'Accept-Encoding': 'gzip, deflate, br', 'Accept': '*/*', 'Connection': 'keep-alive', 'Content-Length': '4566'}
2025-04-11 14:51:23,954 ERROR   wandb-upload_4:17843 [internal_api.py:upload_file():2560] upload_file response body: 
2025-04-11 14:51:24,865 DEBUG   HandlerThread:17843 [handler.py:handle_request():146] handle_request: status_report
2025-04-11 14:51:28,295 DEBUG   HandlerThread:17843 [handler.py:handle_request():146] handle_request: keepalive
2025-04-11 14:51:29,866 DEBUG   HandlerThread:17843 [handler.py:handle_request():146] handle_request: status_report
2025-04-11 14:51:31,183 ERROR   wandb-upload_1:17843 [internal_api.py:upload_file():2556] upload_file exception https://storage.googleapis.com/wandb-production.appspot.com/2931823730-harbin-institute-of-technology/ltu-as/mlm5cp60/config.yaml?X-Goog-Algorithm=GOOG4-RSA-SHA256&X-Goog-Credential=gorilla-files-url-signer-man%40wandb-production.iam.gserviceaccount.com%2F20250411%2Fauto%2Fstorage%2Fgoog4_request&X-Goog-Date=20250411T145114Z&X-Goog-Expires=86399&X-Goog-Signature=944235794937f5025098c1ad39eaa00481a836c99c5822829b310120eb7d5a4666982e0e334a9357d37d9b7e4cb8fd4f3724f2d49c298240333fb06ed6be1b75da245bf972b74d0764218fb8da8150e6196b47290b328b850073b184f52a618c71c6fc15b6faa23f42ea4f43733bcf9b72a4ffce6124a6fabb01094b60566df348dc4ffb6145b7e1b56d8870304b0db1439adbc5d7d36e9dbedcb04ed306c15ea7e5660dd3c1a459a318151493ddac525b223c64c1c3acd07b1074ffb2bae2a2c5748e1ccfa4dba073a06ddff15af3a314e16ae4a851154ac4a30a6b911fdd8835407050fbc7b5592ead92e01e0d5bee0d8d8fcb5b9ea7d5b9b626f96466baed&X-Goog-SignedHeaders=host&X-User=2931823730: HTTPSConnectionPool(host='storage.googleapis.com', port=443): Max retries exceeded with url: /wandb-production.appspot.com/2931823730-harbin-institute-of-technology/ltu-as/mlm5cp60/config.yaml?X-Goog-Algorithm=GOOG4-RSA-SHA256&X-Goog-Credential=gorilla-files-url-signer-man%40wandb-production.iam.gserviceaccount.com%2F20250411%2Fauto%2Fstorage%2Fgoog4_request&X-Goog-Date=20250411T145114Z&X-Goog-Expires=86399&X-Goog-Signature=944235794937f5025098c1ad39eaa00481a836c99c5822829b310120eb7d5a4666982e0e334a9357d37d9b7e4cb8fd4f3724f2d49c298240333fb06ed6be1b75da245bf972b74d0764218fb8da8150e6196b47290b328b850073b184f52a618c71c6fc15b6faa23f42ea4f43733bcf9b72a4ffce6124a6fabb01094b60566df348dc4ffb6145b7e1b56d8870304b0db1439adbc5d7d36e9dbedcb04ed306c15ea7e5660dd3c1a459a318151493ddac525b223c64c1c3acd07b1074ffb2bae2a2c5748e1ccfa4dba073a06ddff15af3a314e16ae4a851154ac4a30a6b911fdd8835407050fbc7b5592ead92e01e0d5bee0d8d8fcb5b9ea7d5b9b626f96466baed&X-Goog-SignedHeaders=host&X-User=2931823730 (Caused by NewConnectionError('<urllib3.connection.HTTPSConnection object at 0x7f462ce1d600>: Failed to establish a new connection: [Errno 101] Network is unreachable'))
2025-04-11 14:51:31,183 ERROR   wandb-upload_1:17843 [internal_api.py:upload_file():2558] upload_file request headers: {'User-Agent': 'python-requests/2.32.3', 'Accept-Encoding': 'gzip, deflate, br', 'Accept': '*/*', 'Connection': 'keep-alive', 'Content-Length': '8685'}
2025-04-11 14:51:31,183 ERROR   wandb-upload_1:17843 [internal_api.py:upload_file():2560] upload_file response body: 
2025-04-11 14:51:31,420 ERROR   wandb-upload_2:17843 [internal_api.py:upload_file():2556] upload_file exception https://storage.googleapis.com/wandb-production.appspot.com/2931823730-harbin-institute-of-technology/ltu-as/mlm5cp60/requirements.txt?X-Goog-Algorithm=GOOG4-RSA-SHA256&X-Goog-Credential=gorilla-files-url-signer-man%40wandb-production.iam.gserviceaccount.com%2F20250411%2Fauto%2Fstorage%2Fgoog4_request&X-Goog-Date=20250411T145114Z&X-Goog-Expires=86399&X-Goog-Signature=acbd028386bc03d94948aaf65bc53bf77977ac5585e79ea0716ec007860ef39ea96f93094178bbe53396288150856563223a0e942bd376af8b161d4d58a6cf0e9dbea71fc7a9410c6f71628492009b7953de41033e7b38937eb708bfb6ada10c77ca0870f3d12be57f6d029ecfb8822e7dc5a62df88082610c8fc02b7aa861cee7e448378ac9d23208529f4a5e6344e6123aa73d657af02d72994735111ae518708f803b7f58dec8713f9eceb068ad7513a1b67628cc6fcf386e87c1a6dad3ca8abbf5fe3d3e33a074098ac226b071cc8aec87b300c8c753ac0940760332a70b2be12d9199bfeb835e45ee4c7766e2aaeab19a9da94cb9c52d45ad6563a0c27f&X-Goog-SignedHeaders=host&X-User=2931823730: HTTPSConnectionPool(host='storage.googleapis.com', port=443): Max retries exceeded with url: /wandb-production.appspot.com/2931823730-harbin-institute-of-technology/ltu-as/mlm5cp60/requirements.txt?X-Goog-Algorithm=GOOG4-RSA-SHA256&X-Goog-Credential=gorilla-files-url-signer-man%40wandb-production.iam.gserviceaccount.com%2F20250411%2Fauto%2Fstorage%2Fgoog4_request&X-Goog-Date=20250411T145114Z&X-Goog-Expires=86399&X-Goog-Signature=acbd028386bc03d94948aaf65bc53bf77977ac5585e79ea0716ec007860ef39ea96f93094178bbe53396288150856563223a0e942bd376af8b161d4d58a6cf0e9dbea71fc7a9410c6f71628492009b7953de41033e7b38937eb708bfb6ada10c77ca0870f3d12be57f6d029ecfb8822e7dc5a62df88082610c8fc02b7aa861cee7e448378ac9d23208529f4a5e6344e6123aa73d657af02d72994735111ae518708f803b7f58dec8713f9eceb068ad7513a1b67628cc6fcf386e87c1a6dad3ca8abbf5fe3d3e33a074098ac226b071cc8aec87b300c8c753ac0940760332a70b2be12d9199bfeb835e45ee4c7766e2aaeab19a9da94cb9c52d45ad6563a0c27f&X-Goog-SignedHeaders=host&X-User=2931823730 (Caused by NewConnectionError('<urllib3.connection.HTTPSConnection object at 0x7f464c197880>: Failed to establish a new connection: [Errno 101] Network is unreachable'))
2025-04-11 14:51:31,420 ERROR   wandb-upload_2:17843 [internal_api.py:upload_file():2558] upload_file request headers: {'User-Agent': 'python-requests/2.32.3', 'Accept-Encoding': 'gzip, deflate, br', 'Accept': '*/*', 'Connection': 'keep-alive', 'Content-Length': '4212'}
2025-04-11 14:51:31,420 ERROR   wandb-upload_2:17843 [internal_api.py:upload_file():2560] upload_file response body: 
2025-04-11 14:51:32,063 ERROR   wandb-upload_3:17843 [internal_api.py:upload_file():2556] upload_file exception https://storage.googleapis.com/wandb-production.appspot.com/2931823730-harbin-institute-of-technology/ltu-as/mlm5cp60/conda-environment.yaml?X-Goog-Algorithm=GOOG4-RSA-SHA256&X-Goog-Credential=gorilla-files-url-signer-man%40wandb-production.iam.gserviceaccount.com%2F20250411%2Fauto%2Fstorage%2Fgoog4_request&X-Goog-Date=20250411T145115Z&X-Goog-Expires=86399&X-Goog-Signature=18c9185561c0e38a4095f6492f7ba3109bb74b7ca241ce5eba7e7367298010776513c088c54a371846d5c60ffa97e1926acad93ddaeb7f1e863a32adfdbd3ffc7bd69000bb824d131ffd311a667fb373a02ed98fdde3d3caad24788ea1354f96c4dc5978d4dd03d993fdc19d79c0bbe55b08cbcf76dd3880dac13b40fb199889896f2944e570131678d4e0919686f72ab8a582d56638e963c3f9f8381660cc5a8e5124ccfb7760a0091bef421e6d0f0d3730b307cd29f88f8c5494dac201cc0a86ef0c41611677a875a6db0e8bddf08d412fb945a3c2ad3f19455ce2420ce93516e3e900072ff66ab558af6cd2677815e466cfd6ffe2abe2071b697185a279bd&X-Goog-SignedHeaders=host&X-User=2931823730: HTTPSConnectionPool(host='storage.googleapis.com', port=443): Max retries exceeded with url: /wandb-production.appspot.com/2931823730-harbin-institute-of-technology/ltu-as/mlm5cp60/conda-environment.yaml?X-Goog-Algorithm=GOOG4-RSA-SHA256&X-Goog-Credential=gorilla-files-url-signer-man%40wandb-production.iam.gserviceaccount.com%2F20250411%2Fauto%2Fstorage%2Fgoog4_request&X-Goog-Date=20250411T145115Z&X-Goog-Expires=86399&X-Goog-Signature=18c9185561c0e38a4095f6492f7ba3109bb74b7ca241ce5eba7e7367298010776513c088c54a371846d5c60ffa97e1926acad93ddaeb7f1e863a32adfdbd3ffc7bd69000bb824d131ffd311a667fb373a02ed98fdde3d3caad24788ea1354f96c4dc5978d4dd03d993fdc19d79c0bbe55b08cbcf76dd3880dac13b40fb199889896f2944e570131678d4e0919686f72ab8a582d56638e963c3f9f8381660cc5a8e5124ccfb7760a0091bef421e6d0f0d3730b307cd29f88f8c5494dac201cc0a86ef0c41611677a875a6db0e8bddf08d412fb945a3c2ad3f19455ce2420ce93516e3e900072ff66ab558af6cd2677815e466cfd6ffe2abe2071b697185a279bd&X-Goog-SignedHeaders=host&X-User=2931823730 (Caused by NewConnectionError('<urllib3.connection.HTTPSConnection object at 0x7f464c195f90>: Failed to establish a new connection: [Errno 101] Network is unreachable'))
2025-04-11 14:51:32,063 ERROR   wandb-upload_3:17843 [internal_api.py:upload_file():2558] upload_file request headers: {'User-Agent': 'python-requests/2.32.3', 'Accept-Encoding': 'gzip, deflate, br', 'Accept': '*/*', 'Connection': 'keep-alive', 'Content-Length': '8281'}
2025-04-11 14:51:32,064 ERROR   wandb-upload_3:17843 [internal_api.py:upload_file():2560] upload_file response body: 
2025-04-11 14:51:33,133 ERROR   wandb-upload_5:17843 [internal_api.py:upload_file():2556] upload_file exception https://storage.googleapis.com/wandb-production.appspot.com/2931823730-harbin-institute-of-technology/ltu-as/mlm5cp60/wandb-summary.json?X-Goog-Algorithm=GOOG4-RSA-SHA256&X-Goog-Credential=gorilla-files-url-signer-man%40wandb-production.iam.gserviceaccount.com%2F20250411%2Fauto%2Fstorage%2Fgoog4_request&X-Goog-Date=20250411T145115Z&X-Goog-Expires=86399&X-Goog-Signature=9df2087e11492ad178d77d9e9fab97630232b0a4f96a431148e4daf3a3ffb76f141a6acc698d2740403fe5d6787ed13f31ea70b94181a053e6e9bfe3b29b740f760a5a90f424f03e99c5b223fc30b089129e72948a62f1760c560b7f1eb6038148a7932d92a6c49a8613d4c7c04501f90b05b4395abd8bec4475d17d5fb0c4f0abdc39833cf913bd4da65c1c091140821a3269fc0d9ca812c0aaaceb66744bedabc6e1cc1b30e8946fc2d71819ae2467e1b4a3a0776572ba1fab93fa95fd681e3209826ea4ec41e0cdd752b417e53356fffd31afc35e8b7c23e46b68c60bd862806ba43d57d1fb048b5ba045a2b204376bd24fe7b11077307f2a2ccff7f3704e&X-Goog-SignedHeaders=host&X-User=2931823730: HTTPSConnectionPool(host='storage.googleapis.com', port=443): Max retries exceeded with url: /wandb-production.appspot.com/2931823730-harbin-institute-of-technology/ltu-as/mlm5cp60/wandb-summary.json?X-Goog-Algorithm=GOOG4-RSA-SHA256&X-Goog-Credential=gorilla-files-url-signer-man%40wandb-production.iam.gserviceaccount.com%2F20250411%2Fauto%2Fstorage%2Fgoog4_request&X-Goog-Date=20250411T145115Z&X-Goog-Expires=86399&X-Goog-Signature=9df2087e11492ad178d77d9e9fab97630232b0a4f96a431148e4daf3a3ffb76f141a6acc698d2740403fe5d6787ed13f31ea70b94181a053e6e9bfe3b29b740f760a5a90f424f03e99c5b223fc30b089129e72948a62f1760c560b7f1eb6038148a7932d92a6c49a8613d4c7c04501f90b05b4395abd8bec4475d17d5fb0c4f0abdc39833cf913bd4da65c1c091140821a3269fc0d9ca812c0aaaceb66744bedabc6e1cc1b30e8946fc2d71819ae2467e1b4a3a0776572ba1fab93fa95fd681e3209826ea4ec41e0cdd752b417e53356fffd31afc35e8b7c23e46b68c60bd862806ba43d57d1fb048b5ba045a2b204376bd24fe7b11077307f2a2ccff7f3704e&X-Goog-SignedHeaders=host&X-User=2931823730 (Caused by NewConnectionError('<urllib3.connection.HTTPSConnection object at 0x7f464c196170>: Failed to establish a new connection: [Errno 101] Network is unreachable'))
2025-04-11 14:51:33,134 ERROR   wandb-upload_5:17843 [internal_api.py:upload_file():2558] upload_file request headers: {'User-Agent': 'python-requests/2.32.3', 'Accept-Encoding': 'gzip, deflate, br', 'Accept': '*/*', 'Connection': 'keep-alive', 'Content-Length': '27'}
2025-04-11 14:51:33,134 ERROR   wandb-upload_5:17843 [internal_api.py:upload_file():2560] upload_file response body: 
2025-04-11 14:51:33,298 DEBUG   HandlerThread:17843 [handler.py:handle_request():146] handle_request: keepalive
2025-04-11 14:51:33,659 ERROR   wandb-upload_4:17843 [internal_api.py:upload_file():2556] upload_file exception https://storage.googleapis.com/wandb-production.appspot.com/2931823730-harbin-institute-of-technology/ltu-as/mlm5cp60/output.log?X-Goog-Algorithm=GOOG4-RSA-SHA256&X-Goog-Credential=gorilla-files-url-signer-man%40wandb-production.iam.gserviceaccount.com%2F20250411%2Fauto%2Fstorage%2Fgoog4_request&X-Goog-Date=20250411T145115Z&X-Goog-Expires=86399&X-Goog-Signature=66829b877c42ca303b639780fff7bf88cbb60209259c7dc6d23083a84ea8a96b64d71ff0c30cfcd6586ba916252610aa15480efdf90421949aa85f951f9b619e468eda017b8e55a28c0dd8aa6f99210f3f778f8a86e71dc469c624bf57498806db03fe0da4046f07d2c7f46ebf78d08027dddd14f7a09c4e83545aa9466da1eb6bbcaa07656e8c5098eb49767523418a66675017d803a591dae803119383f64fd0a7046d0036e02ac698d4dae626392e5291c9836cbd2eaea947ec9227980072d7bf72433004230cc067028ae4702b9478433d2bac33dd2edcdea1ff05ace0e6798c3b76707a6db65d093dae199f68cfbd61847341fb284cad3d6d9cc1489b0e&X-Goog-SignedHeaders=host&X-User=2931823730: HTTPSConnectionPool(host='storage.googleapis.com', port=443): Max retries exceeded with url: /wandb-production.appspot.com/2931823730-harbin-institute-of-technology/ltu-as/mlm5cp60/output.log?X-Goog-Algorithm=GOOG4-RSA-SHA256&X-Goog-Credential=gorilla-files-url-signer-man%40wandb-production.iam.gserviceaccount.com%2F20250411%2Fauto%2Fstorage%2Fgoog4_request&X-Goog-Date=20250411T145115Z&X-Goog-Expires=86399&X-Goog-Signature=66829b877c42ca303b639780fff7bf88cbb60209259c7dc6d23083a84ea8a96b64d71ff0c30cfcd6586ba916252610aa15480efdf90421949aa85f951f9b619e468eda017b8e55a28c0dd8aa6f99210f3f778f8a86e71dc469c624bf57498806db03fe0da4046f07d2c7f46ebf78d08027dddd14f7a09c4e83545aa9466da1eb6bbcaa07656e8c5098eb49767523418a66675017d803a591dae803119383f64fd0a7046d0036e02ac698d4dae626392e5291c9836cbd2eaea947ec9227980072d7bf72433004230cc067028ae4702b9478433d2bac33dd2edcdea1ff05ace0e6798c3b76707a6db65d093dae199f68cfbd61847341fb284cad3d6d9cc1489b0e&X-Goog-SignedHeaders=host&X-User=2931823730 (Caused by NewConnectionError('<urllib3.connection.HTTPSConnection object at 0x7f464c1960e0>: Failed to establish a new connection: [Errno 101] Network is unreachable'))
2025-04-11 14:51:33,659 ERROR   wandb-upload_4:17843 [internal_api.py:upload_file():2558] upload_file request headers: {'User-Agent': 'python-requests/2.32.3', 'Accept-Encoding': 'gzip, deflate, br', 'Accept': '*/*', 'Connection': 'keep-alive', 'Content-Length': '4566'}
2025-04-11 14:51:33,659 ERROR   wandb-upload_4:17843 [internal_api.py:upload_file():2560] upload_file response body: 
2025-04-11 14:51:34,867 DEBUG   HandlerThread:17843 [handler.py:handle_request():146] handle_request: status_report
2025-04-11 14:51:38,300 DEBUG   HandlerThread:17843 [handler.py:handle_request():146] handle_request: keepalive
2025-04-11 14:51:39,869 DEBUG   HandlerThread:17843 [handler.py:handle_request():146] handle_request: status_report
2025-04-11 14:51:41,853 ERROR   wandb-upload_0:17843 [internal_api.py:upload_file():2556] upload_file exception https://storage.googleapis.com/wandb-production.appspot.com/2931823730-harbin-institute-of-technology/ltu-as/mlm5cp60/wandb-metadata.json?X-Goog-Algorithm=GOOG4-RSA-SHA256&X-Goog-Credential=gorilla-files-url-signer-man%40wandb-production.iam.gserviceaccount.com%2F20250411%2Fauto%2Fstorage%2Fgoog4_request&X-Goog-Date=20250411T145106Z&X-Goog-Expires=86399&X-Goog-Signature=5e61366a9cdba14e9366e693773cc7799673c98fe4965f87dc63e9596d3f0187754b4e166d7560ee536e464deebf60499d155fae33d314f1b808bc2ccf04fe2c2b6efba6d43259562807703d0c11efadf701d1f3e05abb6b0468adf02bd6951f959adbbc65e0e0d573f6077508150688e50412733d3f1fd1d82b1064ce9849427b169d276ec4abcb3c6ad012ae7b83463f0f43df52a7831651905f2c417198214e2d77562e52239192e58ea0c1a2ffac95120c36d81ee751e5ad5f0567ad413c9810baa3cdbf48f97d70e2753cf600570333d0c31fed9fdb63c272a974ee3c1de0d894e1ac50b3735ef19c262cef60219e3f1c55b31dfe63d31aed27b25d009c&X-Goog-SignedHeaders=host&X-User=2931823730: HTTPSConnectionPool(host='storage.googleapis.com', port=443): Max retries exceeded with url: /wandb-production.appspot.com/2931823730-harbin-institute-of-technology/ltu-as/mlm5cp60/wandb-metadata.json?X-Goog-Algorithm=GOOG4-RSA-SHA256&X-Goog-Credential=gorilla-files-url-signer-man%40wandb-production.iam.gserviceaccount.com%2F20250411%2Fauto%2Fstorage%2Fgoog4_request&X-Goog-Date=20250411T145106Z&X-Goog-Expires=86399&X-Goog-Signature=5e61366a9cdba14e9366e693773cc7799673c98fe4965f87dc63e9596d3f0187754b4e166d7560ee536e464deebf60499d155fae33d314f1b808bc2ccf04fe2c2b6efba6d43259562807703d0c11efadf701d1f3e05abb6b0468adf02bd6951f959adbbc65e0e0d573f6077508150688e50412733d3f1fd1d82b1064ce9849427b169d276ec4abcb3c6ad012ae7b83463f0f43df52a7831651905f2c417198214e2d77562e52239192e58ea0c1a2ffac95120c36d81ee751e5ad5f0567ad413c9810baa3cdbf48f97d70e2753cf600570333d0c31fed9fdb63c272a974ee3c1de0d894e1ac50b3735ef19c262cef60219e3f1c55b31dfe63d31aed27b25d009c&X-Goog-SignedHeaders=host&X-User=2931823730 (Caused by NewConnectionError('<urllib3.connection.HTTPSConnection object at 0x7f464c197e50>: Failed to establish a new connection: [Errno 101] Network is unreachable'))
2025-04-11 14:51:41,853 ERROR   wandb-upload_0:17843 [internal_api.py:upload_file():2558] upload_file request headers: {'User-Agent': 'python-requests/2.32.3', 'Accept-Encoding': 'gzip, deflate, br', 'Accept': '*/*', 'Connection': 'keep-alive', 'Content-Length': '2274'}
2025-04-11 14:51:41,854 ERROR   wandb-upload_0:17843 [internal_api.py:upload_file():2560] upload_file response body: 
2025-04-11 14:51:43,302 DEBUG   HandlerThread:17843 [handler.py:handle_request():146] handle_request: keepalive
2025-04-11 14:51:44,870 DEBUG   HandlerThread:17843 [handler.py:handle_request():146] handle_request: status_report
2025-04-11 14:51:48,304 DEBUG   HandlerThread:17843 [handler.py:handle_request():146] handle_request: keepalive
2025-04-11 14:51:48,437 ERROR   wandb-upload_2:17843 [internal_api.py:upload_file():2556] upload_file exception https://storage.googleapis.com/wandb-production.appspot.com/2931823730-harbin-institute-of-technology/ltu-as/mlm5cp60/requirements.txt?X-Goog-Algorithm=GOOG4-RSA-SHA256&X-Goog-Credential=gorilla-files-url-signer-man%40wandb-production.iam.gserviceaccount.com%2F20250411%2Fauto%2Fstorage%2Fgoog4_request&X-Goog-Date=20250411T145114Z&X-Goog-Expires=86399&X-Goog-Signature=acbd028386bc03d94948aaf65bc53bf77977ac5585e79ea0716ec007860ef39ea96f93094178bbe53396288150856563223a0e942bd376af8b161d4d58a6cf0e9dbea71fc7a9410c6f71628492009b7953de41033e7b38937eb708bfb6ada10c77ca0870f3d12be57f6d029ecfb8822e7dc5a62df88082610c8fc02b7aa861cee7e448378ac9d23208529f4a5e6344e6123aa73d657af02d72994735111ae518708f803b7f58dec8713f9eceb068ad7513a1b67628cc6fcf386e87c1a6dad3ca8abbf5fe3d3e33a074098ac226b071cc8aec87b300c8c753ac0940760332a70b2be12d9199bfeb835e45ee4c7766e2aaeab19a9da94cb9c52d45ad6563a0c27f&X-Goog-SignedHeaders=host&X-User=2931823730: HTTPSConnectionPool(host='storage.googleapis.com', port=443): Max retries exceeded with url: /wandb-production.appspot.com/2931823730-harbin-institute-of-technology/ltu-as/mlm5cp60/requirements.txt?X-Goog-Algorithm=GOOG4-RSA-SHA256&X-Goog-Credential=gorilla-files-url-signer-man%40wandb-production.iam.gserviceaccount.com%2F20250411%2Fauto%2Fstorage%2Fgoog4_request&X-Goog-Date=20250411T145114Z&X-Goog-Expires=86399&X-Goog-Signature=acbd028386bc03d94948aaf65bc53bf77977ac5585e79ea0716ec007860ef39ea96f93094178bbe53396288150856563223a0e942bd376af8b161d4d58a6cf0e9dbea71fc7a9410c6f71628492009b7953de41033e7b38937eb708bfb6ada10c77ca0870f3d12be57f6d029ecfb8822e7dc5a62df88082610c8fc02b7aa861cee7e448378ac9d23208529f4a5e6344e6123aa73d657af02d72994735111ae518708f803b7f58dec8713f9eceb068ad7513a1b67628cc6fcf386e87c1a6dad3ca8abbf5fe3d3e33a074098ac226b071cc8aec87b300c8c753ac0940760332a70b2be12d9199bfeb835e45ee4c7766e2aaeab19a9da94cb9c52d45ad6563a0c27f&X-Goog-SignedHeaders=host&X-User=2931823730 (Caused by NewConnectionError('<urllib3.connection.HTTPSConnection object at 0x7f462ce1d3f0>: Failed to establish a new connection: [Errno 101] Network is unreachable'))
2025-04-11 14:51:48,437 ERROR   wandb-upload_2:17843 [internal_api.py:upload_file():2558] upload_file request headers: {'User-Agent': 'python-requests/2.32.3', 'Accept-Encoding': 'gzip, deflate, br', 'Accept': '*/*', 'Connection': 'keep-alive', 'Content-Length': '4212'}
2025-04-11 14:51:48,438 ERROR   wandb-upload_2:17843 [internal_api.py:upload_file():2560] upload_file response body: 
2025-04-11 14:51:48,895 ERROR   wandb-upload_1:17843 [internal_api.py:upload_file():2556] upload_file exception https://storage.googleapis.com/wandb-production.appspot.com/2931823730-harbin-institute-of-technology/ltu-as/mlm5cp60/config.yaml?X-Goog-Algorithm=GOOG4-RSA-SHA256&X-Goog-Credential=gorilla-files-url-signer-man%40wandb-production.iam.gserviceaccount.com%2F20250411%2Fauto%2Fstorage%2Fgoog4_request&X-Goog-Date=20250411T145114Z&X-Goog-Expires=86399&X-Goog-Signature=944235794937f5025098c1ad39eaa00481a836c99c5822829b310120eb7d5a4666982e0e334a9357d37d9b7e4cb8fd4f3724f2d49c298240333fb06ed6be1b75da245bf972b74d0764218fb8da8150e6196b47290b328b850073b184f52a618c71c6fc15b6faa23f42ea4f43733bcf9b72a4ffce6124a6fabb01094b60566df348dc4ffb6145b7e1b56d8870304b0db1439adbc5d7d36e9dbedcb04ed306c15ea7e5660dd3c1a459a318151493ddac525b223c64c1c3acd07b1074ffb2bae2a2c5748e1ccfa4dba073a06ddff15af3a314e16ae4a851154ac4a30a6b911fdd8835407050fbc7b5592ead92e01e0d5bee0d8d8fcb5b9ea7d5b9b626f96466baed&X-Goog-SignedHeaders=host&X-User=2931823730: HTTPSConnectionPool(host='storage.googleapis.com', port=443): Max retries exceeded with url: /wandb-production.appspot.com/2931823730-harbin-institute-of-technology/ltu-as/mlm5cp60/config.yaml?X-Goog-Algorithm=GOOG4-RSA-SHA256&X-Goog-Credential=gorilla-files-url-signer-man%40wandb-production.iam.gserviceaccount.com%2F20250411%2Fauto%2Fstorage%2Fgoog4_request&X-Goog-Date=20250411T145114Z&X-Goog-Expires=86399&X-Goog-Signature=944235794937f5025098c1ad39eaa00481a836c99c5822829b310120eb7d5a4666982e0e334a9357d37d9b7e4cb8fd4f3724f2d49c298240333fb06ed6be1b75da245bf972b74d0764218fb8da8150e6196b47290b328b850073b184f52a618c71c6fc15b6faa23f42ea4f43733bcf9b72a4ffce6124a6fabb01094b60566df348dc4ffb6145b7e1b56d8870304b0db1439adbc5d7d36e9dbedcb04ed306c15ea7e5660dd3c1a459a318151493ddac525b223c64c1c3acd07b1074ffb2bae2a2c5748e1ccfa4dba073a06ddff15af3a314e16ae4a851154ac4a30a6b911fdd8835407050fbc7b5592ead92e01e0d5bee0d8d8fcb5b9ea7d5b9b626f96466baed&X-Goog-SignedHeaders=host&X-User=2931823730 (Caused by NewConnectionError('<urllib3.connection.HTTPSConnection object at 0x7f462ce1d7b0>: Failed to establish a new connection: [Errno 101] Network is unreachable'))
2025-04-11 14:51:48,895 ERROR   wandb-upload_1:17843 [internal_api.py:upload_file():2558] upload_file request headers: {'User-Agent': 'python-requests/2.32.3', 'Accept-Encoding': 'gzip, deflate, br', 'Accept': '*/*', 'Connection': 'keep-alive', 'Content-Length': '8685'}
2025-04-11 14:51:48,896 ERROR   wandb-upload_1:17843 [internal_api.py:upload_file():2560] upload_file response body: 
2025-04-11 14:51:49,871 DEBUG   HandlerThread:17843 [handler.py:handle_request():146] handle_request: status_report
2025-04-11 14:51:50,451 ERROR   wandb-upload_3:17843 [internal_api.py:upload_file():2556] upload_file exception https://storage.googleapis.com/wandb-production.appspot.com/2931823730-harbin-institute-of-technology/ltu-as/mlm5cp60/conda-environment.yaml?X-Goog-Algorithm=GOOG4-RSA-SHA256&X-Goog-Credential=gorilla-files-url-signer-man%40wandb-production.iam.gserviceaccount.com%2F20250411%2Fauto%2Fstorage%2Fgoog4_request&X-Goog-Date=20250411T145115Z&X-Goog-Expires=86399&X-Goog-Signature=18c9185561c0e38a4095f6492f7ba3109bb74b7ca241ce5eba7e7367298010776513c088c54a371846d5c60ffa97e1926acad93ddaeb7f1e863a32adfdbd3ffc7bd69000bb824d131ffd311a667fb373a02ed98fdde3d3caad24788ea1354f96c4dc5978d4dd03d993fdc19d79c0bbe55b08cbcf76dd3880dac13b40fb199889896f2944e570131678d4e0919686f72ab8a582d56638e963c3f9f8381660cc5a8e5124ccfb7760a0091bef421e6d0f0d3730b307cd29f88f8c5494dac201cc0a86ef0c41611677a875a6db0e8bddf08d412fb945a3c2ad3f19455ce2420ce93516e3e900072ff66ab558af6cd2677815e466cfd6ffe2abe2071b697185a279bd&X-Goog-SignedHeaders=host&X-User=2931823730: HTTPSConnectionPool(host='storage.googleapis.com', port=443): Max retries exceeded with url: /wandb-production.appspot.com/2931823730-harbin-institute-of-technology/ltu-as/mlm5cp60/conda-environment.yaml?X-Goog-Algorithm=GOOG4-RSA-SHA256&X-Goog-Credential=gorilla-files-url-signer-man%40wandb-production.iam.gserviceaccount.com%2F20250411%2Fauto%2Fstorage%2Fgoog4_request&X-Goog-Date=20250411T145115Z&X-Goog-Expires=86399&X-Goog-Signature=18c9185561c0e38a4095f6492f7ba3109bb74b7ca241ce5eba7e7367298010776513c088c54a371846d5c60ffa97e1926acad93ddaeb7f1e863a32adfdbd3ffc7bd69000bb824d131ffd311a667fb373a02ed98fdde3d3caad24788ea1354f96c4dc5978d4dd03d993fdc19d79c0bbe55b08cbcf76dd3880dac13b40fb199889896f2944e570131678d4e0919686f72ab8a582d56638e963c3f9f8381660cc5a8e5124ccfb7760a0091bef421e6d0f0d3730b307cd29f88f8c5494dac201cc0a86ef0c41611677a875a6db0e8bddf08d412fb945a3c2ad3f19455ce2420ce93516e3e900072ff66ab558af6cd2677815e466cfd6ffe2abe2071b697185a279bd&X-Goog-SignedHeaders=host&X-User=2931823730 (Caused by NewConnectionError('<urllib3.connection.HTTPSConnection object at 0x7f462ce1ee90>: Failed to establish a new connection: [Errno 101] Network is unreachable'))
2025-04-11 14:51:50,451 ERROR   wandb-upload_3:17843 [internal_api.py:upload_file():2558] upload_file request headers: {'User-Agent': 'python-requests/2.32.3', 'Accept-Encoding': 'gzip, deflate, br', 'Accept': '*/*', 'Connection': 'keep-alive', 'Content-Length': '8281'}
2025-04-11 14:51:50,451 ERROR   wandb-upload_3:17843 [internal_api.py:upload_file():2560] upload_file response body: 
2025-04-11 14:51:52,812 ERROR   wandb-upload_5:17843 [internal_api.py:upload_file():2556] upload_file exception https://storage.googleapis.com/wandb-production.appspot.com/2931823730-harbin-institute-of-technology/ltu-as/mlm5cp60/wandb-summary.json?X-Goog-Algorithm=GOOG4-RSA-SHA256&X-Goog-Credential=gorilla-files-url-signer-man%40wandb-production.iam.gserviceaccount.com%2F20250411%2Fauto%2Fstorage%2Fgoog4_request&X-Goog-Date=20250411T145115Z&X-Goog-Expires=86399&X-Goog-Signature=9df2087e11492ad178d77d9e9fab97630232b0a4f96a431148e4daf3a3ffb76f141a6acc698d2740403fe5d6787ed13f31ea70b94181a053e6e9bfe3b29b740f760a5a90f424f03e99c5b223fc30b089129e72948a62f1760c560b7f1eb6038148a7932d92a6c49a8613d4c7c04501f90b05b4395abd8bec4475d17d5fb0c4f0abdc39833cf913bd4da65c1c091140821a3269fc0d9ca812c0aaaceb66744bedabc6e1cc1b30e8946fc2d71819ae2467e1b4a3a0776572ba1fab93fa95fd681e3209826ea4ec41e0cdd752b417e53356fffd31afc35e8b7c23e46b68c60bd862806ba43d57d1fb048b5ba045a2b204376bd24fe7b11077307f2a2ccff7f3704e&X-Goog-SignedHeaders=host&X-User=2931823730: HTTPSConnectionPool(host='storage.googleapis.com', port=443): Max retries exceeded with url: /wandb-production.appspot.com/2931823730-harbin-institute-of-technology/ltu-as/mlm5cp60/wandb-summary.json?X-Goog-Algorithm=GOOG4-RSA-SHA256&X-Goog-Credential=gorilla-files-url-signer-man%40wandb-production.iam.gserviceaccount.com%2F20250411%2Fauto%2Fstorage%2Fgoog4_request&X-Goog-Date=20250411T145115Z&X-Goog-Expires=86399&X-Goog-Signature=9df2087e11492ad178d77d9e9fab97630232b0a4f96a431148e4daf3a3ffb76f141a6acc698d2740403fe5d6787ed13f31ea70b94181a053e6e9bfe3b29b740f760a5a90f424f03e99c5b223fc30b089129e72948a62f1760c560b7f1eb6038148a7932d92a6c49a8613d4c7c04501f90b05b4395abd8bec4475d17d5fb0c4f0abdc39833cf913bd4da65c1c091140821a3269fc0d9ca812c0aaaceb66744bedabc6e1cc1b30e8946fc2d71819ae2467e1b4a3a0776572ba1fab93fa95fd681e3209826ea4ec41e0cdd752b417e53356fffd31afc35e8b7c23e46b68c60bd862806ba43d57d1fb048b5ba045a2b204376bd24fe7b11077307f2a2ccff7f3704e&X-Goog-SignedHeaders=host&X-User=2931823730 (Caused by NewConnectionError('<urllib3.connection.HTTPSConnection object at 0x7f462ce1f0d0>: Failed to establish a new connection: [Errno 101] Network is unreachable'))
2025-04-11 14:51:52,812 ERROR   wandb-upload_5:17843 [internal_api.py:upload_file():2558] upload_file request headers: {'User-Agent': 'python-requests/2.32.3', 'Accept-Encoding': 'gzip, deflate, br', 'Accept': '*/*', 'Connection': 'keep-alive', 'Content-Length': '27'}
2025-04-11 14:51:52,812 ERROR   wandb-upload_5:17843 [internal_api.py:upload_file():2560] upload_file response body: 
2025-04-11 14:51:53,249 ERROR   wandb-upload_4:17843 [internal_api.py:upload_file():2556] upload_file exception https://storage.googleapis.com/wandb-production.appspot.com/2931823730-harbin-institute-of-technology/ltu-as/mlm5cp60/output.log?X-Goog-Algorithm=GOOG4-RSA-SHA256&X-Goog-Credential=gorilla-files-url-signer-man%40wandb-production.iam.gserviceaccount.com%2F20250411%2Fauto%2Fstorage%2Fgoog4_request&X-Goog-Date=20250411T145115Z&X-Goog-Expires=86399&X-Goog-Signature=66829b877c42ca303b639780fff7bf88cbb60209259c7dc6d23083a84ea8a96b64d71ff0c30cfcd6586ba916252610aa15480efdf90421949aa85f951f9b619e468eda017b8e55a28c0dd8aa6f99210f3f778f8a86e71dc469c624bf57498806db03fe0da4046f07d2c7f46ebf78d08027dddd14f7a09c4e83545aa9466da1eb6bbcaa07656e8c5098eb49767523418a66675017d803a591dae803119383f64fd0a7046d0036e02ac698d4dae626392e5291c9836cbd2eaea947ec9227980072d7bf72433004230cc067028ae4702b9478433d2bac33dd2edcdea1ff05ace0e6798c3b76707a6db65d093dae199f68cfbd61847341fb284cad3d6d9cc1489b0e&X-Goog-SignedHeaders=host&X-User=2931823730: HTTPSConnectionPool(host='storage.googleapis.com', port=443): Max retries exceeded with url: /wandb-production.appspot.com/2931823730-harbin-institute-of-technology/ltu-as/mlm5cp60/output.log?X-Goog-Algorithm=GOOG4-RSA-SHA256&X-Goog-Credential=gorilla-files-url-signer-man%40wandb-production.iam.gserviceaccount.com%2F20250411%2Fauto%2Fstorage%2Fgoog4_request&X-Goog-Date=20250411T145115Z&X-Goog-Expires=86399&X-Goog-Signature=66829b877c42ca303b639780fff7bf88cbb60209259c7dc6d23083a84ea8a96b64d71ff0c30cfcd6586ba916252610aa15480efdf90421949aa85f951f9b619e468eda017b8e55a28c0dd8aa6f99210f3f778f8a86e71dc469c624bf57498806db03fe0da4046f07d2c7f46ebf78d08027dddd14f7a09c4e83545aa9466da1eb6bbcaa07656e8c5098eb49767523418a66675017d803a591dae803119383f64fd0a7046d0036e02ac698d4dae626392e5291c9836cbd2eaea947ec9227980072d7bf72433004230cc067028ae4702b9478433d2bac33dd2edcdea1ff05ace0e6798c3b76707a6db65d093dae199f68cfbd61847341fb284cad3d6d9cc1489b0e&X-Goog-SignedHeaders=host&X-User=2931823730 (Caused by NewConnectionError('<urllib3.connection.HTTPSConnection object at 0x7f462ce1c580>: Failed to establish a new connection: [Errno 101] Network is unreachable'))
2025-04-11 14:51:53,249 ERROR   wandb-upload_4:17843 [internal_api.py:upload_file():2558] upload_file request headers: {'User-Agent': 'python-requests/2.32.3', 'Accept-Encoding': 'gzip, deflate, br', 'Accept': '*/*', 'Connection': 'keep-alive', 'Content-Length': '4566'}
2025-04-11 14:51:53,249 ERROR   wandb-upload_4:17843 [internal_api.py:upload_file():2560] upload_file response body: 
2025-04-11 14:51:53,306 DEBUG   HandlerThread:17843 [handler.py:handle_request():146] handle_request: keepalive
2025-04-11 14:51:54,872 DEBUG   HandlerThread:17843 [handler.py:handle_request():146] handle_request: status_report
2025-04-11 14:51:58,308 DEBUG   HandlerThread:17843 [handler.py:handle_request():146] handle_request: keepalive
2025-04-11 14:51:59,873 DEBUG   HandlerThread:17843 [handler.py:handle_request():146] handle_request: status_report
2025-04-11 14:52:03,311 DEBUG   HandlerThread:17843 [handler.py:handle_request():146] handle_request: keepalive
2025-04-11 14:52:04,874 DEBUG   HandlerThread:17843 [handler.py:handle_request():146] handle_request: status_report
2025-04-11 14:52:08,312 DEBUG   HandlerThread:17843 [handler.py:handle_request():146] handle_request: keepalive
2025-04-11 14:52:09,875 DEBUG   HandlerThread:17843 [handler.py:handle_request():146] handle_request: status_report
2025-04-11 14:52:13,315 DEBUG   HandlerThread:17843 [handler.py:handle_request():146] handle_request: keepalive
2025-04-11 14:52:14,876 DEBUG   HandlerThread:17843 [handler.py:handle_request():146] handle_request: status_report
2025-04-11 14:52:18,296 ERROR   wandb-upload_0:17843 [internal_api.py:upload_file():2556] upload_file exception https://storage.googleapis.com/wandb-production.appspot.com/2931823730-harbin-institute-of-technology/ltu-as/mlm5cp60/wandb-metadata.json?X-Goog-Algorithm=GOOG4-RSA-SHA256&X-Goog-Credential=gorilla-files-url-signer-man%40wandb-production.iam.gserviceaccount.com%2F20250411%2Fauto%2Fstorage%2Fgoog4_request&X-Goog-Date=20250411T145106Z&X-Goog-Expires=86399&X-Goog-Signature=5e61366a9cdba14e9366e693773cc7799673c98fe4965f87dc63e9596d3f0187754b4e166d7560ee536e464deebf60499d155fae33d314f1b808bc2ccf04fe2c2b6efba6d43259562807703d0c11efadf701d1f3e05abb6b0468adf02bd6951f959adbbc65e0e0d573f6077508150688e50412733d3f1fd1d82b1064ce9849427b169d276ec4abcb3c6ad012ae7b83463f0f43df52a7831651905f2c417198214e2d77562e52239192e58ea0c1a2ffac95120c36d81ee751e5ad5f0567ad413c9810baa3cdbf48f97d70e2753cf600570333d0c31fed9fdb63c272a974ee3c1de0d894e1ac50b3735ef19c262cef60219e3f1c55b31dfe63d31aed27b25d009c&X-Goog-SignedHeaders=host&X-User=2931823730: HTTPSConnectionPool(host='storage.googleapis.com', port=443): Max retries exceeded with url: /wandb-production.appspot.com/2931823730-harbin-institute-of-technology/ltu-as/mlm5cp60/wandb-metadata.json?X-Goog-Algorithm=GOOG4-RSA-SHA256&X-Goog-Credential=gorilla-files-url-signer-man%40wandb-production.iam.gserviceaccount.com%2F20250411%2Fauto%2Fstorage%2Fgoog4_request&X-Goog-Date=20250411T145106Z&X-Goog-Expires=86399&X-Goog-Signature=5e61366a9cdba14e9366e693773cc7799673c98fe4965f87dc63e9596d3f0187754b4e166d7560ee536e464deebf60499d155fae33d314f1b808bc2ccf04fe2c2b6efba6d43259562807703d0c11efadf701d1f3e05abb6b0468adf02bd6951f959adbbc65e0e0d573f6077508150688e50412733d3f1fd1d82b1064ce9849427b169d276ec4abcb3c6ad012ae7b83463f0f43df52a7831651905f2c417198214e2d77562e52239192e58ea0c1a2ffac95120c36d81ee751e5ad5f0567ad413c9810baa3cdbf48f97d70e2753cf600570333d0c31fed9fdb63c272a974ee3c1de0d894e1ac50b3735ef19c262cef60219e3f1c55b31dfe63d31aed27b25d009c&X-Goog-SignedHeaders=host&X-User=2931823730 (Caused by NewConnectionError('<urllib3.connection.HTTPSConnection object at 0x7f464c197e20>: Failed to establish a new connection: [Errno 101] Network is unreachable'))
2025-04-11 14:52:18,296 ERROR   wandb-upload_0:17843 [internal_api.py:upload_file():2558] upload_file request headers: {'User-Agent': 'python-requests/2.32.3', 'Accept-Encoding': 'gzip, deflate, br', 'Accept': '*/*', 'Connection': 'keep-alive', 'Content-Length': '2274'}
2025-04-11 14:52:18,296 ERROR   wandb-upload_0:17843 [internal_api.py:upload_file():2560] upload_file response body: 
2025-04-11 14:52:18,316 DEBUG   HandlerThread:17843 [handler.py:handle_request():146] handle_request: keepalive
2025-04-11 14:52:19,878 DEBUG   HandlerThread:17843 [handler.py:handle_request():146] handle_request: status_report
2025-04-11 14:52:23,124 ERROR   wandb-upload_1:17843 [internal_api.py:upload_file():2556] upload_file exception https://storage.googleapis.com/wandb-production.appspot.com/2931823730-harbin-institute-of-technology/ltu-as/mlm5cp60/config.yaml?X-Goog-Algorithm=GOOG4-RSA-SHA256&X-Goog-Credential=gorilla-files-url-signer-man%40wandb-production.iam.gserviceaccount.com%2F20250411%2Fauto%2Fstorage%2Fgoog4_request&X-Goog-Date=20250411T145114Z&X-Goog-Expires=86399&X-Goog-Signature=944235794937f5025098c1ad39eaa00481a836c99c5822829b310120eb7d5a4666982e0e334a9357d37d9b7e4cb8fd4f3724f2d49c298240333fb06ed6be1b75da245bf972b74d0764218fb8da8150e6196b47290b328b850073b184f52a618c71c6fc15b6faa23f42ea4f43733bcf9b72a4ffce6124a6fabb01094b60566df348dc4ffb6145b7e1b56d8870304b0db1439adbc5d7d36e9dbedcb04ed306c15ea7e5660dd3c1a459a318151493ddac525b223c64c1c3acd07b1074ffb2bae2a2c5748e1ccfa4dba073a06ddff15af3a314e16ae4a851154ac4a30a6b911fdd8835407050fbc7b5592ead92e01e0d5bee0d8d8fcb5b9ea7d5b9b626f96466baed&X-Goog-SignedHeaders=host&X-User=2931823730: HTTPSConnectionPool(host='storage.googleapis.com', port=443): Max retries exceeded with url: /wandb-production.appspot.com/2931823730-harbin-institute-of-technology/ltu-as/mlm5cp60/config.yaml?X-Goog-Algorithm=GOOG4-RSA-SHA256&X-Goog-Credential=gorilla-files-url-signer-man%40wandb-production.iam.gserviceaccount.com%2F20250411%2Fauto%2Fstorage%2Fgoog4_request&X-Goog-Date=20250411T145114Z&X-Goog-Expires=86399&X-Goog-Signature=944235794937f5025098c1ad39eaa00481a836c99c5822829b310120eb7d5a4666982e0e334a9357d37d9b7e4cb8fd4f3724f2d49c298240333fb06ed6be1b75da245bf972b74d0764218fb8da8150e6196b47290b328b850073b184f52a618c71c6fc15b6faa23f42ea4f43733bcf9b72a4ffce6124a6fabb01094b60566df348dc4ffb6145b7e1b56d8870304b0db1439adbc5d7d36e9dbedcb04ed306c15ea7e5660dd3c1a459a318151493ddac525b223c64c1c3acd07b1074ffb2bae2a2c5748e1ccfa4dba073a06ddff15af3a314e16ae4a851154ac4a30a6b911fdd8835407050fbc7b5592ead92e01e0d5bee0d8d8fcb5b9ea7d5b9b626f96466baed&X-Goog-SignedHeaders=host&X-User=2931823730 (Caused by NewConnectionError('<urllib3.connection.HTTPSConnection object at 0x7f464c197310>: Failed to establish a new connection: [Errno 101] Network is unreachable'))
2025-04-11 14:52:23,125 ERROR   wandb-upload_1:17843 [internal_api.py:upload_file():2558] upload_file request headers: {'User-Agent': 'python-requests/2.32.3', 'Accept-Encoding': 'gzip, deflate, br', 'Accept': '*/*', 'Connection': 'keep-alive', 'Content-Length': '8685'}
2025-04-11 14:52:23,125 ERROR   wandb-upload_1:17843 [internal_api.py:upload_file():2560] upload_file response body: 
2025-04-11 14:52:23,319 DEBUG   HandlerThread:17843 [handler.py:handle_request():146] handle_request: keepalive
2025-04-11 14:52:24,879 DEBUG   HandlerThread:17843 [handler.py:handle_request():146] handle_request: status_report
2025-04-11 14:52:25,274 ERROR   wandb-upload_3:17843 [internal_api.py:upload_file():2556] upload_file exception https://storage.googleapis.com/wandb-production.appspot.com/2931823730-harbin-institute-of-technology/ltu-as/mlm5cp60/conda-environment.yaml?X-Goog-Algorithm=GOOG4-RSA-SHA256&X-Goog-Credential=gorilla-files-url-signer-man%40wandb-production.iam.gserviceaccount.com%2F20250411%2Fauto%2Fstorage%2Fgoog4_request&X-Goog-Date=20250411T145115Z&X-Goog-Expires=86399&X-Goog-Signature=18c9185561c0e38a4095f6492f7ba3109bb74b7ca241ce5eba7e7367298010776513c088c54a371846d5c60ffa97e1926acad93ddaeb7f1e863a32adfdbd3ffc7bd69000bb824d131ffd311a667fb373a02ed98fdde3d3caad24788ea1354f96c4dc5978d4dd03d993fdc19d79c0bbe55b08cbcf76dd3880dac13b40fb199889896f2944e570131678d4e0919686f72ab8a582d56638e963c3f9f8381660cc5a8e5124ccfb7760a0091bef421e6d0f0d3730b307cd29f88f8c5494dac201cc0a86ef0c41611677a875a6db0e8bddf08d412fb945a3c2ad3f19455ce2420ce93516e3e900072ff66ab558af6cd2677815e466cfd6ffe2abe2071b697185a279bd&X-Goog-SignedHeaders=host&X-User=2931823730: HTTPSConnectionPool(host='storage.googleapis.com', port=443): Max retries exceeded with url: /wandb-production.appspot.com/2931823730-harbin-institute-of-technology/ltu-as/mlm5cp60/conda-environment.yaml?X-Goog-Algorithm=GOOG4-RSA-SHA256&X-Goog-Credential=gorilla-files-url-signer-man%40wandb-production.iam.gserviceaccount.com%2F20250411%2Fauto%2Fstorage%2Fgoog4_request&X-Goog-Date=20250411T145115Z&X-Goog-Expires=86399&X-Goog-Signature=18c9185561c0e38a4095f6492f7ba3109bb74b7ca241ce5eba7e7367298010776513c088c54a371846d5c60ffa97e1926acad93ddaeb7f1e863a32adfdbd3ffc7bd69000bb824d131ffd311a667fb373a02ed98fdde3d3caad24788ea1354f96c4dc5978d4dd03d993fdc19d79c0bbe55b08cbcf76dd3880dac13b40fb199889896f2944e570131678d4e0919686f72ab8a582d56638e963c3f9f8381660cc5a8e5124ccfb7760a0091bef421e6d0f0d3730b307cd29f88f8c5494dac201cc0a86ef0c41611677a875a6db0e8bddf08d412fb945a3c2ad3f19455ce2420ce93516e3e900072ff66ab558af6cd2677815e466cfd6ffe2abe2071b697185a279bd&X-Goog-SignedHeaders=host&X-User=2931823730 (Caused by NewConnectionError('<urllib3.connection.HTTPSConnection object at 0x7f464c1962c0>: Failed to establish a new connection: [Errno 101] Network is unreachable'))
2025-04-11 14:52:25,274 ERROR   wandb-upload_3:17843 [internal_api.py:upload_file():2558] upload_file request headers: {'User-Agent': 'python-requests/2.32.3', 'Accept-Encoding': 'gzip, deflate, br', 'Accept': '*/*', 'Connection': 'keep-alive', 'Content-Length': '8281'}
2025-04-11 14:52:25,274 ERROR   wandb-upload_3:17843 [internal_api.py:upload_file():2560] upload_file response body: 
2025-04-11 14:52:26,616 ERROR   wandb-upload_5:17843 [internal_api.py:upload_file():2556] upload_file exception https://storage.googleapis.com/wandb-production.appspot.com/2931823730-harbin-institute-of-technology/ltu-as/mlm5cp60/wandb-summary.json?X-Goog-Algorithm=GOOG4-RSA-SHA256&X-Goog-Credential=gorilla-files-url-signer-man%40wandb-production.iam.gserviceaccount.com%2F20250411%2Fauto%2Fstorage%2Fgoog4_request&X-Goog-Date=20250411T145115Z&X-Goog-Expires=86399&X-Goog-Signature=9df2087e11492ad178d77d9e9fab97630232b0a4f96a431148e4daf3a3ffb76f141a6acc698d2740403fe5d6787ed13f31ea70b94181a053e6e9bfe3b29b740f760a5a90f424f03e99c5b223fc30b089129e72948a62f1760c560b7f1eb6038148a7932d92a6c49a8613d4c7c04501f90b05b4395abd8bec4475d17d5fb0c4f0abdc39833cf913bd4da65c1c091140821a3269fc0d9ca812c0aaaceb66744bedabc6e1cc1b30e8946fc2d71819ae2467e1b4a3a0776572ba1fab93fa95fd681e3209826ea4ec41e0cdd752b417e53356fffd31afc35e8b7c23e46b68c60bd862806ba43d57d1fb048b5ba045a2b204376bd24fe7b11077307f2a2ccff7f3704e&X-Goog-SignedHeaders=host&X-User=2931823730: HTTPSConnectionPool(host='storage.googleapis.com', port=443): Max retries exceeded with url: /wandb-production.appspot.com/2931823730-harbin-institute-of-technology/ltu-as/mlm5cp60/wandb-summary.json?X-Goog-Algorithm=GOOG4-RSA-SHA256&X-Goog-Credential=gorilla-files-url-signer-man%40wandb-production.iam.gserviceaccount.com%2F20250411%2Fauto%2Fstorage%2Fgoog4_request&X-Goog-Date=20250411T145115Z&X-Goog-Expires=86399&X-Goog-Signature=9df2087e11492ad178d77d9e9fab97630232b0a4f96a431148e4daf3a3ffb76f141a6acc698d2740403fe5d6787ed13f31ea70b94181a053e6e9bfe3b29b740f760a5a90f424f03e99c5b223fc30b089129e72948a62f1760c560b7f1eb6038148a7932d92a6c49a8613d4c7c04501f90b05b4395abd8bec4475d17d5fb0c4f0abdc39833cf913bd4da65c1c091140821a3269fc0d9ca812c0aaaceb66744bedabc6e1cc1b30e8946fc2d71819ae2467e1b4a3a0776572ba1fab93fa95fd681e3209826ea4ec41e0cdd752b417e53356fffd31afc35e8b7c23e46b68c60bd862806ba43d57d1fb048b5ba045a2b204376bd24fe7b11077307f2a2ccff7f3704e&X-Goog-SignedHeaders=host&X-User=2931823730 (Caused by NewConnectionError('<urllib3.connection.HTTPSConnection object at 0x7f464c196680>: Failed to establish a new connection: [Errno 101] Network is unreachable'))
2025-04-11 14:52:26,616 ERROR   wandb-upload_5:17843 [internal_api.py:upload_file():2558] upload_file request headers: {'User-Agent': 'python-requests/2.32.3', 'Accept-Encoding': 'gzip, deflate, br', 'Accept': '*/*', 'Connection': 'keep-alive', 'Content-Length': '27'}
2025-04-11 14:52:26,616 ERROR   wandb-upload_5:17843 [internal_api.py:upload_file():2560] upload_file response body: 
2025-04-11 14:52:27,861 ERROR   wandb-upload_2:17843 [internal_api.py:upload_file():2556] upload_file exception https://storage.googleapis.com/wandb-production.appspot.com/2931823730-harbin-institute-of-technology/ltu-as/mlm5cp60/requirements.txt?X-Goog-Algorithm=GOOG4-RSA-SHA256&X-Goog-Credential=gorilla-files-url-signer-man%40wandb-production.iam.gserviceaccount.com%2F20250411%2Fauto%2Fstorage%2Fgoog4_request&X-Goog-Date=20250411T145114Z&X-Goog-Expires=86399&X-Goog-Signature=acbd028386bc03d94948aaf65bc53bf77977ac5585e79ea0716ec007860ef39ea96f93094178bbe53396288150856563223a0e942bd376af8b161d4d58a6cf0e9dbea71fc7a9410c6f71628492009b7953de41033e7b38937eb708bfb6ada10c77ca0870f3d12be57f6d029ecfb8822e7dc5a62df88082610c8fc02b7aa861cee7e448378ac9d23208529f4a5e6344e6123aa73d657af02d72994735111ae518708f803b7f58dec8713f9eceb068ad7513a1b67628cc6fcf386e87c1a6dad3ca8abbf5fe3d3e33a074098ac226b071cc8aec87b300c8c753ac0940760332a70b2be12d9199bfeb835e45ee4c7766e2aaeab19a9da94cb9c52d45ad6563a0c27f&X-Goog-SignedHeaders=host&X-User=2931823730: HTTPSConnectionPool(host='storage.googleapis.com', port=443): Max retries exceeded with url: /wandb-production.appspot.com/2931823730-harbin-institute-of-technology/ltu-as/mlm5cp60/requirements.txt?X-Goog-Algorithm=GOOG4-RSA-SHA256&X-Goog-Credential=gorilla-files-url-signer-man%40wandb-production.iam.gserviceaccount.com%2F20250411%2Fauto%2Fstorage%2Fgoog4_request&X-Goog-Date=20250411T145114Z&X-Goog-Expires=86399&X-Goog-Signature=acbd028386bc03d94948aaf65bc53bf77977ac5585e79ea0716ec007860ef39ea96f93094178bbe53396288150856563223a0e942bd376af8b161d4d58a6cf0e9dbea71fc7a9410c6f71628492009b7953de41033e7b38937eb708bfb6ada10c77ca0870f3d12be57f6d029ecfb8822e7dc5a62df88082610c8fc02b7aa861cee7e448378ac9d23208529f4a5e6344e6123aa73d657af02d72994735111ae518708f803b7f58dec8713f9eceb068ad7513a1b67628cc6fcf386e87c1a6dad3ca8abbf5fe3d3e33a074098ac226b071cc8aec87b300c8c753ac0940760332a70b2be12d9199bfeb835e45ee4c7766e2aaeab19a9da94cb9c52d45ad6563a0c27f&X-Goog-SignedHeaders=host&X-User=2931823730 (Caused by NewConnectionError('<urllib3.connection.HTTPSConnection object at 0x7f464c195930>: Failed to establish a new connection: [Errno 101] Network is unreachable'))
2025-04-11 14:52:27,861 ERROR   wandb-upload_2:17843 [internal_api.py:upload_file():2558] upload_file request headers: {'User-Agent': 'python-requests/2.32.3', 'Accept-Encoding': 'gzip, deflate, br', 'Accept': '*/*', 'Connection': 'keep-alive', 'Content-Length': '4212'}
2025-04-11 14:52:27,861 ERROR   wandb-upload_2:17843 [internal_api.py:upload_file():2560] upload_file response body: 
2025-04-11 14:52:28,321 DEBUG   HandlerThread:17843 [handler.py:handle_request():146] handle_request: keepalive
2025-04-11 14:52:29,880 DEBUG   HandlerThread:17843 [handler.py:handle_request():146] handle_request: status_report
2025-04-11 14:52:30,012 ERROR   wandb-upload_4:17843 [internal_api.py:upload_file():2556] upload_file exception https://storage.googleapis.com/wandb-production.appspot.com/2931823730-harbin-institute-of-technology/ltu-as/mlm5cp60/output.log?X-Goog-Algorithm=GOOG4-RSA-SHA256&X-Goog-Credential=gorilla-files-url-signer-man%40wandb-production.iam.gserviceaccount.com%2F20250411%2Fauto%2Fstorage%2Fgoog4_request&X-Goog-Date=20250411T145115Z&X-Goog-Expires=86399&X-Goog-Signature=66829b877c42ca303b639780fff7bf88cbb60209259c7dc6d23083a84ea8a96b64d71ff0c30cfcd6586ba916252610aa15480efdf90421949aa85f951f9b619e468eda017b8e55a28c0dd8aa6f99210f3f778f8a86e71dc469c624bf57498806db03fe0da4046f07d2c7f46ebf78d08027dddd14f7a09c4e83545aa9466da1eb6bbcaa07656e8c5098eb49767523418a66675017d803a591dae803119383f64fd0a7046d0036e02ac698d4dae626392e5291c9836cbd2eaea947ec9227980072d7bf72433004230cc067028ae4702b9478433d2bac33dd2edcdea1ff05ace0e6798c3b76707a6db65d093dae199f68cfbd61847341fb284cad3d6d9cc1489b0e&X-Goog-SignedHeaders=host&X-User=2931823730: HTTPSConnectionPool(host='storage.googleapis.com', port=443): Max retries exceeded with url: /wandb-production.appspot.com/2931823730-harbin-institute-of-technology/ltu-as/mlm5cp60/output.log?X-Goog-Algorithm=GOOG4-RSA-SHA256&X-Goog-Credential=gorilla-files-url-signer-man%40wandb-production.iam.gserviceaccount.com%2F20250411%2Fauto%2Fstorage%2Fgoog4_request&X-Goog-Date=20250411T145115Z&X-Goog-Expires=86399&X-Goog-Signature=66829b877c42ca303b639780fff7bf88cbb60209259c7dc6d23083a84ea8a96b64d71ff0c30cfcd6586ba916252610aa15480efdf90421949aa85f951f9b619e468eda017b8e55a28c0dd8aa6f99210f3f778f8a86e71dc469c624bf57498806db03fe0da4046f07d2c7f46ebf78d08027dddd14f7a09c4e83545aa9466da1eb6bbcaa07656e8c5098eb49767523418a66675017d803a591dae803119383f64fd0a7046d0036e02ac698d4dae626392e5291c9836cbd2eaea947ec9227980072d7bf72433004230cc067028ae4702b9478433d2bac33dd2edcdea1ff05ace0e6798c3b76707a6db65d093dae199f68cfbd61847341fb284cad3d6d9cc1489b0e&X-Goog-SignedHeaders=host&X-User=2931823730 (Caused by NewConnectionError('<urllib3.connection.HTTPSConnection object at 0x7f462ce1e770>: Failed to establish a new connection: [Errno 101] Network is unreachable'))
2025-04-11 14:52:30,013 ERROR   wandb-upload_4:17843 [internal_api.py:upload_file():2558] upload_file request headers: {'User-Agent': 'python-requests/2.32.3', 'Accept-Encoding': 'gzip, deflate, br', 'Accept': '*/*', 'Connection': 'keep-alive', 'Content-Length': '4566'}
2025-04-11 14:52:30,013 ERROR   wandb-upload_4:17843 [internal_api.py:upload_file():2560] upload_file response body: 
2025-04-11 14:52:33,323 DEBUG   HandlerThread:17843 [handler.py:handle_request():146] handle_request: keepalive
2025-04-11 14:52:34,881 DEBUG   HandlerThread:17843 [handler.py:handle_request():146] handle_request: status_report
2025-04-11 14:52:38,325 DEBUG   HandlerThread:17843 [handler.py:handle_request():146] handle_request: keepalive
2025-04-11 14:52:39,882 DEBUG   HandlerThread:17843 [handler.py:handle_request():146] handle_request: status_report
2025-04-11 14:52:43,328 DEBUG   HandlerThread:17843 [handler.py:handle_request():146] handle_request: keepalive
2025-04-11 14:52:44,883 DEBUG   HandlerThread:17843 [handler.py:handle_request():146] handle_request: status_report
2025-04-11 14:52:48,330 DEBUG   HandlerThread:17843 [handler.py:handle_request():146] handle_request: keepalive
2025-04-11 14:52:49,884 DEBUG   HandlerThread:17843 [handler.py:handle_request():146] handle_request: status_report
2025-04-11 14:52:53,333 DEBUG   HandlerThread:17843 [handler.py:handle_request():146] handle_request: keepalive
2025-04-11 14:52:54,885 DEBUG   HandlerThread:17843 [handler.py:handle_request():146] handle_request: status_report
2025-04-11 14:52:58,335 DEBUG   HandlerThread:17843 [handler.py:handle_request():146] handle_request: keepalive
2025-04-11 14:52:59,887 DEBUG   HandlerThread:17843 [handler.py:handle_request():146] handle_request: status_report
2025-04-11 14:53:03,337 DEBUG   HandlerThread:17843 [handler.py:handle_request():146] handle_request: keepalive
2025-04-11 14:53:04,888 DEBUG   HandlerThread:17843 [handler.py:handle_request():146] handle_request: status_report
2025-04-11 14:53:08,339 DEBUG   HandlerThread:17843 [handler.py:handle_request():146] handle_request: keepalive
2025-04-11 14:53:09,889 DEBUG   HandlerThread:17843 [handler.py:handle_request():146] handle_request: status_report
2025-04-11 14:53:13,341 DEBUG   HandlerThread:17843 [handler.py:handle_request():146] handle_request: keepalive
2025-04-11 14:53:14,890 DEBUG   HandlerThread:17843 [handler.py:handle_request():146] handle_request: status_report
2025-04-11 14:53:18,343 DEBUG   HandlerThread:17843 [handler.py:handle_request():146] handle_request: keepalive
2025-04-11 14:53:19,891 DEBUG   HandlerThread:17843 [handler.py:handle_request():146] handle_request: status_report
2025-04-11 14:53:23,346 DEBUG   HandlerThread:17843 [handler.py:handle_request():146] handle_request: keepalive
2025-04-11 14:53:24,892 DEBUG   HandlerThread:17843 [handler.py:handle_request():146] handle_request: status_report
