2025-04-11 15:00:06,484 INFO    StreamThr :20960 [internal.py:wandb_internal():86] W&B internal server running at pid: 20960, started at: 2025-04-11 15:00:06.483740
2025-04-11 15:00:06,491 DEBUG   HandlerThread:20960 [handler.py:handle_request():146] handle_request: status
2025-04-11 15:00:06,492 INFO    WriterThread:20960 [datastore.py:open_for_write():85] open: /root/ltu-main/ltu-main/src/ltu_as/train_scripts/wandb/run-20250411_150006-p17gmulg/run-p17gmulg.wandb
2025-04-11 15:00:06,492 DEBUG   SenderThread:20960 [sender.py:send():380] send: header
2025-04-11 15:00:06,492 DEBUG   SenderThread:20960 [sender.py:send():380] send: run
2025-04-11 15:00:07,267 DEBUG   HandlerThread:20960 [handler.py:handle_request():146] handle_request: check_version
2025-04-11 15:00:07,366 INFO    SenderThread:20960 [dir_watcher.py:__init__():211] watching files in: /root/ltu-main/ltu-main/src/ltu_as/train_scripts/wandb/run-20250411_150006-p17gmulg/files
2025-04-11 15:00:07,366 INFO    SenderThread:20960 [sender.py:_start_run_threads():1122] run started: p17gmulg with start time 1744383606.483251
2025-04-11 15:00:07,366 DEBUG   SenderThread:20960 [sender.py:send_request():407] send_request: check_version
2025-04-11 15:00:08,012 DEBUG   HandlerThread:20960 [handler.py:handle_request():146] handle_request: run_start
2025-04-11 15:00:08,058 DEBUG   HandlerThread:20960 [system_info.py:__init__():32] System info init
2025-04-11 15:00:08,058 DEBUG   HandlerThread:20960 [system_info.py:__init__():47] System info init done
2025-04-11 15:00:08,058 INFO    HandlerThread:20960 [system_monitor.py:start():194] Starting system monitor
2025-04-11 15:00:08,058 INFO    SystemMonitor:20960 [system_monitor.py:_start():158] Starting system asset monitoring threads
2025-04-11 15:00:08,059 INFO    HandlerThread:20960 [system_monitor.py:probe():214] Collecting system info
2025-04-11 15:00:08,060 INFO    SystemMonitor:20960 [interfaces.py:start():190] Started cpu monitoring
2025-04-11 15:00:08,060 INFO    SystemMonitor:20960 [interfaces.py:start():190] Started disk monitoring
2025-04-11 15:00:08,061 INFO    SystemMonitor:20960 [interfaces.py:start():190] Started gpu monitoring
2025-04-11 15:00:08,062 INFO    SystemMonitor:20960 [interfaces.py:start():190] Started memory monitoring
2025-04-11 15:00:08,064 INFO    SystemMonitor:20960 [interfaces.py:start():190] Started network monitoring
2025-04-11 15:00:08,072 DEBUG   HandlerThread:20960 [system_info.py:probe():196] Probing system
2025-04-11 15:00:08,073 DEBUG   HandlerThread:20960 [gitlib.py:_init_repo():53] git repository is invalid
2025-04-11 15:00:08,073 DEBUG   HandlerThread:20960 [system_info.py:probe():244] Probing system done
2025-04-11 15:00:08,073 DEBUG   HandlerThread:20960 [system_monitor.py:probe():223] {'os': 'Linux-4.15.0-213-generic-x86_64-with-glibc2.27', 'python': '3.10.15', 'heartbeatAt': '2025-04-11T15:00:08.072330', 'startedAt': '2025-04-11T15:00:06.452427', 'docker': None, 'cuda': None, 'args': ('--base_model', '../../../pretrained_mdls/ltuas_long_noqa_a6.bin', '--data_path', '../../../openasqa/data/iemocap_preprocess_with_answers_updated.json', '--output_dir', '../exp/ltuas_ft_meld/', '--batch_size', '256', '--micro_batch_size', '1', '--num_epochs', '1', '--learning_rate', '2e-4', '--cutoff_len', '100', '--val_set_size', '0', '--lora_r', '8', '--lora_alpha', '16', '--lora_dropout', '0.05', '--lora_target_modules', '[q_proj,v_proj]', '--group_by_length', '--save_steps', '30', '--trainable_params', 'all'), 'state': 'running', 'program': '/root/ltu-main/ltu-main/src/ltu_as/train_scripts/../finetune_low_resource.py', 'codePathLocal': None, 'host': 'ubuntu', 'username': 'root', 'executable': '/root/anaconda3/envs/venv_ltu/bin/python', 'cpu_count': 4, 'cpu_count_logical': 4, 'cpu_freq': {'current': 2294.598, 'min': 0.0, 'max': 0.0}, 'cpu_freq_per_core': [{'current': 2294.598, 'min': 0.0, 'max': 0.0}, {'current': 2294.598, 'min': 0.0, 'max': 0.0}, {'current': 2294.598, 'min': 0.0, 'max': 0.0}, {'current': 2294.598, 'min': 0.0, 'max': 0.0}], 'disk': {'/': {'total': 499.9882621765137, 'used': 333.5992012023926}}, 'gpu': 'NVIDIA A100-PCIE-40GB', 'gpu_count': 1, 'gpu_devices': [{'name': 'NVIDIA A100-PCIE-40GB', 'memory_total': 42949672960}], 'memory': {'total': 19.60204315185547}}
2025-04-11 15:00:08,073 INFO    HandlerThread:20960 [system_monitor.py:probe():224] Finished collecting system info
2025-04-11 15:00:08,073 INFO    HandlerThread:20960 [system_monitor.py:probe():227] Publishing system info
2025-04-11 15:00:08,073 DEBUG   HandlerThread:20960 [system_info.py:_save_pip():52] Saving list of pip packages installed into the current environment
2025-04-11 15:00:08,073 DEBUG   HandlerThread:20960 [system_info.py:_save_pip():68] Saving pip packages done
2025-04-11 15:00:08,073 DEBUG   HandlerThread:20960 [system_info.py:_save_conda():75] Saving list of conda packages installed into the current environment
2025-04-11 15:00:08,370 INFO    Thread-12 :20960 [dir_watcher.py:_on_file_created():271] file/dir created: /root/ltu-main/ltu-main/src/ltu_as/train_scripts/wandb/run-20250411_150006-p17gmulg/files/requirements.txt
2025-04-11 15:00:08,370 INFO    Thread-12 :20960 [dir_watcher.py:_on_file_created():271] file/dir created: /root/ltu-main/ltu-main/src/ltu_as/train_scripts/wandb/run-20250411_150006-p17gmulg/files/conda-environment.yaml
2025-04-11 15:00:26,374 INFO    Thread-12 :20960 [dir_watcher.py:_on_file_modified():288] file/dir modified: /root/ltu-main/ltu-main/src/ltu_as/train_scripts/wandb/run-20250411_150006-p17gmulg/files/conda-environment.yaml
2025-04-11 15:00:26,598 DEBUG   HandlerThread:20960 [system_info.py:_save_conda():87] Saving conda packages done
2025-04-11 15:00:26,599 INFO    HandlerThread:20960 [system_monitor.py:probe():229] Finished publishing system info
2025-04-11 15:00:26,626 DEBUG   HandlerThread:20960 [handler.py:handle_request():146] handle_request: status_report
2025-04-11 15:00:26,626 DEBUG   HandlerThread:20960 [handler.py:handle_request():146] handle_request: keepalive
2025-04-11 15:00:26,626 DEBUG   HandlerThread:20960 [handler.py:handle_request():146] handle_request: status_report
2025-04-11 15:00:26,626 DEBUG   HandlerThread:20960 [handler.py:handle_request():146] handle_request: keepalive
2025-04-11 15:00:26,626 DEBUG   HandlerThread:20960 [handler.py:handle_request():146] handle_request: status_report
2025-04-11 15:00:26,626 DEBUG   HandlerThread:20960 [handler.py:handle_request():146] handle_request: keepalive
2025-04-11 15:00:26,628 DEBUG   SenderThread:20960 [sender.py:send():380] send: files
2025-04-11 15:00:26,628 INFO    SenderThread:20960 [sender.py:_save_file():1378] saving file wandb-metadata.json with policy now
2025-04-11 15:00:26,636 DEBUG   HandlerThread:20960 [handler.py:handle_request():146] handle_request: stop_status
2025-04-11 15:00:26,636 DEBUG   SenderThread:20960 [sender.py:send_request():407] send_request: stop_status
2025-04-11 15:00:26,648 DEBUG   HandlerThread:20960 [handler.py:handle_request():146] handle_request: internal_messages
2025-04-11 15:00:27,138 DEBUG   SenderThread:20960 [sender.py:send():380] send: telemetry
2025-04-11 15:00:27,139 DEBUG   SenderThread:20960 [sender.py:send():380] send: config
2025-04-11 15:00:27,140 DEBUG   SenderThread:20960 [sender.py:send():380] send: metric
2025-04-11 15:00:27,140 DEBUG   SenderThread:20960 [sender.py:send():380] send: telemetry
2025-04-11 15:00:27,141 DEBUG   SenderThread:20960 [sender.py:send():380] send: metric
2025-04-11 15:00:27,141 WARNING SenderThread:20960 [sender.py:send_metric():1329] Seen metric with glob (shouldn't happen)
2025-04-11 15:00:27,141 DEBUG   HandlerThread:20960 [handler.py:handle_request():146] handle_request: status_report
2025-04-11 15:00:27,173 ERROR   wandb-upload_0:20960 [internal_api.py:upload_file():2556] upload_file exception https://storage.googleapis.com/wandb-production.appspot.com/2931823730-harbin-institute-of-technology/ltu-as/p17gmulg/wandb-metadata.json?X-Goog-Algorithm=GOOG4-RSA-SHA256&X-Goog-Credential=gorilla-files-url-signer-man%40wandb-production.iam.gserviceaccount.com%2F20250411%2Fauto%2Fstorage%2Fgoog4_request&X-Goog-Date=20250411T150027Z&X-Goog-Expires=86399&X-Goog-Signature=0fca1f09c246b35184e651f2690bb2d36dc49dab5fec1f973e2c65e5bfefebbfd202f9b4caa1608b01be21ef52649952919cd92fe2c7d0cbaa7d85e1dec4688e3d4bce047b086e7704caa70c0e7cd600a6fa32524d987c1e285f028227ad40a92e888252a5c330544b44a0eab8be632c7210336d5e7ecaf9b4c27dfefc250b2e5f8a04f0124c65480524e79e4ebfbf7f17921a78390961ea9ff85a200da5de126487ab0284a7f24abf28c4a11a45df9fe33a42121f13be1d8e478aaebd8536a5f732611162ce46d0392669452a89459b76adcc2538897ad8710d676cf8b168232f3798549d04eb53b7c89783fcdaea6b7933abd4ab75eccaac8647b7588544b8&X-Goog-SignedHeaders=host&X-User=2931823730: HTTPSConnectionPool(host='storage.googleapis.com', port=443): Max retries exceeded with url: /wandb-production.appspot.com/2931823730-harbin-institute-of-technology/ltu-as/p17gmulg/wandb-metadata.json?X-Goog-Algorithm=GOOG4-RSA-SHA256&X-Goog-Credential=gorilla-files-url-signer-man%40wandb-production.iam.gserviceaccount.com%2F20250411%2Fauto%2Fstorage%2Fgoog4_request&X-Goog-Date=20250411T150027Z&X-Goog-Expires=86399&X-Goog-Signature=0fca1f09c246b35184e651f2690bb2d36dc49dab5fec1f973e2c65e5bfefebbfd202f9b4caa1608b01be21ef52649952919cd92fe2c7d0cbaa7d85e1dec4688e3d4bce047b086e7704caa70c0e7cd600a6fa32524d987c1e285f028227ad40a92e888252a5c330544b44a0eab8be632c7210336d5e7ecaf9b4c27dfefc250b2e5f8a04f0124c65480524e79e4ebfbf7f17921a78390961ea9ff85a200da5de126487ab0284a7f24abf28c4a11a45df9fe33a42121f13be1d8e478aaebd8536a5f732611162ce46d0392669452a89459b76adcc2538897ad8710d676cf8b168232f3798549d04eb53b7c89783fcdaea6b7933abd4ab75eccaac8647b7588544b8&X-Goog-SignedHeaders=host&X-User=2931823730 (Caused by NewConnectionError('<urllib3.connection.HTTPSConnection object at 0x7f704e1a8dc0>: Failed to establish a new connection: [Errno 101] Network is unreachable'))
2025-04-11 15:00:27,173 ERROR   wandb-upload_0:20960 [internal_api.py:upload_file():2558] upload_file request headers: {'User-Agent': 'python-requests/2.32.3', 'Accept-Encoding': 'gzip, deflate, br', 'Accept': '*/*', 'Connection': 'keep-alive', 'Content-Length': '2212'}
2025-04-11 15:00:27,173 ERROR   wandb-upload_0:20960 [internal_api.py:upload_file():2560] upload_file response body: 
2025-04-11 15:00:27,375 INFO    Thread-12 :20960 [dir_watcher.py:_on_file_created():271] file/dir created: /root/ltu-main/ltu-main/src/ltu_as/train_scripts/wandb/run-20250411_150006-p17gmulg/files/output.log
2025-04-11 15:00:27,375 INFO    Thread-12 :20960 [dir_watcher.py:_on_file_created():271] file/dir created: /root/ltu-main/ltu-main/src/ltu_as/train_scripts/wandb/run-20250411_150006-p17gmulg/files/wandb-metadata.json
2025-04-11 15:00:28,336 ERROR   wandb-upload_0:20960 [internal_api.py:upload_file():2556] upload_file exception https://storage.googleapis.com/wandb-production.appspot.com/2931823730-harbin-institute-of-technology/ltu-as/p17gmulg/wandb-metadata.json?X-Goog-Algorithm=GOOG4-RSA-SHA256&X-Goog-Credential=gorilla-files-url-signer-man%40wandb-production.iam.gserviceaccount.com%2F20250411%2Fauto%2Fstorage%2Fgoog4_request&X-Goog-Date=20250411T150027Z&X-Goog-Expires=86399&X-Goog-Signature=0fca1f09c246b35184e651f2690bb2d36dc49dab5fec1f973e2c65e5bfefebbfd202f9b4caa1608b01be21ef52649952919cd92fe2c7d0cbaa7d85e1dec4688e3d4bce047b086e7704caa70c0e7cd600a6fa32524d987c1e285f028227ad40a92e888252a5c330544b44a0eab8be632c7210336d5e7ecaf9b4c27dfefc250b2e5f8a04f0124c65480524e79e4ebfbf7f17921a78390961ea9ff85a200da5de126487ab0284a7f24abf28c4a11a45df9fe33a42121f13be1d8e478aaebd8536a5f732611162ce46d0392669452a89459b76adcc2538897ad8710d676cf8b168232f3798549d04eb53b7c89783fcdaea6b7933abd4ab75eccaac8647b7588544b8&X-Goog-SignedHeaders=host&X-User=2931823730: HTTPSConnectionPool(host='storage.googleapis.com', port=443): Max retries exceeded with url: /wandb-production.appspot.com/2931823730-harbin-institute-of-technology/ltu-as/p17gmulg/wandb-metadata.json?X-Goog-Algorithm=GOOG4-RSA-SHA256&X-Goog-Credential=gorilla-files-url-signer-man%40wandb-production.iam.gserviceaccount.com%2F20250411%2Fauto%2Fstorage%2Fgoog4_request&X-Goog-Date=20250411T150027Z&X-Goog-Expires=86399&X-Goog-Signature=0fca1f09c246b35184e651f2690bb2d36dc49dab5fec1f973e2c65e5bfefebbfd202f9b4caa1608b01be21ef52649952919cd92fe2c7d0cbaa7d85e1dec4688e3d4bce047b086e7704caa70c0e7cd600a6fa32524d987c1e285f028227ad40a92e888252a5c330544b44a0eab8be632c7210336d5e7ecaf9b4c27dfefc250b2e5f8a04f0124c65480524e79e4ebfbf7f17921a78390961ea9ff85a200da5de126487ab0284a7f24abf28c4a11a45df9fe33a42121f13be1d8e478aaebd8536a5f732611162ce46d0392669452a89459b76adcc2538897ad8710d676cf8b168232f3798549d04eb53b7c89783fcdaea6b7933abd4ab75eccaac8647b7588544b8&X-Goog-SignedHeaders=host&X-User=2931823730 (Caused by NewConnectionError('<urllib3.connection.HTTPSConnection object at 0x7f704e1aa260>: Failed to establish a new connection: [Errno 101] Network is unreachable'))
2025-04-11 15:00:28,337 ERROR   wandb-upload_0:20960 [internal_api.py:upload_file():2558] upload_file request headers: {'User-Agent': 'python-requests/2.32.3', 'Accept-Encoding': 'gzip, deflate, br', 'Accept': '*/*', 'Connection': 'keep-alive', 'Content-Length': '2212'}
2025-04-11 15:00:28,337 ERROR   wandb-upload_0:20960 [internal_api.py:upload_file():2560] upload_file response body: 
2025-04-11 15:00:29,376 INFO    Thread-12 :20960 [dir_watcher.py:_on_file_modified():288] file/dir modified: /root/ltu-main/ltu-main/src/ltu_as/train_scripts/wandb/run-20250411_150006-p17gmulg/files/output.log
2025-04-11 15:00:30,439 ERROR   wandb-upload_0:20960 [internal_api.py:upload_file():2556] upload_file exception https://storage.googleapis.com/wandb-production.appspot.com/2931823730-harbin-institute-of-technology/ltu-as/p17gmulg/wandb-metadata.json?X-Goog-Algorithm=GOOG4-RSA-SHA256&X-Goog-Credential=gorilla-files-url-signer-man%40wandb-production.iam.gserviceaccount.com%2F20250411%2Fauto%2Fstorage%2Fgoog4_request&X-Goog-Date=20250411T150027Z&X-Goog-Expires=86399&X-Goog-Signature=0fca1f09c246b35184e651f2690bb2d36dc49dab5fec1f973e2c65e5bfefebbfd202f9b4caa1608b01be21ef52649952919cd92fe2c7d0cbaa7d85e1dec4688e3d4bce047b086e7704caa70c0e7cd600a6fa32524d987c1e285f028227ad40a92e888252a5c330544b44a0eab8be632c7210336d5e7ecaf9b4c27dfefc250b2e5f8a04f0124c65480524e79e4ebfbf7f17921a78390961ea9ff85a200da5de126487ab0284a7f24abf28c4a11a45df9fe33a42121f13be1d8e478aaebd8536a5f732611162ce46d0392669452a89459b76adcc2538897ad8710d676cf8b168232f3798549d04eb53b7c89783fcdaea6b7933abd4ab75eccaac8647b7588544b8&X-Goog-SignedHeaders=host&X-User=2931823730: HTTPSConnectionPool(host='storage.googleapis.com', port=443): Max retries exceeded with url: /wandb-production.appspot.com/2931823730-harbin-institute-of-technology/ltu-as/p17gmulg/wandb-metadata.json?X-Goog-Algorithm=GOOG4-RSA-SHA256&X-Goog-Credential=gorilla-files-url-signer-man%40wandb-production.iam.gserviceaccount.com%2F20250411%2Fauto%2Fstorage%2Fgoog4_request&X-Goog-Date=20250411T150027Z&X-Goog-Expires=86399&X-Goog-Signature=0fca1f09c246b35184e651f2690bb2d36dc49dab5fec1f973e2c65e5bfefebbfd202f9b4caa1608b01be21ef52649952919cd92fe2c7d0cbaa7d85e1dec4688e3d4bce047b086e7704caa70c0e7cd600a6fa32524d987c1e285f028227ad40a92e888252a5c330544b44a0eab8be632c7210336d5e7ecaf9b4c27dfefc250b2e5f8a04f0124c65480524e79e4ebfbf7f17921a78390961ea9ff85a200da5de126487ab0284a7f24abf28c4a11a45df9fe33a42121f13be1d8e478aaebd8536a5f732611162ce46d0392669452a89459b76adcc2538897ad8710d676cf8b168232f3798549d04eb53b7c89783fcdaea6b7933abd4ab75eccaac8647b7588544b8&X-Goog-SignedHeaders=host&X-User=2931823730 (Caused by NewConnectionError('<urllib3.connection.HTTPSConnection object at 0x7f704e1aa650>: Failed to establish a new connection: [Errno 101] Network is unreachable'))
2025-04-11 15:00:30,439 ERROR   wandb-upload_0:20960 [internal_api.py:upload_file():2558] upload_file request headers: {'User-Agent': 'python-requests/2.32.3', 'Accept-Encoding': 'gzip, deflate, br', 'Accept': '*/*', 'Connection': 'keep-alive', 'Content-Length': '2212'}
2025-04-11 15:00:30,439 ERROR   wandb-upload_0:20960 [internal_api.py:upload_file():2560] upload_file response body: 
2025-04-11 15:00:30,440 INFO    wandb-upload_0:20960 [retry.py:__call__():172] Retry attempt failed:
Traceback (most recent call last):
  File "/root/anaconda3/envs/venv_ltu/lib/python3.10/site-packages/urllib3/connection.py", line 198, in _new_conn
    sock = connection.create_connection(
  File "/root/anaconda3/envs/venv_ltu/lib/python3.10/site-packages/urllib3/util/connection.py", line 85, in create_connection
    raise err
  File "/root/anaconda3/envs/venv_ltu/lib/python3.10/site-packages/urllib3/util/connection.py", line 73, in create_connection
    sock.connect(sa)
OSError: [Errno 101] Network is unreachable

The above exception was the direct cause of the following exception:

Traceback (most recent call last):
  File "/root/anaconda3/envs/venv_ltu/lib/python3.10/site-packages/urllib3/connectionpool.py", line 793, in urlopen
    response = self._make_request(
  File "/root/anaconda3/envs/venv_ltu/lib/python3.10/site-packages/urllib3/connectionpool.py", line 491, in _make_request
    raise new_e
  File "/root/anaconda3/envs/venv_ltu/lib/python3.10/site-packages/urllib3/connectionpool.py", line 467, in _make_request
    self._validate_conn(conn)
  File "/root/anaconda3/envs/venv_ltu/lib/python3.10/site-packages/urllib3/connectionpool.py", line 1099, in _validate_conn
    conn.connect()
  File "/root/anaconda3/envs/venv_ltu/lib/python3.10/site-packages/urllib3/connection.py", line 616, in connect
    self.sock = sock = self._new_conn()
  File "/root/anaconda3/envs/venv_ltu/lib/python3.10/site-packages/urllib3/connection.py", line 213, in _new_conn
    raise NewConnectionError(
urllib3.exceptions.NewConnectionError: <urllib3.connection.HTTPSConnection object at 0x7f704e1aa650>: Failed to establish a new connection: [Errno 101] Network is unreachable

The above exception was the direct cause of the following exception:

Traceback (most recent call last):
  File "/root/anaconda3/envs/venv_ltu/lib/python3.10/site-packages/requests/adapters.py", line 667, in send
    resp = conn.urlopen(
  File "/root/anaconda3/envs/venv_ltu/lib/python3.10/site-packages/urllib3/connectionpool.py", line 847, in urlopen
    retries = retries.increment(
  File "/root/anaconda3/envs/venv_ltu/lib/python3.10/site-packages/urllib3/util/retry.py", line 515, in increment
    raise MaxRetryError(_pool, url, reason) from reason  # type: ignore[arg-type]
urllib3.exceptions.MaxRetryError: HTTPSConnectionPool(host='storage.googleapis.com', port=443): Max retries exceeded with url: /wandb-production.appspot.com/2931823730-harbin-institute-of-technology/ltu-as/p17gmulg/wandb-metadata.json?X-Goog-Algorithm=GOOG4-RSA-SHA256&X-Goog-Credential=gorilla-files-url-signer-man%40wandb-production.iam.gserviceaccount.com%2F20250411%2Fauto%2Fstorage%2Fgoog4_request&X-Goog-Date=20250411T150027Z&X-Goog-Expires=86399&X-Goog-Signature=0fca1f09c246b35184e651f2690bb2d36dc49dab5fec1f973e2c65e5bfefebbfd202f9b4caa1608b01be21ef52649952919cd92fe2c7d0cbaa7d85e1dec4688e3d4bce047b086e7704caa70c0e7cd600a6fa32524d987c1e285f028227ad40a92e888252a5c330544b44a0eab8be632c7210336d5e7ecaf9b4c27dfefc250b2e5f8a04f0124c65480524e79e4ebfbf7f17921a78390961ea9ff85a200da5de126487ab0284a7f24abf28c4a11a45df9fe33a42121f13be1d8e478aaebd8536a5f732611162ce46d0392669452a89459b76adcc2538897ad8710d676cf8b168232f3798549d04eb53b7c89783fcdaea6b7933abd4ab75eccaac8647b7588544b8&X-Goog-SignedHeaders=host&X-User=2931823730 (Caused by NewConnectionError('<urllib3.connection.HTTPSConnection object at 0x7f704e1aa650>: Failed to establish a new connection: [Errno 101] Network is unreachable'))

During handling of the above exception, another exception occurred:

Traceback (most recent call last):
  File "/root/anaconda3/envs/venv_ltu/lib/python3.10/site-packages/wandb/sdk/internal/internal_api.py", line 2549, in upload_file
    response = self._upload_file_session.put(
  File "/root/anaconda3/envs/venv_ltu/lib/python3.10/site-packages/requests/sessions.py", line 649, in put
    return self.request("PUT", url, data=data, **kwargs)
  File "/root/anaconda3/envs/venv_ltu/lib/python3.10/site-packages/requests/sessions.py", line 589, in request
    resp = self.send(prep, **send_kwargs)
  File "/root/anaconda3/envs/venv_ltu/lib/python3.10/site-packages/requests/sessions.py", line 703, in send
    r = adapter.send(request, **kwargs)
  File "/root/anaconda3/envs/venv_ltu/lib/python3.10/site-packages/requests/adapters.py", line 700, in send
    raise ConnectionError(e, request=request)
requests.exceptions.ConnectionError: HTTPSConnectionPool(host='storage.googleapis.com', port=443): Max retries exceeded with url: /wandb-production.appspot.com/2931823730-harbin-institute-of-technology/ltu-as/p17gmulg/wandb-metadata.json?X-Goog-Algorithm=GOOG4-RSA-SHA256&X-Goog-Credential=gorilla-files-url-signer-man%40wandb-production.iam.gserviceaccount.com%2F20250411%2Fauto%2Fstorage%2Fgoog4_request&X-Goog-Date=20250411T150027Z&X-Goog-Expires=86399&X-Goog-Signature=0fca1f09c246b35184e651f2690bb2d36dc49dab5fec1f973e2c65e5bfefebbfd202f9b4caa1608b01be21ef52649952919cd92fe2c7d0cbaa7d85e1dec4688e3d4bce047b086e7704caa70c0e7cd600a6fa32524d987c1e285f028227ad40a92e888252a5c330544b44a0eab8be632c7210336d5e7ecaf9b4c27dfefc250b2e5f8a04f0124c65480524e79e4ebfbf7f17921a78390961ea9ff85a200da5de126487ab0284a7f24abf28c4a11a45df9fe33a42121f13be1d8e478aaebd8536a5f732611162ce46d0392669452a89459b76adcc2538897ad8710d676cf8b168232f3798549d04eb53b7c89783fcdaea6b7933abd4ab75eccaac8647b7588544b8&X-Goog-SignedHeaders=host&X-User=2931823730 (Caused by NewConnectionError('<urllib3.connection.HTTPSConnection object at 0x7f704e1aa650>: Failed to establish a new connection: [Errno 101] Network is unreachable'))

During handling of the above exception, another exception occurred:

Traceback (most recent call last):
  File "/root/anaconda3/envs/venv_ltu/lib/python3.10/site-packages/wandb/sdk/lib/retry.py", line 131, in __call__
    result = self._call_fn(*args, **kwargs)
  File "/root/anaconda3/envs/venv_ltu/lib/python3.10/site-packages/wandb/sdk/internal/internal_api.py", line 2580, in upload_file
    raise _e.with_traceback(sys.exc_info()[2])
  File "/root/anaconda3/envs/venv_ltu/lib/python3.10/site-packages/wandb/sdk/internal/internal_api.py", line 2549, in upload_file
    response = self._upload_file_session.put(
  File "/root/anaconda3/envs/venv_ltu/lib/python3.10/site-packages/requests/sessions.py", line 649, in put
    return self.request("PUT", url, data=data, **kwargs)
  File "/root/anaconda3/envs/venv_ltu/lib/python3.10/site-packages/requests/sessions.py", line 589, in request
    resp = self.send(prep, **send_kwargs)
  File "/root/anaconda3/envs/venv_ltu/lib/python3.10/site-packages/requests/sessions.py", line 703, in send
    r = adapter.send(request, **kwargs)
  File "/root/anaconda3/envs/venv_ltu/lib/python3.10/site-packages/requests/adapters.py", line 700, in send
    raise ConnectionError(e, request=request)
wandb.sdk.lib.retry.TransientError: None
2025-04-11 15:00:32,143 DEBUG   HandlerThread:20960 [handler.py:handle_request():146] handle_request: status_report
2025-04-11 15:00:34,846 ERROR   wandb-upload_0:20960 [internal_api.py:upload_file():2556] upload_file exception https://storage.googleapis.com/wandb-production.appspot.com/2931823730-harbin-institute-of-technology/ltu-as/p17gmulg/wandb-metadata.json?X-Goog-Algorithm=GOOG4-RSA-SHA256&X-Goog-Credential=gorilla-files-url-signer-man%40wandb-production.iam.gserviceaccount.com%2F20250411%2Fauto%2Fstorage%2Fgoog4_request&X-Goog-Date=20250411T150027Z&X-Goog-Expires=86399&X-Goog-Signature=0fca1f09c246b35184e651f2690bb2d36dc49dab5fec1f973e2c65e5bfefebbfd202f9b4caa1608b01be21ef52649952919cd92fe2c7d0cbaa7d85e1dec4688e3d4bce047b086e7704caa70c0e7cd600a6fa32524d987c1e285f028227ad40a92e888252a5c330544b44a0eab8be632c7210336d5e7ecaf9b4c27dfefc250b2e5f8a04f0124c65480524e79e4ebfbf7f17921a78390961ea9ff85a200da5de126487ab0284a7f24abf28c4a11a45df9fe33a42121f13be1d8e478aaebd8536a5f732611162ce46d0392669452a89459b76adcc2538897ad8710d676cf8b168232f3798549d04eb53b7c89783fcdaea6b7933abd4ab75eccaac8647b7588544b8&X-Goog-SignedHeaders=host&X-User=2931823730: HTTPSConnectionPool(host='storage.googleapis.com', port=443): Max retries exceeded with url: /wandb-production.appspot.com/2931823730-harbin-institute-of-technology/ltu-as/p17gmulg/wandb-metadata.json?X-Goog-Algorithm=GOOG4-RSA-SHA256&X-Goog-Credential=gorilla-files-url-signer-man%40wandb-production.iam.gserviceaccount.com%2F20250411%2Fauto%2Fstorage%2Fgoog4_request&X-Goog-Date=20250411T150027Z&X-Goog-Expires=86399&X-Goog-Signature=0fca1f09c246b35184e651f2690bb2d36dc49dab5fec1f973e2c65e5bfefebbfd202f9b4caa1608b01be21ef52649952919cd92fe2c7d0cbaa7d85e1dec4688e3d4bce047b086e7704caa70c0e7cd600a6fa32524d987c1e285f028227ad40a92e888252a5c330544b44a0eab8be632c7210336d5e7ecaf9b4c27dfefc250b2e5f8a04f0124c65480524e79e4ebfbf7f17921a78390961ea9ff85a200da5de126487ab0284a7f24abf28c4a11a45df9fe33a42121f13be1d8e478aaebd8536a5f732611162ce46d0392669452a89459b76adcc2538897ad8710d676cf8b168232f3798549d04eb53b7c89783fcdaea6b7933abd4ab75eccaac8647b7588544b8&X-Goog-SignedHeaders=host&X-User=2931823730 (Caused by NewConnectionError('<urllib3.connection.HTTPSConnection object at 0x7f704e1aaa70>: Failed to establish a new connection: [Errno 101] Network is unreachable'))
2025-04-11 15:00:34,846 ERROR   wandb-upload_0:20960 [internal_api.py:upload_file():2558] upload_file request headers: {'User-Agent': 'python-requests/2.32.3', 'Accept-Encoding': 'gzip, deflate, br', 'Accept': '*/*', 'Connection': 'keep-alive', 'Content-Length': '2212'}
2025-04-11 15:00:34,846 ERROR   wandb-upload_0:20960 [internal_api.py:upload_file():2560] upload_file response body: 
2025-04-11 15:00:37,149 DEBUG   HandlerThread:20960 [handler.py:handle_request():146] handle_request: status_report
2025-04-11 15:00:38,379 INFO    Thread-12 :20960 [dir_watcher.py:_on_file_modified():288] file/dir modified: /root/ltu-main/ltu-main/src/ltu_as/train_scripts/wandb/run-20250411_150006-p17gmulg/files/config.yaml
2025-04-11 15:00:41,512 DEBUG   SenderThread:20960 [sender.py:send():380] send: exit
2025-04-11 15:00:41,512 INFO    SenderThread:20960 [sender.py:send_exit():585] handling exit code: 1
2025-04-11 15:00:41,513 INFO    SenderThread:20960 [sender.py:send_exit():587] handling runtime: 33
2025-04-11 15:00:41,515 INFO    SenderThread:20960 [sender.py:_save_file():1378] saving file wandb-summary.json with policy end
2025-04-11 15:00:41,515 INFO    SenderThread:20960 [sender.py:send_exit():593] send defer
2025-04-11 15:00:41,516 DEBUG   HandlerThread:20960 [handler.py:handle_request():146] handle_request: defer
2025-04-11 15:00:41,516 INFO    HandlerThread:20960 [handler.py:handle_request_defer():172] handle defer: 0
2025-04-11 15:00:41,516 DEBUG   SenderThread:20960 [sender.py:send_request():407] send_request: defer
2025-04-11 15:00:41,516 INFO    SenderThread:20960 [sender.py:send_request_defer():609] handle sender defer: 0
2025-04-11 15:00:41,516 INFO    SenderThread:20960 [sender.py:transition_state():613] send defer: 1
2025-04-11 15:00:41,516 DEBUG   HandlerThread:20960 [handler.py:handle_request():146] handle_request: defer
2025-04-11 15:00:41,516 INFO    HandlerThread:20960 [handler.py:handle_request_defer():172] handle defer: 1
2025-04-11 15:00:41,517 DEBUG   SenderThread:20960 [sender.py:send_request():407] send_request: defer
2025-04-11 15:00:41,517 INFO    SenderThread:20960 [sender.py:send_request_defer():609] handle sender defer: 1
2025-04-11 15:00:41,517 INFO    SenderThread:20960 [sender.py:transition_state():613] send defer: 2
2025-04-11 15:00:41,517 DEBUG   HandlerThread:20960 [handler.py:handle_request():146] handle_request: defer
2025-04-11 15:00:41,517 INFO    HandlerThread:20960 [handler.py:handle_request_defer():172] handle defer: 2
2025-04-11 15:00:41,517 INFO    HandlerThread:20960 [system_monitor.py:finish():203] Stopping system monitor
2025-04-11 15:00:41,517 DEBUG   SystemMonitor:20960 [system_monitor.py:_start():172] Starting system metrics aggregation loop
2025-04-11 15:00:41,517 DEBUG   SystemMonitor:20960 [system_monitor.py:_start():179] Finished system metrics aggregation loop
2025-04-11 15:00:41,518 DEBUG   SystemMonitor:20960 [system_monitor.py:_start():183] Publishing last batch of metrics
2025-04-11 15:00:41,517 INFO    HandlerThread:20960 [interfaces.py:finish():202] Joined cpu monitor
2025-04-11 15:00:41,528 INFO    HandlerThread:20960 [interfaces.py:finish():202] Joined disk monitor
2025-04-11 15:00:41,537 INFO    HandlerThread:20960 [interfaces.py:finish():202] Joined gpu monitor
2025-04-11 15:00:41,537 INFO    HandlerThread:20960 [interfaces.py:finish():202] Joined memory monitor
2025-04-11 15:00:41,537 INFO    HandlerThread:20960 [interfaces.py:finish():202] Joined network monitor
2025-04-11 15:00:41,538 DEBUG   SenderThread:20960 [sender.py:send_request():407] send_request: defer
2025-04-11 15:00:41,538 INFO    SenderThread:20960 [sender.py:send_request_defer():609] handle sender defer: 2
2025-04-11 15:00:41,538 INFO    SenderThread:20960 [sender.py:transition_state():613] send defer: 3
2025-04-11 15:00:41,538 DEBUG   SenderThread:20960 [sender.py:send():380] send: stats
2025-04-11 15:00:41,539 DEBUG   HandlerThread:20960 [handler.py:handle_request():146] handle_request: defer
2025-04-11 15:00:41,539 INFO    HandlerThread:20960 [handler.py:handle_request_defer():172] handle defer: 3
2025-04-11 15:00:41,539 DEBUG   SenderThread:20960 [sender.py:send_request():407] send_request: defer
2025-04-11 15:00:41,539 INFO    SenderThread:20960 [sender.py:send_request_defer():609] handle sender defer: 3
2025-04-11 15:00:41,539 INFO    SenderThread:20960 [sender.py:transition_state():613] send defer: 4
2025-04-11 15:00:41,539 DEBUG   HandlerThread:20960 [handler.py:handle_request():146] handle_request: defer
2025-04-11 15:00:41,539 INFO    HandlerThread:20960 [handler.py:handle_request_defer():172] handle defer: 4
2025-04-11 15:00:41,540 DEBUG   SenderThread:20960 [sender.py:send_request():407] send_request: defer
2025-04-11 15:00:41,540 INFO    SenderThread:20960 [sender.py:send_request_defer():609] handle sender defer: 4
2025-04-11 15:00:41,540 INFO    SenderThread:20960 [sender.py:transition_state():613] send defer: 5
2025-04-11 15:00:41,540 DEBUG   HandlerThread:20960 [handler.py:handle_request():146] handle_request: defer
2025-04-11 15:00:41,540 INFO    HandlerThread:20960 [handler.py:handle_request_defer():172] handle defer: 5
2025-04-11 15:00:41,540 DEBUG   SenderThread:20960 [sender.py:send():380] send: summary
2025-04-11 15:00:41,681 INFO    SenderThread:20960 [sender.py:_save_file():1378] saving file wandb-summary.json with policy end
2025-04-11 15:00:41,681 DEBUG   SenderThread:20960 [sender.py:send_request():407] send_request: defer
2025-04-11 15:00:41,682 INFO    SenderThread:20960 [sender.py:send_request_defer():609] handle sender defer: 5
2025-04-11 15:00:41,682 INFO    SenderThread:20960 [sender.py:transition_state():613] send defer: 6
2025-04-11 15:00:41,682 DEBUG   HandlerThread:20960 [handler.py:handle_request():146] handle_request: defer
2025-04-11 15:00:41,682 INFO    HandlerThread:20960 [handler.py:handle_request_defer():172] handle defer: 6
2025-04-11 15:00:41,683 DEBUG   SenderThread:20960 [sender.py:send_request():407] send_request: defer
2025-04-11 15:00:41,683 INFO    SenderThread:20960 [sender.py:send_request_defer():609] handle sender defer: 6
2025-04-11 15:00:41,683 INFO    SenderThread:20960 [sender.py:transition_state():613] send defer: 7
2025-04-11 15:00:41,683 DEBUG   HandlerThread:20960 [handler.py:handle_request():146] handle_request: status_report
2025-04-11 15:00:41,684 DEBUG   HandlerThread:20960 [handler.py:handle_request():146] handle_request: defer
2025-04-11 15:00:41,684 INFO    HandlerThread:20960 [handler.py:handle_request_defer():172] handle defer: 7
2025-04-11 15:00:41,684 DEBUG   SenderThread:20960 [sender.py:send_request():407] send_request: defer
2025-04-11 15:00:41,684 INFO    SenderThread:20960 [sender.py:send_request_defer():609] handle sender defer: 7
2025-04-11 15:00:42,382 INFO    Thread-12 :20960 [dir_watcher.py:_on_file_created():271] file/dir created: /root/ltu-main/ltu-main/src/ltu_as/train_scripts/wandb/run-20250411_150006-p17gmulg/files/wandb-summary.json
2025-04-11 15:00:42,511 DEBUG   HandlerThread:20960 [handler.py:handle_request():146] handle_request: poll_exit
2025-04-11 15:00:43,175 INFO    SenderThread:20960 [sender.py:transition_state():613] send defer: 8
2025-04-11 15:00:43,175 DEBUG   SenderThread:20960 [sender.py:send_request():407] send_request: poll_exit
2025-04-11 15:00:43,176 DEBUG   HandlerThread:20960 [handler.py:handle_request():146] handle_request: defer
2025-04-11 15:00:43,176 INFO    HandlerThread:20960 [handler.py:handle_request_defer():172] handle defer: 8
2025-04-11 15:00:43,176 DEBUG   SenderThread:20960 [sender.py:send_request():407] send_request: defer
2025-04-11 15:00:43,177 INFO    SenderThread:20960 [sender.py:send_request_defer():609] handle sender defer: 8
2025-04-11 15:00:43,177 INFO    SenderThread:20960 [job_builder.py:build():281] Attempting to build job artifact
2025-04-11 15:00:43,179 INFO    SenderThread:20960 [job_builder.py:_get_source_type():404] no source found
2025-04-11 15:00:43,179 INFO    SenderThread:20960 [sender.py:transition_state():613] send defer: 9
2025-04-11 15:00:43,179 DEBUG   HandlerThread:20960 [handler.py:handle_request():146] handle_request: defer
2025-04-11 15:00:43,180 INFO    HandlerThread:20960 [handler.py:handle_request_defer():172] handle defer: 9
2025-04-11 15:00:43,180 DEBUG   SenderThread:20960 [sender.py:send_request():407] send_request: defer
2025-04-11 15:00:43,180 INFO    SenderThread:20960 [sender.py:send_request_defer():609] handle sender defer: 9
2025-04-11 15:00:43,180 INFO    SenderThread:20960 [dir_watcher.py:finish():358] shutting down directory watcher
2025-04-11 15:00:43,383 INFO    Thread-12 :20960 [dir_watcher.py:_on_file_modified():288] file/dir modified: /root/ltu-main/ltu-main/src/ltu_as/train_scripts/wandb/run-20250411_150006-p17gmulg/files/output.log
2025-04-11 15:00:43,384 INFO    SenderThread:20960 [dir_watcher.py:finish():388] scan: /root/ltu-main/ltu-main/src/ltu_as/train_scripts/wandb/run-20250411_150006-p17gmulg/files
2025-04-11 15:00:43,384 INFO    SenderThread:20960 [dir_watcher.py:finish():402] scan save: /root/ltu-main/ltu-main/src/ltu_as/train_scripts/wandb/run-20250411_150006-p17gmulg/files/config.yaml config.yaml
2025-04-11 15:00:43,385 INFO    SenderThread:20960 [dir_watcher.py:finish():402] scan save: /root/ltu-main/ltu-main/src/ltu_as/train_scripts/wandb/run-20250411_150006-p17gmulg/files/requirements.txt requirements.txt
2025-04-11 15:00:43,390 INFO    SenderThread:20960 [dir_watcher.py:finish():402] scan save: /root/ltu-main/ltu-main/src/ltu_as/train_scripts/wandb/run-20250411_150006-p17gmulg/files/conda-environment.yaml conda-environment.yaml
2025-04-11 15:00:43,394 INFO    SenderThread:20960 [dir_watcher.py:finish():402] scan save: /root/ltu-main/ltu-main/src/ltu_as/train_scripts/wandb/run-20250411_150006-p17gmulg/files/wandb-metadata.json wandb-metadata.json
2025-04-11 15:00:43,395 INFO    SenderThread:20960 [dir_watcher.py:finish():402] scan save: /root/ltu-main/ltu-main/src/ltu_as/train_scripts/wandb/run-20250411_150006-p17gmulg/files/output.log output.log
2025-04-11 15:00:43,395 INFO    SenderThread:20960 [dir_watcher.py:finish():402] scan save: /root/ltu-main/ltu-main/src/ltu_as/train_scripts/wandb/run-20250411_150006-p17gmulg/files/wandb-summary.json wandb-summary.json
2025-04-11 15:00:43,402 INFO    SenderThread:20960 [sender.py:transition_state():613] send defer: 10
2025-04-11 15:00:43,403 DEBUG   HandlerThread:20960 [handler.py:handle_request():146] handle_request: defer
2025-04-11 15:00:43,404 INFO    HandlerThread:20960 [handler.py:handle_request_defer():172] handle defer: 10
2025-04-11 15:00:43,406 DEBUG   SenderThread:20960 [sender.py:send_request():407] send_request: defer
2025-04-11 15:00:43,406 INFO    SenderThread:20960 [sender.py:send_request_defer():609] handle sender defer: 10
2025-04-11 15:00:43,406 INFO    SenderThread:20960 [file_pusher.py:finish():175] shutting down file pusher
2025-04-11 15:00:43,417 ERROR   wandb-upload_0:20960 [internal_api.py:upload_file():2556] upload_file exception https://storage.googleapis.com/wandb-production.appspot.com/2931823730-harbin-institute-of-technology/ltu-as/p17gmulg/wandb-metadata.json?X-Goog-Algorithm=GOOG4-RSA-SHA256&X-Goog-Credential=gorilla-files-url-signer-man%40wandb-production.iam.gserviceaccount.com%2F20250411%2Fauto%2Fstorage%2Fgoog4_request&X-Goog-Date=20250411T150027Z&X-Goog-Expires=86399&X-Goog-Signature=0fca1f09c246b35184e651f2690bb2d36dc49dab5fec1f973e2c65e5bfefebbfd202f9b4caa1608b01be21ef52649952919cd92fe2c7d0cbaa7d85e1dec4688e3d4bce047b086e7704caa70c0e7cd600a6fa32524d987c1e285f028227ad40a92e888252a5c330544b44a0eab8be632c7210336d5e7ecaf9b4c27dfefc250b2e5f8a04f0124c65480524e79e4ebfbf7f17921a78390961ea9ff85a200da5de126487ab0284a7f24abf28c4a11a45df9fe33a42121f13be1d8e478aaebd8536a5f732611162ce46d0392669452a89459b76adcc2538897ad8710d676cf8b168232f3798549d04eb53b7c89783fcdaea6b7933abd4ab75eccaac8647b7588544b8&X-Goog-SignedHeaders=host&X-User=2931823730: HTTPSConnectionPool(host='storage.googleapis.com', port=443): Max retries exceeded with url: /wandb-production.appspot.com/2931823730-harbin-institute-of-technology/ltu-as/p17gmulg/wandb-metadata.json?X-Goog-Algorithm=GOOG4-RSA-SHA256&X-Goog-Credential=gorilla-files-url-signer-man%40wandb-production.iam.gserviceaccount.com%2F20250411%2Fauto%2Fstorage%2Fgoog4_request&X-Goog-Date=20250411T150027Z&X-Goog-Expires=86399&X-Goog-Signature=0fca1f09c246b35184e651f2690bb2d36dc49dab5fec1f973e2c65e5bfefebbfd202f9b4caa1608b01be21ef52649952919cd92fe2c7d0cbaa7d85e1dec4688e3d4bce047b086e7704caa70c0e7cd600a6fa32524d987c1e285f028227ad40a92e888252a5c330544b44a0eab8be632c7210336d5e7ecaf9b4c27dfefc250b2e5f8a04f0124c65480524e79e4ebfbf7f17921a78390961ea9ff85a200da5de126487ab0284a7f24abf28c4a11a45df9fe33a42121f13be1d8e478aaebd8536a5f732611162ce46d0392669452a89459b76adcc2538897ad8710d676cf8b168232f3798549d04eb53b7c89783fcdaea6b7933abd4ab75eccaac8647b7588544b8&X-Goog-SignedHeaders=host&X-User=2931823730 (Caused by NewConnectionError('<urllib3.connection.HTTPSConnection object at 0x7f704e1ab970>: Failed to establish a new connection: [Errno 101] Network is unreachable'))
2025-04-11 15:00:43,417 ERROR   wandb-upload_0:20960 [internal_api.py:upload_file():2558] upload_file request headers: {'User-Agent': 'python-requests/2.32.3', 'Accept-Encoding': 'gzip, deflate, br', 'Accept': '*/*', 'Connection': 'keep-alive', 'Content-Length': '2212'}
2025-04-11 15:00:43,418 ERROR   wandb-upload_0:20960 [internal_api.py:upload_file():2560] upload_file response body: 
2025-04-11 15:00:43,512 DEBUG   HandlerThread:20960 [handler.py:handle_request():146] handle_request: poll_exit
2025-04-11 15:00:43,513 DEBUG   SenderThread:20960 [sender.py:send_request():407] send_request: poll_exit
2025-04-11 15:00:43,663 ERROR   wandb-upload_1:20960 [internal_api.py:upload_file():2556] upload_file exception https://storage.googleapis.com/wandb-production.appspot.com/2931823730-harbin-institute-of-technology/ltu-as/p17gmulg/config.yaml?X-Goog-Algorithm=GOOG4-RSA-SHA256&X-Goog-Credential=gorilla-files-url-signer-man%40wandb-production.iam.gserviceaccount.com%2F20250411%2Fauto%2Fstorage%2Fgoog4_request&X-Goog-Date=20250411T150043Z&X-Goog-Expires=86399&X-Goog-Signature=2b94521395b91d2c6da28bc88c8fc2fc455de0bcface43802f47c8b6e4bc65bb0576e272b4d89ff080de61ad7e2630455fac8f8556a8d2a1ec83e0f726c7121de7b3c84adbbc041acaa6d30505fb9bb73aba360d8d7b4ca92305f90ec83f114c9376b107f51e30bb10fe0101942367b2da5037b93caba63940e541e0ffa3d92a71c487bd952d659a72612e9bb29d3d5e5ae6c723dd8f91e2eb021292ec34d2126321481511017f837aa8cc0777e29c645f288e5c68da432b266e08df490dd625a85a31dd1fb03e68e1afb786b509ca67234739c6680f80bb31dd4c6da4212ae8dc8e5e0ff83679cfe8036d20ce4154044ae026f98c7e926fd492687e6ba80a2f&X-Goog-SignedHeaders=host&X-User=2931823730: HTTPSConnectionPool(host='storage.googleapis.com', port=443): Max retries exceeded with url: /wandb-production.appspot.com/2931823730-harbin-institute-of-technology/ltu-as/p17gmulg/config.yaml?X-Goog-Algorithm=GOOG4-RSA-SHA256&X-Goog-Credential=gorilla-files-url-signer-man%40wandb-production.iam.gserviceaccount.com%2F20250411%2Fauto%2Fstorage%2Fgoog4_request&X-Goog-Date=20250411T150043Z&X-Goog-Expires=86399&X-Goog-Signature=2b94521395b91d2c6da28bc88c8fc2fc455de0bcface43802f47c8b6e4bc65bb0576e272b4d89ff080de61ad7e2630455fac8f8556a8d2a1ec83e0f726c7121de7b3c84adbbc041acaa6d30505fb9bb73aba360d8d7b4ca92305f90ec83f114c9376b107f51e30bb10fe0101942367b2da5037b93caba63940e541e0ffa3d92a71c487bd952d659a72612e9bb29d3d5e5ae6c723dd8f91e2eb021292ec34d2126321481511017f837aa8cc0777e29c645f288e5c68da432b266e08df490dd625a85a31dd1fb03e68e1afb786b509ca67234739c6680f80bb31dd4c6da4212ae8dc8e5e0ff83679cfe8036d20ce4154044ae026f98c7e926fd492687e6ba80a2f&X-Goog-SignedHeaders=host&X-User=2931823730 (Caused by NewConnectionError('<urllib3.connection.HTTPSConnection object at 0x7f706698ecb0>: Failed to establish a new connection: [Errno 101] Network is unreachable'))
2025-04-11 15:00:43,663 ERROR   wandb-upload_1:20960 [internal_api.py:upload_file():2558] upload_file request headers: {'User-Agent': 'python-requests/2.32.3', 'Accept-Encoding': 'gzip, deflate, br', 'Accept': '*/*', 'Connection': 'keep-alive', 'Content-Length': '8666'}
2025-04-11 15:00:43,663 ERROR   wandb-upload_1:20960 [internal_api.py:upload_file():2560] upload_file response body: 
2025-04-11 15:00:43,667 ERROR   wandb-upload_2:20960 [internal_api.py:upload_file():2556] upload_file exception https://storage.googleapis.com/wandb-production.appspot.com/2931823730-harbin-institute-of-technology/ltu-as/p17gmulg/requirements.txt?X-Goog-Algorithm=GOOG4-RSA-SHA256&X-Goog-Credential=gorilla-files-url-signer-man%40wandb-production.iam.gserviceaccount.com%2F20250411%2Fauto%2Fstorage%2Fgoog4_request&X-Goog-Date=20250411T150043Z&X-Goog-Expires=86399&X-Goog-Signature=14dcd9bd7741ba854922781779b244d065a2f93e20042ce112d03d9a74fa6ceafd1a02b76cfe7e1d83ceecfb3b6c3b3ccc9fadcd34593f606440f4b7136578ec49a47ec7af23ddefb386a812922c26eb929dc0da3c7b5a24d04fe645d171ed6cbdf2dd3f41534425b4a709b793de783fa2b973ef1eb68ca4cbc8697ba576ff13534ced1f4976d8b3d7739d7b5ee6c113c7c67453905e7311f37f8bde9ebd13a60597a748a421ab730351a19b37ae016bf30b884b6e554c62df963c76284dfca9faf6a980b28817387e6dc67e8ed6fd758c92deb55a34f2eb5b303f7083028b548986861f2398dbaa3b2d08172b60c61edf28e44efed84920699974adac927b5f&X-Goog-SignedHeaders=host&X-User=2931823730: HTTPSConnectionPool(host='storage.googleapis.com', port=443): Max retries exceeded with url: /wandb-production.appspot.com/2931823730-harbin-institute-of-technology/ltu-as/p17gmulg/requirements.txt?X-Goog-Algorithm=GOOG4-RSA-SHA256&X-Goog-Credential=gorilla-files-url-signer-man%40wandb-production.iam.gserviceaccount.com%2F20250411%2Fauto%2Fstorage%2Fgoog4_request&X-Goog-Date=20250411T150043Z&X-Goog-Expires=86399&X-Goog-Signature=14dcd9bd7741ba854922781779b244d065a2f93e20042ce112d03d9a74fa6ceafd1a02b76cfe7e1d83ceecfb3b6c3b3ccc9fadcd34593f606440f4b7136578ec49a47ec7af23ddefb386a812922c26eb929dc0da3c7b5a24d04fe645d171ed6cbdf2dd3f41534425b4a709b793de783fa2b973ef1eb68ca4cbc8697ba576ff13534ced1f4976d8b3d7739d7b5ee6c113c7c67453905e7311f37f8bde9ebd13a60597a748a421ab730351a19b37ae016bf30b884b6e554c62df963c76284dfca9faf6a980b28817387e6dc67e8ed6fd758c92deb55a34f2eb5b303f7083028b548986861f2398dbaa3b2d08172b60c61edf28e44efed84920699974adac927b5f&X-Goog-SignedHeaders=host&X-User=2931823730 (Caused by NewConnectionError('<urllib3.connection.HTTPSConnection object at 0x7f702edb5a80>: Failed to establish a new connection: [Errno 101] Network is unreachable'))
2025-04-11 15:00:43,667 ERROR   wandb-upload_2:20960 [internal_api.py:upload_file():2558] upload_file request headers: {'User-Agent': 'python-requests/2.32.3', 'Accept-Encoding': 'gzip, deflate, br', 'Accept': '*/*', 'Connection': 'keep-alive', 'Content-Length': '4212'}
2025-04-11 15:00:43,667 ERROR   wandb-upload_2:20960 [internal_api.py:upload_file():2560] upload_file response body: 
2025-04-11 15:00:43,817 ERROR   wandb-upload_4:20960 [internal_api.py:upload_file():2556] upload_file exception https://storage.googleapis.com/wandb-production.appspot.com/2931823730-harbin-institute-of-technology/ltu-as/p17gmulg/output.log?X-Goog-Algorithm=GOOG4-RSA-SHA256&X-Goog-Credential=gorilla-files-url-signer-man%40wandb-production.iam.gserviceaccount.com%2F20250411%2Fauto%2Fstorage%2Fgoog4_request&X-Goog-Date=20250411T150043Z&X-Goog-Expires=86399&X-Goog-Signature=0308420c548c6bc687992243d2a177fab7c1e559bf54fdb3fcef576cbdb35fedc146e60d263e4a67d7dcf10d49fc5fce2b200db779ede9932190768ef7045285e94ebcab25d5c53df1ac3faccb2e1b3123697207c801b2f9ed9445e272209bc83528d2b276b120193046794812b634842c87ec4fb6a455019b7629adb328930593761b298218336a3352fe2b3ff4677801486c5fbe6d691a897ba443a75ff0090308631a57a9f25c185a2aa064157f9fcd720807f256f1830810dbc582f2f82e719ba0316a4b5743320f3ccfc2826623c2139bccbce4c58bcebd511da09c54dcb483ba9d761279f3786b202a99bd6e9a82147286632175a2481cd79591fa6901&X-Goog-SignedHeaders=host&X-User=2931823730: HTTPSConnectionPool(host='storage.googleapis.com', port=443): Max retries exceeded with url: /wandb-production.appspot.com/2931823730-harbin-institute-of-technology/ltu-as/p17gmulg/output.log?X-Goog-Algorithm=GOOG4-RSA-SHA256&X-Goog-Credential=gorilla-files-url-signer-man%40wandb-production.iam.gserviceaccount.com%2F20250411%2Fauto%2Fstorage%2Fgoog4_request&X-Goog-Date=20250411T150043Z&X-Goog-Expires=86399&X-Goog-Signature=0308420c548c6bc687992243d2a177fab7c1e559bf54fdb3fcef576cbdb35fedc146e60d263e4a67d7dcf10d49fc5fce2b200db779ede9932190768ef7045285e94ebcab25d5c53df1ac3faccb2e1b3123697207c801b2f9ed9445e272209bc83528d2b276b120193046794812b634842c87ec4fb6a455019b7629adb328930593761b298218336a3352fe2b3ff4677801486c5fbe6d691a897ba443a75ff0090308631a57a9f25c185a2aa064157f9fcd720807f256f1830810dbc582f2f82e719ba0316a4b5743320f3ccfc2826623c2139bccbce4c58bcebd511da09c54dcb483ba9d761279f3786b202a99bd6e9a82147286632175a2481cd79591fa6901&X-Goog-SignedHeaders=host&X-User=2931823730 (Caused by NewConnectionError('<urllib3.connection.HTTPSConnection object at 0x7f702edb66e0>: Failed to establish a new connection: [Errno 101] Network is unreachable'))
2025-04-11 15:00:43,817 ERROR   wandb-upload_4:20960 [internal_api.py:upload_file():2558] upload_file request headers: {'User-Agent': 'python-requests/2.32.3', 'Accept-Encoding': 'gzip, deflate, br', 'Accept': '*/*', 'Connection': 'keep-alive', 'Content-Length': '4566'}
2025-04-11 15:00:43,817 ERROR   wandb-upload_4:20960 [internal_api.py:upload_file():2560] upload_file response body: 
2025-04-11 15:00:44,126 ERROR   wandb-upload_3:20960 [internal_api.py:upload_file():2556] upload_file exception https://storage.googleapis.com/wandb-production.appspot.com/2931823730-harbin-institute-of-technology/ltu-as/p17gmulg/conda-environment.yaml?X-Goog-Algorithm=GOOG4-RSA-SHA256&X-Goog-Credential=gorilla-files-url-signer-man%40wandb-production.iam.gserviceaccount.com%2F20250411%2Fauto%2Fstorage%2Fgoog4_request&X-Goog-Date=20250411T150043Z&X-Goog-Expires=86399&X-Goog-Signature=00f2737f97b7b1f937f7a9aebdfea9b77a2c6c8e1517ac5604b0ab1d0c7220099661943fa06351c6a2fc07c285f7cde727cfd97257af5eec33c10ff58653cf9d6ebbfa07ca47153a6c0bb6e66bdc5460d4faccd98405adea9703c4f7553f8301273fcfa04cced1cd05c064254e7dbb600c8767e195c3109aa0466581c2735ab0ed4b1f21f2ba2046c29b2199a29cbcedb0f7ba1bce4992ef9fd04257dff85ead08d2ea2f4e835b64a2a3428bb295fd3523de6c1dbcd055c8962bd057f4c676fa028b90c343670ac851f3c26fc59ad1f13a6de4c9ea39dcbd845b4092616d0fe18bd2b09525b48943a5122a270e5637a422663aefc15274ec3ff901174e8eed50&X-Goog-SignedHeaders=host&X-User=2931823730: HTTPSConnectionPool(host='storage.googleapis.com', port=443): Max retries exceeded with url: /wandb-production.appspot.com/2931823730-harbin-institute-of-technology/ltu-as/p17gmulg/conda-environment.yaml?X-Goog-Algorithm=GOOG4-RSA-SHA256&X-Goog-Credential=gorilla-files-url-signer-man%40wandb-production.iam.gserviceaccount.com%2F20250411%2Fauto%2Fstorage%2Fgoog4_request&X-Goog-Date=20250411T150043Z&X-Goog-Expires=86399&X-Goog-Signature=00f2737f97b7b1f937f7a9aebdfea9b77a2c6c8e1517ac5604b0ab1d0c7220099661943fa06351c6a2fc07c285f7cde727cfd97257af5eec33c10ff58653cf9d6ebbfa07ca47153a6c0bb6e66bdc5460d4faccd98405adea9703c4f7553f8301273fcfa04cced1cd05c064254e7dbb600c8767e195c3109aa0466581c2735ab0ed4b1f21f2ba2046c29b2199a29cbcedb0f7ba1bce4992ef9fd04257dff85ead08d2ea2f4e835b64a2a3428bb295fd3523de6c1dbcd055c8962bd057f4c676fa028b90c343670ac851f3c26fc59ad1f13a6de4c9ea39dcbd845b4092616d0fe18bd2b09525b48943a5122a270e5637a422663aefc15274ec3ff901174e8eed50&X-Goog-SignedHeaders=host&X-User=2931823730 (Caused by NewConnectionError('<urllib3.connection.HTTPSConnection object at 0x7f702edb4e80>: Failed to establish a new connection: [Errno 101] Network is unreachable'))
2025-04-11 15:00:44,126 ERROR   wandb-upload_3:20960 [internal_api.py:upload_file():2558] upload_file request headers: {'User-Agent': 'python-requests/2.32.3', 'Accept-Encoding': 'gzip, deflate, br', 'Accept': '*/*', 'Connection': 'keep-alive', 'Content-Length': '8281'}
2025-04-11 15:00:44,127 ERROR   wandb-upload_3:20960 [internal_api.py:upload_file():2560] upload_file response body: 
2025-04-11 15:00:44,350 ERROR   wandb-upload_5:20960 [internal_api.py:upload_file():2556] upload_file exception https://storage.googleapis.com/wandb-production.appspot.com/2931823730-harbin-institute-of-technology/ltu-as/p17gmulg/wandb-summary.json?X-Goog-Algorithm=GOOG4-RSA-SHA256&X-Goog-Credential=gorilla-files-url-signer-man%40wandb-production.iam.gserviceaccount.com%2F20250411%2Fauto%2Fstorage%2Fgoog4_request&X-Goog-Date=20250411T150044Z&X-Goog-Expires=86399&X-Goog-Signature=24104ea3df52b0b0fce0141d2d6615d36298eb5ea08485b2dc4a616d8119698ba118d11a5f44e94354266eab45d4324499348fa21cbe0c4ba8fa5416f5d335df3cfd7f6375fd0c35836e0226a4611fe7b4e0f043aecba8910f16dbbe5ef52e0c1717e30949ed1b19d3656214206bf4119b065b8502f7c60223b66c33a0f306ebfb9892023b673278d5fc199b3db2f45eb469e4325de8426d897ab25d2fdef8b01f20a0e0440edd3be494bd732b6c55ed61f734c068dbb035289a3be40f4fe4597d3935b3425583450c92d72d5d0ffba8a0ff9533eab69377449395aab5b7bb990fbe8cc08bff93c2c6504738548e83e4a5e31b2924272307412886d6276d63ca&X-Goog-SignedHeaders=host&X-User=2931823730: HTTPSConnectionPool(host='storage.googleapis.com', port=443): Max retries exceeded with url: /wandb-production.appspot.com/2931823730-harbin-institute-of-technology/ltu-as/p17gmulg/wandb-summary.json?X-Goog-Algorithm=GOOG4-RSA-SHA256&X-Goog-Credential=gorilla-files-url-signer-man%40wandb-production.iam.gserviceaccount.com%2F20250411%2Fauto%2Fstorage%2Fgoog4_request&X-Goog-Date=20250411T150044Z&X-Goog-Expires=86399&X-Goog-Signature=24104ea3df52b0b0fce0141d2d6615d36298eb5ea08485b2dc4a616d8119698ba118d11a5f44e94354266eab45d4324499348fa21cbe0c4ba8fa5416f5d335df3cfd7f6375fd0c35836e0226a4611fe7b4e0f043aecba8910f16dbbe5ef52e0c1717e30949ed1b19d3656214206bf4119b065b8502f7c60223b66c33a0f306ebfb9892023b673278d5fc199b3db2f45eb469e4325de8426d897ab25d2fdef8b01f20a0e0440edd3be494bd732b6c55ed61f734c068dbb035289a3be40f4fe4597d3935b3425583450c92d72d5d0ffba8a0ff9533eab69377449395aab5b7bb990fbe8cc08bff93c2c6504738548e83e4a5e31b2924272307412886d6276d63ca&X-Goog-SignedHeaders=host&X-User=2931823730 (Caused by NewConnectionError('<urllib3.connection.HTTPSConnection object at 0x7f702edb63b0>: Failed to establish a new connection: [Errno 101] Network is unreachable'))
2025-04-11 15:00:44,350 ERROR   wandb-upload_5:20960 [internal_api.py:upload_file():2558] upload_file request headers: {'User-Agent': 'python-requests/2.32.3', 'Accept-Encoding': 'gzip, deflate, br', 'Accept': '*/*', 'Connection': 'keep-alive', 'Content-Length': '27'}
2025-04-11 15:00:44,350 ERROR   wandb-upload_5:20960 [internal_api.py:upload_file():2560] upload_file response body: 
2025-04-11 15:00:44,514 DEBUG   HandlerThread:20960 [handler.py:handle_request():146] handle_request: poll_exit
2025-04-11 15:00:44,515 DEBUG   SenderThread:20960 [sender.py:send_request():407] send_request: poll_exit
2025-04-11 15:00:44,736 ERROR   wandb-upload_2:20960 [internal_api.py:upload_file():2556] upload_file exception https://storage.googleapis.com/wandb-production.appspot.com/2931823730-harbin-institute-of-technology/ltu-as/p17gmulg/requirements.txt?X-Goog-Algorithm=GOOG4-RSA-SHA256&X-Goog-Credential=gorilla-files-url-signer-man%40wandb-production.iam.gserviceaccount.com%2F20250411%2Fauto%2Fstorage%2Fgoog4_request&X-Goog-Date=20250411T150043Z&X-Goog-Expires=86399&X-Goog-Signature=14dcd9bd7741ba854922781779b244d065a2f93e20042ce112d03d9a74fa6ceafd1a02b76cfe7e1d83ceecfb3b6c3b3ccc9fadcd34593f606440f4b7136578ec49a47ec7af23ddefb386a812922c26eb929dc0da3c7b5a24d04fe645d171ed6cbdf2dd3f41534425b4a709b793de783fa2b973ef1eb68ca4cbc8697ba576ff13534ced1f4976d8b3d7739d7b5ee6c113c7c67453905e7311f37f8bde9ebd13a60597a748a421ab730351a19b37ae016bf30b884b6e554c62df963c76284dfca9faf6a980b28817387e6dc67e8ed6fd758c92deb55a34f2eb5b303f7083028b548986861f2398dbaa3b2d08172b60c61edf28e44efed84920699974adac927b5f&X-Goog-SignedHeaders=host&X-User=2931823730: HTTPSConnectionPool(host='storage.googleapis.com', port=443): Max retries exceeded with url: /wandb-production.appspot.com/2931823730-harbin-institute-of-technology/ltu-as/p17gmulg/requirements.txt?X-Goog-Algorithm=GOOG4-RSA-SHA256&X-Goog-Credential=gorilla-files-url-signer-man%40wandb-production.iam.gserviceaccount.com%2F20250411%2Fauto%2Fstorage%2Fgoog4_request&X-Goog-Date=20250411T150043Z&X-Goog-Expires=86399&X-Goog-Signature=14dcd9bd7741ba854922781779b244d065a2f93e20042ce112d03d9a74fa6ceafd1a02b76cfe7e1d83ceecfb3b6c3b3ccc9fadcd34593f606440f4b7136578ec49a47ec7af23ddefb386a812922c26eb929dc0da3c7b5a24d04fe645d171ed6cbdf2dd3f41534425b4a709b793de783fa2b973ef1eb68ca4cbc8697ba576ff13534ced1f4976d8b3d7739d7b5ee6c113c7c67453905e7311f37f8bde9ebd13a60597a748a421ab730351a19b37ae016bf30b884b6e554c62df963c76284dfca9faf6a980b28817387e6dc67e8ed6fd758c92deb55a34f2eb5b303f7083028b548986861f2398dbaa3b2d08172b60c61edf28e44efed84920699974adac927b5f&X-Goog-SignedHeaders=host&X-User=2931823730 (Caused by NewConnectionError('<urllib3.connection.HTTPSConnection object at 0x7f702edb6ef0>: Failed to establish a new connection: [Errno 101] Network is unreachable'))
2025-04-11 15:00:44,736 ERROR   wandb-upload_2:20960 [internal_api.py:upload_file():2558] upload_file request headers: {'User-Agent': 'python-requests/2.32.3', 'Accept-Encoding': 'gzip, deflate, br', 'Accept': '*/*', 'Connection': 'keep-alive', 'Content-Length': '4212'}
2025-04-11 15:00:44,736 ERROR   wandb-upload_2:20960 [internal_api.py:upload_file():2560] upload_file response body: 
2025-04-11 15:00:44,814 ERROR   wandb-upload_1:20960 [internal_api.py:upload_file():2556] upload_file exception https://storage.googleapis.com/wandb-production.appspot.com/2931823730-harbin-institute-of-technology/ltu-as/p17gmulg/config.yaml?X-Goog-Algorithm=GOOG4-RSA-SHA256&X-Goog-Credential=gorilla-files-url-signer-man%40wandb-production.iam.gserviceaccount.com%2F20250411%2Fauto%2Fstorage%2Fgoog4_request&X-Goog-Date=20250411T150043Z&X-Goog-Expires=86399&X-Goog-Signature=2b94521395b91d2c6da28bc88c8fc2fc455de0bcface43802f47c8b6e4bc65bb0576e272b4d89ff080de61ad7e2630455fac8f8556a8d2a1ec83e0f726c7121de7b3c84adbbc041acaa6d30505fb9bb73aba360d8d7b4ca92305f90ec83f114c9376b107f51e30bb10fe0101942367b2da5037b93caba63940e541e0ffa3d92a71c487bd952d659a72612e9bb29d3d5e5ae6c723dd8f91e2eb021292ec34d2126321481511017f837aa8cc0777e29c645f288e5c68da432b266e08df490dd625a85a31dd1fb03e68e1afb786b509ca67234739c6680f80bb31dd4c6da4212ae8dc8e5e0ff83679cfe8036d20ce4154044ae026f98c7e926fd492687e6ba80a2f&X-Goog-SignedHeaders=host&X-User=2931823730: HTTPSConnectionPool(host='storage.googleapis.com', port=443): Max retries exceeded with url: /wandb-production.appspot.com/2931823730-harbin-institute-of-technology/ltu-as/p17gmulg/config.yaml?X-Goog-Algorithm=GOOG4-RSA-SHA256&X-Goog-Credential=gorilla-files-url-signer-man%40wandb-production.iam.gserviceaccount.com%2F20250411%2Fauto%2Fstorage%2Fgoog4_request&X-Goog-Date=20250411T150043Z&X-Goog-Expires=86399&X-Goog-Signature=2b94521395b91d2c6da28bc88c8fc2fc455de0bcface43802f47c8b6e4bc65bb0576e272b4d89ff080de61ad7e2630455fac8f8556a8d2a1ec83e0f726c7121de7b3c84adbbc041acaa6d30505fb9bb73aba360d8d7b4ca92305f90ec83f114c9376b107f51e30bb10fe0101942367b2da5037b93caba63940e541e0ffa3d92a71c487bd952d659a72612e9bb29d3d5e5ae6c723dd8f91e2eb021292ec34d2126321481511017f837aa8cc0777e29c645f288e5c68da432b266e08df490dd625a85a31dd1fb03e68e1afb786b509ca67234739c6680f80bb31dd4c6da4212ae8dc8e5e0ff83679cfe8036d20ce4154044ae026f98c7e926fd492687e6ba80a2f&X-Goog-SignedHeaders=host&X-User=2931823730 (Caused by NewConnectionError('<urllib3.connection.HTTPSConnection object at 0x7f702edb60e0>: Failed to establish a new connection: [Errno 101] Network is unreachable'))
2025-04-11 15:00:44,814 ERROR   wandb-upload_1:20960 [internal_api.py:upload_file():2558] upload_file request headers: {'User-Agent': 'python-requests/2.32.3', 'Accept-Encoding': 'gzip, deflate, br', 'Accept': '*/*', 'Connection': 'keep-alive', 'Content-Length': '8666'}
2025-04-11 15:00:44,815 ERROR   wandb-upload_1:20960 [internal_api.py:upload_file():2560] upload_file response body: 
2025-04-11 15:00:44,815 INFO    wandb-upload_1:20960 [retry.py:__call__():172] Retry attempt failed:
Traceback (most recent call last):
  File "/root/anaconda3/envs/venv_ltu/lib/python3.10/site-packages/urllib3/connection.py", line 198, in _new_conn
    sock = connection.create_connection(
  File "/root/anaconda3/envs/venv_ltu/lib/python3.10/site-packages/urllib3/util/connection.py", line 85, in create_connection
    raise err
  File "/root/anaconda3/envs/venv_ltu/lib/python3.10/site-packages/urllib3/util/connection.py", line 73, in create_connection
    sock.connect(sa)
OSError: [Errno 101] Network is unreachable

The above exception was the direct cause of the following exception:

Traceback (most recent call last):
  File "/root/anaconda3/envs/venv_ltu/lib/python3.10/site-packages/urllib3/connectionpool.py", line 793, in urlopen
    response = self._make_request(
  File "/root/anaconda3/envs/venv_ltu/lib/python3.10/site-packages/urllib3/connectionpool.py", line 491, in _make_request
    raise new_e
  File "/root/anaconda3/envs/venv_ltu/lib/python3.10/site-packages/urllib3/connectionpool.py", line 467, in _make_request
    self._validate_conn(conn)
  File "/root/anaconda3/envs/venv_ltu/lib/python3.10/site-packages/urllib3/connectionpool.py", line 1099, in _validate_conn
    conn.connect()
  File "/root/anaconda3/envs/venv_ltu/lib/python3.10/site-packages/urllib3/connection.py", line 616, in connect
    self.sock = sock = self._new_conn()
  File "/root/anaconda3/envs/venv_ltu/lib/python3.10/site-packages/urllib3/connection.py", line 213, in _new_conn
    raise NewConnectionError(
urllib3.exceptions.NewConnectionError: <urllib3.connection.HTTPSConnection object at 0x7f702edb60e0>: Failed to establish a new connection: [Errno 101] Network is unreachable

The above exception was the direct cause of the following exception:

Traceback (most recent call last):
  File "/root/anaconda3/envs/venv_ltu/lib/python3.10/site-packages/requests/adapters.py", line 667, in send
    resp = conn.urlopen(
  File "/root/anaconda3/envs/venv_ltu/lib/python3.10/site-packages/urllib3/connectionpool.py", line 847, in urlopen
    retries = retries.increment(
  File "/root/anaconda3/envs/venv_ltu/lib/python3.10/site-packages/urllib3/util/retry.py", line 515, in increment
    raise MaxRetryError(_pool, url, reason) from reason  # type: ignore[arg-type]
urllib3.exceptions.MaxRetryError: HTTPSConnectionPool(host='storage.googleapis.com', port=443): Max retries exceeded with url: /wandb-production.appspot.com/2931823730-harbin-institute-of-technology/ltu-as/p17gmulg/config.yaml?X-Goog-Algorithm=GOOG4-RSA-SHA256&X-Goog-Credential=gorilla-files-url-signer-man%40wandb-production.iam.gserviceaccount.com%2F20250411%2Fauto%2Fstorage%2Fgoog4_request&X-Goog-Date=20250411T150043Z&X-Goog-Expires=86399&X-Goog-Signature=2b94521395b91d2c6da28bc88c8fc2fc455de0bcface43802f47c8b6e4bc65bb0576e272b4d89ff080de61ad7e2630455fac8f8556a8d2a1ec83e0f726c7121de7b3c84adbbc041acaa6d30505fb9bb73aba360d8d7b4ca92305f90ec83f114c9376b107f51e30bb10fe0101942367b2da5037b93caba63940e541e0ffa3d92a71c487bd952d659a72612e9bb29d3d5e5ae6c723dd8f91e2eb021292ec34d2126321481511017f837aa8cc0777e29c645f288e5c68da432b266e08df490dd625a85a31dd1fb03e68e1afb786b509ca67234739c6680f80bb31dd4c6da4212ae8dc8e5e0ff83679cfe8036d20ce4154044ae026f98c7e926fd492687e6ba80a2f&X-Goog-SignedHeaders=host&X-User=2931823730 (Caused by NewConnectionError('<urllib3.connection.HTTPSConnection object at 0x7f702edb60e0>: Failed to establish a new connection: [Errno 101] Network is unreachable'))

During handling of the above exception, another exception occurred:

Traceback (most recent call last):
  File "/root/anaconda3/envs/venv_ltu/lib/python3.10/site-packages/wandb/sdk/internal/internal_api.py", line 2549, in upload_file
    response = self._upload_file_session.put(
  File "/root/anaconda3/envs/venv_ltu/lib/python3.10/site-packages/requests/sessions.py", line 649, in put
    return self.request("PUT", url, data=data, **kwargs)
  File "/root/anaconda3/envs/venv_ltu/lib/python3.10/site-packages/requests/sessions.py", line 589, in request
    resp = self.send(prep, **send_kwargs)
  File "/root/anaconda3/envs/venv_ltu/lib/python3.10/site-packages/requests/sessions.py", line 703, in send
    r = adapter.send(request, **kwargs)
  File "/root/anaconda3/envs/venv_ltu/lib/python3.10/site-packages/requests/adapters.py", line 700, in send
    raise ConnectionError(e, request=request)
requests.exceptions.ConnectionError: HTTPSConnectionPool(host='storage.googleapis.com', port=443): Max retries exceeded with url: /wandb-production.appspot.com/2931823730-harbin-institute-of-technology/ltu-as/p17gmulg/config.yaml?X-Goog-Algorithm=GOOG4-RSA-SHA256&X-Goog-Credential=gorilla-files-url-signer-man%40wandb-production.iam.gserviceaccount.com%2F20250411%2Fauto%2Fstorage%2Fgoog4_request&X-Goog-Date=20250411T150043Z&X-Goog-Expires=86399&X-Goog-Signature=2b94521395b91d2c6da28bc88c8fc2fc455de0bcface43802f47c8b6e4bc65bb0576e272b4d89ff080de61ad7e2630455fac8f8556a8d2a1ec83e0f726c7121de7b3c84adbbc041acaa6d30505fb9bb73aba360d8d7b4ca92305f90ec83f114c9376b107f51e30bb10fe0101942367b2da5037b93caba63940e541e0ffa3d92a71c487bd952d659a72612e9bb29d3d5e5ae6c723dd8f91e2eb021292ec34d2126321481511017f837aa8cc0777e29c645f288e5c68da432b266e08df490dd625a85a31dd1fb03e68e1afb786b509ca67234739c6680f80bb31dd4c6da4212ae8dc8e5e0ff83679cfe8036d20ce4154044ae026f98c7e926fd492687e6ba80a2f&X-Goog-SignedHeaders=host&X-User=2931823730 (Caused by NewConnectionError('<urllib3.connection.HTTPSConnection object at 0x7f702edb60e0>: Failed to establish a new connection: [Errno 101] Network is unreachable'))

During handling of the above exception, another exception occurred:

Traceback (most recent call last):
  File "/root/anaconda3/envs/venv_ltu/lib/python3.10/site-packages/wandb/sdk/lib/retry.py", line 131, in __call__
    result = self._call_fn(*args, **kwargs)
  File "/root/anaconda3/envs/venv_ltu/lib/python3.10/site-packages/wandb/sdk/internal/internal_api.py", line 2580, in upload_file
    raise _e.with_traceback(sys.exc_info()[2])
  File "/root/anaconda3/envs/venv_ltu/lib/python3.10/site-packages/wandb/sdk/internal/internal_api.py", line 2549, in upload_file
    response = self._upload_file_session.put(
  File "/root/anaconda3/envs/venv_ltu/lib/python3.10/site-packages/requests/sessions.py", line 649, in put
    return self.request("PUT", url, data=data, **kwargs)
  File "/root/anaconda3/envs/venv_ltu/lib/python3.10/site-packages/requests/sessions.py", line 589, in request
    resp = self.send(prep, **send_kwargs)
  File "/root/anaconda3/envs/venv_ltu/lib/python3.10/site-packages/requests/sessions.py", line 703, in send
    r = adapter.send(request, **kwargs)
  File "/root/anaconda3/envs/venv_ltu/lib/python3.10/site-packages/requests/adapters.py", line 700, in send
    raise ConnectionError(e, request=request)
wandb.sdk.lib.retry.TransientError: None
2025-04-11 15:00:44,836 ERROR   wandb-upload_4:20960 [internal_api.py:upload_file():2556] upload_file exception https://storage.googleapis.com/wandb-production.appspot.com/2931823730-harbin-institute-of-technology/ltu-as/p17gmulg/output.log?X-Goog-Algorithm=GOOG4-RSA-SHA256&X-Goog-Credential=gorilla-files-url-signer-man%40wandb-production.iam.gserviceaccount.com%2F20250411%2Fauto%2Fstorage%2Fgoog4_request&X-Goog-Date=20250411T150043Z&X-Goog-Expires=86399&X-Goog-Signature=0308420c548c6bc687992243d2a177fab7c1e559bf54fdb3fcef576cbdb35fedc146e60d263e4a67d7dcf10d49fc5fce2b200db779ede9932190768ef7045285e94ebcab25d5c53df1ac3faccb2e1b3123697207c801b2f9ed9445e272209bc83528d2b276b120193046794812b634842c87ec4fb6a455019b7629adb328930593761b298218336a3352fe2b3ff4677801486c5fbe6d691a897ba443a75ff0090308631a57a9f25c185a2aa064157f9fcd720807f256f1830810dbc582f2f82e719ba0316a4b5743320f3ccfc2826623c2139bccbce4c58bcebd511da09c54dcb483ba9d761279f3786b202a99bd6e9a82147286632175a2481cd79591fa6901&X-Goog-SignedHeaders=host&X-User=2931823730: HTTPSConnectionPool(host='storage.googleapis.com', port=443): Max retries exceeded with url: /wandb-production.appspot.com/2931823730-harbin-institute-of-technology/ltu-as/p17gmulg/output.log?X-Goog-Algorithm=GOOG4-RSA-SHA256&X-Goog-Credential=gorilla-files-url-signer-man%40wandb-production.iam.gserviceaccount.com%2F20250411%2Fauto%2Fstorage%2Fgoog4_request&X-Goog-Date=20250411T150043Z&X-Goog-Expires=86399&X-Goog-Signature=0308420c548c6bc687992243d2a177fab7c1e559bf54fdb3fcef576cbdb35fedc146e60d263e4a67d7dcf10d49fc5fce2b200db779ede9932190768ef7045285e94ebcab25d5c53df1ac3faccb2e1b3123697207c801b2f9ed9445e272209bc83528d2b276b120193046794812b634842c87ec4fb6a455019b7629adb328930593761b298218336a3352fe2b3ff4677801486c5fbe6d691a897ba443a75ff0090308631a57a9f25c185a2aa064157f9fcd720807f256f1830810dbc582f2f82e719ba0316a4b5743320f3ccfc2826623c2139bccbce4c58bcebd511da09c54dcb483ba9d761279f3786b202a99bd6e9a82147286632175a2481cd79591fa6901&X-Goog-SignedHeaders=host&X-User=2931823730 (Caused by NewConnectionError('<urllib3.connection.HTTPSConnection object at 0x7f702edb5600>: Failed to establish a new connection: [Errno 101] Network is unreachable'))
2025-04-11 15:00:44,837 ERROR   wandb-upload_4:20960 [internal_api.py:upload_file():2558] upload_file request headers: {'User-Agent': 'python-requests/2.32.3', 'Accept-Encoding': 'gzip, deflate, br', 'Accept': '*/*', 'Connection': 'keep-alive', 'Content-Length': '4566'}
2025-04-11 15:00:44,837 ERROR   wandb-upload_4:20960 [internal_api.py:upload_file():2560] upload_file response body: 
2025-04-11 15:00:45,162 ERROR   wandb-upload_3:20960 [internal_api.py:upload_file():2556] upload_file exception https://storage.googleapis.com/wandb-production.appspot.com/2931823730-harbin-institute-of-technology/ltu-as/p17gmulg/conda-environment.yaml?X-Goog-Algorithm=GOOG4-RSA-SHA256&X-Goog-Credential=gorilla-files-url-signer-man%40wandb-production.iam.gserviceaccount.com%2F20250411%2Fauto%2Fstorage%2Fgoog4_request&X-Goog-Date=20250411T150043Z&X-Goog-Expires=86399&X-Goog-Signature=00f2737f97b7b1f937f7a9aebdfea9b77a2c6c8e1517ac5604b0ab1d0c7220099661943fa06351c6a2fc07c285f7cde727cfd97257af5eec33c10ff58653cf9d6ebbfa07ca47153a6c0bb6e66bdc5460d4faccd98405adea9703c4f7553f8301273fcfa04cced1cd05c064254e7dbb600c8767e195c3109aa0466581c2735ab0ed4b1f21f2ba2046c29b2199a29cbcedb0f7ba1bce4992ef9fd04257dff85ead08d2ea2f4e835b64a2a3428bb295fd3523de6c1dbcd055c8962bd057f4c676fa028b90c343670ac851f3c26fc59ad1f13a6de4c9ea39dcbd845b4092616d0fe18bd2b09525b48943a5122a270e5637a422663aefc15274ec3ff901174e8eed50&X-Goog-SignedHeaders=host&X-User=2931823730: HTTPSConnectionPool(host='storage.googleapis.com', port=443): Max retries exceeded with url: /wandb-production.appspot.com/2931823730-harbin-institute-of-technology/ltu-as/p17gmulg/conda-environment.yaml?X-Goog-Algorithm=GOOG4-RSA-SHA256&X-Goog-Credential=gorilla-files-url-signer-man%40wandb-production.iam.gserviceaccount.com%2F20250411%2Fauto%2Fstorage%2Fgoog4_request&X-Goog-Date=20250411T150043Z&X-Goog-Expires=86399&X-Goog-Signature=00f2737f97b7b1f937f7a9aebdfea9b77a2c6c8e1517ac5604b0ab1d0c7220099661943fa06351c6a2fc07c285f7cde727cfd97257af5eec33c10ff58653cf9d6ebbfa07ca47153a6c0bb6e66bdc5460d4faccd98405adea9703c4f7553f8301273fcfa04cced1cd05c064254e7dbb600c8767e195c3109aa0466581c2735ab0ed4b1f21f2ba2046c29b2199a29cbcedb0f7ba1bce4992ef9fd04257dff85ead08d2ea2f4e835b64a2a3428bb295fd3523de6c1dbcd055c8962bd057f4c676fa028b90c343670ac851f3c26fc59ad1f13a6de4c9ea39dcbd845b4092616d0fe18bd2b09525b48943a5122a270e5637a422663aefc15274ec3ff901174e8eed50&X-Goog-SignedHeaders=host&X-User=2931823730 (Caused by NewConnectionError('<urllib3.connection.HTTPSConnection object at 0x7f702edb5f00>: Failed to establish a new connection: [Errno 101] Network is unreachable'))
2025-04-11 15:00:45,163 ERROR   wandb-upload_3:20960 [internal_api.py:upload_file():2558] upload_file request headers: {'User-Agent': 'python-requests/2.32.3', 'Accept-Encoding': 'gzip, deflate, br', 'Accept': '*/*', 'Connection': 'keep-alive', 'Content-Length': '8281'}
2025-04-11 15:00:45,163 ERROR   wandb-upload_3:20960 [internal_api.py:upload_file():2560] upload_file response body: 
2025-04-11 15:00:45,516 DEBUG   HandlerThread:20960 [handler.py:handle_request():146] handle_request: poll_exit
2025-04-11 15:00:45,517 DEBUG   SenderThread:20960 [sender.py:send_request():407] send_request: poll_exit
2025-04-11 15:00:45,539 ERROR   wandb-upload_5:20960 [internal_api.py:upload_file():2556] upload_file exception https://storage.googleapis.com/wandb-production.appspot.com/2931823730-harbin-institute-of-technology/ltu-as/p17gmulg/wandb-summary.json?X-Goog-Algorithm=GOOG4-RSA-SHA256&X-Goog-Credential=gorilla-files-url-signer-man%40wandb-production.iam.gserviceaccount.com%2F20250411%2Fauto%2Fstorage%2Fgoog4_request&X-Goog-Date=20250411T150044Z&X-Goog-Expires=86399&X-Goog-Signature=24104ea3df52b0b0fce0141d2d6615d36298eb5ea08485b2dc4a616d8119698ba118d11a5f44e94354266eab45d4324499348fa21cbe0c4ba8fa5416f5d335df3cfd7f6375fd0c35836e0226a4611fe7b4e0f043aecba8910f16dbbe5ef52e0c1717e30949ed1b19d3656214206bf4119b065b8502f7c60223b66c33a0f306ebfb9892023b673278d5fc199b3db2f45eb469e4325de8426d897ab25d2fdef8b01f20a0e0440edd3be494bd732b6c55ed61f734c068dbb035289a3be40f4fe4597d3935b3425583450c92d72d5d0ffba8a0ff9533eab69377449395aab5b7bb990fbe8cc08bff93c2c6504738548e83e4a5e31b2924272307412886d6276d63ca&X-Goog-SignedHeaders=host&X-User=2931823730: HTTPSConnectionPool(host='storage.googleapis.com', port=443): Max retries exceeded with url: /wandb-production.appspot.com/2931823730-harbin-institute-of-technology/ltu-as/p17gmulg/wandb-summary.json?X-Goog-Algorithm=GOOG4-RSA-SHA256&X-Goog-Credential=gorilla-files-url-signer-man%40wandb-production.iam.gserviceaccount.com%2F20250411%2Fauto%2Fstorage%2Fgoog4_request&X-Goog-Date=20250411T150044Z&X-Goog-Expires=86399&X-Goog-Signature=24104ea3df52b0b0fce0141d2d6615d36298eb5ea08485b2dc4a616d8119698ba118d11a5f44e94354266eab45d4324499348fa21cbe0c4ba8fa5416f5d335df3cfd7f6375fd0c35836e0226a4611fe7b4e0f043aecba8910f16dbbe5ef52e0c1717e30949ed1b19d3656214206bf4119b065b8502f7c60223b66c33a0f306ebfb9892023b673278d5fc199b3db2f45eb469e4325de8426d897ab25d2fdef8b01f20a0e0440edd3be494bd732b6c55ed61f734c068dbb035289a3be40f4fe4597d3935b3425583450c92d72d5d0ffba8a0ff9533eab69377449395aab5b7bb990fbe8cc08bff93c2c6504738548e83e4a5e31b2924272307412886d6276d63ca&X-Goog-SignedHeaders=host&X-User=2931823730 (Caused by NewConnectionError('<urllib3.connection.HTTPSConnection object at 0x7f702edb5840>: Failed to establish a new connection: [Errno 101] Network is unreachable'))
2025-04-11 15:00:45,539 ERROR   wandb-upload_5:20960 [internal_api.py:upload_file():2558] upload_file request headers: {'User-Agent': 'python-requests/2.32.3', 'Accept-Encoding': 'gzip, deflate, br', 'Accept': '*/*', 'Connection': 'keep-alive', 'Content-Length': '27'}
2025-04-11 15:00:45,539 ERROR   wandb-upload_5:20960 [internal_api.py:upload_file():2560] upload_file response body: 
2025-04-11 15:00:46,516 DEBUG   HandlerThread:20960 [handler.py:handle_request():146] handle_request: poll_exit
2025-04-11 15:00:46,517 DEBUG   SenderThread:20960 [sender.py:send_request():407] send_request: poll_exit
2025-04-11 15:00:46,847 ERROR   wandb-upload_2:20960 [internal_api.py:upload_file():2556] upload_file exception https://storage.googleapis.com/wandb-production.appspot.com/2931823730-harbin-institute-of-technology/ltu-as/p17gmulg/requirements.txt?X-Goog-Algorithm=GOOG4-RSA-SHA256&X-Goog-Credential=gorilla-files-url-signer-man%40wandb-production.iam.gserviceaccount.com%2F20250411%2Fauto%2Fstorage%2Fgoog4_request&X-Goog-Date=20250411T150043Z&X-Goog-Expires=86399&X-Goog-Signature=14dcd9bd7741ba854922781779b244d065a2f93e20042ce112d03d9a74fa6ceafd1a02b76cfe7e1d83ceecfb3b6c3b3ccc9fadcd34593f606440f4b7136578ec49a47ec7af23ddefb386a812922c26eb929dc0da3c7b5a24d04fe645d171ed6cbdf2dd3f41534425b4a709b793de783fa2b973ef1eb68ca4cbc8697ba576ff13534ced1f4976d8b3d7739d7b5ee6c113c7c67453905e7311f37f8bde9ebd13a60597a748a421ab730351a19b37ae016bf30b884b6e554c62df963c76284dfca9faf6a980b28817387e6dc67e8ed6fd758c92deb55a34f2eb5b303f7083028b548986861f2398dbaa3b2d08172b60c61edf28e44efed84920699974adac927b5f&X-Goog-SignedHeaders=host&X-User=2931823730: HTTPSConnectionPool(host='storage.googleapis.com', port=443): Max retries exceeded with url: /wandb-production.appspot.com/2931823730-harbin-institute-of-technology/ltu-as/p17gmulg/requirements.txt?X-Goog-Algorithm=GOOG4-RSA-SHA256&X-Goog-Credential=gorilla-files-url-signer-man%40wandb-production.iam.gserviceaccount.com%2F20250411%2Fauto%2Fstorage%2Fgoog4_request&X-Goog-Date=20250411T150043Z&X-Goog-Expires=86399&X-Goog-Signature=14dcd9bd7741ba854922781779b244d065a2f93e20042ce112d03d9a74fa6ceafd1a02b76cfe7e1d83ceecfb3b6c3b3ccc9fadcd34593f606440f4b7136578ec49a47ec7af23ddefb386a812922c26eb929dc0da3c7b5a24d04fe645d171ed6cbdf2dd3f41534425b4a709b793de783fa2b973ef1eb68ca4cbc8697ba576ff13534ced1f4976d8b3d7739d7b5ee6c113c7c67453905e7311f37f8bde9ebd13a60597a748a421ab730351a19b37ae016bf30b884b6e554c62df963c76284dfca9faf6a980b28817387e6dc67e8ed6fd758c92deb55a34f2eb5b303f7083028b548986861f2398dbaa3b2d08172b60c61edf28e44efed84920699974adac927b5f&X-Goog-SignedHeaders=host&X-User=2931823730 (Caused by NewConnectionError('<urllib3.connection.HTTPSConnection object at 0x7f704e1a8b20>: Failed to establish a new connection: [Errno 101] Network is unreachable'))
2025-04-11 15:00:46,847 ERROR   wandb-upload_2:20960 [internal_api.py:upload_file():2558] upload_file request headers: {'User-Agent': 'python-requests/2.32.3', 'Accept-Encoding': 'gzip, deflate, br', 'Accept': '*/*', 'Connection': 'keep-alive', 'Content-Length': '4212'}
2025-04-11 15:00:46,848 ERROR   wandb-upload_2:20960 [internal_api.py:upload_file():2560] upload_file response body: 
2025-04-11 15:00:47,066 ERROR   wandb-upload_4:20960 [internal_api.py:upload_file():2556] upload_file exception https://storage.googleapis.com/wandb-production.appspot.com/2931823730-harbin-institute-of-technology/ltu-as/p17gmulg/output.log?X-Goog-Algorithm=GOOG4-RSA-SHA256&X-Goog-Credential=gorilla-files-url-signer-man%40wandb-production.iam.gserviceaccount.com%2F20250411%2Fauto%2Fstorage%2Fgoog4_request&X-Goog-Date=20250411T150043Z&X-Goog-Expires=86399&X-Goog-Signature=0308420c548c6bc687992243d2a177fab7c1e559bf54fdb3fcef576cbdb35fedc146e60d263e4a67d7dcf10d49fc5fce2b200db779ede9932190768ef7045285e94ebcab25d5c53df1ac3faccb2e1b3123697207c801b2f9ed9445e272209bc83528d2b276b120193046794812b634842c87ec4fb6a455019b7629adb328930593761b298218336a3352fe2b3ff4677801486c5fbe6d691a897ba443a75ff0090308631a57a9f25c185a2aa064157f9fcd720807f256f1830810dbc582f2f82e719ba0316a4b5743320f3ccfc2826623c2139bccbce4c58bcebd511da09c54dcb483ba9d761279f3786b202a99bd6e9a82147286632175a2481cd79591fa6901&X-Goog-SignedHeaders=host&X-User=2931823730: HTTPSConnectionPool(host='storage.googleapis.com', port=443): Max retries exceeded with url: /wandb-production.appspot.com/2931823730-harbin-institute-of-technology/ltu-as/p17gmulg/output.log?X-Goog-Algorithm=GOOG4-RSA-SHA256&X-Goog-Credential=gorilla-files-url-signer-man%40wandb-production.iam.gserviceaccount.com%2F20250411%2Fauto%2Fstorage%2Fgoog4_request&X-Goog-Date=20250411T150043Z&X-Goog-Expires=86399&X-Goog-Signature=0308420c548c6bc687992243d2a177fab7c1e559bf54fdb3fcef576cbdb35fedc146e60d263e4a67d7dcf10d49fc5fce2b200db779ede9932190768ef7045285e94ebcab25d5c53df1ac3faccb2e1b3123697207c801b2f9ed9445e272209bc83528d2b276b120193046794812b634842c87ec4fb6a455019b7629adb328930593761b298218336a3352fe2b3ff4677801486c5fbe6d691a897ba443a75ff0090308631a57a9f25c185a2aa064157f9fcd720807f256f1830810dbc582f2f82e719ba0316a4b5743320f3ccfc2826623c2139bccbce4c58bcebd511da09c54dcb483ba9d761279f3786b202a99bd6e9a82147286632175a2481cd79591fa6901&X-Goog-SignedHeaders=host&X-User=2931823730 (Caused by NewConnectionError('<urllib3.connection.HTTPSConnection object at 0x7f704e1aa110>: Failed to establish a new connection: [Errno 101] Network is unreachable'))
2025-04-11 15:00:47,067 ERROR   wandb-upload_4:20960 [internal_api.py:upload_file():2558] upload_file request headers: {'User-Agent': 'python-requests/2.32.3', 'Accept-Encoding': 'gzip, deflate, br', 'Accept': '*/*', 'Connection': 'keep-alive', 'Content-Length': '4566'}
2025-04-11 15:00:47,067 ERROR   wandb-upload_4:20960 [internal_api.py:upload_file():2560] upload_file response body: 
2025-04-11 15:00:47,315 ERROR   wandb-upload_1:20960 [internal_api.py:upload_file():2556] upload_file exception https://storage.googleapis.com/wandb-production.appspot.com/2931823730-harbin-institute-of-technology/ltu-as/p17gmulg/config.yaml?X-Goog-Algorithm=GOOG4-RSA-SHA256&X-Goog-Credential=gorilla-files-url-signer-man%40wandb-production.iam.gserviceaccount.com%2F20250411%2Fauto%2Fstorage%2Fgoog4_request&X-Goog-Date=20250411T150043Z&X-Goog-Expires=86399&X-Goog-Signature=2b94521395b91d2c6da28bc88c8fc2fc455de0bcface43802f47c8b6e4bc65bb0576e272b4d89ff080de61ad7e2630455fac8f8556a8d2a1ec83e0f726c7121de7b3c84adbbc041acaa6d30505fb9bb73aba360d8d7b4ca92305f90ec83f114c9376b107f51e30bb10fe0101942367b2da5037b93caba63940e541e0ffa3d92a71c487bd952d659a72612e9bb29d3d5e5ae6c723dd8f91e2eb021292ec34d2126321481511017f837aa8cc0777e29c645f288e5c68da432b266e08df490dd625a85a31dd1fb03e68e1afb786b509ca67234739c6680f80bb31dd4c6da4212ae8dc8e5e0ff83679cfe8036d20ce4154044ae026f98c7e926fd492687e6ba80a2f&X-Goog-SignedHeaders=host&X-User=2931823730: HTTPSConnectionPool(host='storage.googleapis.com', port=443): Max retries exceeded with url: /wandb-production.appspot.com/2931823730-harbin-institute-of-technology/ltu-as/p17gmulg/config.yaml?X-Goog-Algorithm=GOOG4-RSA-SHA256&X-Goog-Credential=gorilla-files-url-signer-man%40wandb-production.iam.gserviceaccount.com%2F20250411%2Fauto%2Fstorage%2Fgoog4_request&X-Goog-Date=20250411T150043Z&X-Goog-Expires=86399&X-Goog-Signature=2b94521395b91d2c6da28bc88c8fc2fc455de0bcface43802f47c8b6e4bc65bb0576e272b4d89ff080de61ad7e2630455fac8f8556a8d2a1ec83e0f726c7121de7b3c84adbbc041acaa6d30505fb9bb73aba360d8d7b4ca92305f90ec83f114c9376b107f51e30bb10fe0101942367b2da5037b93caba63940e541e0ffa3d92a71c487bd952d659a72612e9bb29d3d5e5ae6c723dd8f91e2eb021292ec34d2126321481511017f837aa8cc0777e29c645f288e5c68da432b266e08df490dd625a85a31dd1fb03e68e1afb786b509ca67234739c6680f80bb31dd4c6da4212ae8dc8e5e0ff83679cfe8036d20ce4154044ae026f98c7e926fd492687e6ba80a2f&X-Goog-SignedHeaders=host&X-User=2931823730 (Caused by NewConnectionError('<urllib3.connection.HTTPSConnection object at 0x7f702edb52a0>: Failed to establish a new connection: [Errno 101] Network is unreachable'))
2025-04-11 15:00:47,315 ERROR   wandb-upload_1:20960 [internal_api.py:upload_file():2558] upload_file request headers: {'User-Agent': 'python-requests/2.32.3', 'Accept-Encoding': 'gzip, deflate, br', 'Accept': '*/*', 'Connection': 'keep-alive', 'Content-Length': '8666'}
2025-04-11 15:00:47,316 ERROR   wandb-upload_1:20960 [internal_api.py:upload_file():2560] upload_file response body: 
2025-04-11 15:00:47,519 DEBUG   HandlerThread:20960 [handler.py:handle_request():146] handle_request: poll_exit
2025-04-11 15:00:47,519 DEBUG   SenderThread:20960 [sender.py:send_request():407] send_request: poll_exit
2025-04-11 15:00:47,609 ERROR   wandb-upload_5:20960 [internal_api.py:upload_file():2556] upload_file exception https://storage.googleapis.com/wandb-production.appspot.com/2931823730-harbin-institute-of-technology/ltu-as/p17gmulg/wandb-summary.json?X-Goog-Algorithm=GOOG4-RSA-SHA256&X-Goog-Credential=gorilla-files-url-signer-man%40wandb-production.iam.gserviceaccount.com%2F20250411%2Fauto%2Fstorage%2Fgoog4_request&X-Goog-Date=20250411T150044Z&X-Goog-Expires=86399&X-Goog-Signature=24104ea3df52b0b0fce0141d2d6615d36298eb5ea08485b2dc4a616d8119698ba118d11a5f44e94354266eab45d4324499348fa21cbe0c4ba8fa5416f5d335df3cfd7f6375fd0c35836e0226a4611fe7b4e0f043aecba8910f16dbbe5ef52e0c1717e30949ed1b19d3656214206bf4119b065b8502f7c60223b66c33a0f306ebfb9892023b673278d5fc199b3db2f45eb469e4325de8426d897ab25d2fdef8b01f20a0e0440edd3be494bd732b6c55ed61f734c068dbb035289a3be40f4fe4597d3935b3425583450c92d72d5d0ffba8a0ff9533eab69377449395aab5b7bb990fbe8cc08bff93c2c6504738548e83e4a5e31b2924272307412886d6276d63ca&X-Goog-SignedHeaders=host&X-User=2931823730: HTTPSConnectionPool(host='storage.googleapis.com', port=443): Max retries exceeded with url: /wandb-production.appspot.com/2931823730-harbin-institute-of-technology/ltu-as/p17gmulg/wandb-summary.json?X-Goog-Algorithm=GOOG4-RSA-SHA256&X-Goog-Credential=gorilla-files-url-signer-man%40wandb-production.iam.gserviceaccount.com%2F20250411%2Fauto%2Fstorage%2Fgoog4_request&X-Goog-Date=20250411T150044Z&X-Goog-Expires=86399&X-Goog-Signature=24104ea3df52b0b0fce0141d2d6615d36298eb5ea08485b2dc4a616d8119698ba118d11a5f44e94354266eab45d4324499348fa21cbe0c4ba8fa5416f5d335df3cfd7f6375fd0c35836e0226a4611fe7b4e0f043aecba8910f16dbbe5ef52e0c1717e30949ed1b19d3656214206bf4119b065b8502f7c60223b66c33a0f306ebfb9892023b673278d5fc199b3db2f45eb469e4325de8426d897ab25d2fdef8b01f20a0e0440edd3be494bd732b6c55ed61f734c068dbb035289a3be40f4fe4597d3935b3425583450c92d72d5d0ffba8a0ff9533eab69377449395aab5b7bb990fbe8cc08bff93c2c6504738548e83e4a5e31b2924272307412886d6276d63ca&X-Goog-SignedHeaders=host&X-User=2931823730 (Caused by NewConnectionError('<urllib3.connection.HTTPSConnection object at 0x7f702edb5ed0>: Failed to establish a new connection: [Errno 101] Network is unreachable'))
2025-04-11 15:00:47,609 ERROR   wandb-upload_5:20960 [internal_api.py:upload_file():2558] upload_file request headers: {'User-Agent': 'python-requests/2.32.3', 'Accept-Encoding': 'gzip, deflate, br', 'Accept': '*/*', 'Connection': 'keep-alive', 'Content-Length': '27'}
2025-04-11 15:00:47,609 ERROR   wandb-upload_5:20960 [internal_api.py:upload_file():2560] upload_file response body: 
2025-04-11 15:00:47,665 ERROR   wandb-upload_3:20960 [internal_api.py:upload_file():2556] upload_file exception https://storage.googleapis.com/wandb-production.appspot.com/2931823730-harbin-institute-of-technology/ltu-as/p17gmulg/conda-environment.yaml?X-Goog-Algorithm=GOOG4-RSA-SHA256&X-Goog-Credential=gorilla-files-url-signer-man%40wandb-production.iam.gserviceaccount.com%2F20250411%2Fauto%2Fstorage%2Fgoog4_request&X-Goog-Date=20250411T150043Z&X-Goog-Expires=86399&X-Goog-Signature=00f2737f97b7b1f937f7a9aebdfea9b77a2c6c8e1517ac5604b0ab1d0c7220099661943fa06351c6a2fc07c285f7cde727cfd97257af5eec33c10ff58653cf9d6ebbfa07ca47153a6c0bb6e66bdc5460d4faccd98405adea9703c4f7553f8301273fcfa04cced1cd05c064254e7dbb600c8767e195c3109aa0466581c2735ab0ed4b1f21f2ba2046c29b2199a29cbcedb0f7ba1bce4992ef9fd04257dff85ead08d2ea2f4e835b64a2a3428bb295fd3523de6c1dbcd055c8962bd057f4c676fa028b90c343670ac851f3c26fc59ad1f13a6de4c9ea39dcbd845b4092616d0fe18bd2b09525b48943a5122a270e5637a422663aefc15274ec3ff901174e8eed50&X-Goog-SignedHeaders=host&X-User=2931823730: HTTPSConnectionPool(host='storage.googleapis.com', port=443): Max retries exceeded with url: /wandb-production.appspot.com/2931823730-harbin-institute-of-technology/ltu-as/p17gmulg/conda-environment.yaml?X-Goog-Algorithm=GOOG4-RSA-SHA256&X-Goog-Credential=gorilla-files-url-signer-man%40wandb-production.iam.gserviceaccount.com%2F20250411%2Fauto%2Fstorage%2Fgoog4_request&X-Goog-Date=20250411T150043Z&X-Goog-Expires=86399&X-Goog-Signature=00f2737f97b7b1f937f7a9aebdfea9b77a2c6c8e1517ac5604b0ab1d0c7220099661943fa06351c6a2fc07c285f7cde727cfd97257af5eec33c10ff58653cf9d6ebbfa07ca47153a6c0bb6e66bdc5460d4faccd98405adea9703c4f7553f8301273fcfa04cced1cd05c064254e7dbb600c8767e195c3109aa0466581c2735ab0ed4b1f21f2ba2046c29b2199a29cbcedb0f7ba1bce4992ef9fd04257dff85ead08d2ea2f4e835b64a2a3428bb295fd3523de6c1dbcd055c8962bd057f4c676fa028b90c343670ac851f3c26fc59ad1f13a6de4c9ea39dcbd845b4092616d0fe18bd2b09525b48943a5122a270e5637a422663aefc15274ec3ff901174e8eed50&X-Goog-SignedHeaders=host&X-User=2931823730 (Caused by NewConnectionError('<urllib3.connection.HTTPSConnection object at 0x7f702edb5f60>: Failed to establish a new connection: [Errno 101] Network is unreachable'))
2025-04-11 15:00:47,665 ERROR   wandb-upload_3:20960 [internal_api.py:upload_file():2558] upload_file request headers: {'User-Agent': 'python-requests/2.32.3', 'Accept-Encoding': 'gzip, deflate, br', 'Accept': '*/*', 'Connection': 'keep-alive', 'Content-Length': '8281'}
2025-04-11 15:00:47,665 ERROR   wandb-upload_3:20960 [internal_api.py:upload_file():2560] upload_file response body: 
2025-04-11 15:00:48,520 DEBUG   HandlerThread:20960 [handler.py:handle_request():146] handle_request: status_report
2025-04-11 15:00:48,521 DEBUG   HandlerThread:20960 [handler.py:handle_request():146] handle_request: poll_exit
2025-04-11 15:00:48,522 DEBUG   SenderThread:20960 [sender.py:send_request():407] send_request: poll_exit
2025-04-11 15:00:49,523 DEBUG   HandlerThread:20960 [handler.py:handle_request():146] handle_request: poll_exit
2025-04-11 15:00:49,525 DEBUG   SenderThread:20960 [sender.py:send_request():407] send_request: poll_exit
2025-04-11 15:00:50,525 DEBUG   HandlerThread:20960 [handler.py:handle_request():146] handle_request: poll_exit
2025-04-11 15:00:50,526 DEBUG   SenderThread:20960 [sender.py:send_request():407] send_request: poll_exit
2025-04-11 15:00:51,127 ERROR   wandb-upload_4:20960 [internal_api.py:upload_file():2556] upload_file exception https://storage.googleapis.com/wandb-production.appspot.com/2931823730-harbin-institute-of-technology/ltu-as/p17gmulg/output.log?X-Goog-Algorithm=GOOG4-RSA-SHA256&X-Goog-Credential=gorilla-files-url-signer-man%40wandb-production.iam.gserviceaccount.com%2F20250411%2Fauto%2Fstorage%2Fgoog4_request&X-Goog-Date=20250411T150043Z&X-Goog-Expires=86399&X-Goog-Signature=0308420c548c6bc687992243d2a177fab7c1e559bf54fdb3fcef576cbdb35fedc146e60d263e4a67d7dcf10d49fc5fce2b200db779ede9932190768ef7045285e94ebcab25d5c53df1ac3faccb2e1b3123697207c801b2f9ed9445e272209bc83528d2b276b120193046794812b634842c87ec4fb6a455019b7629adb328930593761b298218336a3352fe2b3ff4677801486c5fbe6d691a897ba443a75ff0090308631a57a9f25c185a2aa064157f9fcd720807f256f1830810dbc582f2f82e719ba0316a4b5743320f3ccfc2826623c2139bccbce4c58bcebd511da09c54dcb483ba9d761279f3786b202a99bd6e9a82147286632175a2481cd79591fa6901&X-Goog-SignedHeaders=host&X-User=2931823730: HTTPSConnectionPool(host='storage.googleapis.com', port=443): Max retries exceeded with url: /wandb-production.appspot.com/2931823730-harbin-institute-of-technology/ltu-as/p17gmulg/output.log?X-Goog-Algorithm=GOOG4-RSA-SHA256&X-Goog-Credential=gorilla-files-url-signer-man%40wandb-production.iam.gserviceaccount.com%2F20250411%2Fauto%2Fstorage%2Fgoog4_request&X-Goog-Date=20250411T150043Z&X-Goog-Expires=86399&X-Goog-Signature=0308420c548c6bc687992243d2a177fab7c1e559bf54fdb3fcef576cbdb35fedc146e60d263e4a67d7dcf10d49fc5fce2b200db779ede9932190768ef7045285e94ebcab25d5c53df1ac3faccb2e1b3123697207c801b2f9ed9445e272209bc83528d2b276b120193046794812b634842c87ec4fb6a455019b7629adb328930593761b298218336a3352fe2b3ff4677801486c5fbe6d691a897ba443a75ff0090308631a57a9f25c185a2aa064157f9fcd720807f256f1830810dbc582f2f82e719ba0316a4b5743320f3ccfc2826623c2139bccbce4c58bcebd511da09c54dcb483ba9d761279f3786b202a99bd6e9a82147286632175a2481cd79591fa6901&X-Goog-SignedHeaders=host&X-User=2931823730 (Caused by NewConnectionError('<urllib3.connection.HTTPSConnection object at 0x7f702edb5780>: Failed to establish a new connection: [Errno 101] Network is unreachable'))
2025-04-11 15:00:51,127 ERROR   wandb-upload_4:20960 [internal_api.py:upload_file():2558] upload_file request headers: {'User-Agent': 'python-requests/2.32.3', 'Accept-Encoding': 'gzip, deflate, br', 'Accept': '*/*', 'Connection': 'keep-alive', 'Content-Length': '4566'}
2025-04-11 15:00:51,127 ERROR   wandb-upload_4:20960 [internal_api.py:upload_file():2560] upload_file response body: 
2025-04-11 15:00:51,295 ERROR   wandb-upload_2:20960 [internal_api.py:upload_file():2556] upload_file exception https://storage.googleapis.com/wandb-production.appspot.com/2931823730-harbin-institute-of-technology/ltu-as/p17gmulg/requirements.txt?X-Goog-Algorithm=GOOG4-RSA-SHA256&X-Goog-Credential=gorilla-files-url-signer-man%40wandb-production.iam.gserviceaccount.com%2F20250411%2Fauto%2Fstorage%2Fgoog4_request&X-Goog-Date=20250411T150043Z&X-Goog-Expires=86399&X-Goog-Signature=14dcd9bd7741ba854922781779b244d065a2f93e20042ce112d03d9a74fa6ceafd1a02b76cfe7e1d83ceecfb3b6c3b3ccc9fadcd34593f606440f4b7136578ec49a47ec7af23ddefb386a812922c26eb929dc0da3c7b5a24d04fe645d171ed6cbdf2dd3f41534425b4a709b793de783fa2b973ef1eb68ca4cbc8697ba576ff13534ced1f4976d8b3d7739d7b5ee6c113c7c67453905e7311f37f8bde9ebd13a60597a748a421ab730351a19b37ae016bf30b884b6e554c62df963c76284dfca9faf6a980b28817387e6dc67e8ed6fd758c92deb55a34f2eb5b303f7083028b548986861f2398dbaa3b2d08172b60c61edf28e44efed84920699974adac927b5f&X-Goog-SignedHeaders=host&X-User=2931823730: HTTPSConnectionPool(host='storage.googleapis.com', port=443): Max retries exceeded with url: /wandb-production.appspot.com/2931823730-harbin-institute-of-technology/ltu-as/p17gmulg/requirements.txt?X-Goog-Algorithm=GOOG4-RSA-SHA256&X-Goog-Credential=gorilla-files-url-signer-man%40wandb-production.iam.gserviceaccount.com%2F20250411%2Fauto%2Fstorage%2Fgoog4_request&X-Goog-Date=20250411T150043Z&X-Goog-Expires=86399&X-Goog-Signature=14dcd9bd7741ba854922781779b244d065a2f93e20042ce112d03d9a74fa6ceafd1a02b76cfe7e1d83ceecfb3b6c3b3ccc9fadcd34593f606440f4b7136578ec49a47ec7af23ddefb386a812922c26eb929dc0da3c7b5a24d04fe645d171ed6cbdf2dd3f41534425b4a709b793de783fa2b973ef1eb68ca4cbc8697ba576ff13534ced1f4976d8b3d7739d7b5ee6c113c7c67453905e7311f37f8bde9ebd13a60597a748a421ab730351a19b37ae016bf30b884b6e554c62df963c76284dfca9faf6a980b28817387e6dc67e8ed6fd758c92deb55a34f2eb5b303f7083028b548986861f2398dbaa3b2d08172b60c61edf28e44efed84920699974adac927b5f&X-Goog-SignedHeaders=host&X-User=2931823730 (Caused by NewConnectionError('<urllib3.connection.HTTPSConnection object at 0x7f702edb5120>: Failed to establish a new connection: [Errno 101] Network is unreachable'))
2025-04-11 15:00:51,296 ERROR   wandb-upload_2:20960 [internal_api.py:upload_file():2558] upload_file request headers: {'User-Agent': 'python-requests/2.32.3', 'Accept-Encoding': 'gzip, deflate, br', 'Accept': '*/*', 'Connection': 'keep-alive', 'Content-Length': '4212'}
2025-04-11 15:00:51,296 ERROR   wandb-upload_2:20960 [internal_api.py:upload_file():2560] upload_file response body: 
2025-04-11 15:00:51,527 DEBUG   HandlerThread:20960 [handler.py:handle_request():146] handle_request: poll_exit
2025-04-11 15:00:51,528 DEBUG   SenderThread:20960 [sender.py:send_request():407] send_request: poll_exit
2025-04-11 15:00:51,596 ERROR   wandb-upload_1:20960 [internal_api.py:upload_file():2556] upload_file exception https://storage.googleapis.com/wandb-production.appspot.com/2931823730-harbin-institute-of-technology/ltu-as/p17gmulg/config.yaml?X-Goog-Algorithm=GOOG4-RSA-SHA256&X-Goog-Credential=gorilla-files-url-signer-man%40wandb-production.iam.gserviceaccount.com%2F20250411%2Fauto%2Fstorage%2Fgoog4_request&X-Goog-Date=20250411T150043Z&X-Goog-Expires=86399&X-Goog-Signature=2b94521395b91d2c6da28bc88c8fc2fc455de0bcface43802f47c8b6e4bc65bb0576e272b4d89ff080de61ad7e2630455fac8f8556a8d2a1ec83e0f726c7121de7b3c84adbbc041acaa6d30505fb9bb73aba360d8d7b4ca92305f90ec83f114c9376b107f51e30bb10fe0101942367b2da5037b93caba63940e541e0ffa3d92a71c487bd952d659a72612e9bb29d3d5e5ae6c723dd8f91e2eb021292ec34d2126321481511017f837aa8cc0777e29c645f288e5c68da432b266e08df490dd625a85a31dd1fb03e68e1afb786b509ca67234739c6680f80bb31dd4c6da4212ae8dc8e5e0ff83679cfe8036d20ce4154044ae026f98c7e926fd492687e6ba80a2f&X-Goog-SignedHeaders=host&X-User=2931823730: HTTPSConnectionPool(host='storage.googleapis.com', port=443): Max retries exceeded with url: /wandb-production.appspot.com/2931823730-harbin-institute-of-technology/ltu-as/p17gmulg/config.yaml?X-Goog-Algorithm=GOOG4-RSA-SHA256&X-Goog-Credential=gorilla-files-url-signer-man%40wandb-production.iam.gserviceaccount.com%2F20250411%2Fauto%2Fstorage%2Fgoog4_request&X-Goog-Date=20250411T150043Z&X-Goog-Expires=86399&X-Goog-Signature=2b94521395b91d2c6da28bc88c8fc2fc455de0bcface43802f47c8b6e4bc65bb0576e272b4d89ff080de61ad7e2630455fac8f8556a8d2a1ec83e0f726c7121de7b3c84adbbc041acaa6d30505fb9bb73aba360d8d7b4ca92305f90ec83f114c9376b107f51e30bb10fe0101942367b2da5037b93caba63940e541e0ffa3d92a71c487bd952d659a72612e9bb29d3d5e5ae6c723dd8f91e2eb021292ec34d2126321481511017f837aa8cc0777e29c645f288e5c68da432b266e08df490dd625a85a31dd1fb03e68e1afb786b509ca67234739c6680f80bb31dd4c6da4212ae8dc8e5e0ff83679cfe8036d20ce4154044ae026f98c7e926fd492687e6ba80a2f&X-Goog-SignedHeaders=host&X-User=2931823730 (Caused by NewConnectionError('<urllib3.connection.HTTPSConnection object at 0x7f702edb73a0>: Failed to establish a new connection: [Errno 101] Network is unreachable'))
2025-04-11 15:00:51,596 ERROR   wandb-upload_1:20960 [internal_api.py:upload_file():2558] upload_file request headers: {'User-Agent': 'python-requests/2.32.3', 'Accept-Encoding': 'gzip, deflate, br', 'Accept': '*/*', 'Connection': 'keep-alive', 'Content-Length': '8666'}
2025-04-11 15:00:51,596 ERROR   wandb-upload_1:20960 [internal_api.py:upload_file():2560] upload_file response body: 
2025-04-11 15:00:51,819 ERROR   wandb-upload_5:20960 [internal_api.py:upload_file():2556] upload_file exception https://storage.googleapis.com/wandb-production.appspot.com/2931823730-harbin-institute-of-technology/ltu-as/p17gmulg/wandb-summary.json?X-Goog-Algorithm=GOOG4-RSA-SHA256&X-Goog-Credential=gorilla-files-url-signer-man%40wandb-production.iam.gserviceaccount.com%2F20250411%2Fauto%2Fstorage%2Fgoog4_request&X-Goog-Date=20250411T150044Z&X-Goog-Expires=86399&X-Goog-Signature=24104ea3df52b0b0fce0141d2d6615d36298eb5ea08485b2dc4a616d8119698ba118d11a5f44e94354266eab45d4324499348fa21cbe0c4ba8fa5416f5d335df3cfd7f6375fd0c35836e0226a4611fe7b4e0f043aecba8910f16dbbe5ef52e0c1717e30949ed1b19d3656214206bf4119b065b8502f7c60223b66c33a0f306ebfb9892023b673278d5fc199b3db2f45eb469e4325de8426d897ab25d2fdef8b01f20a0e0440edd3be494bd732b6c55ed61f734c068dbb035289a3be40f4fe4597d3935b3425583450c92d72d5d0ffba8a0ff9533eab69377449395aab5b7bb990fbe8cc08bff93c2c6504738548e83e4a5e31b2924272307412886d6276d63ca&X-Goog-SignedHeaders=host&X-User=2931823730: HTTPSConnectionPool(host='storage.googleapis.com', port=443): Max retries exceeded with url: /wandb-production.appspot.com/2931823730-harbin-institute-of-technology/ltu-as/p17gmulg/wandb-summary.json?X-Goog-Algorithm=GOOG4-RSA-SHA256&X-Goog-Credential=gorilla-files-url-signer-man%40wandb-production.iam.gserviceaccount.com%2F20250411%2Fauto%2Fstorage%2Fgoog4_request&X-Goog-Date=20250411T150044Z&X-Goog-Expires=86399&X-Goog-Signature=24104ea3df52b0b0fce0141d2d6615d36298eb5ea08485b2dc4a616d8119698ba118d11a5f44e94354266eab45d4324499348fa21cbe0c4ba8fa5416f5d335df3cfd7f6375fd0c35836e0226a4611fe7b4e0f043aecba8910f16dbbe5ef52e0c1717e30949ed1b19d3656214206bf4119b065b8502f7c60223b66c33a0f306ebfb9892023b673278d5fc199b3db2f45eb469e4325de8426d897ab25d2fdef8b01f20a0e0440edd3be494bd732b6c55ed61f734c068dbb035289a3be40f4fe4597d3935b3425583450c92d72d5d0ffba8a0ff9533eab69377449395aab5b7bb990fbe8cc08bff93c2c6504738548e83e4a5e31b2924272307412886d6276d63ca&X-Goog-SignedHeaders=host&X-User=2931823730 (Caused by NewConnectionError('<urllib3.connection.HTTPSConnection object at 0x7f702edb7280>: Failed to establish a new connection: [Errno 101] Network is unreachable'))
2025-04-11 15:00:51,819 ERROR   wandb-upload_5:20960 [internal_api.py:upload_file():2558] upload_file request headers: {'User-Agent': 'python-requests/2.32.3', 'Accept-Encoding': 'gzip, deflate, br', 'Accept': '*/*', 'Connection': 'keep-alive', 'Content-Length': '27'}
2025-04-11 15:00:51,819 ERROR   wandb-upload_5:20960 [internal_api.py:upload_file():2560] upload_file response body: 
2025-04-11 15:00:51,899 ERROR   wandb-upload_3:20960 [internal_api.py:upload_file():2556] upload_file exception https://storage.googleapis.com/wandb-production.appspot.com/2931823730-harbin-institute-of-technology/ltu-as/p17gmulg/conda-environment.yaml?X-Goog-Algorithm=GOOG4-RSA-SHA256&X-Goog-Credential=gorilla-files-url-signer-man%40wandb-production.iam.gserviceaccount.com%2F20250411%2Fauto%2Fstorage%2Fgoog4_request&X-Goog-Date=20250411T150043Z&X-Goog-Expires=86399&X-Goog-Signature=00f2737f97b7b1f937f7a9aebdfea9b77a2c6c8e1517ac5604b0ab1d0c7220099661943fa06351c6a2fc07c285f7cde727cfd97257af5eec33c10ff58653cf9d6ebbfa07ca47153a6c0bb6e66bdc5460d4faccd98405adea9703c4f7553f8301273fcfa04cced1cd05c064254e7dbb600c8767e195c3109aa0466581c2735ab0ed4b1f21f2ba2046c29b2199a29cbcedb0f7ba1bce4992ef9fd04257dff85ead08d2ea2f4e835b64a2a3428bb295fd3523de6c1dbcd055c8962bd057f4c676fa028b90c343670ac851f3c26fc59ad1f13a6de4c9ea39dcbd845b4092616d0fe18bd2b09525b48943a5122a270e5637a422663aefc15274ec3ff901174e8eed50&X-Goog-SignedHeaders=host&X-User=2931823730: HTTPSConnectionPool(host='storage.googleapis.com', port=443): Max retries exceeded with url: /wandb-production.appspot.com/2931823730-harbin-institute-of-technology/ltu-as/p17gmulg/conda-environment.yaml?X-Goog-Algorithm=GOOG4-RSA-SHA256&X-Goog-Credential=gorilla-files-url-signer-man%40wandb-production.iam.gserviceaccount.com%2F20250411%2Fauto%2Fstorage%2Fgoog4_request&X-Goog-Date=20250411T150043Z&X-Goog-Expires=86399&X-Goog-Signature=00f2737f97b7b1f937f7a9aebdfea9b77a2c6c8e1517ac5604b0ab1d0c7220099661943fa06351c6a2fc07c285f7cde727cfd97257af5eec33c10ff58653cf9d6ebbfa07ca47153a6c0bb6e66bdc5460d4faccd98405adea9703c4f7553f8301273fcfa04cced1cd05c064254e7dbb600c8767e195c3109aa0466581c2735ab0ed4b1f21f2ba2046c29b2199a29cbcedb0f7ba1bce4992ef9fd04257dff85ead08d2ea2f4e835b64a2a3428bb295fd3523de6c1dbcd055c8962bd057f4c676fa028b90c343670ac851f3c26fc59ad1f13a6de4c9ea39dcbd845b4092616d0fe18bd2b09525b48943a5122a270e5637a422663aefc15274ec3ff901174e8eed50&X-Goog-SignedHeaders=host&X-User=2931823730 (Caused by NewConnectionError('<urllib3.connection.HTTPSConnection object at 0x7f702edb6830>: Failed to establish a new connection: [Errno 101] Network is unreachable'))
2025-04-11 15:00:51,899 ERROR   wandb-upload_3:20960 [internal_api.py:upload_file():2558] upload_file request headers: {'User-Agent': 'python-requests/2.32.3', 'Accept-Encoding': 'gzip, deflate, br', 'Accept': '*/*', 'Connection': 'keep-alive', 'Content-Length': '8281'}
2025-04-11 15:00:51,899 ERROR   wandb-upload_3:20960 [internal_api.py:upload_file():2560] upload_file response body: 
2025-04-11 15:00:52,528 DEBUG   HandlerThread:20960 [handler.py:handle_request():146] handle_request: poll_exit
2025-04-11 15:00:52,529 DEBUG   SenderThread:20960 [sender.py:send_request():407] send_request: poll_exit
2025-04-11 15:00:53,530 DEBUG   HandlerThread:20960 [handler.py:handle_request():146] handle_request: status_report
2025-04-11 15:00:53,531 DEBUG   HandlerThread:20960 [handler.py:handle_request():146] handle_request: poll_exit
2025-04-11 15:00:53,532 DEBUG   SenderThread:20960 [sender.py:send_request():407] send_request: poll_exit
2025-04-11 15:00:54,533 DEBUG   HandlerThread:20960 [handler.py:handle_request():146] handle_request: poll_exit
2025-04-11 15:00:54,535 DEBUG   SenderThread:20960 [sender.py:send_request():407] send_request: poll_exit
2025-04-11 15:00:55,535 DEBUG   HandlerThread:20960 [handler.py:handle_request():146] handle_request: poll_exit
2025-04-11 15:00:55,536 DEBUG   SenderThread:20960 [sender.py:send_request():407] send_request: poll_exit
2025-04-11 15:00:56,536 DEBUG   HandlerThread:20960 [handler.py:handle_request():146] handle_request: poll_exit
2025-04-11 15:00:56,538 DEBUG   SenderThread:20960 [sender.py:send_request():407] send_request: poll_exit
2025-04-11 15:00:57,538 DEBUG   HandlerThread:20960 [handler.py:handle_request():146] handle_request: poll_exit
2025-04-11 15:00:57,539 DEBUG   SenderThread:20960 [sender.py:send_request():407] send_request: poll_exit
2025-04-11 15:00:58,540 DEBUG   HandlerThread:20960 [handler.py:handle_request():146] handle_request: poll_exit
2025-04-11 15:00:58,540 DEBUG   HandlerThread:20960 [handler.py:handle_request():146] handle_request: status_report
2025-04-11 15:00:58,541 DEBUG   SenderThread:20960 [sender.py:send_request():407] send_request: poll_exit
2025-04-11 15:00:59,542 DEBUG   HandlerThread:20960 [handler.py:handle_request():146] handle_request: poll_exit
2025-04-11 15:00:59,543 DEBUG   SenderThread:20960 [sender.py:send_request():407] send_request: poll_exit
2025-04-11 15:00:59,837 ERROR   wandb-upload_2:20960 [internal_api.py:upload_file():2556] upload_file exception https://storage.googleapis.com/wandb-production.appspot.com/2931823730-harbin-institute-of-technology/ltu-as/p17gmulg/requirements.txt?X-Goog-Algorithm=GOOG4-RSA-SHA256&X-Goog-Credential=gorilla-files-url-signer-man%40wandb-production.iam.gserviceaccount.com%2F20250411%2Fauto%2Fstorage%2Fgoog4_request&X-Goog-Date=20250411T150043Z&X-Goog-Expires=86399&X-Goog-Signature=14dcd9bd7741ba854922781779b244d065a2f93e20042ce112d03d9a74fa6ceafd1a02b76cfe7e1d83ceecfb3b6c3b3ccc9fadcd34593f606440f4b7136578ec49a47ec7af23ddefb386a812922c26eb929dc0da3c7b5a24d04fe645d171ed6cbdf2dd3f41534425b4a709b793de783fa2b973ef1eb68ca4cbc8697ba576ff13534ced1f4976d8b3d7739d7b5ee6c113c7c67453905e7311f37f8bde9ebd13a60597a748a421ab730351a19b37ae016bf30b884b6e554c62df963c76284dfca9faf6a980b28817387e6dc67e8ed6fd758c92deb55a34f2eb5b303f7083028b548986861f2398dbaa3b2d08172b60c61edf28e44efed84920699974adac927b5f&X-Goog-SignedHeaders=host&X-User=2931823730: HTTPSConnectionPool(host='storage.googleapis.com', port=443): Max retries exceeded with url: /wandb-production.appspot.com/2931823730-harbin-institute-of-technology/ltu-as/p17gmulg/requirements.txt?X-Goog-Algorithm=GOOG4-RSA-SHA256&X-Goog-Credential=gorilla-files-url-signer-man%40wandb-production.iam.gserviceaccount.com%2F20250411%2Fauto%2Fstorage%2Fgoog4_request&X-Goog-Date=20250411T150043Z&X-Goog-Expires=86399&X-Goog-Signature=14dcd9bd7741ba854922781779b244d065a2f93e20042ce112d03d9a74fa6ceafd1a02b76cfe7e1d83ceecfb3b6c3b3ccc9fadcd34593f606440f4b7136578ec49a47ec7af23ddefb386a812922c26eb929dc0da3c7b5a24d04fe645d171ed6cbdf2dd3f41534425b4a709b793de783fa2b973ef1eb68ca4cbc8697ba576ff13534ced1f4976d8b3d7739d7b5ee6c113c7c67453905e7311f37f8bde9ebd13a60597a748a421ab730351a19b37ae016bf30b884b6e554c62df963c76284dfca9faf6a980b28817387e6dc67e8ed6fd758c92deb55a34f2eb5b303f7083028b548986861f2398dbaa3b2d08172b60c61edf28e44efed84920699974adac927b5f&X-Goog-SignedHeaders=host&X-User=2931823730 (Caused by NewConnectionError('<urllib3.connection.HTTPSConnection object at 0x7f702edb5300>: Failed to establish a new connection: [Errno 101] Network is unreachable'))
2025-04-11 15:00:59,837 ERROR   wandb-upload_2:20960 [internal_api.py:upload_file():2558] upload_file request headers: {'User-Agent': 'python-requests/2.32.3', 'Accept-Encoding': 'gzip, deflate, br', 'Accept': '*/*', 'Connection': 'keep-alive', 'Content-Length': '4212'}
2025-04-11 15:00:59,837 ERROR   wandb-upload_2:20960 [internal_api.py:upload_file():2560] upload_file response body: 
2025-04-11 15:01:00,242 ERROR   wandb-upload_3:20960 [internal_api.py:upload_file():2556] upload_file exception https://storage.googleapis.com/wandb-production.appspot.com/2931823730-harbin-institute-of-technology/ltu-as/p17gmulg/conda-environment.yaml?X-Goog-Algorithm=GOOG4-RSA-SHA256&X-Goog-Credential=gorilla-files-url-signer-man%40wandb-production.iam.gserviceaccount.com%2F20250411%2Fauto%2Fstorage%2Fgoog4_request&X-Goog-Date=20250411T150043Z&X-Goog-Expires=86399&X-Goog-Signature=00f2737f97b7b1f937f7a9aebdfea9b77a2c6c8e1517ac5604b0ab1d0c7220099661943fa06351c6a2fc07c285f7cde727cfd97257af5eec33c10ff58653cf9d6ebbfa07ca47153a6c0bb6e66bdc5460d4faccd98405adea9703c4f7553f8301273fcfa04cced1cd05c064254e7dbb600c8767e195c3109aa0466581c2735ab0ed4b1f21f2ba2046c29b2199a29cbcedb0f7ba1bce4992ef9fd04257dff85ead08d2ea2f4e835b64a2a3428bb295fd3523de6c1dbcd055c8962bd057f4c676fa028b90c343670ac851f3c26fc59ad1f13a6de4c9ea39dcbd845b4092616d0fe18bd2b09525b48943a5122a270e5637a422663aefc15274ec3ff901174e8eed50&X-Goog-SignedHeaders=host&X-User=2931823730: HTTPSConnectionPool(host='storage.googleapis.com', port=443): Max retries exceeded with url: /wandb-production.appspot.com/2931823730-harbin-institute-of-technology/ltu-as/p17gmulg/conda-environment.yaml?X-Goog-Algorithm=GOOG4-RSA-SHA256&X-Goog-Credential=gorilla-files-url-signer-man%40wandb-production.iam.gserviceaccount.com%2F20250411%2Fauto%2Fstorage%2Fgoog4_request&X-Goog-Date=20250411T150043Z&X-Goog-Expires=86399&X-Goog-Signature=00f2737f97b7b1f937f7a9aebdfea9b77a2c6c8e1517ac5604b0ab1d0c7220099661943fa06351c6a2fc07c285f7cde727cfd97257af5eec33c10ff58653cf9d6ebbfa07ca47153a6c0bb6e66bdc5460d4faccd98405adea9703c4f7553f8301273fcfa04cced1cd05c064254e7dbb600c8767e195c3109aa0466581c2735ab0ed4b1f21f2ba2046c29b2199a29cbcedb0f7ba1bce4992ef9fd04257dff85ead08d2ea2f4e835b64a2a3428bb295fd3523de6c1dbcd055c8962bd057f4c676fa028b90c343670ac851f3c26fc59ad1f13a6de4c9ea39dcbd845b4092616d0fe18bd2b09525b48943a5122a270e5637a422663aefc15274ec3ff901174e8eed50&X-Goog-SignedHeaders=host&X-User=2931823730 (Caused by NewConnectionError('<urllib3.connection.HTTPSConnection object at 0x7f706698ecb0>: Failed to establish a new connection: [Errno 101] Network is unreachable'))
2025-04-11 15:01:00,242 ERROR   wandb-upload_3:20960 [internal_api.py:upload_file():2558] upload_file request headers: {'User-Agent': 'python-requests/2.32.3', 'Accept-Encoding': 'gzip, deflate, br', 'Accept': '*/*', 'Connection': 'keep-alive', 'Content-Length': '8281'}
2025-04-11 15:01:00,242 ERROR   wandb-upload_3:20960 [internal_api.py:upload_file():2560] upload_file response body: 
2025-04-11 15:01:00,544 DEBUG   HandlerThread:20960 [handler.py:handle_request():146] handle_request: poll_exit
2025-04-11 15:01:00,545 DEBUG   SenderThread:20960 [sender.py:send_request():407] send_request: poll_exit
2025-04-11 15:01:00,949 ERROR   wandb-upload_4:20960 [internal_api.py:upload_file():2556] upload_file exception https://storage.googleapis.com/wandb-production.appspot.com/2931823730-harbin-institute-of-technology/ltu-as/p17gmulg/output.log?X-Goog-Algorithm=GOOG4-RSA-SHA256&X-Goog-Credential=gorilla-files-url-signer-man%40wandb-production.iam.gserviceaccount.com%2F20250411%2Fauto%2Fstorage%2Fgoog4_request&X-Goog-Date=20250411T150043Z&X-Goog-Expires=86399&X-Goog-Signature=0308420c548c6bc687992243d2a177fab7c1e559bf54fdb3fcef576cbdb35fedc146e60d263e4a67d7dcf10d49fc5fce2b200db779ede9932190768ef7045285e94ebcab25d5c53df1ac3faccb2e1b3123697207c801b2f9ed9445e272209bc83528d2b276b120193046794812b634842c87ec4fb6a455019b7629adb328930593761b298218336a3352fe2b3ff4677801486c5fbe6d691a897ba443a75ff0090308631a57a9f25c185a2aa064157f9fcd720807f256f1830810dbc582f2f82e719ba0316a4b5743320f3ccfc2826623c2139bccbce4c58bcebd511da09c54dcb483ba9d761279f3786b202a99bd6e9a82147286632175a2481cd79591fa6901&X-Goog-SignedHeaders=host&X-User=2931823730: HTTPSConnectionPool(host='storage.googleapis.com', port=443): Max retries exceeded with url: /wandb-production.appspot.com/2931823730-harbin-institute-of-technology/ltu-as/p17gmulg/output.log?X-Goog-Algorithm=GOOG4-RSA-SHA256&X-Goog-Credential=gorilla-files-url-signer-man%40wandb-production.iam.gserviceaccount.com%2F20250411%2Fauto%2Fstorage%2Fgoog4_request&X-Goog-Date=20250411T150043Z&X-Goog-Expires=86399&X-Goog-Signature=0308420c548c6bc687992243d2a177fab7c1e559bf54fdb3fcef576cbdb35fedc146e60d263e4a67d7dcf10d49fc5fce2b200db779ede9932190768ef7045285e94ebcab25d5c53df1ac3faccb2e1b3123697207c801b2f9ed9445e272209bc83528d2b276b120193046794812b634842c87ec4fb6a455019b7629adb328930593761b298218336a3352fe2b3ff4677801486c5fbe6d691a897ba443a75ff0090308631a57a9f25c185a2aa064157f9fcd720807f256f1830810dbc582f2f82e719ba0316a4b5743320f3ccfc2826623c2139bccbce4c58bcebd511da09c54dcb483ba9d761279f3786b202a99bd6e9a82147286632175a2481cd79591fa6901&X-Goog-SignedHeaders=host&X-User=2931823730 (Caused by NewConnectionError('<urllib3.connection.HTTPSConnection object at 0x7f706698dc30>: Failed to establish a new connection: [Errno 101] Network is unreachable'))
2025-04-11 15:01:00,949 ERROR   wandb-upload_4:20960 [internal_api.py:upload_file():2558] upload_file request headers: {'User-Agent': 'python-requests/2.32.3', 'Accept-Encoding': 'gzip, deflate, br', 'Accept': '*/*', 'Connection': 'keep-alive', 'Content-Length': '4566'}
2025-04-11 15:01:00,949 ERROR   wandb-upload_4:20960 [internal_api.py:upload_file():2560] upload_file response body: 
2025-04-11 15:01:01,211 ERROR   wandb-upload_5:20960 [internal_api.py:upload_file():2556] upload_file exception https://storage.googleapis.com/wandb-production.appspot.com/2931823730-harbin-institute-of-technology/ltu-as/p17gmulg/wandb-summary.json?X-Goog-Algorithm=GOOG4-RSA-SHA256&X-Goog-Credential=gorilla-files-url-signer-man%40wandb-production.iam.gserviceaccount.com%2F20250411%2Fauto%2Fstorage%2Fgoog4_request&X-Goog-Date=20250411T150044Z&X-Goog-Expires=86399&X-Goog-Signature=24104ea3df52b0b0fce0141d2d6615d36298eb5ea08485b2dc4a616d8119698ba118d11a5f44e94354266eab45d4324499348fa21cbe0c4ba8fa5416f5d335df3cfd7f6375fd0c35836e0226a4611fe7b4e0f043aecba8910f16dbbe5ef52e0c1717e30949ed1b19d3656214206bf4119b065b8502f7c60223b66c33a0f306ebfb9892023b673278d5fc199b3db2f45eb469e4325de8426d897ab25d2fdef8b01f20a0e0440edd3be494bd732b6c55ed61f734c068dbb035289a3be40f4fe4597d3935b3425583450c92d72d5d0ffba8a0ff9533eab69377449395aab5b7bb990fbe8cc08bff93c2c6504738548e83e4a5e31b2924272307412886d6276d63ca&X-Goog-SignedHeaders=host&X-User=2931823730: HTTPSConnectionPool(host='storage.googleapis.com', port=443): Max retries exceeded with url: /wandb-production.appspot.com/2931823730-harbin-institute-of-technology/ltu-as/p17gmulg/wandb-summary.json?X-Goog-Algorithm=GOOG4-RSA-SHA256&X-Goog-Credential=gorilla-files-url-signer-man%40wandb-production.iam.gserviceaccount.com%2F20250411%2Fauto%2Fstorage%2Fgoog4_request&X-Goog-Date=20250411T150044Z&X-Goog-Expires=86399&X-Goog-Signature=24104ea3df52b0b0fce0141d2d6615d36298eb5ea08485b2dc4a616d8119698ba118d11a5f44e94354266eab45d4324499348fa21cbe0c4ba8fa5416f5d335df3cfd7f6375fd0c35836e0226a4611fe7b4e0f043aecba8910f16dbbe5ef52e0c1717e30949ed1b19d3656214206bf4119b065b8502f7c60223b66c33a0f306ebfb9892023b673278d5fc199b3db2f45eb469e4325de8426d897ab25d2fdef8b01f20a0e0440edd3be494bd732b6c55ed61f734c068dbb035289a3be40f4fe4597d3935b3425583450c92d72d5d0ffba8a0ff9533eab69377449395aab5b7bb990fbe8cc08bff93c2c6504738548e83e4a5e31b2924272307412886d6276d63ca&X-Goog-SignedHeaders=host&X-User=2931823730 (Caused by NewConnectionError('<urllib3.connection.HTTPSConnection object at 0x7f702edb5ab0>: Failed to establish a new connection: [Errno 101] Network is unreachable'))
2025-04-11 15:01:01,211 ERROR   wandb-upload_5:20960 [internal_api.py:upload_file():2558] upload_file request headers: {'User-Agent': 'python-requests/2.32.3', 'Accept-Encoding': 'gzip, deflate, br', 'Accept': '*/*', 'Connection': 'keep-alive', 'Content-Length': '27'}
2025-04-11 15:01:01,211 ERROR   wandb-upload_5:20960 [internal_api.py:upload_file():2560] upload_file response body: 
2025-04-11 15:01:01,214 ERROR   wandb-upload_1:20960 [internal_api.py:upload_file():2556] upload_file exception https://storage.googleapis.com/wandb-production.appspot.com/2931823730-harbin-institute-of-technology/ltu-as/p17gmulg/config.yaml?X-Goog-Algorithm=GOOG4-RSA-SHA256&X-Goog-Credential=gorilla-files-url-signer-man%40wandb-production.iam.gserviceaccount.com%2F20250411%2Fauto%2Fstorage%2Fgoog4_request&X-Goog-Date=20250411T150043Z&X-Goog-Expires=86399&X-Goog-Signature=2b94521395b91d2c6da28bc88c8fc2fc455de0bcface43802f47c8b6e4bc65bb0576e272b4d89ff080de61ad7e2630455fac8f8556a8d2a1ec83e0f726c7121de7b3c84adbbc041acaa6d30505fb9bb73aba360d8d7b4ca92305f90ec83f114c9376b107f51e30bb10fe0101942367b2da5037b93caba63940e541e0ffa3d92a71c487bd952d659a72612e9bb29d3d5e5ae6c723dd8f91e2eb021292ec34d2126321481511017f837aa8cc0777e29c645f288e5c68da432b266e08df490dd625a85a31dd1fb03e68e1afb786b509ca67234739c6680f80bb31dd4c6da4212ae8dc8e5e0ff83679cfe8036d20ce4154044ae026f98c7e926fd492687e6ba80a2f&X-Goog-SignedHeaders=host&X-User=2931823730: HTTPSConnectionPool(host='storage.googleapis.com', port=443): Max retries exceeded with url: /wandb-production.appspot.com/2931823730-harbin-institute-of-technology/ltu-as/p17gmulg/config.yaml?X-Goog-Algorithm=GOOG4-RSA-SHA256&X-Goog-Credential=gorilla-files-url-signer-man%40wandb-production.iam.gserviceaccount.com%2F20250411%2Fauto%2Fstorage%2Fgoog4_request&X-Goog-Date=20250411T150043Z&X-Goog-Expires=86399&X-Goog-Signature=2b94521395b91d2c6da28bc88c8fc2fc455de0bcface43802f47c8b6e4bc65bb0576e272b4d89ff080de61ad7e2630455fac8f8556a8d2a1ec83e0f726c7121de7b3c84adbbc041acaa6d30505fb9bb73aba360d8d7b4ca92305f90ec83f114c9376b107f51e30bb10fe0101942367b2da5037b93caba63940e541e0ffa3d92a71c487bd952d659a72612e9bb29d3d5e5ae6c723dd8f91e2eb021292ec34d2126321481511017f837aa8cc0777e29c645f288e5c68da432b266e08df490dd625a85a31dd1fb03e68e1afb786b509ca67234739c6680f80bb31dd4c6da4212ae8dc8e5e0ff83679cfe8036d20ce4154044ae026f98c7e926fd492687e6ba80a2f&X-Goog-SignedHeaders=host&X-User=2931823730 (Caused by NewConnectionError('<urllib3.connection.HTTPSConnection object at 0x7f702edb6470>: Failed to establish a new connection: [Errno 101] Network is unreachable'))
2025-04-11 15:01:01,214 ERROR   wandb-upload_1:20960 [internal_api.py:upload_file():2558] upload_file request headers: {'User-Agent': 'python-requests/2.32.3', 'Accept-Encoding': 'gzip, deflate, br', 'Accept': '*/*', 'Connection': 'keep-alive', 'Content-Length': '8666'}
2025-04-11 15:01:01,214 ERROR   wandb-upload_1:20960 [internal_api.py:upload_file():2560] upload_file response body: 
2025-04-11 15:01:01,546 DEBUG   HandlerThread:20960 [handler.py:handle_request():146] handle_request: poll_exit
2025-04-11 15:01:01,547 DEBUG   SenderThread:20960 [sender.py:send_request():407] send_request: poll_exit
2025-04-11 15:01:02,242 ERROR   wandb-upload_0:20960 [internal_api.py:upload_file():2556] upload_file exception https://storage.googleapis.com/wandb-production.appspot.com/2931823730-harbin-institute-of-technology/ltu-as/p17gmulg/wandb-metadata.json?X-Goog-Algorithm=GOOG4-RSA-SHA256&X-Goog-Credential=gorilla-files-url-signer-man%40wandb-production.iam.gserviceaccount.com%2F20250411%2Fauto%2Fstorage%2Fgoog4_request&X-Goog-Date=20250411T150027Z&X-Goog-Expires=86399&X-Goog-Signature=0fca1f09c246b35184e651f2690bb2d36dc49dab5fec1f973e2c65e5bfefebbfd202f9b4caa1608b01be21ef52649952919cd92fe2c7d0cbaa7d85e1dec4688e3d4bce047b086e7704caa70c0e7cd600a6fa32524d987c1e285f028227ad40a92e888252a5c330544b44a0eab8be632c7210336d5e7ecaf9b4c27dfefc250b2e5f8a04f0124c65480524e79e4ebfbf7f17921a78390961ea9ff85a200da5de126487ab0284a7f24abf28c4a11a45df9fe33a42121f13be1d8e478aaebd8536a5f732611162ce46d0392669452a89459b76adcc2538897ad8710d676cf8b168232f3798549d04eb53b7c89783fcdaea6b7933abd4ab75eccaac8647b7588544b8&X-Goog-SignedHeaders=host&X-User=2931823730: HTTPSConnectionPool(host='storage.googleapis.com', port=443): Max retries exceeded with url: /wandb-production.appspot.com/2931823730-harbin-institute-of-technology/ltu-as/p17gmulg/wandb-metadata.json?X-Goog-Algorithm=GOOG4-RSA-SHA256&X-Goog-Credential=gorilla-files-url-signer-man%40wandb-production.iam.gserviceaccount.com%2F20250411%2Fauto%2Fstorage%2Fgoog4_request&X-Goog-Date=20250411T150027Z&X-Goog-Expires=86399&X-Goog-Signature=0fca1f09c246b35184e651f2690bb2d36dc49dab5fec1f973e2c65e5bfefebbfd202f9b4caa1608b01be21ef52649952919cd92fe2c7d0cbaa7d85e1dec4688e3d4bce047b086e7704caa70c0e7cd600a6fa32524d987c1e285f028227ad40a92e888252a5c330544b44a0eab8be632c7210336d5e7ecaf9b4c27dfefc250b2e5f8a04f0124c65480524e79e4ebfbf7f17921a78390961ea9ff85a200da5de126487ab0284a7f24abf28c4a11a45df9fe33a42121f13be1d8e478aaebd8536a5f732611162ce46d0392669452a89459b76adcc2538897ad8710d676cf8b168232f3798549d04eb53b7c89783fcdaea6b7933abd4ab75eccaac8647b7588544b8&X-Goog-SignedHeaders=host&X-User=2931823730 (Caused by NewConnectionError('<urllib3.connection.HTTPSConnection object at 0x7f702edb44c0>: Failed to establish a new connection: [Errno 101] Network is unreachable'))
2025-04-11 15:01:02,242 ERROR   wandb-upload_0:20960 [internal_api.py:upload_file():2558] upload_file request headers: {'User-Agent': 'python-requests/2.32.3', 'Accept-Encoding': 'gzip, deflate, br', 'Accept': '*/*', 'Connection': 'keep-alive', 'Content-Length': '2212'}
2025-04-11 15:01:02,242 ERROR   wandb-upload_0:20960 [internal_api.py:upload_file():2560] upload_file response body: 
2025-04-11 15:01:02,547 DEBUG   HandlerThread:20960 [handler.py:handle_request():146] handle_request: poll_exit
2025-04-11 15:01:02,548 DEBUG   SenderThread:20960 [sender.py:send_request():407] send_request: poll_exit
2025-04-11 15:01:03,548 DEBUG   HandlerThread:20960 [handler.py:handle_request():146] handle_request: poll_exit
2025-04-11 15:01:03,549 DEBUG   SenderThread:20960 [sender.py:send_request():407] send_request: poll_exit
2025-04-11 15:01:03,550 DEBUG   HandlerThread:20960 [handler.py:handle_request():146] handle_request: status_report
2025-04-11 15:01:04,549 DEBUG   HandlerThread:20960 [handler.py:handle_request():146] handle_request: poll_exit
2025-04-11 15:01:04,551 DEBUG   SenderThread:20960 [sender.py:send_request():407] send_request: poll_exit
2025-04-11 15:01:05,552 DEBUG   HandlerThread:20960 [handler.py:handle_request():146] handle_request: poll_exit
2025-04-11 15:01:05,553 DEBUG   SenderThread:20960 [sender.py:send_request():407] send_request: poll_exit
2025-04-11 15:01:06,554 DEBUG   HandlerThread:20960 [handler.py:handle_request():146] handle_request: poll_exit
2025-04-11 15:01:06,556 DEBUG   SenderThread:20960 [sender.py:send_request():407] send_request: poll_exit
2025-04-11 15:01:07,556 DEBUG   HandlerThread:20960 [handler.py:handle_request():146] handle_request: poll_exit
2025-04-11 15:01:07,557 DEBUG   SenderThread:20960 [sender.py:send_request():407] send_request: poll_exit
2025-04-11 15:01:08,557 DEBUG   HandlerThread:20960 [handler.py:handle_request():146] handle_request: poll_exit
2025-04-11 15:01:08,558 DEBUG   HandlerThread:20960 [handler.py:handle_request():146] handle_request: status_report
2025-04-11 15:01:08,559 DEBUG   SenderThread:20960 [sender.py:send_request():407] send_request: poll_exit
2025-04-11 15:01:09,560 DEBUG   HandlerThread:20960 [handler.py:handle_request():146] handle_request: poll_exit
2025-04-11 15:01:09,561 DEBUG   SenderThread:20960 [sender.py:send_request():407] send_request: poll_exit
2025-04-11 15:01:10,561 DEBUG   HandlerThread:20960 [handler.py:handle_request():146] handle_request: poll_exit
2025-04-11 15:01:10,562 DEBUG   SenderThread:20960 [sender.py:send_request():407] send_request: poll_exit
2025-04-11 15:01:11,562 DEBUG   HandlerThread:20960 [handler.py:handle_request():146] handle_request: poll_exit
2025-04-11 15:01:11,563 DEBUG   SenderThread:20960 [sender.py:send_request():407] send_request: poll_exit
2025-04-11 15:01:12,563 DEBUG   HandlerThread:20960 [handler.py:handle_request():146] handle_request: poll_exit
2025-04-11 15:01:12,564 DEBUG   SenderThread:20960 [sender.py:send_request():407] send_request: poll_exit
2025-04-11 15:01:13,565 DEBUG   HandlerThread:20960 [handler.py:handle_request():146] handle_request: poll_exit
2025-04-11 15:01:13,566 DEBUG   HandlerThread:20960 [handler.py:handle_request():146] handle_request: status_report
2025-04-11 15:01:13,566 DEBUG   SenderThread:20960 [sender.py:send_request():407] send_request: poll_exit
2025-04-11 15:01:14,567 DEBUG   HandlerThread:20960 [handler.py:handle_request():146] handle_request: poll_exit
2025-04-11 15:01:14,568 DEBUG   SenderThread:20960 [sender.py:send_request():407] send_request: poll_exit
2025-04-11 15:01:15,570 DEBUG   HandlerThread:20960 [handler.py:handle_request():146] handle_request: poll_exit
2025-04-11 15:01:15,571 DEBUG   SenderThread:20960 [sender.py:send_request():407] send_request: poll_exit
2025-04-11 15:01:16,061 ERROR   wandb-upload_2:20960 [internal_api.py:upload_file():2556] upload_file exception https://storage.googleapis.com/wandb-production.appspot.com/2931823730-harbin-institute-of-technology/ltu-as/p17gmulg/requirements.txt?X-Goog-Algorithm=GOOG4-RSA-SHA256&X-Goog-Credential=gorilla-files-url-signer-man%40wandb-production.iam.gserviceaccount.com%2F20250411%2Fauto%2Fstorage%2Fgoog4_request&X-Goog-Date=20250411T150043Z&X-Goog-Expires=86399&X-Goog-Signature=14dcd9bd7741ba854922781779b244d065a2f93e20042ce112d03d9a74fa6ceafd1a02b76cfe7e1d83ceecfb3b6c3b3ccc9fadcd34593f606440f4b7136578ec49a47ec7af23ddefb386a812922c26eb929dc0da3c7b5a24d04fe645d171ed6cbdf2dd3f41534425b4a709b793de783fa2b973ef1eb68ca4cbc8697ba576ff13534ced1f4976d8b3d7739d7b5ee6c113c7c67453905e7311f37f8bde9ebd13a60597a748a421ab730351a19b37ae016bf30b884b6e554c62df963c76284dfca9faf6a980b28817387e6dc67e8ed6fd758c92deb55a34f2eb5b303f7083028b548986861f2398dbaa3b2d08172b60c61edf28e44efed84920699974adac927b5f&X-Goog-SignedHeaders=host&X-User=2931823730: HTTPSConnectionPool(host='storage.googleapis.com', port=443): Max retries exceeded with url: /wandb-production.appspot.com/2931823730-harbin-institute-of-technology/ltu-as/p17gmulg/requirements.txt?X-Goog-Algorithm=GOOG4-RSA-SHA256&X-Goog-Credential=gorilla-files-url-signer-man%40wandb-production.iam.gserviceaccount.com%2F20250411%2Fauto%2Fstorage%2Fgoog4_request&X-Goog-Date=20250411T150043Z&X-Goog-Expires=86399&X-Goog-Signature=14dcd9bd7741ba854922781779b244d065a2f93e20042ce112d03d9a74fa6ceafd1a02b76cfe7e1d83ceecfb3b6c3b3ccc9fadcd34593f606440f4b7136578ec49a47ec7af23ddefb386a812922c26eb929dc0da3c7b5a24d04fe645d171ed6cbdf2dd3f41534425b4a709b793de783fa2b973ef1eb68ca4cbc8697ba576ff13534ced1f4976d8b3d7739d7b5ee6c113c7c67453905e7311f37f8bde9ebd13a60597a748a421ab730351a19b37ae016bf30b884b6e554c62df963c76284dfca9faf6a980b28817387e6dc67e8ed6fd758c92deb55a34f2eb5b303f7083028b548986861f2398dbaa3b2d08172b60c61edf28e44efed84920699974adac927b5f&X-Goog-SignedHeaders=host&X-User=2931823730 (Caused by NewConnectionError('<urllib3.connection.HTTPSConnection object at 0x7f702edb4eb0>: Failed to establish a new connection: [Errno 101] Network is unreachable'))
2025-04-11 15:01:16,062 ERROR   wandb-upload_2:20960 [internal_api.py:upload_file():2558] upload_file request headers: {'User-Agent': 'python-requests/2.32.3', 'Accept-Encoding': 'gzip, deflate, br', 'Accept': '*/*', 'Connection': 'keep-alive', 'Content-Length': '4212'}
2025-04-11 15:01:16,062 ERROR   wandb-upload_2:20960 [internal_api.py:upload_file():2560] upload_file response body: 
2025-04-11 15:01:16,572 DEBUG   HandlerThread:20960 [handler.py:handle_request():146] handle_request: poll_exit
2025-04-11 15:01:16,573 DEBUG   SenderThread:20960 [sender.py:send_request():407] send_request: poll_exit
2025-04-11 15:01:17,574 DEBUG   HandlerThread:20960 [handler.py:handle_request():146] handle_request: poll_exit
2025-04-11 15:01:17,575 DEBUG   SenderThread:20960 [sender.py:send_request():407] send_request: poll_exit
2025-04-11 15:01:18,177 ERROR   wandb-upload_4:20960 [internal_api.py:upload_file():2556] upload_file exception https://storage.googleapis.com/wandb-production.appspot.com/2931823730-harbin-institute-of-technology/ltu-as/p17gmulg/output.log?X-Goog-Algorithm=GOOG4-RSA-SHA256&X-Goog-Credential=gorilla-files-url-signer-man%40wandb-production.iam.gserviceaccount.com%2F20250411%2Fauto%2Fstorage%2Fgoog4_request&X-Goog-Date=20250411T150043Z&X-Goog-Expires=86399&X-Goog-Signature=0308420c548c6bc687992243d2a177fab7c1e559bf54fdb3fcef576cbdb35fedc146e60d263e4a67d7dcf10d49fc5fce2b200db779ede9932190768ef7045285e94ebcab25d5c53df1ac3faccb2e1b3123697207c801b2f9ed9445e272209bc83528d2b276b120193046794812b634842c87ec4fb6a455019b7629adb328930593761b298218336a3352fe2b3ff4677801486c5fbe6d691a897ba443a75ff0090308631a57a9f25c185a2aa064157f9fcd720807f256f1830810dbc582f2f82e719ba0316a4b5743320f3ccfc2826623c2139bccbce4c58bcebd511da09c54dcb483ba9d761279f3786b202a99bd6e9a82147286632175a2481cd79591fa6901&X-Goog-SignedHeaders=host&X-User=2931823730: HTTPSConnectionPool(host='storage.googleapis.com', port=443): Max retries exceeded with url: /wandb-production.appspot.com/2931823730-harbin-institute-of-technology/ltu-as/p17gmulg/output.log?X-Goog-Algorithm=GOOG4-RSA-SHA256&X-Goog-Credential=gorilla-files-url-signer-man%40wandb-production.iam.gserviceaccount.com%2F20250411%2Fauto%2Fstorage%2Fgoog4_request&X-Goog-Date=20250411T150043Z&X-Goog-Expires=86399&X-Goog-Signature=0308420c548c6bc687992243d2a177fab7c1e559bf54fdb3fcef576cbdb35fedc146e60d263e4a67d7dcf10d49fc5fce2b200db779ede9932190768ef7045285e94ebcab25d5c53df1ac3faccb2e1b3123697207c801b2f9ed9445e272209bc83528d2b276b120193046794812b634842c87ec4fb6a455019b7629adb328930593761b298218336a3352fe2b3ff4677801486c5fbe6d691a897ba443a75ff0090308631a57a9f25c185a2aa064157f9fcd720807f256f1830810dbc582f2f82e719ba0316a4b5743320f3ccfc2826623c2139bccbce4c58bcebd511da09c54dcb483ba9d761279f3786b202a99bd6e9a82147286632175a2481cd79591fa6901&X-Goog-SignedHeaders=host&X-User=2931823730 (Caused by NewConnectionError('<urllib3.connection.HTTPSConnection object at 0x7f702edb4670>: Failed to establish a new connection: [Errno 101] Network is unreachable'))
2025-04-11 15:01:18,177 ERROR   wandb-upload_4:20960 [internal_api.py:upload_file():2558] upload_file request headers: {'User-Agent': 'python-requests/2.32.3', 'Accept-Encoding': 'gzip, deflate, br', 'Accept': '*/*', 'Connection': 'keep-alive', 'Content-Length': '4566'}
2025-04-11 15:01:18,177 ERROR   wandb-upload_4:20960 [internal_api.py:upload_file():2560] upload_file response body: 
2025-04-11 15:01:18,441 ERROR   wandb-upload_5:20960 [internal_api.py:upload_file():2556] upload_file exception https://storage.googleapis.com/wandb-production.appspot.com/2931823730-harbin-institute-of-technology/ltu-as/p17gmulg/wandb-summary.json?X-Goog-Algorithm=GOOG4-RSA-SHA256&X-Goog-Credential=gorilla-files-url-signer-man%40wandb-production.iam.gserviceaccount.com%2F20250411%2Fauto%2Fstorage%2Fgoog4_request&X-Goog-Date=20250411T150044Z&X-Goog-Expires=86399&X-Goog-Signature=24104ea3df52b0b0fce0141d2d6615d36298eb5ea08485b2dc4a616d8119698ba118d11a5f44e94354266eab45d4324499348fa21cbe0c4ba8fa5416f5d335df3cfd7f6375fd0c35836e0226a4611fe7b4e0f043aecba8910f16dbbe5ef52e0c1717e30949ed1b19d3656214206bf4119b065b8502f7c60223b66c33a0f306ebfb9892023b673278d5fc199b3db2f45eb469e4325de8426d897ab25d2fdef8b01f20a0e0440edd3be494bd732b6c55ed61f734c068dbb035289a3be40f4fe4597d3935b3425583450c92d72d5d0ffba8a0ff9533eab69377449395aab5b7bb990fbe8cc08bff93c2c6504738548e83e4a5e31b2924272307412886d6276d63ca&X-Goog-SignedHeaders=host&X-User=2931823730: HTTPSConnectionPool(host='storage.googleapis.com', port=443): Max retries exceeded with url: /wandb-production.appspot.com/2931823730-harbin-institute-of-technology/ltu-as/p17gmulg/wandb-summary.json?X-Goog-Algorithm=GOOG4-RSA-SHA256&X-Goog-Credential=gorilla-files-url-signer-man%40wandb-production.iam.gserviceaccount.com%2F20250411%2Fauto%2Fstorage%2Fgoog4_request&X-Goog-Date=20250411T150044Z&X-Goog-Expires=86399&X-Goog-Signature=24104ea3df52b0b0fce0141d2d6615d36298eb5ea08485b2dc4a616d8119698ba118d11a5f44e94354266eab45d4324499348fa21cbe0c4ba8fa5416f5d335df3cfd7f6375fd0c35836e0226a4611fe7b4e0f043aecba8910f16dbbe5ef52e0c1717e30949ed1b19d3656214206bf4119b065b8502f7c60223b66c33a0f306ebfb9892023b673278d5fc199b3db2f45eb469e4325de8426d897ab25d2fdef8b01f20a0e0440edd3be494bd732b6c55ed61f734c068dbb035289a3be40f4fe4597d3935b3425583450c92d72d5d0ffba8a0ff9533eab69377449395aab5b7bb990fbe8cc08bff93c2c6504738548e83e4a5e31b2924272307412886d6276d63ca&X-Goog-SignedHeaders=host&X-User=2931823730 (Caused by NewConnectionError('<urllib3.connection.HTTPSConnection object at 0x7f702edb5780>: Failed to establish a new connection: [Errno 101] Network is unreachable'))
2025-04-11 15:01:18,441 ERROR   wandb-upload_5:20960 [internal_api.py:upload_file():2558] upload_file request headers: {'User-Agent': 'python-requests/2.32.3', 'Accept-Encoding': 'gzip, deflate, br', 'Accept': '*/*', 'Connection': 'keep-alive', 'Content-Length': '27'}
2025-04-11 15:01:18,441 ERROR   wandb-upload_5:20960 [internal_api.py:upload_file():2560] upload_file response body: 
2025-04-11 15:01:18,575 DEBUG   HandlerThread:20960 [handler.py:handle_request():146] handle_request: poll_exit
2025-04-11 15:01:18,576 DEBUG   SenderThread:20960 [sender.py:send_request():407] send_request: poll_exit
2025-04-11 15:01:18,577 DEBUG   HandlerThread:20960 [handler.py:handle_request():146] handle_request: status_report
2025-04-11 15:01:19,578 DEBUG   HandlerThread:20960 [handler.py:handle_request():146] handle_request: poll_exit
2025-04-11 15:01:19,578 DEBUG   SenderThread:20960 [sender.py:send_request():407] send_request: poll_exit
2025-04-11 15:01:19,627 ERROR   wandb-upload_3:20960 [internal_api.py:upload_file():2556] upload_file exception https://storage.googleapis.com/wandb-production.appspot.com/2931823730-harbin-institute-of-technology/ltu-as/p17gmulg/conda-environment.yaml?X-Goog-Algorithm=GOOG4-RSA-SHA256&X-Goog-Credential=gorilla-files-url-signer-man%40wandb-production.iam.gserviceaccount.com%2F20250411%2Fauto%2Fstorage%2Fgoog4_request&X-Goog-Date=20250411T150043Z&X-Goog-Expires=86399&X-Goog-Signature=00f2737f97b7b1f937f7a9aebdfea9b77a2c6c8e1517ac5604b0ab1d0c7220099661943fa06351c6a2fc07c285f7cde727cfd97257af5eec33c10ff58653cf9d6ebbfa07ca47153a6c0bb6e66bdc5460d4faccd98405adea9703c4f7553f8301273fcfa04cced1cd05c064254e7dbb600c8767e195c3109aa0466581c2735ab0ed4b1f21f2ba2046c29b2199a29cbcedb0f7ba1bce4992ef9fd04257dff85ead08d2ea2f4e835b64a2a3428bb295fd3523de6c1dbcd055c8962bd057f4c676fa028b90c343670ac851f3c26fc59ad1f13a6de4c9ea39dcbd845b4092616d0fe18bd2b09525b48943a5122a270e5637a422663aefc15274ec3ff901174e8eed50&X-Goog-SignedHeaders=host&X-User=2931823730: HTTPSConnectionPool(host='storage.googleapis.com', port=443): Max retries exceeded with url: /wandb-production.appspot.com/2931823730-harbin-institute-of-technology/ltu-as/p17gmulg/conda-environment.yaml?X-Goog-Algorithm=GOOG4-RSA-SHA256&X-Goog-Credential=gorilla-files-url-signer-man%40wandb-production.iam.gserviceaccount.com%2F20250411%2Fauto%2Fstorage%2Fgoog4_request&X-Goog-Date=20250411T150043Z&X-Goog-Expires=86399&X-Goog-Signature=00f2737f97b7b1f937f7a9aebdfea9b77a2c6c8e1517ac5604b0ab1d0c7220099661943fa06351c6a2fc07c285f7cde727cfd97257af5eec33c10ff58653cf9d6ebbfa07ca47153a6c0bb6e66bdc5460d4faccd98405adea9703c4f7553f8301273fcfa04cced1cd05c064254e7dbb600c8767e195c3109aa0466581c2735ab0ed4b1f21f2ba2046c29b2199a29cbcedb0f7ba1bce4992ef9fd04257dff85ead08d2ea2f4e835b64a2a3428bb295fd3523de6c1dbcd055c8962bd057f4c676fa028b90c343670ac851f3c26fc59ad1f13a6de4c9ea39dcbd845b4092616d0fe18bd2b09525b48943a5122a270e5637a422663aefc15274ec3ff901174e8eed50&X-Goog-SignedHeaders=host&X-User=2931823730 (Caused by NewConnectionError('<urllib3.connection.HTTPSConnection object at 0x7f702edb5f60>: Failed to establish a new connection: [Errno 101] Network is unreachable'))
2025-04-11 15:01:19,628 ERROR   wandb-upload_3:20960 [internal_api.py:upload_file():2558] upload_file request headers: {'User-Agent': 'python-requests/2.32.3', 'Accept-Encoding': 'gzip, deflate, br', 'Accept': '*/*', 'Connection': 'keep-alive', 'Content-Length': '8281'}
2025-04-11 15:01:19,628 ERROR   wandb-upload_3:20960 [internal_api.py:upload_file():2560] upload_file response body: 
2025-04-11 15:01:20,579 DEBUG   HandlerThread:20960 [handler.py:handle_request():146] handle_request: poll_exit
2025-04-11 15:01:20,580 DEBUG   SenderThread:20960 [sender.py:send_request():407] send_request: poll_exit
2025-04-11 15:01:20,683 ERROR   wandb-upload_1:20960 [internal_api.py:upload_file():2556] upload_file exception https://storage.googleapis.com/wandb-production.appspot.com/2931823730-harbin-institute-of-technology/ltu-as/p17gmulg/config.yaml?X-Goog-Algorithm=GOOG4-RSA-SHA256&X-Goog-Credential=gorilla-files-url-signer-man%40wandb-production.iam.gserviceaccount.com%2F20250411%2Fauto%2Fstorage%2Fgoog4_request&X-Goog-Date=20250411T150043Z&X-Goog-Expires=86399&X-Goog-Signature=2b94521395b91d2c6da28bc88c8fc2fc455de0bcface43802f47c8b6e4bc65bb0576e272b4d89ff080de61ad7e2630455fac8f8556a8d2a1ec83e0f726c7121de7b3c84adbbc041acaa6d30505fb9bb73aba360d8d7b4ca92305f90ec83f114c9376b107f51e30bb10fe0101942367b2da5037b93caba63940e541e0ffa3d92a71c487bd952d659a72612e9bb29d3d5e5ae6c723dd8f91e2eb021292ec34d2126321481511017f837aa8cc0777e29c645f288e5c68da432b266e08df490dd625a85a31dd1fb03e68e1afb786b509ca67234739c6680f80bb31dd4c6da4212ae8dc8e5e0ff83679cfe8036d20ce4154044ae026f98c7e926fd492687e6ba80a2f&X-Goog-SignedHeaders=host&X-User=2931823730: HTTPSConnectionPool(host='storage.googleapis.com', port=443): Max retries exceeded with url: /wandb-production.appspot.com/2931823730-harbin-institute-of-technology/ltu-as/p17gmulg/config.yaml?X-Goog-Algorithm=GOOG4-RSA-SHA256&X-Goog-Credential=gorilla-files-url-signer-man%40wandb-production.iam.gserviceaccount.com%2F20250411%2Fauto%2Fstorage%2Fgoog4_request&X-Goog-Date=20250411T150043Z&X-Goog-Expires=86399&X-Goog-Signature=2b94521395b91d2c6da28bc88c8fc2fc455de0bcface43802f47c8b6e4bc65bb0576e272b4d89ff080de61ad7e2630455fac8f8556a8d2a1ec83e0f726c7121de7b3c84adbbc041acaa6d30505fb9bb73aba360d8d7b4ca92305f90ec83f114c9376b107f51e30bb10fe0101942367b2da5037b93caba63940e541e0ffa3d92a71c487bd952d659a72612e9bb29d3d5e5ae6c723dd8f91e2eb021292ec34d2126321481511017f837aa8cc0777e29c645f288e5c68da432b266e08df490dd625a85a31dd1fb03e68e1afb786b509ca67234739c6680f80bb31dd4c6da4212ae8dc8e5e0ff83679cfe8036d20ce4154044ae026f98c7e926fd492687e6ba80a2f&X-Goog-SignedHeaders=host&X-User=2931823730 (Caused by NewConnectionError('<urllib3.connection.HTTPSConnection object at 0x7f702edb43a0>: Failed to establish a new connection: [Errno 101] Network is unreachable'))
2025-04-11 15:01:20,683 ERROR   wandb-upload_1:20960 [internal_api.py:upload_file():2558] upload_file request headers: {'User-Agent': 'python-requests/2.32.3', 'Accept-Encoding': 'gzip, deflate, br', 'Accept': '*/*', 'Connection': 'keep-alive', 'Content-Length': '8666'}
2025-04-11 15:01:20,683 ERROR   wandb-upload_1:20960 [internal_api.py:upload_file():2560] upload_file response body: 
2025-04-11 15:01:21,581 DEBUG   HandlerThread:20960 [handler.py:handle_request():146] handle_request: poll_exit
2025-04-11 15:01:21,582 DEBUG   SenderThread:20960 [sender.py:send_request():407] send_request: poll_exit
2025-04-11 15:01:22,582 DEBUG   HandlerThread:20960 [handler.py:handle_request():146] handle_request: poll_exit
2025-04-11 15:01:22,584 DEBUG   SenderThread:20960 [sender.py:send_request():407] send_request: poll_exit
2025-04-11 15:01:23,584 DEBUG   HandlerThread:20960 [handler.py:handle_request():146] handle_request: poll_exit
2025-04-11 15:01:23,585 DEBUG   HandlerThread:20960 [handler.py:handle_request():146] handle_request: status_report
2025-04-11 15:01:23,586 DEBUG   SenderThread:20960 [sender.py:send_request():407] send_request: poll_exit
2025-04-11 15:01:24,586 DEBUG   HandlerThread:20960 [handler.py:handle_request():146] handle_request: poll_exit
2025-04-11 15:01:24,586 DEBUG   SenderThread:20960 [sender.py:send_request():407] send_request: poll_exit
2025-04-11 15:01:25,588 DEBUG   HandlerThread:20960 [handler.py:handle_request():146] handle_request: poll_exit
2025-04-11 15:01:25,588 DEBUG   SenderThread:20960 [sender.py:send_request():407] send_request: poll_exit
2025-04-11 15:01:26,589 DEBUG   HandlerThread:20960 [handler.py:handle_request():146] handle_request: poll_exit
2025-04-11 15:01:26,590 DEBUG   SenderThread:20960 [sender.py:send_request():407] send_request: poll_exit
2025-04-11 15:01:27,591 DEBUG   HandlerThread:20960 [handler.py:handle_request():146] handle_request: poll_exit
2025-04-11 15:01:27,592 DEBUG   SenderThread:20960 [sender.py:send_request():407] send_request: poll_exit
2025-04-11 15:01:28,592 DEBUG   HandlerThread:20960 [handler.py:handle_request():146] handle_request: poll_exit
2025-04-11 15:01:28,593 DEBUG   HandlerThread:20960 [handler.py:handle_request():146] handle_request: status_report
2025-04-11 15:01:28,594 DEBUG   SenderThread:20960 [sender.py:send_request():407] send_request: poll_exit
2025-04-11 15:01:29,594 DEBUG   HandlerThread:20960 [handler.py:handle_request():146] handle_request: poll_exit
2025-04-11 15:01:29,594 DEBUG   SenderThread:20960 [sender.py:send_request():407] send_request: poll_exit
2025-04-11 15:01:30,594 DEBUG   HandlerThread:20960 [handler.py:handle_request():146] handle_request: poll_exit
2025-04-11 15:01:30,595 DEBUG   SenderThread:20960 [sender.py:send_request():407] send_request: poll_exit
2025-04-11 15:01:31,595 DEBUG   HandlerThread:20960 [handler.py:handle_request():146] handle_request: poll_exit
2025-04-11 15:01:31,596 DEBUG   SenderThread:20960 [sender.py:send_request():407] send_request: poll_exit
2025-04-11 15:01:32,596 DEBUG   HandlerThread:20960 [handler.py:handle_request():146] handle_request: poll_exit
2025-04-11 15:01:32,597 DEBUG   SenderThread:20960 [sender.py:send_request():407] send_request: poll_exit
2025-04-11 15:01:33,597 DEBUG   HandlerThread:20960 [handler.py:handle_request():146] handle_request: poll_exit
2025-04-11 15:01:33,598 DEBUG   HandlerThread:20960 [handler.py:handle_request():146] handle_request: status_report
2025-04-11 15:01:33,599 DEBUG   SenderThread:20960 [sender.py:send_request():407] send_request: poll_exit
2025-04-11 15:01:34,598 DEBUG   HandlerThread:20960 [handler.py:handle_request():146] handle_request: poll_exit
2025-04-11 15:01:34,599 DEBUG   SenderThread:20960 [sender.py:send_request():407] send_request: poll_exit
2025-04-11 15:01:34,688 ERROR   wandb-upload_0:20960 [internal_api.py:upload_file():2556] upload_file exception https://storage.googleapis.com/wandb-production.appspot.com/2931823730-harbin-institute-of-technology/ltu-as/p17gmulg/wandb-metadata.json?X-Goog-Algorithm=GOOG4-RSA-SHA256&X-Goog-Credential=gorilla-files-url-signer-man%40wandb-production.iam.gserviceaccount.com%2F20250411%2Fauto%2Fstorage%2Fgoog4_request&X-Goog-Date=20250411T150027Z&X-Goog-Expires=86399&X-Goog-Signature=0fca1f09c246b35184e651f2690bb2d36dc49dab5fec1f973e2c65e5bfefebbfd202f9b4caa1608b01be21ef52649952919cd92fe2c7d0cbaa7d85e1dec4688e3d4bce047b086e7704caa70c0e7cd600a6fa32524d987c1e285f028227ad40a92e888252a5c330544b44a0eab8be632c7210336d5e7ecaf9b4c27dfefc250b2e5f8a04f0124c65480524e79e4ebfbf7f17921a78390961ea9ff85a200da5de126487ab0284a7f24abf28c4a11a45df9fe33a42121f13be1d8e478aaebd8536a5f732611162ce46d0392669452a89459b76adcc2538897ad8710d676cf8b168232f3798549d04eb53b7c89783fcdaea6b7933abd4ab75eccaac8647b7588544b8&X-Goog-SignedHeaders=host&X-User=2931823730: HTTPSConnectionPool(host='storage.googleapis.com', port=443): Max retries exceeded with url: /wandb-production.appspot.com/2931823730-harbin-institute-of-technology/ltu-as/p17gmulg/wandb-metadata.json?X-Goog-Algorithm=GOOG4-RSA-SHA256&X-Goog-Credential=gorilla-files-url-signer-man%40wandb-production.iam.gserviceaccount.com%2F20250411%2Fauto%2Fstorage%2Fgoog4_request&X-Goog-Date=20250411T150027Z&X-Goog-Expires=86399&X-Goog-Signature=0fca1f09c246b35184e651f2690bb2d36dc49dab5fec1f973e2c65e5bfefebbfd202f9b4caa1608b01be21ef52649952919cd92fe2c7d0cbaa7d85e1dec4688e3d4bce047b086e7704caa70c0e7cd600a6fa32524d987c1e285f028227ad40a92e888252a5c330544b44a0eab8be632c7210336d5e7ecaf9b4c27dfefc250b2e5f8a04f0124c65480524e79e4ebfbf7f17921a78390961ea9ff85a200da5de126487ab0284a7f24abf28c4a11a45df9fe33a42121f13be1d8e478aaebd8536a5f732611162ce46d0392669452a89459b76adcc2538897ad8710d676cf8b168232f3798549d04eb53b7c89783fcdaea6b7933abd4ab75eccaac8647b7588544b8&X-Goog-SignedHeaders=host&X-User=2931823730 (Caused by NewConnectionError('<urllib3.connection.HTTPSConnection object at 0x7f702edb7df0>: Failed to establish a new connection: [Errno 101] Network is unreachable'))
2025-04-11 15:01:34,688 ERROR   wandb-upload_0:20960 [internal_api.py:upload_file():2558] upload_file request headers: {'User-Agent': 'python-requests/2.32.3', 'Accept-Encoding': 'gzip, deflate, br', 'Accept': '*/*', 'Connection': 'keep-alive', 'Content-Length': '2212'}
2025-04-11 15:01:34,688 ERROR   wandb-upload_0:20960 [internal_api.py:upload_file():2560] upload_file response body: 
2025-04-11 15:01:35,600 DEBUG   HandlerThread:20960 [handler.py:handle_request():146] handle_request: poll_exit
2025-04-11 15:01:35,601 DEBUG   SenderThread:20960 [sender.py:send_request():407] send_request: poll_exit
2025-04-11 15:01:36,602 DEBUG   HandlerThread:20960 [handler.py:handle_request():146] handle_request: poll_exit
2025-04-11 15:01:36,603 DEBUG   SenderThread:20960 [sender.py:send_request():407] send_request: poll_exit
2025-04-11 15:01:37,604 DEBUG   HandlerThread:20960 [handler.py:handle_request():146] handle_request: poll_exit
2025-04-11 15:01:37,604 DEBUG   SenderThread:20960 [sender.py:send_request():407] send_request: poll_exit
2025-04-11 15:01:38,605 DEBUG   HandlerThread:20960 [handler.py:handle_request():146] handle_request: poll_exit
2025-04-11 15:01:38,606 DEBUG   SenderThread:20960 [sender.py:send_request():407] send_request: poll_exit
2025-04-11 15:01:38,606 DEBUG   HandlerThread:20960 [handler.py:handle_request():146] handle_request: status_report
2025-04-11 15:01:39,606 DEBUG   HandlerThread:20960 [handler.py:handle_request():146] handle_request: poll_exit
2025-04-11 15:01:39,607 DEBUG   SenderThread:20960 [sender.py:send_request():407] send_request: poll_exit
2025-04-11 15:01:40,608 DEBUG   HandlerThread:20960 [handler.py:handle_request():146] handle_request: poll_exit
2025-04-11 15:01:40,609 DEBUG   SenderThread:20960 [sender.py:send_request():407] send_request: poll_exit
2025-04-11 15:01:41,610 DEBUG   HandlerThread:20960 [handler.py:handle_request():146] handle_request: poll_exit
2025-04-11 15:01:41,611 DEBUG   SenderThread:20960 [sender.py:send_request():407] send_request: poll_exit
2025-04-11 15:01:42,611 DEBUG   HandlerThread:20960 [handler.py:handle_request():146] handle_request: poll_exit
2025-04-11 15:01:42,612 DEBUG   SenderThread:20960 [sender.py:send_request():407] send_request: poll_exit
2025-04-11 15:01:43,613 DEBUG   HandlerThread:20960 [handler.py:handle_request():146] handle_request: status_report
2025-04-11 15:01:43,614 DEBUG   HandlerThread:20960 [handler.py:handle_request():146] handle_request: poll_exit
2025-04-11 15:01:43,615 DEBUG   SenderThread:20960 [sender.py:send_request():407] send_request: poll_exit
2025-04-11 15:01:44,616 DEBUG   HandlerThread:20960 [handler.py:handle_request():146] handle_request: poll_exit
2025-04-11 15:01:44,617 DEBUG   SenderThread:20960 [sender.py:send_request():407] send_request: poll_exit
2025-04-11 15:01:45,618 DEBUG   HandlerThread:20960 [handler.py:handle_request():146] handle_request: poll_exit
2025-04-11 15:01:45,618 DEBUG   SenderThread:20960 [sender.py:send_request():407] send_request: poll_exit
2025-04-11 15:01:46,618 DEBUG   HandlerThread:20960 [handler.py:handle_request():146] handle_request: poll_exit
2025-04-11 15:01:46,620 DEBUG   SenderThread:20960 [sender.py:send_request():407] send_request: poll_exit
2025-04-11 15:01:47,621 DEBUG   HandlerThread:20960 [handler.py:handle_request():146] handle_request: poll_exit
2025-04-11 15:01:47,622 DEBUG   SenderThread:20960 [sender.py:send_request():407] send_request: poll_exit
2025-04-11 15:01:48,622 DEBUG   HandlerThread:20960 [handler.py:handle_request():146] handle_request: poll_exit
2025-04-11 15:01:48,623 DEBUG   HandlerThread:20960 [handler.py:handle_request():146] handle_request: status_report
2025-04-11 15:01:48,624 DEBUG   SenderThread:20960 [sender.py:send_request():407] send_request: poll_exit
2025-04-11 15:01:49,626 DEBUG   HandlerThread:20960 [handler.py:handle_request():146] handle_request: poll_exit
2025-04-11 15:01:49,626 DEBUG   SenderThread:20960 [sender.py:send_request():407] send_request: poll_exit
2025-04-11 15:01:50,627 DEBUG   HandlerThread:20960 [handler.py:handle_request():146] handle_request: poll_exit
2025-04-11 15:01:50,628 DEBUG   SenderThread:20960 [sender.py:send_request():407] send_request: poll_exit
2025-04-11 15:01:51,628 DEBUG   HandlerThread:20960 [handler.py:handle_request():146] handle_request: poll_exit
2025-04-11 15:01:51,629 DEBUG   SenderThread:20960 [sender.py:send_request():407] send_request: poll_exit
2025-04-11 15:01:52,255 ERROR   wandb-upload_5:20960 [internal_api.py:upload_file():2556] upload_file exception https://storage.googleapis.com/wandb-production.appspot.com/2931823730-harbin-institute-of-technology/ltu-as/p17gmulg/wandb-summary.json?X-Goog-Algorithm=GOOG4-RSA-SHA256&X-Goog-Credential=gorilla-files-url-signer-man%40wandb-production.iam.gserviceaccount.com%2F20250411%2Fauto%2Fstorage%2Fgoog4_request&X-Goog-Date=20250411T150044Z&X-Goog-Expires=86399&X-Goog-Signature=24104ea3df52b0b0fce0141d2d6615d36298eb5ea08485b2dc4a616d8119698ba118d11a5f44e94354266eab45d4324499348fa21cbe0c4ba8fa5416f5d335df3cfd7f6375fd0c35836e0226a4611fe7b4e0f043aecba8910f16dbbe5ef52e0c1717e30949ed1b19d3656214206bf4119b065b8502f7c60223b66c33a0f306ebfb9892023b673278d5fc199b3db2f45eb469e4325de8426d897ab25d2fdef8b01f20a0e0440edd3be494bd732b6c55ed61f734c068dbb035289a3be40f4fe4597d3935b3425583450c92d72d5d0ffba8a0ff9533eab69377449395aab5b7bb990fbe8cc08bff93c2c6504738548e83e4a5e31b2924272307412886d6276d63ca&X-Goog-SignedHeaders=host&X-User=2931823730: HTTPSConnectionPool(host='storage.googleapis.com', port=443): Max retries exceeded with url: /wandb-production.appspot.com/2931823730-harbin-institute-of-technology/ltu-as/p17gmulg/wandb-summary.json?X-Goog-Algorithm=GOOG4-RSA-SHA256&X-Goog-Credential=gorilla-files-url-signer-man%40wandb-production.iam.gserviceaccount.com%2F20250411%2Fauto%2Fstorage%2Fgoog4_request&X-Goog-Date=20250411T150044Z&X-Goog-Expires=86399&X-Goog-Signature=24104ea3df52b0b0fce0141d2d6615d36298eb5ea08485b2dc4a616d8119698ba118d11a5f44e94354266eab45d4324499348fa21cbe0c4ba8fa5416f5d335df3cfd7f6375fd0c35836e0226a4611fe7b4e0f043aecba8910f16dbbe5ef52e0c1717e30949ed1b19d3656214206bf4119b065b8502f7c60223b66c33a0f306ebfb9892023b673278d5fc199b3db2f45eb469e4325de8426d897ab25d2fdef8b01f20a0e0440edd3be494bd732b6c55ed61f734c068dbb035289a3be40f4fe4597d3935b3425583450c92d72d5d0ffba8a0ff9533eab69377449395aab5b7bb990fbe8cc08bff93c2c6504738548e83e4a5e31b2924272307412886d6276d63ca&X-Goog-SignedHeaders=host&X-User=2931823730 (Caused by NewConnectionError('<urllib3.connection.HTTPSConnection object at 0x7f702edb5cc0>: Failed to establish a new connection: [Errno 101] Network is unreachable'))
2025-04-11 15:01:52,255 ERROR   wandb-upload_5:20960 [internal_api.py:upload_file():2558] upload_file request headers: {'User-Agent': 'python-requests/2.32.3', 'Accept-Encoding': 'gzip, deflate, br', 'Accept': '*/*', 'Connection': 'keep-alive', 'Content-Length': '27'}
2025-04-11 15:01:52,255 ERROR   wandb-upload_5:20960 [internal_api.py:upload_file():2560] upload_file response body: 
2025-04-11 15:01:52,629 DEBUG   HandlerThread:20960 [handler.py:handle_request():146] handle_request: poll_exit
2025-04-11 15:01:52,630 DEBUG   SenderThread:20960 [sender.py:send_request():407] send_request: poll_exit
2025-04-11 15:01:52,830 ERROR   wandb-upload_2:20960 [internal_api.py:upload_file():2556] upload_file exception https://storage.googleapis.com/wandb-production.appspot.com/2931823730-harbin-institute-of-technology/ltu-as/p17gmulg/requirements.txt?X-Goog-Algorithm=GOOG4-RSA-SHA256&X-Goog-Credential=gorilla-files-url-signer-man%40wandb-production.iam.gserviceaccount.com%2F20250411%2Fauto%2Fstorage%2Fgoog4_request&X-Goog-Date=20250411T150043Z&X-Goog-Expires=86399&X-Goog-Signature=14dcd9bd7741ba854922781779b244d065a2f93e20042ce112d03d9a74fa6ceafd1a02b76cfe7e1d83ceecfb3b6c3b3ccc9fadcd34593f606440f4b7136578ec49a47ec7af23ddefb386a812922c26eb929dc0da3c7b5a24d04fe645d171ed6cbdf2dd3f41534425b4a709b793de783fa2b973ef1eb68ca4cbc8697ba576ff13534ced1f4976d8b3d7739d7b5ee6c113c7c67453905e7311f37f8bde9ebd13a60597a748a421ab730351a19b37ae016bf30b884b6e554c62df963c76284dfca9faf6a980b28817387e6dc67e8ed6fd758c92deb55a34f2eb5b303f7083028b548986861f2398dbaa3b2d08172b60c61edf28e44efed84920699974adac927b5f&X-Goog-SignedHeaders=host&X-User=2931823730: HTTPSConnectionPool(host='storage.googleapis.com', port=443): Max retries exceeded with url: /wandb-production.appspot.com/2931823730-harbin-institute-of-technology/ltu-as/p17gmulg/requirements.txt?X-Goog-Algorithm=GOOG4-RSA-SHA256&X-Goog-Credential=gorilla-files-url-signer-man%40wandb-production.iam.gserviceaccount.com%2F20250411%2Fauto%2Fstorage%2Fgoog4_request&X-Goog-Date=20250411T150043Z&X-Goog-Expires=86399&X-Goog-Signature=14dcd9bd7741ba854922781779b244d065a2f93e20042ce112d03d9a74fa6ceafd1a02b76cfe7e1d83ceecfb3b6c3b3ccc9fadcd34593f606440f4b7136578ec49a47ec7af23ddefb386a812922c26eb929dc0da3c7b5a24d04fe645d171ed6cbdf2dd3f41534425b4a709b793de783fa2b973ef1eb68ca4cbc8697ba576ff13534ced1f4976d8b3d7739d7b5ee6c113c7c67453905e7311f37f8bde9ebd13a60597a748a421ab730351a19b37ae016bf30b884b6e554c62df963c76284dfca9faf6a980b28817387e6dc67e8ed6fd758c92deb55a34f2eb5b303f7083028b548986861f2398dbaa3b2d08172b60c61edf28e44efed84920699974adac927b5f&X-Goog-SignedHeaders=host&X-User=2931823730 (Caused by NewConnectionError('<urllib3.connection.HTTPSConnection object at 0x7f702edb5ed0>: Failed to establish a new connection: [Errno 101] Network is unreachable'))
2025-04-11 15:01:52,830 ERROR   wandb-upload_2:20960 [internal_api.py:upload_file():2558] upload_file request headers: {'User-Agent': 'python-requests/2.32.3', 'Accept-Encoding': 'gzip, deflate, br', 'Accept': '*/*', 'Connection': 'keep-alive', 'Content-Length': '4212'}
2025-04-11 15:01:52,830 ERROR   wandb-upload_2:20960 [internal_api.py:upload_file():2560] upload_file response body: 
2025-04-11 15:01:53,630 DEBUG   HandlerThread:20960 [handler.py:handle_request():146] handle_request: status_report
2025-04-11 15:01:53,631 DEBUG   HandlerThread:20960 [handler.py:handle_request():146] handle_request: poll_exit
2025-04-11 15:01:53,632 DEBUG   SenderThread:20960 [sender.py:send_request():407] send_request: poll_exit
2025-04-11 15:01:54,633 DEBUG   HandlerThread:20960 [handler.py:handle_request():146] handle_request: poll_exit
2025-04-11 15:01:54,634 DEBUG   SenderThread:20960 [sender.py:send_request():407] send_request: poll_exit
2025-04-11 15:01:54,881 ERROR   wandb-upload_4:20960 [internal_api.py:upload_file():2556] upload_file exception https://storage.googleapis.com/wandb-production.appspot.com/2931823730-harbin-institute-of-technology/ltu-as/p17gmulg/output.log?X-Goog-Algorithm=GOOG4-RSA-SHA256&X-Goog-Credential=gorilla-files-url-signer-man%40wandb-production.iam.gserviceaccount.com%2F20250411%2Fauto%2Fstorage%2Fgoog4_request&X-Goog-Date=20250411T150043Z&X-Goog-Expires=86399&X-Goog-Signature=0308420c548c6bc687992243d2a177fab7c1e559bf54fdb3fcef576cbdb35fedc146e60d263e4a67d7dcf10d49fc5fce2b200db779ede9932190768ef7045285e94ebcab25d5c53df1ac3faccb2e1b3123697207c801b2f9ed9445e272209bc83528d2b276b120193046794812b634842c87ec4fb6a455019b7629adb328930593761b298218336a3352fe2b3ff4677801486c5fbe6d691a897ba443a75ff0090308631a57a9f25c185a2aa064157f9fcd720807f256f1830810dbc582f2f82e719ba0316a4b5743320f3ccfc2826623c2139bccbce4c58bcebd511da09c54dcb483ba9d761279f3786b202a99bd6e9a82147286632175a2481cd79591fa6901&X-Goog-SignedHeaders=host&X-User=2931823730: HTTPSConnectionPool(host='storage.googleapis.com', port=443): Max retries exceeded with url: /wandb-production.appspot.com/2931823730-harbin-institute-of-technology/ltu-as/p17gmulg/output.log?X-Goog-Algorithm=GOOG4-RSA-SHA256&X-Goog-Credential=gorilla-files-url-signer-man%40wandb-production.iam.gserviceaccount.com%2F20250411%2Fauto%2Fstorage%2Fgoog4_request&X-Goog-Date=20250411T150043Z&X-Goog-Expires=86399&X-Goog-Signature=0308420c548c6bc687992243d2a177fab7c1e559bf54fdb3fcef576cbdb35fedc146e60d263e4a67d7dcf10d49fc5fce2b200db779ede9932190768ef7045285e94ebcab25d5c53df1ac3faccb2e1b3123697207c801b2f9ed9445e272209bc83528d2b276b120193046794812b634842c87ec4fb6a455019b7629adb328930593761b298218336a3352fe2b3ff4677801486c5fbe6d691a897ba443a75ff0090308631a57a9f25c185a2aa064157f9fcd720807f256f1830810dbc582f2f82e719ba0316a4b5743320f3ccfc2826623c2139bccbce4c58bcebd511da09c54dcb483ba9d761279f3786b202a99bd6e9a82147286632175a2481cd79591fa6901&X-Goog-SignedHeaders=host&X-User=2931823730 (Caused by NewConnectionError('<urllib3.connection.HTTPSConnection object at 0x7f702edb5ff0>: Failed to establish a new connection: [Errno 101] Network is unreachable'))
2025-04-11 15:01:54,881 ERROR   wandb-upload_4:20960 [internal_api.py:upload_file():2558] upload_file request headers: {'User-Agent': 'python-requests/2.32.3', 'Accept-Encoding': 'gzip, deflate, br', 'Accept': '*/*', 'Connection': 'keep-alive', 'Content-Length': '4566'}
2025-04-11 15:01:54,881 ERROR   wandb-upload_4:20960 [internal_api.py:upload_file():2560] upload_file response body: 
2025-04-11 15:01:55,636 DEBUG   HandlerThread:20960 [handler.py:handle_request():146] handle_request: poll_exit
2025-04-11 15:01:55,636 DEBUG   SenderThread:20960 [sender.py:send_request():407] send_request: poll_exit
2025-04-11 15:01:56,637 DEBUG   HandlerThread:20960 [handler.py:handle_request():146] handle_request: poll_exit
2025-04-11 15:01:56,638 DEBUG   SenderThread:20960 [sender.py:send_request():407] send_request: poll_exit
2025-04-11 15:01:57,639 DEBUG   HandlerThread:20960 [handler.py:handle_request():146] handle_request: poll_exit
2025-04-11 15:01:57,640 DEBUG   SenderThread:20960 [sender.py:send_request():407] send_request: poll_exit
2025-04-11 15:01:57,717 ERROR   wandb-upload_3:20960 [internal_api.py:upload_file():2556] upload_file exception https://storage.googleapis.com/wandb-production.appspot.com/2931823730-harbin-institute-of-technology/ltu-as/p17gmulg/conda-environment.yaml?X-Goog-Algorithm=GOOG4-RSA-SHA256&X-Goog-Credential=gorilla-files-url-signer-man%40wandb-production.iam.gserviceaccount.com%2F20250411%2Fauto%2Fstorage%2Fgoog4_request&X-Goog-Date=20250411T150043Z&X-Goog-Expires=86399&X-Goog-Signature=00f2737f97b7b1f937f7a9aebdfea9b77a2c6c8e1517ac5604b0ab1d0c7220099661943fa06351c6a2fc07c285f7cde727cfd97257af5eec33c10ff58653cf9d6ebbfa07ca47153a6c0bb6e66bdc5460d4faccd98405adea9703c4f7553f8301273fcfa04cced1cd05c064254e7dbb600c8767e195c3109aa0466581c2735ab0ed4b1f21f2ba2046c29b2199a29cbcedb0f7ba1bce4992ef9fd04257dff85ead08d2ea2f4e835b64a2a3428bb295fd3523de6c1dbcd055c8962bd057f4c676fa028b90c343670ac851f3c26fc59ad1f13a6de4c9ea39dcbd845b4092616d0fe18bd2b09525b48943a5122a270e5637a422663aefc15274ec3ff901174e8eed50&X-Goog-SignedHeaders=host&X-User=2931823730: HTTPSConnectionPool(host='storage.googleapis.com', port=443): Max retries exceeded with url: /wandb-production.appspot.com/2931823730-harbin-institute-of-technology/ltu-as/p17gmulg/conda-environment.yaml?X-Goog-Algorithm=GOOG4-RSA-SHA256&X-Goog-Credential=gorilla-files-url-signer-man%40wandb-production.iam.gserviceaccount.com%2F20250411%2Fauto%2Fstorage%2Fgoog4_request&X-Goog-Date=20250411T150043Z&X-Goog-Expires=86399&X-Goog-Signature=00f2737f97b7b1f937f7a9aebdfea9b77a2c6c8e1517ac5604b0ab1d0c7220099661943fa06351c6a2fc07c285f7cde727cfd97257af5eec33c10ff58653cf9d6ebbfa07ca47153a6c0bb6e66bdc5460d4faccd98405adea9703c4f7553f8301273fcfa04cced1cd05c064254e7dbb600c8767e195c3109aa0466581c2735ab0ed4b1f21f2ba2046c29b2199a29cbcedb0f7ba1bce4992ef9fd04257dff85ead08d2ea2f4e835b64a2a3428bb295fd3523de6c1dbcd055c8962bd057f4c676fa028b90c343670ac851f3c26fc59ad1f13a6de4c9ea39dcbd845b4092616d0fe18bd2b09525b48943a5122a270e5637a422663aefc15274ec3ff901174e8eed50&X-Goog-SignedHeaders=host&X-User=2931823730 (Caused by NewConnectionError('<urllib3.connection.HTTPSConnection object at 0x7f702edb69b0>: Failed to establish a new connection: [Errno 101] Network is unreachable'))
2025-04-11 15:01:57,717 ERROR   wandb-upload_3:20960 [internal_api.py:upload_file():2558] upload_file request headers: {'User-Agent': 'python-requests/2.32.3', 'Accept-Encoding': 'gzip, deflate, br', 'Accept': '*/*', 'Connection': 'keep-alive', 'Content-Length': '8281'}
2025-04-11 15:01:57,717 ERROR   wandb-upload_3:20960 [internal_api.py:upload_file():2560] upload_file response body: 
2025-04-11 15:01:58,631 ERROR   wandb-upload_1:20960 [internal_api.py:upload_file():2556] upload_file exception https://storage.googleapis.com/wandb-production.appspot.com/2931823730-harbin-institute-of-technology/ltu-as/p17gmulg/config.yaml?X-Goog-Algorithm=GOOG4-RSA-SHA256&X-Goog-Credential=gorilla-files-url-signer-man%40wandb-production.iam.gserviceaccount.com%2F20250411%2Fauto%2Fstorage%2Fgoog4_request&X-Goog-Date=20250411T150043Z&X-Goog-Expires=86399&X-Goog-Signature=2b94521395b91d2c6da28bc88c8fc2fc455de0bcface43802f47c8b6e4bc65bb0576e272b4d89ff080de61ad7e2630455fac8f8556a8d2a1ec83e0f726c7121de7b3c84adbbc041acaa6d30505fb9bb73aba360d8d7b4ca92305f90ec83f114c9376b107f51e30bb10fe0101942367b2da5037b93caba63940e541e0ffa3d92a71c487bd952d659a72612e9bb29d3d5e5ae6c723dd8f91e2eb021292ec34d2126321481511017f837aa8cc0777e29c645f288e5c68da432b266e08df490dd625a85a31dd1fb03e68e1afb786b509ca67234739c6680f80bb31dd4c6da4212ae8dc8e5e0ff83679cfe8036d20ce4154044ae026f98c7e926fd492687e6ba80a2f&X-Goog-SignedHeaders=host&X-User=2931823730: HTTPSConnectionPool(host='storage.googleapis.com', port=443): Max retries exceeded with url: /wandb-production.appspot.com/2931823730-harbin-institute-of-technology/ltu-as/p17gmulg/config.yaml?X-Goog-Algorithm=GOOG4-RSA-SHA256&X-Goog-Credential=gorilla-files-url-signer-man%40wandb-production.iam.gserviceaccount.com%2F20250411%2Fauto%2Fstorage%2Fgoog4_request&X-Goog-Date=20250411T150043Z&X-Goog-Expires=86399&X-Goog-Signature=2b94521395b91d2c6da28bc88c8fc2fc455de0bcface43802f47c8b6e4bc65bb0576e272b4d89ff080de61ad7e2630455fac8f8556a8d2a1ec83e0f726c7121de7b3c84adbbc041acaa6d30505fb9bb73aba360d8d7b4ca92305f90ec83f114c9376b107f51e30bb10fe0101942367b2da5037b93caba63940e541e0ffa3d92a71c487bd952d659a72612e9bb29d3d5e5ae6c723dd8f91e2eb021292ec34d2126321481511017f837aa8cc0777e29c645f288e5c68da432b266e08df490dd625a85a31dd1fb03e68e1afb786b509ca67234739c6680f80bb31dd4c6da4212ae8dc8e5e0ff83679cfe8036d20ce4154044ae026f98c7e926fd492687e6ba80a2f&X-Goog-SignedHeaders=host&X-User=2931823730 (Caused by NewConnectionError('<urllib3.connection.HTTPSConnection object at 0x7f702edb6530>: Failed to establish a new connection: [Errno 101] Network is unreachable'))
2025-04-11 15:01:58,632 ERROR   wandb-upload_1:20960 [internal_api.py:upload_file():2558] upload_file request headers: {'User-Agent': 'python-requests/2.32.3', 'Accept-Encoding': 'gzip, deflate, br', 'Accept': '*/*', 'Connection': 'keep-alive', 'Content-Length': '8666'}
2025-04-11 15:01:58,632 ERROR   wandb-upload_1:20960 [internal_api.py:upload_file():2560] upload_file response body: 
2025-04-11 15:01:58,640 DEBUG   HandlerThread:20960 [handler.py:handle_request():146] handle_request: poll_exit
2025-04-11 15:01:58,641 DEBUG   HandlerThread:20960 [handler.py:handle_request():146] handle_request: status_report
2025-04-11 15:01:58,642 DEBUG   SenderThread:20960 [sender.py:send_request():407] send_request: poll_exit
2025-04-11 15:01:59,643 DEBUG   HandlerThread:20960 [handler.py:handle_request():146] handle_request: poll_exit
2025-04-11 15:01:59,644 DEBUG   SenderThread:20960 [sender.py:send_request():407] send_request: poll_exit
2025-04-11 15:02:00,645 DEBUG   HandlerThread:20960 [handler.py:handle_request():146] handle_request: poll_exit
2025-04-11 15:02:00,646 DEBUG   SenderThread:20960 [sender.py:send_request():407] send_request: poll_exit
2025-04-11 15:02:01,648 DEBUG   HandlerThread:20960 [handler.py:handle_request():146] handle_request: poll_exit
2025-04-11 15:02:01,649 DEBUG   SenderThread:20960 [sender.py:send_request():407] send_request: poll_exit
2025-04-11 15:02:02,649 DEBUG   HandlerThread:20960 [handler.py:handle_request():146] handle_request: poll_exit
2025-04-11 15:02:02,651 DEBUG   SenderThread:20960 [sender.py:send_request():407] send_request: poll_exit
2025-04-11 15:02:03,651 DEBUG   HandlerThread:20960 [handler.py:handle_request():146] handle_request: poll_exit
2025-04-11 15:02:03,652 DEBUG   HandlerThread:20960 [handler.py:handle_request():146] handle_request: status_report
2025-04-11 15:02:03,653 DEBUG   SenderThread:20960 [sender.py:send_request():407] send_request: poll_exit
2025-04-11 15:02:04,653 DEBUG   HandlerThread:20960 [handler.py:handle_request():146] handle_request: poll_exit
2025-04-11 15:02:04,655 DEBUG   SenderThread:20960 [sender.py:send_request():407] send_request: poll_exit
2025-04-11 15:02:05,656 DEBUG   HandlerThread:20960 [handler.py:handle_request():146] handle_request: poll_exit
2025-04-11 15:02:05,657 DEBUG   SenderThread:20960 [sender.py:send_request():407] send_request: poll_exit
2025-04-11 15:02:06,657 DEBUG   HandlerThread:20960 [handler.py:handle_request():146] handle_request: poll_exit
2025-04-11 15:02:06,659 DEBUG   SenderThread:20960 [sender.py:send_request():407] send_request: poll_exit
2025-04-11 15:02:07,660 DEBUG   HandlerThread:20960 [handler.py:handle_request():146] handle_request: poll_exit
2025-04-11 15:02:07,661 DEBUG   SenderThread:20960 [sender.py:send_request():407] send_request: poll_exit
2025-04-11 15:02:08,662 DEBUG   HandlerThread:20960 [handler.py:handle_request():146] handle_request: poll_exit
2025-04-11 15:02:08,663 DEBUG   HandlerThread:20960 [handler.py:handle_request():146] handle_request: status_report
2025-04-11 15:02:08,664 DEBUG   SenderThread:20960 [sender.py:send_request():407] send_request: poll_exit
2025-04-11 15:02:09,665 DEBUG   HandlerThread:20960 [handler.py:handle_request():146] handle_request: poll_exit
2025-04-11 15:02:09,666 DEBUG   SenderThread:20960 [sender.py:send_request():407] send_request: poll_exit
2025-04-11 15:02:10,667 DEBUG   HandlerThread:20960 [handler.py:handle_request():146] handle_request: poll_exit
2025-04-11 15:02:10,668 DEBUG   SenderThread:20960 [sender.py:send_request():407] send_request: poll_exit
2025-04-11 15:02:11,669 DEBUG   HandlerThread:20960 [handler.py:handle_request():146] handle_request: poll_exit
2025-04-11 15:02:11,670 DEBUG   SenderThread:20960 [sender.py:send_request():407] send_request: poll_exit
2025-04-11 15:02:12,670 DEBUG   HandlerThread:20960 [handler.py:handle_request():146] handle_request: poll_exit
2025-04-11 15:02:12,672 DEBUG   SenderThread:20960 [sender.py:send_request():407] send_request: poll_exit
2025-04-11 15:02:13,673 DEBUG   HandlerThread:20960 [handler.py:handle_request():146] handle_request: poll_exit
2025-04-11 15:02:13,673 DEBUG   HandlerThread:20960 [handler.py:handle_request():146] handle_request: status_report
2025-04-11 15:02:13,674 DEBUG   SenderThread:20960 [sender.py:send_request():407] send_request: poll_exit
2025-04-11 15:02:14,674 DEBUG   HandlerThread:20960 [handler.py:handle_request():146] handle_request: poll_exit
2025-04-11 15:02:14,675 DEBUG   SenderThread:20960 [sender.py:send_request():407] send_request: poll_exit
2025-04-11 15:02:15,676 DEBUG   HandlerThread:20960 [handler.py:handle_request():146] handle_request: poll_exit
2025-04-11 15:02:15,677 DEBUG   SenderThread:20960 [sender.py:send_request():407] send_request: poll_exit
2025-04-11 15:02:16,678 DEBUG   HandlerThread:20960 [handler.py:handle_request():146] handle_request: poll_exit
2025-04-11 15:02:16,679 DEBUG   SenderThread:20960 [sender.py:send_request():407] send_request: poll_exit
2025-04-11 15:02:17,680 DEBUG   HandlerThread:20960 [handler.py:handle_request():146] handle_request: poll_exit
2025-04-11 15:02:17,681 DEBUG   SenderThread:20960 [sender.py:send_request():407] send_request: poll_exit
2025-04-11 15:02:18,682 DEBUG   HandlerThread:20960 [handler.py:handle_request():146] handle_request: poll_exit
2025-04-11 15:02:18,682 DEBUG   HandlerThread:20960 [handler.py:handle_request():146] handle_request: status_report
2025-04-11 15:02:18,683 DEBUG   SenderThread:20960 [sender.py:send_request():407] send_request: poll_exit
2025-04-11 15:02:19,684 DEBUG   HandlerThread:20960 [handler.py:handle_request():146] handle_request: poll_exit
2025-04-11 15:02:19,685 DEBUG   SenderThread:20960 [sender.py:send_request():407] send_request: poll_exit
2025-04-11 15:02:20,686 DEBUG   HandlerThread:20960 [handler.py:handle_request():146] handle_request: poll_exit
2025-04-11 15:02:20,687 DEBUG   SenderThread:20960 [sender.py:send_request():407] send_request: poll_exit
2025-04-11 15:02:21,688 DEBUG   HandlerThread:20960 [handler.py:handle_request():146] handle_request: poll_exit
2025-04-11 15:02:21,689 DEBUG   SenderThread:20960 [sender.py:send_request():407] send_request: poll_exit
2025-04-11 15:02:22,690 DEBUG   HandlerThread:20960 [handler.py:handle_request():146] handle_request: poll_exit
2025-04-11 15:02:22,691 DEBUG   SenderThread:20960 [sender.py:send_request():407] send_request: poll_exit
2025-04-11 15:02:23,632 WARNING StreamThr :20960 [internal.py:is_dead():414] Internal process exiting, parent pid 18152 disappeared
2025-04-11 15:02:23,633 ERROR   StreamThr :20960 [internal.py:wandb_internal():152] Internal process shutdown.
2025-04-11 15:02:23,691 DEBUG   HandlerThread:20960 [handler.py:handle_request():146] handle_request: poll_exit
2025-04-11 15:02:23,691 INFO    WriterThread:20960 [datastore.py:close():294] close: /root/ltu-main/ltu-main/src/ltu_as/train_scripts/wandb/run-20250411_150006-p17gmulg/run-p17gmulg.wandb
2025-04-11 15:02:23,692 INFO    HandlerThread:20960 [handler.py:finish():866] shutting down handler
2025-04-11 15:02:23,692 INFO    SenderThread:20960 [sender.py:finish():1534] shutting down sender
2025-04-11 15:02:23,693 INFO    SenderThread:20960 [file_pusher.py:finish():175] shutting down file pusher
2025-04-11 15:02:23,693 INFO    SenderThread:20960 [file_pusher.py:join():181] waiting for file pusher
2025-04-11 15:02:44,793 ERROR   wandb-upload_0:20960 [internal_api.py:upload_file():2556] upload_file exception https://storage.googleapis.com/wandb-production.appspot.com/2931823730-harbin-institute-of-technology/ltu-as/p17gmulg/wandb-metadata.json?X-Goog-Algorithm=GOOG4-RSA-SHA256&X-Goog-Credential=gorilla-files-url-signer-man%40wandb-production.iam.gserviceaccount.com%2F20250411%2Fauto%2Fstorage%2Fgoog4_request&X-Goog-Date=20250411T150027Z&X-Goog-Expires=86399&X-Goog-Signature=0fca1f09c246b35184e651f2690bb2d36dc49dab5fec1f973e2c65e5bfefebbfd202f9b4caa1608b01be21ef52649952919cd92fe2c7d0cbaa7d85e1dec4688e3d4bce047b086e7704caa70c0e7cd600a6fa32524d987c1e285f028227ad40a92e888252a5c330544b44a0eab8be632c7210336d5e7ecaf9b4c27dfefc250b2e5f8a04f0124c65480524e79e4ebfbf7f17921a78390961ea9ff85a200da5de126487ab0284a7f24abf28c4a11a45df9fe33a42121f13be1d8e478aaebd8536a5f732611162ce46d0392669452a89459b76adcc2538897ad8710d676cf8b168232f3798549d04eb53b7c89783fcdaea6b7933abd4ab75eccaac8647b7588544b8&X-Goog-SignedHeaders=host&X-User=2931823730: HTTPSConnectionPool(host='storage.googleapis.com', port=443): Max retries exceeded with url: /wandb-production.appspot.com/2931823730-harbin-institute-of-technology/ltu-as/p17gmulg/wandb-metadata.json?X-Goog-Algorithm=GOOG4-RSA-SHA256&X-Goog-Credential=gorilla-files-url-signer-man%40wandb-production.iam.gserviceaccount.com%2F20250411%2Fauto%2Fstorage%2Fgoog4_request&X-Goog-Date=20250411T150027Z&X-Goog-Expires=86399&X-Goog-Signature=0fca1f09c246b35184e651f2690bb2d36dc49dab5fec1f973e2c65e5bfefebbfd202f9b4caa1608b01be21ef52649952919cd92fe2c7d0cbaa7d85e1dec4688e3d4bce047b086e7704caa70c0e7cd600a6fa32524d987c1e285f028227ad40a92e888252a5c330544b44a0eab8be632c7210336d5e7ecaf9b4c27dfefc250b2e5f8a04f0124c65480524e79e4ebfbf7f17921a78390961ea9ff85a200da5de126487ab0284a7f24abf28c4a11a45df9fe33a42121f13be1d8e478aaebd8536a5f732611162ce46d0392669452a89459b76adcc2538897ad8710d676cf8b168232f3798549d04eb53b7c89783fcdaea6b7933abd4ab75eccaac8647b7588544b8&X-Goog-SignedHeaders=host&X-User=2931823730 (Caused by NewConnectionError('<urllib3.connection.HTTPSConnection object at 0x7f702edb59f0>: Failed to establish a new connection: [Errno 101] Network is unreachable'))
2025-04-11 15:02:44,793 ERROR   wandb-upload_0:20960 [internal_api.py:upload_file():2558] upload_file request headers: {'User-Agent': 'python-requests/2.32.3', 'Accept-Encoding': 'gzip, deflate, br', 'Accept': '*/*', 'Connection': 'keep-alive', 'Content-Length': '2212'}
2025-04-11 15:02:44,793 ERROR   wandb-upload_0:20960 [internal_api.py:upload_file():2560] upload_file response body: 
