2025-04-14 14:17:24,764 INFO    StreamThr :8632 [internal.py:wandb_internal():86] W&B internal server running at pid: 8632, started at: 2025-04-14 14:17:24.763236
2025-04-14 14:17:24,768 DEBUG   HandlerThread:8632 [handler.py:handle_request():146] handle_request: status
2025-04-14 14:17:24,772 INFO    WriterThread:8632 [datastore.py:open_for_write():85] open: /root/ltu-main/ltu-main/src/ltu_as/train_scripts/wandb/run-20250414_141724-31odaggz/run-31odaggz.wandb
2025-04-14 14:17:24,795 DEBUG   SenderThread:8632 [sender.py:send():380] send: header
2025-04-14 14:17:24,796 DEBUG   SenderThread:8632 [sender.py:send():380] send: run
2025-04-14 14:17:25,557 INFO    SenderThread:8632 [dir_watcher.py:__init__():211] watching files in: /root/ltu-main/ltu-main/src/ltu_as/train_scripts/wandb/run-20250414_141724-31odaggz/files
2025-04-14 14:17:25,557 INFO    SenderThread:8632 [sender.py:_start_run_threads():1122] run started: 31odaggz with start time 1744640244.764524
2025-04-14 14:17:25,564 DEBUG   HandlerThread:8632 [handler.py:handle_request():146] handle_request: check_version
2025-04-14 14:17:25,565 DEBUG   SenderThread:8632 [sender.py:send_request():407] send_request: check_version
2025-04-14 14:17:25,979 DEBUG   HandlerThread:8632 [handler.py:handle_request():146] handle_request: run_start
2025-04-14 14:17:26,048 DEBUG   HandlerThread:8632 [system_info.py:__init__():32] System info init
2025-04-14 14:17:26,048 DEBUG   HandlerThread:8632 [system_info.py:__init__():47] System info init done
2025-04-14 14:17:26,048 INFO    HandlerThread:8632 [system_monitor.py:start():194] Starting system monitor
2025-04-14 14:17:26,049 INFO    SystemMonitor:8632 [system_monitor.py:_start():158] Starting system asset monitoring threads
2025-04-14 14:17:26,049 INFO    HandlerThread:8632 [system_monitor.py:probe():214] Collecting system info
2025-04-14 14:17:26,050 INFO    SystemMonitor:8632 [interfaces.py:start():190] Started cpu monitoring
2025-04-14 14:17:26,052 INFO    SystemMonitor:8632 [interfaces.py:start():190] Started disk monitoring
2025-04-14 14:17:26,053 INFO    SystemMonitor:8632 [interfaces.py:start():190] Started gpu monitoring
2025-04-14 14:17:26,055 INFO    SystemMonitor:8632 [interfaces.py:start():190] Started memory monitoring
2025-04-14 14:17:26,056 INFO    SystemMonitor:8632 [interfaces.py:start():190] Started network monitoring
2025-04-14 14:17:26,067 DEBUG   HandlerThread:8632 [system_info.py:probe():196] Probing system
2025-04-14 14:17:26,069 DEBUG   HandlerThread:8632 [gitlib.py:_init_repo():53] git repository is invalid
2025-04-14 14:17:26,069 DEBUG   HandlerThread:8632 [system_info.py:probe():244] Probing system done
2025-04-14 14:17:26,069 DEBUG   HandlerThread:8632 [system_monitor.py:probe():223] {'os': 'Linux-4.15.0-213-generic-x86_64-with-glibc2.27', 'python': '3.10.15', 'heartbeatAt': '2025-04-14T14:17:26.067562', 'startedAt': '2025-04-14T14:17:24.622778', 'docker': None, 'cuda': None, 'args': ('--base_model', '../../../pretrained_mdls/ltuas_long_noqa_a6.bin', '--data_path', '../../../openasqa/data/iemocap_preprocess_with_answers_updated.json', '--output_dir', '../exp/ltuas_ft_meld/', '--batch_size', '256', '--micro_batch_size', '1', '--num_epochs', '1', '--learning_rate', '2e-4', '--cutoff_len', '100', '--val_set_size', '0', '--lora_r', '8', '--lora_alpha', '16', '--lora_dropout', '0.05', '--lora_target_modules', '[q_proj,v_proj]', '--group_by_length', '--wandb_run_name', '../exp/ltuas_ft_meld/', '--save_steps', '30', '--trainable_params', 'all'), 'state': 'running', 'program': '/root/ltu-main/ltu-main/src/ltu_as/train_scripts/../finetune_low_resource.py', 'codePathLocal': None, 'host': 'ubuntu', 'username': 'root', 'executable': '/root/anaconda3/envs/venv_ltu/bin/python', 'cpu_count': 4, 'cpu_count_logical': 4, 'cpu_freq': {'current': 2294.523, 'min': 0.0, 'max': 0.0}, 'cpu_freq_per_core': [{'current': 2294.523, 'min': 0.0, 'max': 0.0}, {'current': 2294.523, 'min': 0.0, 'max': 0.0}, {'current': 2294.523, 'min': 0.0, 'max': 0.0}, {'current': 2294.523, 'min': 0.0, 'max': 0.0}], 'disk': {'/': {'total': 499.9882621765137, 'used': 375.69766998291016}}, 'gpu': 'NVIDIA A100-PCIE-40GB', 'gpu_count': 2, 'gpu_devices': [{'name': 'NVIDIA A100-PCIE-40GB', 'memory_total': 42949672960}, {'name': 'NVIDIA A100-PCIE-40GB', 'memory_total': 42949672960}], 'memory': {'total': 19.60204315185547}}
2025-04-14 14:17:26,069 INFO    HandlerThread:8632 [system_monitor.py:probe():224] Finished collecting system info
2025-04-14 14:17:26,069 INFO    HandlerThread:8632 [system_monitor.py:probe():227] Publishing system info
2025-04-14 14:17:26,070 DEBUG   HandlerThread:8632 [system_info.py:_save_pip():52] Saving list of pip packages installed into the current environment
2025-04-14 14:17:26,070 DEBUG   HandlerThread:8632 [system_info.py:_save_pip():68] Saving pip packages done
2025-04-14 14:17:26,070 DEBUG   HandlerThread:8632 [system_info.py:_save_conda():75] Saving list of conda packages installed into the current environment
2025-04-14 14:17:26,561 INFO    Thread-12 :8632 [dir_watcher.py:_on_file_created():271] file/dir created: /root/ltu-main/ltu-main/src/ltu_as/train_scripts/wandb/run-20250414_141724-31odaggz/files/requirements.txt
2025-04-14 14:17:26,562 INFO    Thread-12 :8632 [dir_watcher.py:_on_file_created():271] file/dir created: /root/ltu-main/ltu-main/src/ltu_as/train_scripts/wandb/run-20250414_141724-31odaggz/files/conda-environment.yaml
2025-04-14 14:17:52,074 INFO    cpu       :8632 [interfaces.py:monitor():140] Process cpu has exited.
2025-04-14 14:17:52,075 INFO    memory    :8632 [interfaces.py:monitor():140] Process proc.memory.rssMB has exited.
2025-04-14 14:17:52,075 DEBUG   SystemMonitor:8632 [system_monitor.py:_start():172] Starting system metrics aggregation loop
2025-04-14 14:17:52,077 DEBUG   SystemMonitor:8632 [system_monitor.py:_start():179] Finished system metrics aggregation loop
2025-04-14 14:17:52,077 DEBUG   SystemMonitor:8632 [system_monitor.py:_start():183] Publishing last batch of metrics
2025-04-14 14:17:57,804 WARNING StreamThr :8632 [internal.py:is_dead():414] Internal process exiting, parent pid 8366 disappeared
2025-04-14 14:17:57,804 ERROR   StreamThr :8632 [internal.py:wandb_internal():152] Internal process shutdown.
2025-04-14 14:17:57,975 INFO    SenderThread:8632 [sender.py:finish():1534] shutting down sender
2025-04-14 14:17:57,976 INFO    SenderThread:8632 [dir_watcher.py:finish():358] shutting down directory watcher
2025-04-14 14:17:58,569 INFO    SenderThread:8632 [dir_watcher.py:finish():388] scan: /root/ltu-main/ltu-main/src/ltu_as/train_scripts/wandb/run-20250414_141724-31odaggz/files
2025-04-14 14:17:58,569 INFO    SenderThread:8632 [dir_watcher.py:finish():402] scan save: /root/ltu-main/ltu-main/src/ltu_as/train_scripts/wandb/run-20250414_141724-31odaggz/files/config.yaml config.yaml
2025-04-14 14:17:58,570 INFO    SenderThread:8632 [dir_watcher.py:finish():402] scan save: /root/ltu-main/ltu-main/src/ltu_as/train_scripts/wandb/run-20250414_141724-31odaggz/files/requirements.txt requirements.txt
2025-04-14 14:17:58,570 INFO    SenderThread:8632 [dir_watcher.py:finish():402] scan save: /root/ltu-main/ltu-main/src/ltu_as/train_scripts/wandb/run-20250414_141724-31odaggz/files/conda-environment.yaml conda-environment.yaml
2025-04-14 14:17:58,570 INFO    WriterThread:8632 [datastore.py:close():294] close: /root/ltu-main/ltu-main/src/ltu_as/train_scripts/wandb/run-20250414_141724-31odaggz/run-31odaggz.wandb
2025-04-14 14:17:58,571 INFO    SenderThread:8632 [file_pusher.py:finish():175] shutting down file pusher
2025-04-14 14:17:58,571 INFO    SenderThread:8632 [file_pusher.py:join():181] waiting for file pusher
2025-04-14 14:17:59,126 ERROR   wandb-upload_0:8632 [internal_api.py:upload_file():2556] upload_file exception https://storage.googleapis.com/wandb-production.appspot.com/2931823730-harbin-institute-of-technology/ltu-as/31odaggz/config.yaml?X-Goog-Algorithm=GOOG4-RSA-SHA256&X-Goog-Credential=gorilla-files-url-signer-man%40wandb-production.iam.gserviceaccount.com%2F20250414%2Fauto%2Fstorage%2Fgoog4_request&X-Goog-Date=20250414T141758Z&X-Goog-Expires=86399&X-Goog-Signature=194cc2540813956d5c8881739ee12da627ab3bbc9613646e1fa19950a9fbcc97f73ab2038fb24591ccd6d418d705866191f288db79710c6da977d9eab63e107ec482b8f9c047c1f6b1635d6623dc275398201a0e178592ee283d8a4c18f55aa371b4593564f190f2cb30d32d966224135d41dabfe0e17ee9dc99287431ce1828dbeee990f1ded78bf9a3a9c1855596c220b8ee27e0b993b4113ab5b5a61196cb2e9f4415c0d4600507f84950ab4768125c04edff4ea45832f2ed0f995347e212aafca04c189c117aa7b0526097a07c57714519abbb5adeab4b07e3fac776215d41433663593012ca0635dc00382a328ff58282da55adade619f56b37f96ffa58&X-Goog-SignedHeaders=host&X-User=2931823730: HTTPSConnectionPool(host='storage.googleapis.com', port=443): Max retries exceeded with url: /wandb-production.appspot.com/2931823730-harbin-institute-of-technology/ltu-as/31odaggz/config.yaml?X-Goog-Algorithm=GOOG4-RSA-SHA256&X-Goog-Credential=gorilla-files-url-signer-man%40wandb-production.iam.gserviceaccount.com%2F20250414%2Fauto%2Fstorage%2Fgoog4_request&X-Goog-Date=20250414T141758Z&X-Goog-Expires=86399&X-Goog-Signature=194cc2540813956d5c8881739ee12da627ab3bbc9613646e1fa19950a9fbcc97f73ab2038fb24591ccd6d418d705866191f288db79710c6da977d9eab63e107ec482b8f9c047c1f6b1635d6623dc275398201a0e178592ee283d8a4c18f55aa371b4593564f190f2cb30d32d966224135d41dabfe0e17ee9dc99287431ce1828dbeee990f1ded78bf9a3a9c1855596c220b8ee27e0b993b4113ab5b5a61196cb2e9f4415c0d4600507f84950ab4768125c04edff4ea45832f2ed0f995347e212aafca04c189c117aa7b0526097a07c57714519abbb5adeab4b07e3fac776215d41433663593012ca0635dc00382a328ff58282da55adade619f56b37f96ffa58&X-Goog-SignedHeaders=host&X-User=2931823730 (Caused by NewConnectionError('<urllib3.connection.HTTPSConnection object at 0x7f2914097310>: Failed to establish a new connection: [Errno 101] Network is unreachable'))
2025-04-14 14:17:59,127 ERROR   wandb-upload_0:8632 [internal_api.py:upload_file():2558] upload_file request headers: {'User-Agent': 'python-requests/2.32.3', 'Accept-Encoding': 'gzip, deflate, br', 'Accept': '*/*', 'Connection': 'keep-alive', 'Content-Length': '495'}
2025-04-14 14:17:59,127 ERROR   wandb-upload_0:8632 [internal_api.py:upload_file():2560] upload_file response body: 
2025-04-14 14:17:59,272 ERROR   wandb-upload_1:8632 [internal_api.py:upload_file():2556] upload_file exception https://storage.googleapis.com/wandb-production.appspot.com/2931823730-harbin-institute-of-technology/ltu-as/31odaggz/requirements.txt?X-Goog-Algorithm=GOOG4-RSA-SHA256&X-Goog-Credential=gorilla-files-url-signer-man%40wandb-production.iam.gserviceaccount.com%2F20250414%2Fauto%2Fstorage%2Fgoog4_request&X-Goog-Date=20250414T141759Z&X-Goog-Expires=86399&X-Goog-Signature=5f6153b93ed9fa74deff765545f8c201587fbeb911e62cb3cc4910c63f6fdca03854136261a6bbd672c2d42fbda91a03dfd5489d78595df6bae13a047cfbfbe769a2900d5de43d8c4c2fdb4ff2f62fed69a11d701473162b74edb7cc02410ec05c5598e39df6e9bb66ffd2078fdedad8c5b49972c266a23e216383e15a77f2341156622943959493793689e200b67ed6794be9327090cb298b0aa05d0542348be451ab5ef0eb5d562c63ca86f4825fd09ef41a9735f1b4b10fb4694a9ecfd425ec23727d25a7349defdfe02d9e6ea4e9df4daa5f95cf118267e0c0cc2fcb5a59dc9052a1dbda63c7a3b8ef1aefb68ed47651b521b6d4d3d836c1e68bffd402e8&X-Goog-SignedHeaders=host&X-User=2931823730: HTTPSConnectionPool(host='storage.googleapis.com', port=443): Max retries exceeded with url: /wandb-production.appspot.com/2931823730-harbin-institute-of-technology/ltu-as/31odaggz/requirements.txt?X-Goog-Algorithm=GOOG4-RSA-SHA256&X-Goog-Credential=gorilla-files-url-signer-man%40wandb-production.iam.gserviceaccount.com%2F20250414%2Fauto%2Fstorage%2Fgoog4_request&X-Goog-Date=20250414T141759Z&X-Goog-Expires=86399&X-Goog-Signature=5f6153b93ed9fa74deff765545f8c201587fbeb911e62cb3cc4910c63f6fdca03854136261a6bbd672c2d42fbda91a03dfd5489d78595df6bae13a047cfbfbe769a2900d5de43d8c4c2fdb4ff2f62fed69a11d701473162b74edb7cc02410ec05c5598e39df6e9bb66ffd2078fdedad8c5b49972c266a23e216383e15a77f2341156622943959493793689e200b67ed6794be9327090cb298b0aa05d0542348be451ab5ef0eb5d562c63ca86f4825fd09ef41a9735f1b4b10fb4694a9ecfd425ec23727d25a7349defdfe02d9e6ea4e9df4daa5f95cf118267e0c0cc2fcb5a59dc9052a1dbda63c7a3b8ef1aefb68ed47651b521b6d4d3d836c1e68bffd402e8&X-Goog-SignedHeaders=host&X-User=2931823730 (Caused by NewConnectionError('<urllib3.connection.HTTPSConnection object at 0x7f29140967a0>: Failed to establish a new connection: [Errno 101] Network is unreachable'))
2025-04-14 14:17:59,272 ERROR   wandb-upload_1:8632 [internal_api.py:upload_file():2558] upload_file request headers: {'User-Agent': 'python-requests/2.32.3', 'Accept-Encoding': 'gzip, deflate, br', 'Accept': '*/*', 'Connection': 'keep-alive', 'Content-Length': '5836'}
2025-04-14 14:17:59,273 ERROR   wandb-upload_1:8632 [internal_api.py:upload_file():2560] upload_file response body: 
2025-04-14 14:18:00,187 ERROR   wandb-upload_0:8632 [internal_api.py:upload_file():2556] upload_file exception https://storage.googleapis.com/wandb-production.appspot.com/2931823730-harbin-institute-of-technology/ltu-as/31odaggz/config.yaml?X-Goog-Algorithm=GOOG4-RSA-SHA256&X-Goog-Credential=gorilla-files-url-signer-man%40wandb-production.iam.gserviceaccount.com%2F20250414%2Fauto%2Fstorage%2Fgoog4_request&X-Goog-Date=20250414T141758Z&X-Goog-Expires=86399&X-Goog-Signature=194cc2540813956d5c8881739ee12da627ab3bbc9613646e1fa19950a9fbcc97f73ab2038fb24591ccd6d418d705866191f288db79710c6da977d9eab63e107ec482b8f9c047c1f6b1635d6623dc275398201a0e178592ee283d8a4c18f55aa371b4593564f190f2cb30d32d966224135d41dabfe0e17ee9dc99287431ce1828dbeee990f1ded78bf9a3a9c1855596c220b8ee27e0b993b4113ab5b5a61196cb2e9f4415c0d4600507f84950ab4768125c04edff4ea45832f2ed0f995347e212aafca04c189c117aa7b0526097a07c57714519abbb5adeab4b07e3fac776215d41433663593012ca0635dc00382a328ff58282da55adade619f56b37f96ffa58&X-Goog-SignedHeaders=host&X-User=2931823730: HTTPSConnectionPool(host='storage.googleapis.com', port=443): Max retries exceeded with url: /wandb-production.appspot.com/2931823730-harbin-institute-of-technology/ltu-as/31odaggz/config.yaml?X-Goog-Algorithm=GOOG4-RSA-SHA256&X-Goog-Credential=gorilla-files-url-signer-man%40wandb-production.iam.gserviceaccount.com%2F20250414%2Fauto%2Fstorage%2Fgoog4_request&X-Goog-Date=20250414T141758Z&X-Goog-Expires=86399&X-Goog-Signature=194cc2540813956d5c8881739ee12da627ab3bbc9613646e1fa19950a9fbcc97f73ab2038fb24591ccd6d418d705866191f288db79710c6da977d9eab63e107ec482b8f9c047c1f6b1635d6623dc275398201a0e178592ee283d8a4c18f55aa371b4593564f190f2cb30d32d966224135d41dabfe0e17ee9dc99287431ce1828dbeee990f1ded78bf9a3a9c1855596c220b8ee27e0b993b4113ab5b5a61196cb2e9f4415c0d4600507f84950ab4768125c04edff4ea45832f2ed0f995347e212aafca04c189c117aa7b0526097a07c57714519abbb5adeab4b07e3fac776215d41433663593012ca0635dc00382a328ff58282da55adade619f56b37f96ffa58&X-Goog-SignedHeaders=host&X-User=2931823730 (Caused by NewConnectionError('<urllib3.connection.HTTPSConnection object at 0x7f29140958d0>: Failed to establish a new connection: [Errno 101] Network is unreachable'))
2025-04-14 14:18:00,188 ERROR   wandb-upload_0:8632 [internal_api.py:upload_file():2558] upload_file request headers: {'User-Agent': 'python-requests/2.32.3', 'Accept-Encoding': 'gzip, deflate, br', 'Accept': '*/*', 'Connection': 'keep-alive', 'Content-Length': '495'}
2025-04-14 14:18:00,188 ERROR   wandb-upload_0:8632 [internal_api.py:upload_file():2560] upload_file response body: 
2025-04-14 14:18:00,307 ERROR   wandb-upload_1:8632 [internal_api.py:upload_file():2556] upload_file exception https://storage.googleapis.com/wandb-production.appspot.com/2931823730-harbin-institute-of-technology/ltu-as/31odaggz/requirements.txt?X-Goog-Algorithm=GOOG4-RSA-SHA256&X-Goog-Credential=gorilla-files-url-signer-man%40wandb-production.iam.gserviceaccount.com%2F20250414%2Fauto%2Fstorage%2Fgoog4_request&X-Goog-Date=20250414T141759Z&X-Goog-Expires=86399&X-Goog-Signature=5f6153b93ed9fa74deff765545f8c201587fbeb911e62cb3cc4910c63f6fdca03854136261a6bbd672c2d42fbda91a03dfd5489d78595df6bae13a047cfbfbe769a2900d5de43d8c4c2fdb4ff2f62fed69a11d701473162b74edb7cc02410ec05c5598e39df6e9bb66ffd2078fdedad8c5b49972c266a23e216383e15a77f2341156622943959493793689e200b67ed6794be9327090cb298b0aa05d0542348be451ab5ef0eb5d562c63ca86f4825fd09ef41a9735f1b4b10fb4694a9ecfd425ec23727d25a7349defdfe02d9e6ea4e9df4daa5f95cf118267e0c0cc2fcb5a59dc9052a1dbda63c7a3b8ef1aefb68ed47651b521b6d4d3d836c1e68bffd402e8&X-Goog-SignedHeaders=host&X-User=2931823730: HTTPSConnectionPool(host='storage.googleapis.com', port=443): Max retries exceeded with url: /wandb-production.appspot.com/2931823730-harbin-institute-of-technology/ltu-as/31odaggz/requirements.txt?X-Goog-Algorithm=GOOG4-RSA-SHA256&X-Goog-Credential=gorilla-files-url-signer-man%40wandb-production.iam.gserviceaccount.com%2F20250414%2Fauto%2Fstorage%2Fgoog4_request&X-Goog-Date=20250414T141759Z&X-Goog-Expires=86399&X-Goog-Signature=5f6153b93ed9fa74deff765545f8c201587fbeb911e62cb3cc4910c63f6fdca03854136261a6bbd672c2d42fbda91a03dfd5489d78595df6bae13a047cfbfbe769a2900d5de43d8c4c2fdb4ff2f62fed69a11d701473162b74edb7cc02410ec05c5598e39df6e9bb66ffd2078fdedad8c5b49972c266a23e216383e15a77f2341156622943959493793689e200b67ed6794be9327090cb298b0aa05d0542348be451ab5ef0eb5d562c63ca86f4825fd09ef41a9735f1b4b10fb4694a9ecfd425ec23727d25a7349defdfe02d9e6ea4e9df4daa5f95cf118267e0c0cc2fcb5a59dc9052a1dbda63c7a3b8ef1aefb68ed47651b521b6d4d3d836c1e68bffd402e8&X-Goog-SignedHeaders=host&X-User=2931823730 (Caused by NewConnectionError('<urllib3.connection.HTTPSConnection object at 0x7f2914097940>: Failed to establish a new connection: [Errno 101] Network is unreachable'))
2025-04-14 14:18:00,307 ERROR   wandb-upload_1:8632 [internal_api.py:upload_file():2558] upload_file request headers: {'User-Agent': 'python-requests/2.32.3', 'Accept-Encoding': 'gzip, deflate, br', 'Accept': '*/*', 'Connection': 'keep-alive', 'Content-Length': '5836'}
2025-04-14 14:18:00,307 ERROR   wandb-upload_1:8632 [internal_api.py:upload_file():2560] upload_file response body: 
2025-04-14 14:18:00,308 INFO    wandb-upload_1:8632 [retry.py:__call__():172] Retry attempt failed:
Traceback (most recent call last):
  File "/root/anaconda3/envs/venv_ltu/lib/python3.10/site-packages/urllib3/connection.py", line 198, in _new_conn
    sock = connection.create_connection(
  File "/root/anaconda3/envs/venv_ltu/lib/python3.10/site-packages/urllib3/util/connection.py", line 85, in create_connection
    raise err
  File "/root/anaconda3/envs/venv_ltu/lib/python3.10/site-packages/urllib3/util/connection.py", line 73, in create_connection
    sock.connect(sa)
OSError: [Errno 101] Network is unreachable

The above exception was the direct cause of the following exception:

Traceback (most recent call last):
  File "/root/anaconda3/envs/venv_ltu/lib/python3.10/site-packages/urllib3/connectionpool.py", line 793, in urlopen
    response = self._make_request(
  File "/root/anaconda3/envs/venv_ltu/lib/python3.10/site-packages/urllib3/connectionpool.py", line 491, in _make_request
    raise new_e
  File "/root/anaconda3/envs/venv_ltu/lib/python3.10/site-packages/urllib3/connectionpool.py", line 467, in _make_request
    self._validate_conn(conn)
  File "/root/anaconda3/envs/venv_ltu/lib/python3.10/site-packages/urllib3/connectionpool.py", line 1099, in _validate_conn
    conn.connect()
  File "/root/anaconda3/envs/venv_ltu/lib/python3.10/site-packages/urllib3/connection.py", line 616, in connect
    self.sock = sock = self._new_conn()
  File "/root/anaconda3/envs/venv_ltu/lib/python3.10/site-packages/urllib3/connection.py", line 213, in _new_conn
    raise NewConnectionError(
urllib3.exceptions.NewConnectionError: <urllib3.connection.HTTPSConnection object at 0x7f2914097940>: Failed to establish a new connection: [Errno 101] Network is unreachable

The above exception was the direct cause of the following exception:

Traceback (most recent call last):
  File "/root/anaconda3/envs/venv_ltu/lib/python3.10/site-packages/requests/adapters.py", line 667, in send
    resp = conn.urlopen(
  File "/root/anaconda3/envs/venv_ltu/lib/python3.10/site-packages/urllib3/connectionpool.py", line 847, in urlopen
    retries = retries.increment(
  File "/root/anaconda3/envs/venv_ltu/lib/python3.10/site-packages/urllib3/util/retry.py", line 515, in increment
    raise MaxRetryError(_pool, url, reason) from reason  # type: ignore[arg-type]
urllib3.exceptions.MaxRetryError: HTTPSConnectionPool(host='storage.googleapis.com', port=443): Max retries exceeded with url: /wandb-production.appspot.com/2931823730-harbin-institute-of-technology/ltu-as/31odaggz/requirements.txt?X-Goog-Algorithm=GOOG4-RSA-SHA256&X-Goog-Credential=gorilla-files-url-signer-man%40wandb-production.iam.gserviceaccount.com%2F20250414%2Fauto%2Fstorage%2Fgoog4_request&X-Goog-Date=20250414T141759Z&X-Goog-Expires=86399&X-Goog-Signature=5f6153b93ed9fa74deff765545f8c201587fbeb911e62cb3cc4910c63f6fdca03854136261a6bbd672c2d42fbda91a03dfd5489d78595df6bae13a047cfbfbe769a2900d5de43d8c4c2fdb4ff2f62fed69a11d701473162b74edb7cc02410ec05c5598e39df6e9bb66ffd2078fdedad8c5b49972c266a23e216383e15a77f2341156622943959493793689e200b67ed6794be9327090cb298b0aa05d0542348be451ab5ef0eb5d562c63ca86f4825fd09ef41a9735f1b4b10fb4694a9ecfd425ec23727d25a7349defdfe02d9e6ea4e9df4daa5f95cf118267e0c0cc2fcb5a59dc9052a1dbda63c7a3b8ef1aefb68ed47651b521b6d4d3d836c1e68bffd402e8&X-Goog-SignedHeaders=host&X-User=2931823730 (Caused by NewConnectionError('<urllib3.connection.HTTPSConnection object at 0x7f2914097940>: Failed to establish a new connection: [Errno 101] Network is unreachable'))

During handling of the above exception, another exception occurred:

Traceback (most recent call last):
  File "/root/anaconda3/envs/venv_ltu/lib/python3.10/site-packages/wandb/sdk/internal/internal_api.py", line 2549, in upload_file
    response = self._upload_file_session.put(
  File "/root/anaconda3/envs/venv_ltu/lib/python3.10/site-packages/requests/sessions.py", line 649, in put
    return self.request("PUT", url, data=data, **kwargs)
  File "/root/anaconda3/envs/venv_ltu/lib/python3.10/site-packages/requests/sessions.py", line 589, in request
    resp = self.send(prep, **send_kwargs)
  File "/root/anaconda3/envs/venv_ltu/lib/python3.10/site-packages/requests/sessions.py", line 703, in send
    r = adapter.send(request, **kwargs)
  File "/root/anaconda3/envs/venv_ltu/lib/python3.10/site-packages/requests/adapters.py", line 700, in send
    raise ConnectionError(e, request=request)
requests.exceptions.ConnectionError: HTTPSConnectionPool(host='storage.googleapis.com', port=443): Max retries exceeded with url: /wandb-production.appspot.com/2931823730-harbin-institute-of-technology/ltu-as/31odaggz/requirements.txt?X-Goog-Algorithm=GOOG4-RSA-SHA256&X-Goog-Credential=gorilla-files-url-signer-man%40wandb-production.iam.gserviceaccount.com%2F20250414%2Fauto%2Fstorage%2Fgoog4_request&X-Goog-Date=20250414T141759Z&X-Goog-Expires=86399&X-Goog-Signature=5f6153b93ed9fa74deff765545f8c201587fbeb911e62cb3cc4910c63f6fdca03854136261a6bbd672c2d42fbda91a03dfd5489d78595df6bae13a047cfbfbe769a2900d5de43d8c4c2fdb4ff2f62fed69a11d701473162b74edb7cc02410ec05c5598e39df6e9bb66ffd2078fdedad8c5b49972c266a23e216383e15a77f2341156622943959493793689e200b67ed6794be9327090cb298b0aa05d0542348be451ab5ef0eb5d562c63ca86f4825fd09ef41a9735f1b4b10fb4694a9ecfd425ec23727d25a7349defdfe02d9e6ea4e9df4daa5f95cf118267e0c0cc2fcb5a59dc9052a1dbda63c7a3b8ef1aefb68ed47651b521b6d4d3d836c1e68bffd402e8&X-Goog-SignedHeaders=host&X-User=2931823730 (Caused by NewConnectionError('<urllib3.connection.HTTPSConnection object at 0x7f2914097940>: Failed to establish a new connection: [Errno 101] Network is unreachable'))

During handling of the above exception, another exception occurred:

Traceback (most recent call last):
  File "/root/anaconda3/envs/venv_ltu/lib/python3.10/site-packages/wandb/sdk/lib/retry.py", line 131, in __call__
    result = self._call_fn(*args, **kwargs)
  File "/root/anaconda3/envs/venv_ltu/lib/python3.10/site-packages/wandb/sdk/internal/internal_api.py", line 2580, in upload_file
    raise _e.with_traceback(sys.exc_info()[2])
  File "/root/anaconda3/envs/venv_ltu/lib/python3.10/site-packages/wandb/sdk/internal/internal_api.py", line 2549, in upload_file
    response = self._upload_file_session.put(
  File "/root/anaconda3/envs/venv_ltu/lib/python3.10/site-packages/requests/sessions.py", line 649, in put
    return self.request("PUT", url, data=data, **kwargs)
  File "/root/anaconda3/envs/venv_ltu/lib/python3.10/site-packages/requests/sessions.py", line 589, in request
    resp = self.send(prep, **send_kwargs)
  File "/root/anaconda3/envs/venv_ltu/lib/python3.10/site-packages/requests/sessions.py", line 703, in send
    r = adapter.send(request, **kwargs)
  File "/root/anaconda3/envs/venv_ltu/lib/python3.10/site-packages/requests/adapters.py", line 700, in send
    raise ConnectionError(e, request=request)
wandb.sdk.lib.retry.TransientError: None
2025-04-14 14:18:02,408 ERROR   wandb-upload_0:8632 [internal_api.py:upload_file():2556] upload_file exception https://storage.googleapis.com/wandb-production.appspot.com/2931823730-harbin-institute-of-technology/ltu-as/31odaggz/config.yaml?X-Goog-Algorithm=GOOG4-RSA-SHA256&X-Goog-Credential=gorilla-files-url-signer-man%40wandb-production.iam.gserviceaccount.com%2F20250414%2Fauto%2Fstorage%2Fgoog4_request&X-Goog-Date=20250414T141758Z&X-Goog-Expires=86399&X-Goog-Signature=194cc2540813956d5c8881739ee12da627ab3bbc9613646e1fa19950a9fbcc97f73ab2038fb24591ccd6d418d705866191f288db79710c6da977d9eab63e107ec482b8f9c047c1f6b1635d6623dc275398201a0e178592ee283d8a4c18f55aa371b4593564f190f2cb30d32d966224135d41dabfe0e17ee9dc99287431ce1828dbeee990f1ded78bf9a3a9c1855596c220b8ee27e0b993b4113ab5b5a61196cb2e9f4415c0d4600507f84950ab4768125c04edff4ea45832f2ed0f995347e212aafca04c189c117aa7b0526097a07c57714519abbb5adeab4b07e3fac776215d41433663593012ca0635dc00382a328ff58282da55adade619f56b37f96ffa58&X-Goog-SignedHeaders=host&X-User=2931823730: HTTPSConnectionPool(host='storage.googleapis.com', port=443): Max retries exceeded with url: /wandb-production.appspot.com/2931823730-harbin-institute-of-technology/ltu-as/31odaggz/config.yaml?X-Goog-Algorithm=GOOG4-RSA-SHA256&X-Goog-Credential=gorilla-files-url-signer-man%40wandb-production.iam.gserviceaccount.com%2F20250414%2Fauto%2Fstorage%2Fgoog4_request&X-Goog-Date=20250414T141758Z&X-Goog-Expires=86399&X-Goog-Signature=194cc2540813956d5c8881739ee12da627ab3bbc9613646e1fa19950a9fbcc97f73ab2038fb24591ccd6d418d705866191f288db79710c6da977d9eab63e107ec482b8f9c047c1f6b1635d6623dc275398201a0e178592ee283d8a4c18f55aa371b4593564f190f2cb30d32d966224135d41dabfe0e17ee9dc99287431ce1828dbeee990f1ded78bf9a3a9c1855596c220b8ee27e0b993b4113ab5b5a61196cb2e9f4415c0d4600507f84950ab4768125c04edff4ea45832f2ed0f995347e212aafca04c189c117aa7b0526097a07c57714519abbb5adeab4b07e3fac776215d41433663593012ca0635dc00382a328ff58282da55adade619f56b37f96ffa58&X-Goog-SignedHeaders=host&X-User=2931823730 (Caused by NewConnectionError('<urllib3.connection.HTTPSConnection object at 0x7f29140ec370>: Failed to establish a new connection: [Errno 101] Network is unreachable'))
2025-04-14 14:18:02,408 ERROR   wandb-upload_0:8632 [internal_api.py:upload_file():2558] upload_file request headers: {'User-Agent': 'python-requests/2.32.3', 'Accept-Encoding': 'gzip, deflate, br', 'Accept': '*/*', 'Connection': 'keep-alive', 'Content-Length': '495'}
2025-04-14 14:18:02,408 ERROR   wandb-upload_0:8632 [internal_api.py:upload_file():2560] upload_file response body: 
2025-04-14 14:18:03,168 ERROR   wandb-upload_1:8632 [internal_api.py:upload_file():2556] upload_file exception https://storage.googleapis.com/wandb-production.appspot.com/2931823730-harbin-institute-of-technology/ltu-as/31odaggz/requirements.txt?X-Goog-Algorithm=GOOG4-RSA-SHA256&X-Goog-Credential=gorilla-files-url-signer-man%40wandb-production.iam.gserviceaccount.com%2F20250414%2Fauto%2Fstorage%2Fgoog4_request&X-Goog-Date=20250414T141759Z&X-Goog-Expires=86399&X-Goog-Signature=5f6153b93ed9fa74deff765545f8c201587fbeb911e62cb3cc4910c63f6fdca03854136261a6bbd672c2d42fbda91a03dfd5489d78595df6bae13a047cfbfbe769a2900d5de43d8c4c2fdb4ff2f62fed69a11d701473162b74edb7cc02410ec05c5598e39df6e9bb66ffd2078fdedad8c5b49972c266a23e216383e15a77f2341156622943959493793689e200b67ed6794be9327090cb298b0aa05d0542348be451ab5ef0eb5d562c63ca86f4825fd09ef41a9735f1b4b10fb4694a9ecfd425ec23727d25a7349defdfe02d9e6ea4e9df4daa5f95cf118267e0c0cc2fcb5a59dc9052a1dbda63c7a3b8ef1aefb68ed47651b521b6d4d3d836c1e68bffd402e8&X-Goog-SignedHeaders=host&X-User=2931823730: HTTPSConnectionPool(host='storage.googleapis.com', port=443): Max retries exceeded with url: /wandb-production.appspot.com/2931823730-harbin-institute-of-technology/ltu-as/31odaggz/requirements.txt?X-Goog-Algorithm=GOOG4-RSA-SHA256&X-Goog-Credential=gorilla-files-url-signer-man%40wandb-production.iam.gserviceaccount.com%2F20250414%2Fauto%2Fstorage%2Fgoog4_request&X-Goog-Date=20250414T141759Z&X-Goog-Expires=86399&X-Goog-Signature=5f6153b93ed9fa74deff765545f8c201587fbeb911e62cb3cc4910c63f6fdca03854136261a6bbd672c2d42fbda91a03dfd5489d78595df6bae13a047cfbfbe769a2900d5de43d8c4c2fdb4ff2f62fed69a11d701473162b74edb7cc02410ec05c5598e39df6e9bb66ffd2078fdedad8c5b49972c266a23e216383e15a77f2341156622943959493793689e200b67ed6794be9327090cb298b0aa05d0542348be451ab5ef0eb5d562c63ca86f4825fd09ef41a9735f1b4b10fb4694a9ecfd425ec23727d25a7349defdfe02d9e6ea4e9df4daa5f95cf118267e0c0cc2fcb5a59dc9052a1dbda63c7a3b8ef1aefb68ed47651b521b6d4d3d836c1e68bffd402e8&X-Goog-SignedHeaders=host&X-User=2931823730 (Caused by NewConnectionError('<urllib3.connection.HTTPSConnection object at 0x7f29140ec7c0>: Failed to establish a new connection: [Errno 101] Network is unreachable'))
2025-04-14 14:18:03,169 ERROR   wandb-upload_1:8632 [internal_api.py:upload_file():2558] upload_file request headers: {'User-Agent': 'python-requests/2.32.3', 'Accept-Encoding': 'gzip, deflate, br', 'Accept': '*/*', 'Connection': 'keep-alive', 'Content-Length': '5836'}
2025-04-14 14:18:03,169 ERROR   wandb-upload_1:8632 [internal_api.py:upload_file():2560] upload_file response body: 
2025-04-14 14:18:07,052 ERROR   wandb-upload_0:8632 [internal_api.py:upload_file():2556] upload_file exception https://storage.googleapis.com/wandb-production.appspot.com/2931823730-harbin-institute-of-technology/ltu-as/31odaggz/config.yaml?X-Goog-Algorithm=GOOG4-RSA-SHA256&X-Goog-Credential=gorilla-files-url-signer-man%40wandb-production.iam.gserviceaccount.com%2F20250414%2Fauto%2Fstorage%2Fgoog4_request&X-Goog-Date=20250414T141758Z&X-Goog-Expires=86399&X-Goog-Signature=194cc2540813956d5c8881739ee12da627ab3bbc9613646e1fa19950a9fbcc97f73ab2038fb24591ccd6d418d705866191f288db79710c6da977d9eab63e107ec482b8f9c047c1f6b1635d6623dc275398201a0e178592ee283d8a4c18f55aa371b4593564f190f2cb30d32d966224135d41dabfe0e17ee9dc99287431ce1828dbeee990f1ded78bf9a3a9c1855596c220b8ee27e0b993b4113ab5b5a61196cb2e9f4415c0d4600507f84950ab4768125c04edff4ea45832f2ed0f995347e212aafca04c189c117aa7b0526097a07c57714519abbb5adeab4b07e3fac776215d41433663593012ca0635dc00382a328ff58282da55adade619f56b37f96ffa58&X-Goog-SignedHeaders=host&X-User=2931823730: HTTPSConnectionPool(host='storage.googleapis.com', port=443): Max retries exceeded with url: /wandb-production.appspot.com/2931823730-harbin-institute-of-technology/ltu-as/31odaggz/config.yaml?X-Goog-Algorithm=GOOG4-RSA-SHA256&X-Goog-Credential=gorilla-files-url-signer-man%40wandb-production.iam.gserviceaccount.com%2F20250414%2Fauto%2Fstorage%2Fgoog4_request&X-Goog-Date=20250414T141758Z&X-Goog-Expires=86399&X-Goog-Signature=194cc2540813956d5c8881739ee12da627ab3bbc9613646e1fa19950a9fbcc97f73ab2038fb24591ccd6d418d705866191f288db79710c6da977d9eab63e107ec482b8f9c047c1f6b1635d6623dc275398201a0e178592ee283d8a4c18f55aa371b4593564f190f2cb30d32d966224135d41dabfe0e17ee9dc99287431ce1828dbeee990f1ded78bf9a3a9c1855596c220b8ee27e0b993b4113ab5b5a61196cb2e9f4415c0d4600507f84950ab4768125c04edff4ea45832f2ed0f995347e212aafca04c189c117aa7b0526097a07c57714519abbb5adeab4b07e3fac776215d41433663593012ca0635dc00382a328ff58282da55adade619f56b37f96ffa58&X-Goog-SignedHeaders=host&X-User=2931823730 (Caused by NewConnectionError('<urllib3.connection.HTTPSConnection object at 0x7f29140ecbe0>: Failed to establish a new connection: [Errno 101] Network is unreachable'))
2025-04-14 14:18:07,052 ERROR   wandb-upload_0:8632 [internal_api.py:upload_file():2558] upload_file request headers: {'User-Agent': 'python-requests/2.32.3', 'Accept-Encoding': 'gzip, deflate, br', 'Accept': '*/*', 'Connection': 'keep-alive', 'Content-Length': '495'}
2025-04-14 14:18:07,052 ERROR   wandb-upload_0:8632 [internal_api.py:upload_file():2560] upload_file response body: 
2025-04-14 14:18:07,813 ERROR   wandb-upload_1:8632 [internal_api.py:upload_file():2556] upload_file exception https://storage.googleapis.com/wandb-production.appspot.com/2931823730-harbin-institute-of-technology/ltu-as/31odaggz/requirements.txt?X-Goog-Algorithm=GOOG4-RSA-SHA256&X-Goog-Credential=gorilla-files-url-signer-man%40wandb-production.iam.gserviceaccount.com%2F20250414%2Fauto%2Fstorage%2Fgoog4_request&X-Goog-Date=20250414T141759Z&X-Goog-Expires=86399&X-Goog-Signature=5f6153b93ed9fa74deff765545f8c201587fbeb911e62cb3cc4910c63f6fdca03854136261a6bbd672c2d42fbda91a03dfd5489d78595df6bae13a047cfbfbe769a2900d5de43d8c4c2fdb4ff2f62fed69a11d701473162b74edb7cc02410ec05c5598e39df6e9bb66ffd2078fdedad8c5b49972c266a23e216383e15a77f2341156622943959493793689e200b67ed6794be9327090cb298b0aa05d0542348be451ab5ef0eb5d562c63ca86f4825fd09ef41a9735f1b4b10fb4694a9ecfd425ec23727d25a7349defdfe02d9e6ea4e9df4daa5f95cf118267e0c0cc2fcb5a59dc9052a1dbda63c7a3b8ef1aefb68ed47651b521b6d4d3d836c1e68bffd402e8&X-Goog-SignedHeaders=host&X-User=2931823730: HTTPSConnectionPool(host='storage.googleapis.com', port=443): Max retries exceeded with url: /wandb-production.appspot.com/2931823730-harbin-institute-of-technology/ltu-as/31odaggz/requirements.txt?X-Goog-Algorithm=GOOG4-RSA-SHA256&X-Goog-Credential=gorilla-files-url-signer-man%40wandb-production.iam.gserviceaccount.com%2F20250414%2Fauto%2Fstorage%2Fgoog4_request&X-Goog-Date=20250414T141759Z&X-Goog-Expires=86399&X-Goog-Signature=5f6153b93ed9fa74deff765545f8c201587fbeb911e62cb3cc4910c63f6fdca03854136261a6bbd672c2d42fbda91a03dfd5489d78595df6bae13a047cfbfbe769a2900d5de43d8c4c2fdb4ff2f62fed69a11d701473162b74edb7cc02410ec05c5598e39df6e9bb66ffd2078fdedad8c5b49972c266a23e216383e15a77f2341156622943959493793689e200b67ed6794be9327090cb298b0aa05d0542348be451ab5ef0eb5d562c63ca86f4825fd09ef41a9735f1b4b10fb4694a9ecfd425ec23727d25a7349defdfe02d9e6ea4e9df4daa5f95cf118267e0c0cc2fcb5a59dc9052a1dbda63c7a3b8ef1aefb68ed47651b521b6d4d3d836c1e68bffd402e8&X-Goog-SignedHeaders=host&X-User=2931823730 (Caused by NewConnectionError('<urllib3.connection.HTTPSConnection object at 0x7f29140ed120>: Failed to establish a new connection: [Errno 101] Network is unreachable'))
2025-04-14 14:18:07,813 ERROR   wandb-upload_1:8632 [internal_api.py:upload_file():2558] upload_file request headers: {'User-Agent': 'python-requests/2.32.3', 'Accept-Encoding': 'gzip, deflate, br', 'Accept': '*/*', 'Connection': 'keep-alive', 'Content-Length': '5836'}
2025-04-14 14:18:07,814 ERROR   wandb-upload_1:8632 [internal_api.py:upload_file():2560] upload_file response body: 
2025-04-14 14:18:16,102 ERROR   wandb-upload_0:8632 [internal_api.py:upload_file():2556] upload_file exception https://storage.googleapis.com/wandb-production.appspot.com/2931823730-harbin-institute-of-technology/ltu-as/31odaggz/config.yaml?X-Goog-Algorithm=GOOG4-RSA-SHA256&X-Goog-Credential=gorilla-files-url-signer-man%40wandb-production.iam.gserviceaccount.com%2F20250414%2Fauto%2Fstorage%2Fgoog4_request&X-Goog-Date=20250414T141758Z&X-Goog-Expires=86399&X-Goog-Signature=194cc2540813956d5c8881739ee12da627ab3bbc9613646e1fa19950a9fbcc97f73ab2038fb24591ccd6d418d705866191f288db79710c6da977d9eab63e107ec482b8f9c047c1f6b1635d6623dc275398201a0e178592ee283d8a4c18f55aa371b4593564f190f2cb30d32d966224135d41dabfe0e17ee9dc99287431ce1828dbeee990f1ded78bf9a3a9c1855596c220b8ee27e0b993b4113ab5b5a61196cb2e9f4415c0d4600507f84950ab4768125c04edff4ea45832f2ed0f995347e212aafca04c189c117aa7b0526097a07c57714519abbb5adeab4b07e3fac776215d41433663593012ca0635dc00382a328ff58282da55adade619f56b37f96ffa58&X-Goog-SignedHeaders=host&X-User=2931823730: HTTPSConnectionPool(host='storage.googleapis.com', port=443): Max retries exceeded with url: /wandb-production.appspot.com/2931823730-harbin-institute-of-technology/ltu-as/31odaggz/config.yaml?X-Goog-Algorithm=GOOG4-RSA-SHA256&X-Goog-Credential=gorilla-files-url-signer-man%40wandb-production.iam.gserviceaccount.com%2F20250414%2Fauto%2Fstorage%2Fgoog4_request&X-Goog-Date=20250414T141758Z&X-Goog-Expires=86399&X-Goog-Signature=194cc2540813956d5c8881739ee12da627ab3bbc9613646e1fa19950a9fbcc97f73ab2038fb24591ccd6d418d705866191f288db79710c6da977d9eab63e107ec482b8f9c047c1f6b1635d6623dc275398201a0e178592ee283d8a4c18f55aa371b4593564f190f2cb30d32d966224135d41dabfe0e17ee9dc99287431ce1828dbeee990f1ded78bf9a3a9c1855596c220b8ee27e0b993b4113ab5b5a61196cb2e9f4415c0d4600507f84950ab4768125c04edff4ea45832f2ed0f995347e212aafca04c189c117aa7b0526097a07c57714519abbb5adeab4b07e3fac776215d41433663593012ca0635dc00382a328ff58282da55adade619f56b37f96ffa58&X-Goog-SignedHeaders=host&X-User=2931823730 (Caused by NewConnectionError('<urllib3.connection.HTTPSConnection object at 0x7f2914095e70>: Failed to establish a new connection: [Errno 101] Network is unreachable'))
2025-04-14 14:18:16,102 ERROR   wandb-upload_0:8632 [internal_api.py:upload_file():2558] upload_file request headers: {'User-Agent': 'python-requests/2.32.3', 'Accept-Encoding': 'gzip, deflate, br', 'Accept': '*/*', 'Connection': 'keep-alive', 'Content-Length': '495'}
2025-04-14 14:18:16,102 ERROR   wandb-upload_0:8632 [internal_api.py:upload_file():2560] upload_file response body: 
2025-04-14 14:18:16,124 DEBUG   HandlerThread:8632 [system_info.py:_save_conda():87] Saving conda packages done
2025-04-14 14:18:16,125 INFO    HandlerThread:8632 [system_monitor.py:probe():229] Finished publishing system info
2025-04-14 14:18:16,552 INFO    HandlerThread:8632 [handler.py:finish():866] shutting down handler
2025-04-14 14:18:16,552 INFO    HandlerThread:8632 [system_monitor.py:finish():203] Stopping system monitor
2025-04-14 14:18:16,552 INFO    HandlerThread:8632 [interfaces.py:finish():202] Joined cpu monitor
2025-04-14 14:18:16,552 INFO    HandlerThread:8632 [interfaces.py:finish():202] Joined disk monitor
2025-04-14 14:18:16,553 INFO    HandlerThread:8632 [interfaces.py:finish():202] Joined gpu monitor
2025-04-14 14:18:16,553 INFO    HandlerThread:8632 [interfaces.py:finish():202] Joined memory monitor
2025-04-14 14:18:16,553 INFO    HandlerThread:8632 [interfaces.py:finish():202] Joined network monitor
2025-04-14 14:18:16,561 ERROR   wandb-upload_1:8632 [internal_api.py:upload_file():2556] upload_file exception https://storage.googleapis.com/wandb-production.appspot.com/2931823730-harbin-institute-of-technology/ltu-as/31odaggz/requirements.txt?X-Goog-Algorithm=GOOG4-RSA-SHA256&X-Goog-Credential=gorilla-files-url-signer-man%40wandb-production.iam.gserviceaccount.com%2F20250414%2Fauto%2Fstorage%2Fgoog4_request&X-Goog-Date=20250414T141759Z&X-Goog-Expires=86399&X-Goog-Signature=5f6153b93ed9fa74deff765545f8c201587fbeb911e62cb3cc4910c63f6fdca03854136261a6bbd672c2d42fbda91a03dfd5489d78595df6bae13a047cfbfbe769a2900d5de43d8c4c2fdb4ff2f62fed69a11d701473162b74edb7cc02410ec05c5598e39df6e9bb66ffd2078fdedad8c5b49972c266a23e216383e15a77f2341156622943959493793689e200b67ed6794be9327090cb298b0aa05d0542348be451ab5ef0eb5d562c63ca86f4825fd09ef41a9735f1b4b10fb4694a9ecfd425ec23727d25a7349defdfe02d9e6ea4e9df4daa5f95cf118267e0c0cc2fcb5a59dc9052a1dbda63c7a3b8ef1aefb68ed47651b521b6d4d3d836c1e68bffd402e8&X-Goog-SignedHeaders=host&X-User=2931823730: HTTPSConnectionPool(host='storage.googleapis.com', port=443): Max retries exceeded with url: /wandb-production.appspot.com/2931823730-harbin-institute-of-technology/ltu-as/31odaggz/requirements.txt?X-Goog-Algorithm=GOOG4-RSA-SHA256&X-Goog-Credential=gorilla-files-url-signer-man%40wandb-production.iam.gserviceaccount.com%2F20250414%2Fauto%2Fstorage%2Fgoog4_request&X-Goog-Date=20250414T141759Z&X-Goog-Expires=86399&X-Goog-Signature=5f6153b93ed9fa74deff765545f8c201587fbeb911e62cb3cc4910c63f6fdca03854136261a6bbd672c2d42fbda91a03dfd5489d78595df6bae13a047cfbfbe769a2900d5de43d8c4c2fdb4ff2f62fed69a11d701473162b74edb7cc02410ec05c5598e39df6e9bb66ffd2078fdedad8c5b49972c266a23e216383e15a77f2341156622943959493793689e200b67ed6794be9327090cb298b0aa05d0542348be451ab5ef0eb5d562c63ca86f4825fd09ef41a9735f1b4b10fb4694a9ecfd425ec23727d25a7349defdfe02d9e6ea4e9df4daa5f95cf118267e0c0cc2fcb5a59dc9052a1dbda63c7a3b8ef1aefb68ed47651b521b6d4d3d836c1e68bffd402e8&X-Goog-SignedHeaders=host&X-User=2931823730 (Caused by NewConnectionError('<urllib3.connection.HTTPSConnection object at 0x7f29140ee650>: Failed to establish a new connection: [Errno 101] Network is unreachable'))
2025-04-14 14:18:16,561 ERROR   wandb-upload_1:8632 [internal_api.py:upload_file():2558] upload_file request headers: {'User-Agent': 'python-requests/2.32.3', 'Accept-Encoding': 'gzip, deflate, br', 'Accept': '*/*', 'Connection': 'keep-alive', 'Content-Length': '5836'}
2025-04-14 14:18:16,561 ERROR   wandb-upload_1:8632 [internal_api.py:upload_file():2560] upload_file response body: 
2025-04-14 14:18:32,634 ERROR   wandb-upload_1:8632 [internal_api.py:upload_file():2556] upload_file exception https://storage.googleapis.com/wandb-production.appspot.com/2931823730-harbin-institute-of-technology/ltu-as/31odaggz/requirements.txt?X-Goog-Algorithm=GOOG4-RSA-SHA256&X-Goog-Credential=gorilla-files-url-signer-man%40wandb-production.iam.gserviceaccount.com%2F20250414%2Fauto%2Fstorage%2Fgoog4_request&X-Goog-Date=20250414T141759Z&X-Goog-Expires=86399&X-Goog-Signature=5f6153b93ed9fa74deff765545f8c201587fbeb911e62cb3cc4910c63f6fdca03854136261a6bbd672c2d42fbda91a03dfd5489d78595df6bae13a047cfbfbe769a2900d5de43d8c4c2fdb4ff2f62fed69a11d701473162b74edb7cc02410ec05c5598e39df6e9bb66ffd2078fdedad8c5b49972c266a23e216383e15a77f2341156622943959493793689e200b67ed6794be9327090cb298b0aa05d0542348be451ab5ef0eb5d562c63ca86f4825fd09ef41a9735f1b4b10fb4694a9ecfd425ec23727d25a7349defdfe02d9e6ea4e9df4daa5f95cf118267e0c0cc2fcb5a59dc9052a1dbda63c7a3b8ef1aefb68ed47651b521b6d4d3d836c1e68bffd402e8&X-Goog-SignedHeaders=host&X-User=2931823730: HTTPSConnectionPool(host='storage.googleapis.com', port=443): Max retries exceeded with url: /wandb-production.appspot.com/2931823730-harbin-institute-of-technology/ltu-as/31odaggz/requirements.txt?X-Goog-Algorithm=GOOG4-RSA-SHA256&X-Goog-Credential=gorilla-files-url-signer-man%40wandb-production.iam.gserviceaccount.com%2F20250414%2Fauto%2Fstorage%2Fgoog4_request&X-Goog-Date=20250414T141759Z&X-Goog-Expires=86399&X-Goog-Signature=5f6153b93ed9fa74deff765545f8c201587fbeb911e62cb3cc4910c63f6fdca03854136261a6bbd672c2d42fbda91a03dfd5489d78595df6bae13a047cfbfbe769a2900d5de43d8c4c2fdb4ff2f62fed69a11d701473162b74edb7cc02410ec05c5598e39df6e9bb66ffd2078fdedad8c5b49972c266a23e216383e15a77f2341156622943959493793689e200b67ed6794be9327090cb298b0aa05d0542348be451ab5ef0eb5d562c63ca86f4825fd09ef41a9735f1b4b10fb4694a9ecfd425ec23727d25a7349defdfe02d9e6ea4e9df4daa5f95cf118267e0c0cc2fcb5a59dc9052a1dbda63c7a3b8ef1aefb68ed47651b521b6d4d3d836c1e68bffd402e8&X-Goog-SignedHeaders=host&X-User=2931823730 (Caused by NewConnectionError('<urllib3.connection.HTTPSConnection object at 0x7f2914095630>: Failed to establish a new connection: [Errno 101] Network is unreachable'))
2025-04-14 14:18:32,635 ERROR   wandb-upload_1:8632 [internal_api.py:upload_file():2558] upload_file request headers: {'User-Agent': 'python-requests/2.32.3', 'Accept-Encoding': 'gzip, deflate, br', 'Accept': '*/*', 'Connection': 'keep-alive', 'Content-Length': '5836'}
2025-04-14 14:18:32,635 ERROR   wandb-upload_1:8632 [internal_api.py:upload_file():2560] upload_file response body: 
2025-04-14 14:18:35,555 ERROR   wandb-upload_0:8632 [internal_api.py:upload_file():2556] upload_file exception https://storage.googleapis.com/wandb-production.appspot.com/2931823730-harbin-institute-of-technology/ltu-as/31odaggz/config.yaml?X-Goog-Algorithm=GOOG4-RSA-SHA256&X-Goog-Credential=gorilla-files-url-signer-man%40wandb-production.iam.gserviceaccount.com%2F20250414%2Fauto%2Fstorage%2Fgoog4_request&X-Goog-Date=20250414T141758Z&X-Goog-Expires=86399&X-Goog-Signature=194cc2540813956d5c8881739ee12da627ab3bbc9613646e1fa19950a9fbcc97f73ab2038fb24591ccd6d418d705866191f288db79710c6da977d9eab63e107ec482b8f9c047c1f6b1635d6623dc275398201a0e178592ee283d8a4c18f55aa371b4593564f190f2cb30d32d966224135d41dabfe0e17ee9dc99287431ce1828dbeee990f1ded78bf9a3a9c1855596c220b8ee27e0b993b4113ab5b5a61196cb2e9f4415c0d4600507f84950ab4768125c04edff4ea45832f2ed0f995347e212aafca04c189c117aa7b0526097a07c57714519abbb5adeab4b07e3fac776215d41433663593012ca0635dc00382a328ff58282da55adade619f56b37f96ffa58&X-Goog-SignedHeaders=host&X-User=2931823730: HTTPSConnectionPool(host='storage.googleapis.com', port=443): Max retries exceeded with url: /wandb-production.appspot.com/2931823730-harbin-institute-of-technology/ltu-as/31odaggz/config.yaml?X-Goog-Algorithm=GOOG4-RSA-SHA256&X-Goog-Credential=gorilla-files-url-signer-man%40wandb-production.iam.gserviceaccount.com%2F20250414%2Fauto%2Fstorage%2Fgoog4_request&X-Goog-Date=20250414T141758Z&X-Goog-Expires=86399&X-Goog-Signature=194cc2540813956d5c8881739ee12da627ab3bbc9613646e1fa19950a9fbcc97f73ab2038fb24591ccd6d418d705866191f288db79710c6da977d9eab63e107ec482b8f9c047c1f6b1635d6623dc275398201a0e178592ee283d8a4c18f55aa371b4593564f190f2cb30d32d966224135d41dabfe0e17ee9dc99287431ce1828dbeee990f1ded78bf9a3a9c1855596c220b8ee27e0b993b4113ab5b5a61196cb2e9f4415c0d4600507f84950ab4768125c04edff4ea45832f2ed0f995347e212aafca04c189c117aa7b0526097a07c57714519abbb5adeab4b07e3fac776215d41433663593012ca0635dc00382a328ff58282da55adade619f56b37f96ffa58&X-Goog-SignedHeaders=host&X-User=2931823730 (Caused by NewConnectionError('<urllib3.connection.HTTPSConnection object at 0x7f29140955d0>: Failed to establish a new connection: [Errno 101] Network is unreachable'))
2025-04-14 14:18:35,555 ERROR   wandb-upload_0:8632 [internal_api.py:upload_file():2558] upload_file request headers: {'User-Agent': 'python-requests/2.32.3', 'Accept-Encoding': 'gzip, deflate, br', 'Accept': '*/*', 'Connection': 'keep-alive', 'Content-Length': '495'}
2025-04-14 14:18:35,555 ERROR   wandb-upload_0:8632 [internal_api.py:upload_file():2560] upload_file response body: 
2025-04-14 14:19:12,065 ERROR   wandb-upload_1:8632 [internal_api.py:upload_file():2556] upload_file exception https://storage.googleapis.com/wandb-production.appspot.com/2931823730-harbin-institute-of-technology/ltu-as/31odaggz/requirements.txt?X-Goog-Algorithm=GOOG4-RSA-SHA256&X-Goog-Credential=gorilla-files-url-signer-man%40wandb-production.iam.gserviceaccount.com%2F20250414%2Fauto%2Fstorage%2Fgoog4_request&X-Goog-Date=20250414T141759Z&X-Goog-Expires=86399&X-Goog-Signature=5f6153b93ed9fa74deff765545f8c201587fbeb911e62cb3cc4910c63f6fdca03854136261a6bbd672c2d42fbda91a03dfd5489d78595df6bae13a047cfbfbe769a2900d5de43d8c4c2fdb4ff2f62fed69a11d701473162b74edb7cc02410ec05c5598e39df6e9bb66ffd2078fdedad8c5b49972c266a23e216383e15a77f2341156622943959493793689e200b67ed6794be9327090cb298b0aa05d0542348be451ab5ef0eb5d562c63ca86f4825fd09ef41a9735f1b4b10fb4694a9ecfd425ec23727d25a7349defdfe02d9e6ea4e9df4daa5f95cf118267e0c0cc2fcb5a59dc9052a1dbda63c7a3b8ef1aefb68ed47651b521b6d4d3d836c1e68bffd402e8&X-Goog-SignedHeaders=host&X-User=2931823730: HTTPSConnectionPool(host='storage.googleapis.com', port=443): Max retries exceeded with url: /wandb-production.appspot.com/2931823730-harbin-institute-of-technology/ltu-as/31odaggz/requirements.txt?X-Goog-Algorithm=GOOG4-RSA-SHA256&X-Goog-Credential=gorilla-files-url-signer-man%40wandb-production.iam.gserviceaccount.com%2F20250414%2Fauto%2Fstorage%2Fgoog4_request&X-Goog-Date=20250414T141759Z&X-Goog-Expires=86399&X-Goog-Signature=5f6153b93ed9fa74deff765545f8c201587fbeb911e62cb3cc4910c63f6fdca03854136261a6bbd672c2d42fbda91a03dfd5489d78595df6bae13a047cfbfbe769a2900d5de43d8c4c2fdb4ff2f62fed69a11d701473162b74edb7cc02410ec05c5598e39df6e9bb66ffd2078fdedad8c5b49972c266a23e216383e15a77f2341156622943959493793689e200b67ed6794be9327090cb298b0aa05d0542348be451ab5ef0eb5d562c63ca86f4825fd09ef41a9735f1b4b10fb4694a9ecfd425ec23727d25a7349defdfe02d9e6ea4e9df4daa5f95cf118267e0c0cc2fcb5a59dc9052a1dbda63c7a3b8ef1aefb68ed47651b521b6d4d3d836c1e68bffd402e8&X-Goog-SignedHeaders=host&X-User=2931823730 (Caused by NewConnectionError('<urllib3.connection.HTTPSConnection object at 0x7f29140956f0>: Failed to establish a new connection: [Errno 101] Network is unreachable'))
2025-04-14 14:19:12,065 ERROR   wandb-upload_1:8632 [internal_api.py:upload_file():2558] upload_file request headers: {'User-Agent': 'python-requests/2.32.3', 'Accept-Encoding': 'gzip, deflate, br', 'Accept': '*/*', 'Connection': 'keep-alive', 'Content-Length': '5836'}
2025-04-14 14:19:12,065 ERROR   wandb-upload_1:8632 [internal_api.py:upload_file():2560] upload_file response body: 
2025-04-14 14:19:13,035 ERROR   wandb-upload_0:8632 [internal_api.py:upload_file():2556] upload_file exception https://storage.googleapis.com/wandb-production.appspot.com/2931823730-harbin-institute-of-technology/ltu-as/31odaggz/config.yaml?X-Goog-Algorithm=GOOG4-RSA-SHA256&X-Goog-Credential=gorilla-files-url-signer-man%40wandb-production.iam.gserviceaccount.com%2F20250414%2Fauto%2Fstorage%2Fgoog4_request&X-Goog-Date=20250414T141758Z&X-Goog-Expires=86399&X-Goog-Signature=194cc2540813956d5c8881739ee12da627ab3bbc9613646e1fa19950a9fbcc97f73ab2038fb24591ccd6d418d705866191f288db79710c6da977d9eab63e107ec482b8f9c047c1f6b1635d6623dc275398201a0e178592ee283d8a4c18f55aa371b4593564f190f2cb30d32d966224135d41dabfe0e17ee9dc99287431ce1828dbeee990f1ded78bf9a3a9c1855596c220b8ee27e0b993b4113ab5b5a61196cb2e9f4415c0d4600507f84950ab4768125c04edff4ea45832f2ed0f995347e212aafca04c189c117aa7b0526097a07c57714519abbb5adeab4b07e3fac776215d41433663593012ca0635dc00382a328ff58282da55adade619f56b37f96ffa58&X-Goog-SignedHeaders=host&X-User=2931823730: HTTPSConnectionPool(host='storage.googleapis.com', port=443): Max retries exceeded with url: /wandb-production.appspot.com/2931823730-harbin-institute-of-technology/ltu-as/31odaggz/config.yaml?X-Goog-Algorithm=GOOG4-RSA-SHA256&X-Goog-Credential=gorilla-files-url-signer-man%40wandb-production.iam.gserviceaccount.com%2F20250414%2Fauto%2Fstorage%2Fgoog4_request&X-Goog-Date=20250414T141758Z&X-Goog-Expires=86399&X-Goog-Signature=194cc2540813956d5c8881739ee12da627ab3bbc9613646e1fa19950a9fbcc97f73ab2038fb24591ccd6d418d705866191f288db79710c6da977d9eab63e107ec482b8f9c047c1f6b1635d6623dc275398201a0e178592ee283d8a4c18f55aa371b4593564f190f2cb30d32d966224135d41dabfe0e17ee9dc99287431ce1828dbeee990f1ded78bf9a3a9c1855596c220b8ee27e0b993b4113ab5b5a61196cb2e9f4415c0d4600507f84950ab4768125c04edff4ea45832f2ed0f995347e212aafca04c189c117aa7b0526097a07c57714519abbb5adeab4b07e3fac776215d41433663593012ca0635dc00382a328ff58282da55adade619f56b37f96ffa58&X-Goog-SignedHeaders=host&X-User=2931823730 (Caused by NewConnectionError('<urllib3.connection.HTTPSConnection object at 0x7f2914095000>: Failed to establish a new connection: [Errno 101] Network is unreachable'))
2025-04-14 14:19:13,036 ERROR   wandb-upload_0:8632 [internal_api.py:upload_file():2558] upload_file request headers: {'User-Agent': 'python-requests/2.32.3', 'Accept-Encoding': 'gzip, deflate, br', 'Accept': '*/*', 'Connection': 'keep-alive', 'Content-Length': '495'}
2025-04-14 14:19:13,036 ERROR   wandb-upload_0:8632 [internal_api.py:upload_file():2560] upload_file response body: 
2025-04-14 14:20:19,689 ERROR   wandb-upload_1:8632 [internal_api.py:upload_file():2556] upload_file exception https://storage.googleapis.com/wandb-production.appspot.com/2931823730-harbin-institute-of-technology/ltu-as/31odaggz/requirements.txt?X-Goog-Algorithm=GOOG4-RSA-SHA256&X-Goog-Credential=gorilla-files-url-signer-man%40wandb-production.iam.gserviceaccount.com%2F20250414%2Fauto%2Fstorage%2Fgoog4_request&X-Goog-Date=20250414T141759Z&X-Goog-Expires=86399&X-Goog-Signature=5f6153b93ed9fa74deff765545f8c201587fbeb911e62cb3cc4910c63f6fdca03854136261a6bbd672c2d42fbda91a03dfd5489d78595df6bae13a047cfbfbe769a2900d5de43d8c4c2fdb4ff2f62fed69a11d701473162b74edb7cc02410ec05c5598e39df6e9bb66ffd2078fdedad8c5b49972c266a23e216383e15a77f2341156622943959493793689e200b67ed6794be9327090cb298b0aa05d0542348be451ab5ef0eb5d562c63ca86f4825fd09ef41a9735f1b4b10fb4694a9ecfd425ec23727d25a7349defdfe02d9e6ea4e9df4daa5f95cf118267e0c0cc2fcb5a59dc9052a1dbda63c7a3b8ef1aefb68ed47651b521b6d4d3d836c1e68bffd402e8&X-Goog-SignedHeaders=host&X-User=2931823730: HTTPSConnectionPool(host='storage.googleapis.com', port=443): Max retries exceeded with url: /wandb-production.appspot.com/2931823730-harbin-institute-of-technology/ltu-as/31odaggz/requirements.txt?X-Goog-Algorithm=GOOG4-RSA-SHA256&X-Goog-Credential=gorilla-files-url-signer-man%40wandb-production.iam.gserviceaccount.com%2F20250414%2Fauto%2Fstorage%2Fgoog4_request&X-Goog-Date=20250414T141759Z&X-Goog-Expires=86399&X-Goog-Signature=5f6153b93ed9fa74deff765545f8c201587fbeb911e62cb3cc4910c63f6fdca03854136261a6bbd672c2d42fbda91a03dfd5489d78595df6bae13a047cfbfbe769a2900d5de43d8c4c2fdb4ff2f62fed69a11d701473162b74edb7cc02410ec05c5598e39df6e9bb66ffd2078fdedad8c5b49972c266a23e216383e15a77f2341156622943959493793689e200b67ed6794be9327090cb298b0aa05d0542348be451ab5ef0eb5d562c63ca86f4825fd09ef41a9735f1b4b10fb4694a9ecfd425ec23727d25a7349defdfe02d9e6ea4e9df4daa5f95cf118267e0c0cc2fcb5a59dc9052a1dbda63c7a3b8ef1aefb68ed47651b521b6d4d3d836c1e68bffd402e8&X-Goog-SignedHeaders=host&X-User=2931823730 (Caused by NewConnectionError('<urllib3.connection.HTTPSConnection object at 0x7f2914096920>: Failed to establish a new connection: [Errno 101] Network is unreachable'))
2025-04-14 14:20:19,746 ERROR   wandb-upload_1:8632 [internal_api.py:upload_file():2558] upload_file request headers: {'User-Agent': 'python-requests/2.32.3', 'Accept-Encoding': 'gzip, deflate, br', 'Accept': '*/*', 'Connection': 'keep-alive', 'Content-Length': '5836'}
2025-04-14 14:20:19,746 ERROR   wandb-upload_1:8632 [internal_api.py:upload_file():2560] upload_file response body: 
2025-04-14 14:20:26,663 ERROR   wandb-upload_0:8632 [internal_api.py:upload_file():2556] upload_file exception https://storage.googleapis.com/wandb-production.appspot.com/2931823730-harbin-institute-of-technology/ltu-as/31odaggz/config.yaml?X-Goog-Algorithm=GOOG4-RSA-SHA256&X-Goog-Credential=gorilla-files-url-signer-man%40wandb-production.iam.gserviceaccount.com%2F20250414%2Fauto%2Fstorage%2Fgoog4_request&X-Goog-Date=20250414T141758Z&X-Goog-Expires=86399&X-Goog-Signature=194cc2540813956d5c8881739ee12da627ab3bbc9613646e1fa19950a9fbcc97f73ab2038fb24591ccd6d418d705866191f288db79710c6da977d9eab63e107ec482b8f9c047c1f6b1635d6623dc275398201a0e178592ee283d8a4c18f55aa371b4593564f190f2cb30d32d966224135d41dabfe0e17ee9dc99287431ce1828dbeee990f1ded78bf9a3a9c1855596c220b8ee27e0b993b4113ab5b5a61196cb2e9f4415c0d4600507f84950ab4768125c04edff4ea45832f2ed0f995347e212aafca04c189c117aa7b0526097a07c57714519abbb5adeab4b07e3fac776215d41433663593012ca0635dc00382a328ff58282da55adade619f56b37f96ffa58&X-Goog-SignedHeaders=host&X-User=2931823730: HTTPSConnectionPool(host='storage.googleapis.com', port=443): Max retries exceeded with url: /wandb-production.appspot.com/2931823730-harbin-institute-of-technology/ltu-as/31odaggz/config.yaml?X-Goog-Algorithm=GOOG4-RSA-SHA256&X-Goog-Credential=gorilla-files-url-signer-man%40wandb-production.iam.gserviceaccount.com%2F20250414%2Fauto%2Fstorage%2Fgoog4_request&X-Goog-Date=20250414T141758Z&X-Goog-Expires=86399&X-Goog-Signature=194cc2540813956d5c8881739ee12da627ab3bbc9613646e1fa19950a9fbcc97f73ab2038fb24591ccd6d418d705866191f288db79710c6da977d9eab63e107ec482b8f9c047c1f6b1635d6623dc275398201a0e178592ee283d8a4c18f55aa371b4593564f190f2cb30d32d966224135d41dabfe0e17ee9dc99287431ce1828dbeee990f1ded78bf9a3a9c1855596c220b8ee27e0b993b4113ab5b5a61196cb2e9f4415c0d4600507f84950ab4768125c04edff4ea45832f2ed0f995347e212aafca04c189c117aa7b0526097a07c57714519abbb5adeab4b07e3fac776215d41433663593012ca0635dc00382a328ff58282da55adade619f56b37f96ffa58&X-Goog-SignedHeaders=host&X-User=2931823730 (Caused by NewConnectionError('<urllib3.connection.HTTPSConnection object at 0x7f2914096c50>: Failed to establish a new connection: [Errno 101] Network is unreachable'))
2025-04-14 14:20:26,663 ERROR   wandb-upload_0:8632 [internal_api.py:upload_file():2558] upload_file request headers: {'User-Agent': 'python-requests/2.32.3', 'Accept-Encoding': 'gzip, deflate, br', 'Accept': '*/*', 'Connection': 'keep-alive', 'Content-Length': '495'}
2025-04-14 14:20:26,663 ERROR   wandb-upload_0:8632 [internal_api.py:upload_file():2560] upload_file response body: 
2025-04-14 14:22:46,663 ERROR   wandb-upload_1:8632 [internal_api.py:upload_file():2556] upload_file exception https://storage.googleapis.com/wandb-production.appspot.com/2931823730-harbin-institute-of-technology/ltu-as/31odaggz/requirements.txt?X-Goog-Algorithm=GOOG4-RSA-SHA256&X-Goog-Credential=gorilla-files-url-signer-man%40wandb-production.iam.gserviceaccount.com%2F20250414%2Fauto%2Fstorage%2Fgoog4_request&X-Goog-Date=20250414T141759Z&X-Goog-Expires=86399&X-Goog-Signature=5f6153b93ed9fa74deff765545f8c201587fbeb911e62cb3cc4910c63f6fdca03854136261a6bbd672c2d42fbda91a03dfd5489d78595df6bae13a047cfbfbe769a2900d5de43d8c4c2fdb4ff2f62fed69a11d701473162b74edb7cc02410ec05c5598e39df6e9bb66ffd2078fdedad8c5b49972c266a23e216383e15a77f2341156622943959493793689e200b67ed6794be9327090cb298b0aa05d0542348be451ab5ef0eb5d562c63ca86f4825fd09ef41a9735f1b4b10fb4694a9ecfd425ec23727d25a7349defdfe02d9e6ea4e9df4daa5f95cf118267e0c0cc2fcb5a59dc9052a1dbda63c7a3b8ef1aefb68ed47651b521b6d4d3d836c1e68bffd402e8&X-Goog-SignedHeaders=host&X-User=2931823730: HTTPSConnectionPool(host='storage.googleapis.com', port=443): Max retries exceeded with url: /wandb-production.appspot.com/2931823730-harbin-institute-of-technology/ltu-as/31odaggz/requirements.txt?X-Goog-Algorithm=GOOG4-RSA-SHA256&X-Goog-Credential=gorilla-files-url-signer-man%40wandb-production.iam.gserviceaccount.com%2F20250414%2Fauto%2Fstorage%2Fgoog4_request&X-Goog-Date=20250414T141759Z&X-Goog-Expires=86399&X-Goog-Signature=5f6153b93ed9fa74deff765545f8c201587fbeb911e62cb3cc4910c63f6fdca03854136261a6bbd672c2d42fbda91a03dfd5489d78595df6bae13a047cfbfbe769a2900d5de43d8c4c2fdb4ff2f62fed69a11d701473162b74edb7cc02410ec05c5598e39df6e9bb66ffd2078fdedad8c5b49972c266a23e216383e15a77f2341156622943959493793689e200b67ed6794be9327090cb298b0aa05d0542348be451ab5ef0eb5d562c63ca86f4825fd09ef41a9735f1b4b10fb4694a9ecfd425ec23727d25a7349defdfe02d9e6ea4e9df4daa5f95cf118267e0c0cc2fcb5a59dc9052a1dbda63c7a3b8ef1aefb68ed47651b521b6d4d3d836c1e68bffd402e8&X-Goog-SignedHeaders=host&X-User=2931823730 (Caused by NewConnectionError('<urllib3.connection.HTTPSConnection object at 0x7f29140975b0>: Failed to establish a new connection: [Errno 101] Network is unreachable'))
2025-04-14 14:22:46,663 ERROR   wandb-upload_1:8632 [internal_api.py:upload_file():2558] upload_file request headers: {'User-Agent': 'python-requests/2.32.3', 'Accept-Encoding': 'gzip, deflate, br', 'Accept': '*/*', 'Connection': 'keep-alive', 'Content-Length': '5836'}
2025-04-14 14:22:46,663 ERROR   wandb-upload_1:8632 [internal_api.py:upload_file():2560] upload_file response body: 
2025-04-14 14:22:51,673 ERROR   wandb-upload_0:8632 [internal_api.py:upload_file():2556] upload_file exception https://storage.googleapis.com/wandb-production.appspot.com/2931823730-harbin-institute-of-technology/ltu-as/31odaggz/config.yaml?X-Goog-Algorithm=GOOG4-RSA-SHA256&X-Goog-Credential=gorilla-files-url-signer-man%40wandb-production.iam.gserviceaccount.com%2F20250414%2Fauto%2Fstorage%2Fgoog4_request&X-Goog-Date=20250414T141758Z&X-Goog-Expires=86399&X-Goog-Signature=194cc2540813956d5c8881739ee12da627ab3bbc9613646e1fa19950a9fbcc97f73ab2038fb24591ccd6d418d705866191f288db79710c6da977d9eab63e107ec482b8f9c047c1f6b1635d6623dc275398201a0e178592ee283d8a4c18f55aa371b4593564f190f2cb30d32d966224135d41dabfe0e17ee9dc99287431ce1828dbeee990f1ded78bf9a3a9c1855596c220b8ee27e0b993b4113ab5b5a61196cb2e9f4415c0d4600507f84950ab4768125c04edff4ea45832f2ed0f995347e212aafca04c189c117aa7b0526097a07c57714519abbb5adeab4b07e3fac776215d41433663593012ca0635dc00382a328ff58282da55adade619f56b37f96ffa58&X-Goog-SignedHeaders=host&X-User=2931823730: HTTPSConnectionPool(host='storage.googleapis.com', port=443): Max retries exceeded with url: /wandb-production.appspot.com/2931823730-harbin-institute-of-technology/ltu-as/31odaggz/config.yaml?X-Goog-Algorithm=GOOG4-RSA-SHA256&X-Goog-Credential=gorilla-files-url-signer-man%40wandb-production.iam.gserviceaccount.com%2F20250414%2Fauto%2Fstorage%2Fgoog4_request&X-Goog-Date=20250414T141758Z&X-Goog-Expires=86399&X-Goog-Signature=194cc2540813956d5c8881739ee12da627ab3bbc9613646e1fa19950a9fbcc97f73ab2038fb24591ccd6d418d705866191f288db79710c6da977d9eab63e107ec482b8f9c047c1f6b1635d6623dc275398201a0e178592ee283d8a4c18f55aa371b4593564f190f2cb30d32d966224135d41dabfe0e17ee9dc99287431ce1828dbeee990f1ded78bf9a3a9c1855596c220b8ee27e0b993b4113ab5b5a61196cb2e9f4415c0d4600507f84950ab4768125c04edff4ea45832f2ed0f995347e212aafca04c189c117aa7b0526097a07c57714519abbb5adeab4b07e3fac776215d41433663593012ca0635dc00382a328ff58282da55adade619f56b37f96ffa58&X-Goog-SignedHeaders=host&X-User=2931823730 (Caused by NewConnectionError('<urllib3.connection.HTTPSConnection object at 0x7f29140ed4e0>: Failed to establish a new connection: [Errno 101] Network is unreachable'))
2025-04-14 14:22:51,673 ERROR   wandb-upload_0:8632 [internal_api.py:upload_file():2558] upload_file request headers: {'User-Agent': 'python-requests/2.32.3', 'Accept-Encoding': 'gzip, deflate, br', 'Accept': '*/*', 'Connection': 'keep-alive', 'Content-Length': '495'}
2025-04-14 14:22:51,673 ERROR   wandb-upload_0:8632 [internal_api.py:upload_file():2560] upload_file response body: 
2025-04-14 14:27:10,988 ERROR   wandb-upload_0:8632 [internal_api.py:upload_file():2556] upload_file exception https://storage.googleapis.com/wandb-production.appspot.com/2931823730-harbin-institute-of-technology/ltu-as/31odaggz/config.yaml?X-Goog-Algorithm=GOOG4-RSA-SHA256&X-Goog-Credential=gorilla-files-url-signer-man%40wandb-production.iam.gserviceaccount.com%2F20250414%2Fauto%2Fstorage%2Fgoog4_request&X-Goog-Date=20250414T141758Z&X-Goog-Expires=86399&X-Goog-Signature=194cc2540813956d5c8881739ee12da627ab3bbc9613646e1fa19950a9fbcc97f73ab2038fb24591ccd6d418d705866191f288db79710c6da977d9eab63e107ec482b8f9c047c1f6b1635d6623dc275398201a0e178592ee283d8a4c18f55aa371b4593564f190f2cb30d32d966224135d41dabfe0e17ee9dc99287431ce1828dbeee990f1ded78bf9a3a9c1855596c220b8ee27e0b993b4113ab5b5a61196cb2e9f4415c0d4600507f84950ab4768125c04edff4ea45832f2ed0f995347e212aafca04c189c117aa7b0526097a07c57714519abbb5adeab4b07e3fac776215d41433663593012ca0635dc00382a328ff58282da55adade619f56b37f96ffa58&X-Goog-SignedHeaders=host&X-User=2931823730: HTTPSConnectionPool(host='storage.googleapis.com', port=443): Max retries exceeded with url: /wandb-production.appspot.com/2931823730-harbin-institute-of-technology/ltu-as/31odaggz/config.yaml?X-Goog-Algorithm=GOOG4-RSA-SHA256&X-Goog-Credential=gorilla-files-url-signer-man%40wandb-production.iam.gserviceaccount.com%2F20250414%2Fauto%2Fstorage%2Fgoog4_request&X-Goog-Date=20250414T141758Z&X-Goog-Expires=86399&X-Goog-Signature=194cc2540813956d5c8881739ee12da627ab3bbc9613646e1fa19950a9fbcc97f73ab2038fb24591ccd6d418d705866191f288db79710c6da977d9eab63e107ec482b8f9c047c1f6b1635d6623dc275398201a0e178592ee283d8a4c18f55aa371b4593564f190f2cb30d32d966224135d41dabfe0e17ee9dc99287431ce1828dbeee990f1ded78bf9a3a9c1855596c220b8ee27e0b993b4113ab5b5a61196cb2e9f4415c0d4600507f84950ab4768125c04edff4ea45832f2ed0f995347e212aafca04c189c117aa7b0526097a07c57714519abbb5adeab4b07e3fac776215d41433663593012ca0635dc00382a328ff58282da55adade619f56b37f96ffa58&X-Goog-SignedHeaders=host&X-User=2931823730 (Caused by NewConnectionError('<urllib3.connection.HTTPSConnection object at 0x7f29140ee9b0>: Failed to establish a new connection: [Errno 101] Network is unreachable'))
2025-04-14 14:27:10,988 ERROR   wandb-upload_0:8632 [internal_api.py:upload_file():2558] upload_file request headers: {'User-Agent': 'python-requests/2.32.3', 'Accept-Encoding': 'gzip, deflate, br', 'Accept': '*/*', 'Connection': 'keep-alive', 'Content-Length': '495'}
2025-04-14 14:27:10,988 ERROR   wandb-upload_0:8632 [internal_api.py:upload_file():2560] upload_file response body: 
2025-04-14 14:27:42,663 ERROR   wandb-upload_1:8632 [internal_api.py:upload_file():2556] upload_file exception https://storage.googleapis.com/wandb-production.appspot.com/2931823730-harbin-institute-of-technology/ltu-as/31odaggz/requirements.txt?X-Goog-Algorithm=GOOG4-RSA-SHA256&X-Goog-Credential=gorilla-files-url-signer-man%40wandb-production.iam.gserviceaccount.com%2F20250414%2Fauto%2Fstorage%2Fgoog4_request&X-Goog-Date=20250414T141759Z&X-Goog-Expires=86399&X-Goog-Signature=5f6153b93ed9fa74deff765545f8c201587fbeb911e62cb3cc4910c63f6fdca03854136261a6bbd672c2d42fbda91a03dfd5489d78595df6bae13a047cfbfbe769a2900d5de43d8c4c2fdb4ff2f62fed69a11d701473162b74edb7cc02410ec05c5598e39df6e9bb66ffd2078fdedad8c5b49972c266a23e216383e15a77f2341156622943959493793689e200b67ed6794be9327090cb298b0aa05d0542348be451ab5ef0eb5d562c63ca86f4825fd09ef41a9735f1b4b10fb4694a9ecfd425ec23727d25a7349defdfe02d9e6ea4e9df4daa5f95cf118267e0c0cc2fcb5a59dc9052a1dbda63c7a3b8ef1aefb68ed47651b521b6d4d3d836c1e68bffd402e8&X-Goog-SignedHeaders=host&X-User=2931823730: HTTPSConnectionPool(host='storage.googleapis.com', port=443): Max retries exceeded with url: /wandb-production.appspot.com/2931823730-harbin-institute-of-technology/ltu-as/31odaggz/requirements.txt?X-Goog-Algorithm=GOOG4-RSA-SHA256&X-Goog-Credential=gorilla-files-url-signer-man%40wandb-production.iam.gserviceaccount.com%2F20250414%2Fauto%2Fstorage%2Fgoog4_request&X-Goog-Date=20250414T141759Z&X-Goog-Expires=86399&X-Goog-Signature=5f6153b93ed9fa74deff765545f8c201587fbeb911e62cb3cc4910c63f6fdca03854136261a6bbd672c2d42fbda91a03dfd5489d78595df6bae13a047cfbfbe769a2900d5de43d8c4c2fdb4ff2f62fed69a11d701473162b74edb7cc02410ec05c5598e39df6e9bb66ffd2078fdedad8c5b49972c266a23e216383e15a77f2341156622943959493793689e200b67ed6794be9327090cb298b0aa05d0542348be451ab5ef0eb5d562c63ca86f4825fd09ef41a9735f1b4b10fb4694a9ecfd425ec23727d25a7349defdfe02d9e6ea4e9df4daa5f95cf118267e0c0cc2fcb5a59dc9052a1dbda63c7a3b8ef1aefb68ed47651b521b6d4d3d836c1e68bffd402e8&X-Goog-SignedHeaders=host&X-User=2931823730 (Caused by NewConnectionError('<urllib3.connection.HTTPSConnection object at 0x7f29140ef040>: Failed to establish a new connection: [Errno 101] Network is unreachable'))
2025-04-14 14:27:42,664 ERROR   wandb-upload_1:8632 [internal_api.py:upload_file():2558] upload_file request headers: {'User-Agent': 'python-requests/2.32.3', 'Accept-Encoding': 'gzip, deflate, br', 'Accept': '*/*', 'Connection': 'keep-alive', 'Content-Length': '5836'}
2025-04-14 14:27:42,664 ERROR   wandb-upload_1:8632 [internal_api.py:upload_file():2560] upload_file response body: 
2025-04-14 14:32:44,863 ERROR   wandb-upload_1:8632 [internal_api.py:upload_file():2556] upload_file exception https://storage.googleapis.com/wandb-production.appspot.com/2931823730-harbin-institute-of-technology/ltu-as/31odaggz/requirements.txt?X-Goog-Algorithm=GOOG4-RSA-SHA256&X-Goog-Credential=gorilla-files-url-signer-man%40wandb-production.iam.gserviceaccount.com%2F20250414%2Fauto%2Fstorage%2Fgoog4_request&X-Goog-Date=20250414T141759Z&X-Goog-Expires=86399&X-Goog-Signature=5f6153b93ed9fa74deff765545f8c201587fbeb911e62cb3cc4910c63f6fdca03854136261a6bbd672c2d42fbda91a03dfd5489d78595df6bae13a047cfbfbe769a2900d5de43d8c4c2fdb4ff2f62fed69a11d701473162b74edb7cc02410ec05c5598e39df6e9bb66ffd2078fdedad8c5b49972c266a23e216383e15a77f2341156622943959493793689e200b67ed6794be9327090cb298b0aa05d0542348be451ab5ef0eb5d562c63ca86f4825fd09ef41a9735f1b4b10fb4694a9ecfd425ec23727d25a7349defdfe02d9e6ea4e9df4daa5f95cf118267e0c0cc2fcb5a59dc9052a1dbda63c7a3b8ef1aefb68ed47651b521b6d4d3d836c1e68bffd402e8&X-Goog-SignedHeaders=host&X-User=2931823730: HTTPSConnectionPool(host='storage.googleapis.com', port=443): Max retries exceeded with url: /wandb-production.appspot.com/2931823730-harbin-institute-of-technology/ltu-as/31odaggz/requirements.txt?X-Goog-Algorithm=GOOG4-RSA-SHA256&X-Goog-Credential=gorilla-files-url-signer-man%40wandb-production.iam.gserviceaccount.com%2F20250414%2Fauto%2Fstorage%2Fgoog4_request&X-Goog-Date=20250414T141759Z&X-Goog-Expires=86399&X-Goog-Signature=5f6153b93ed9fa74deff765545f8c201587fbeb911e62cb3cc4910c63f6fdca03854136261a6bbd672c2d42fbda91a03dfd5489d78595df6bae13a047cfbfbe769a2900d5de43d8c4c2fdb4ff2f62fed69a11d701473162b74edb7cc02410ec05c5598e39df6e9bb66ffd2078fdedad8c5b49972c266a23e216383e15a77f2341156622943959493793689e200b67ed6794be9327090cb298b0aa05d0542348be451ab5ef0eb5d562c63ca86f4825fd09ef41a9735f1b4b10fb4694a9ecfd425ec23727d25a7349defdfe02d9e6ea4e9df4daa5f95cf118267e0c0cc2fcb5a59dc9052a1dbda63c7a3b8ef1aefb68ed47651b521b6d4d3d836c1e68bffd402e8&X-Goog-SignedHeaders=host&X-User=2931823730 (Caused by NewConnectionError('<urllib3.connection.HTTPSConnection object at 0x7f29140974c0>: Failed to establish a new connection: [Errno 101] Network is unreachable'))
2025-04-14 14:32:44,863 ERROR   wandb-upload_1:8632 [internal_api.py:upload_file():2558] upload_file request headers: {'User-Agent': 'python-requests/2.32.3', 'Accept-Encoding': 'gzip, deflate, br', 'Accept': '*/*', 'Connection': 'keep-alive', 'Content-Length': '5836'}
2025-04-14 14:32:44,863 ERROR   wandb-upload_1:8632 [internal_api.py:upload_file():2560] upload_file response body: 
2025-04-14 14:33:22,231 ERROR   wandb-upload_0:8632 [internal_api.py:upload_file():2556] upload_file exception https://storage.googleapis.com/wandb-production.appspot.com/2931823730-harbin-institute-of-technology/ltu-as/31odaggz/config.yaml?X-Goog-Algorithm=GOOG4-RSA-SHA256&X-Goog-Credential=gorilla-files-url-signer-man%40wandb-production.iam.gserviceaccount.com%2F20250414%2Fauto%2Fstorage%2Fgoog4_request&X-Goog-Date=20250414T141758Z&X-Goog-Expires=86399&X-Goog-Signature=194cc2540813956d5c8881739ee12da627ab3bbc9613646e1fa19950a9fbcc97f73ab2038fb24591ccd6d418d705866191f288db79710c6da977d9eab63e107ec482b8f9c047c1f6b1635d6623dc275398201a0e178592ee283d8a4c18f55aa371b4593564f190f2cb30d32d966224135d41dabfe0e17ee9dc99287431ce1828dbeee990f1ded78bf9a3a9c1855596c220b8ee27e0b993b4113ab5b5a61196cb2e9f4415c0d4600507f84950ab4768125c04edff4ea45832f2ed0f995347e212aafca04c189c117aa7b0526097a07c57714519abbb5adeab4b07e3fac776215d41433663593012ca0635dc00382a328ff58282da55adade619f56b37f96ffa58&X-Goog-SignedHeaders=host&X-User=2931823730: HTTPSConnectionPool(host='storage.googleapis.com', port=443): Max retries exceeded with url: /wandb-production.appspot.com/2931823730-harbin-institute-of-technology/ltu-as/31odaggz/config.yaml?X-Goog-Algorithm=GOOG4-RSA-SHA256&X-Goog-Credential=gorilla-files-url-signer-man%40wandb-production.iam.gserviceaccount.com%2F20250414%2Fauto%2Fstorage%2Fgoog4_request&X-Goog-Date=20250414T141758Z&X-Goog-Expires=86399&X-Goog-Signature=194cc2540813956d5c8881739ee12da627ab3bbc9613646e1fa19950a9fbcc97f73ab2038fb24591ccd6d418d705866191f288db79710c6da977d9eab63e107ec482b8f9c047c1f6b1635d6623dc275398201a0e178592ee283d8a4c18f55aa371b4593564f190f2cb30d32d966224135d41dabfe0e17ee9dc99287431ce1828dbeee990f1ded78bf9a3a9c1855596c220b8ee27e0b993b4113ab5b5a61196cb2e9f4415c0d4600507f84950ab4768125c04edff4ea45832f2ed0f995347e212aafca04c189c117aa7b0526097a07c57714519abbb5adeab4b07e3fac776215d41433663593012ca0635dc00382a328ff58282da55adade619f56b37f96ffa58&X-Goog-SignedHeaders=host&X-User=2931823730 (Caused by NewConnectionError('<urllib3.connection.HTTPSConnection object at 0x7f29140952d0>: Failed to establish a new connection: [Errno 101] Network is unreachable'))
2025-04-14 14:33:22,231 ERROR   wandb-upload_0:8632 [internal_api.py:upload_file():2558] upload_file request headers: {'User-Agent': 'python-requests/2.32.3', 'Accept-Encoding': 'gzip, deflate, br', 'Accept': '*/*', 'Connection': 'keep-alive', 'Content-Length': '495'}
2025-04-14 14:33:22,231 ERROR   wandb-upload_0:8632 [internal_api.py:upload_file():2560] upload_file response body: 
2025-04-14 14:37:59,135 ERROR   wandb-upload_1:8632 [internal_api.py:upload_file():2556] upload_file exception https://storage.googleapis.com/wandb-production.appspot.com/2931823730-harbin-institute-of-technology/ltu-as/31odaggz/requirements.txt?X-Goog-Algorithm=GOOG4-RSA-SHA256&X-Goog-Credential=gorilla-files-url-signer-man%40wandb-production.iam.gserviceaccount.com%2F20250414%2Fauto%2Fstorage%2Fgoog4_request&X-Goog-Date=20250414T141759Z&X-Goog-Expires=86399&X-Goog-Signature=5f6153b93ed9fa74deff765545f8c201587fbeb911e62cb3cc4910c63f6fdca03854136261a6bbd672c2d42fbda91a03dfd5489d78595df6bae13a047cfbfbe769a2900d5de43d8c4c2fdb4ff2f62fed69a11d701473162b74edb7cc02410ec05c5598e39df6e9bb66ffd2078fdedad8c5b49972c266a23e216383e15a77f2341156622943959493793689e200b67ed6794be9327090cb298b0aa05d0542348be451ab5ef0eb5d562c63ca86f4825fd09ef41a9735f1b4b10fb4694a9ecfd425ec23727d25a7349defdfe02d9e6ea4e9df4daa5f95cf118267e0c0cc2fcb5a59dc9052a1dbda63c7a3b8ef1aefb68ed47651b521b6d4d3d836c1e68bffd402e8&X-Goog-SignedHeaders=host&X-User=2931823730: HTTPSConnectionPool(host='storage.googleapis.com', port=443): Max retries exceeded with url: /wandb-production.appspot.com/2931823730-harbin-institute-of-technology/ltu-as/31odaggz/requirements.txt?X-Goog-Algorithm=GOOG4-RSA-SHA256&X-Goog-Credential=gorilla-files-url-signer-man%40wandb-production.iam.gserviceaccount.com%2F20250414%2Fauto%2Fstorage%2Fgoog4_request&X-Goog-Date=20250414T141759Z&X-Goog-Expires=86399&X-Goog-Signature=5f6153b93ed9fa74deff765545f8c201587fbeb911e62cb3cc4910c63f6fdca03854136261a6bbd672c2d42fbda91a03dfd5489d78595df6bae13a047cfbfbe769a2900d5de43d8c4c2fdb4ff2f62fed69a11d701473162b74edb7cc02410ec05c5598e39df6e9bb66ffd2078fdedad8c5b49972c266a23e216383e15a77f2341156622943959493793689e200b67ed6794be9327090cb298b0aa05d0542348be451ab5ef0eb5d562c63ca86f4825fd09ef41a9735f1b4b10fb4694a9ecfd425ec23727d25a7349defdfe02d9e6ea4e9df4daa5f95cf118267e0c0cc2fcb5a59dc9052a1dbda63c7a3b8ef1aefb68ed47651b521b6d4d3d836c1e68bffd402e8&X-Goog-SignedHeaders=host&X-User=2931823730 (Caused by NewConnectionError('<urllib3.connection.HTTPSConnection object at 0x7f2914094c70>: Failed to establish a new connection: [Errno 101] Network is unreachable'))
2025-04-14 14:37:59,136 ERROR   wandb-upload_1:8632 [internal_api.py:upload_file():2558] upload_file request headers: {'User-Agent': 'python-requests/2.32.3', 'Accept-Encoding': 'gzip, deflate, br', 'Accept': '*/*', 'Connection': 'keep-alive', 'Content-Length': '5836'}
2025-04-14 14:37:59,136 ERROR   wandb-upload_1:8632 [internal_api.py:upload_file():2560] upload_file response body: 
2025-04-14 14:39:16,388 ERROR   wandb-upload_0:8632 [internal_api.py:upload_file():2556] upload_file exception https://storage.googleapis.com/wandb-production.appspot.com/2931823730-harbin-institute-of-technology/ltu-as/31odaggz/config.yaml?X-Goog-Algorithm=GOOG4-RSA-SHA256&X-Goog-Credential=gorilla-files-url-signer-man%40wandb-production.iam.gserviceaccount.com%2F20250414%2Fauto%2Fstorage%2Fgoog4_request&X-Goog-Date=20250414T141758Z&X-Goog-Expires=86399&X-Goog-Signature=194cc2540813956d5c8881739ee12da627ab3bbc9613646e1fa19950a9fbcc97f73ab2038fb24591ccd6d418d705866191f288db79710c6da977d9eab63e107ec482b8f9c047c1f6b1635d6623dc275398201a0e178592ee283d8a4c18f55aa371b4593564f190f2cb30d32d966224135d41dabfe0e17ee9dc99287431ce1828dbeee990f1ded78bf9a3a9c1855596c220b8ee27e0b993b4113ab5b5a61196cb2e9f4415c0d4600507f84950ab4768125c04edff4ea45832f2ed0f995347e212aafca04c189c117aa7b0526097a07c57714519abbb5adeab4b07e3fac776215d41433663593012ca0635dc00382a328ff58282da55adade619f56b37f96ffa58&X-Goog-SignedHeaders=host&X-User=2931823730: HTTPSConnectionPool(host='storage.googleapis.com', port=443): Max retries exceeded with url: /wandb-production.appspot.com/2931823730-harbin-institute-of-technology/ltu-as/31odaggz/config.yaml?X-Goog-Algorithm=GOOG4-RSA-SHA256&X-Goog-Credential=gorilla-files-url-signer-man%40wandb-production.iam.gserviceaccount.com%2F20250414%2Fauto%2Fstorage%2Fgoog4_request&X-Goog-Date=20250414T141758Z&X-Goog-Expires=86399&X-Goog-Signature=194cc2540813956d5c8881739ee12da627ab3bbc9613646e1fa19950a9fbcc97f73ab2038fb24591ccd6d418d705866191f288db79710c6da977d9eab63e107ec482b8f9c047c1f6b1635d6623dc275398201a0e178592ee283d8a4c18f55aa371b4593564f190f2cb30d32d966224135d41dabfe0e17ee9dc99287431ce1828dbeee990f1ded78bf9a3a9c1855596c220b8ee27e0b993b4113ab5b5a61196cb2e9f4415c0d4600507f84950ab4768125c04edff4ea45832f2ed0f995347e212aafca04c189c117aa7b0526097a07c57714519abbb5adeab4b07e3fac776215d41433663593012ca0635dc00382a328ff58282da55adade619f56b37f96ffa58&X-Goog-SignedHeaders=host&X-User=2931823730 (Caused by NewConnectionError('<urllib3.connection.HTTPSConnection object at 0x7f29140ef310>: Failed to establish a new connection: [Errno 101] Network is unreachable'))
2025-04-14 14:39:16,388 ERROR   wandb-upload_0:8632 [internal_api.py:upload_file():2558] upload_file request headers: {'User-Agent': 'python-requests/2.32.3', 'Accept-Encoding': 'gzip, deflate, br', 'Accept': '*/*', 'Connection': 'keep-alive', 'Content-Length': '495'}
2025-04-14 14:39:16,388 ERROR   wandb-upload_0:8632 [internal_api.py:upload_file():2560] upload_file response body: 
2025-04-14 14:43:54,257 ERROR   wandb-upload_1:8632 [internal_api.py:upload_file():2556] upload_file exception https://storage.googleapis.com/wandb-production.appspot.com/2931823730-harbin-institute-of-technology/ltu-as/31odaggz/requirements.txt?X-Goog-Algorithm=GOOG4-RSA-SHA256&X-Goog-Credential=gorilla-files-url-signer-man%40wandb-production.iam.gserviceaccount.com%2F20250414%2Fauto%2Fstorage%2Fgoog4_request&X-Goog-Date=20250414T141759Z&X-Goog-Expires=86399&X-Goog-Signature=5f6153b93ed9fa74deff765545f8c201587fbeb911e62cb3cc4910c63f6fdca03854136261a6bbd672c2d42fbda91a03dfd5489d78595df6bae13a047cfbfbe769a2900d5de43d8c4c2fdb4ff2f62fed69a11d701473162b74edb7cc02410ec05c5598e39df6e9bb66ffd2078fdedad8c5b49972c266a23e216383e15a77f2341156622943959493793689e200b67ed6794be9327090cb298b0aa05d0542348be451ab5ef0eb5d562c63ca86f4825fd09ef41a9735f1b4b10fb4694a9ecfd425ec23727d25a7349defdfe02d9e6ea4e9df4daa5f95cf118267e0c0cc2fcb5a59dc9052a1dbda63c7a3b8ef1aefb68ed47651b521b6d4d3d836c1e68bffd402e8&X-Goog-SignedHeaders=host&X-User=2931823730: HTTPSConnectionPool(host='storage.googleapis.com', port=443): Max retries exceeded with url: /wandb-production.appspot.com/2931823730-harbin-institute-of-technology/ltu-as/31odaggz/requirements.txt?X-Goog-Algorithm=GOOG4-RSA-SHA256&X-Goog-Credential=gorilla-files-url-signer-man%40wandb-production.iam.gserviceaccount.com%2F20250414%2Fauto%2Fstorage%2Fgoog4_request&X-Goog-Date=20250414T141759Z&X-Goog-Expires=86399&X-Goog-Signature=5f6153b93ed9fa74deff765545f8c201587fbeb911e62cb3cc4910c63f6fdca03854136261a6bbd672c2d42fbda91a03dfd5489d78595df6bae13a047cfbfbe769a2900d5de43d8c4c2fdb4ff2f62fed69a11d701473162b74edb7cc02410ec05c5598e39df6e9bb66ffd2078fdedad8c5b49972c266a23e216383e15a77f2341156622943959493793689e200b67ed6794be9327090cb298b0aa05d0542348be451ab5ef0eb5d562c63ca86f4825fd09ef41a9735f1b4b10fb4694a9ecfd425ec23727d25a7349defdfe02d9e6ea4e9df4daa5f95cf118267e0c0cc2fcb5a59dc9052a1dbda63c7a3b8ef1aefb68ed47651b521b6d4d3d836c1e68bffd402e8&X-Goog-SignedHeaders=host&X-User=2931823730 (Caused by NewConnectionError('<urllib3.connection.HTTPSConnection object at 0x7f29140eefb0>: Failed to establish a new connection: [Errno 101] Network is unreachable'))
2025-04-14 14:43:54,258 ERROR   wandb-upload_1:8632 [internal_api.py:upload_file():2558] upload_file request headers: {'User-Agent': 'python-requests/2.32.3', 'Accept-Encoding': 'gzip, deflate, br', 'Accept': '*/*', 'Connection': 'keep-alive', 'Content-Length': '5836'}
2025-04-14 14:43:54,258 ERROR   wandb-upload_1:8632 [internal_api.py:upload_file():2560] upload_file response body: 
2025-04-14 14:44:52,383 ERROR   wandb-upload_0:8632 [internal_api.py:upload_file():2556] upload_file exception https://storage.googleapis.com/wandb-production.appspot.com/2931823730-harbin-institute-of-technology/ltu-as/31odaggz/config.yaml?X-Goog-Algorithm=GOOG4-RSA-SHA256&X-Goog-Credential=gorilla-files-url-signer-man%40wandb-production.iam.gserviceaccount.com%2F20250414%2Fauto%2Fstorage%2Fgoog4_request&X-Goog-Date=20250414T141758Z&X-Goog-Expires=86399&X-Goog-Signature=194cc2540813956d5c8881739ee12da627ab3bbc9613646e1fa19950a9fbcc97f73ab2038fb24591ccd6d418d705866191f288db79710c6da977d9eab63e107ec482b8f9c047c1f6b1635d6623dc275398201a0e178592ee283d8a4c18f55aa371b4593564f190f2cb30d32d966224135d41dabfe0e17ee9dc99287431ce1828dbeee990f1ded78bf9a3a9c1855596c220b8ee27e0b993b4113ab5b5a61196cb2e9f4415c0d4600507f84950ab4768125c04edff4ea45832f2ed0f995347e212aafca04c189c117aa7b0526097a07c57714519abbb5adeab4b07e3fac776215d41433663593012ca0635dc00382a328ff58282da55adade619f56b37f96ffa58&X-Goog-SignedHeaders=host&X-User=2931823730: HTTPSConnectionPool(host='storage.googleapis.com', port=443): Max retries exceeded with url: /wandb-production.appspot.com/2931823730-harbin-institute-of-technology/ltu-as/31odaggz/config.yaml?X-Goog-Algorithm=GOOG4-RSA-SHA256&X-Goog-Credential=gorilla-files-url-signer-man%40wandb-production.iam.gserviceaccount.com%2F20250414%2Fauto%2Fstorage%2Fgoog4_request&X-Goog-Date=20250414T141758Z&X-Goog-Expires=86399&X-Goog-Signature=194cc2540813956d5c8881739ee12da627ab3bbc9613646e1fa19950a9fbcc97f73ab2038fb24591ccd6d418d705866191f288db79710c6da977d9eab63e107ec482b8f9c047c1f6b1635d6623dc275398201a0e178592ee283d8a4c18f55aa371b4593564f190f2cb30d32d966224135d41dabfe0e17ee9dc99287431ce1828dbeee990f1ded78bf9a3a9c1855596c220b8ee27e0b993b4113ab5b5a61196cb2e9f4415c0d4600507f84950ab4768125c04edff4ea45832f2ed0f995347e212aafca04c189c117aa7b0526097a07c57714519abbb5adeab4b07e3fac776215d41433663593012ca0635dc00382a328ff58282da55adade619f56b37f96ffa58&X-Goog-SignedHeaders=host&X-User=2931823730 (Caused by NewConnectionError('<urllib3.connection.HTTPSConnection object at 0x7f29140ee980>: Failed to establish a new connection: [Errno 101] Network is unreachable'))
2025-04-14 14:44:52,383 ERROR   wandb-upload_0:8632 [internal_api.py:upload_file():2558] upload_file request headers: {'User-Agent': 'python-requests/2.32.3', 'Accept-Encoding': 'gzip, deflate, br', 'Accept': '*/*', 'Connection': 'keep-alive', 'Content-Length': '495'}
2025-04-14 14:44:52,384 ERROR   wandb-upload_0:8632 [internal_api.py:upload_file():2560] upload_file response body: 
2025-04-14 14:49:03,627 ERROR   wandb-upload_1:8632 [internal_api.py:upload_file():2556] upload_file exception https://storage.googleapis.com/wandb-production.appspot.com/2931823730-harbin-institute-of-technology/ltu-as/31odaggz/requirements.txt?X-Goog-Algorithm=GOOG4-RSA-SHA256&X-Goog-Credential=gorilla-files-url-signer-man%40wandb-production.iam.gserviceaccount.com%2F20250414%2Fauto%2Fstorage%2Fgoog4_request&X-Goog-Date=20250414T141759Z&X-Goog-Expires=86399&X-Goog-Signature=5f6153b93ed9fa74deff765545f8c201587fbeb911e62cb3cc4910c63f6fdca03854136261a6bbd672c2d42fbda91a03dfd5489d78595df6bae13a047cfbfbe769a2900d5de43d8c4c2fdb4ff2f62fed69a11d701473162b74edb7cc02410ec05c5598e39df6e9bb66ffd2078fdedad8c5b49972c266a23e216383e15a77f2341156622943959493793689e200b67ed6794be9327090cb298b0aa05d0542348be451ab5ef0eb5d562c63ca86f4825fd09ef41a9735f1b4b10fb4694a9ecfd425ec23727d25a7349defdfe02d9e6ea4e9df4daa5f95cf118267e0c0cc2fcb5a59dc9052a1dbda63c7a3b8ef1aefb68ed47651b521b6d4d3d836c1e68bffd402e8&X-Goog-SignedHeaders=host&X-User=2931823730: HTTPSConnectionPool(host='storage.googleapis.com', port=443): Max retries exceeded with url: /wandb-production.appspot.com/2931823730-harbin-institute-of-technology/ltu-as/31odaggz/requirements.txt?X-Goog-Algorithm=GOOG4-RSA-SHA256&X-Goog-Credential=gorilla-files-url-signer-man%40wandb-production.iam.gserviceaccount.com%2F20250414%2Fauto%2Fstorage%2Fgoog4_request&X-Goog-Date=20250414T141759Z&X-Goog-Expires=86399&X-Goog-Signature=5f6153b93ed9fa74deff765545f8c201587fbeb911e62cb3cc4910c63f6fdca03854136261a6bbd672c2d42fbda91a03dfd5489d78595df6bae13a047cfbfbe769a2900d5de43d8c4c2fdb4ff2f62fed69a11d701473162b74edb7cc02410ec05c5598e39df6e9bb66ffd2078fdedad8c5b49972c266a23e216383e15a77f2341156622943959493793689e200b67ed6794be9327090cb298b0aa05d0542348be451ab5ef0eb5d562c63ca86f4825fd09ef41a9735f1b4b10fb4694a9ecfd425ec23727d25a7349defdfe02d9e6ea4e9df4daa5f95cf118267e0c0cc2fcb5a59dc9052a1dbda63c7a3b8ef1aefb68ed47651b521b6d4d3d836c1e68bffd402e8&X-Goog-SignedHeaders=host&X-User=2931823730 (Caused by NewConnectionError('<urllib3.connection.HTTPSConnection object at 0x7f2914096d70>: Failed to establish a new connection: [Errno 101] Network is unreachable'))
2025-04-14 14:49:03,627 ERROR   wandb-upload_1:8632 [internal_api.py:upload_file():2558] upload_file request headers: {'User-Agent': 'python-requests/2.32.3', 'Accept-Encoding': 'gzip, deflate, br', 'Accept': '*/*', 'Connection': 'keep-alive', 'Content-Length': '5836'}
2025-04-14 14:49:03,627 ERROR   wandb-upload_1:8632 [internal_api.py:upload_file():2560] upload_file response body: 
2025-04-14 14:50:43,556 ERROR   wandb-upload_0:8632 [internal_api.py:upload_file():2556] upload_file exception https://storage.googleapis.com/wandb-production.appspot.com/2931823730-harbin-institute-of-technology/ltu-as/31odaggz/config.yaml?X-Goog-Algorithm=GOOG4-RSA-SHA256&X-Goog-Credential=gorilla-files-url-signer-man%40wandb-production.iam.gserviceaccount.com%2F20250414%2Fauto%2Fstorage%2Fgoog4_request&X-Goog-Date=20250414T141758Z&X-Goog-Expires=86399&X-Goog-Signature=194cc2540813956d5c8881739ee12da627ab3bbc9613646e1fa19950a9fbcc97f73ab2038fb24591ccd6d418d705866191f288db79710c6da977d9eab63e107ec482b8f9c047c1f6b1635d6623dc275398201a0e178592ee283d8a4c18f55aa371b4593564f190f2cb30d32d966224135d41dabfe0e17ee9dc99287431ce1828dbeee990f1ded78bf9a3a9c1855596c220b8ee27e0b993b4113ab5b5a61196cb2e9f4415c0d4600507f84950ab4768125c04edff4ea45832f2ed0f995347e212aafca04c189c117aa7b0526097a07c57714519abbb5adeab4b07e3fac776215d41433663593012ca0635dc00382a328ff58282da55adade619f56b37f96ffa58&X-Goog-SignedHeaders=host&X-User=2931823730: HTTPSConnectionPool(host='storage.googleapis.com', port=443): Max retries exceeded with url: /wandb-production.appspot.com/2931823730-harbin-institute-of-technology/ltu-as/31odaggz/config.yaml?X-Goog-Algorithm=GOOG4-RSA-SHA256&X-Goog-Credential=gorilla-files-url-signer-man%40wandb-production.iam.gserviceaccount.com%2F20250414%2Fauto%2Fstorage%2Fgoog4_request&X-Goog-Date=20250414T141758Z&X-Goog-Expires=86399&X-Goog-Signature=194cc2540813956d5c8881739ee12da627ab3bbc9613646e1fa19950a9fbcc97f73ab2038fb24591ccd6d418d705866191f288db79710c6da977d9eab63e107ec482b8f9c047c1f6b1635d6623dc275398201a0e178592ee283d8a4c18f55aa371b4593564f190f2cb30d32d966224135d41dabfe0e17ee9dc99287431ce1828dbeee990f1ded78bf9a3a9c1855596c220b8ee27e0b993b4113ab5b5a61196cb2e9f4415c0d4600507f84950ab4768125c04edff4ea45832f2ed0f995347e212aafca04c189c117aa7b0526097a07c57714519abbb5adeab4b07e3fac776215d41433663593012ca0635dc00382a328ff58282da55adade619f56b37f96ffa58&X-Goog-SignedHeaders=host&X-User=2931823730 (Caused by NewConnectionError('<urllib3.connection.HTTPSConnection object at 0x7f29140957b0>: Failed to establish a new connection: [Errno 101] Network is unreachable'))
2025-04-14 14:50:43,556 ERROR   wandb-upload_0:8632 [internal_api.py:upload_file():2558] upload_file request headers: {'User-Agent': 'python-requests/2.32.3', 'Accept-Encoding': 'gzip, deflate, br', 'Accept': '*/*', 'Connection': 'keep-alive', 'Content-Length': '495'}
2025-04-14 14:50:43,556 ERROR   wandb-upload_0:8632 [internal_api.py:upload_file():2560] upload_file response body: 
2025-04-14 14:54:24,066 ERROR   wandb-upload_1:8632 [internal_api.py:upload_file():2556] upload_file exception https://storage.googleapis.com/wandb-production.appspot.com/2931823730-harbin-institute-of-technology/ltu-as/31odaggz/requirements.txt?X-Goog-Algorithm=GOOG4-RSA-SHA256&X-Goog-Credential=gorilla-files-url-signer-man%40wandb-production.iam.gserviceaccount.com%2F20250414%2Fauto%2Fstorage%2Fgoog4_request&X-Goog-Date=20250414T141759Z&X-Goog-Expires=86399&X-Goog-Signature=5f6153b93ed9fa74deff765545f8c201587fbeb911e62cb3cc4910c63f6fdca03854136261a6bbd672c2d42fbda91a03dfd5489d78595df6bae13a047cfbfbe769a2900d5de43d8c4c2fdb4ff2f62fed69a11d701473162b74edb7cc02410ec05c5598e39df6e9bb66ffd2078fdedad8c5b49972c266a23e216383e15a77f2341156622943959493793689e200b67ed6794be9327090cb298b0aa05d0542348be451ab5ef0eb5d562c63ca86f4825fd09ef41a9735f1b4b10fb4694a9ecfd425ec23727d25a7349defdfe02d9e6ea4e9df4daa5f95cf118267e0c0cc2fcb5a59dc9052a1dbda63c7a3b8ef1aefb68ed47651b521b6d4d3d836c1e68bffd402e8&X-Goog-SignedHeaders=host&X-User=2931823730: HTTPSConnectionPool(host='storage.googleapis.com', port=443): Max retries exceeded with url: /wandb-production.appspot.com/2931823730-harbin-institute-of-technology/ltu-as/31odaggz/requirements.txt?X-Goog-Algorithm=GOOG4-RSA-SHA256&X-Goog-Credential=gorilla-files-url-signer-man%40wandb-production.iam.gserviceaccount.com%2F20250414%2Fauto%2Fstorage%2Fgoog4_request&X-Goog-Date=20250414T141759Z&X-Goog-Expires=86399&X-Goog-Signature=5f6153b93ed9fa74deff765545f8c201587fbeb911e62cb3cc4910c63f6fdca03854136261a6bbd672c2d42fbda91a03dfd5489d78595df6bae13a047cfbfbe769a2900d5de43d8c4c2fdb4ff2f62fed69a11d701473162b74edb7cc02410ec05c5598e39df6e9bb66ffd2078fdedad8c5b49972c266a23e216383e15a77f2341156622943959493793689e200b67ed6794be9327090cb298b0aa05d0542348be451ab5ef0eb5d562c63ca86f4825fd09ef41a9735f1b4b10fb4694a9ecfd425ec23727d25a7349defdfe02d9e6ea4e9df4daa5f95cf118267e0c0cc2fcb5a59dc9052a1dbda63c7a3b8ef1aefb68ed47651b521b6d4d3d836c1e68bffd402e8&X-Goog-SignedHeaders=host&X-User=2931823730 (Caused by NewConnectionError('<urllib3.connection.HTTPSConnection object at 0x7f2914097eb0>: Failed to establish a new connection: [Errno 101] Network is unreachable'))
2025-04-14 14:54:24,066 ERROR   wandb-upload_1:8632 [internal_api.py:upload_file():2558] upload_file request headers: {'User-Agent': 'python-requests/2.32.3', 'Accept-Encoding': 'gzip, deflate, br', 'Accept': '*/*', 'Connection': 'keep-alive', 'Content-Length': '5836'}
2025-04-14 14:54:24,066 ERROR   wandb-upload_1:8632 [internal_api.py:upload_file():2560] upload_file response body: 
2025-04-14 14:56:05,990 ERROR   wandb-upload_0:8632 [internal_api.py:upload_file():2556] upload_file exception https://storage.googleapis.com/wandb-production.appspot.com/2931823730-harbin-institute-of-technology/ltu-as/31odaggz/config.yaml?X-Goog-Algorithm=GOOG4-RSA-SHA256&X-Goog-Credential=gorilla-files-url-signer-man%40wandb-production.iam.gserviceaccount.com%2F20250414%2Fauto%2Fstorage%2Fgoog4_request&X-Goog-Date=20250414T141758Z&X-Goog-Expires=86399&X-Goog-Signature=194cc2540813956d5c8881739ee12da627ab3bbc9613646e1fa19950a9fbcc97f73ab2038fb24591ccd6d418d705866191f288db79710c6da977d9eab63e107ec482b8f9c047c1f6b1635d6623dc275398201a0e178592ee283d8a4c18f55aa371b4593564f190f2cb30d32d966224135d41dabfe0e17ee9dc99287431ce1828dbeee990f1ded78bf9a3a9c1855596c220b8ee27e0b993b4113ab5b5a61196cb2e9f4415c0d4600507f84950ab4768125c04edff4ea45832f2ed0f995347e212aafca04c189c117aa7b0526097a07c57714519abbb5adeab4b07e3fac776215d41433663593012ca0635dc00382a328ff58282da55adade619f56b37f96ffa58&X-Goog-SignedHeaders=host&X-User=2931823730: HTTPSConnectionPool(host='storage.googleapis.com', port=443): Max retries exceeded with url: /wandb-production.appspot.com/2931823730-harbin-institute-of-technology/ltu-as/31odaggz/config.yaml?X-Goog-Algorithm=GOOG4-RSA-SHA256&X-Goog-Credential=gorilla-files-url-signer-man%40wandb-production.iam.gserviceaccount.com%2F20250414%2Fauto%2Fstorage%2Fgoog4_request&X-Goog-Date=20250414T141758Z&X-Goog-Expires=86399&X-Goog-Signature=194cc2540813956d5c8881739ee12da627ab3bbc9613646e1fa19950a9fbcc97f73ab2038fb24591ccd6d418d705866191f288db79710c6da977d9eab63e107ec482b8f9c047c1f6b1635d6623dc275398201a0e178592ee283d8a4c18f55aa371b4593564f190f2cb30d32d966224135d41dabfe0e17ee9dc99287431ce1828dbeee990f1ded78bf9a3a9c1855596c220b8ee27e0b993b4113ab5b5a61196cb2e9f4415c0d4600507f84950ab4768125c04edff4ea45832f2ed0f995347e212aafca04c189c117aa7b0526097a07c57714519abbb5adeab4b07e3fac776215d41433663593012ca0635dc00382a328ff58282da55adade619f56b37f96ffa58&X-Goog-SignedHeaders=host&X-User=2931823730 (Caused by NewConnectionError('<urllib3.connection.HTTPSConnection object at 0x7f29140ee8f0>: Failed to establish a new connection: [Errno 101] Network is unreachable'))
2025-04-14 14:56:05,990 ERROR   wandb-upload_0:8632 [internal_api.py:upload_file():2558] upload_file request headers: {'User-Agent': 'python-requests/2.32.3', 'Accept-Encoding': 'gzip, deflate, br', 'Accept': '*/*', 'Connection': 'keep-alive', 'Content-Length': '495'}
2025-04-14 14:56:05,990 ERROR   wandb-upload_0:8632 [internal_api.py:upload_file():2560] upload_file response body: 
