2025-04-14 15:11:40,330 INFO    StreamThr :16610 [internal.py:wandb_internal():86] W&B internal server running at pid: 16610, started at: 2025-04-14 15:11:40.329535
2025-04-14 15:11:40,334 DEBUG   HandlerThread:16610 [handler.py:handle_request():146] handle_request: status
2025-04-14 15:11:40,340 INFO    WriterThread:16610 [datastore.py:open_for_write():85] open: /root/ltu-main/ltu-main/src/ltu_as/train_scripts/wandb/run-20250414_151140-sro21n02/run-sro21n02.wandb
2025-04-14 15:11:40,341 DEBUG   SenderThread:16610 [sender.py:send():380] send: header
2025-04-14 15:11:40,341 DEBUG   SenderThread:16610 [sender.py:send():380] send: run
2025-04-14 15:11:41,159 DEBUG   HandlerThread:16610 [handler.py:handle_request():146] handle_request: check_version
2025-04-14 15:11:41,166 INFO    SenderThread:16610 [dir_watcher.py:__init__():211] watching files in: /root/ltu-main/ltu-main/src/ltu_as/train_scripts/wandb/run-20250414_151140-sro21n02/files
2025-04-14 15:11:41,167 INFO    SenderThread:16610 [sender.py:_start_run_threads():1122] run started: sro21n02 with start time 1744643500.330247
2025-04-14 15:11:41,167 DEBUG   SenderThread:16610 [sender.py:send_request():407] send_request: check_version
2025-04-14 15:11:41,794 DEBUG   HandlerThread:16610 [handler.py:handle_request():146] handle_request: run_start
2025-04-14 15:11:41,860 DEBUG   HandlerThread:16610 [system_info.py:__init__():32] System info init
2025-04-14 15:11:41,860 DEBUG   HandlerThread:16610 [system_info.py:__init__():47] System info init done
2025-04-14 15:11:41,861 INFO    HandlerThread:16610 [system_monitor.py:start():194] Starting system monitor
2025-04-14 15:11:41,861 INFO    SystemMonitor:16610 [system_monitor.py:_start():158] Starting system asset monitoring threads
2025-04-14 15:11:41,861 INFO    HandlerThread:16610 [system_monitor.py:probe():214] Collecting system info
2025-04-14 15:11:41,862 INFO    SystemMonitor:16610 [interfaces.py:start():190] Started cpu monitoring
2025-04-14 15:11:41,863 INFO    SystemMonitor:16610 [interfaces.py:start():190] Started disk monitoring
2025-04-14 15:11:41,864 INFO    SystemMonitor:16610 [interfaces.py:start():190] Started gpu monitoring
2025-04-14 15:11:41,866 INFO    SystemMonitor:16610 [interfaces.py:start():190] Started memory monitoring
2025-04-14 15:11:41,866 INFO    SystemMonitor:16610 [interfaces.py:start():190] Started network monitoring
2025-04-14 15:11:41,884 DEBUG   HandlerThread:16610 [system_info.py:probe():196] Probing system
2025-04-14 15:11:41,885 DEBUG   HandlerThread:16610 [gitlib.py:_init_repo():53] git repository is invalid
2025-04-14 15:11:41,885 DEBUG   HandlerThread:16610 [system_info.py:probe():244] Probing system done
2025-04-14 15:11:41,885 DEBUG   HandlerThread:16610 [system_monitor.py:probe():223] {'os': 'Linux-4.15.0-213-generic-x86_64-with-glibc2.27', 'python': '3.10.15', 'heartbeatAt': '2025-04-14T15:11:41.884243', 'startedAt': '2025-04-14T15:11:40.101515', 'docker': None, 'cuda': None, 'args': ('--base_model', '../../../pretrained_mdls/ltuas_long_noqa_a6.bin', '--data_path', '../../../openasqa/data/iemocap_preprocess_with_answers_updated.json', '--output_dir', '../exp/ltuas_ft_meld/', '--batch_size', '256', '--micro_batch_size', '1', '--num_epochs', '1', '--learning_rate', '2e-4', '--cutoff_len', '100', '--val_set_size', '0', '--lora_r', '8', '--lora_alpha', '16', '--lora_dropout', '0.05', '--lora_target_modules', '[q_proj,v_proj]', '--group_by_length', '--wandb_run_name', '../exp/ltuas_ft_meld/', '--save_steps', '30', '--trainable_params', 'all'), 'state': 'running', 'program': '/root/ltu-main/ltu-main/src/ltu_as/train_scripts/../finetune_low_resource.py', 'codePathLocal': None, 'host': 'ubuntu', 'username': 'root', 'executable': '/root/anaconda3/envs/venv_ltu/bin/python', 'cpu_count': 4, 'cpu_count_logical': 4, 'cpu_freq': {'current': 2294.523, 'min': 0.0, 'max': 0.0}, 'cpu_freq_per_core': [{'current': 2294.523, 'min': 0.0, 'max': 0.0}, {'current': 2294.523, 'min': 0.0, 'max': 0.0}, {'current': 2294.523, 'min': 0.0, 'max': 0.0}, {'current': 2294.523, 'min': 0.0, 'max': 0.0}], 'disk': {'/': {'total': 499.9882621765137, 'used': 375.72207260131836}}, 'gpu': 'NVIDIA A100-PCIE-40GB', 'gpu_count': 2, 'gpu_devices': [{'name': 'NVIDIA A100-PCIE-40GB', 'memory_total': 42949672960}, {'name': 'NVIDIA A100-PCIE-40GB', 'memory_total': 42949672960}], 'memory': {'total': 19.60204315185547}}
2025-04-14 15:11:41,886 INFO    HandlerThread:16610 [system_monitor.py:probe():224] Finished collecting system info
2025-04-14 15:11:41,886 INFO    HandlerThread:16610 [system_monitor.py:probe():227] Publishing system info
2025-04-14 15:11:41,886 DEBUG   HandlerThread:16610 [system_info.py:_save_pip():52] Saving list of pip packages installed into the current environment
2025-04-14 15:11:41,887 DEBUG   HandlerThread:16610 [system_info.py:_save_pip():68] Saving pip packages done
2025-04-14 15:11:41,887 DEBUG   HandlerThread:16610 [system_info.py:_save_conda():75] Saving list of conda packages installed into the current environment
2025-04-14 15:11:42,170 INFO    Thread-12 :16610 [dir_watcher.py:_on_file_created():271] file/dir created: /root/ltu-main/ltu-main/src/ltu_as/train_scripts/wandb/run-20250414_151140-sro21n02/files/requirements.txt
2025-04-14 15:11:42,171 INFO    Thread-12 :16610 [dir_watcher.py:_on_file_created():271] file/dir created: /root/ltu-main/ltu-main/src/ltu_as/train_scripts/wandb/run-20250414_151140-sro21n02/files/conda-environment.yaml
2025-04-14 15:12:41,867 DEBUG   SystemMonitor:16610 [system_monitor.py:_start():172] Starting system metrics aggregation loop
2025-04-14 15:13:02,723 DEBUG   HandlerThread:16610 [system_info.py:_save_conda():87] Saving conda packages done
2025-04-14 15:13:02,723 INFO    HandlerThread:16610 [system_monitor.py:probe():229] Finished publishing system info
2025-04-14 15:13:03,200 INFO    Thread-12 :16610 [dir_watcher.py:_on_file_modified():288] file/dir modified: /root/ltu-main/ltu-main/src/ltu_as/train_scripts/wandb/run-20250414_151140-sro21n02/files/conda-environment.yaml
2025-04-14 15:13:03,201 INFO    Thread-12 :16610 [dir_watcher.py:_on_file_created():271] file/dir created: /root/ltu-main/ltu-main/src/ltu_as/train_scripts/wandb/run-20250414_151140-sro21n02/files/wandb-metadata.json
2025-04-14 15:13:06,134 DEBUG   HandlerThread:16610 [handler.py:handle_request():146] handle_request: status_report
2025-04-14 15:13:06,135 DEBUG   HandlerThread:16610 [handler.py:handle_request():146] handle_request: keepalive
2025-04-14 15:13:06,135 DEBUG   HandlerThread:16610 [handler.py:handle_request():146] handle_request: status_report
2025-04-14 15:13:06,135 DEBUG   HandlerThread:16610 [handler.py:handle_request():146] handle_request: keepalive
2025-04-14 15:13:06,135 DEBUG   HandlerThread:16610 [handler.py:handle_request():146] handle_request: status_report
2025-04-14 15:13:06,135 DEBUG   HandlerThread:16610 [handler.py:handle_request():146] handle_request: keepalive
2025-04-14 15:13:06,135 DEBUG   HandlerThread:16610 [handler.py:handle_request():146] handle_request: status_report
2025-04-14 15:13:06,135 DEBUG   HandlerThread:16610 [handler.py:handle_request():146] handle_request: keepalive
2025-04-14 15:13:06,135 DEBUG   HandlerThread:16610 [handler.py:handle_request():146] handle_request: status_report
2025-04-14 15:13:06,136 DEBUG   HandlerThread:16610 [handler.py:handle_request():146] handle_request: keepalive
2025-04-14 15:13:06,136 DEBUG   HandlerThread:16610 [handler.py:handle_request():146] handle_request: status_report
2025-04-14 15:13:06,136 DEBUG   HandlerThread:16610 [handler.py:handle_request():146] handle_request: internal_messages
2025-04-14 15:13:06,136 DEBUG   HandlerThread:16610 [handler.py:handle_request():146] handle_request: stop_status
2025-04-14 15:13:06,136 DEBUG   HandlerThread:16610 [handler.py:handle_request():146] handle_request: status_report
2025-04-14 15:13:06,137 DEBUG   HandlerThread:16610 [handler.py:handle_request():146] handle_request: keepalive
2025-04-14 15:13:06,137 DEBUG   HandlerThread:16610 [handler.py:handle_request():146] handle_request: status_report
2025-04-14 15:13:06,137 DEBUG   HandlerThread:16610 [handler.py:handle_request():146] handle_request: keepalive
2025-04-14 15:13:06,137 DEBUG   HandlerThread:16610 [handler.py:handle_request():146] handle_request: status_report
2025-04-14 15:13:06,138 DEBUG   HandlerThread:16610 [handler.py:handle_request():146] handle_request: keepalive
2025-04-14 15:13:06,138 DEBUG   HandlerThread:16610 [handler.py:handle_request():146] handle_request: status_report
2025-04-14 15:13:06,138 DEBUG   HandlerThread:16610 [handler.py:handle_request():146] handle_request: keepalive
2025-04-14 15:13:06,138 DEBUG   HandlerThread:16610 [handler.py:handle_request():146] handle_request: status_report
2025-04-14 15:13:06,138 DEBUG   HandlerThread:16610 [handler.py:handle_request():146] handle_request: keepalive
2025-04-14 15:13:06,138 DEBUG   HandlerThread:16610 [handler.py:handle_request():146] handle_request: status_report
2025-04-14 15:13:06,138 DEBUG   HandlerThread:16610 [handler.py:handle_request():146] handle_request: keepalive
2025-04-14 15:13:06,138 DEBUG   HandlerThread:16610 [handler.py:handle_request():146] handle_request: status_report
2025-04-14 15:13:06,139 DEBUG   HandlerThread:16610 [handler.py:handle_request():146] handle_request: keepalive
2025-04-14 15:13:06,139 DEBUG   HandlerThread:16610 [handler.py:handle_request():146] handle_request: status_report
2025-04-14 15:13:06,139 DEBUG   HandlerThread:16610 [handler.py:handle_request():146] handle_request: keepalive
2025-04-14 15:13:06,139 DEBUG   HandlerThread:16610 [handler.py:handle_request():146] handle_request: status_report
2025-04-14 15:13:06,139 DEBUG   HandlerThread:16610 [handler.py:handle_request():146] handle_request: keepalive
2025-04-14 15:13:06,139 DEBUG   HandlerThread:16610 [handler.py:handle_request():146] handle_request: status_report
2025-04-14 15:13:06,139 DEBUG   HandlerThread:16610 [handler.py:handle_request():146] handle_request: keepalive
2025-04-14 15:13:06,139 DEBUG   HandlerThread:16610 [handler.py:handle_request():146] handle_request: status_report
2025-04-14 15:13:06,138 DEBUG   SenderThread:16610 [sender.py:send():380] send: telemetry
2025-04-14 15:13:06,140 DEBUG   SenderThread:16610 [sender.py:send():380] send: config
2025-04-14 15:13:06,140 DEBUG   SenderThread:16610 [sender.py:send():380] send: metric
2025-04-14 15:13:06,140 DEBUG   SenderThread:16610 [sender.py:send():380] send: telemetry
2025-04-14 15:13:06,141 DEBUG   SenderThread:16610 [sender.py:send():380] send: metric
2025-04-14 15:13:06,141 WARNING SenderThread:16610 [sender.py:send_metric():1329] Seen metric with glob (shouldn't happen)
2025-04-14 15:13:06,141 DEBUG   SenderThread:16610 [sender.py:send_request():407] send_request: stop_status
2025-04-14 15:13:06,457 DEBUG   SenderThread:16610 [sender.py:send():380] send: stats
2025-04-14 15:13:06,457 DEBUG   SenderThread:16610 [sender.py:send():380] send: files
2025-04-14 15:13:06,457 INFO    SenderThread:16610 [sender.py:_save_file():1378] saving file wandb-metadata.json with policy now
2025-04-14 15:13:06,834 DEBUG   HandlerThread:16610 [handler.py:handle_request():146] handle_request: keepalive
2025-04-14 15:13:06,985 ERROR   wandb-upload_0:16610 [internal_api.py:upload_file():2556] upload_file exception https://storage.googleapis.com/wandb-production.appspot.com/2931823730-harbin-institute-of-technology/ltu-as/sro21n02/wandb-metadata.json?X-Goog-Algorithm=GOOG4-RSA-SHA256&X-Goog-Credential=gorilla-files-url-signer-man%40wandb-production.iam.gserviceaccount.com%2F20250414%2Fauto%2Fstorage%2Fgoog4_request&X-Goog-Date=20250414T151306Z&X-Goog-Expires=86399&X-Goog-Signature=0bf0b2bd8b586c4629cadf1b33955ead125425c9929b4db02171f92ae5780d32456d214d433d6d319596799bcbcb937ce5a1f7aee1c48cb9ac1c99a4aa3fc2356f2a3c710a9a6654c05b606b01ca1e97d9eaae6993f275d0c5967cccf57e2fe28f0f5bd4bca6f0f0c63aa5c6ce17990fb8c9f433425f087c76eec8c8916ab0eb376a85e82f84dce56bec266fd96c22c1f9354c90c63719ece160fd1bb61261f79adf64168e7b3c2b680ecc3e6025130fbc86e9885ee5d0cd41b40a6e82022f2115d5b5a683323cee548e6365923416e21c23b9daf0e147f86c6180af83d1df6a3f54eb98d1d885b465d7933177b8fb84b0eb944852291b001a237e586a9d35cf&X-Goog-SignedHeaders=host&X-User=2931823730: HTTPSConnectionPool(host='storage.googleapis.com', port=443): Max retries exceeded with url: /wandb-production.appspot.com/2931823730-harbin-institute-of-technology/ltu-as/sro21n02/wandb-metadata.json?X-Goog-Algorithm=GOOG4-RSA-SHA256&X-Goog-Credential=gorilla-files-url-signer-man%40wandb-production.iam.gserviceaccount.com%2F20250414%2Fauto%2Fstorage%2Fgoog4_request&X-Goog-Date=20250414T151306Z&X-Goog-Expires=86399&X-Goog-Signature=0bf0b2bd8b586c4629cadf1b33955ead125425c9929b4db02171f92ae5780d32456d214d433d6d319596799bcbcb937ce5a1f7aee1c48cb9ac1c99a4aa3fc2356f2a3c710a9a6654c05b606b01ca1e97d9eaae6993f275d0c5967cccf57e2fe28f0f5bd4bca6f0f0c63aa5c6ce17990fb8c9f433425f087c76eec8c8916ab0eb376a85e82f84dce56bec266fd96c22c1f9354c90c63719ece160fd1bb61261f79adf64168e7b3c2b680ecc3e6025130fbc86e9885ee5d0cd41b40a6e82022f2115d5b5a683323cee548e6365923416e21c23b9daf0e147f86c6180af83d1df6a3f54eb98d1d885b465d7933177b8fb84b0eb944852291b001a237e586a9d35cf&X-Goog-SignedHeaders=host&X-User=2931823730 (Caused by NewConnectionError('<urllib3.connection.HTTPSConnection object at 0x7f87003be1a0>: Failed to establish a new connection: [Errno 101] Network is unreachable'))
2025-04-14 15:13:06,985 ERROR   wandb-upload_0:16610 [internal_api.py:upload_file():2558] upload_file request headers: {'User-Agent': 'python-requests/2.32.3', 'Accept-Encoding': 'gzip, deflate, br', 'Accept': '*/*', 'Connection': 'keep-alive', 'Content-Length': '2380'}
2025-04-14 15:13:06,985 ERROR   wandb-upload_0:16610 [internal_api.py:upload_file():2560] upload_file response body: 
2025-04-14 15:13:07,202 INFO    Thread-12 :16610 [dir_watcher.py:_on_file_created():271] file/dir created: /root/ltu-main/ltu-main/src/ltu_as/train_scripts/wandb/run-20250414_151140-sro21n02/files/output.log
2025-04-14 15:13:08,156 ERROR   wandb-upload_0:16610 [internal_api.py:upload_file():2556] upload_file exception https://storage.googleapis.com/wandb-production.appspot.com/2931823730-harbin-institute-of-technology/ltu-as/sro21n02/wandb-metadata.json?X-Goog-Algorithm=GOOG4-RSA-SHA256&X-Goog-Credential=gorilla-files-url-signer-man%40wandb-production.iam.gserviceaccount.com%2F20250414%2Fauto%2Fstorage%2Fgoog4_request&X-Goog-Date=20250414T151306Z&X-Goog-Expires=86399&X-Goog-Signature=0bf0b2bd8b586c4629cadf1b33955ead125425c9929b4db02171f92ae5780d32456d214d433d6d319596799bcbcb937ce5a1f7aee1c48cb9ac1c99a4aa3fc2356f2a3c710a9a6654c05b606b01ca1e97d9eaae6993f275d0c5967cccf57e2fe28f0f5bd4bca6f0f0c63aa5c6ce17990fb8c9f433425f087c76eec8c8916ab0eb376a85e82f84dce56bec266fd96c22c1f9354c90c63719ece160fd1bb61261f79adf64168e7b3c2b680ecc3e6025130fbc86e9885ee5d0cd41b40a6e82022f2115d5b5a683323cee548e6365923416e21c23b9daf0e147f86c6180af83d1df6a3f54eb98d1d885b465d7933177b8fb84b0eb944852291b001a237e586a9d35cf&X-Goog-SignedHeaders=host&X-User=2931823730: HTTPSConnectionPool(host='storage.googleapis.com', port=443): Max retries exceeded with url: /wandb-production.appspot.com/2931823730-harbin-institute-of-technology/ltu-as/sro21n02/wandb-metadata.json?X-Goog-Algorithm=GOOG4-RSA-SHA256&X-Goog-Credential=gorilla-files-url-signer-man%40wandb-production.iam.gserviceaccount.com%2F20250414%2Fauto%2Fstorage%2Fgoog4_request&X-Goog-Date=20250414T151306Z&X-Goog-Expires=86399&X-Goog-Signature=0bf0b2bd8b586c4629cadf1b33955ead125425c9929b4db02171f92ae5780d32456d214d433d6d319596799bcbcb937ce5a1f7aee1c48cb9ac1c99a4aa3fc2356f2a3c710a9a6654c05b606b01ca1e97d9eaae6993f275d0c5967cccf57e2fe28f0f5bd4bca6f0f0c63aa5c6ce17990fb8c9f433425f087c76eec8c8916ab0eb376a85e82f84dce56bec266fd96c22c1f9354c90c63719ece160fd1bb61261f79adf64168e7b3c2b680ecc3e6025130fbc86e9885ee5d0cd41b40a6e82022f2115d5b5a683323cee548e6365923416e21c23b9daf0e147f86c6180af83d1df6a3f54eb98d1d885b465d7933177b8fb84b0eb944852291b001a237e586a9d35cf&X-Goog-SignedHeaders=host&X-User=2931823730 (Caused by NewConnectionError('<urllib3.connection.HTTPSConnection object at 0x7f87003bdc60>: Failed to establish a new connection: [Errno 101] Network is unreachable'))
2025-04-14 15:13:08,156 ERROR   wandb-upload_0:16610 [internal_api.py:upload_file():2558] upload_file request headers: {'User-Agent': 'python-requests/2.32.3', 'Accept-Encoding': 'gzip, deflate, br', 'Accept': '*/*', 'Connection': 'keep-alive', 'Content-Length': '2380'}
2025-04-14 15:13:08,156 ERROR   wandb-upload_0:16610 [internal_api.py:upload_file():2560] upload_file response body: 
2025-04-14 15:13:09,203 INFO    Thread-12 :16610 [dir_watcher.py:_on_file_modified():288] file/dir modified: /root/ltu-main/ltu-main/src/ltu_as/train_scripts/wandb/run-20250414_151140-sro21n02/files/output.log
2025-04-14 15:13:10,647 ERROR   wandb-upload_0:16610 [internal_api.py:upload_file():2556] upload_file exception https://storage.googleapis.com/wandb-production.appspot.com/2931823730-harbin-institute-of-technology/ltu-as/sro21n02/wandb-metadata.json?X-Goog-Algorithm=GOOG4-RSA-SHA256&X-Goog-Credential=gorilla-files-url-signer-man%40wandb-production.iam.gserviceaccount.com%2F20250414%2Fauto%2Fstorage%2Fgoog4_request&X-Goog-Date=20250414T151306Z&X-Goog-Expires=86399&X-Goog-Signature=0bf0b2bd8b586c4629cadf1b33955ead125425c9929b4db02171f92ae5780d32456d214d433d6d319596799bcbcb937ce5a1f7aee1c48cb9ac1c99a4aa3fc2356f2a3c710a9a6654c05b606b01ca1e97d9eaae6993f275d0c5967cccf57e2fe28f0f5bd4bca6f0f0c63aa5c6ce17990fb8c9f433425f087c76eec8c8916ab0eb376a85e82f84dce56bec266fd96c22c1f9354c90c63719ece160fd1bb61261f79adf64168e7b3c2b680ecc3e6025130fbc86e9885ee5d0cd41b40a6e82022f2115d5b5a683323cee548e6365923416e21c23b9daf0e147f86c6180af83d1df6a3f54eb98d1d885b465d7933177b8fb84b0eb944852291b001a237e586a9d35cf&X-Goog-SignedHeaders=host&X-User=2931823730: HTTPSConnectionPool(host='storage.googleapis.com', port=443): Max retries exceeded with url: /wandb-production.appspot.com/2931823730-harbin-institute-of-technology/ltu-as/sro21n02/wandb-metadata.json?X-Goog-Algorithm=GOOG4-RSA-SHA256&X-Goog-Credential=gorilla-files-url-signer-man%40wandb-production.iam.gserviceaccount.com%2F20250414%2Fauto%2Fstorage%2Fgoog4_request&X-Goog-Date=20250414T151306Z&X-Goog-Expires=86399&X-Goog-Signature=0bf0b2bd8b586c4629cadf1b33955ead125425c9929b4db02171f92ae5780d32456d214d433d6d319596799bcbcb937ce5a1f7aee1c48cb9ac1c99a4aa3fc2356f2a3c710a9a6654c05b606b01ca1e97d9eaae6993f275d0c5967cccf57e2fe28f0f5bd4bca6f0f0c63aa5c6ce17990fb8c9f433425f087c76eec8c8916ab0eb376a85e82f84dce56bec266fd96c22c1f9354c90c63719ece160fd1bb61261f79adf64168e7b3c2b680ecc3e6025130fbc86e9885ee5d0cd41b40a6e82022f2115d5b5a683323cee548e6365923416e21c23b9daf0e147f86c6180af83d1df6a3f54eb98d1d885b465d7933177b8fb84b0eb944852291b001a237e586a9d35cf&X-Goog-SignedHeaders=host&X-User=2931823730 (Caused by NewConnectionError('<urllib3.connection.HTTPSConnection object at 0x7f87003bc790>: Failed to establish a new connection: [Errno 101] Network is unreachable'))
2025-04-14 15:13:10,648 ERROR   wandb-upload_0:16610 [internal_api.py:upload_file():2558] upload_file request headers: {'User-Agent': 'python-requests/2.32.3', 'Accept-Encoding': 'gzip, deflate, br', 'Accept': '*/*', 'Connection': 'keep-alive', 'Content-Length': '2380'}
2025-04-14 15:13:10,648 ERROR   wandb-upload_0:16610 [internal_api.py:upload_file():2560] upload_file response body: 
2025-04-14 15:13:10,648 INFO    wandb-upload_0:16610 [retry.py:__call__():172] Retry attempt failed:
Traceback (most recent call last):
  File "/root/anaconda3/envs/venv_ltu/lib/python3.10/site-packages/urllib3/connection.py", line 198, in _new_conn
    sock = connection.create_connection(
  File "/root/anaconda3/envs/venv_ltu/lib/python3.10/site-packages/urllib3/util/connection.py", line 85, in create_connection
    raise err
  File "/root/anaconda3/envs/venv_ltu/lib/python3.10/site-packages/urllib3/util/connection.py", line 73, in create_connection
    sock.connect(sa)
OSError: [Errno 101] Network is unreachable

The above exception was the direct cause of the following exception:

Traceback (most recent call last):
  File "/root/anaconda3/envs/venv_ltu/lib/python3.10/site-packages/urllib3/connectionpool.py", line 793, in urlopen
    response = self._make_request(
  File "/root/anaconda3/envs/venv_ltu/lib/python3.10/site-packages/urllib3/connectionpool.py", line 491, in _make_request
    raise new_e
  File "/root/anaconda3/envs/venv_ltu/lib/python3.10/site-packages/urllib3/connectionpool.py", line 467, in _make_request
    self._validate_conn(conn)
  File "/root/anaconda3/envs/venv_ltu/lib/python3.10/site-packages/urllib3/connectionpool.py", line 1099, in _validate_conn
    conn.connect()
  File "/root/anaconda3/envs/venv_ltu/lib/python3.10/site-packages/urllib3/connection.py", line 616, in connect
    self.sock = sock = self._new_conn()
  File "/root/anaconda3/envs/venv_ltu/lib/python3.10/site-packages/urllib3/connection.py", line 213, in _new_conn
    raise NewConnectionError(
urllib3.exceptions.NewConnectionError: <urllib3.connection.HTTPSConnection object at 0x7f87003bc790>: Failed to establish a new connection: [Errno 101] Network is unreachable

The above exception was the direct cause of the following exception:

Traceback (most recent call last):
  File "/root/anaconda3/envs/venv_ltu/lib/python3.10/site-packages/requests/adapters.py", line 667, in send
    resp = conn.urlopen(
  File "/root/anaconda3/envs/venv_ltu/lib/python3.10/site-packages/urllib3/connectionpool.py", line 847, in urlopen
    retries = retries.increment(
  File "/root/anaconda3/envs/venv_ltu/lib/python3.10/site-packages/urllib3/util/retry.py", line 515, in increment
    raise MaxRetryError(_pool, url, reason) from reason  # type: ignore[arg-type]
urllib3.exceptions.MaxRetryError: HTTPSConnectionPool(host='storage.googleapis.com', port=443): Max retries exceeded with url: /wandb-production.appspot.com/2931823730-harbin-institute-of-technology/ltu-as/sro21n02/wandb-metadata.json?X-Goog-Algorithm=GOOG4-RSA-SHA256&X-Goog-Credential=gorilla-files-url-signer-man%40wandb-production.iam.gserviceaccount.com%2F20250414%2Fauto%2Fstorage%2Fgoog4_request&X-Goog-Date=20250414T151306Z&X-Goog-Expires=86399&X-Goog-Signature=0bf0b2bd8b586c4629cadf1b33955ead125425c9929b4db02171f92ae5780d32456d214d433d6d319596799bcbcb937ce5a1f7aee1c48cb9ac1c99a4aa3fc2356f2a3c710a9a6654c05b606b01ca1e97d9eaae6993f275d0c5967cccf57e2fe28f0f5bd4bca6f0f0c63aa5c6ce17990fb8c9f433425f087c76eec8c8916ab0eb376a85e82f84dce56bec266fd96c22c1f9354c90c63719ece160fd1bb61261f79adf64168e7b3c2b680ecc3e6025130fbc86e9885ee5d0cd41b40a6e82022f2115d5b5a683323cee548e6365923416e21c23b9daf0e147f86c6180af83d1df6a3f54eb98d1d885b465d7933177b8fb84b0eb944852291b001a237e586a9d35cf&X-Goog-SignedHeaders=host&X-User=2931823730 (Caused by NewConnectionError('<urllib3.connection.HTTPSConnection object at 0x7f87003bc790>: Failed to establish a new connection: [Errno 101] Network is unreachable'))

During handling of the above exception, another exception occurred:

Traceback (most recent call last):
  File "/root/anaconda3/envs/venv_ltu/lib/python3.10/site-packages/wandb/sdk/internal/internal_api.py", line 2549, in upload_file
    response = self._upload_file_session.put(
  File "/root/anaconda3/envs/venv_ltu/lib/python3.10/site-packages/requests/sessions.py", line 649, in put
    return self.request("PUT", url, data=data, **kwargs)
  File "/root/anaconda3/envs/venv_ltu/lib/python3.10/site-packages/requests/sessions.py", line 589, in request
    resp = self.send(prep, **send_kwargs)
  File "/root/anaconda3/envs/venv_ltu/lib/python3.10/site-packages/requests/sessions.py", line 703, in send
    r = adapter.send(request, **kwargs)
  File "/root/anaconda3/envs/venv_ltu/lib/python3.10/site-packages/requests/adapters.py", line 700, in send
    raise ConnectionError(e, request=request)
requests.exceptions.ConnectionError: HTTPSConnectionPool(host='storage.googleapis.com', port=443): Max retries exceeded with url: /wandb-production.appspot.com/2931823730-harbin-institute-of-technology/ltu-as/sro21n02/wandb-metadata.json?X-Goog-Algorithm=GOOG4-RSA-SHA256&X-Goog-Credential=gorilla-files-url-signer-man%40wandb-production.iam.gserviceaccount.com%2F20250414%2Fauto%2Fstorage%2Fgoog4_request&X-Goog-Date=20250414T151306Z&X-Goog-Expires=86399&X-Goog-Signature=0bf0b2bd8b586c4629cadf1b33955ead125425c9929b4db02171f92ae5780d32456d214d433d6d319596799bcbcb937ce5a1f7aee1c48cb9ac1c99a4aa3fc2356f2a3c710a9a6654c05b606b01ca1e97d9eaae6993f275d0c5967cccf57e2fe28f0f5bd4bca6f0f0c63aa5c6ce17990fb8c9f433425f087c76eec8c8916ab0eb376a85e82f84dce56bec266fd96c22c1f9354c90c63719ece160fd1bb61261f79adf64168e7b3c2b680ecc3e6025130fbc86e9885ee5d0cd41b40a6e82022f2115d5b5a683323cee548e6365923416e21c23b9daf0e147f86c6180af83d1df6a3f54eb98d1d885b465d7933177b8fb84b0eb944852291b001a237e586a9d35cf&X-Goog-SignedHeaders=host&X-User=2931823730 (Caused by NewConnectionError('<urllib3.connection.HTTPSConnection object at 0x7f87003bc790>: Failed to establish a new connection: [Errno 101] Network is unreachable'))

During handling of the above exception, another exception occurred:

Traceback (most recent call last):
  File "/root/anaconda3/envs/venv_ltu/lib/python3.10/site-packages/wandb/sdk/lib/retry.py", line 131, in __call__
    result = self._call_fn(*args, **kwargs)
  File "/root/anaconda3/envs/venv_ltu/lib/python3.10/site-packages/wandb/sdk/internal/internal_api.py", line 2580, in upload_file
    raise _e.with_traceback(sys.exc_info()[2])
  File "/root/anaconda3/envs/venv_ltu/lib/python3.10/site-packages/wandb/sdk/internal/internal_api.py", line 2549, in upload_file
    response = self._upload_file_session.put(
  File "/root/anaconda3/envs/venv_ltu/lib/python3.10/site-packages/requests/sessions.py", line 649, in put
    return self.request("PUT", url, data=data, **kwargs)
  File "/root/anaconda3/envs/venv_ltu/lib/python3.10/site-packages/requests/sessions.py", line 589, in request
    resp = self.send(prep, **send_kwargs)
  File "/root/anaconda3/envs/venv_ltu/lib/python3.10/site-packages/requests/sessions.py", line 703, in send
    r = adapter.send(request, **kwargs)
  File "/root/anaconda3/envs/venv_ltu/lib/python3.10/site-packages/requests/adapters.py", line 700, in send
    raise ConnectionError(e, request=request)
wandb.sdk.lib.retry.TransientError: None
2025-04-14 15:13:11,466 DEBUG   HandlerThread:16610 [handler.py:handle_request():146] handle_request: status_report
2025-04-14 15:13:11,835 DEBUG   HandlerThread:16610 [handler.py:handle_request():146] handle_request: keepalive
2025-04-14 15:13:11,870 DEBUG   SenderThread:16610 [sender.py:send():380] send: stats
2025-04-14 15:13:12,204 INFO    Thread-12 :16610 [dir_watcher.py:_on_file_modified():288] file/dir modified: /root/ltu-main/ltu-main/src/ltu_as/train_scripts/wandb/run-20250414_151140-sro21n02/files/config.yaml
2025-04-14 15:13:15,302 ERROR   wandb-upload_0:16610 [internal_api.py:upload_file():2556] upload_file exception https://storage.googleapis.com/wandb-production.appspot.com/2931823730-harbin-institute-of-technology/ltu-as/sro21n02/wandb-metadata.json?X-Goog-Algorithm=GOOG4-RSA-SHA256&X-Goog-Credential=gorilla-files-url-signer-man%40wandb-production.iam.gserviceaccount.com%2F20250414%2Fauto%2Fstorage%2Fgoog4_request&X-Goog-Date=20250414T151306Z&X-Goog-Expires=86399&X-Goog-Signature=0bf0b2bd8b586c4629cadf1b33955ead125425c9929b4db02171f92ae5780d32456d214d433d6d319596799bcbcb937ce5a1f7aee1c48cb9ac1c99a4aa3fc2356f2a3c710a9a6654c05b606b01ca1e97d9eaae6993f275d0c5967cccf57e2fe28f0f5bd4bca6f0f0c63aa5c6ce17990fb8c9f433425f087c76eec8c8916ab0eb376a85e82f84dce56bec266fd96c22c1f9354c90c63719ece160fd1bb61261f79adf64168e7b3c2b680ecc3e6025130fbc86e9885ee5d0cd41b40a6e82022f2115d5b5a683323cee548e6365923416e21c23b9daf0e147f86c6180af83d1df6a3f54eb98d1d885b465d7933177b8fb84b0eb944852291b001a237e586a9d35cf&X-Goog-SignedHeaders=host&X-User=2931823730: HTTPSConnectionPool(host='storage.googleapis.com', port=443): Max retries exceeded with url: /wandb-production.appspot.com/2931823730-harbin-institute-of-technology/ltu-as/sro21n02/wandb-metadata.json?X-Goog-Algorithm=GOOG4-RSA-SHA256&X-Goog-Credential=gorilla-files-url-signer-man%40wandb-production.iam.gserviceaccount.com%2F20250414%2Fauto%2Fstorage%2Fgoog4_request&X-Goog-Date=20250414T151306Z&X-Goog-Expires=86399&X-Goog-Signature=0bf0b2bd8b586c4629cadf1b33955ead125425c9929b4db02171f92ae5780d32456d214d433d6d319596799bcbcb937ce5a1f7aee1c48cb9ac1c99a4aa3fc2356f2a3c710a9a6654c05b606b01ca1e97d9eaae6993f275d0c5967cccf57e2fe28f0f5bd4bca6f0f0c63aa5c6ce17990fb8c9f433425f087c76eec8c8916ab0eb376a85e82f84dce56bec266fd96c22c1f9354c90c63719ece160fd1bb61261f79adf64168e7b3c2b680ecc3e6025130fbc86e9885ee5d0cd41b40a6e82022f2115d5b5a683323cee548e6365923416e21c23b9daf0e147f86c6180af83d1df6a3f54eb98d1d885b465d7933177b8fb84b0eb944852291b001a237e586a9d35cf&X-Goog-SignedHeaders=host&X-User=2931823730 (Caused by NewConnectionError('<urllib3.connection.HTTPSConnection object at 0x7f87003beda0>: Failed to establish a new connection: [Errno 101] Network is unreachable'))
2025-04-14 15:13:15,303 ERROR   wandb-upload_0:16610 [internal_api.py:upload_file():2558] upload_file request headers: {'User-Agent': 'python-requests/2.32.3', 'Accept-Encoding': 'gzip, deflate, br', 'Accept': '*/*', 'Connection': 'keep-alive', 'Content-Length': '2380'}
2025-04-14 15:13:15,303 ERROR   wandb-upload_0:16610 [internal_api.py:upload_file():2560] upload_file response body: 
2025-04-14 15:13:16,836 DEBUG   HandlerThread:16610 [handler.py:handle_request():146] handle_request: keepalive
2025-04-14 15:13:16,871 DEBUG   HandlerThread:16610 [handler.py:handle_request():146] handle_request: status_report
2025-04-14 15:13:21,837 DEBUG   HandlerThread:16610 [handler.py:handle_request():146] handle_request: keepalive
2025-04-14 15:13:21,872 DEBUG   HandlerThread:16610 [handler.py:handle_request():146] handle_request: status_report
2025-04-14 15:13:25,134 ERROR   wandb-upload_0:16610 [internal_api.py:upload_file():2556] upload_file exception https://storage.googleapis.com/wandb-production.appspot.com/2931823730-harbin-institute-of-technology/ltu-as/sro21n02/wandb-metadata.json?X-Goog-Algorithm=GOOG4-RSA-SHA256&X-Goog-Credential=gorilla-files-url-signer-man%40wandb-production.iam.gserviceaccount.com%2F20250414%2Fauto%2Fstorage%2Fgoog4_request&X-Goog-Date=20250414T151306Z&X-Goog-Expires=86399&X-Goog-Signature=0bf0b2bd8b586c4629cadf1b33955ead125425c9929b4db02171f92ae5780d32456d214d433d6d319596799bcbcb937ce5a1f7aee1c48cb9ac1c99a4aa3fc2356f2a3c710a9a6654c05b606b01ca1e97d9eaae6993f275d0c5967cccf57e2fe28f0f5bd4bca6f0f0c63aa5c6ce17990fb8c9f433425f087c76eec8c8916ab0eb376a85e82f84dce56bec266fd96c22c1f9354c90c63719ece160fd1bb61261f79adf64168e7b3c2b680ecc3e6025130fbc86e9885ee5d0cd41b40a6e82022f2115d5b5a683323cee548e6365923416e21c23b9daf0e147f86c6180af83d1df6a3f54eb98d1d885b465d7933177b8fb84b0eb944852291b001a237e586a9d35cf&X-Goog-SignedHeaders=host&X-User=2931823730: HTTPSConnectionPool(host='storage.googleapis.com', port=443): Max retries exceeded with url: /wandb-production.appspot.com/2931823730-harbin-institute-of-technology/ltu-as/sro21n02/wandb-metadata.json?X-Goog-Algorithm=GOOG4-RSA-SHA256&X-Goog-Credential=gorilla-files-url-signer-man%40wandb-production.iam.gserviceaccount.com%2F20250414%2Fauto%2Fstorage%2Fgoog4_request&X-Goog-Date=20250414T151306Z&X-Goog-Expires=86399&X-Goog-Signature=0bf0b2bd8b586c4629cadf1b33955ead125425c9929b4db02171f92ae5780d32456d214d433d6d319596799bcbcb937ce5a1f7aee1c48cb9ac1c99a4aa3fc2356f2a3c710a9a6654c05b606b01ca1e97d9eaae6993f275d0c5967cccf57e2fe28f0f5bd4bca6f0f0c63aa5c6ce17990fb8c9f433425f087c76eec8c8916ab0eb376a85e82f84dce56bec266fd96c22c1f9354c90c63719ece160fd1bb61261f79adf64168e7b3c2b680ecc3e6025130fbc86e9885ee5d0cd41b40a6e82022f2115d5b5a683323cee548e6365923416e21c23b9daf0e147f86c6180af83d1df6a3f54eb98d1d885b465d7933177b8fb84b0eb944852291b001a237e586a9d35cf&X-Goog-SignedHeaders=host&X-User=2931823730 (Caused by NewConnectionError('<urllib3.connection.HTTPSConnection object at 0x7f87003be110>: Failed to establish a new connection: [Errno 101] Network is unreachable'))
2025-04-14 15:13:25,134 ERROR   wandb-upload_0:16610 [internal_api.py:upload_file():2558] upload_file request headers: {'User-Agent': 'python-requests/2.32.3', 'Accept-Encoding': 'gzip, deflate, br', 'Accept': '*/*', 'Connection': 'keep-alive', 'Content-Length': '2380'}
2025-04-14 15:13:25,134 ERROR   wandb-upload_0:16610 [internal_api.py:upload_file():2560] upload_file response body: 
2025-04-14 15:13:26,840 DEBUG   HandlerThread:16610 [handler.py:handle_request():146] handle_request: keepalive
2025-04-14 15:13:26,878 DEBUG   HandlerThread:16610 [handler.py:handle_request():146] handle_request: status_report
2025-04-14 15:13:31,393 DEBUG   SenderThread:16610 [sender.py:send():380] send: exit
2025-04-14 15:13:31,393 INFO    SenderThread:16610 [sender.py:send_exit():585] handling exit code: 255
2025-04-14 15:13:31,393 INFO    SenderThread:16610 [sender.py:send_exit():587] handling runtime: 109
2025-04-14 15:13:31,394 INFO    SenderThread:16610 [sender.py:_save_file():1378] saving file wandb-summary.json with policy end
2025-04-14 15:13:31,394 INFO    SenderThread:16610 [sender.py:send_exit():593] send defer
2025-04-14 15:13:31,394 DEBUG   HandlerThread:16610 [handler.py:handle_request():146] handle_request: defer
2025-04-14 15:13:31,394 INFO    HandlerThread:16610 [handler.py:handle_request_defer():172] handle defer: 0
2025-04-14 15:13:31,395 DEBUG   SenderThread:16610 [sender.py:send_request():407] send_request: defer
2025-04-14 15:13:31,395 INFO    SenderThread:16610 [sender.py:send_request_defer():609] handle sender defer: 0
2025-04-14 15:13:31,395 INFO    SenderThread:16610 [sender.py:transition_state():613] send defer: 1
2025-04-14 15:13:31,395 DEBUG   HandlerThread:16610 [handler.py:handle_request():146] handle_request: defer
2025-04-14 15:13:31,395 INFO    HandlerThread:16610 [handler.py:handle_request_defer():172] handle defer: 1
2025-04-14 15:13:31,395 DEBUG   SenderThread:16610 [sender.py:send_request():407] send_request: defer
2025-04-14 15:13:31,395 INFO    SenderThread:16610 [sender.py:send_request_defer():609] handle sender defer: 1
2025-04-14 15:13:31,395 INFO    SenderThread:16610 [sender.py:transition_state():613] send defer: 2
2025-04-14 15:13:31,395 DEBUG   HandlerThread:16610 [handler.py:handle_request():146] handle_request: defer
2025-04-14 15:13:31,395 INFO    HandlerThread:16610 [handler.py:handle_request_defer():172] handle defer: 2
2025-04-14 15:13:31,395 INFO    HandlerThread:16610 [system_monitor.py:finish():203] Stopping system monitor
2025-04-14 15:13:31,396 INFO    HandlerThread:16610 [interfaces.py:finish():202] Joined cpu monitor
2025-04-14 15:13:31,396 DEBUG   SystemMonitor:16610 [system_monitor.py:_start():179] Finished system metrics aggregation loop
2025-04-14 15:13:31,396 DEBUG   SystemMonitor:16610 [system_monitor.py:_start():183] Publishing last batch of metrics
2025-04-14 15:13:31,397 INFO    HandlerThread:16610 [interfaces.py:finish():202] Joined disk monitor
2025-04-14 15:13:31,440 INFO    HandlerThread:16610 [interfaces.py:finish():202] Joined gpu monitor
2025-04-14 15:13:31,440 INFO    HandlerThread:16610 [interfaces.py:finish():202] Joined memory monitor
2025-04-14 15:13:31,440 INFO    HandlerThread:16610 [interfaces.py:finish():202] Joined network monitor
2025-04-14 15:13:31,441 DEBUG   SenderThread:16610 [sender.py:send_request():407] send_request: defer
2025-04-14 15:13:31,441 INFO    SenderThread:16610 [sender.py:send_request_defer():609] handle sender defer: 2
2025-04-14 15:13:31,441 INFO    SenderThread:16610 [sender.py:transition_state():613] send defer: 3
2025-04-14 15:13:31,442 DEBUG   SenderThread:16610 [sender.py:send():380] send: stats
2025-04-14 15:13:31,442 DEBUG   HandlerThread:16610 [handler.py:handle_request():146] handle_request: defer
2025-04-14 15:13:31,443 INFO    HandlerThread:16610 [handler.py:handle_request_defer():172] handle defer: 3
2025-04-14 15:13:31,443 DEBUG   SenderThread:16610 [sender.py:send_request():407] send_request: defer
2025-04-14 15:13:31,443 INFO    SenderThread:16610 [sender.py:send_request_defer():609] handle sender defer: 3
2025-04-14 15:13:31,443 INFO    SenderThread:16610 [sender.py:transition_state():613] send defer: 4
2025-04-14 15:13:31,444 DEBUG   HandlerThread:16610 [handler.py:handle_request():146] handle_request: defer
2025-04-14 15:13:31,444 INFO    HandlerThread:16610 [handler.py:handle_request_defer():172] handle defer: 4
2025-04-14 15:13:31,444 DEBUG   SenderThread:16610 [sender.py:send_request():407] send_request: defer
2025-04-14 15:13:31,444 INFO    SenderThread:16610 [sender.py:send_request_defer():609] handle sender defer: 4
2025-04-14 15:13:31,444 INFO    SenderThread:16610 [sender.py:transition_state():613] send defer: 5
2025-04-14 15:13:31,444 DEBUG   HandlerThread:16610 [handler.py:handle_request():146] handle_request: defer
2025-04-14 15:13:31,445 INFO    HandlerThread:16610 [handler.py:handle_request_defer():172] handle defer: 5
2025-04-14 15:13:31,445 DEBUG   SenderThread:16610 [sender.py:send():380] send: summary
2025-04-14 15:13:31,526 INFO    SenderThread:16610 [sender.py:_save_file():1378] saving file wandb-summary.json with policy end
2025-04-14 15:13:31,526 DEBUG   SenderThread:16610 [sender.py:send_request():407] send_request: defer
2025-04-14 15:13:31,526 INFO    SenderThread:16610 [sender.py:send_request_defer():609] handle sender defer: 5
2025-04-14 15:13:31,526 INFO    SenderThread:16610 [sender.py:transition_state():613] send defer: 6
2025-04-14 15:13:31,526 DEBUG   HandlerThread:16610 [handler.py:handle_request():146] handle_request: defer
2025-04-14 15:13:31,527 INFO    HandlerThread:16610 [handler.py:handle_request_defer():172] handle defer: 6
2025-04-14 15:13:31,527 DEBUG   SenderThread:16610 [sender.py:send_request():407] send_request: defer
2025-04-14 15:13:31,527 INFO    SenderThread:16610 [sender.py:send_request_defer():609] handle sender defer: 6
2025-04-14 15:13:31,527 INFO    SenderThread:16610 [sender.py:transition_state():613] send defer: 7
2025-04-14 15:13:31,527 DEBUG   HandlerThread:16610 [handler.py:handle_request():146] handle_request: status_report
2025-04-14 15:13:31,528 DEBUG   HandlerThread:16610 [handler.py:handle_request():146] handle_request: defer
2025-04-14 15:13:31,528 INFO    HandlerThread:16610 [handler.py:handle_request_defer():172] handle defer: 7
2025-04-14 15:13:31,528 DEBUG   SenderThread:16610 [sender.py:send_request():407] send_request: defer
2025-04-14 15:13:31,528 INFO    SenderThread:16610 [sender.py:send_request_defer():609] handle sender defer: 7
2025-04-14 15:13:32,211 INFO    Thread-12 :16610 [dir_watcher.py:_on_file_created():271] file/dir created: /root/ltu-main/ltu-main/src/ltu_as/train_scripts/wandb/run-20250414_151140-sro21n02/files/wandb-summary.json
2025-04-14 15:13:32,391 DEBUG   HandlerThread:16610 [handler.py:handle_request():146] handle_request: poll_exit
2025-04-14 15:13:32,495 INFO    SenderThread:16610 [sender.py:transition_state():613] send defer: 8
2025-04-14 15:13:32,496 DEBUG   SenderThread:16610 [sender.py:send_request():407] send_request: poll_exit
2025-04-14 15:13:32,496 DEBUG   HandlerThread:16610 [handler.py:handle_request():146] handle_request: defer
2025-04-14 15:13:32,496 INFO    HandlerThread:16610 [handler.py:handle_request_defer():172] handle defer: 8
2025-04-14 15:13:32,497 DEBUG   SenderThread:16610 [sender.py:send_request():407] send_request: defer
2025-04-14 15:13:32,497 INFO    SenderThread:16610 [sender.py:send_request_defer():609] handle sender defer: 8
2025-04-14 15:13:32,497 INFO    SenderThread:16610 [job_builder.py:build():281] Attempting to build job artifact
2025-04-14 15:13:32,498 INFO    SenderThread:16610 [job_builder.py:_get_source_type():404] no source found
2025-04-14 15:13:32,498 INFO    SenderThread:16610 [sender.py:transition_state():613] send defer: 9
2025-04-14 15:13:32,498 DEBUG   HandlerThread:16610 [handler.py:handle_request():146] handle_request: defer
2025-04-14 15:13:32,498 INFO    HandlerThread:16610 [handler.py:handle_request_defer():172] handle defer: 9
2025-04-14 15:13:32,498 DEBUG   SenderThread:16610 [sender.py:send_request():407] send_request: defer
2025-04-14 15:13:32,498 INFO    SenderThread:16610 [sender.py:send_request_defer():609] handle sender defer: 9
2025-04-14 15:13:32,498 INFO    SenderThread:16610 [dir_watcher.py:finish():358] shutting down directory watcher
2025-04-14 15:13:33,212 INFO    Thread-12 :16610 [dir_watcher.py:_on_file_modified():288] file/dir modified: /root/ltu-main/ltu-main/src/ltu_as/train_scripts/wandb/run-20250414_151140-sro21n02/files/output.log
2025-04-14 15:13:33,213 INFO    SenderThread:16610 [dir_watcher.py:finish():388] scan: /root/ltu-main/ltu-main/src/ltu_as/train_scripts/wandb/run-20250414_151140-sro21n02/files
2025-04-14 15:13:33,213 INFO    SenderThread:16610 [dir_watcher.py:finish():402] scan save: /root/ltu-main/ltu-main/src/ltu_as/train_scripts/wandb/run-20250414_151140-sro21n02/files/config.yaml config.yaml
2025-04-14 15:13:33,214 INFO    SenderThread:16610 [dir_watcher.py:finish():402] scan save: /root/ltu-main/ltu-main/src/ltu_as/train_scripts/wandb/run-20250414_151140-sro21n02/files/requirements.txt requirements.txt
2025-04-14 15:13:33,219 INFO    SenderThread:16610 [dir_watcher.py:finish():402] scan save: /root/ltu-main/ltu-main/src/ltu_as/train_scripts/wandb/run-20250414_151140-sro21n02/files/conda-environment.yaml conda-environment.yaml
2025-04-14 15:13:33,220 INFO    SenderThread:16610 [dir_watcher.py:finish():402] scan save: /root/ltu-main/ltu-main/src/ltu_as/train_scripts/wandb/run-20250414_151140-sro21n02/files/wandb-metadata.json wandb-metadata.json
2025-04-14 15:13:33,220 INFO    SenderThread:16610 [dir_watcher.py:finish():402] scan save: /root/ltu-main/ltu-main/src/ltu_as/train_scripts/wandb/run-20250414_151140-sro21n02/files/output.log output.log
2025-04-14 15:13:33,220 INFO    SenderThread:16610 [dir_watcher.py:finish():402] scan save: /root/ltu-main/ltu-main/src/ltu_as/train_scripts/wandb/run-20250414_151140-sro21n02/files/wandb-summary.json wandb-summary.json
2025-04-14 15:13:33,227 INFO    SenderThread:16610 [sender.py:transition_state():613] send defer: 10
2025-04-14 15:13:33,228 DEBUG   HandlerThread:16610 [handler.py:handle_request():146] handle_request: defer
2025-04-14 15:13:33,228 INFO    HandlerThread:16610 [handler.py:handle_request_defer():172] handle defer: 10
2025-04-14 15:13:33,228 DEBUG   SenderThread:16610 [sender.py:send_request():407] send_request: defer
2025-04-14 15:13:33,228 INFO    SenderThread:16610 [sender.py:send_request_defer():609] handle sender defer: 10
2025-04-14 15:13:33,228 INFO    SenderThread:16610 [file_pusher.py:finish():175] shutting down file pusher
2025-04-14 15:13:33,392 DEBUG   HandlerThread:16610 [handler.py:handle_request():146] handle_request: poll_exit
2025-04-14 15:13:33,393 DEBUG   SenderThread:16610 [sender.py:send_request():407] send_request: poll_exit
2025-04-14 15:13:33,491 ERROR   wandb-upload_1:16610 [internal_api.py:upload_file():2556] upload_file exception https://storage.googleapis.com/wandb-production.appspot.com/2931823730-harbin-institute-of-technology/ltu-as/sro21n02/config.yaml?X-Goog-Algorithm=GOOG4-RSA-SHA256&X-Goog-Credential=gorilla-files-url-signer-man%40wandb-production.iam.gserviceaccount.com%2F20250414%2Fauto%2Fstorage%2Fgoog4_request&X-Goog-Date=20250414T151333Z&X-Goog-Expires=86399&X-Goog-Signature=2f73e93adaa04407e79c1d548385c55943fdf3db36963bfdf350643aa1b36dae813f5626aaaa750a4bede213fdbf01567d7849c255d958ccd82bb15aae31926ef2cb8142328b26778f2203ecbf35a11e72c8b6968ecfdc910d13ecb0d1c8203f98f95824cddf7c77c6d98174c1a272e56c9fee7836d9b384f88d0e5366792f80e0ac49470f62e30e729583e849f555474ab8021dfebe960bf62ab5c74c8a5de192142c1278ce895934f2e559a74830fc98bbe1048f7b1480b81d89ce5d5da5e4ead191f9e8785bf30c7c829de0a9685a99a16ca07c58d7690c12c5d4c96a20f270453ab953c96813cc31dfe1cb8ad8af66ef18162ab0b43a8eda9c5df2be20e9&X-Goog-SignedHeaders=host&X-User=2931823730: HTTPSConnectionPool(host='storage.googleapis.com', port=443): Max retries exceeded with url: /wandb-production.appspot.com/2931823730-harbin-institute-of-technology/ltu-as/sro21n02/config.yaml?X-Goog-Algorithm=GOOG4-RSA-SHA256&X-Goog-Credential=gorilla-files-url-signer-man%40wandb-production.iam.gserviceaccount.com%2F20250414%2Fauto%2Fstorage%2Fgoog4_request&X-Goog-Date=20250414T151333Z&X-Goog-Expires=86399&X-Goog-Signature=2f73e93adaa04407e79c1d548385c55943fdf3db36963bfdf350643aa1b36dae813f5626aaaa750a4bede213fdbf01567d7849c255d958ccd82bb15aae31926ef2cb8142328b26778f2203ecbf35a11e72c8b6968ecfdc910d13ecb0d1c8203f98f95824cddf7c77c6d98174c1a272e56c9fee7836d9b384f88d0e5366792f80e0ac49470f62e30e729583e849f555474ab8021dfebe960bf62ab5c74c8a5de192142c1278ce895934f2e559a74830fc98bbe1048f7b1480b81d89ce5d5da5e4ead191f9e8785bf30c7c829de0a9685a99a16ca07c58d7690c12c5d4c96a20f270453ab953c96813cc31dfe1cb8ad8af66ef18162ab0b43a8eda9c5df2be20e9&X-Goog-SignedHeaders=host&X-User=2931823730 (Caused by NewConnectionError('<urllib3.connection.HTTPSConnection object at 0x7f87003bcc40>: Failed to establish a new connection: [Errno 101] Network is unreachable'))
2025-04-14 15:13:33,491 ERROR   wandb-upload_1:16610 [internal_api.py:upload_file():2558] upload_file request headers: {'User-Agent': 'python-requests/2.32.3', 'Accept-Encoding': 'gzip, deflate, br', 'Accept': '*/*', 'Connection': 'keep-alive', 'Content-Length': '8685'}
2025-04-14 15:13:33,491 ERROR   wandb-upload_1:16610 [internal_api.py:upload_file():2560] upload_file response body: 
2025-04-14 15:13:33,669 ERROR   wandb-upload_4:16610 [internal_api.py:upload_file():2556] upload_file exception https://storage.googleapis.com/wandb-production.appspot.com/2931823730-harbin-institute-of-technology/ltu-as/sro21n02/output.log?X-Goog-Algorithm=GOOG4-RSA-SHA256&X-Goog-Credential=gorilla-files-url-signer-man%40wandb-production.iam.gserviceaccount.com%2F20250414%2Fauto%2Fstorage%2Fgoog4_request&X-Goog-Date=20250414T151333Z&X-Goog-Expires=86399&X-Goog-Signature=c1b3d7a13962ac49c7c2542d07fc489216f963e1200f55034b20dcf718bfadea225d00f606037301d3163d0bcc6c723ac40ba61e901e43e0c2b4affc0cf59d8d0e87c42a048461dfb388bee91715da165b7d56016980b76e11e57db92a471bec391c0ce0681ed11eb937b2400195fa49b7e00e37551763edd99ecc1683df8aed7f765f565688bf99dcdbfaa26f25bb16cb58d2cad4e1dc46b0214559475d19c210a94c0e623f1e9b7363b55a7b2ee7730ac02de63bcd07075d4d1cf12cc2d74be322f92ff01972c74aea148c7f4e2ecd2e53d3ed5ca31db45eb0fb37c10edd7cdc41c02049ec2c67dfe9acb64b40903a5a22d0e059999942328737c2397a7dbf&X-Goog-SignedHeaders=host&X-User=2931823730: HTTPSConnectionPool(host='storage.googleapis.com', port=443): Max retries exceeded with url: /wandb-production.appspot.com/2931823730-harbin-institute-of-technology/ltu-as/sro21n02/output.log?X-Goog-Algorithm=GOOG4-RSA-SHA256&X-Goog-Credential=gorilla-files-url-signer-man%40wandb-production.iam.gserviceaccount.com%2F20250414%2Fauto%2Fstorage%2Fgoog4_request&X-Goog-Date=20250414T151333Z&X-Goog-Expires=86399&X-Goog-Signature=c1b3d7a13962ac49c7c2542d07fc489216f963e1200f55034b20dcf718bfadea225d00f606037301d3163d0bcc6c723ac40ba61e901e43e0c2b4affc0cf59d8d0e87c42a048461dfb388bee91715da165b7d56016980b76e11e57db92a471bec391c0ce0681ed11eb937b2400195fa49b7e00e37551763edd99ecc1683df8aed7f765f565688bf99dcdbfaa26f25bb16cb58d2cad4e1dc46b0214559475d19c210a94c0e623f1e9b7363b55a7b2ee7730ac02de63bcd07075d4d1cf12cc2d74be322f92ff01972c74aea148c7f4e2ecd2e53d3ed5ca31db45eb0fb37c10edd7cdc41c02049ec2c67dfe9acb64b40903a5a22d0e059999942328737c2397a7dbf&X-Goog-SignedHeaders=host&X-User=2931823730 (Caused by NewConnectionError('<urllib3.connection.HTTPSConnection object at 0x7f87003be980>: Failed to establish a new connection: [Errno 101] Network is unreachable'))
2025-04-14 15:13:33,669 ERROR   wandb-upload_4:16610 [internal_api.py:upload_file():2558] upload_file request headers: {'User-Agent': 'python-requests/2.32.3', 'Accept-Encoding': 'gzip, deflate, br', 'Accept': '*/*', 'Connection': 'keep-alive', 'Content-Length': '4916'}
2025-04-14 15:13:33,669 ERROR   wandb-upload_4:16610 [internal_api.py:upload_file():2560] upload_file response body: 
2025-04-14 15:13:33,671 ERROR   wandb-upload_2:16610 [internal_api.py:upload_file():2556] upload_file exception https://storage.googleapis.com/wandb-production.appspot.com/2931823730-harbin-institute-of-technology/ltu-as/sro21n02/requirements.txt?X-Goog-Algorithm=GOOG4-RSA-SHA256&X-Goog-Credential=gorilla-files-url-signer-man%40wandb-production.iam.gserviceaccount.com%2F20250414%2Fauto%2Fstorage%2Fgoog4_request&X-Goog-Date=20250414T151333Z&X-Goog-Expires=86399&X-Goog-Signature=b68928fa0e2b525ca9c2a4d65e8ea36df3dbec3ea8e07a9b57488ed89a18368728d569f35fd3a3b6ca9d006c8392e823f6d6fbef9acdedfdfbdea9dad501ddc1b68a8c3da4ef9a3d38b5151d52891b7d34e027965272f5738f0c9424f5f56686d85cd3224ecb738c6004f884ec680ea391556784a77a9635964958cca0550fb2964a9d249f9592c4612a80c37dacfa24de7da22cb81cc60580456b322e673c980e695f58ed8f8ec247a7076cd46757b6ed864432d0b7a8ebfe3798a4d4748a28cc0c109743ab0cc91f1b3aec691745a5a876dd34d6743fa8b507c86f6f5f6c4e2a5436c6a2e552806d88cd2cd6c69fae0fb8beb7a580df5fa7b602788538d255&X-Goog-SignedHeaders=host&X-User=2931823730: HTTPSConnectionPool(host='storage.googleapis.com', port=443): Max retries exceeded with url: /wandb-production.appspot.com/2931823730-harbin-institute-of-technology/ltu-as/sro21n02/requirements.txt?X-Goog-Algorithm=GOOG4-RSA-SHA256&X-Goog-Credential=gorilla-files-url-signer-man%40wandb-production.iam.gserviceaccount.com%2F20250414%2Fauto%2Fstorage%2Fgoog4_request&X-Goog-Date=20250414T151333Z&X-Goog-Expires=86399&X-Goog-Signature=b68928fa0e2b525ca9c2a4d65e8ea36df3dbec3ea8e07a9b57488ed89a18368728d569f35fd3a3b6ca9d006c8392e823f6d6fbef9acdedfdfbdea9dad501ddc1b68a8c3da4ef9a3d38b5151d52891b7d34e027965272f5738f0c9424f5f56686d85cd3224ecb738c6004f884ec680ea391556784a77a9635964958cca0550fb2964a9d249f9592c4612a80c37dacfa24de7da22cb81cc60580456b322e673c980e695f58ed8f8ec247a7076cd46757b6ed864432d0b7a8ebfe3798a4d4748a28cc0c109743ab0cc91f1b3aec691745a5a876dd34d6743fa8b507c86f6f5f6c4e2a5436c6a2e552806d88cd2cd6c69fae0fb8beb7a580df5fa7b602788538d255&X-Goog-SignedHeaders=host&X-User=2931823730 (Caused by NewConnectionError('<urllib3.connection.HTTPSConnection object at 0x7f87003bcac0>: Failed to establish a new connection: [Errno 101] Network is unreachable'))
2025-04-14 15:13:33,671 ERROR   wandb-upload_2:16610 [internal_api.py:upload_file():2558] upload_file request headers: {'User-Agent': 'python-requests/2.32.3', 'Accept-Encoding': 'gzip, deflate, br', 'Accept': '*/*', 'Connection': 'keep-alive', 'Content-Length': '5836'}
2025-04-14 15:13:33,671 ERROR   wandb-upload_2:16610 [internal_api.py:upload_file():2560] upload_file response body: 
2025-04-14 15:13:33,672 ERROR   wandb-upload_5:16610 [internal_api.py:upload_file():2556] upload_file exception https://storage.googleapis.com/wandb-production.appspot.com/2931823730-harbin-institute-of-technology/ltu-as/sro21n02/wandb-summary.json?X-Goog-Algorithm=GOOG4-RSA-SHA256&X-Goog-Credential=gorilla-files-url-signer-man%40wandb-production.iam.gserviceaccount.com%2F20250414%2Fauto%2Fstorage%2Fgoog4_request&X-Goog-Date=20250414T151333Z&X-Goog-Expires=86399&X-Goog-Signature=1c62f3b6170db7b48818210bba95fa79cd7f43ca58b6649b0428570d3e8fcd4ca90cf9b087445b3c029a3a5140f42e4d052866f04bd68d93eb3ee96043ef83b1d04c735088f00ff00499677a95cd84c38a034bc58f50f0e30e8b710c7d003d84d488f7ad190ad01237f37aad21878dd5cafe07a27bcac5fb00a0c4ede0be7f9673e8d79381fa2ee8915ffddb163c4c3cefd67b96d065f83bf0d938fd38a763c3d75406bc83901267d8e75a5585d8862a7c7d68ab04ad3b9427824ed9f88ceee45e62757cdc63f7a87cf0e9ac9acb56705639c1d06018727ff251278bfcf3e68f5cdc69b06df7b41f6e080f2353f45a3e19e1da994c54be7bb021e8118023095f&X-Goog-SignedHeaders=host&X-User=2931823730: HTTPSConnectionPool(host='storage.googleapis.com', port=443): Max retries exceeded with url: /wandb-production.appspot.com/2931823730-harbin-institute-of-technology/ltu-as/sro21n02/wandb-summary.json?X-Goog-Algorithm=GOOG4-RSA-SHA256&X-Goog-Credential=gorilla-files-url-signer-man%40wandb-production.iam.gserviceaccount.com%2F20250414%2Fauto%2Fstorage%2Fgoog4_request&X-Goog-Date=20250414T151333Z&X-Goog-Expires=86399&X-Goog-Signature=1c62f3b6170db7b48818210bba95fa79cd7f43ca58b6649b0428570d3e8fcd4ca90cf9b087445b3c029a3a5140f42e4d052866f04bd68d93eb3ee96043ef83b1d04c735088f00ff00499677a95cd84c38a034bc58f50f0e30e8b710c7d003d84d488f7ad190ad01237f37aad21878dd5cafe07a27bcac5fb00a0c4ede0be7f9673e8d79381fa2ee8915ffddb163c4c3cefd67b96d065f83bf0d938fd38a763c3d75406bc83901267d8e75a5585d8862a7c7d68ab04ad3b9427824ed9f88ceee45e62757cdc63f7a87cf0e9ac9acb56705639c1d06018727ff251278bfcf3e68f5cdc69b06df7b41f6e080f2353f45a3e19e1da994c54be7bb021e8118023095f&X-Goog-SignedHeaders=host&X-User=2931823730 (Caused by NewConnectionError('<urllib3.connection.HTTPSConnection object at 0x7f8700354fa0>: Failed to establish a new connection: [Errno 101] Network is unreachable'))
2025-04-14 15:13:33,672 ERROR   wandb-upload_5:16610 [internal_api.py:upload_file():2558] upload_file request headers: {'User-Agent': 'python-requests/2.32.3', 'Accept-Encoding': 'gzip, deflate, br', 'Accept': '*/*', 'Connection': 'keep-alive', 'Content-Length': '28'}
2025-04-14 15:13:33,672 ERROR   wandb-upload_5:16610 [internal_api.py:upload_file():2560] upload_file response body: 
2025-04-14 15:13:33,673 ERROR   wandb-upload_3:16610 [internal_api.py:upload_file():2556] upload_file exception https://storage.googleapis.com/wandb-production.appspot.com/2931823730-harbin-institute-of-technology/ltu-as/sro21n02/conda-environment.yaml?X-Goog-Algorithm=GOOG4-RSA-SHA256&X-Goog-Credential=gorilla-files-url-signer-man%40wandb-production.iam.gserviceaccount.com%2F20250414%2Fauto%2Fstorage%2Fgoog4_request&X-Goog-Date=20250414T151333Z&X-Goog-Expires=86399&X-Goog-Signature=8baaa21661194630a1882e9ed7d315c11d50e573164af7eea55e95ea5953fd3753e98b46a842fe08f503515df18f8fec23a1b271a20bb7458c002170e1ebdd8483b5e2add7e3a8be1f646f1e2361148d782932620251502d2a34b98fc93d70437b2f3c1a672cc8883b684e4df9db83cff0b6477537a2c9f56b12f33118f45063e2abeb73a874b52185f0e7b731bb801545fd9d9cdba619ce48938fed831ab0e64f80cb3e5b15e0de3825420374059423d9ff49f5dd49b3f143c76929b5a9acd4e508e6817a9f3d25eb0441ab4f9be1c4523af1abfaf83ba139a7bffef05151b68a34b1f37c4e2fb49eb2e9893dc7553d87dfef018ac0c0995b7e1898f230da7d&X-Goog-SignedHeaders=host&X-User=2931823730: HTTPSConnectionPool(host='storage.googleapis.com', port=443): Max retries exceeded with url: /wandb-production.appspot.com/2931823730-harbin-institute-of-technology/ltu-as/sro21n02/conda-environment.yaml?X-Goog-Algorithm=GOOG4-RSA-SHA256&X-Goog-Credential=gorilla-files-url-signer-man%40wandb-production.iam.gserviceaccount.com%2F20250414%2Fauto%2Fstorage%2Fgoog4_request&X-Goog-Date=20250414T151333Z&X-Goog-Expires=86399&X-Goog-Signature=8baaa21661194630a1882e9ed7d315c11d50e573164af7eea55e95ea5953fd3753e98b46a842fe08f503515df18f8fec23a1b271a20bb7458c002170e1ebdd8483b5e2add7e3a8be1f646f1e2361148d782932620251502d2a34b98fc93d70437b2f3c1a672cc8883b684e4df9db83cff0b6477537a2c9f56b12f33118f45063e2abeb73a874b52185f0e7b731bb801545fd9d9cdba619ce48938fed831ab0e64f80cb3e5b15e0de3825420374059423d9ff49f5dd49b3f143c76929b5a9acd4e508e6817a9f3d25eb0441ab4f9be1c4523af1abfaf83ba139a7bffef05151b68a34b1f37c4e2fb49eb2e9893dc7553d87dfef018ac0c0995b7e1898f230da7d&X-Goog-SignedHeaders=host&X-User=2931823730 (Caused by NewConnectionError('<urllib3.connection.HTTPSConnection object at 0x7f8700354ee0>: Failed to establish a new connection: [Errno 101] Network is unreachable'))
2025-04-14 15:13:33,673 ERROR   wandb-upload_3:16610 [internal_api.py:upload_file():2558] upload_file request headers: {'User-Agent': 'python-requests/2.32.3', 'Accept-Encoding': 'gzip, deflate, br', 'Accept': '*/*', 'Connection': 'keep-alive', 'Content-Length': '12277'}
2025-04-14 15:13:33,673 ERROR   wandb-upload_3:16610 [internal_api.py:upload_file():2560] upload_file response body: 
2025-04-14 15:13:34,394 DEBUG   HandlerThread:16610 [handler.py:handle_request():146] handle_request: poll_exit
2025-04-14 15:13:34,395 DEBUG   SenderThread:16610 [sender.py:send_request():407] send_request: poll_exit
2025-04-14 15:13:34,536 ERROR   wandb-upload_1:16610 [internal_api.py:upload_file():2556] upload_file exception https://storage.googleapis.com/wandb-production.appspot.com/2931823730-harbin-institute-of-technology/ltu-as/sro21n02/config.yaml?X-Goog-Algorithm=GOOG4-RSA-SHA256&X-Goog-Credential=gorilla-files-url-signer-man%40wandb-production.iam.gserviceaccount.com%2F20250414%2Fauto%2Fstorage%2Fgoog4_request&X-Goog-Date=20250414T151333Z&X-Goog-Expires=86399&X-Goog-Signature=2f73e93adaa04407e79c1d548385c55943fdf3db36963bfdf350643aa1b36dae813f5626aaaa750a4bede213fdbf01567d7849c255d958ccd82bb15aae31926ef2cb8142328b26778f2203ecbf35a11e72c8b6968ecfdc910d13ecb0d1c8203f98f95824cddf7c77c6d98174c1a272e56c9fee7836d9b384f88d0e5366792f80e0ac49470f62e30e729583e849f555474ab8021dfebe960bf62ab5c74c8a5de192142c1278ce895934f2e559a74830fc98bbe1048f7b1480b81d89ce5d5da5e4ead191f9e8785bf30c7c829de0a9685a99a16ca07c58d7690c12c5d4c96a20f270453ab953c96813cc31dfe1cb8ad8af66ef18162ab0b43a8eda9c5df2be20e9&X-Goog-SignedHeaders=host&X-User=2931823730: HTTPSConnectionPool(host='storage.googleapis.com', port=443): Max retries exceeded with url: /wandb-production.appspot.com/2931823730-harbin-institute-of-technology/ltu-as/sro21n02/config.yaml?X-Goog-Algorithm=GOOG4-RSA-SHA256&X-Goog-Credential=gorilla-files-url-signer-man%40wandb-production.iam.gserviceaccount.com%2F20250414%2Fauto%2Fstorage%2Fgoog4_request&X-Goog-Date=20250414T151333Z&X-Goog-Expires=86399&X-Goog-Signature=2f73e93adaa04407e79c1d548385c55943fdf3db36963bfdf350643aa1b36dae813f5626aaaa750a4bede213fdbf01567d7849c255d958ccd82bb15aae31926ef2cb8142328b26778f2203ecbf35a11e72c8b6968ecfdc910d13ecb0d1c8203f98f95824cddf7c77c6d98174c1a272e56c9fee7836d9b384f88d0e5366792f80e0ac49470f62e30e729583e849f555474ab8021dfebe960bf62ab5c74c8a5de192142c1278ce895934f2e559a74830fc98bbe1048f7b1480b81d89ce5d5da5e4ead191f9e8785bf30c7c829de0a9685a99a16ca07c58d7690c12c5d4c96a20f270453ab953c96813cc31dfe1cb8ad8af66ef18162ab0b43a8eda9c5df2be20e9&X-Goog-SignedHeaders=host&X-User=2931823730 (Caused by NewConnectionError('<urllib3.connection.HTTPSConnection object at 0x7f87003bc4c0>: Failed to establish a new connection: [Errno 101] Network is unreachable'))
2025-04-14 15:13:34,536 ERROR   wandb-upload_1:16610 [internal_api.py:upload_file():2558] upload_file request headers: {'User-Agent': 'python-requests/2.32.3', 'Accept-Encoding': 'gzip, deflate, br', 'Accept': '*/*', 'Connection': 'keep-alive', 'Content-Length': '8685'}
2025-04-14 15:13:34,537 ERROR   wandb-upload_1:16610 [internal_api.py:upload_file():2560] upload_file response body: 
2025-04-14 15:13:34,759 ERROR   wandb-upload_2:16610 [internal_api.py:upload_file():2556] upload_file exception https://storage.googleapis.com/wandb-production.appspot.com/2931823730-harbin-institute-of-technology/ltu-as/sro21n02/requirements.txt?X-Goog-Algorithm=GOOG4-RSA-SHA256&X-Goog-Credential=gorilla-files-url-signer-man%40wandb-production.iam.gserviceaccount.com%2F20250414%2Fauto%2Fstorage%2Fgoog4_request&X-Goog-Date=20250414T151333Z&X-Goog-Expires=86399&X-Goog-Signature=b68928fa0e2b525ca9c2a4d65e8ea36df3dbec3ea8e07a9b57488ed89a18368728d569f35fd3a3b6ca9d006c8392e823f6d6fbef9acdedfdfbdea9dad501ddc1b68a8c3da4ef9a3d38b5151d52891b7d34e027965272f5738f0c9424f5f56686d85cd3224ecb738c6004f884ec680ea391556784a77a9635964958cca0550fb2964a9d249f9592c4612a80c37dacfa24de7da22cb81cc60580456b322e673c980e695f58ed8f8ec247a7076cd46757b6ed864432d0b7a8ebfe3798a4d4748a28cc0c109743ab0cc91f1b3aec691745a5a876dd34d6743fa8b507c86f6f5f6c4e2a5436c6a2e552806d88cd2cd6c69fae0fb8beb7a580df5fa7b602788538d255&X-Goog-SignedHeaders=host&X-User=2931823730: HTTPSConnectionPool(host='storage.googleapis.com', port=443): Max retries exceeded with url: /wandb-production.appspot.com/2931823730-harbin-institute-of-technology/ltu-as/sro21n02/requirements.txt?X-Goog-Algorithm=GOOG4-RSA-SHA256&X-Goog-Credential=gorilla-files-url-signer-man%40wandb-production.iam.gserviceaccount.com%2F20250414%2Fauto%2Fstorage%2Fgoog4_request&X-Goog-Date=20250414T151333Z&X-Goog-Expires=86399&X-Goog-Signature=b68928fa0e2b525ca9c2a4d65e8ea36df3dbec3ea8e07a9b57488ed89a18368728d569f35fd3a3b6ca9d006c8392e823f6d6fbef9acdedfdfbdea9dad501ddc1b68a8c3da4ef9a3d38b5151d52891b7d34e027965272f5738f0c9424f5f56686d85cd3224ecb738c6004f884ec680ea391556784a77a9635964958cca0550fb2964a9d249f9592c4612a80c37dacfa24de7da22cb81cc60580456b322e673c980e695f58ed8f8ec247a7076cd46757b6ed864432d0b7a8ebfe3798a4d4748a28cc0c109743ab0cc91f1b3aec691745a5a876dd34d6743fa8b507c86f6f5f6c4e2a5436c6a2e552806d88cd2cd6c69fae0fb8beb7a580df5fa7b602788538d255&X-Goog-SignedHeaders=host&X-User=2931823730 (Caused by NewConnectionError('<urllib3.connection.HTTPSConnection object at 0x7f87003bee90>: Failed to establish a new connection: [Errno 101] Network is unreachable'))
2025-04-14 15:13:34,759 ERROR   wandb-upload_2:16610 [internal_api.py:upload_file():2558] upload_file request headers: {'User-Agent': 'python-requests/2.32.3', 'Accept-Encoding': 'gzip, deflate, br', 'Accept': '*/*', 'Connection': 'keep-alive', 'Content-Length': '5836'}
2025-04-14 15:13:34,759 ERROR   wandb-upload_2:16610 [internal_api.py:upload_file():2560] upload_file response body: 
2025-04-14 15:13:34,761 ERROR   wandb-upload_5:16610 [internal_api.py:upload_file():2556] upload_file exception https://storage.googleapis.com/wandb-production.appspot.com/2931823730-harbin-institute-of-technology/ltu-as/sro21n02/wandb-summary.json?X-Goog-Algorithm=GOOG4-RSA-SHA256&X-Goog-Credential=gorilla-files-url-signer-man%40wandb-production.iam.gserviceaccount.com%2F20250414%2Fauto%2Fstorage%2Fgoog4_request&X-Goog-Date=20250414T151333Z&X-Goog-Expires=86399&X-Goog-Signature=1c62f3b6170db7b48818210bba95fa79cd7f43ca58b6649b0428570d3e8fcd4ca90cf9b087445b3c029a3a5140f42e4d052866f04bd68d93eb3ee96043ef83b1d04c735088f00ff00499677a95cd84c38a034bc58f50f0e30e8b710c7d003d84d488f7ad190ad01237f37aad21878dd5cafe07a27bcac5fb00a0c4ede0be7f9673e8d79381fa2ee8915ffddb163c4c3cefd67b96d065f83bf0d938fd38a763c3d75406bc83901267d8e75a5585d8862a7c7d68ab04ad3b9427824ed9f88ceee45e62757cdc63f7a87cf0e9ac9acb56705639c1d06018727ff251278bfcf3e68f5cdc69b06df7b41f6e080f2353f45a3e19e1da994c54be7bb021e8118023095f&X-Goog-SignedHeaders=host&X-User=2931823730: HTTPSConnectionPool(host='storage.googleapis.com', port=443): Max retries exceeded with url: /wandb-production.appspot.com/2931823730-harbin-institute-of-technology/ltu-as/sro21n02/wandb-summary.json?X-Goog-Algorithm=GOOG4-RSA-SHA256&X-Goog-Credential=gorilla-files-url-signer-man%40wandb-production.iam.gserviceaccount.com%2F20250414%2Fauto%2Fstorage%2Fgoog4_request&X-Goog-Date=20250414T151333Z&X-Goog-Expires=86399&X-Goog-Signature=1c62f3b6170db7b48818210bba95fa79cd7f43ca58b6649b0428570d3e8fcd4ca90cf9b087445b3c029a3a5140f42e4d052866f04bd68d93eb3ee96043ef83b1d04c735088f00ff00499677a95cd84c38a034bc58f50f0e30e8b710c7d003d84d488f7ad190ad01237f37aad21878dd5cafe07a27bcac5fb00a0c4ede0be7f9673e8d79381fa2ee8915ffddb163c4c3cefd67b96d065f83bf0d938fd38a763c3d75406bc83901267d8e75a5585d8862a7c7d68ab04ad3b9427824ed9f88ceee45e62757cdc63f7a87cf0e9ac9acb56705639c1d06018727ff251278bfcf3e68f5cdc69b06df7b41f6e080f2353f45a3e19e1da994c54be7bb021e8118023095f&X-Goog-SignedHeaders=host&X-User=2931823730 (Caused by NewConnectionError('<urllib3.connection.HTTPSConnection object at 0x7f86f83d1600>: Failed to establish a new connection: [Errno 101] Network is unreachable'))
2025-04-14 15:13:34,761 ERROR   wandb-upload_5:16610 [internal_api.py:upload_file():2558] upload_file request headers: {'User-Agent': 'python-requests/2.32.3', 'Accept-Encoding': 'gzip, deflate, br', 'Accept': '*/*', 'Connection': 'keep-alive', 'Content-Length': '28'}
2025-04-14 15:13:34,761 ERROR   wandb-upload_5:16610 [internal_api.py:upload_file():2560] upload_file response body: 
2025-04-14 15:13:34,797 ERROR   wandb-upload_4:16610 [internal_api.py:upload_file():2556] upload_file exception https://storage.googleapis.com/wandb-production.appspot.com/2931823730-harbin-institute-of-technology/ltu-as/sro21n02/output.log?X-Goog-Algorithm=GOOG4-RSA-SHA256&X-Goog-Credential=gorilla-files-url-signer-man%40wandb-production.iam.gserviceaccount.com%2F20250414%2Fauto%2Fstorage%2Fgoog4_request&X-Goog-Date=20250414T151333Z&X-Goog-Expires=86399&X-Goog-Signature=c1b3d7a13962ac49c7c2542d07fc489216f963e1200f55034b20dcf718bfadea225d00f606037301d3163d0bcc6c723ac40ba61e901e43e0c2b4affc0cf59d8d0e87c42a048461dfb388bee91715da165b7d56016980b76e11e57db92a471bec391c0ce0681ed11eb937b2400195fa49b7e00e37551763edd99ecc1683df8aed7f765f565688bf99dcdbfaa26f25bb16cb58d2cad4e1dc46b0214559475d19c210a94c0e623f1e9b7363b55a7b2ee7730ac02de63bcd07075d4d1cf12cc2d74be322f92ff01972c74aea148c7f4e2ecd2e53d3ed5ca31db45eb0fb37c10edd7cdc41c02049ec2c67dfe9acb64b40903a5a22d0e059999942328737c2397a7dbf&X-Goog-SignedHeaders=host&X-User=2931823730: HTTPSConnectionPool(host='storage.googleapis.com', port=443): Max retries exceeded with url: /wandb-production.appspot.com/2931823730-harbin-institute-of-technology/ltu-as/sro21n02/output.log?X-Goog-Algorithm=GOOG4-RSA-SHA256&X-Goog-Credential=gorilla-files-url-signer-man%40wandb-production.iam.gserviceaccount.com%2F20250414%2Fauto%2Fstorage%2Fgoog4_request&X-Goog-Date=20250414T151333Z&X-Goog-Expires=86399&X-Goog-Signature=c1b3d7a13962ac49c7c2542d07fc489216f963e1200f55034b20dcf718bfadea225d00f606037301d3163d0bcc6c723ac40ba61e901e43e0c2b4affc0cf59d8d0e87c42a048461dfb388bee91715da165b7d56016980b76e11e57db92a471bec391c0ce0681ed11eb937b2400195fa49b7e00e37551763edd99ecc1683df8aed7f765f565688bf99dcdbfaa26f25bb16cb58d2cad4e1dc46b0214559475d19c210a94c0e623f1e9b7363b55a7b2ee7730ac02de63bcd07075d4d1cf12cc2d74be322f92ff01972c74aea148c7f4e2ecd2e53d3ed5ca31db45eb0fb37c10edd7cdc41c02049ec2c67dfe9acb64b40903a5a22d0e059999942328737c2397a7dbf&X-Goog-SignedHeaders=host&X-User=2931823730 (Caused by NewConnectionError('<urllib3.connection.HTTPSConnection object at 0x7f86f83d1d20>: Failed to establish a new connection: [Errno 101] Network is unreachable'))
2025-04-14 15:13:34,797 ERROR   wandb-upload_4:16610 [internal_api.py:upload_file():2558] upload_file request headers: {'User-Agent': 'python-requests/2.32.3', 'Accept-Encoding': 'gzip, deflate, br', 'Accept': '*/*', 'Connection': 'keep-alive', 'Content-Length': '4916'}
2025-04-14 15:13:34,797 ERROR   wandb-upload_4:16610 [internal_api.py:upload_file():2560] upload_file response body: 
2025-04-14 15:13:34,888 ERROR   wandb-upload_3:16610 [internal_api.py:upload_file():2556] upload_file exception https://storage.googleapis.com/wandb-production.appspot.com/2931823730-harbin-institute-of-technology/ltu-as/sro21n02/conda-environment.yaml?X-Goog-Algorithm=GOOG4-RSA-SHA256&X-Goog-Credential=gorilla-files-url-signer-man%40wandb-production.iam.gserviceaccount.com%2F20250414%2Fauto%2Fstorage%2Fgoog4_request&X-Goog-Date=20250414T151333Z&X-Goog-Expires=86399&X-Goog-Signature=8baaa21661194630a1882e9ed7d315c11d50e573164af7eea55e95ea5953fd3753e98b46a842fe08f503515df18f8fec23a1b271a20bb7458c002170e1ebdd8483b5e2add7e3a8be1f646f1e2361148d782932620251502d2a34b98fc93d70437b2f3c1a672cc8883b684e4df9db83cff0b6477537a2c9f56b12f33118f45063e2abeb73a874b52185f0e7b731bb801545fd9d9cdba619ce48938fed831ab0e64f80cb3e5b15e0de3825420374059423d9ff49f5dd49b3f143c76929b5a9acd4e508e6817a9f3d25eb0441ab4f9be1c4523af1abfaf83ba139a7bffef05151b68a34b1f37c4e2fb49eb2e9893dc7553d87dfef018ac0c0995b7e1898f230da7d&X-Goog-SignedHeaders=host&X-User=2931823730: HTTPSConnectionPool(host='storage.googleapis.com', port=443): Max retries exceeded with url: /wandb-production.appspot.com/2931823730-harbin-institute-of-technology/ltu-as/sro21n02/conda-environment.yaml?X-Goog-Algorithm=GOOG4-RSA-SHA256&X-Goog-Credential=gorilla-files-url-signer-man%40wandb-production.iam.gserviceaccount.com%2F20250414%2Fauto%2Fstorage%2Fgoog4_request&X-Goog-Date=20250414T151333Z&X-Goog-Expires=86399&X-Goog-Signature=8baaa21661194630a1882e9ed7d315c11d50e573164af7eea55e95ea5953fd3753e98b46a842fe08f503515df18f8fec23a1b271a20bb7458c002170e1ebdd8483b5e2add7e3a8be1f646f1e2361148d782932620251502d2a34b98fc93d70437b2f3c1a672cc8883b684e4df9db83cff0b6477537a2c9f56b12f33118f45063e2abeb73a874b52185f0e7b731bb801545fd9d9cdba619ce48938fed831ab0e64f80cb3e5b15e0de3825420374059423d9ff49f5dd49b3f143c76929b5a9acd4e508e6817a9f3d25eb0441ab4f9be1c4523af1abfaf83ba139a7bffef05151b68a34b1f37c4e2fb49eb2e9893dc7553d87dfef018ac0c0995b7e1898f230da7d&X-Goog-SignedHeaders=host&X-User=2931823730 (Caused by NewConnectionError('<urllib3.connection.HTTPSConnection object at 0x7f86f83d21d0>: Failed to establish a new connection: [Errno 101] Network is unreachable'))
2025-04-14 15:13:34,888 ERROR   wandb-upload_3:16610 [internal_api.py:upload_file():2558] upload_file request headers: {'User-Agent': 'python-requests/2.32.3', 'Accept-Encoding': 'gzip, deflate, br', 'Accept': '*/*', 'Connection': 'keep-alive', 'Content-Length': '12277'}
2025-04-14 15:13:34,888 ERROR   wandb-upload_3:16610 [internal_api.py:upload_file():2560] upload_file response body: 
2025-04-14 15:13:35,397 DEBUG   HandlerThread:16610 [handler.py:handle_request():146] handle_request: poll_exit
2025-04-14 15:13:35,398 DEBUG   SenderThread:16610 [sender.py:send_request():407] send_request: poll_exit
2025-04-14 15:13:36,398 DEBUG   HandlerThread:16610 [handler.py:handle_request():146] handle_request: poll_exit
2025-04-14 15:13:36,399 DEBUG   SenderThread:16610 [sender.py:send_request():407] send_request: poll_exit
2025-04-14 15:13:36,876 ERROR   wandb-upload_1:16610 [internal_api.py:upload_file():2556] upload_file exception https://storage.googleapis.com/wandb-production.appspot.com/2931823730-harbin-institute-of-technology/ltu-as/sro21n02/config.yaml?X-Goog-Algorithm=GOOG4-RSA-SHA256&X-Goog-Credential=gorilla-files-url-signer-man%40wandb-production.iam.gserviceaccount.com%2F20250414%2Fauto%2Fstorage%2Fgoog4_request&X-Goog-Date=20250414T151333Z&X-Goog-Expires=86399&X-Goog-Signature=2f73e93adaa04407e79c1d548385c55943fdf3db36963bfdf350643aa1b36dae813f5626aaaa750a4bede213fdbf01567d7849c255d958ccd82bb15aae31926ef2cb8142328b26778f2203ecbf35a11e72c8b6968ecfdc910d13ecb0d1c8203f98f95824cddf7c77c6d98174c1a272e56c9fee7836d9b384f88d0e5366792f80e0ac49470f62e30e729583e849f555474ab8021dfebe960bf62ab5c74c8a5de192142c1278ce895934f2e559a74830fc98bbe1048f7b1480b81d89ce5d5da5e4ead191f9e8785bf30c7c829de0a9685a99a16ca07c58d7690c12c5d4c96a20f270453ab953c96813cc31dfe1cb8ad8af66ef18162ab0b43a8eda9c5df2be20e9&X-Goog-SignedHeaders=host&X-User=2931823730: HTTPSConnectionPool(host='storage.googleapis.com', port=443): Max retries exceeded with url: /wandb-production.appspot.com/2931823730-harbin-institute-of-technology/ltu-as/sro21n02/config.yaml?X-Goog-Algorithm=GOOG4-RSA-SHA256&X-Goog-Credential=gorilla-files-url-signer-man%40wandb-production.iam.gserviceaccount.com%2F20250414%2Fauto%2Fstorage%2Fgoog4_request&X-Goog-Date=20250414T151333Z&X-Goog-Expires=86399&X-Goog-Signature=2f73e93adaa04407e79c1d548385c55943fdf3db36963bfdf350643aa1b36dae813f5626aaaa750a4bede213fdbf01567d7849c255d958ccd82bb15aae31926ef2cb8142328b26778f2203ecbf35a11e72c8b6968ecfdc910d13ecb0d1c8203f98f95824cddf7c77c6d98174c1a272e56c9fee7836d9b384f88d0e5366792f80e0ac49470f62e30e729583e849f555474ab8021dfebe960bf62ab5c74c8a5de192142c1278ce895934f2e559a74830fc98bbe1048f7b1480b81d89ce5d5da5e4ead191f9e8785bf30c7c829de0a9685a99a16ca07c58d7690c12c5d4c96a20f270453ab953c96813cc31dfe1cb8ad8af66ef18162ab0b43a8eda9c5df2be20e9&X-Goog-SignedHeaders=host&X-User=2931823730 (Caused by NewConnectionError('<urllib3.connection.HTTPSConnection object at 0x7f86f83d0b20>: Failed to establish a new connection: [Errno 101] Network is unreachable'))
2025-04-14 15:13:36,876 ERROR   wandb-upload_1:16610 [internal_api.py:upload_file():2558] upload_file request headers: {'User-Agent': 'python-requests/2.32.3', 'Accept-Encoding': 'gzip, deflate, br', 'Accept': '*/*', 'Connection': 'keep-alive', 'Content-Length': '8685'}
2025-04-14 15:13:36,876 ERROR   wandb-upload_1:16610 [internal_api.py:upload_file():2560] upload_file response body: 
2025-04-14 15:13:36,877 ERROR   wandb-upload_5:16610 [internal_api.py:upload_file():2556] upload_file exception https://storage.googleapis.com/wandb-production.appspot.com/2931823730-harbin-institute-of-technology/ltu-as/sro21n02/wandb-summary.json?X-Goog-Algorithm=GOOG4-RSA-SHA256&X-Goog-Credential=gorilla-files-url-signer-man%40wandb-production.iam.gserviceaccount.com%2F20250414%2Fauto%2Fstorage%2Fgoog4_request&X-Goog-Date=20250414T151333Z&X-Goog-Expires=86399&X-Goog-Signature=1c62f3b6170db7b48818210bba95fa79cd7f43ca58b6649b0428570d3e8fcd4ca90cf9b087445b3c029a3a5140f42e4d052866f04bd68d93eb3ee96043ef83b1d04c735088f00ff00499677a95cd84c38a034bc58f50f0e30e8b710c7d003d84d488f7ad190ad01237f37aad21878dd5cafe07a27bcac5fb00a0c4ede0be7f9673e8d79381fa2ee8915ffddb163c4c3cefd67b96d065f83bf0d938fd38a763c3d75406bc83901267d8e75a5585d8862a7c7d68ab04ad3b9427824ed9f88ceee45e62757cdc63f7a87cf0e9ac9acb56705639c1d06018727ff251278bfcf3e68f5cdc69b06df7b41f6e080f2353f45a3e19e1da994c54be7bb021e8118023095f&X-Goog-SignedHeaders=host&X-User=2931823730: HTTPSConnectionPool(host='storage.googleapis.com', port=443): Max retries exceeded with url: /wandb-production.appspot.com/2931823730-harbin-institute-of-technology/ltu-as/sro21n02/wandb-summary.json?X-Goog-Algorithm=GOOG4-RSA-SHA256&X-Goog-Credential=gorilla-files-url-signer-man%40wandb-production.iam.gserviceaccount.com%2F20250414%2Fauto%2Fstorage%2Fgoog4_request&X-Goog-Date=20250414T151333Z&X-Goog-Expires=86399&X-Goog-Signature=1c62f3b6170db7b48818210bba95fa79cd7f43ca58b6649b0428570d3e8fcd4ca90cf9b087445b3c029a3a5140f42e4d052866f04bd68d93eb3ee96043ef83b1d04c735088f00ff00499677a95cd84c38a034bc58f50f0e30e8b710c7d003d84d488f7ad190ad01237f37aad21878dd5cafe07a27bcac5fb00a0c4ede0be7f9673e8d79381fa2ee8915ffddb163c4c3cefd67b96d065f83bf0d938fd38a763c3d75406bc83901267d8e75a5585d8862a7c7d68ab04ad3b9427824ed9f88ceee45e62757cdc63f7a87cf0e9ac9acb56705639c1d06018727ff251278bfcf3e68f5cdc69b06df7b41f6e080f2353f45a3e19e1da994c54be7bb021e8118023095f&X-Goog-SignedHeaders=host&X-User=2931823730 (Caused by NewConnectionError('<urllib3.connection.HTTPSConnection object at 0x7f8700354f70>: Failed to establish a new connection: [Errno 101] Network is unreachable'))
2025-04-14 15:13:36,878 ERROR   wandb-upload_5:16610 [internal_api.py:upload_file():2558] upload_file request headers: {'User-Agent': 'python-requests/2.32.3', 'Accept-Encoding': 'gzip, deflate, br', 'Accept': '*/*', 'Connection': 'keep-alive', 'Content-Length': '28'}
2025-04-14 15:13:36,878 ERROR   wandb-upload_5:16610 [internal_api.py:upload_file():2560] upload_file response body: 
2025-04-14 15:13:37,018 ERROR   wandb-upload_3:16610 [internal_api.py:upload_file():2556] upload_file exception https://storage.googleapis.com/wandb-production.appspot.com/2931823730-harbin-institute-of-technology/ltu-as/sro21n02/conda-environment.yaml?X-Goog-Algorithm=GOOG4-RSA-SHA256&X-Goog-Credential=gorilla-files-url-signer-man%40wandb-production.iam.gserviceaccount.com%2F20250414%2Fauto%2Fstorage%2Fgoog4_request&X-Goog-Date=20250414T151333Z&X-Goog-Expires=86399&X-Goog-Signature=8baaa21661194630a1882e9ed7d315c11d50e573164af7eea55e95ea5953fd3753e98b46a842fe08f503515df18f8fec23a1b271a20bb7458c002170e1ebdd8483b5e2add7e3a8be1f646f1e2361148d782932620251502d2a34b98fc93d70437b2f3c1a672cc8883b684e4df9db83cff0b6477537a2c9f56b12f33118f45063e2abeb73a874b52185f0e7b731bb801545fd9d9cdba619ce48938fed831ab0e64f80cb3e5b15e0de3825420374059423d9ff49f5dd49b3f143c76929b5a9acd4e508e6817a9f3d25eb0441ab4f9be1c4523af1abfaf83ba139a7bffef05151b68a34b1f37c4e2fb49eb2e9893dc7553d87dfef018ac0c0995b7e1898f230da7d&X-Goog-SignedHeaders=host&X-User=2931823730: HTTPSConnectionPool(host='storage.googleapis.com', port=443): Max retries exceeded with url: /wandb-production.appspot.com/2931823730-harbin-institute-of-technology/ltu-as/sro21n02/conda-environment.yaml?X-Goog-Algorithm=GOOG4-RSA-SHA256&X-Goog-Credential=gorilla-files-url-signer-man%40wandb-production.iam.gserviceaccount.com%2F20250414%2Fauto%2Fstorage%2Fgoog4_request&X-Goog-Date=20250414T151333Z&X-Goog-Expires=86399&X-Goog-Signature=8baaa21661194630a1882e9ed7d315c11d50e573164af7eea55e95ea5953fd3753e98b46a842fe08f503515df18f8fec23a1b271a20bb7458c002170e1ebdd8483b5e2add7e3a8be1f646f1e2361148d782932620251502d2a34b98fc93d70437b2f3c1a672cc8883b684e4df9db83cff0b6477537a2c9f56b12f33118f45063e2abeb73a874b52185f0e7b731bb801545fd9d9cdba619ce48938fed831ab0e64f80cb3e5b15e0de3825420374059423d9ff49f5dd49b3f143c76929b5a9acd4e508e6817a9f3d25eb0441ab4f9be1c4523af1abfaf83ba139a7bffef05151b68a34b1f37c4e2fb49eb2e9893dc7553d87dfef018ac0c0995b7e1898f230da7d&X-Goog-SignedHeaders=host&X-User=2931823730 (Caused by NewConnectionError('<urllib3.connection.HTTPSConnection object at 0x7f8700355b40>: Failed to establish a new connection: [Errno 101] Network is unreachable'))
2025-04-14 15:13:37,018 ERROR   wandb-upload_3:16610 [internal_api.py:upload_file():2558] upload_file request headers: {'User-Agent': 'python-requests/2.32.3', 'Accept-Encoding': 'gzip, deflate, br', 'Accept': '*/*', 'Connection': 'keep-alive', 'Content-Length': '12277'}
2025-04-14 15:13:37,018 ERROR   wandb-upload_3:16610 [internal_api.py:upload_file():2560] upload_file response body: 
2025-04-14 15:13:37,094 ERROR   wandb-upload_4:16610 [internal_api.py:upload_file():2556] upload_file exception https://storage.googleapis.com/wandb-production.appspot.com/2931823730-harbin-institute-of-technology/ltu-as/sro21n02/output.log?X-Goog-Algorithm=GOOG4-RSA-SHA256&X-Goog-Credential=gorilla-files-url-signer-man%40wandb-production.iam.gserviceaccount.com%2F20250414%2Fauto%2Fstorage%2Fgoog4_request&X-Goog-Date=20250414T151333Z&X-Goog-Expires=86399&X-Goog-Signature=c1b3d7a13962ac49c7c2542d07fc489216f963e1200f55034b20dcf718bfadea225d00f606037301d3163d0bcc6c723ac40ba61e901e43e0c2b4affc0cf59d8d0e87c42a048461dfb388bee91715da165b7d56016980b76e11e57db92a471bec391c0ce0681ed11eb937b2400195fa49b7e00e37551763edd99ecc1683df8aed7f765f565688bf99dcdbfaa26f25bb16cb58d2cad4e1dc46b0214559475d19c210a94c0e623f1e9b7363b55a7b2ee7730ac02de63bcd07075d4d1cf12cc2d74be322f92ff01972c74aea148c7f4e2ecd2e53d3ed5ca31db45eb0fb37c10edd7cdc41c02049ec2c67dfe9acb64b40903a5a22d0e059999942328737c2397a7dbf&X-Goog-SignedHeaders=host&X-User=2931823730: HTTPSConnectionPool(host='storage.googleapis.com', port=443): Max retries exceeded with url: /wandb-production.appspot.com/2931823730-harbin-institute-of-technology/ltu-as/sro21n02/output.log?X-Goog-Algorithm=GOOG4-RSA-SHA256&X-Goog-Credential=gorilla-files-url-signer-man%40wandb-production.iam.gserviceaccount.com%2F20250414%2Fauto%2Fstorage%2Fgoog4_request&X-Goog-Date=20250414T151333Z&X-Goog-Expires=86399&X-Goog-Signature=c1b3d7a13962ac49c7c2542d07fc489216f963e1200f55034b20dcf718bfadea225d00f606037301d3163d0bcc6c723ac40ba61e901e43e0c2b4affc0cf59d8d0e87c42a048461dfb388bee91715da165b7d56016980b76e11e57db92a471bec391c0ce0681ed11eb937b2400195fa49b7e00e37551763edd99ecc1683df8aed7f765f565688bf99dcdbfaa26f25bb16cb58d2cad4e1dc46b0214559475d19c210a94c0e623f1e9b7363b55a7b2ee7730ac02de63bcd07075d4d1cf12cc2d74be322f92ff01972c74aea148c7f4e2ecd2e53d3ed5ca31db45eb0fb37c10edd7cdc41c02049ec2c67dfe9acb64b40903a5a22d0e059999942328737c2397a7dbf&X-Goog-SignedHeaders=host&X-User=2931823730 (Caused by NewConnectionError('<urllib3.connection.HTTPSConnection object at 0x7f87003beb00>: Failed to establish a new connection: [Errno 101] Network is unreachable'))
2025-04-14 15:13:37,094 ERROR   wandb-upload_4:16610 [internal_api.py:upload_file():2558] upload_file request headers: {'User-Agent': 'python-requests/2.32.3', 'Accept-Encoding': 'gzip, deflate, br', 'Accept': '*/*', 'Connection': 'keep-alive', 'Content-Length': '4916'}
2025-04-14 15:13:37,094 ERROR   wandb-upload_4:16610 [internal_api.py:upload_file():2560] upload_file response body: 
2025-04-14 15:13:37,230 ERROR   wandb-upload_2:16610 [internal_api.py:upload_file():2556] upload_file exception https://storage.googleapis.com/wandb-production.appspot.com/2931823730-harbin-institute-of-technology/ltu-as/sro21n02/requirements.txt?X-Goog-Algorithm=GOOG4-RSA-SHA256&X-Goog-Credential=gorilla-files-url-signer-man%40wandb-production.iam.gserviceaccount.com%2F20250414%2Fauto%2Fstorage%2Fgoog4_request&X-Goog-Date=20250414T151333Z&X-Goog-Expires=86399&X-Goog-Signature=b68928fa0e2b525ca9c2a4d65e8ea36df3dbec3ea8e07a9b57488ed89a18368728d569f35fd3a3b6ca9d006c8392e823f6d6fbef9acdedfdfbdea9dad501ddc1b68a8c3da4ef9a3d38b5151d52891b7d34e027965272f5738f0c9424f5f56686d85cd3224ecb738c6004f884ec680ea391556784a77a9635964958cca0550fb2964a9d249f9592c4612a80c37dacfa24de7da22cb81cc60580456b322e673c980e695f58ed8f8ec247a7076cd46757b6ed864432d0b7a8ebfe3798a4d4748a28cc0c109743ab0cc91f1b3aec691745a5a876dd34d6743fa8b507c86f6f5f6c4e2a5436c6a2e552806d88cd2cd6c69fae0fb8beb7a580df5fa7b602788538d255&X-Goog-SignedHeaders=host&X-User=2931823730: HTTPSConnectionPool(host='storage.googleapis.com', port=443): Max retries exceeded with url: /wandb-production.appspot.com/2931823730-harbin-institute-of-technology/ltu-as/sro21n02/requirements.txt?X-Goog-Algorithm=GOOG4-RSA-SHA256&X-Goog-Credential=gorilla-files-url-signer-man%40wandb-production.iam.gserviceaccount.com%2F20250414%2Fauto%2Fstorage%2Fgoog4_request&X-Goog-Date=20250414T151333Z&X-Goog-Expires=86399&X-Goog-Signature=b68928fa0e2b525ca9c2a4d65e8ea36df3dbec3ea8e07a9b57488ed89a18368728d569f35fd3a3b6ca9d006c8392e823f6d6fbef9acdedfdfbdea9dad501ddc1b68a8c3da4ef9a3d38b5151d52891b7d34e027965272f5738f0c9424f5f56686d85cd3224ecb738c6004f884ec680ea391556784a77a9635964958cca0550fb2964a9d249f9592c4612a80c37dacfa24de7da22cb81cc60580456b322e673c980e695f58ed8f8ec247a7076cd46757b6ed864432d0b7a8ebfe3798a4d4748a28cc0c109743ab0cc91f1b3aec691745a5a876dd34d6743fa8b507c86f6f5f6c4e2a5436c6a2e552806d88cd2cd6c69fae0fb8beb7a580df5fa7b602788538d255&X-Goog-SignedHeaders=host&X-User=2931823730 (Caused by NewConnectionError('<urllib3.connection.HTTPSConnection object at 0x7f87003bfca0>: Failed to establish a new connection: [Errno 101] Network is unreachable'))
2025-04-14 15:13:37,231 ERROR   wandb-upload_2:16610 [internal_api.py:upload_file():2558] upload_file request headers: {'User-Agent': 'python-requests/2.32.3', 'Accept-Encoding': 'gzip, deflate, br', 'Accept': '*/*', 'Connection': 'keep-alive', 'Content-Length': '5836'}
2025-04-14 15:13:37,231 ERROR   wandb-upload_2:16610 [internal_api.py:upload_file():2560] upload_file response body: 
2025-04-14 15:13:37,401 DEBUG   HandlerThread:16610 [handler.py:handle_request():146] handle_request: poll_exit
2025-04-14 15:13:37,412 DEBUG   SenderThread:16610 [sender.py:send_request():407] send_request: poll_exit
2025-04-14 15:13:38,402 DEBUG   HandlerThread:16610 [handler.py:handle_request():146] handle_request: poll_exit
2025-04-14 15:13:38,403 DEBUG   SenderThread:16610 [sender.py:send_request():407] send_request: poll_exit
2025-04-14 15:13:38,404 DEBUG   HandlerThread:16610 [handler.py:handle_request():146] handle_request: status_report
2025-04-14 15:13:39,403 DEBUG   HandlerThread:16610 [handler.py:handle_request():146] handle_request: poll_exit
2025-04-14 15:13:39,404 DEBUG   SenderThread:16610 [sender.py:send_request():407] send_request: poll_exit
2025-04-14 15:13:40,405 DEBUG   HandlerThread:16610 [handler.py:handle_request():146] handle_request: poll_exit
2025-04-14 15:13:40,406 DEBUG   SenderThread:16610 [sender.py:send_request():407] send_request: poll_exit
2025-04-14 15:13:41,058 ERROR   wandb-upload_1:16610 [internal_api.py:upload_file():2556] upload_file exception https://storage.googleapis.com/wandb-production.appspot.com/2931823730-harbin-institute-of-technology/ltu-as/sro21n02/config.yaml?X-Goog-Algorithm=GOOG4-RSA-SHA256&X-Goog-Credential=gorilla-files-url-signer-man%40wandb-production.iam.gserviceaccount.com%2F20250414%2Fauto%2Fstorage%2Fgoog4_request&X-Goog-Date=20250414T151333Z&X-Goog-Expires=86399&X-Goog-Signature=2f73e93adaa04407e79c1d548385c55943fdf3db36963bfdf350643aa1b36dae813f5626aaaa750a4bede213fdbf01567d7849c255d958ccd82bb15aae31926ef2cb8142328b26778f2203ecbf35a11e72c8b6968ecfdc910d13ecb0d1c8203f98f95824cddf7c77c6d98174c1a272e56c9fee7836d9b384f88d0e5366792f80e0ac49470f62e30e729583e849f555474ab8021dfebe960bf62ab5c74c8a5de192142c1278ce895934f2e559a74830fc98bbe1048f7b1480b81d89ce5d5da5e4ead191f9e8785bf30c7c829de0a9685a99a16ca07c58d7690c12c5d4c96a20f270453ab953c96813cc31dfe1cb8ad8af66ef18162ab0b43a8eda9c5df2be20e9&X-Goog-SignedHeaders=host&X-User=2931823730: HTTPSConnectionPool(host='storage.googleapis.com', port=443): Max retries exceeded with url: /wandb-production.appspot.com/2931823730-harbin-institute-of-technology/ltu-as/sro21n02/config.yaml?X-Goog-Algorithm=GOOG4-RSA-SHA256&X-Goog-Credential=gorilla-files-url-signer-man%40wandb-production.iam.gserviceaccount.com%2F20250414%2Fauto%2Fstorage%2Fgoog4_request&X-Goog-Date=20250414T151333Z&X-Goog-Expires=86399&X-Goog-Signature=2f73e93adaa04407e79c1d548385c55943fdf3db36963bfdf350643aa1b36dae813f5626aaaa750a4bede213fdbf01567d7849c255d958ccd82bb15aae31926ef2cb8142328b26778f2203ecbf35a11e72c8b6968ecfdc910d13ecb0d1c8203f98f95824cddf7c77c6d98174c1a272e56c9fee7836d9b384f88d0e5366792f80e0ac49470f62e30e729583e849f555474ab8021dfebe960bf62ab5c74c8a5de192142c1278ce895934f2e559a74830fc98bbe1048f7b1480b81d89ce5d5da5e4ead191f9e8785bf30c7c829de0a9685a99a16ca07c58d7690c12c5d4c96a20f270453ab953c96813cc31dfe1cb8ad8af66ef18162ab0b43a8eda9c5df2be20e9&X-Goog-SignedHeaders=host&X-User=2931823730 (Caused by NewConnectionError('<urllib3.connection.HTTPSConnection object at 0x7f87003bead0>: Failed to establish a new connection: [Errno 101] Network is unreachable'))
2025-04-14 15:13:41,059 ERROR   wandb-upload_1:16610 [internal_api.py:upload_file():2558] upload_file request headers: {'User-Agent': 'python-requests/2.32.3', 'Accept-Encoding': 'gzip, deflate, br', 'Accept': '*/*', 'Connection': 'keep-alive', 'Content-Length': '8685'}
2025-04-14 15:13:41,059 ERROR   wandb-upload_1:16610 [internal_api.py:upload_file():2560] upload_file response body: 
2025-04-14 15:13:41,262 ERROR   wandb-upload_5:16610 [internal_api.py:upload_file():2556] upload_file exception https://storage.googleapis.com/wandb-production.appspot.com/2931823730-harbin-institute-of-technology/ltu-as/sro21n02/wandb-summary.json?X-Goog-Algorithm=GOOG4-RSA-SHA256&X-Goog-Credential=gorilla-files-url-signer-man%40wandb-production.iam.gserviceaccount.com%2F20250414%2Fauto%2Fstorage%2Fgoog4_request&X-Goog-Date=20250414T151333Z&X-Goog-Expires=86399&X-Goog-Signature=1c62f3b6170db7b48818210bba95fa79cd7f43ca58b6649b0428570d3e8fcd4ca90cf9b087445b3c029a3a5140f42e4d052866f04bd68d93eb3ee96043ef83b1d04c735088f00ff00499677a95cd84c38a034bc58f50f0e30e8b710c7d003d84d488f7ad190ad01237f37aad21878dd5cafe07a27bcac5fb00a0c4ede0be7f9673e8d79381fa2ee8915ffddb163c4c3cefd67b96d065f83bf0d938fd38a763c3d75406bc83901267d8e75a5585d8862a7c7d68ab04ad3b9427824ed9f88ceee45e62757cdc63f7a87cf0e9ac9acb56705639c1d06018727ff251278bfcf3e68f5cdc69b06df7b41f6e080f2353f45a3e19e1da994c54be7bb021e8118023095f&X-Goog-SignedHeaders=host&X-User=2931823730: HTTPSConnectionPool(host='storage.googleapis.com', port=443): Max retries exceeded with url: /wandb-production.appspot.com/2931823730-harbin-institute-of-technology/ltu-as/sro21n02/wandb-summary.json?X-Goog-Algorithm=GOOG4-RSA-SHA256&X-Goog-Credential=gorilla-files-url-signer-man%40wandb-production.iam.gserviceaccount.com%2F20250414%2Fauto%2Fstorage%2Fgoog4_request&X-Goog-Date=20250414T151333Z&X-Goog-Expires=86399&X-Goog-Signature=1c62f3b6170db7b48818210bba95fa79cd7f43ca58b6649b0428570d3e8fcd4ca90cf9b087445b3c029a3a5140f42e4d052866f04bd68d93eb3ee96043ef83b1d04c735088f00ff00499677a95cd84c38a034bc58f50f0e30e8b710c7d003d84d488f7ad190ad01237f37aad21878dd5cafe07a27bcac5fb00a0c4ede0be7f9673e8d79381fa2ee8915ffddb163c4c3cefd67b96d065f83bf0d938fd38a763c3d75406bc83901267d8e75a5585d8862a7c7d68ab04ad3b9427824ed9f88ceee45e62757cdc63f7a87cf0e9ac9acb56705639c1d06018727ff251278bfcf3e68f5cdc69b06df7b41f6e080f2353f45a3e19e1da994c54be7bb021e8118023095f&X-Goog-SignedHeaders=host&X-User=2931823730 (Caused by NewConnectionError('<urllib3.connection.HTTPSConnection object at 0x7f87003bcac0>: Failed to establish a new connection: [Errno 101] Network is unreachable'))
2025-04-14 15:13:41,262 ERROR   wandb-upload_5:16610 [internal_api.py:upload_file():2558] upload_file request headers: {'User-Agent': 'python-requests/2.32.3', 'Accept-Encoding': 'gzip, deflate, br', 'Accept': '*/*', 'Connection': 'keep-alive', 'Content-Length': '28'}
2025-04-14 15:13:41,263 ERROR   wandb-upload_5:16610 [internal_api.py:upload_file():2560] upload_file response body: 
2025-04-14 15:13:41,342 ERROR   wandb-upload_4:16610 [internal_api.py:upload_file():2556] upload_file exception https://storage.googleapis.com/wandb-production.appspot.com/2931823730-harbin-institute-of-technology/ltu-as/sro21n02/output.log?X-Goog-Algorithm=GOOG4-RSA-SHA256&X-Goog-Credential=gorilla-files-url-signer-man%40wandb-production.iam.gserviceaccount.com%2F20250414%2Fauto%2Fstorage%2Fgoog4_request&X-Goog-Date=20250414T151333Z&X-Goog-Expires=86399&X-Goog-Signature=c1b3d7a13962ac49c7c2542d07fc489216f963e1200f55034b20dcf718bfadea225d00f606037301d3163d0bcc6c723ac40ba61e901e43e0c2b4affc0cf59d8d0e87c42a048461dfb388bee91715da165b7d56016980b76e11e57db92a471bec391c0ce0681ed11eb937b2400195fa49b7e00e37551763edd99ecc1683df8aed7f765f565688bf99dcdbfaa26f25bb16cb58d2cad4e1dc46b0214559475d19c210a94c0e623f1e9b7363b55a7b2ee7730ac02de63bcd07075d4d1cf12cc2d74be322f92ff01972c74aea148c7f4e2ecd2e53d3ed5ca31db45eb0fb37c10edd7cdc41c02049ec2c67dfe9acb64b40903a5a22d0e059999942328737c2397a7dbf&X-Goog-SignedHeaders=host&X-User=2931823730: HTTPSConnectionPool(host='storage.googleapis.com', port=443): Max retries exceeded with url: /wandb-production.appspot.com/2931823730-harbin-institute-of-technology/ltu-as/sro21n02/output.log?X-Goog-Algorithm=GOOG4-RSA-SHA256&X-Goog-Credential=gorilla-files-url-signer-man%40wandb-production.iam.gserviceaccount.com%2F20250414%2Fauto%2Fstorage%2Fgoog4_request&X-Goog-Date=20250414T151333Z&X-Goog-Expires=86399&X-Goog-Signature=c1b3d7a13962ac49c7c2542d07fc489216f963e1200f55034b20dcf718bfadea225d00f606037301d3163d0bcc6c723ac40ba61e901e43e0c2b4affc0cf59d8d0e87c42a048461dfb388bee91715da165b7d56016980b76e11e57db92a471bec391c0ce0681ed11eb937b2400195fa49b7e00e37551763edd99ecc1683df8aed7f765f565688bf99dcdbfaa26f25bb16cb58d2cad4e1dc46b0214559475d19c210a94c0e623f1e9b7363b55a7b2ee7730ac02de63bcd07075d4d1cf12cc2d74be322f92ff01972c74aea148c7f4e2ecd2e53d3ed5ca31db45eb0fb37c10edd7cdc41c02049ec2c67dfe9acb64b40903a5a22d0e059999942328737c2397a7dbf&X-Goog-SignedHeaders=host&X-User=2931823730 (Caused by NewConnectionError('<urllib3.connection.HTTPSConnection object at 0x7f87003bdde0>: Failed to establish a new connection: [Errno 101] Network is unreachable'))
2025-04-14 15:13:41,342 ERROR   wandb-upload_4:16610 [internal_api.py:upload_file():2558] upload_file request headers: {'User-Agent': 'python-requests/2.32.3', 'Accept-Encoding': 'gzip, deflate, br', 'Accept': '*/*', 'Connection': 'keep-alive', 'Content-Length': '4916'}
2025-04-14 15:13:41,342 ERROR   wandb-upload_4:16610 [internal_api.py:upload_file():2560] upload_file response body: 
2025-04-14 15:13:41,407 DEBUG   HandlerThread:16610 [handler.py:handle_request():146] handle_request: poll_exit
2025-04-14 15:13:41,408 DEBUG   SenderThread:16610 [sender.py:send_request():407] send_request: poll_exit
2025-04-14 15:13:41,460 WARNING StreamThr :16610 [internal.py:is_dead():414] Internal process exiting, parent pid 16362 disappeared
2025-04-14 15:13:41,460 ERROR   StreamThr :16610 [internal.py:wandb_internal():152] Internal process shutdown.
2025-04-14 15:13:41,679 ERROR   wandb-upload_3:16610 [internal_api.py:upload_file():2556] upload_file exception https://storage.googleapis.com/wandb-production.appspot.com/2931823730-harbin-institute-of-technology/ltu-as/sro21n02/conda-environment.yaml?X-Goog-Algorithm=GOOG4-RSA-SHA256&X-Goog-Credential=gorilla-files-url-signer-man%40wandb-production.iam.gserviceaccount.com%2F20250414%2Fauto%2Fstorage%2Fgoog4_request&X-Goog-Date=20250414T151333Z&X-Goog-Expires=86399&X-Goog-Signature=8baaa21661194630a1882e9ed7d315c11d50e573164af7eea55e95ea5953fd3753e98b46a842fe08f503515df18f8fec23a1b271a20bb7458c002170e1ebdd8483b5e2add7e3a8be1f646f1e2361148d782932620251502d2a34b98fc93d70437b2f3c1a672cc8883b684e4df9db83cff0b6477537a2c9f56b12f33118f45063e2abeb73a874b52185f0e7b731bb801545fd9d9cdba619ce48938fed831ab0e64f80cb3e5b15e0de3825420374059423d9ff49f5dd49b3f143c76929b5a9acd4e508e6817a9f3d25eb0441ab4f9be1c4523af1abfaf83ba139a7bffef05151b68a34b1f37c4e2fb49eb2e9893dc7553d87dfef018ac0c0995b7e1898f230da7d&X-Goog-SignedHeaders=host&X-User=2931823730: HTTPSConnectionPool(host='storage.googleapis.com', port=443): Max retries exceeded with url: /wandb-production.appspot.com/2931823730-harbin-institute-of-technology/ltu-as/sro21n02/conda-environment.yaml?X-Goog-Algorithm=GOOG4-RSA-SHA256&X-Goog-Credential=gorilla-files-url-signer-man%40wandb-production.iam.gserviceaccount.com%2F20250414%2Fauto%2Fstorage%2Fgoog4_request&X-Goog-Date=20250414T151333Z&X-Goog-Expires=86399&X-Goog-Signature=8baaa21661194630a1882e9ed7d315c11d50e573164af7eea55e95ea5953fd3753e98b46a842fe08f503515df18f8fec23a1b271a20bb7458c002170e1ebdd8483b5e2add7e3a8be1f646f1e2361148d782932620251502d2a34b98fc93d70437b2f3c1a672cc8883b684e4df9db83cff0b6477537a2c9f56b12f33118f45063e2abeb73a874b52185f0e7b731bb801545fd9d9cdba619ce48938fed831ab0e64f80cb3e5b15e0de3825420374059423d9ff49f5dd49b3f143c76929b5a9acd4e508e6817a9f3d25eb0441ab4f9be1c4523af1abfaf83ba139a7bffef05151b68a34b1f37c4e2fb49eb2e9893dc7553d87dfef018ac0c0995b7e1898f230da7d&X-Goog-SignedHeaders=host&X-User=2931823730 (Caused by NewConnectionError('<urllib3.connection.HTTPSConnection object at 0x7f87003bfb80>: Failed to establish a new connection: [Errno 101] Network is unreachable'))
2025-04-14 15:13:41,680 ERROR   wandb-upload_3:16610 [internal_api.py:upload_file():2558] upload_file request headers: {'User-Agent': 'python-requests/2.32.3', 'Accept-Encoding': 'gzip, deflate, br', 'Accept': '*/*', 'Connection': 'keep-alive', 'Content-Length': '12277'}
2025-04-14 15:13:41,680 ERROR   wandb-upload_3:16610 [internal_api.py:upload_file():2560] upload_file response body: 
2025-04-14 15:13:42,135 ERROR   wandb-upload_2:16610 [internal_api.py:upload_file():2556] upload_file exception https://storage.googleapis.com/wandb-production.appspot.com/2931823730-harbin-institute-of-technology/ltu-as/sro21n02/requirements.txt?X-Goog-Algorithm=GOOG4-RSA-SHA256&X-Goog-Credential=gorilla-files-url-signer-man%40wandb-production.iam.gserviceaccount.com%2F20250414%2Fauto%2Fstorage%2Fgoog4_request&X-Goog-Date=20250414T151333Z&X-Goog-Expires=86399&X-Goog-Signature=b68928fa0e2b525ca9c2a4d65e8ea36df3dbec3ea8e07a9b57488ed89a18368728d569f35fd3a3b6ca9d006c8392e823f6d6fbef9acdedfdfbdea9dad501ddc1b68a8c3da4ef9a3d38b5151d52891b7d34e027965272f5738f0c9424f5f56686d85cd3224ecb738c6004f884ec680ea391556784a77a9635964958cca0550fb2964a9d249f9592c4612a80c37dacfa24de7da22cb81cc60580456b322e673c980e695f58ed8f8ec247a7076cd46757b6ed864432d0b7a8ebfe3798a4d4748a28cc0c109743ab0cc91f1b3aec691745a5a876dd34d6743fa8b507c86f6f5f6c4e2a5436c6a2e552806d88cd2cd6c69fae0fb8beb7a580df5fa7b602788538d255&X-Goog-SignedHeaders=host&X-User=2931823730: HTTPSConnectionPool(host='storage.googleapis.com', port=443): Max retries exceeded with url: /wandb-production.appspot.com/2931823730-harbin-institute-of-technology/ltu-as/sro21n02/requirements.txt?X-Goog-Algorithm=GOOG4-RSA-SHA256&X-Goog-Credential=gorilla-files-url-signer-man%40wandb-production.iam.gserviceaccount.com%2F20250414%2Fauto%2Fstorage%2Fgoog4_request&X-Goog-Date=20250414T151333Z&X-Goog-Expires=86399&X-Goog-Signature=b68928fa0e2b525ca9c2a4d65e8ea36df3dbec3ea8e07a9b57488ed89a18368728d569f35fd3a3b6ca9d006c8392e823f6d6fbef9acdedfdfbdea9dad501ddc1b68a8c3da4ef9a3d38b5151d52891b7d34e027965272f5738f0c9424f5f56686d85cd3224ecb738c6004f884ec680ea391556784a77a9635964958cca0550fb2964a9d249f9592c4612a80c37dacfa24de7da22cb81cc60580456b322e673c980e695f58ed8f8ec247a7076cd46757b6ed864432d0b7a8ebfe3798a4d4748a28cc0c109743ab0cc91f1b3aec691745a5a876dd34d6743fa8b507c86f6f5f6c4e2a5436c6a2e552806d88cd2cd6c69fae0fb8beb7a580df5fa7b602788538d255&X-Goog-SignedHeaders=host&X-User=2931823730 (Caused by NewConnectionError('<urllib3.connection.HTTPSConnection object at 0x7f86f83d1a50>: Failed to establish a new connection: [Errno 101] Network is unreachable'))
2025-04-14 15:13:42,135 ERROR   wandb-upload_2:16610 [internal_api.py:upload_file():2558] upload_file request headers: {'User-Agent': 'python-requests/2.32.3', 'Accept-Encoding': 'gzip, deflate, br', 'Accept': '*/*', 'Connection': 'keep-alive', 'Content-Length': '5836'}
2025-04-14 15:13:42,135 ERROR   wandb-upload_2:16610 [internal_api.py:upload_file():2560] upload_file response body: 
2025-04-14 15:13:42,407 INFO    HandlerThread:16610 [handler.py:finish():866] shutting down handler
2025-04-14 15:13:42,408 INFO    WriterThread:16610 [datastore.py:close():294] close: /root/ltu-main/ltu-main/src/ltu_as/train_scripts/wandb/run-20250414_151140-sro21n02/run-sro21n02.wandb
2025-04-14 15:13:42,408 INFO    SenderThread:16610 [sender.py:finish():1534] shutting down sender
2025-04-14 15:13:42,409 INFO    SenderThread:16610 [file_pusher.py:finish():175] shutting down file pusher
2025-04-14 15:13:42,409 INFO    SenderThread:16610 [file_pusher.py:join():181] waiting for file pusher
2025-04-14 15:13:45,117 ERROR   wandb-upload_0:16610 [internal_api.py:upload_file():2556] upload_file exception https://storage.googleapis.com/wandb-production.appspot.com/2931823730-harbin-institute-of-technology/ltu-as/sro21n02/wandb-metadata.json?X-Goog-Algorithm=GOOG4-RSA-SHA256&X-Goog-Credential=gorilla-files-url-signer-man%40wandb-production.iam.gserviceaccount.com%2F20250414%2Fauto%2Fstorage%2Fgoog4_request&X-Goog-Date=20250414T151306Z&X-Goog-Expires=86399&X-Goog-Signature=0bf0b2bd8b586c4629cadf1b33955ead125425c9929b4db02171f92ae5780d32456d214d433d6d319596799bcbcb937ce5a1f7aee1c48cb9ac1c99a4aa3fc2356f2a3c710a9a6654c05b606b01ca1e97d9eaae6993f275d0c5967cccf57e2fe28f0f5bd4bca6f0f0c63aa5c6ce17990fb8c9f433425f087c76eec8c8916ab0eb376a85e82f84dce56bec266fd96c22c1f9354c90c63719ece160fd1bb61261f79adf64168e7b3c2b680ecc3e6025130fbc86e9885ee5d0cd41b40a6e82022f2115d5b5a683323cee548e6365923416e21c23b9daf0e147f86c6180af83d1df6a3f54eb98d1d885b465d7933177b8fb84b0eb944852291b001a237e586a9d35cf&X-Goog-SignedHeaders=host&X-User=2931823730: HTTPSConnectionPool(host='storage.googleapis.com', port=443): Max retries exceeded with url: /wandb-production.appspot.com/2931823730-harbin-institute-of-technology/ltu-as/sro21n02/wandb-metadata.json?X-Goog-Algorithm=GOOG4-RSA-SHA256&X-Goog-Credential=gorilla-files-url-signer-man%40wandb-production.iam.gserviceaccount.com%2F20250414%2Fauto%2Fstorage%2Fgoog4_request&X-Goog-Date=20250414T151306Z&X-Goog-Expires=86399&X-Goog-Signature=0bf0b2bd8b586c4629cadf1b33955ead125425c9929b4db02171f92ae5780d32456d214d433d6d319596799bcbcb937ce5a1f7aee1c48cb9ac1c99a4aa3fc2356f2a3c710a9a6654c05b606b01ca1e97d9eaae6993f275d0c5967cccf57e2fe28f0f5bd4bca6f0f0c63aa5c6ce17990fb8c9f433425f087c76eec8c8916ab0eb376a85e82f84dce56bec266fd96c22c1f9354c90c63719ece160fd1bb61261f79adf64168e7b3c2b680ecc3e6025130fbc86e9885ee5d0cd41b40a6e82022f2115d5b5a683323cee548e6365923416e21c23b9daf0e147f86c6180af83d1df6a3f54eb98d1d885b465d7933177b8fb84b0eb944852291b001a237e586a9d35cf&X-Goog-SignedHeaders=host&X-User=2931823730 (Caused by NewConnectionError('<urllib3.connection.HTTPSConnection object at 0x7f86f83d1de0>: Failed to establish a new connection: [Errno 101] Network is unreachable'))
2025-04-14 15:13:45,117 ERROR   wandb-upload_0:16610 [internal_api.py:upload_file():2558] upload_file request headers: {'User-Agent': 'python-requests/2.32.3', 'Accept-Encoding': 'gzip, deflate, br', 'Accept': '*/*', 'Connection': 'keep-alive', 'Content-Length': '2380'}
2025-04-14 15:13:45,117 ERROR   wandb-upload_0:16610 [internal_api.py:upload_file():2560] upload_file response body: 
2025-04-14 15:13:49,552 ERROR   wandb-upload_5:16610 [internal_api.py:upload_file():2556] upload_file exception https://storage.googleapis.com/wandb-production.appspot.com/2931823730-harbin-institute-of-technology/ltu-as/sro21n02/wandb-summary.json?X-Goog-Algorithm=GOOG4-RSA-SHA256&X-Goog-Credential=gorilla-files-url-signer-man%40wandb-production.iam.gserviceaccount.com%2F20250414%2Fauto%2Fstorage%2Fgoog4_request&X-Goog-Date=20250414T151333Z&X-Goog-Expires=86399&X-Goog-Signature=1c62f3b6170db7b48818210bba95fa79cd7f43ca58b6649b0428570d3e8fcd4ca90cf9b087445b3c029a3a5140f42e4d052866f04bd68d93eb3ee96043ef83b1d04c735088f00ff00499677a95cd84c38a034bc58f50f0e30e8b710c7d003d84d488f7ad190ad01237f37aad21878dd5cafe07a27bcac5fb00a0c4ede0be7f9673e8d79381fa2ee8915ffddb163c4c3cefd67b96d065f83bf0d938fd38a763c3d75406bc83901267d8e75a5585d8862a7c7d68ab04ad3b9427824ed9f88ceee45e62757cdc63f7a87cf0e9ac9acb56705639c1d06018727ff251278bfcf3e68f5cdc69b06df7b41f6e080f2353f45a3e19e1da994c54be7bb021e8118023095f&X-Goog-SignedHeaders=host&X-User=2931823730: HTTPSConnectionPool(host='storage.googleapis.com', port=443): Max retries exceeded with url: /wandb-production.appspot.com/2931823730-harbin-institute-of-technology/ltu-as/sro21n02/wandb-summary.json?X-Goog-Algorithm=GOOG4-RSA-SHA256&X-Goog-Credential=gorilla-files-url-signer-man%40wandb-production.iam.gserviceaccount.com%2F20250414%2Fauto%2Fstorage%2Fgoog4_request&X-Goog-Date=20250414T151333Z&X-Goog-Expires=86399&X-Goog-Signature=1c62f3b6170db7b48818210bba95fa79cd7f43ca58b6649b0428570d3e8fcd4ca90cf9b087445b3c029a3a5140f42e4d052866f04bd68d93eb3ee96043ef83b1d04c735088f00ff00499677a95cd84c38a034bc58f50f0e30e8b710c7d003d84d488f7ad190ad01237f37aad21878dd5cafe07a27bcac5fb00a0c4ede0be7f9673e8d79381fa2ee8915ffddb163c4c3cefd67b96d065f83bf0d938fd38a763c3d75406bc83901267d8e75a5585d8862a7c7d68ab04ad3b9427824ed9f88ceee45e62757cdc63f7a87cf0e9ac9acb56705639c1d06018727ff251278bfcf3e68f5cdc69b06df7b41f6e080f2353f45a3e19e1da994c54be7bb021e8118023095f&X-Goog-SignedHeaders=host&X-User=2931823730 (Caused by NewConnectionError('<urllib3.connection.HTTPSConnection object at 0x7f87014ec220>: Failed to establish a new connection: [Errno 101] Network is unreachable'))
2025-04-14 15:13:49,552 ERROR   wandb-upload_5:16610 [internal_api.py:upload_file():2558] upload_file request headers: {'User-Agent': 'python-requests/2.32.3', 'Accept-Encoding': 'gzip, deflate, br', 'Accept': '*/*', 'Connection': 'keep-alive', 'Content-Length': '28'}
2025-04-14 15:13:49,552 ERROR   wandb-upload_5:16610 [internal_api.py:upload_file():2560] upload_file response body: 
2025-04-14 15:13:49,646 ERROR   wandb-upload_4:16610 [internal_api.py:upload_file():2556] upload_file exception https://storage.googleapis.com/wandb-production.appspot.com/2931823730-harbin-institute-of-technology/ltu-as/sro21n02/output.log?X-Goog-Algorithm=GOOG4-RSA-SHA256&X-Goog-Credential=gorilla-files-url-signer-man%40wandb-production.iam.gserviceaccount.com%2F20250414%2Fauto%2Fstorage%2Fgoog4_request&X-Goog-Date=20250414T151333Z&X-Goog-Expires=86399&X-Goog-Signature=c1b3d7a13962ac49c7c2542d07fc489216f963e1200f55034b20dcf718bfadea225d00f606037301d3163d0bcc6c723ac40ba61e901e43e0c2b4affc0cf59d8d0e87c42a048461dfb388bee91715da165b7d56016980b76e11e57db92a471bec391c0ce0681ed11eb937b2400195fa49b7e00e37551763edd99ecc1683df8aed7f765f565688bf99dcdbfaa26f25bb16cb58d2cad4e1dc46b0214559475d19c210a94c0e623f1e9b7363b55a7b2ee7730ac02de63bcd07075d4d1cf12cc2d74be322f92ff01972c74aea148c7f4e2ecd2e53d3ed5ca31db45eb0fb37c10edd7cdc41c02049ec2c67dfe9acb64b40903a5a22d0e059999942328737c2397a7dbf&X-Goog-SignedHeaders=host&X-User=2931823730: HTTPSConnectionPool(host='storage.googleapis.com', port=443): Max retries exceeded with url: /wandb-production.appspot.com/2931823730-harbin-institute-of-technology/ltu-as/sro21n02/output.log?X-Goog-Algorithm=GOOG4-RSA-SHA256&X-Goog-Credential=gorilla-files-url-signer-man%40wandb-production.iam.gserviceaccount.com%2F20250414%2Fauto%2Fstorage%2Fgoog4_request&X-Goog-Date=20250414T151333Z&X-Goog-Expires=86399&X-Goog-Signature=c1b3d7a13962ac49c7c2542d07fc489216f963e1200f55034b20dcf718bfadea225d00f606037301d3163d0bcc6c723ac40ba61e901e43e0c2b4affc0cf59d8d0e87c42a048461dfb388bee91715da165b7d56016980b76e11e57db92a471bec391c0ce0681ed11eb937b2400195fa49b7e00e37551763edd99ecc1683df8aed7f765f565688bf99dcdbfaa26f25bb16cb58d2cad4e1dc46b0214559475d19c210a94c0e623f1e9b7363b55a7b2ee7730ac02de63bcd07075d4d1cf12cc2d74be322f92ff01972c74aea148c7f4e2ecd2e53d3ed5ca31db45eb0fb37c10edd7cdc41c02049ec2c67dfe9acb64b40903a5a22d0e059999942328737c2397a7dbf&X-Goog-SignedHeaders=host&X-User=2931823730 (Caused by NewConnectionError('<urllib3.connection.HTTPSConnection object at 0x7f87003be7a0>: Failed to establish a new connection: [Errno 101] Network is unreachable'))
2025-04-14 15:13:49,646 ERROR   wandb-upload_4:16610 [internal_api.py:upload_file():2558] upload_file request headers: {'User-Agent': 'python-requests/2.32.3', 'Accept-Encoding': 'gzip, deflate, br', 'Accept': '*/*', 'Connection': 'keep-alive', 'Content-Length': '4916'}
2025-04-14 15:13:49,646 ERROR   wandb-upload_4:16610 [internal_api.py:upload_file():2560] upload_file response body: 
2025-04-14 15:13:50,589 ERROR   wandb-upload_1:16610 [internal_api.py:upload_file():2556] upload_file exception https://storage.googleapis.com/wandb-production.appspot.com/2931823730-harbin-institute-of-technology/ltu-as/sro21n02/config.yaml?X-Goog-Algorithm=GOOG4-RSA-SHA256&X-Goog-Credential=gorilla-files-url-signer-man%40wandb-production.iam.gserviceaccount.com%2F20250414%2Fauto%2Fstorage%2Fgoog4_request&X-Goog-Date=20250414T151333Z&X-Goog-Expires=86399&X-Goog-Signature=2f73e93adaa04407e79c1d548385c55943fdf3db36963bfdf350643aa1b36dae813f5626aaaa750a4bede213fdbf01567d7849c255d958ccd82bb15aae31926ef2cb8142328b26778f2203ecbf35a11e72c8b6968ecfdc910d13ecb0d1c8203f98f95824cddf7c77c6d98174c1a272e56c9fee7836d9b384f88d0e5366792f80e0ac49470f62e30e729583e849f555474ab8021dfebe960bf62ab5c74c8a5de192142c1278ce895934f2e559a74830fc98bbe1048f7b1480b81d89ce5d5da5e4ead191f9e8785bf30c7c829de0a9685a99a16ca07c58d7690c12c5d4c96a20f270453ab953c96813cc31dfe1cb8ad8af66ef18162ab0b43a8eda9c5df2be20e9&X-Goog-SignedHeaders=host&X-User=2931823730: HTTPSConnectionPool(host='storage.googleapis.com', port=443): Max retries exceeded with url: /wandb-production.appspot.com/2931823730-harbin-institute-of-technology/ltu-as/sro21n02/config.yaml?X-Goog-Algorithm=GOOG4-RSA-SHA256&X-Goog-Credential=gorilla-files-url-signer-man%40wandb-production.iam.gserviceaccount.com%2F20250414%2Fauto%2Fstorage%2Fgoog4_request&X-Goog-Date=20250414T151333Z&X-Goog-Expires=86399&X-Goog-Signature=2f73e93adaa04407e79c1d548385c55943fdf3db36963bfdf350643aa1b36dae813f5626aaaa750a4bede213fdbf01567d7849c255d958ccd82bb15aae31926ef2cb8142328b26778f2203ecbf35a11e72c8b6968ecfdc910d13ecb0d1c8203f98f95824cddf7c77c6d98174c1a272e56c9fee7836d9b384f88d0e5366792f80e0ac49470f62e30e729583e849f555474ab8021dfebe960bf62ab5c74c8a5de192142c1278ce895934f2e559a74830fc98bbe1048f7b1480b81d89ce5d5da5e4ead191f9e8785bf30c7c829de0a9685a99a16ca07c58d7690c12c5d4c96a20f270453ab953c96813cc31dfe1cb8ad8af66ef18162ab0b43a8eda9c5df2be20e9&X-Goog-SignedHeaders=host&X-User=2931823730 (Caused by NewConnectionError('<urllib3.connection.HTTPSConnection object at 0x7f87003bf460>: Failed to establish a new connection: [Errno 101] Network is unreachable'))
2025-04-14 15:13:50,589 ERROR   wandb-upload_1:16610 [internal_api.py:upload_file():2558] upload_file request headers: {'User-Agent': 'python-requests/2.32.3', 'Accept-Encoding': 'gzip, deflate, br', 'Accept': '*/*', 'Connection': 'keep-alive', 'Content-Length': '8685'}
2025-04-14 15:13:50,589 ERROR   wandb-upload_1:16610 [internal_api.py:upload_file():2560] upload_file response body: 
2025-04-14 15:13:51,126 ERROR   wandb-upload_3:16610 [internal_api.py:upload_file():2556] upload_file exception https://storage.googleapis.com/wandb-production.appspot.com/2931823730-harbin-institute-of-technology/ltu-as/sro21n02/conda-environment.yaml?X-Goog-Algorithm=GOOG4-RSA-SHA256&X-Goog-Credential=gorilla-files-url-signer-man%40wandb-production.iam.gserviceaccount.com%2F20250414%2Fauto%2Fstorage%2Fgoog4_request&X-Goog-Date=20250414T151333Z&X-Goog-Expires=86399&X-Goog-Signature=8baaa21661194630a1882e9ed7d315c11d50e573164af7eea55e95ea5953fd3753e98b46a842fe08f503515df18f8fec23a1b271a20bb7458c002170e1ebdd8483b5e2add7e3a8be1f646f1e2361148d782932620251502d2a34b98fc93d70437b2f3c1a672cc8883b684e4df9db83cff0b6477537a2c9f56b12f33118f45063e2abeb73a874b52185f0e7b731bb801545fd9d9cdba619ce48938fed831ab0e64f80cb3e5b15e0de3825420374059423d9ff49f5dd49b3f143c76929b5a9acd4e508e6817a9f3d25eb0441ab4f9be1c4523af1abfaf83ba139a7bffef05151b68a34b1f37c4e2fb49eb2e9893dc7553d87dfef018ac0c0995b7e1898f230da7d&X-Goog-SignedHeaders=host&X-User=2931823730: HTTPSConnectionPool(host='storage.googleapis.com', port=443): Max retries exceeded with url: /wandb-production.appspot.com/2931823730-harbin-institute-of-technology/ltu-as/sro21n02/conda-environment.yaml?X-Goog-Algorithm=GOOG4-RSA-SHA256&X-Goog-Credential=gorilla-files-url-signer-man%40wandb-production.iam.gserviceaccount.com%2F20250414%2Fauto%2Fstorage%2Fgoog4_request&X-Goog-Date=20250414T151333Z&X-Goog-Expires=86399&X-Goog-Signature=8baaa21661194630a1882e9ed7d315c11d50e573164af7eea55e95ea5953fd3753e98b46a842fe08f503515df18f8fec23a1b271a20bb7458c002170e1ebdd8483b5e2add7e3a8be1f646f1e2361148d782932620251502d2a34b98fc93d70437b2f3c1a672cc8883b684e4df9db83cff0b6477537a2c9f56b12f33118f45063e2abeb73a874b52185f0e7b731bb801545fd9d9cdba619ce48938fed831ab0e64f80cb3e5b15e0de3825420374059423d9ff49f5dd49b3f143c76929b5a9acd4e508e6817a9f3d25eb0441ab4f9be1c4523af1abfaf83ba139a7bffef05151b68a34b1f37c4e2fb49eb2e9893dc7553d87dfef018ac0c0995b7e1898f230da7d&X-Goog-SignedHeaders=host&X-User=2931823730 (Caused by NewConnectionError('<urllib3.connection.HTTPSConnection object at 0x7f87003be620>: Failed to establish a new connection: [Errno 101] Network is unreachable'))
2025-04-14 15:13:51,127 ERROR   wandb-upload_3:16610 [internal_api.py:upload_file():2558] upload_file request headers: {'User-Agent': 'python-requests/2.32.3', 'Accept-Encoding': 'gzip, deflate, br', 'Accept': '*/*', 'Connection': 'keep-alive', 'Content-Length': '12277'}
2025-04-14 15:13:51,127 ERROR   wandb-upload_3:16610 [internal_api.py:upload_file():2560] upload_file response body: 
2025-04-14 15:13:51,335 ERROR   wandb-upload_2:16610 [internal_api.py:upload_file():2556] upload_file exception https://storage.googleapis.com/wandb-production.appspot.com/2931823730-harbin-institute-of-technology/ltu-as/sro21n02/requirements.txt?X-Goog-Algorithm=GOOG4-RSA-SHA256&X-Goog-Credential=gorilla-files-url-signer-man%40wandb-production.iam.gserviceaccount.com%2F20250414%2Fauto%2Fstorage%2Fgoog4_request&X-Goog-Date=20250414T151333Z&X-Goog-Expires=86399&X-Goog-Signature=b68928fa0e2b525ca9c2a4d65e8ea36df3dbec3ea8e07a9b57488ed89a18368728d569f35fd3a3b6ca9d006c8392e823f6d6fbef9acdedfdfbdea9dad501ddc1b68a8c3da4ef9a3d38b5151d52891b7d34e027965272f5738f0c9424f5f56686d85cd3224ecb738c6004f884ec680ea391556784a77a9635964958cca0550fb2964a9d249f9592c4612a80c37dacfa24de7da22cb81cc60580456b322e673c980e695f58ed8f8ec247a7076cd46757b6ed864432d0b7a8ebfe3798a4d4748a28cc0c109743ab0cc91f1b3aec691745a5a876dd34d6743fa8b507c86f6f5f6c4e2a5436c6a2e552806d88cd2cd6c69fae0fb8beb7a580df5fa7b602788538d255&X-Goog-SignedHeaders=host&X-User=2931823730: HTTPSConnectionPool(host='storage.googleapis.com', port=443): Max retries exceeded with url: /wandb-production.appspot.com/2931823730-harbin-institute-of-technology/ltu-as/sro21n02/requirements.txt?X-Goog-Algorithm=GOOG4-RSA-SHA256&X-Goog-Credential=gorilla-files-url-signer-man%40wandb-production.iam.gserviceaccount.com%2F20250414%2Fauto%2Fstorage%2Fgoog4_request&X-Goog-Date=20250414T151333Z&X-Goog-Expires=86399&X-Goog-Signature=b68928fa0e2b525ca9c2a4d65e8ea36df3dbec3ea8e07a9b57488ed89a18368728d569f35fd3a3b6ca9d006c8392e823f6d6fbef9acdedfdfbdea9dad501ddc1b68a8c3da4ef9a3d38b5151d52891b7d34e027965272f5738f0c9424f5f56686d85cd3224ecb738c6004f884ec680ea391556784a77a9635964958cca0550fb2964a9d249f9592c4612a80c37dacfa24de7da22cb81cc60580456b322e673c980e695f58ed8f8ec247a7076cd46757b6ed864432d0b7a8ebfe3798a4d4748a28cc0c109743ab0cc91f1b3aec691745a5a876dd34d6743fa8b507c86f6f5f6c4e2a5436c6a2e552806d88cd2cd6c69fae0fb8beb7a580df5fa7b602788538d255&X-Goog-SignedHeaders=host&X-User=2931823730 (Caused by NewConnectionError('<urllib3.connection.HTTPSConnection object at 0x7f87003bcb50>: Failed to establish a new connection: [Errno 101] Network is unreachable'))
2025-04-14 15:13:51,335 ERROR   wandb-upload_2:16610 [internal_api.py:upload_file():2558] upload_file request headers: {'User-Agent': 'python-requests/2.32.3', 'Accept-Encoding': 'gzip, deflate, br', 'Accept': '*/*', 'Connection': 'keep-alive', 'Content-Length': '5836'}
2025-04-14 15:13:51,335 ERROR   wandb-upload_2:16610 [internal_api.py:upload_file():2560] upload_file response body: 
2025-04-14 15:14:08,713 ERROR   wandb-upload_4:16610 [internal_api.py:upload_file():2556] upload_file exception https://storage.googleapis.com/wandb-production.appspot.com/2931823730-harbin-institute-of-technology/ltu-as/sro21n02/output.log?X-Goog-Algorithm=GOOG4-RSA-SHA256&X-Goog-Credential=gorilla-files-url-signer-man%40wandb-production.iam.gserviceaccount.com%2F20250414%2Fauto%2Fstorage%2Fgoog4_request&X-Goog-Date=20250414T151333Z&X-Goog-Expires=86399&X-Goog-Signature=c1b3d7a13962ac49c7c2542d07fc489216f963e1200f55034b20dcf718bfadea225d00f606037301d3163d0bcc6c723ac40ba61e901e43e0c2b4affc0cf59d8d0e87c42a048461dfb388bee91715da165b7d56016980b76e11e57db92a471bec391c0ce0681ed11eb937b2400195fa49b7e00e37551763edd99ecc1683df8aed7f765f565688bf99dcdbfaa26f25bb16cb58d2cad4e1dc46b0214559475d19c210a94c0e623f1e9b7363b55a7b2ee7730ac02de63bcd07075d4d1cf12cc2d74be322f92ff01972c74aea148c7f4e2ecd2e53d3ed5ca31db45eb0fb37c10edd7cdc41c02049ec2c67dfe9acb64b40903a5a22d0e059999942328737c2397a7dbf&X-Goog-SignedHeaders=host&X-User=2931823730: HTTPSConnectionPool(host='storage.googleapis.com', port=443): Max retries exceeded with url: /wandb-production.appspot.com/2931823730-harbin-institute-of-technology/ltu-as/sro21n02/output.log?X-Goog-Algorithm=GOOG4-RSA-SHA256&X-Goog-Credential=gorilla-files-url-signer-man%40wandb-production.iam.gserviceaccount.com%2F20250414%2Fauto%2Fstorage%2Fgoog4_request&X-Goog-Date=20250414T151333Z&X-Goog-Expires=86399&X-Goog-Signature=c1b3d7a13962ac49c7c2542d07fc489216f963e1200f55034b20dcf718bfadea225d00f606037301d3163d0bcc6c723ac40ba61e901e43e0c2b4affc0cf59d8d0e87c42a048461dfb388bee91715da165b7d56016980b76e11e57db92a471bec391c0ce0681ed11eb937b2400195fa49b7e00e37551763edd99ecc1683df8aed7f765f565688bf99dcdbfaa26f25bb16cb58d2cad4e1dc46b0214559475d19c210a94c0e623f1e9b7363b55a7b2ee7730ac02de63bcd07075d4d1cf12cc2d74be322f92ff01972c74aea148c7f4e2ecd2e53d3ed5ca31db45eb0fb37c10edd7cdc41c02049ec2c67dfe9acb64b40903a5a22d0e059999942328737c2397a7dbf&X-Goog-SignedHeaders=host&X-User=2931823730 (Caused by NewConnectionError('<urllib3.connection.HTTPSConnection object at 0x7f87003be2c0>: Failed to establish a new connection: [Errno 101] Network is unreachable'))
2025-04-14 15:14:08,714 ERROR   wandb-upload_4:16610 [internal_api.py:upload_file():2558] upload_file request headers: {'User-Agent': 'python-requests/2.32.3', 'Accept-Encoding': 'gzip, deflate, br', 'Accept': '*/*', 'Connection': 'keep-alive', 'Content-Length': '4916'}
2025-04-14 15:14:08,714 ERROR   wandb-upload_4:16610 [internal_api.py:upload_file():2560] upload_file response body: 
2025-04-14 15:14:09,111 ERROR   wandb-upload_3:16610 [internal_api.py:upload_file():2556] upload_file exception https://storage.googleapis.com/wandb-production.appspot.com/2931823730-harbin-institute-of-technology/ltu-as/sro21n02/conda-environment.yaml?X-Goog-Algorithm=GOOG4-RSA-SHA256&X-Goog-Credential=gorilla-files-url-signer-man%40wandb-production.iam.gserviceaccount.com%2F20250414%2Fauto%2Fstorage%2Fgoog4_request&X-Goog-Date=20250414T151333Z&X-Goog-Expires=86399&X-Goog-Signature=8baaa21661194630a1882e9ed7d315c11d50e573164af7eea55e95ea5953fd3753e98b46a842fe08f503515df18f8fec23a1b271a20bb7458c002170e1ebdd8483b5e2add7e3a8be1f646f1e2361148d782932620251502d2a34b98fc93d70437b2f3c1a672cc8883b684e4df9db83cff0b6477537a2c9f56b12f33118f45063e2abeb73a874b52185f0e7b731bb801545fd9d9cdba619ce48938fed831ab0e64f80cb3e5b15e0de3825420374059423d9ff49f5dd49b3f143c76929b5a9acd4e508e6817a9f3d25eb0441ab4f9be1c4523af1abfaf83ba139a7bffef05151b68a34b1f37c4e2fb49eb2e9893dc7553d87dfef018ac0c0995b7e1898f230da7d&X-Goog-SignedHeaders=host&X-User=2931823730: HTTPSConnectionPool(host='storage.googleapis.com', port=443): Max retries exceeded with url: /wandb-production.appspot.com/2931823730-harbin-institute-of-technology/ltu-as/sro21n02/conda-environment.yaml?X-Goog-Algorithm=GOOG4-RSA-SHA256&X-Goog-Credential=gorilla-files-url-signer-man%40wandb-production.iam.gserviceaccount.com%2F20250414%2Fauto%2Fstorage%2Fgoog4_request&X-Goog-Date=20250414T151333Z&X-Goog-Expires=86399&X-Goog-Signature=8baaa21661194630a1882e9ed7d315c11d50e573164af7eea55e95ea5953fd3753e98b46a842fe08f503515df18f8fec23a1b271a20bb7458c002170e1ebdd8483b5e2add7e3a8be1f646f1e2361148d782932620251502d2a34b98fc93d70437b2f3c1a672cc8883b684e4df9db83cff0b6477537a2c9f56b12f33118f45063e2abeb73a874b52185f0e7b731bb801545fd9d9cdba619ce48938fed831ab0e64f80cb3e5b15e0de3825420374059423d9ff49f5dd49b3f143c76929b5a9acd4e508e6817a9f3d25eb0441ab4f9be1c4523af1abfaf83ba139a7bffef05151b68a34b1f37c4e2fb49eb2e9893dc7553d87dfef018ac0c0995b7e1898f230da7d&X-Goog-SignedHeaders=host&X-User=2931823730 (Caused by NewConnectionError('<urllib3.connection.HTTPSConnection object at 0x7f87003552a0>: Failed to establish a new connection: [Errno 101] Network is unreachable'))
2025-04-14 15:14:09,112 ERROR   wandb-upload_3:16610 [internal_api.py:upload_file():2558] upload_file request headers: {'User-Agent': 'python-requests/2.32.3', 'Accept-Encoding': 'gzip, deflate, br', 'Accept': '*/*', 'Connection': 'keep-alive', 'Content-Length': '12277'}
2025-04-14 15:14:09,112 ERROR   wandb-upload_3:16610 [internal_api.py:upload_file():2560] upload_file response body: 
2025-04-14 15:14:09,461 ERROR   wandb-upload_5:16610 [internal_api.py:upload_file():2556] upload_file exception https://storage.googleapis.com/wandb-production.appspot.com/2931823730-harbin-institute-of-technology/ltu-as/sro21n02/wandb-summary.json?X-Goog-Algorithm=GOOG4-RSA-SHA256&X-Goog-Credential=gorilla-files-url-signer-man%40wandb-production.iam.gserviceaccount.com%2F20250414%2Fauto%2Fstorage%2Fgoog4_request&X-Goog-Date=20250414T151333Z&X-Goog-Expires=86399&X-Goog-Signature=1c62f3b6170db7b48818210bba95fa79cd7f43ca58b6649b0428570d3e8fcd4ca90cf9b087445b3c029a3a5140f42e4d052866f04bd68d93eb3ee96043ef83b1d04c735088f00ff00499677a95cd84c38a034bc58f50f0e30e8b710c7d003d84d488f7ad190ad01237f37aad21878dd5cafe07a27bcac5fb00a0c4ede0be7f9673e8d79381fa2ee8915ffddb163c4c3cefd67b96d065f83bf0d938fd38a763c3d75406bc83901267d8e75a5585d8862a7c7d68ab04ad3b9427824ed9f88ceee45e62757cdc63f7a87cf0e9ac9acb56705639c1d06018727ff251278bfcf3e68f5cdc69b06df7b41f6e080f2353f45a3e19e1da994c54be7bb021e8118023095f&X-Goog-SignedHeaders=host&X-User=2931823730: HTTPSConnectionPool(host='storage.googleapis.com', port=443): Max retries exceeded with url: /wandb-production.appspot.com/2931823730-harbin-institute-of-technology/ltu-as/sro21n02/wandb-summary.json?X-Goog-Algorithm=GOOG4-RSA-SHA256&X-Goog-Credential=gorilla-files-url-signer-man%40wandb-production.iam.gserviceaccount.com%2F20250414%2Fauto%2Fstorage%2Fgoog4_request&X-Goog-Date=20250414T151333Z&X-Goog-Expires=86399&X-Goog-Signature=1c62f3b6170db7b48818210bba95fa79cd7f43ca58b6649b0428570d3e8fcd4ca90cf9b087445b3c029a3a5140f42e4d052866f04bd68d93eb3ee96043ef83b1d04c735088f00ff00499677a95cd84c38a034bc58f50f0e30e8b710c7d003d84d488f7ad190ad01237f37aad21878dd5cafe07a27bcac5fb00a0c4ede0be7f9673e8d79381fa2ee8915ffddb163c4c3cefd67b96d065f83bf0d938fd38a763c3d75406bc83901267d8e75a5585d8862a7c7d68ab04ad3b9427824ed9f88ceee45e62757cdc63f7a87cf0e9ac9acb56705639c1d06018727ff251278bfcf3e68f5cdc69b06df7b41f6e080f2353f45a3e19e1da994c54be7bb021e8118023095f&X-Goog-SignedHeaders=host&X-User=2931823730 (Caused by NewConnectionError('<urllib3.connection.HTTPSConnection object at 0x7f8700355120>: Failed to establish a new connection: [Errno 101] Network is unreachable'))
2025-04-14 15:14:09,461 ERROR   wandb-upload_5:16610 [internal_api.py:upload_file():2558] upload_file request headers: {'User-Agent': 'python-requests/2.32.3', 'Accept-Encoding': 'gzip, deflate, br', 'Accept': '*/*', 'Connection': 'keep-alive', 'Content-Length': '28'}
2025-04-14 15:14:09,461 ERROR   wandb-upload_5:16610 [internal_api.py:upload_file():2560] upload_file response body: 
2025-04-14 15:14:10,357 ERROR   wandb-upload_1:16610 [internal_api.py:upload_file():2556] upload_file exception https://storage.googleapis.com/wandb-production.appspot.com/2931823730-harbin-institute-of-technology/ltu-as/sro21n02/config.yaml?X-Goog-Algorithm=GOOG4-RSA-SHA256&X-Goog-Credential=gorilla-files-url-signer-man%40wandb-production.iam.gserviceaccount.com%2F20250414%2Fauto%2Fstorage%2Fgoog4_request&X-Goog-Date=20250414T151333Z&X-Goog-Expires=86399&X-Goog-Signature=2f73e93adaa04407e79c1d548385c55943fdf3db36963bfdf350643aa1b36dae813f5626aaaa750a4bede213fdbf01567d7849c255d958ccd82bb15aae31926ef2cb8142328b26778f2203ecbf35a11e72c8b6968ecfdc910d13ecb0d1c8203f98f95824cddf7c77c6d98174c1a272e56c9fee7836d9b384f88d0e5366792f80e0ac49470f62e30e729583e849f555474ab8021dfebe960bf62ab5c74c8a5de192142c1278ce895934f2e559a74830fc98bbe1048f7b1480b81d89ce5d5da5e4ead191f9e8785bf30c7c829de0a9685a99a16ca07c58d7690c12c5d4c96a20f270453ab953c96813cc31dfe1cb8ad8af66ef18162ab0b43a8eda9c5df2be20e9&X-Goog-SignedHeaders=host&X-User=2931823730: HTTPSConnectionPool(host='storage.googleapis.com', port=443): Max retries exceeded with url: /wandb-production.appspot.com/2931823730-harbin-institute-of-technology/ltu-as/sro21n02/config.yaml?X-Goog-Algorithm=GOOG4-RSA-SHA256&X-Goog-Credential=gorilla-files-url-signer-man%40wandb-production.iam.gserviceaccount.com%2F20250414%2Fauto%2Fstorage%2Fgoog4_request&X-Goog-Date=20250414T151333Z&X-Goog-Expires=86399&X-Goog-Signature=2f73e93adaa04407e79c1d548385c55943fdf3db36963bfdf350643aa1b36dae813f5626aaaa750a4bede213fdbf01567d7849c255d958ccd82bb15aae31926ef2cb8142328b26778f2203ecbf35a11e72c8b6968ecfdc910d13ecb0d1c8203f98f95824cddf7c77c6d98174c1a272e56c9fee7836d9b384f88d0e5366792f80e0ac49470f62e30e729583e849f555474ab8021dfebe960bf62ab5c74c8a5de192142c1278ce895934f2e559a74830fc98bbe1048f7b1480b81d89ce5d5da5e4ead191f9e8785bf30c7c829de0a9685a99a16ca07c58d7690c12c5d4c96a20f270453ab953c96813cc31dfe1cb8ad8af66ef18162ab0b43a8eda9c5df2be20e9&X-Goog-SignedHeaders=host&X-User=2931823730 (Caused by NewConnectionError('<urllib3.connection.HTTPSConnection object at 0x7f86f83d1de0>: Failed to establish a new connection: [Errno 101] Network is unreachable'))
2025-04-14 15:14:10,358 ERROR   wandb-upload_1:16610 [internal_api.py:upload_file():2558] upload_file request headers: {'User-Agent': 'python-requests/2.32.3', 'Accept-Encoding': 'gzip, deflate, br', 'Accept': '*/*', 'Connection': 'keep-alive', 'Content-Length': '8685'}
2025-04-14 15:14:10,358 ERROR   wandb-upload_1:16610 [internal_api.py:upload_file():2560] upload_file response body: 
2025-04-14 15:14:11,019 ERROR   wandb-upload_2:16610 [internal_api.py:upload_file():2556] upload_file exception https://storage.googleapis.com/wandb-production.appspot.com/2931823730-harbin-institute-of-technology/ltu-as/sro21n02/requirements.txt?X-Goog-Algorithm=GOOG4-RSA-SHA256&X-Goog-Credential=gorilla-files-url-signer-man%40wandb-production.iam.gserviceaccount.com%2F20250414%2Fauto%2Fstorage%2Fgoog4_request&X-Goog-Date=20250414T151333Z&X-Goog-Expires=86399&X-Goog-Signature=b68928fa0e2b525ca9c2a4d65e8ea36df3dbec3ea8e07a9b57488ed89a18368728d569f35fd3a3b6ca9d006c8392e823f6d6fbef9acdedfdfbdea9dad501ddc1b68a8c3da4ef9a3d38b5151d52891b7d34e027965272f5738f0c9424f5f56686d85cd3224ecb738c6004f884ec680ea391556784a77a9635964958cca0550fb2964a9d249f9592c4612a80c37dacfa24de7da22cb81cc60580456b322e673c980e695f58ed8f8ec247a7076cd46757b6ed864432d0b7a8ebfe3798a4d4748a28cc0c109743ab0cc91f1b3aec691745a5a876dd34d6743fa8b507c86f6f5f6c4e2a5436c6a2e552806d88cd2cd6c69fae0fb8beb7a580df5fa7b602788538d255&X-Goog-SignedHeaders=host&X-User=2931823730: HTTPSConnectionPool(host='storage.googleapis.com', port=443): Max retries exceeded with url: /wandb-production.appspot.com/2931823730-harbin-institute-of-technology/ltu-as/sro21n02/requirements.txt?X-Goog-Algorithm=GOOG4-RSA-SHA256&X-Goog-Credential=gorilla-files-url-signer-man%40wandb-production.iam.gserviceaccount.com%2F20250414%2Fauto%2Fstorage%2Fgoog4_request&X-Goog-Date=20250414T151333Z&X-Goog-Expires=86399&X-Goog-Signature=b68928fa0e2b525ca9c2a4d65e8ea36df3dbec3ea8e07a9b57488ed89a18368728d569f35fd3a3b6ca9d006c8392e823f6d6fbef9acdedfdfbdea9dad501ddc1b68a8c3da4ef9a3d38b5151d52891b7d34e027965272f5738f0c9424f5f56686d85cd3224ecb738c6004f884ec680ea391556784a77a9635964958cca0550fb2964a9d249f9592c4612a80c37dacfa24de7da22cb81cc60580456b322e673c980e695f58ed8f8ec247a7076cd46757b6ed864432d0b7a8ebfe3798a4d4748a28cc0c109743ab0cc91f1b3aec691745a5a876dd34d6743fa8b507c86f6f5f6c4e2a5436c6a2e552806d88cd2cd6c69fae0fb8beb7a580df5fa7b602788538d255&X-Goog-SignedHeaders=host&X-User=2931823730 (Caused by NewConnectionError('<urllib3.connection.HTTPSConnection object at 0x7f86f83d1840>: Failed to establish a new connection: [Errno 101] Network is unreachable'))
2025-04-14 15:14:11,019 ERROR   wandb-upload_2:16610 [internal_api.py:upload_file():2558] upload_file request headers: {'User-Agent': 'python-requests/2.32.3', 'Accept-Encoding': 'gzip, deflate, br', 'Accept': '*/*', 'Connection': 'keep-alive', 'Content-Length': '5836'}
2025-04-14 15:14:11,020 ERROR   wandb-upload_2:16610 [internal_api.py:upload_file():2560] upload_file response body: 
2025-04-14 15:14:20,362 ERROR   wandb-upload_0:16610 [internal_api.py:upload_file():2556] upload_file exception https://storage.googleapis.com/wandb-production.appspot.com/2931823730-harbin-institute-of-technology/ltu-as/sro21n02/wandb-metadata.json?X-Goog-Algorithm=GOOG4-RSA-SHA256&X-Goog-Credential=gorilla-files-url-signer-man%40wandb-production.iam.gserviceaccount.com%2F20250414%2Fauto%2Fstorage%2Fgoog4_request&X-Goog-Date=20250414T151306Z&X-Goog-Expires=86399&X-Goog-Signature=0bf0b2bd8b586c4629cadf1b33955ead125425c9929b4db02171f92ae5780d32456d214d433d6d319596799bcbcb937ce5a1f7aee1c48cb9ac1c99a4aa3fc2356f2a3c710a9a6654c05b606b01ca1e97d9eaae6993f275d0c5967cccf57e2fe28f0f5bd4bca6f0f0c63aa5c6ce17990fb8c9f433425f087c76eec8c8916ab0eb376a85e82f84dce56bec266fd96c22c1f9354c90c63719ece160fd1bb61261f79adf64168e7b3c2b680ecc3e6025130fbc86e9885ee5d0cd41b40a6e82022f2115d5b5a683323cee548e6365923416e21c23b9daf0e147f86c6180af83d1df6a3f54eb98d1d885b465d7933177b8fb84b0eb944852291b001a237e586a9d35cf&X-Goog-SignedHeaders=host&X-User=2931823730: HTTPSConnectionPool(host='storage.googleapis.com', port=443): Max retries exceeded with url: /wandb-production.appspot.com/2931823730-harbin-institute-of-technology/ltu-as/sro21n02/wandb-metadata.json?X-Goog-Algorithm=GOOG4-RSA-SHA256&X-Goog-Credential=gorilla-files-url-signer-man%40wandb-production.iam.gserviceaccount.com%2F20250414%2Fauto%2Fstorage%2Fgoog4_request&X-Goog-Date=20250414T151306Z&X-Goog-Expires=86399&X-Goog-Signature=0bf0b2bd8b586c4629cadf1b33955ead125425c9929b4db02171f92ae5780d32456d214d433d6d319596799bcbcb937ce5a1f7aee1c48cb9ac1c99a4aa3fc2356f2a3c710a9a6654c05b606b01ca1e97d9eaae6993f275d0c5967cccf57e2fe28f0f5bd4bca6f0f0c63aa5c6ce17990fb8c9f433425f087c76eec8c8916ab0eb376a85e82f84dce56bec266fd96c22c1f9354c90c63719ece160fd1bb61261f79adf64168e7b3c2b680ecc3e6025130fbc86e9885ee5d0cd41b40a6e82022f2115d5b5a683323cee548e6365923416e21c23b9daf0e147f86c6180af83d1df6a3f54eb98d1d885b465d7933177b8fb84b0eb944852291b001a237e586a9d35cf&X-Goog-SignedHeaders=host&X-User=2931823730 (Caused by NewConnectionError('<urllib3.connection.HTTPSConnection object at 0x7f8700355840>: Failed to establish a new connection: [Errno 101] Network is unreachable'))
2025-04-14 15:14:20,363 ERROR   wandb-upload_0:16610 [internal_api.py:upload_file():2558] upload_file request headers: {'User-Agent': 'python-requests/2.32.3', 'Accept-Encoding': 'gzip, deflate, br', 'Accept': '*/*', 'Connection': 'keep-alive', 'Content-Length': '2380'}
2025-04-14 15:14:20,363 ERROR   wandb-upload_0:16610 [internal_api.py:upload_file():2560] upload_file response body: 
2025-04-14 15:14:42,548 ERROR   wandb-upload_3:16610 [internal_api.py:upload_file():2556] upload_file exception https://storage.googleapis.com/wandb-production.appspot.com/2931823730-harbin-institute-of-technology/ltu-as/sro21n02/conda-environment.yaml?X-Goog-Algorithm=GOOG4-RSA-SHA256&X-Goog-Credential=gorilla-files-url-signer-man%40wandb-production.iam.gserviceaccount.com%2F20250414%2Fauto%2Fstorage%2Fgoog4_request&X-Goog-Date=20250414T151333Z&X-Goog-Expires=86399&X-Goog-Signature=8baaa21661194630a1882e9ed7d315c11d50e573164af7eea55e95ea5953fd3753e98b46a842fe08f503515df18f8fec23a1b271a20bb7458c002170e1ebdd8483b5e2add7e3a8be1f646f1e2361148d782932620251502d2a34b98fc93d70437b2f3c1a672cc8883b684e4df9db83cff0b6477537a2c9f56b12f33118f45063e2abeb73a874b52185f0e7b731bb801545fd9d9cdba619ce48938fed831ab0e64f80cb3e5b15e0de3825420374059423d9ff49f5dd49b3f143c76929b5a9acd4e508e6817a9f3d25eb0441ab4f9be1c4523af1abfaf83ba139a7bffef05151b68a34b1f37c4e2fb49eb2e9893dc7553d87dfef018ac0c0995b7e1898f230da7d&X-Goog-SignedHeaders=host&X-User=2931823730: HTTPSConnectionPool(host='storage.googleapis.com', port=443): Max retries exceeded with url: /wandb-production.appspot.com/2931823730-harbin-institute-of-technology/ltu-as/sro21n02/conda-environment.yaml?X-Goog-Algorithm=GOOG4-RSA-SHA256&X-Goog-Credential=gorilla-files-url-signer-man%40wandb-production.iam.gserviceaccount.com%2F20250414%2Fauto%2Fstorage%2Fgoog4_request&X-Goog-Date=20250414T151333Z&X-Goog-Expires=86399&X-Goog-Signature=8baaa21661194630a1882e9ed7d315c11d50e573164af7eea55e95ea5953fd3753e98b46a842fe08f503515df18f8fec23a1b271a20bb7458c002170e1ebdd8483b5e2add7e3a8be1f646f1e2361148d782932620251502d2a34b98fc93d70437b2f3c1a672cc8883b684e4df9db83cff0b6477537a2c9f56b12f33118f45063e2abeb73a874b52185f0e7b731bb801545fd9d9cdba619ce48938fed831ab0e64f80cb3e5b15e0de3825420374059423d9ff49f5dd49b3f143c76929b5a9acd4e508e6817a9f3d25eb0441ab4f9be1c4523af1abfaf83ba139a7bffef05151b68a34b1f37c4e2fb49eb2e9893dc7553d87dfef018ac0c0995b7e1898f230da7d&X-Goog-SignedHeaders=host&X-User=2931823730 (Caused by NewConnectionError('<urllib3.connection.HTTPSConnection object at 0x7f8700356e30>: Failed to establish a new connection: [Errno 101] Network is unreachable'))
2025-04-14 15:14:42,548 ERROR   wandb-upload_3:16610 [internal_api.py:upload_file():2558] upload_file request headers: {'User-Agent': 'python-requests/2.32.3', 'Accept-Encoding': 'gzip, deflate, br', 'Accept': '*/*', 'Connection': 'keep-alive', 'Content-Length': '12277'}
2025-04-14 15:14:42,548 ERROR   wandb-upload_3:16610 [internal_api.py:upload_file():2560] upload_file response body: 
2025-04-14 15:14:44,126 ERROR   wandb-upload_5:16610 [internal_api.py:upload_file():2556] upload_file exception https://storage.googleapis.com/wandb-production.appspot.com/2931823730-harbin-institute-of-technology/ltu-as/sro21n02/wandb-summary.json?X-Goog-Algorithm=GOOG4-RSA-SHA256&X-Goog-Credential=gorilla-files-url-signer-man%40wandb-production.iam.gserviceaccount.com%2F20250414%2Fauto%2Fstorage%2Fgoog4_request&X-Goog-Date=20250414T151333Z&X-Goog-Expires=86399&X-Goog-Signature=1c62f3b6170db7b48818210bba95fa79cd7f43ca58b6649b0428570d3e8fcd4ca90cf9b087445b3c029a3a5140f42e4d052866f04bd68d93eb3ee96043ef83b1d04c735088f00ff00499677a95cd84c38a034bc58f50f0e30e8b710c7d003d84d488f7ad190ad01237f37aad21878dd5cafe07a27bcac5fb00a0c4ede0be7f9673e8d79381fa2ee8915ffddb163c4c3cefd67b96d065f83bf0d938fd38a763c3d75406bc83901267d8e75a5585d8862a7c7d68ab04ad3b9427824ed9f88ceee45e62757cdc63f7a87cf0e9ac9acb56705639c1d06018727ff251278bfcf3e68f5cdc69b06df7b41f6e080f2353f45a3e19e1da994c54be7bb021e8118023095f&X-Goog-SignedHeaders=host&X-User=2931823730: HTTPSConnectionPool(host='storage.googleapis.com', port=443): Max retries exceeded with url: /wandb-production.appspot.com/2931823730-harbin-institute-of-technology/ltu-as/sro21n02/wandb-summary.json?X-Goog-Algorithm=GOOG4-RSA-SHA256&X-Goog-Credential=gorilla-files-url-signer-man%40wandb-production.iam.gserviceaccount.com%2F20250414%2Fauto%2Fstorage%2Fgoog4_request&X-Goog-Date=20250414T151333Z&X-Goog-Expires=86399&X-Goog-Signature=1c62f3b6170db7b48818210bba95fa79cd7f43ca58b6649b0428570d3e8fcd4ca90cf9b087445b3c029a3a5140f42e4d052866f04bd68d93eb3ee96043ef83b1d04c735088f00ff00499677a95cd84c38a034bc58f50f0e30e8b710c7d003d84d488f7ad190ad01237f37aad21878dd5cafe07a27bcac5fb00a0c4ede0be7f9673e8d79381fa2ee8915ffddb163c4c3cefd67b96d065f83bf0d938fd38a763c3d75406bc83901267d8e75a5585d8862a7c7d68ab04ad3b9427824ed9f88ceee45e62757cdc63f7a87cf0e9ac9acb56705639c1d06018727ff251278bfcf3e68f5cdc69b06df7b41f6e080f2353f45a3e19e1da994c54be7bb021e8118023095f&X-Goog-SignedHeaders=host&X-User=2931823730 (Caused by NewConnectionError('<urllib3.connection.HTTPSConnection object at 0x7f87003bc5e0>: Failed to establish a new connection: [Errno 101] Network is unreachable'))
2025-04-14 15:14:44,126 ERROR   wandb-upload_5:16610 [internal_api.py:upload_file():2558] upload_file request headers: {'User-Agent': 'python-requests/2.32.3', 'Accept-Encoding': 'gzip, deflate, br', 'Accept': '*/*', 'Connection': 'keep-alive', 'Content-Length': '28'}
2025-04-14 15:14:44,126 ERROR   wandb-upload_5:16610 [internal_api.py:upload_file():2560] upload_file response body: 
2025-04-14 15:14:45,849 ERROR   wandb-upload_1:16610 [internal_api.py:upload_file():2556] upload_file exception https://storage.googleapis.com/wandb-production.appspot.com/2931823730-harbin-institute-of-technology/ltu-as/sro21n02/config.yaml?X-Goog-Algorithm=GOOG4-RSA-SHA256&X-Goog-Credential=gorilla-files-url-signer-man%40wandb-production.iam.gserviceaccount.com%2F20250414%2Fauto%2Fstorage%2Fgoog4_request&X-Goog-Date=20250414T151333Z&X-Goog-Expires=86399&X-Goog-Signature=2f73e93adaa04407e79c1d548385c55943fdf3db36963bfdf350643aa1b36dae813f5626aaaa750a4bede213fdbf01567d7849c255d958ccd82bb15aae31926ef2cb8142328b26778f2203ecbf35a11e72c8b6968ecfdc910d13ecb0d1c8203f98f95824cddf7c77c6d98174c1a272e56c9fee7836d9b384f88d0e5366792f80e0ac49470f62e30e729583e849f555474ab8021dfebe960bf62ab5c74c8a5de192142c1278ce895934f2e559a74830fc98bbe1048f7b1480b81d89ce5d5da5e4ead191f9e8785bf30c7c829de0a9685a99a16ca07c58d7690c12c5d4c96a20f270453ab953c96813cc31dfe1cb8ad8af66ef18162ab0b43a8eda9c5df2be20e9&X-Goog-SignedHeaders=host&X-User=2931823730: HTTPSConnectionPool(host='storage.googleapis.com', port=443): Max retries exceeded with url: /wandb-production.appspot.com/2931823730-harbin-institute-of-technology/ltu-as/sro21n02/config.yaml?X-Goog-Algorithm=GOOG4-RSA-SHA256&X-Goog-Credential=gorilla-files-url-signer-man%40wandb-production.iam.gserviceaccount.com%2F20250414%2Fauto%2Fstorage%2Fgoog4_request&X-Goog-Date=20250414T151333Z&X-Goog-Expires=86399&X-Goog-Signature=2f73e93adaa04407e79c1d548385c55943fdf3db36963bfdf350643aa1b36dae813f5626aaaa750a4bede213fdbf01567d7849c255d958ccd82bb15aae31926ef2cb8142328b26778f2203ecbf35a11e72c8b6968ecfdc910d13ecb0d1c8203f98f95824cddf7c77c6d98174c1a272e56c9fee7836d9b384f88d0e5366792f80e0ac49470f62e30e729583e849f555474ab8021dfebe960bf62ab5c74c8a5de192142c1278ce895934f2e559a74830fc98bbe1048f7b1480b81d89ce5d5da5e4ead191f9e8785bf30c7c829de0a9685a99a16ca07c58d7690c12c5d4c96a20f270453ab953c96813cc31dfe1cb8ad8af66ef18162ab0b43a8eda9c5df2be20e9&X-Goog-SignedHeaders=host&X-User=2931823730 (Caused by NewConnectionError('<urllib3.connection.HTTPSConnection object at 0x7f87003bcbb0>: Failed to establish a new connection: [Errno 101] Network is unreachable'))
2025-04-14 15:14:45,850 ERROR   wandb-upload_1:16610 [internal_api.py:upload_file():2558] upload_file request headers: {'User-Agent': 'python-requests/2.32.3', 'Accept-Encoding': 'gzip, deflate, br', 'Accept': '*/*', 'Connection': 'keep-alive', 'Content-Length': '8685'}
2025-04-14 15:14:45,850 ERROR   wandb-upload_1:16610 [internal_api.py:upload_file():2560] upload_file response body: 
2025-04-14 15:14:46,655 ERROR   wandb-upload_4:16610 [internal_api.py:upload_file():2556] upload_file exception https://storage.googleapis.com/wandb-production.appspot.com/2931823730-harbin-institute-of-technology/ltu-as/sro21n02/output.log?X-Goog-Algorithm=GOOG4-RSA-SHA256&X-Goog-Credential=gorilla-files-url-signer-man%40wandb-production.iam.gserviceaccount.com%2F20250414%2Fauto%2Fstorage%2Fgoog4_request&X-Goog-Date=20250414T151333Z&X-Goog-Expires=86399&X-Goog-Signature=c1b3d7a13962ac49c7c2542d07fc489216f963e1200f55034b20dcf718bfadea225d00f606037301d3163d0bcc6c723ac40ba61e901e43e0c2b4affc0cf59d8d0e87c42a048461dfb388bee91715da165b7d56016980b76e11e57db92a471bec391c0ce0681ed11eb937b2400195fa49b7e00e37551763edd99ecc1683df8aed7f765f565688bf99dcdbfaa26f25bb16cb58d2cad4e1dc46b0214559475d19c210a94c0e623f1e9b7363b55a7b2ee7730ac02de63bcd07075d4d1cf12cc2d74be322f92ff01972c74aea148c7f4e2ecd2e53d3ed5ca31db45eb0fb37c10edd7cdc41c02049ec2c67dfe9acb64b40903a5a22d0e059999942328737c2397a7dbf&X-Goog-SignedHeaders=host&X-User=2931823730: HTTPSConnectionPool(host='storage.googleapis.com', port=443): Max retries exceeded with url: /wandb-production.appspot.com/2931823730-harbin-institute-of-technology/ltu-as/sro21n02/output.log?X-Goog-Algorithm=GOOG4-RSA-SHA256&X-Goog-Credential=gorilla-files-url-signer-man%40wandb-production.iam.gserviceaccount.com%2F20250414%2Fauto%2Fstorage%2Fgoog4_request&X-Goog-Date=20250414T151333Z&X-Goog-Expires=86399&X-Goog-Signature=c1b3d7a13962ac49c7c2542d07fc489216f963e1200f55034b20dcf718bfadea225d00f606037301d3163d0bcc6c723ac40ba61e901e43e0c2b4affc0cf59d8d0e87c42a048461dfb388bee91715da165b7d56016980b76e11e57db92a471bec391c0ce0681ed11eb937b2400195fa49b7e00e37551763edd99ecc1683df8aed7f765f565688bf99dcdbfaa26f25bb16cb58d2cad4e1dc46b0214559475d19c210a94c0e623f1e9b7363b55a7b2ee7730ac02de63bcd07075d4d1cf12cc2d74be322f92ff01972c74aea148c7f4e2ecd2e53d3ed5ca31db45eb0fb37c10edd7cdc41c02049ec2c67dfe9acb64b40903a5a22d0e059999942328737c2397a7dbf&X-Goog-SignedHeaders=host&X-User=2931823730 (Caused by NewConnectionError('<urllib3.connection.HTTPSConnection object at 0x7f87003bf700>: Failed to establish a new connection: [Errno 101] Network is unreachable'))
2025-04-14 15:14:46,655 ERROR   wandb-upload_4:16610 [internal_api.py:upload_file():2558] upload_file request headers: {'User-Agent': 'python-requests/2.32.3', 'Accept-Encoding': 'gzip, deflate, br', 'Accept': '*/*', 'Connection': 'keep-alive', 'Content-Length': '4916'}
2025-04-14 15:14:46,655 ERROR   wandb-upload_4:16610 [internal_api.py:upload_file():2560] upload_file response body: 
2025-04-14 15:14:49,839 ERROR   wandb-upload_2:16610 [internal_api.py:upload_file():2556] upload_file exception https://storage.googleapis.com/wandb-production.appspot.com/2931823730-harbin-institute-of-technology/ltu-as/sro21n02/requirements.txt?X-Goog-Algorithm=GOOG4-RSA-SHA256&X-Goog-Credential=gorilla-files-url-signer-man%40wandb-production.iam.gserviceaccount.com%2F20250414%2Fauto%2Fstorage%2Fgoog4_request&X-Goog-Date=20250414T151333Z&X-Goog-Expires=86399&X-Goog-Signature=b68928fa0e2b525ca9c2a4d65e8ea36df3dbec3ea8e07a9b57488ed89a18368728d569f35fd3a3b6ca9d006c8392e823f6d6fbef9acdedfdfbdea9dad501ddc1b68a8c3da4ef9a3d38b5151d52891b7d34e027965272f5738f0c9424f5f56686d85cd3224ecb738c6004f884ec680ea391556784a77a9635964958cca0550fb2964a9d249f9592c4612a80c37dacfa24de7da22cb81cc60580456b322e673c980e695f58ed8f8ec247a7076cd46757b6ed864432d0b7a8ebfe3798a4d4748a28cc0c109743ab0cc91f1b3aec691745a5a876dd34d6743fa8b507c86f6f5f6c4e2a5436c6a2e552806d88cd2cd6c69fae0fb8beb7a580df5fa7b602788538d255&X-Goog-SignedHeaders=host&X-User=2931823730: HTTPSConnectionPool(host='storage.googleapis.com', port=443): Max retries exceeded with url: /wandb-production.appspot.com/2931823730-harbin-institute-of-technology/ltu-as/sro21n02/requirements.txt?X-Goog-Algorithm=GOOG4-RSA-SHA256&X-Goog-Credential=gorilla-files-url-signer-man%40wandb-production.iam.gserviceaccount.com%2F20250414%2Fauto%2Fstorage%2Fgoog4_request&X-Goog-Date=20250414T151333Z&X-Goog-Expires=86399&X-Goog-Signature=b68928fa0e2b525ca9c2a4d65e8ea36df3dbec3ea8e07a9b57488ed89a18368728d569f35fd3a3b6ca9d006c8392e823f6d6fbef9acdedfdfbdea9dad501ddc1b68a8c3da4ef9a3d38b5151d52891b7d34e027965272f5738f0c9424f5f56686d85cd3224ecb738c6004f884ec680ea391556784a77a9635964958cca0550fb2964a9d249f9592c4612a80c37dacfa24de7da22cb81cc60580456b322e673c980e695f58ed8f8ec247a7076cd46757b6ed864432d0b7a8ebfe3798a4d4748a28cc0c109743ab0cc91f1b3aec691745a5a876dd34d6743fa8b507c86f6f5f6c4e2a5436c6a2e552806d88cd2cd6c69fae0fb8beb7a580df5fa7b602788538d255&X-Goog-SignedHeaders=host&X-User=2931823730 (Caused by NewConnectionError('<urllib3.connection.HTTPSConnection object at 0x7f87003bdbd0>: Failed to establish a new connection: [Errno 101] Network is unreachable'))
2025-04-14 15:14:49,839 ERROR   wandb-upload_2:16610 [internal_api.py:upload_file():2558] upload_file request headers: {'User-Agent': 'python-requests/2.32.3', 'Accept-Encoding': 'gzip, deflate, br', 'Accept': '*/*', 'Connection': 'keep-alive', 'Content-Length': '5836'}
2025-04-14 15:14:49,839 ERROR   wandb-upload_2:16610 [internal_api.py:upload_file():2560] upload_file response body: 
2025-04-14 15:15:32,848 ERROR   wandb-upload_0:16610 [internal_api.py:upload_file():2556] upload_file exception https://storage.googleapis.com/wandb-production.appspot.com/2931823730-harbin-institute-of-technology/ltu-as/sro21n02/wandb-metadata.json?X-Goog-Algorithm=GOOG4-RSA-SHA256&X-Goog-Credential=gorilla-files-url-signer-man%40wandb-production.iam.gserviceaccount.com%2F20250414%2Fauto%2Fstorage%2Fgoog4_request&X-Goog-Date=20250414T151306Z&X-Goog-Expires=86399&X-Goog-Signature=0bf0b2bd8b586c4629cadf1b33955ead125425c9929b4db02171f92ae5780d32456d214d433d6d319596799bcbcb937ce5a1f7aee1c48cb9ac1c99a4aa3fc2356f2a3c710a9a6654c05b606b01ca1e97d9eaae6993f275d0c5967cccf57e2fe28f0f5bd4bca6f0f0c63aa5c6ce17990fb8c9f433425f087c76eec8c8916ab0eb376a85e82f84dce56bec266fd96c22c1f9354c90c63719ece160fd1bb61261f79adf64168e7b3c2b680ecc3e6025130fbc86e9885ee5d0cd41b40a6e82022f2115d5b5a683323cee548e6365923416e21c23b9daf0e147f86c6180af83d1df6a3f54eb98d1d885b465d7933177b8fb84b0eb944852291b001a237e586a9d35cf&X-Goog-SignedHeaders=host&X-User=2931823730: HTTPSConnectionPool(host='storage.googleapis.com', port=443): Max retries exceeded with url: /wandb-production.appspot.com/2931823730-harbin-institute-of-technology/ltu-as/sro21n02/wandb-metadata.json?X-Goog-Algorithm=GOOG4-RSA-SHA256&X-Goog-Credential=gorilla-files-url-signer-man%40wandb-production.iam.gserviceaccount.com%2F20250414%2Fauto%2Fstorage%2Fgoog4_request&X-Goog-Date=20250414T151306Z&X-Goog-Expires=86399&X-Goog-Signature=0bf0b2bd8b586c4629cadf1b33955ead125425c9929b4db02171f92ae5780d32456d214d433d6d319596799bcbcb937ce5a1f7aee1c48cb9ac1c99a4aa3fc2356f2a3c710a9a6654c05b606b01ca1e97d9eaae6993f275d0c5967cccf57e2fe28f0f5bd4bca6f0f0c63aa5c6ce17990fb8c9f433425f087c76eec8c8916ab0eb376a85e82f84dce56bec266fd96c22c1f9354c90c63719ece160fd1bb61261f79adf64168e7b3c2b680ecc3e6025130fbc86e9885ee5d0cd41b40a6e82022f2115d5b5a683323cee548e6365923416e21c23b9daf0e147f86c6180af83d1df6a3f54eb98d1d885b465d7933177b8fb84b0eb944852291b001a237e586a9d35cf&X-Goog-SignedHeaders=host&X-User=2931823730 (Caused by NewConnectionError('<urllib3.connection.HTTPSConnection object at 0x7f87003bcd30>: Failed to establish a new connection: [Errno 101] Network is unreachable'))
2025-04-14 15:15:32,848 ERROR   wandb-upload_0:16610 [internal_api.py:upload_file():2558] upload_file request headers: {'User-Agent': 'python-requests/2.32.3', 'Accept-Encoding': 'gzip, deflate, br', 'Accept': '*/*', 'Connection': 'keep-alive', 'Content-Length': '2380'}
2025-04-14 15:15:32,848 ERROR   wandb-upload_0:16610 [internal_api.py:upload_file():2560] upload_file response body: 
2025-04-14 15:15:51,498 ERROR   wandb-upload_5:16610 [internal_api.py:upload_file():2556] upload_file exception https://storage.googleapis.com/wandb-production.appspot.com/2931823730-harbin-institute-of-technology/ltu-as/sro21n02/wandb-summary.json?X-Goog-Algorithm=GOOG4-RSA-SHA256&X-Goog-Credential=gorilla-files-url-signer-man%40wandb-production.iam.gserviceaccount.com%2F20250414%2Fauto%2Fstorage%2Fgoog4_request&X-Goog-Date=20250414T151333Z&X-Goog-Expires=86399&X-Goog-Signature=1c62f3b6170db7b48818210bba95fa79cd7f43ca58b6649b0428570d3e8fcd4ca90cf9b087445b3c029a3a5140f42e4d052866f04bd68d93eb3ee96043ef83b1d04c735088f00ff00499677a95cd84c38a034bc58f50f0e30e8b710c7d003d84d488f7ad190ad01237f37aad21878dd5cafe07a27bcac5fb00a0c4ede0be7f9673e8d79381fa2ee8915ffddb163c4c3cefd67b96d065f83bf0d938fd38a763c3d75406bc83901267d8e75a5585d8862a7c7d68ab04ad3b9427824ed9f88ceee45e62757cdc63f7a87cf0e9ac9acb56705639c1d06018727ff251278bfcf3e68f5cdc69b06df7b41f6e080f2353f45a3e19e1da994c54be7bb021e8118023095f&X-Goog-SignedHeaders=host&X-User=2931823730: HTTPSConnectionPool(host='storage.googleapis.com', port=443): Max retries exceeded with url: /wandb-production.appspot.com/2931823730-harbin-institute-of-technology/ltu-as/sro21n02/wandb-summary.json?X-Goog-Algorithm=GOOG4-RSA-SHA256&X-Goog-Credential=gorilla-files-url-signer-man%40wandb-production.iam.gserviceaccount.com%2F20250414%2Fauto%2Fstorage%2Fgoog4_request&X-Goog-Date=20250414T151333Z&X-Goog-Expires=86399&X-Goog-Signature=1c62f3b6170db7b48818210bba95fa79cd7f43ca58b6649b0428570d3e8fcd4ca90cf9b087445b3c029a3a5140f42e4d052866f04bd68d93eb3ee96043ef83b1d04c735088f00ff00499677a95cd84c38a034bc58f50f0e30e8b710c7d003d84d488f7ad190ad01237f37aad21878dd5cafe07a27bcac5fb00a0c4ede0be7f9673e8d79381fa2ee8915ffddb163c4c3cefd67b96d065f83bf0d938fd38a763c3d75406bc83901267d8e75a5585d8862a7c7d68ab04ad3b9427824ed9f88ceee45e62757cdc63f7a87cf0e9ac9acb56705639c1d06018727ff251278bfcf3e68f5cdc69b06df7b41f6e080f2353f45a3e19e1da994c54be7bb021e8118023095f&X-Goog-SignedHeaders=host&X-User=2931823730 (Caused by NewConnectionError('<urllib3.connection.HTTPSConnection object at 0x7f87014a3070>: Failed to establish a new connection: [Errno 101] Network is unreachable'))
2025-04-14 15:15:51,498 ERROR   wandb-upload_5:16610 [internal_api.py:upload_file():2558] upload_file request headers: {'User-Agent': 'python-requests/2.32.3', 'Accept-Encoding': 'gzip, deflate, br', 'Accept': '*/*', 'Connection': 'keep-alive', 'Content-Length': '28'}
2025-04-14 15:15:51,499 ERROR   wandb-upload_5:16610 [internal_api.py:upload_file():2560] upload_file response body: 
2025-04-14 15:15:51,596 ERROR   wandb-upload_3:16610 [internal_api.py:upload_file():2556] upload_file exception https://storage.googleapis.com/wandb-production.appspot.com/2931823730-harbin-institute-of-technology/ltu-as/sro21n02/conda-environment.yaml?X-Goog-Algorithm=GOOG4-RSA-SHA256&X-Goog-Credential=gorilla-files-url-signer-man%40wandb-production.iam.gserviceaccount.com%2F20250414%2Fauto%2Fstorage%2Fgoog4_request&X-Goog-Date=20250414T151333Z&X-Goog-Expires=86399&X-Goog-Signature=8baaa21661194630a1882e9ed7d315c11d50e573164af7eea55e95ea5953fd3753e98b46a842fe08f503515df18f8fec23a1b271a20bb7458c002170e1ebdd8483b5e2add7e3a8be1f646f1e2361148d782932620251502d2a34b98fc93d70437b2f3c1a672cc8883b684e4df9db83cff0b6477537a2c9f56b12f33118f45063e2abeb73a874b52185f0e7b731bb801545fd9d9cdba619ce48938fed831ab0e64f80cb3e5b15e0de3825420374059423d9ff49f5dd49b3f143c76929b5a9acd4e508e6817a9f3d25eb0441ab4f9be1c4523af1abfaf83ba139a7bffef05151b68a34b1f37c4e2fb49eb2e9893dc7553d87dfef018ac0c0995b7e1898f230da7d&X-Goog-SignedHeaders=host&X-User=2931823730: HTTPSConnectionPool(host='storage.googleapis.com', port=443): Max retries exceeded with url: /wandb-production.appspot.com/2931823730-harbin-institute-of-technology/ltu-as/sro21n02/conda-environment.yaml?X-Goog-Algorithm=GOOG4-RSA-SHA256&X-Goog-Credential=gorilla-files-url-signer-man%40wandb-production.iam.gserviceaccount.com%2F20250414%2Fauto%2Fstorage%2Fgoog4_request&X-Goog-Date=20250414T151333Z&X-Goog-Expires=86399&X-Goog-Signature=8baaa21661194630a1882e9ed7d315c11d50e573164af7eea55e95ea5953fd3753e98b46a842fe08f503515df18f8fec23a1b271a20bb7458c002170e1ebdd8483b5e2add7e3a8be1f646f1e2361148d782932620251502d2a34b98fc93d70437b2f3c1a672cc8883b684e4df9db83cff0b6477537a2c9f56b12f33118f45063e2abeb73a874b52185f0e7b731bb801545fd9d9cdba619ce48938fed831ab0e64f80cb3e5b15e0de3825420374059423d9ff49f5dd49b3f143c76929b5a9acd4e508e6817a9f3d25eb0441ab4f9be1c4523af1abfaf83ba139a7bffef05151b68a34b1f37c4e2fb49eb2e9893dc7553d87dfef018ac0c0995b7e1898f230da7d&X-Goog-SignedHeaders=host&X-User=2931823730 (Caused by NewConnectionError('<urllib3.connection.HTTPSConnection object at 0x7f86f83d1c90>: Failed to establish a new connection: [Errno 101] Network is unreachable'))
2025-04-14 15:15:51,596 ERROR   wandb-upload_3:16610 [internal_api.py:upload_file():2558] upload_file request headers: {'User-Agent': 'python-requests/2.32.3', 'Accept-Encoding': 'gzip, deflate, br', 'Accept': '*/*', 'Connection': 'keep-alive', 'Content-Length': '12277'}
2025-04-14 15:15:51,596 ERROR   wandb-upload_3:16610 [internal_api.py:upload_file():2560] upload_file response body: 
2025-04-14 15:15:54,124 ERROR   wandb-upload_1:16610 [internal_api.py:upload_file():2556] upload_file exception https://storage.googleapis.com/wandb-production.appspot.com/2931823730-harbin-institute-of-technology/ltu-as/sro21n02/config.yaml?X-Goog-Algorithm=GOOG4-RSA-SHA256&X-Goog-Credential=gorilla-files-url-signer-man%40wandb-production.iam.gserviceaccount.com%2F20250414%2Fauto%2Fstorage%2Fgoog4_request&X-Goog-Date=20250414T151333Z&X-Goog-Expires=86399&X-Goog-Signature=2f73e93adaa04407e79c1d548385c55943fdf3db36963bfdf350643aa1b36dae813f5626aaaa750a4bede213fdbf01567d7849c255d958ccd82bb15aae31926ef2cb8142328b26778f2203ecbf35a11e72c8b6968ecfdc910d13ecb0d1c8203f98f95824cddf7c77c6d98174c1a272e56c9fee7836d9b384f88d0e5366792f80e0ac49470f62e30e729583e849f555474ab8021dfebe960bf62ab5c74c8a5de192142c1278ce895934f2e559a74830fc98bbe1048f7b1480b81d89ce5d5da5e4ead191f9e8785bf30c7c829de0a9685a99a16ca07c58d7690c12c5d4c96a20f270453ab953c96813cc31dfe1cb8ad8af66ef18162ab0b43a8eda9c5df2be20e9&X-Goog-SignedHeaders=host&X-User=2931823730: HTTPSConnectionPool(host='storage.googleapis.com', port=443): Max retries exceeded with url: /wandb-production.appspot.com/2931823730-harbin-institute-of-technology/ltu-as/sro21n02/config.yaml?X-Goog-Algorithm=GOOG4-RSA-SHA256&X-Goog-Credential=gorilla-files-url-signer-man%40wandb-production.iam.gserviceaccount.com%2F20250414%2Fauto%2Fstorage%2Fgoog4_request&X-Goog-Date=20250414T151333Z&X-Goog-Expires=86399&X-Goog-Signature=2f73e93adaa04407e79c1d548385c55943fdf3db36963bfdf350643aa1b36dae813f5626aaaa750a4bede213fdbf01567d7849c255d958ccd82bb15aae31926ef2cb8142328b26778f2203ecbf35a11e72c8b6968ecfdc910d13ecb0d1c8203f98f95824cddf7c77c6d98174c1a272e56c9fee7836d9b384f88d0e5366792f80e0ac49470f62e30e729583e849f555474ab8021dfebe960bf62ab5c74c8a5de192142c1278ce895934f2e559a74830fc98bbe1048f7b1480b81d89ce5d5da5e4ead191f9e8785bf30c7c829de0a9685a99a16ca07c58d7690c12c5d4c96a20f270453ab953c96813cc31dfe1cb8ad8af66ef18162ab0b43a8eda9c5df2be20e9&X-Goog-SignedHeaders=host&X-User=2931823730 (Caused by NewConnectionError('<urllib3.connection.HTTPSConnection object at 0x7f86f83d1d20>: Failed to establish a new connection: [Errno 101] Network is unreachable'))
2025-04-14 15:15:54,125 ERROR   wandb-upload_1:16610 [internal_api.py:upload_file():2558] upload_file request headers: {'User-Agent': 'python-requests/2.32.3', 'Accept-Encoding': 'gzip, deflate, br', 'Accept': '*/*', 'Connection': 'keep-alive', 'Content-Length': '8685'}
2025-04-14 15:15:54,125 ERROR   wandb-upload_1:16610 [internal_api.py:upload_file():2560] upload_file response body: 
2025-04-14 15:15:55,508 ERROR   wandb-upload_4:16610 [internal_api.py:upload_file():2556] upload_file exception https://storage.googleapis.com/wandb-production.appspot.com/2931823730-harbin-institute-of-technology/ltu-as/sro21n02/output.log?X-Goog-Algorithm=GOOG4-RSA-SHA256&X-Goog-Credential=gorilla-files-url-signer-man%40wandb-production.iam.gserviceaccount.com%2F20250414%2Fauto%2Fstorage%2Fgoog4_request&X-Goog-Date=20250414T151333Z&X-Goog-Expires=86399&X-Goog-Signature=c1b3d7a13962ac49c7c2542d07fc489216f963e1200f55034b20dcf718bfadea225d00f606037301d3163d0bcc6c723ac40ba61e901e43e0c2b4affc0cf59d8d0e87c42a048461dfb388bee91715da165b7d56016980b76e11e57db92a471bec391c0ce0681ed11eb937b2400195fa49b7e00e37551763edd99ecc1683df8aed7f765f565688bf99dcdbfaa26f25bb16cb58d2cad4e1dc46b0214559475d19c210a94c0e623f1e9b7363b55a7b2ee7730ac02de63bcd07075d4d1cf12cc2d74be322f92ff01972c74aea148c7f4e2ecd2e53d3ed5ca31db45eb0fb37c10edd7cdc41c02049ec2c67dfe9acb64b40903a5a22d0e059999942328737c2397a7dbf&X-Goog-SignedHeaders=host&X-User=2931823730: HTTPSConnectionPool(host='storage.googleapis.com', port=443): Max retries exceeded with url: /wandb-production.appspot.com/2931823730-harbin-institute-of-technology/ltu-as/sro21n02/output.log?X-Goog-Algorithm=GOOG4-RSA-SHA256&X-Goog-Credential=gorilla-files-url-signer-man%40wandb-production.iam.gserviceaccount.com%2F20250414%2Fauto%2Fstorage%2Fgoog4_request&X-Goog-Date=20250414T151333Z&X-Goog-Expires=86399&X-Goog-Signature=c1b3d7a13962ac49c7c2542d07fc489216f963e1200f55034b20dcf718bfadea225d00f606037301d3163d0bcc6c723ac40ba61e901e43e0c2b4affc0cf59d8d0e87c42a048461dfb388bee91715da165b7d56016980b76e11e57db92a471bec391c0ce0681ed11eb937b2400195fa49b7e00e37551763edd99ecc1683df8aed7f765f565688bf99dcdbfaa26f25bb16cb58d2cad4e1dc46b0214559475d19c210a94c0e623f1e9b7363b55a7b2ee7730ac02de63bcd07075d4d1cf12cc2d74be322f92ff01972c74aea148c7f4e2ecd2e53d3ed5ca31db45eb0fb37c10edd7cdc41c02049ec2c67dfe9acb64b40903a5a22d0e059999942328737c2397a7dbf&X-Goog-SignedHeaders=host&X-User=2931823730 (Caused by NewConnectionError('<urllib3.connection.HTTPSConnection object at 0x7f87014ec250>: Failed to establish a new connection: [Errno 101] Network is unreachable'))
2025-04-14 15:15:55,508 ERROR   wandb-upload_4:16610 [internal_api.py:upload_file():2558] upload_file request headers: {'User-Agent': 'python-requests/2.32.3', 'Accept-Encoding': 'gzip, deflate, br', 'Accept': '*/*', 'Connection': 'keep-alive', 'Content-Length': '4916'}
2025-04-14 15:15:55,508 ERROR   wandb-upload_4:16610 [internal_api.py:upload_file():2560] upload_file response body: 
2025-04-14 15:16:09,137 ERROR   wandb-upload_2:16610 [internal_api.py:upload_file():2556] upload_file exception https://storage.googleapis.com/wandb-production.appspot.com/2931823730-harbin-institute-of-technology/ltu-as/sro21n02/requirements.txt?X-Goog-Algorithm=GOOG4-RSA-SHA256&X-Goog-Credential=gorilla-files-url-signer-man%40wandb-production.iam.gserviceaccount.com%2F20250414%2Fauto%2Fstorage%2Fgoog4_request&X-Goog-Date=20250414T151333Z&X-Goog-Expires=86399&X-Goog-Signature=b68928fa0e2b525ca9c2a4d65e8ea36df3dbec3ea8e07a9b57488ed89a18368728d569f35fd3a3b6ca9d006c8392e823f6d6fbef9acdedfdfbdea9dad501ddc1b68a8c3da4ef9a3d38b5151d52891b7d34e027965272f5738f0c9424f5f56686d85cd3224ecb738c6004f884ec680ea391556784a77a9635964958cca0550fb2964a9d249f9592c4612a80c37dacfa24de7da22cb81cc60580456b322e673c980e695f58ed8f8ec247a7076cd46757b6ed864432d0b7a8ebfe3798a4d4748a28cc0c109743ab0cc91f1b3aec691745a5a876dd34d6743fa8b507c86f6f5f6c4e2a5436c6a2e552806d88cd2cd6c69fae0fb8beb7a580df5fa7b602788538d255&X-Goog-SignedHeaders=host&X-User=2931823730: HTTPSConnectionPool(host='storage.googleapis.com', port=443): Max retries exceeded with url: /wandb-production.appspot.com/2931823730-harbin-institute-of-technology/ltu-as/sro21n02/requirements.txt?X-Goog-Algorithm=GOOG4-RSA-SHA256&X-Goog-Credential=gorilla-files-url-signer-man%40wandb-production.iam.gserviceaccount.com%2F20250414%2Fauto%2Fstorage%2Fgoog4_request&X-Goog-Date=20250414T151333Z&X-Goog-Expires=86399&X-Goog-Signature=b68928fa0e2b525ca9c2a4d65e8ea36df3dbec3ea8e07a9b57488ed89a18368728d569f35fd3a3b6ca9d006c8392e823f6d6fbef9acdedfdfbdea9dad501ddc1b68a8c3da4ef9a3d38b5151d52891b7d34e027965272f5738f0c9424f5f56686d85cd3224ecb738c6004f884ec680ea391556784a77a9635964958cca0550fb2964a9d249f9592c4612a80c37dacfa24de7da22cb81cc60580456b322e673c980e695f58ed8f8ec247a7076cd46757b6ed864432d0b7a8ebfe3798a4d4748a28cc0c109743ab0cc91f1b3aec691745a5a876dd34d6743fa8b507c86f6f5f6c4e2a5436c6a2e552806d88cd2cd6c69fae0fb8beb7a580df5fa7b602788538d255&X-Goog-SignedHeaders=host&X-User=2931823730 (Caused by NewConnectionError('<urllib3.connection.HTTPSConnection object at 0x7f87003bea40>: Failed to establish a new connection: [Errno 101] Network is unreachable'))
2025-04-14 15:16:09,137 ERROR   wandb-upload_2:16610 [internal_api.py:upload_file():2558] upload_file request headers: {'User-Agent': 'python-requests/2.32.3', 'Accept-Encoding': 'gzip, deflate, br', 'Accept': '*/*', 'Connection': 'keep-alive', 'Content-Length': '5836'}
2025-04-14 15:16:09,137 ERROR   wandb-upload_2:16610 [internal_api.py:upload_file():2560] upload_file response body: 
2025-04-14 15:17:49,142 INFO    wandb-upload_0:16610 [upload_job.py:push():131] Uploaded file /tmp/tmpdu3bp9cxwandb/e0ep1hsm-wandb-metadata.json
2025-04-14 15:18:10,741 INFO    wandb-upload_1:16610 [upload_job.py:push():131] Uploaded file /root/ltu-main/ltu-main/src/ltu_as/train_scripts/wandb/run-20250414_151140-sro21n02/files/config.yaml
2025-04-14 15:18:11,456 INFO    wandb-upload_5:16610 [upload_job.py:push():131] Uploaded file /root/ltu-main/ltu-main/src/ltu_as/train_scripts/wandb/run-20250414_151140-sro21n02/files/wandb-summary.json
2025-04-14 15:18:29,484 ERROR   wandb-upload_4:16610 [internal_api.py:upload_file():2556] upload_file exception https://storage.googleapis.com/wandb-production.appspot.com/2931823730-harbin-institute-of-technology/ltu-as/sro21n02/output.log?X-Goog-Algorithm=GOOG4-RSA-SHA256&X-Goog-Credential=gorilla-files-url-signer-man%40wandb-production.iam.gserviceaccount.com%2F20250414%2Fauto%2Fstorage%2Fgoog4_request&X-Goog-Date=20250414T151333Z&X-Goog-Expires=86399&X-Goog-Signature=c1b3d7a13962ac49c7c2542d07fc489216f963e1200f55034b20dcf718bfadea225d00f606037301d3163d0bcc6c723ac40ba61e901e43e0c2b4affc0cf59d8d0e87c42a048461dfb388bee91715da165b7d56016980b76e11e57db92a471bec391c0ce0681ed11eb937b2400195fa49b7e00e37551763edd99ecc1683df8aed7f765f565688bf99dcdbfaa26f25bb16cb58d2cad4e1dc46b0214559475d19c210a94c0e623f1e9b7363b55a7b2ee7730ac02de63bcd07075d4d1cf12cc2d74be322f92ff01972c74aea148c7f4e2ecd2e53d3ed5ca31db45eb0fb37c10edd7cdc41c02049ec2c67dfe9acb64b40903a5a22d0e059999942328737c2397a7dbf&X-Goog-SignedHeaders=host&X-User=2931823730: ('Connection aborted.', RemoteDisconnected('Remote end closed connection without response'))
2025-04-14 15:18:29,484 ERROR   wandb-upload_4:16610 [internal_api.py:upload_file():2558] upload_file request headers: {'User-Agent': 'python-requests/2.32.3', 'Accept-Encoding': 'gzip, deflate, br', 'Accept': '*/*', 'Connection': 'keep-alive', 'Content-Length': '4916'}
2025-04-14 15:18:29,484 ERROR   wandb-upload_4:16610 [internal_api.py:upload_file():2560] upload_file response body: 
2025-04-14 15:18:30,636 ERROR   wandb-upload_3:16610 [internal_api.py:upload_file():2556] upload_file exception https://storage.googleapis.com/wandb-production.appspot.com/2931823730-harbin-institute-of-technology/ltu-as/sro21n02/conda-environment.yaml?X-Goog-Algorithm=GOOG4-RSA-SHA256&X-Goog-Credential=gorilla-files-url-signer-man%40wandb-production.iam.gserviceaccount.com%2F20250414%2Fauto%2Fstorage%2Fgoog4_request&X-Goog-Date=20250414T151333Z&X-Goog-Expires=86399&X-Goog-Signature=8baaa21661194630a1882e9ed7d315c11d50e573164af7eea55e95ea5953fd3753e98b46a842fe08f503515df18f8fec23a1b271a20bb7458c002170e1ebdd8483b5e2add7e3a8be1f646f1e2361148d782932620251502d2a34b98fc93d70437b2f3c1a672cc8883b684e4df9db83cff0b6477537a2c9f56b12f33118f45063e2abeb73a874b52185f0e7b731bb801545fd9d9cdba619ce48938fed831ab0e64f80cb3e5b15e0de3825420374059423d9ff49f5dd49b3f143c76929b5a9acd4e508e6817a9f3d25eb0441ab4f9be1c4523af1abfaf83ba139a7bffef05151b68a34b1f37c4e2fb49eb2e9893dc7553d87dfef018ac0c0995b7e1898f230da7d&X-Goog-SignedHeaders=host&X-User=2931823730: HTTPSConnectionPool(host='storage.googleapis.com', port=443): Max retries exceeded with url: /wandb-production.appspot.com/2931823730-harbin-institute-of-technology/ltu-as/sro21n02/conda-environment.yaml?X-Goog-Algorithm=GOOG4-RSA-SHA256&X-Goog-Credential=gorilla-files-url-signer-man%40wandb-production.iam.gserviceaccount.com%2F20250414%2Fauto%2Fstorage%2Fgoog4_request&X-Goog-Date=20250414T151333Z&X-Goog-Expires=86399&X-Goog-Signature=8baaa21661194630a1882e9ed7d315c11d50e573164af7eea55e95ea5953fd3753e98b46a842fe08f503515df18f8fec23a1b271a20bb7458c002170e1ebdd8483b5e2add7e3a8be1f646f1e2361148d782932620251502d2a34b98fc93d70437b2f3c1a672cc8883b684e4df9db83cff0b6477537a2c9f56b12f33118f45063e2abeb73a874b52185f0e7b731bb801545fd9d9cdba619ce48938fed831ab0e64f80cb3e5b15e0de3825420374059423d9ff49f5dd49b3f143c76929b5a9acd4e508e6817a9f3d25eb0441ab4f9be1c4523af1abfaf83ba139a7bffef05151b68a34b1f37c4e2fb49eb2e9893dc7553d87dfef018ac0c0995b7e1898f230da7d&X-Goog-SignedHeaders=host&X-User=2931823730 (Caused by NewConnectionError('<urllib3.connection.HTTPSConnection object at 0x7f87003bc430>: Failed to establish a new connection: [Errno 101] Network is unreachable'))
2025-04-14 15:18:30,636 ERROR   wandb-upload_3:16610 [internal_api.py:upload_file():2558] upload_file request headers: {'User-Agent': 'python-requests/2.32.3', 'Accept-Encoding': 'gzip, deflate, br', 'Accept': '*/*', 'Connection': 'keep-alive', 'Content-Length': '12277'}
2025-04-14 15:18:30,637 ERROR   wandb-upload_3:16610 [internal_api.py:upload_file():2560] upload_file response body: 
2025-04-14 15:18:40,896 ERROR   wandb-upload_2:16610 [internal_api.py:upload_file():2556] upload_file exception https://storage.googleapis.com/wandb-production.appspot.com/2931823730-harbin-institute-of-technology/ltu-as/sro21n02/requirements.txt?X-Goog-Algorithm=GOOG4-RSA-SHA256&X-Goog-Credential=gorilla-files-url-signer-man%40wandb-production.iam.gserviceaccount.com%2F20250414%2Fauto%2Fstorage%2Fgoog4_request&X-Goog-Date=20250414T151333Z&X-Goog-Expires=86399&X-Goog-Signature=b68928fa0e2b525ca9c2a4d65e8ea36df3dbec3ea8e07a9b57488ed89a18368728d569f35fd3a3b6ca9d006c8392e823f6d6fbef9acdedfdfbdea9dad501ddc1b68a8c3da4ef9a3d38b5151d52891b7d34e027965272f5738f0c9424f5f56686d85cd3224ecb738c6004f884ec680ea391556784a77a9635964958cca0550fb2964a9d249f9592c4612a80c37dacfa24de7da22cb81cc60580456b322e673c980e695f58ed8f8ec247a7076cd46757b6ed864432d0b7a8ebfe3798a4d4748a28cc0c109743ab0cc91f1b3aec691745a5a876dd34d6743fa8b507c86f6f5f6c4e2a5436c6a2e552806d88cd2cd6c69fae0fb8beb7a580df5fa7b602788538d255&X-Goog-SignedHeaders=host&X-User=2931823730: HTTPSConnectionPool(host='storage.googleapis.com', port=443): Max retries exceeded with url: /wandb-production.appspot.com/2931823730-harbin-institute-of-technology/ltu-as/sro21n02/requirements.txt?X-Goog-Algorithm=GOOG4-RSA-SHA256&X-Goog-Credential=gorilla-files-url-signer-man%40wandb-production.iam.gserviceaccount.com%2F20250414%2Fauto%2Fstorage%2Fgoog4_request&X-Goog-Date=20250414T151333Z&X-Goog-Expires=86399&X-Goog-Signature=b68928fa0e2b525ca9c2a4d65e8ea36df3dbec3ea8e07a9b57488ed89a18368728d569f35fd3a3b6ca9d006c8392e823f6d6fbef9acdedfdfbdea9dad501ddc1b68a8c3da4ef9a3d38b5151d52891b7d34e027965272f5738f0c9424f5f56686d85cd3224ecb738c6004f884ec680ea391556784a77a9635964958cca0550fb2964a9d249f9592c4612a80c37dacfa24de7da22cb81cc60580456b322e673c980e695f58ed8f8ec247a7076cd46757b6ed864432d0b7a8ebfe3798a4d4748a28cc0c109743ab0cc91f1b3aec691745a5a876dd34d6743fa8b507c86f6f5f6c4e2a5436c6a2e552806d88cd2cd6c69fae0fb8beb7a580df5fa7b602788538d255&X-Goog-SignedHeaders=host&X-User=2931823730 (Caused by NewConnectionError('<urllib3.connection.HTTPSConnection object at 0x7f87003bf5e0>: Failed to establish a new connection: [Errno 101] Network is unreachable'))
2025-04-14 15:18:40,896 ERROR   wandb-upload_2:16610 [internal_api.py:upload_file():2558] upload_file request headers: {'User-Agent': 'python-requests/2.32.3', 'Accept-Encoding': 'gzip, deflate, br', 'Accept': '*/*', 'Connection': 'keep-alive', 'Content-Length': '5836'}
2025-04-14 15:18:40,896 ERROR   wandb-upload_2:16610 [internal_api.py:upload_file():2560] upload_file response body: 
2025-04-14 15:22:58,235 ERROR   wandb-upload_2:16610 [internal_api.py:upload_file():2556] upload_file exception https://storage.googleapis.com/wandb-production.appspot.com/2931823730-harbin-institute-of-technology/ltu-as/sro21n02/requirements.txt?X-Goog-Algorithm=GOOG4-RSA-SHA256&X-Goog-Credential=gorilla-files-url-signer-man%40wandb-production.iam.gserviceaccount.com%2F20250414%2Fauto%2Fstorage%2Fgoog4_request&X-Goog-Date=20250414T151333Z&X-Goog-Expires=86399&X-Goog-Signature=b68928fa0e2b525ca9c2a4d65e8ea36df3dbec3ea8e07a9b57488ed89a18368728d569f35fd3a3b6ca9d006c8392e823f6d6fbef9acdedfdfbdea9dad501ddc1b68a8c3da4ef9a3d38b5151d52891b7d34e027965272f5738f0c9424f5f56686d85cd3224ecb738c6004f884ec680ea391556784a77a9635964958cca0550fb2964a9d249f9592c4612a80c37dacfa24de7da22cb81cc60580456b322e673c980e695f58ed8f8ec247a7076cd46757b6ed864432d0b7a8ebfe3798a4d4748a28cc0c109743ab0cc91f1b3aec691745a5a876dd34d6743fa8b507c86f6f5f6c4e2a5436c6a2e552806d88cd2cd6c69fae0fb8beb7a580df5fa7b602788538d255&X-Goog-SignedHeaders=host&X-User=2931823730: HTTPSConnectionPool(host='storage.googleapis.com', port=443): Max retries exceeded with url: /wandb-production.appspot.com/2931823730-harbin-institute-of-technology/ltu-as/sro21n02/requirements.txt?X-Goog-Algorithm=GOOG4-RSA-SHA256&X-Goog-Credential=gorilla-files-url-signer-man%40wandb-production.iam.gserviceaccount.com%2F20250414%2Fauto%2Fstorage%2Fgoog4_request&X-Goog-Date=20250414T151333Z&X-Goog-Expires=86399&X-Goog-Signature=b68928fa0e2b525ca9c2a4d65e8ea36df3dbec3ea8e07a9b57488ed89a18368728d569f35fd3a3b6ca9d006c8392e823f6d6fbef9acdedfdfbdea9dad501ddc1b68a8c3da4ef9a3d38b5151d52891b7d34e027965272f5738f0c9424f5f56686d85cd3224ecb738c6004f884ec680ea391556784a77a9635964958cca0550fb2964a9d249f9592c4612a80c37dacfa24de7da22cb81cc60580456b322e673c980e695f58ed8f8ec247a7076cd46757b6ed864432d0b7a8ebfe3798a4d4748a28cc0c109743ab0cc91f1b3aec691745a5a876dd34d6743fa8b507c86f6f5f6c4e2a5436c6a2e552806d88cd2cd6c69fae0fb8beb7a580df5fa7b602788538d255&X-Goog-SignedHeaders=host&X-User=2931823730 (Caused by NewConnectionError('<urllib3.connection.HTTPSConnection object at 0x7f87003beb90>: Failed to establish a new connection: [Errno 101] Network is unreachable'))
2025-04-14 15:22:58,235 ERROR   wandb-upload_2:16610 [internal_api.py:upload_file():2558] upload_file request headers: {'User-Agent': 'python-requests/2.32.3', 'Accept-Encoding': 'gzip, deflate, br', 'Accept': '*/*', 'Connection': 'keep-alive', 'Content-Length': '5836'}
2025-04-14 15:22:58,235 ERROR   wandb-upload_2:16610 [internal_api.py:upload_file():2560] upload_file response body: 
2025-04-14 15:23:23,388 ERROR   wandb-upload_3:16610 [internal_api.py:upload_file():2556] upload_file exception https://storage.googleapis.com/wandb-production.appspot.com/2931823730-harbin-institute-of-technology/ltu-as/sro21n02/conda-environment.yaml?X-Goog-Algorithm=GOOG4-RSA-SHA256&X-Goog-Credential=gorilla-files-url-signer-man%40wandb-production.iam.gserviceaccount.com%2F20250414%2Fauto%2Fstorage%2Fgoog4_request&X-Goog-Date=20250414T151333Z&X-Goog-Expires=86399&X-Goog-Signature=8baaa21661194630a1882e9ed7d315c11d50e573164af7eea55e95ea5953fd3753e98b46a842fe08f503515df18f8fec23a1b271a20bb7458c002170e1ebdd8483b5e2add7e3a8be1f646f1e2361148d782932620251502d2a34b98fc93d70437b2f3c1a672cc8883b684e4df9db83cff0b6477537a2c9f56b12f33118f45063e2abeb73a874b52185f0e7b731bb801545fd9d9cdba619ce48938fed831ab0e64f80cb3e5b15e0de3825420374059423d9ff49f5dd49b3f143c76929b5a9acd4e508e6817a9f3d25eb0441ab4f9be1c4523af1abfaf83ba139a7bffef05151b68a34b1f37c4e2fb49eb2e9893dc7553d87dfef018ac0c0995b7e1898f230da7d&X-Goog-SignedHeaders=host&X-User=2931823730: HTTPSConnectionPool(host='storage.googleapis.com', port=443): Max retries exceeded with url: /wandb-production.appspot.com/2931823730-harbin-institute-of-technology/ltu-as/sro21n02/conda-environment.yaml?X-Goog-Algorithm=GOOG4-RSA-SHA256&X-Goog-Credential=gorilla-files-url-signer-man%40wandb-production.iam.gserviceaccount.com%2F20250414%2Fauto%2Fstorage%2Fgoog4_request&X-Goog-Date=20250414T151333Z&X-Goog-Expires=86399&X-Goog-Signature=8baaa21661194630a1882e9ed7d315c11d50e573164af7eea55e95ea5953fd3753e98b46a842fe08f503515df18f8fec23a1b271a20bb7458c002170e1ebdd8483b5e2add7e3a8be1f646f1e2361148d782932620251502d2a34b98fc93d70437b2f3c1a672cc8883b684e4df9db83cff0b6477537a2c9f56b12f33118f45063e2abeb73a874b52185f0e7b731bb801545fd9d9cdba619ce48938fed831ab0e64f80cb3e5b15e0de3825420374059423d9ff49f5dd49b3f143c76929b5a9acd4e508e6817a9f3d25eb0441ab4f9be1c4523af1abfaf83ba139a7bffef05151b68a34b1f37c4e2fb49eb2e9893dc7553d87dfef018ac0c0995b7e1898f230da7d&X-Goog-SignedHeaders=host&X-User=2931823730 (Caused by NewConnectionError('<urllib3.connection.HTTPSConnection object at 0x7f8700355420>: Failed to establish a new connection: [Errno 101] Network is unreachable'))
2025-04-14 15:23:23,389 ERROR   wandb-upload_3:16610 [internal_api.py:upload_file():2558] upload_file request headers: {'User-Agent': 'python-requests/2.32.3', 'Accept-Encoding': 'gzip, deflate, br', 'Accept': '*/*', 'Connection': 'keep-alive', 'Content-Length': '12277'}
2025-04-14 15:23:23,389 ERROR   wandb-upload_3:16610 [internal_api.py:upload_file():2560] upload_file response body: 
2025-04-14 15:23:45,441 ERROR   wandb-upload_4:16610 [internal_api.py:upload_file():2556] upload_file exception https://storage.googleapis.com/wandb-production.appspot.com/2931823730-harbin-institute-of-technology/ltu-as/sro21n02/output.log?X-Goog-Algorithm=GOOG4-RSA-SHA256&X-Goog-Credential=gorilla-files-url-signer-man%40wandb-production.iam.gserviceaccount.com%2F20250414%2Fauto%2Fstorage%2Fgoog4_request&X-Goog-Date=20250414T151333Z&X-Goog-Expires=86399&X-Goog-Signature=c1b3d7a13962ac49c7c2542d07fc489216f963e1200f55034b20dcf718bfadea225d00f606037301d3163d0bcc6c723ac40ba61e901e43e0c2b4affc0cf59d8d0e87c42a048461dfb388bee91715da165b7d56016980b76e11e57db92a471bec391c0ce0681ed11eb937b2400195fa49b7e00e37551763edd99ecc1683df8aed7f765f565688bf99dcdbfaa26f25bb16cb58d2cad4e1dc46b0214559475d19c210a94c0e623f1e9b7363b55a7b2ee7730ac02de63bcd07075d4d1cf12cc2d74be322f92ff01972c74aea148c7f4e2ecd2e53d3ed5ca31db45eb0fb37c10edd7cdc41c02049ec2c67dfe9acb64b40903a5a22d0e059999942328737c2397a7dbf&X-Goog-SignedHeaders=host&X-User=2931823730: HTTPSConnectionPool(host='storage.googleapis.com', port=443): Max retries exceeded with url: /wandb-production.appspot.com/2931823730-harbin-institute-of-technology/ltu-as/sro21n02/output.log?X-Goog-Algorithm=GOOG4-RSA-SHA256&X-Goog-Credential=gorilla-files-url-signer-man%40wandb-production.iam.gserviceaccount.com%2F20250414%2Fauto%2Fstorage%2Fgoog4_request&X-Goog-Date=20250414T151333Z&X-Goog-Expires=86399&X-Goog-Signature=c1b3d7a13962ac49c7c2542d07fc489216f963e1200f55034b20dcf718bfadea225d00f606037301d3163d0bcc6c723ac40ba61e901e43e0c2b4affc0cf59d8d0e87c42a048461dfb388bee91715da165b7d56016980b76e11e57db92a471bec391c0ce0681ed11eb937b2400195fa49b7e00e37551763edd99ecc1683df8aed7f765f565688bf99dcdbfaa26f25bb16cb58d2cad4e1dc46b0214559475d19c210a94c0e623f1e9b7363b55a7b2ee7730ac02de63bcd07075d4d1cf12cc2d74be322f92ff01972c74aea148c7f4e2ecd2e53d3ed5ca31db45eb0fb37c10edd7cdc41c02049ec2c67dfe9acb64b40903a5a22d0e059999942328737c2397a7dbf&X-Goog-SignedHeaders=host&X-User=2931823730 (Caused by NewConnectionError('<urllib3.connection.HTTPSConnection object at 0x7f8700354fd0>: Failed to establish a new connection: [Errno 101] Network is unreachable'))
2025-04-14 15:23:45,441 ERROR   wandb-upload_4:16610 [internal_api.py:upload_file():2558] upload_file request headers: {'User-Agent': 'python-requests/2.32.3', 'Accept-Encoding': 'gzip, deflate, br', 'Accept': '*/*', 'Connection': 'keep-alive', 'Content-Length': '4916'}
2025-04-14 15:23:45,441 ERROR   wandb-upload_4:16610 [internal_api.py:upload_file():2560] upload_file response body: 
2025-04-14 15:28:48,759 ERROR   wandb-upload_2:16610 [internal_api.py:upload_file():2556] upload_file exception https://storage.googleapis.com/wandb-production.appspot.com/2931823730-harbin-institute-of-technology/ltu-as/sro21n02/requirements.txt?X-Goog-Algorithm=GOOG4-RSA-SHA256&X-Goog-Credential=gorilla-files-url-signer-man%40wandb-production.iam.gserviceaccount.com%2F20250414%2Fauto%2Fstorage%2Fgoog4_request&X-Goog-Date=20250414T151333Z&X-Goog-Expires=86399&X-Goog-Signature=b68928fa0e2b525ca9c2a4d65e8ea36df3dbec3ea8e07a9b57488ed89a18368728d569f35fd3a3b6ca9d006c8392e823f6d6fbef9acdedfdfbdea9dad501ddc1b68a8c3da4ef9a3d38b5151d52891b7d34e027965272f5738f0c9424f5f56686d85cd3224ecb738c6004f884ec680ea391556784a77a9635964958cca0550fb2964a9d249f9592c4612a80c37dacfa24de7da22cb81cc60580456b322e673c980e695f58ed8f8ec247a7076cd46757b6ed864432d0b7a8ebfe3798a4d4748a28cc0c109743ab0cc91f1b3aec691745a5a876dd34d6743fa8b507c86f6f5f6c4e2a5436c6a2e552806d88cd2cd6c69fae0fb8beb7a580df5fa7b602788538d255&X-Goog-SignedHeaders=host&X-User=2931823730: HTTPSConnectionPool(host='storage.googleapis.com', port=443): Max retries exceeded with url: /wandb-production.appspot.com/2931823730-harbin-institute-of-technology/ltu-as/sro21n02/requirements.txt?X-Goog-Algorithm=GOOG4-RSA-SHA256&X-Goog-Credential=gorilla-files-url-signer-man%40wandb-production.iam.gserviceaccount.com%2F20250414%2Fauto%2Fstorage%2Fgoog4_request&X-Goog-Date=20250414T151333Z&X-Goog-Expires=86399&X-Goog-Signature=b68928fa0e2b525ca9c2a4d65e8ea36df3dbec3ea8e07a9b57488ed89a18368728d569f35fd3a3b6ca9d006c8392e823f6d6fbef9acdedfdfbdea9dad501ddc1b68a8c3da4ef9a3d38b5151d52891b7d34e027965272f5738f0c9424f5f56686d85cd3224ecb738c6004f884ec680ea391556784a77a9635964958cca0550fb2964a9d249f9592c4612a80c37dacfa24de7da22cb81cc60580456b322e673c980e695f58ed8f8ec247a7076cd46757b6ed864432d0b7a8ebfe3798a4d4748a28cc0c109743ab0cc91f1b3aec691745a5a876dd34d6743fa8b507c86f6f5f6c4e2a5436c6a2e552806d88cd2cd6c69fae0fb8beb7a580df5fa7b602788538d255&X-Goog-SignedHeaders=host&X-User=2931823730 (Caused by NewConnectionError('<urllib3.connection.HTTPSConnection object at 0x7f8700356b30>: Failed to establish a new connection: [Errno 101] Network is unreachable'))
2025-04-14 15:28:48,760 ERROR   wandb-upload_2:16610 [internal_api.py:upload_file():2558] upload_file request headers: {'User-Agent': 'python-requests/2.32.3', 'Accept-Encoding': 'gzip, deflate, br', 'Accept': '*/*', 'Connection': 'keep-alive', 'Content-Length': '5836'}
2025-04-14 15:28:48,760 ERROR   wandb-upload_2:16610 [internal_api.py:upload_file():2560] upload_file response body: 
2025-04-14 15:29:20,337 ERROR   wandb-upload_3:16610 [internal_api.py:upload_file():2556] upload_file exception https://storage.googleapis.com/wandb-production.appspot.com/2931823730-harbin-institute-of-technology/ltu-as/sro21n02/conda-environment.yaml?X-Goog-Algorithm=GOOG4-RSA-SHA256&X-Goog-Credential=gorilla-files-url-signer-man%40wandb-production.iam.gserviceaccount.com%2F20250414%2Fauto%2Fstorage%2Fgoog4_request&X-Goog-Date=20250414T151333Z&X-Goog-Expires=86399&X-Goog-Signature=8baaa21661194630a1882e9ed7d315c11d50e573164af7eea55e95ea5953fd3753e98b46a842fe08f503515df18f8fec23a1b271a20bb7458c002170e1ebdd8483b5e2add7e3a8be1f646f1e2361148d782932620251502d2a34b98fc93d70437b2f3c1a672cc8883b684e4df9db83cff0b6477537a2c9f56b12f33118f45063e2abeb73a874b52185f0e7b731bb801545fd9d9cdba619ce48938fed831ab0e64f80cb3e5b15e0de3825420374059423d9ff49f5dd49b3f143c76929b5a9acd4e508e6817a9f3d25eb0441ab4f9be1c4523af1abfaf83ba139a7bffef05151b68a34b1f37c4e2fb49eb2e9893dc7553d87dfef018ac0c0995b7e1898f230da7d&X-Goog-SignedHeaders=host&X-User=2931823730: HTTPSConnectionPool(host='storage.googleapis.com', port=443): Max retries exceeded with url: /wandb-production.appspot.com/2931823730-harbin-institute-of-technology/ltu-as/sro21n02/conda-environment.yaml?X-Goog-Algorithm=GOOG4-RSA-SHA256&X-Goog-Credential=gorilla-files-url-signer-man%40wandb-production.iam.gserviceaccount.com%2F20250414%2Fauto%2Fstorage%2Fgoog4_request&X-Goog-Date=20250414T151333Z&X-Goog-Expires=86399&X-Goog-Signature=8baaa21661194630a1882e9ed7d315c11d50e573164af7eea55e95ea5953fd3753e98b46a842fe08f503515df18f8fec23a1b271a20bb7458c002170e1ebdd8483b5e2add7e3a8be1f646f1e2361148d782932620251502d2a34b98fc93d70437b2f3c1a672cc8883b684e4df9db83cff0b6477537a2c9f56b12f33118f45063e2abeb73a874b52185f0e7b731bb801545fd9d9cdba619ce48938fed831ab0e64f80cb3e5b15e0de3825420374059423d9ff49f5dd49b3f143c76929b5a9acd4e508e6817a9f3d25eb0441ab4f9be1c4523af1abfaf83ba139a7bffef05151b68a34b1f37c4e2fb49eb2e9893dc7553d87dfef018ac0c0995b7e1898f230da7d&X-Goog-SignedHeaders=host&X-User=2931823730 (Caused by NewConnectionError('<urllib3.connection.HTTPSConnection object at 0x7f86f83d1e40>: Failed to establish a new connection: [Errno 101] Network is unreachable'))
2025-04-14 15:29:20,338 ERROR   wandb-upload_3:16610 [internal_api.py:upload_file():2558] upload_file request headers: {'User-Agent': 'python-requests/2.32.3', 'Accept-Encoding': 'gzip, deflate, br', 'Accept': '*/*', 'Connection': 'keep-alive', 'Content-Length': '12277'}
2025-04-14 15:29:20,338 ERROR   wandb-upload_3:16610 [internal_api.py:upload_file():2560] upload_file response body: 
2025-04-14 15:29:52,807 ERROR   wandb-upload_4:16610 [internal_api.py:upload_file():2556] upload_file exception https://storage.googleapis.com/wandb-production.appspot.com/2931823730-harbin-institute-of-technology/ltu-as/sro21n02/output.log?X-Goog-Algorithm=GOOG4-RSA-SHA256&X-Goog-Credential=gorilla-files-url-signer-man%40wandb-production.iam.gserviceaccount.com%2F20250414%2Fauto%2Fstorage%2Fgoog4_request&X-Goog-Date=20250414T151333Z&X-Goog-Expires=86399&X-Goog-Signature=c1b3d7a13962ac49c7c2542d07fc489216f963e1200f55034b20dcf718bfadea225d00f606037301d3163d0bcc6c723ac40ba61e901e43e0c2b4affc0cf59d8d0e87c42a048461dfb388bee91715da165b7d56016980b76e11e57db92a471bec391c0ce0681ed11eb937b2400195fa49b7e00e37551763edd99ecc1683df8aed7f765f565688bf99dcdbfaa26f25bb16cb58d2cad4e1dc46b0214559475d19c210a94c0e623f1e9b7363b55a7b2ee7730ac02de63bcd07075d4d1cf12cc2d74be322f92ff01972c74aea148c7f4e2ecd2e53d3ed5ca31db45eb0fb37c10edd7cdc41c02049ec2c67dfe9acb64b40903a5a22d0e059999942328737c2397a7dbf&X-Goog-SignedHeaders=host&X-User=2931823730: HTTPSConnectionPool(host='storage.googleapis.com', port=443): Max retries exceeded with url: /wandb-production.appspot.com/2931823730-harbin-institute-of-technology/ltu-as/sro21n02/output.log?X-Goog-Algorithm=GOOG4-RSA-SHA256&X-Goog-Credential=gorilla-files-url-signer-man%40wandb-production.iam.gserviceaccount.com%2F20250414%2Fauto%2Fstorage%2Fgoog4_request&X-Goog-Date=20250414T151333Z&X-Goog-Expires=86399&X-Goog-Signature=c1b3d7a13962ac49c7c2542d07fc489216f963e1200f55034b20dcf718bfadea225d00f606037301d3163d0bcc6c723ac40ba61e901e43e0c2b4affc0cf59d8d0e87c42a048461dfb388bee91715da165b7d56016980b76e11e57db92a471bec391c0ce0681ed11eb937b2400195fa49b7e00e37551763edd99ecc1683df8aed7f765f565688bf99dcdbfaa26f25bb16cb58d2cad4e1dc46b0214559475d19c210a94c0e623f1e9b7363b55a7b2ee7730ac02de63bcd07075d4d1cf12cc2d74be322f92ff01972c74aea148c7f4e2ecd2e53d3ed5ca31db45eb0fb37c10edd7cdc41c02049ec2c67dfe9acb64b40903a5a22d0e059999942328737c2397a7dbf&X-Goog-SignedHeaders=host&X-User=2931823730 (Caused by NewConnectionError('<urllib3.connection.HTTPSConnection object at 0x7f86f83d1e70>: Failed to establish a new connection: [Errno 101] Network is unreachable'))
2025-04-14 15:29:52,807 ERROR   wandb-upload_4:16610 [internal_api.py:upload_file():2558] upload_file request headers: {'User-Agent': 'python-requests/2.32.3', 'Accept-Encoding': 'gzip, deflate, br', 'Accept': '*/*', 'Connection': 'keep-alive', 'Content-Length': '4916'}
2025-04-14 15:29:52,807 ERROR   wandb-upload_4:16610 [internal_api.py:upload_file():2560] upload_file response body: 
2025-04-14 15:33:53,703 ERROR   wandb-upload_2:16610 [internal_api.py:upload_file():2556] upload_file exception https://storage.googleapis.com/wandb-production.appspot.com/2931823730-harbin-institute-of-technology/ltu-as/sro21n02/requirements.txt?X-Goog-Algorithm=GOOG4-RSA-SHA256&X-Goog-Credential=gorilla-files-url-signer-man%40wandb-production.iam.gserviceaccount.com%2F20250414%2Fauto%2Fstorage%2Fgoog4_request&X-Goog-Date=20250414T151333Z&X-Goog-Expires=86399&X-Goog-Signature=b68928fa0e2b525ca9c2a4d65e8ea36df3dbec3ea8e07a9b57488ed89a18368728d569f35fd3a3b6ca9d006c8392e823f6d6fbef9acdedfdfbdea9dad501ddc1b68a8c3da4ef9a3d38b5151d52891b7d34e027965272f5738f0c9424f5f56686d85cd3224ecb738c6004f884ec680ea391556784a77a9635964958cca0550fb2964a9d249f9592c4612a80c37dacfa24de7da22cb81cc60580456b322e673c980e695f58ed8f8ec247a7076cd46757b6ed864432d0b7a8ebfe3798a4d4748a28cc0c109743ab0cc91f1b3aec691745a5a876dd34d6743fa8b507c86f6f5f6c4e2a5436c6a2e552806d88cd2cd6c69fae0fb8beb7a580df5fa7b602788538d255&X-Goog-SignedHeaders=host&X-User=2931823730: HTTPSConnectionPool(host='storage.googleapis.com', port=443): Max retries exceeded with url: /wandb-production.appspot.com/2931823730-harbin-institute-of-technology/ltu-as/sro21n02/requirements.txt?X-Goog-Algorithm=GOOG4-RSA-SHA256&X-Goog-Credential=gorilla-files-url-signer-man%40wandb-production.iam.gserviceaccount.com%2F20250414%2Fauto%2Fstorage%2Fgoog4_request&X-Goog-Date=20250414T151333Z&X-Goog-Expires=86399&X-Goog-Signature=b68928fa0e2b525ca9c2a4d65e8ea36df3dbec3ea8e07a9b57488ed89a18368728d569f35fd3a3b6ca9d006c8392e823f6d6fbef9acdedfdfbdea9dad501ddc1b68a8c3da4ef9a3d38b5151d52891b7d34e027965272f5738f0c9424f5f56686d85cd3224ecb738c6004f884ec680ea391556784a77a9635964958cca0550fb2964a9d249f9592c4612a80c37dacfa24de7da22cb81cc60580456b322e673c980e695f58ed8f8ec247a7076cd46757b6ed864432d0b7a8ebfe3798a4d4748a28cc0c109743ab0cc91f1b3aec691745a5a876dd34d6743fa8b507c86f6f5f6c4e2a5436c6a2e552806d88cd2cd6c69fae0fb8beb7a580df5fa7b602788538d255&X-Goog-SignedHeaders=host&X-User=2931823730 (Caused by NewConnectionError('<urllib3.connection.HTTPSConnection object at 0x7f8700355a50>: Failed to establish a new connection: [Errno 101] Network is unreachable'))
2025-04-14 15:33:53,703 ERROR   wandb-upload_2:16610 [internal_api.py:upload_file():2558] upload_file request headers: {'User-Agent': 'python-requests/2.32.3', 'Accept-Encoding': 'gzip, deflate, br', 'Accept': '*/*', 'Connection': 'keep-alive', 'Content-Length': '5836'}
2025-04-14 15:33:53,703 ERROR   wandb-upload_2:16610 [internal_api.py:upload_file():2560] upload_file response body: 
2025-04-14 15:35:24,642 ERROR   wandb-upload_3:16610 [internal_api.py:upload_file():2556] upload_file exception https://storage.googleapis.com/wandb-production.appspot.com/2931823730-harbin-institute-of-technology/ltu-as/sro21n02/conda-environment.yaml?X-Goog-Algorithm=GOOG4-RSA-SHA256&X-Goog-Credential=gorilla-files-url-signer-man%40wandb-production.iam.gserviceaccount.com%2F20250414%2Fauto%2Fstorage%2Fgoog4_request&X-Goog-Date=20250414T151333Z&X-Goog-Expires=86399&X-Goog-Signature=8baaa21661194630a1882e9ed7d315c11d50e573164af7eea55e95ea5953fd3753e98b46a842fe08f503515df18f8fec23a1b271a20bb7458c002170e1ebdd8483b5e2add7e3a8be1f646f1e2361148d782932620251502d2a34b98fc93d70437b2f3c1a672cc8883b684e4df9db83cff0b6477537a2c9f56b12f33118f45063e2abeb73a874b52185f0e7b731bb801545fd9d9cdba619ce48938fed831ab0e64f80cb3e5b15e0de3825420374059423d9ff49f5dd49b3f143c76929b5a9acd4e508e6817a9f3d25eb0441ab4f9be1c4523af1abfaf83ba139a7bffef05151b68a34b1f37c4e2fb49eb2e9893dc7553d87dfef018ac0c0995b7e1898f230da7d&X-Goog-SignedHeaders=host&X-User=2931823730: HTTPSConnectionPool(host='storage.googleapis.com', port=443): Max retries exceeded with url: /wandb-production.appspot.com/2931823730-harbin-institute-of-technology/ltu-as/sro21n02/conda-environment.yaml?X-Goog-Algorithm=GOOG4-RSA-SHA256&X-Goog-Credential=gorilla-files-url-signer-man%40wandb-production.iam.gserviceaccount.com%2F20250414%2Fauto%2Fstorage%2Fgoog4_request&X-Goog-Date=20250414T151333Z&X-Goog-Expires=86399&X-Goog-Signature=8baaa21661194630a1882e9ed7d315c11d50e573164af7eea55e95ea5953fd3753e98b46a842fe08f503515df18f8fec23a1b271a20bb7458c002170e1ebdd8483b5e2add7e3a8be1f646f1e2361148d782932620251502d2a34b98fc93d70437b2f3c1a672cc8883b684e4df9db83cff0b6477537a2c9f56b12f33118f45063e2abeb73a874b52185f0e7b731bb801545fd9d9cdba619ce48938fed831ab0e64f80cb3e5b15e0de3825420374059423d9ff49f5dd49b3f143c76929b5a9acd4e508e6817a9f3d25eb0441ab4f9be1c4523af1abfaf83ba139a7bffef05151b68a34b1f37c4e2fb49eb2e9893dc7553d87dfef018ac0c0995b7e1898f230da7d&X-Goog-SignedHeaders=host&X-User=2931823730 (Caused by NewConnectionError('<urllib3.connection.HTTPSConnection object at 0x7f8700355600>: Failed to establish a new connection: [Errno 101] Network is unreachable'))
2025-04-14 15:35:24,643 ERROR   wandb-upload_3:16610 [internal_api.py:upload_file():2558] upload_file request headers: {'User-Agent': 'python-requests/2.32.3', 'Accept-Encoding': 'gzip, deflate, br', 'Accept': '*/*', 'Connection': 'keep-alive', 'Content-Length': '12277'}
2025-04-14 15:35:24,643 ERROR   wandb-upload_3:16610 [internal_api.py:upload_file():2560] upload_file response body: 
2025-04-14 15:35:45,983 ERROR   wandb-upload_4:16610 [internal_api.py:upload_file():2556] upload_file exception https://storage.googleapis.com/wandb-production.appspot.com/2931823730-harbin-institute-of-technology/ltu-as/sro21n02/output.log?X-Goog-Algorithm=GOOG4-RSA-SHA256&X-Goog-Credential=gorilla-files-url-signer-man%40wandb-production.iam.gserviceaccount.com%2F20250414%2Fauto%2Fstorage%2Fgoog4_request&X-Goog-Date=20250414T151333Z&X-Goog-Expires=86399&X-Goog-Signature=c1b3d7a13962ac49c7c2542d07fc489216f963e1200f55034b20dcf718bfadea225d00f606037301d3163d0bcc6c723ac40ba61e901e43e0c2b4affc0cf59d8d0e87c42a048461dfb388bee91715da165b7d56016980b76e11e57db92a471bec391c0ce0681ed11eb937b2400195fa49b7e00e37551763edd99ecc1683df8aed7f765f565688bf99dcdbfaa26f25bb16cb58d2cad4e1dc46b0214559475d19c210a94c0e623f1e9b7363b55a7b2ee7730ac02de63bcd07075d4d1cf12cc2d74be322f92ff01972c74aea148c7f4e2ecd2e53d3ed5ca31db45eb0fb37c10edd7cdc41c02049ec2c67dfe9acb64b40903a5a22d0e059999942328737c2397a7dbf&X-Goog-SignedHeaders=host&X-User=2931823730: HTTPSConnectionPool(host='storage.googleapis.com', port=443): Max retries exceeded with url: /wandb-production.appspot.com/2931823730-harbin-institute-of-technology/ltu-as/sro21n02/output.log?X-Goog-Algorithm=GOOG4-RSA-SHA256&X-Goog-Credential=gorilla-files-url-signer-man%40wandb-production.iam.gserviceaccount.com%2F20250414%2Fauto%2Fstorage%2Fgoog4_request&X-Goog-Date=20250414T151333Z&X-Goog-Expires=86399&X-Goog-Signature=c1b3d7a13962ac49c7c2542d07fc489216f963e1200f55034b20dcf718bfadea225d00f606037301d3163d0bcc6c723ac40ba61e901e43e0c2b4affc0cf59d8d0e87c42a048461dfb388bee91715da165b7d56016980b76e11e57db92a471bec391c0ce0681ed11eb937b2400195fa49b7e00e37551763edd99ecc1683df8aed7f765f565688bf99dcdbfaa26f25bb16cb58d2cad4e1dc46b0214559475d19c210a94c0e623f1e9b7363b55a7b2ee7730ac02de63bcd07075d4d1cf12cc2d74be322f92ff01972c74aea148c7f4e2ecd2e53d3ed5ca31db45eb0fb37c10edd7cdc41c02049ec2c67dfe9acb64b40903a5a22d0e059999942328737c2397a7dbf&X-Goog-SignedHeaders=host&X-User=2931823730 (Caused by NewConnectionError('<urllib3.connection.HTTPSConnection object at 0x7f87003bc8b0>: Failed to establish a new connection: [Errno 101] Network is unreachable'))
2025-04-14 15:35:45,983 ERROR   wandb-upload_4:16610 [internal_api.py:upload_file():2558] upload_file request headers: {'User-Agent': 'python-requests/2.32.3', 'Accept-Encoding': 'gzip, deflate, br', 'Accept': '*/*', 'Connection': 'keep-alive', 'Content-Length': '4916'}
2025-04-14 15:35:45,983 ERROR   wandb-upload_4:16610 [internal_api.py:upload_file():2560] upload_file response body: 
