2025-04-14 15:35:53,345 INFO    StreamThr :17909 [internal.py:wandb_internal():86] W&B internal server running at pid: 17909, started at: 2025-04-14 15:35:53.344790
2025-04-14 15:35:53,350 DEBUG   HandlerThread:17909 [handler.py:handle_request():146] handle_request: status
2025-04-14 15:35:53,359 INFO    WriterThread:17909 [datastore.py:open_for_write():85] open: /root/ltu-main/ltu-main/src/ltu_as/train_scripts/wandb/run-20250414_153553-wb7imiry/run-wb7imiry.wandb
2025-04-14 15:35:53,361 DEBUG   SenderThread:17909 [sender.py:send():380] send: header
2025-04-14 15:35:53,361 DEBUG   SenderThread:17909 [sender.py:send():380] send: run
2025-04-14 15:35:54,162 DEBUG   HandlerThread:17909 [handler.py:handle_request():146] handle_request: check_version
2025-04-14 15:35:54,222 INFO    SenderThread:17909 [dir_watcher.py:__init__():211] watching files in: /root/ltu-main/ltu-main/src/ltu_as/train_scripts/wandb/run-20250414_153553-wb7imiry/files
2025-04-14 15:35:54,222 INFO    SenderThread:17909 [sender.py:_start_run_threads():1122] run started: wb7imiry with start time 1744644953.357232
2025-04-14 15:35:54,223 DEBUG   SenderThread:17909 [sender.py:send_request():407] send_request: check_version
2025-04-14 15:35:54,827 DEBUG   HandlerThread:17909 [handler.py:handle_request():146] handle_request: run_start
2025-04-14 15:35:54,964 DEBUG   HandlerThread:17909 [system_info.py:__init__():32] System info init
2025-04-14 15:35:54,964 DEBUG   HandlerThread:17909 [system_info.py:__init__():47] System info init done
2025-04-14 15:35:54,964 INFO    HandlerThread:17909 [system_monitor.py:start():194] Starting system monitor
2025-04-14 15:35:54,964 INFO    SystemMonitor:17909 [system_monitor.py:_start():158] Starting system asset monitoring threads
2025-04-14 15:35:54,964 INFO    HandlerThread:17909 [system_monitor.py:probe():214] Collecting system info
2025-04-14 15:35:54,965 INFO    SystemMonitor:17909 [interfaces.py:start():190] Started cpu monitoring
2025-04-14 15:35:54,966 INFO    SystemMonitor:17909 [interfaces.py:start():190] Started disk monitoring
2025-04-14 15:35:54,968 INFO    SystemMonitor:17909 [interfaces.py:start():190] Started gpu monitoring
2025-04-14 15:35:54,977 INFO    SystemMonitor:17909 [interfaces.py:start():190] Started memory monitoring
2025-04-14 15:35:54,978 INFO    SystemMonitor:17909 [interfaces.py:start():190] Started network monitoring
2025-04-14 15:35:54,983 DEBUG   HandlerThread:17909 [system_info.py:probe():196] Probing system
2025-04-14 15:35:54,988 DEBUG   HandlerThread:17909 [gitlib.py:_init_repo():53] git repository is invalid
2025-04-14 15:35:54,989 DEBUG   HandlerThread:17909 [system_info.py:probe():244] Probing system done
2025-04-14 15:35:54,989 DEBUG   HandlerThread:17909 [system_monitor.py:probe():223] {'os': 'Linux-4.15.0-213-generic-x86_64-with-glibc2.27', 'python': '3.10.15', 'heartbeatAt': '2025-04-14T15:35:54.983556', 'startedAt': '2025-04-14T15:35:53.168519', 'docker': None, 'cuda': None, 'args': ('--base_model', '../../../pretrained_mdls/ltuas_long_noqa_a6.bin', '--data_path', '../../../openasqa/data/iemocap_preprocess_with_answers_updated.json', '--output_dir', '../exp/ltuas_ft_meld/', '--batch_size', '256', '--micro_batch_size', '1', '--num_epochs', '1', '--learning_rate', '2e-4', '--cutoff_len', '100', '--val_set_size', '0', '--lora_r', '8', '--lora_alpha', '16', '--lora_dropout', '0.05', '--lora_target_modules', '[q_proj,v_proj]', '--group_by_length', '--wandb_run_name', '../exp/ltuas_ft_meld/', '--save_steps', '30', '--trainable_params', 'all'), 'state': 'running', 'program': '/root/ltu-main/ltu-main/src/ltu_as/train_scripts/../finetune_low_resource.py', 'codePathLocal': None, 'host': 'ubuntu', 'username': 'root', 'executable': '/root/anaconda3/envs/venv_ltu/bin/python', 'cpu_count': 4, 'cpu_count_logical': 4, 'cpu_freq': {'current': 2294.523, 'min': 0.0, 'max': 0.0}, 'cpu_freq_per_core': [{'current': 2294.523, 'min': 0.0, 'max': 0.0}, {'current': 2294.523, 'min': 0.0, 'max': 0.0}, {'current': 2294.523, 'min': 0.0, 'max': 0.0}, {'current': 2294.523, 'min': 0.0, 'max': 0.0}], 'disk': {'/': {'total': 499.9882621765137, 'used': 375.73498916625977}}, 'gpu': 'NVIDIA A100-PCIE-40GB', 'gpu_count': 2, 'gpu_devices': [{'name': 'NVIDIA A100-PCIE-40GB', 'memory_total': 42949672960}, {'name': 'NVIDIA A100-PCIE-40GB', 'memory_total': 42949672960}], 'memory': {'total': 19.60204315185547}}
2025-04-14 15:35:54,989 INFO    HandlerThread:17909 [system_monitor.py:probe():224] Finished collecting system info
2025-04-14 15:35:54,989 INFO    HandlerThread:17909 [system_monitor.py:probe():227] Publishing system info
2025-04-14 15:35:54,989 DEBUG   HandlerThread:17909 [system_info.py:_save_pip():52] Saving list of pip packages installed into the current environment
2025-04-14 15:35:54,989 DEBUG   HandlerThread:17909 [system_info.py:_save_pip():68] Saving pip packages done
2025-04-14 15:35:54,989 DEBUG   HandlerThread:17909 [system_info.py:_save_conda():75] Saving list of conda packages installed into the current environment
2025-04-14 15:35:55,225 INFO    Thread-12 :17909 [dir_watcher.py:_on_file_created():271] file/dir created: /root/ltu-main/ltu-main/src/ltu_as/train_scripts/wandb/run-20250414_153553-wb7imiry/files/conda-environment.yaml
2025-04-14 15:35:55,226 INFO    Thread-12 :17909 [dir_watcher.py:_on_file_created():271] file/dir created: /root/ltu-main/ltu-main/src/ltu_as/train_scripts/wandb/run-20250414_153553-wb7imiry/files/requirements.txt
2025-04-14 15:36:54,978 DEBUG   SystemMonitor:17909 [system_monitor.py:_start():172] Starting system metrics aggregation loop
2025-04-14 15:37:15,066 DEBUG   HandlerThread:17909 [system_info.py:_save_conda():87] Saving conda packages done
2025-04-14 15:37:15,067 INFO    HandlerThread:17909 [system_monitor.py:probe():229] Finished publishing system info
2025-04-14 15:37:15,255 INFO    Thread-12 :17909 [dir_watcher.py:_on_file_modified():288] file/dir modified: /root/ltu-main/ltu-main/src/ltu_as/train_scripts/wandb/run-20250414_153553-wb7imiry/files/conda-environment.yaml
2025-04-14 15:37:15,256 INFO    Thread-12 :17909 [dir_watcher.py:_on_file_created():271] file/dir created: /root/ltu-main/ltu-main/src/ltu_as/train_scripts/wandb/run-20250414_153553-wb7imiry/files/wandb-metadata.json
2025-04-14 15:37:18,103 DEBUG   HandlerThread:17909 [handler.py:handle_request():146] handle_request: status_report
2025-04-14 15:37:18,104 DEBUG   HandlerThread:17909 [handler.py:handle_request():146] handle_request: keepalive
2025-04-14 15:37:18,104 DEBUG   HandlerThread:17909 [handler.py:handle_request():146] handle_request: status_report
2025-04-14 15:37:18,104 DEBUG   HandlerThread:17909 [handler.py:handle_request():146] handle_request: keepalive
2025-04-14 15:37:18,104 DEBUG   HandlerThread:17909 [handler.py:handle_request():146] handle_request: status_report
2025-04-14 15:37:18,104 DEBUG   HandlerThread:17909 [handler.py:handle_request():146] handle_request: keepalive
2025-04-14 15:37:18,104 DEBUG   HandlerThread:17909 [handler.py:handle_request():146] handle_request: status_report
2025-04-14 15:37:18,104 DEBUG   HandlerThread:17909 [handler.py:handle_request():146] handle_request: keepalive
2025-04-14 15:37:18,104 DEBUG   HandlerThread:17909 [handler.py:handle_request():146] handle_request: status_report
2025-04-14 15:37:18,104 DEBUG   HandlerThread:17909 [handler.py:handle_request():146] handle_request: keepalive
2025-04-14 15:37:18,104 DEBUG   HandlerThread:17909 [handler.py:handle_request():146] handle_request: status_report
2025-04-14 15:37:18,105 DEBUG   HandlerThread:17909 [handler.py:handle_request():146] handle_request: internal_messages
2025-04-14 15:37:18,105 DEBUG   HandlerThread:17909 [handler.py:handle_request():146] handle_request: stop_status
2025-04-14 15:37:18,105 DEBUG   HandlerThread:17909 [handler.py:handle_request():146] handle_request: status_report
2025-04-14 15:37:18,105 DEBUG   HandlerThread:17909 [handler.py:handle_request():146] handle_request: keepalive
2025-04-14 15:37:18,105 DEBUG   HandlerThread:17909 [handler.py:handle_request():146] handle_request: status_report
2025-04-14 15:37:18,105 DEBUG   HandlerThread:17909 [handler.py:handle_request():146] handle_request: keepalive
2025-04-14 15:37:18,106 DEBUG   SenderThread:17909 [sender.py:send_request():407] send_request: stop_status
2025-04-14 15:37:18,106 DEBUG   HandlerThread:17909 [handler.py:handle_request():146] handle_request: status_report
2025-04-14 15:37:18,113 DEBUG   HandlerThread:17909 [handler.py:handle_request():146] handle_request: keepalive
2025-04-14 15:37:18,113 DEBUG   HandlerThread:17909 [handler.py:handle_request():146] handle_request: status_report
2025-04-14 15:37:18,113 DEBUG   HandlerThread:17909 [handler.py:handle_request():146] handle_request: keepalive
2025-04-14 15:37:18,113 DEBUG   HandlerThread:17909 [handler.py:handle_request():146] handle_request: status_report
2025-04-14 15:37:18,113 DEBUG   HandlerThread:17909 [handler.py:handle_request():146] handle_request: keepalive
2025-04-14 15:37:18,113 DEBUG   HandlerThread:17909 [handler.py:handle_request():146] handle_request: status_report
2025-04-14 15:37:18,113 DEBUG   HandlerThread:17909 [handler.py:handle_request():146] handle_request: keepalive
2025-04-14 15:37:18,114 DEBUG   HandlerThread:17909 [handler.py:handle_request():146] handle_request: status_report
2025-04-14 15:37:18,114 DEBUG   HandlerThread:17909 [handler.py:handle_request():146] handle_request: keepalive
2025-04-14 15:37:18,114 DEBUG   HandlerThread:17909 [handler.py:handle_request():146] handle_request: status_report
2025-04-14 15:37:18,114 DEBUG   HandlerThread:17909 [handler.py:handle_request():146] handle_request: keepalive
2025-04-14 15:37:18,114 DEBUG   HandlerThread:17909 [handler.py:handle_request():146] handle_request: status_report
2025-04-14 15:37:18,114 DEBUG   HandlerThread:17909 [handler.py:handle_request():146] handle_request: keepalive
2025-04-14 15:37:18,114 DEBUG   HandlerThread:17909 [handler.py:handle_request():146] handle_request: status_report
2025-04-14 15:37:18,114 DEBUG   HandlerThread:17909 [handler.py:handle_request():146] handle_request: keepalive
2025-04-14 15:37:18,414 DEBUG   SenderThread:17909 [sender.py:send():380] send: telemetry
2025-04-14 15:37:18,414 DEBUG   SenderThread:17909 [sender.py:send():380] send: config
2025-04-14 15:37:18,415 DEBUG   SenderThread:17909 [sender.py:send():380] send: metric
2025-04-14 15:37:18,415 DEBUG   SenderThread:17909 [sender.py:send():380] send: telemetry
2025-04-14 15:37:18,415 DEBUG   SenderThread:17909 [sender.py:send():380] send: metric
2025-04-14 15:37:18,415 WARNING SenderThread:17909 [sender.py:send_metric():1329] Seen metric with glob (shouldn't happen)
2025-04-14 15:37:18,416 DEBUG   SenderThread:17909 [sender.py:send():380] send: stats
2025-04-14 15:37:18,417 DEBUG   SenderThread:17909 [sender.py:send():380] send: files
2025-04-14 15:37:18,417 INFO    SenderThread:17909 [sender.py:_save_file():1378] saving file wandb-metadata.json with policy now
2025-04-14 15:37:18,948 ERROR   wandb-upload_0:17909 [internal_api.py:upload_file():2556] upload_file exception https://storage.googleapis.com/wandb-production.appspot.com/2931823730-harbin-institute-of-technology/ltu-as/wb7imiry/wandb-metadata.json?X-Goog-Algorithm=GOOG4-RSA-SHA256&X-Goog-Credential=gorilla-files-url-signer-man%40wandb-production.iam.gserviceaccount.com%2F20250414%2Fauto%2Fstorage%2Fgoog4_request&X-Goog-Date=20250414T153718Z&X-Goog-Expires=86399&X-Goog-Signature=133ce96984b25332e1c6ffbb9e47ac06b76e9be107576432f958a39307ee215044e48789fcd0afd74c7a07e46b6f7d048e68a2e61aaaf129526ffc11ccdcca23dacdcb877cf906889b08f6cd1678dc0ec1feb0cdc8bf78dd26f372b6fd1d718149884b5269ca33e6f40a1bcf89ade53be62765aa00625415b091b40c81324e83586558cf027a5feae64fe4294afd4e5560cedd85c1f2f0105f91c5a158600793fa3034b8240a7d2e379591474bd825c8c817e5da730178eda2015d4a1436f7cc9eec094ac820ec8ccb6644c4fb6de8ebf03ecd355bb1ccbf49eb060d221e5850113ad223708496b3b9462377d6f1a2fbca6ac238fb0d1d062afe377190c112a9&X-Goog-SignedHeaders=host&X-User=2931823730: HTTPSConnectionPool(host='storage.googleapis.com', port=443): Max retries exceeded with url: /wandb-production.appspot.com/2931823730-harbin-institute-of-technology/ltu-as/wb7imiry/wandb-metadata.json?X-Goog-Algorithm=GOOG4-RSA-SHA256&X-Goog-Credential=gorilla-files-url-signer-man%40wandb-production.iam.gserviceaccount.com%2F20250414%2Fauto%2Fstorage%2Fgoog4_request&X-Goog-Date=20250414T153718Z&X-Goog-Expires=86399&X-Goog-Signature=133ce96984b25332e1c6ffbb9e47ac06b76e9be107576432f958a39307ee215044e48789fcd0afd74c7a07e46b6f7d048e68a2e61aaaf129526ffc11ccdcca23dacdcb877cf906889b08f6cd1678dc0ec1feb0cdc8bf78dd26f372b6fd1d718149884b5269ca33e6f40a1bcf89ade53be62765aa00625415b091b40c81324e83586558cf027a5feae64fe4294afd4e5560cedd85c1f2f0105f91c5a158600793fa3034b8240a7d2e379591474bd825c8c817e5da730178eda2015d4a1436f7cc9eec094ac820ec8ccb6644c4fb6de8ebf03ecd355bb1ccbf49eb060d221e5850113ad223708496b3b9462377d6f1a2fbca6ac238fb0d1d062afe377190c112a9&X-Goog-SignedHeaders=host&X-User=2931823730 (Caused by NewConnectionError('<urllib3.connection.HTTPSConnection object at 0x7fcf802ee0e0>: Failed to establish a new connection: [Errno 101] Network is unreachable'))
2025-04-14 15:37:18,948 ERROR   wandb-upload_0:17909 [internal_api.py:upload_file():2558] upload_file request headers: {'User-Agent': 'python-requests/2.32.3', 'Accept-Encoding': 'gzip, deflate, br', 'Accept': '*/*', 'Connection': 'keep-alive', 'Content-Length': '2380'}
2025-04-14 15:37:18,948 ERROR   wandb-upload_0:17909 [internal_api.py:upload_file():2560] upload_file response body: 
2025-04-14 15:37:19,257 INFO    Thread-12 :17909 [dir_watcher.py:_on_file_created():271] file/dir created: /root/ltu-main/ltu-main/src/ltu_as/train_scripts/wandb/run-20250414_153553-wb7imiry/files/output.log
2025-04-14 15:37:19,417 DEBUG   HandlerThread:17909 [handler.py:handle_request():146] handle_request: status_report
2025-04-14 15:37:20,013 ERROR   wandb-upload_0:17909 [internal_api.py:upload_file():2556] upload_file exception https://storage.googleapis.com/wandb-production.appspot.com/2931823730-harbin-institute-of-technology/ltu-as/wb7imiry/wandb-metadata.json?X-Goog-Algorithm=GOOG4-RSA-SHA256&X-Goog-Credential=gorilla-files-url-signer-man%40wandb-production.iam.gserviceaccount.com%2F20250414%2Fauto%2Fstorage%2Fgoog4_request&X-Goog-Date=20250414T153718Z&X-Goog-Expires=86399&X-Goog-Signature=133ce96984b25332e1c6ffbb9e47ac06b76e9be107576432f958a39307ee215044e48789fcd0afd74c7a07e46b6f7d048e68a2e61aaaf129526ffc11ccdcca23dacdcb877cf906889b08f6cd1678dc0ec1feb0cdc8bf78dd26f372b6fd1d718149884b5269ca33e6f40a1bcf89ade53be62765aa00625415b091b40c81324e83586558cf027a5feae64fe4294afd4e5560cedd85c1f2f0105f91c5a158600793fa3034b8240a7d2e379591474bd825c8c817e5da730178eda2015d4a1436f7cc9eec094ac820ec8ccb6644c4fb6de8ebf03ecd355bb1ccbf49eb060d221e5850113ad223708496b3b9462377d6f1a2fbca6ac238fb0d1d062afe377190c112a9&X-Goog-SignedHeaders=host&X-User=2931823730: HTTPSConnectionPool(host='storage.googleapis.com', port=443): Max retries exceeded with url: /wandb-production.appspot.com/2931823730-harbin-institute-of-technology/ltu-as/wb7imiry/wandb-metadata.json?X-Goog-Algorithm=GOOG4-RSA-SHA256&X-Goog-Credential=gorilla-files-url-signer-man%40wandb-production.iam.gserviceaccount.com%2F20250414%2Fauto%2Fstorage%2Fgoog4_request&X-Goog-Date=20250414T153718Z&X-Goog-Expires=86399&X-Goog-Signature=133ce96984b25332e1c6ffbb9e47ac06b76e9be107576432f958a39307ee215044e48789fcd0afd74c7a07e46b6f7d048e68a2e61aaaf129526ffc11ccdcca23dacdcb877cf906889b08f6cd1678dc0ec1feb0cdc8bf78dd26f372b6fd1d718149884b5269ca33e6f40a1bcf89ade53be62765aa00625415b091b40c81324e83586558cf027a5feae64fe4294afd4e5560cedd85c1f2f0105f91c5a158600793fa3034b8240a7d2e379591474bd825c8c817e5da730178eda2015d4a1436f7cc9eec094ac820ec8ccb6644c4fb6de8ebf03ecd355bb1ccbf49eb060d221e5850113ad223708496b3b9462377d6f1a2fbca6ac238fb0d1d062afe377190c112a9&X-Goog-SignedHeaders=host&X-User=2931823730 (Caused by NewConnectionError('<urllib3.connection.HTTPSConnection object at 0x7fcf802ee380>: Failed to establish a new connection: [Errno 101] Network is unreachable'))
2025-04-14 15:37:20,013 ERROR   wandb-upload_0:17909 [internal_api.py:upload_file():2558] upload_file request headers: {'User-Agent': 'python-requests/2.32.3', 'Accept-Encoding': 'gzip, deflate, br', 'Accept': '*/*', 'Connection': 'keep-alive', 'Content-Length': '2380'}
2025-04-14 15:37:20,013 ERROR   wandb-upload_0:17909 [internal_api.py:upload_file():2560] upload_file response body: 
2025-04-14 15:37:20,117 DEBUG   HandlerThread:17909 [handler.py:handle_request():146] handle_request: keepalive
2025-04-14 15:37:21,258 INFO    Thread-12 :17909 [dir_watcher.py:_on_file_modified():288] file/dir modified: /root/ltu-main/ltu-main/src/ltu_as/train_scripts/wandb/run-20250414_153553-wb7imiry/files/output.log
2025-04-14 15:37:22,288 ERROR   wandb-upload_0:17909 [internal_api.py:upload_file():2556] upload_file exception https://storage.googleapis.com/wandb-production.appspot.com/2931823730-harbin-institute-of-technology/ltu-as/wb7imiry/wandb-metadata.json?X-Goog-Algorithm=GOOG4-RSA-SHA256&X-Goog-Credential=gorilla-files-url-signer-man%40wandb-production.iam.gserviceaccount.com%2F20250414%2Fauto%2Fstorage%2Fgoog4_request&X-Goog-Date=20250414T153718Z&X-Goog-Expires=86399&X-Goog-Signature=133ce96984b25332e1c6ffbb9e47ac06b76e9be107576432f958a39307ee215044e48789fcd0afd74c7a07e46b6f7d048e68a2e61aaaf129526ffc11ccdcca23dacdcb877cf906889b08f6cd1678dc0ec1feb0cdc8bf78dd26f372b6fd1d718149884b5269ca33e6f40a1bcf89ade53be62765aa00625415b091b40c81324e83586558cf027a5feae64fe4294afd4e5560cedd85c1f2f0105f91c5a158600793fa3034b8240a7d2e379591474bd825c8c817e5da730178eda2015d4a1436f7cc9eec094ac820ec8ccb6644c4fb6de8ebf03ecd355bb1ccbf49eb060d221e5850113ad223708496b3b9462377d6f1a2fbca6ac238fb0d1d062afe377190c112a9&X-Goog-SignedHeaders=host&X-User=2931823730: HTTPSConnectionPool(host='storage.googleapis.com', port=443): Max retries exceeded with url: /wandb-production.appspot.com/2931823730-harbin-institute-of-technology/ltu-as/wb7imiry/wandb-metadata.json?X-Goog-Algorithm=GOOG4-RSA-SHA256&X-Goog-Credential=gorilla-files-url-signer-man%40wandb-production.iam.gserviceaccount.com%2F20250414%2Fauto%2Fstorage%2Fgoog4_request&X-Goog-Date=20250414T153718Z&X-Goog-Expires=86399&X-Goog-Signature=133ce96984b25332e1c6ffbb9e47ac06b76e9be107576432f958a39307ee215044e48789fcd0afd74c7a07e46b6f7d048e68a2e61aaaf129526ffc11ccdcca23dacdcb877cf906889b08f6cd1678dc0ec1feb0cdc8bf78dd26f372b6fd1d718149884b5269ca33e6f40a1bcf89ade53be62765aa00625415b091b40c81324e83586558cf027a5feae64fe4294afd4e5560cedd85c1f2f0105f91c5a158600793fa3034b8240a7d2e379591474bd825c8c817e5da730178eda2015d4a1436f7cc9eec094ac820ec8ccb6644c4fb6de8ebf03ecd355bb1ccbf49eb060d221e5850113ad223708496b3b9462377d6f1a2fbca6ac238fb0d1d062afe377190c112a9&X-Goog-SignedHeaders=host&X-User=2931823730 (Caused by NewConnectionError('<urllib3.connection.HTTPSConnection object at 0x7fcf802ee8f0>: Failed to establish a new connection: [Errno 101] Network is unreachable'))
2025-04-14 15:37:22,288 ERROR   wandb-upload_0:17909 [internal_api.py:upload_file():2558] upload_file request headers: {'User-Agent': 'python-requests/2.32.3', 'Accept-Encoding': 'gzip, deflate, br', 'Accept': '*/*', 'Connection': 'keep-alive', 'Content-Length': '2380'}
2025-04-14 15:37:22,288 ERROR   wandb-upload_0:17909 [internal_api.py:upload_file():2560] upload_file response body: 
2025-04-14 15:37:22,288 INFO    wandb-upload_0:17909 [retry.py:__call__():172] Retry attempt failed:
Traceback (most recent call last):
  File "/root/anaconda3/envs/venv_ltu/lib/python3.10/site-packages/urllib3/connection.py", line 198, in _new_conn
    sock = connection.create_connection(
  File "/root/anaconda3/envs/venv_ltu/lib/python3.10/site-packages/urllib3/util/connection.py", line 85, in create_connection
    raise err
  File "/root/anaconda3/envs/venv_ltu/lib/python3.10/site-packages/urllib3/util/connection.py", line 73, in create_connection
    sock.connect(sa)
OSError: [Errno 101] Network is unreachable

The above exception was the direct cause of the following exception:

Traceback (most recent call last):
  File "/root/anaconda3/envs/venv_ltu/lib/python3.10/site-packages/urllib3/connectionpool.py", line 793, in urlopen
    response = self._make_request(
  File "/root/anaconda3/envs/venv_ltu/lib/python3.10/site-packages/urllib3/connectionpool.py", line 491, in _make_request
    raise new_e
  File "/root/anaconda3/envs/venv_ltu/lib/python3.10/site-packages/urllib3/connectionpool.py", line 467, in _make_request
    self._validate_conn(conn)
  File "/root/anaconda3/envs/venv_ltu/lib/python3.10/site-packages/urllib3/connectionpool.py", line 1099, in _validate_conn
    conn.connect()
  File "/root/anaconda3/envs/venv_ltu/lib/python3.10/site-packages/urllib3/connection.py", line 616, in connect
    self.sock = sock = self._new_conn()
  File "/root/anaconda3/envs/venv_ltu/lib/python3.10/site-packages/urllib3/connection.py", line 213, in _new_conn
    raise NewConnectionError(
urllib3.exceptions.NewConnectionError: <urllib3.connection.HTTPSConnection object at 0x7fcf802ee8f0>: Failed to establish a new connection: [Errno 101] Network is unreachable

The above exception was the direct cause of the following exception:

Traceback (most recent call last):
  File "/root/anaconda3/envs/venv_ltu/lib/python3.10/site-packages/requests/adapters.py", line 667, in send
    resp = conn.urlopen(
  File "/root/anaconda3/envs/venv_ltu/lib/python3.10/site-packages/urllib3/connectionpool.py", line 847, in urlopen
    retries = retries.increment(
  File "/root/anaconda3/envs/venv_ltu/lib/python3.10/site-packages/urllib3/util/retry.py", line 515, in increment
    raise MaxRetryError(_pool, url, reason) from reason  # type: ignore[arg-type]
urllib3.exceptions.MaxRetryError: HTTPSConnectionPool(host='storage.googleapis.com', port=443): Max retries exceeded with url: /wandb-production.appspot.com/2931823730-harbin-institute-of-technology/ltu-as/wb7imiry/wandb-metadata.json?X-Goog-Algorithm=GOOG4-RSA-SHA256&X-Goog-Credential=gorilla-files-url-signer-man%40wandb-production.iam.gserviceaccount.com%2F20250414%2Fauto%2Fstorage%2Fgoog4_request&X-Goog-Date=20250414T153718Z&X-Goog-Expires=86399&X-Goog-Signature=133ce96984b25332e1c6ffbb9e47ac06b76e9be107576432f958a39307ee215044e48789fcd0afd74c7a07e46b6f7d048e68a2e61aaaf129526ffc11ccdcca23dacdcb877cf906889b08f6cd1678dc0ec1feb0cdc8bf78dd26f372b6fd1d718149884b5269ca33e6f40a1bcf89ade53be62765aa00625415b091b40c81324e83586558cf027a5feae64fe4294afd4e5560cedd85c1f2f0105f91c5a158600793fa3034b8240a7d2e379591474bd825c8c817e5da730178eda2015d4a1436f7cc9eec094ac820ec8ccb6644c4fb6de8ebf03ecd355bb1ccbf49eb060d221e5850113ad223708496b3b9462377d6f1a2fbca6ac238fb0d1d062afe377190c112a9&X-Goog-SignedHeaders=host&X-User=2931823730 (Caused by NewConnectionError('<urllib3.connection.HTTPSConnection object at 0x7fcf802ee8f0>: Failed to establish a new connection: [Errno 101] Network is unreachable'))

During handling of the above exception, another exception occurred:

Traceback (most recent call last):
  File "/root/anaconda3/envs/venv_ltu/lib/python3.10/site-packages/wandb/sdk/internal/internal_api.py", line 2549, in upload_file
    response = self._upload_file_session.put(
  File "/root/anaconda3/envs/venv_ltu/lib/python3.10/site-packages/requests/sessions.py", line 649, in put
    return self.request("PUT", url, data=data, **kwargs)
  File "/root/anaconda3/envs/venv_ltu/lib/python3.10/site-packages/requests/sessions.py", line 589, in request
    resp = self.send(prep, **send_kwargs)
  File "/root/anaconda3/envs/venv_ltu/lib/python3.10/site-packages/requests/sessions.py", line 703, in send
    r = adapter.send(request, **kwargs)
  File "/root/anaconda3/envs/venv_ltu/lib/python3.10/site-packages/requests/adapters.py", line 700, in send
    raise ConnectionError(e, request=request)
requests.exceptions.ConnectionError: HTTPSConnectionPool(host='storage.googleapis.com', port=443): Max retries exceeded with url: /wandb-production.appspot.com/2931823730-harbin-institute-of-technology/ltu-as/wb7imiry/wandb-metadata.json?X-Goog-Algorithm=GOOG4-RSA-SHA256&X-Goog-Credential=gorilla-files-url-signer-man%40wandb-production.iam.gserviceaccount.com%2F20250414%2Fauto%2Fstorage%2Fgoog4_request&X-Goog-Date=20250414T153718Z&X-Goog-Expires=86399&X-Goog-Signature=133ce96984b25332e1c6ffbb9e47ac06b76e9be107576432f958a39307ee215044e48789fcd0afd74c7a07e46b6f7d048e68a2e61aaaf129526ffc11ccdcca23dacdcb877cf906889b08f6cd1678dc0ec1feb0cdc8bf78dd26f372b6fd1d718149884b5269ca33e6f40a1bcf89ade53be62765aa00625415b091b40c81324e83586558cf027a5feae64fe4294afd4e5560cedd85c1f2f0105f91c5a158600793fa3034b8240a7d2e379591474bd825c8c817e5da730178eda2015d4a1436f7cc9eec094ac820ec8ccb6644c4fb6de8ebf03ecd355bb1ccbf49eb060d221e5850113ad223708496b3b9462377d6f1a2fbca6ac238fb0d1d062afe377190c112a9&X-Goog-SignedHeaders=host&X-User=2931823730 (Caused by NewConnectionError('<urllib3.connection.HTTPSConnection object at 0x7fcf802ee8f0>: Failed to establish a new connection: [Errno 101] Network is unreachable'))

During handling of the above exception, another exception occurred:

Traceback (most recent call last):
  File "/root/anaconda3/envs/venv_ltu/lib/python3.10/site-packages/wandb/sdk/lib/retry.py", line 131, in __call__
    result = self._call_fn(*args, **kwargs)
  File "/root/anaconda3/envs/venv_ltu/lib/python3.10/site-packages/wandb/sdk/internal/internal_api.py", line 2580, in upload_file
    raise _e.with_traceback(sys.exc_info()[2])
  File "/root/anaconda3/envs/venv_ltu/lib/python3.10/site-packages/wandb/sdk/internal/internal_api.py", line 2549, in upload_file
    response = self._upload_file_session.put(
  File "/root/anaconda3/envs/venv_ltu/lib/python3.10/site-packages/requests/sessions.py", line 649, in put
    return self.request("PUT", url, data=data, **kwargs)
  File "/root/anaconda3/envs/venv_ltu/lib/python3.10/site-packages/requests/sessions.py", line 589, in request
    resp = self.send(prep, **send_kwargs)
  File "/root/anaconda3/envs/venv_ltu/lib/python3.10/site-packages/requests/sessions.py", line 703, in send
    r = adapter.send(request, **kwargs)
  File "/root/anaconda3/envs/venv_ltu/lib/python3.10/site-packages/requests/adapters.py", line 700, in send
    raise ConnectionError(e, request=request)
wandb.sdk.lib.retry.TransientError: None
2025-04-14 15:37:24,423 DEBUG   HandlerThread:17909 [handler.py:handle_request():146] handle_request: status_report
2025-04-14 15:37:24,982 DEBUG   SenderThread:17909 [sender.py:send():380] send: stats
2025-04-14 15:37:25,120 DEBUG   HandlerThread:17909 [handler.py:handle_request():146] handle_request: keepalive
2025-04-14 15:37:25,259 INFO    Thread-12 :17909 [dir_watcher.py:_on_file_modified():288] file/dir modified: /root/ltu-main/ltu-main/src/ltu_as/train_scripts/wandb/run-20250414_153553-wb7imiry/files/config.yaml
2025-04-14 15:37:26,383 DEBUG   SenderThread:17909 [sender.py:send():380] send: exit
2025-04-14 15:37:26,383 INFO    SenderThread:17909 [sender.py:send_exit():585] handling exit code: 255
2025-04-14 15:37:26,383 INFO    SenderThread:17909 [sender.py:send_exit():587] handling runtime: 91
2025-04-14 15:37:26,383 INFO    SenderThread:17909 [sender.py:_save_file():1378] saving file wandb-summary.json with policy end
2025-04-14 15:37:26,384 INFO    SenderThread:17909 [sender.py:send_exit():593] send defer
2025-04-14 15:37:26,384 DEBUG   HandlerThread:17909 [handler.py:handle_request():146] handle_request: defer
2025-04-14 15:37:26,384 INFO    HandlerThread:17909 [handler.py:handle_request_defer():172] handle defer: 0
2025-04-14 15:37:26,385 DEBUG   SenderThread:17909 [sender.py:send_request():407] send_request: defer
2025-04-14 15:37:26,385 INFO    SenderThread:17909 [sender.py:send_request_defer():609] handle sender defer: 0
2025-04-14 15:37:26,385 INFO    SenderThread:17909 [sender.py:transition_state():613] send defer: 1
2025-04-14 15:37:26,385 DEBUG   HandlerThread:17909 [handler.py:handle_request():146] handle_request: defer
2025-04-14 15:37:26,385 INFO    HandlerThread:17909 [handler.py:handle_request_defer():172] handle defer: 1
2025-04-14 15:37:26,385 DEBUG   SenderThread:17909 [sender.py:send_request():407] send_request: defer
2025-04-14 15:37:26,386 INFO    SenderThread:17909 [sender.py:send_request_defer():609] handle sender defer: 1
2025-04-14 15:37:26,386 INFO    SenderThread:17909 [sender.py:transition_state():613] send defer: 2
2025-04-14 15:37:26,386 DEBUG   HandlerThread:17909 [handler.py:handle_request():146] handle_request: defer
2025-04-14 15:37:26,386 INFO    HandlerThread:17909 [handler.py:handle_request_defer():172] handle defer: 2
2025-04-14 15:37:26,386 INFO    HandlerThread:17909 [system_monitor.py:finish():203] Stopping system monitor
2025-04-14 15:37:26,386 DEBUG   SystemMonitor:17909 [system_monitor.py:_start():179] Finished system metrics aggregation loop
2025-04-14 15:37:26,386 DEBUG   SystemMonitor:17909 [system_monitor.py:_start():183] Publishing last batch of metrics
2025-04-14 15:37:26,388 INFO    HandlerThread:17909 [interfaces.py:finish():202] Joined cpu monitor
2025-04-14 15:37:26,388 INFO    HandlerThread:17909 [interfaces.py:finish():202] Joined disk monitor
2025-04-14 15:37:26,438 INFO    HandlerThread:17909 [interfaces.py:finish():202] Joined gpu monitor
2025-04-14 15:37:26,438 INFO    HandlerThread:17909 [interfaces.py:finish():202] Joined memory monitor
2025-04-14 15:37:26,438 INFO    HandlerThread:17909 [interfaces.py:finish():202] Joined network monitor
2025-04-14 15:37:26,439 DEBUG   SenderThread:17909 [sender.py:send_request():407] send_request: defer
2025-04-14 15:37:26,439 INFO    SenderThread:17909 [sender.py:send_request_defer():609] handle sender defer: 2
2025-04-14 15:37:26,439 INFO    SenderThread:17909 [sender.py:transition_state():613] send defer: 3
2025-04-14 15:37:26,439 DEBUG   SenderThread:17909 [sender.py:send():380] send: stats
2025-04-14 15:37:26,440 DEBUG   HandlerThread:17909 [handler.py:handle_request():146] handle_request: defer
2025-04-14 15:37:26,440 INFO    HandlerThread:17909 [handler.py:handle_request_defer():172] handle defer: 3
2025-04-14 15:37:26,441 DEBUG   SenderThread:17909 [sender.py:send_request():407] send_request: defer
2025-04-14 15:37:26,441 INFO    SenderThread:17909 [sender.py:send_request_defer():609] handle sender defer: 3
2025-04-14 15:37:26,441 INFO    SenderThread:17909 [sender.py:transition_state():613] send defer: 4
2025-04-14 15:37:26,441 DEBUG   HandlerThread:17909 [handler.py:handle_request():146] handle_request: defer
2025-04-14 15:37:26,441 INFO    HandlerThread:17909 [handler.py:handle_request_defer():172] handle defer: 4
2025-04-14 15:37:26,441 DEBUG   SenderThread:17909 [sender.py:send_request():407] send_request: defer
2025-04-14 15:37:26,441 INFO    SenderThread:17909 [sender.py:send_request_defer():609] handle sender defer: 4
2025-04-14 15:37:26,441 INFO    SenderThread:17909 [sender.py:transition_state():613] send defer: 5
2025-04-14 15:37:26,442 DEBUG   HandlerThread:17909 [handler.py:handle_request():146] handle_request: defer
2025-04-14 15:37:26,442 INFO    HandlerThread:17909 [handler.py:handle_request_defer():172] handle defer: 5
2025-04-14 15:37:26,442 DEBUG   SenderThread:17909 [sender.py:send():380] send: summary
2025-04-14 15:37:26,457 INFO    SenderThread:17909 [sender.py:_save_file():1378] saving file wandb-summary.json with policy end
2025-04-14 15:37:26,457 DEBUG   SenderThread:17909 [sender.py:send_request():407] send_request: defer
2025-04-14 15:37:26,457 INFO    SenderThread:17909 [sender.py:send_request_defer():609] handle sender defer: 5
2025-04-14 15:37:26,457 INFO    SenderThread:17909 [sender.py:transition_state():613] send defer: 6
2025-04-14 15:37:26,457 DEBUG   HandlerThread:17909 [handler.py:handle_request():146] handle_request: defer
2025-04-14 15:37:26,457 INFO    HandlerThread:17909 [handler.py:handle_request_defer():172] handle defer: 6
2025-04-14 15:37:26,458 DEBUG   SenderThread:17909 [sender.py:send_request():407] send_request: defer
2025-04-14 15:37:26,458 INFO    SenderThread:17909 [sender.py:send_request_defer():609] handle sender defer: 6
2025-04-14 15:37:26,458 INFO    SenderThread:17909 [sender.py:transition_state():613] send defer: 7
2025-04-14 15:37:26,458 DEBUG   HandlerThread:17909 [handler.py:handle_request():146] handle_request: status_report
2025-04-14 15:37:26,458 DEBUG   HandlerThread:17909 [handler.py:handle_request():146] handle_request: defer
2025-04-14 15:37:26,459 INFO    HandlerThread:17909 [handler.py:handle_request_defer():172] handle defer: 7
2025-04-14 15:37:26,459 DEBUG   SenderThread:17909 [sender.py:send_request():407] send_request: defer
2025-04-14 15:37:26,459 INFO    SenderThread:17909 [sender.py:send_request_defer():609] handle sender defer: 7
2025-04-14 15:37:27,072 ERROR   wandb-upload_0:17909 [internal_api.py:upload_file():2556] upload_file exception https://storage.googleapis.com/wandb-production.appspot.com/2931823730-harbin-institute-of-technology/ltu-as/wb7imiry/wandb-metadata.json?X-Goog-Algorithm=GOOG4-RSA-SHA256&X-Goog-Credential=gorilla-files-url-signer-man%40wandb-production.iam.gserviceaccount.com%2F20250414%2Fauto%2Fstorage%2Fgoog4_request&X-Goog-Date=20250414T153718Z&X-Goog-Expires=86399&X-Goog-Signature=133ce96984b25332e1c6ffbb9e47ac06b76e9be107576432f958a39307ee215044e48789fcd0afd74c7a07e46b6f7d048e68a2e61aaaf129526ffc11ccdcca23dacdcb877cf906889b08f6cd1678dc0ec1feb0cdc8bf78dd26f372b6fd1d718149884b5269ca33e6f40a1bcf89ade53be62765aa00625415b091b40c81324e83586558cf027a5feae64fe4294afd4e5560cedd85c1f2f0105f91c5a158600793fa3034b8240a7d2e379591474bd825c8c817e5da730178eda2015d4a1436f7cc9eec094ac820ec8ccb6644c4fb6de8ebf03ecd355bb1ccbf49eb060d221e5850113ad223708496b3b9462377d6f1a2fbca6ac238fb0d1d062afe377190c112a9&X-Goog-SignedHeaders=host&X-User=2931823730: HTTPSConnectionPool(host='storage.googleapis.com', port=443): Max retries exceeded with url: /wandb-production.appspot.com/2931823730-harbin-institute-of-technology/ltu-as/wb7imiry/wandb-metadata.json?X-Goog-Algorithm=GOOG4-RSA-SHA256&X-Goog-Credential=gorilla-files-url-signer-man%40wandb-production.iam.gserviceaccount.com%2F20250414%2Fauto%2Fstorage%2Fgoog4_request&X-Goog-Date=20250414T153718Z&X-Goog-Expires=86399&X-Goog-Signature=133ce96984b25332e1c6ffbb9e47ac06b76e9be107576432f958a39307ee215044e48789fcd0afd74c7a07e46b6f7d048e68a2e61aaaf129526ffc11ccdcca23dacdcb877cf906889b08f6cd1678dc0ec1feb0cdc8bf78dd26f372b6fd1d718149884b5269ca33e6f40a1bcf89ade53be62765aa00625415b091b40c81324e83586558cf027a5feae64fe4294afd4e5560cedd85c1f2f0105f91c5a158600793fa3034b8240a7d2e379591474bd825c8c817e5da730178eda2015d4a1436f7cc9eec094ac820ec8ccb6644c4fb6de8ebf03ecd355bb1ccbf49eb060d221e5850113ad223708496b3b9462377d6f1a2fbca6ac238fb0d1d062afe377190c112a9&X-Goog-SignedHeaders=host&X-User=2931823730 (Caused by NewConnectionError('<urllib3.connection.HTTPSConnection object at 0x7fcf802efd30>: Failed to establish a new connection: [Errno 101] Network is unreachable'))
2025-04-14 15:37:27,072 ERROR   wandb-upload_0:17909 [internal_api.py:upload_file():2558] upload_file request headers: {'User-Agent': 'python-requests/2.32.3', 'Accept-Encoding': 'gzip, deflate, br', 'Accept': '*/*', 'Connection': 'keep-alive', 'Content-Length': '2380'}
2025-04-14 15:37:27,072 ERROR   wandb-upload_0:17909 [internal_api.py:upload_file():2560] upload_file response body: 
2025-04-14 15:37:27,260 INFO    Thread-12 :17909 [dir_watcher.py:_on_file_created():271] file/dir created: /root/ltu-main/ltu-main/src/ltu_as/train_scripts/wandb/run-20250414_153553-wb7imiry/files/wandb-summary.json
2025-04-14 15:37:27,383 DEBUG   HandlerThread:17909 [handler.py:handle_request():146] handle_request: poll_exit
2025-04-14 15:37:28,440 INFO    SenderThread:17909 [sender.py:transition_state():613] send defer: 8
2025-04-14 15:37:28,441 DEBUG   SenderThread:17909 [sender.py:send_request():407] send_request: poll_exit
2025-04-14 15:37:28,441 DEBUG   HandlerThread:17909 [handler.py:handle_request():146] handle_request: defer
2025-04-14 15:37:28,442 INFO    HandlerThread:17909 [handler.py:handle_request_defer():172] handle defer: 8
2025-04-14 15:37:28,442 DEBUG   SenderThread:17909 [sender.py:send_request():407] send_request: defer
2025-04-14 15:37:28,442 INFO    SenderThread:17909 [sender.py:send_request_defer():609] handle sender defer: 8
2025-04-14 15:37:28,442 INFO    SenderThread:17909 [job_builder.py:build():281] Attempting to build job artifact
2025-04-14 15:37:28,443 INFO    SenderThread:17909 [job_builder.py:_get_source_type():404] no source found
2025-04-14 15:37:28,443 INFO    SenderThread:17909 [sender.py:transition_state():613] send defer: 9
2025-04-14 15:37:28,443 DEBUG   HandlerThread:17909 [handler.py:handle_request():146] handle_request: defer
2025-04-14 15:37:28,444 INFO    HandlerThread:17909 [handler.py:handle_request_defer():172] handle defer: 9
2025-04-14 15:37:28,444 DEBUG   SenderThread:17909 [sender.py:send_request():407] send_request: defer
2025-04-14 15:37:28,444 INFO    SenderThread:17909 [sender.py:send_request_defer():609] handle sender defer: 9
2025-04-14 15:37:28,444 INFO    SenderThread:17909 [dir_watcher.py:finish():358] shutting down directory watcher
2025-04-14 15:37:29,261 INFO    Thread-12 :17909 [dir_watcher.py:_on_file_modified():288] file/dir modified: /root/ltu-main/ltu-main/src/ltu_as/train_scripts/wandb/run-20250414_153553-wb7imiry/files/output.log
2025-04-14 15:37:29,262 INFO    SenderThread:17909 [dir_watcher.py:finish():388] scan: /root/ltu-main/ltu-main/src/ltu_as/train_scripts/wandb/run-20250414_153553-wb7imiry/files
2025-04-14 15:37:29,263 INFO    SenderThread:17909 [dir_watcher.py:finish():402] scan save: /root/ltu-main/ltu-main/src/ltu_as/train_scripts/wandb/run-20250414_153553-wb7imiry/files/config.yaml config.yaml
2025-04-14 15:37:29,263 INFO    SenderThread:17909 [dir_watcher.py:finish():402] scan save: /root/ltu-main/ltu-main/src/ltu_as/train_scripts/wandb/run-20250414_153553-wb7imiry/files/requirements.txt requirements.txt
2025-04-14 15:37:29,264 INFO    SenderThread:17909 [dir_watcher.py:finish():402] scan save: /root/ltu-main/ltu-main/src/ltu_as/train_scripts/wandb/run-20250414_153553-wb7imiry/files/conda-environment.yaml conda-environment.yaml
2025-04-14 15:37:29,268 INFO    SenderThread:17909 [dir_watcher.py:finish():402] scan save: /root/ltu-main/ltu-main/src/ltu_as/train_scripts/wandb/run-20250414_153553-wb7imiry/files/wandb-metadata.json wandb-metadata.json
2025-04-14 15:37:29,269 INFO    SenderThread:17909 [dir_watcher.py:finish():402] scan save: /root/ltu-main/ltu-main/src/ltu_as/train_scripts/wandb/run-20250414_153553-wb7imiry/files/output.log output.log
2025-04-14 15:37:29,276 INFO    SenderThread:17909 [dir_watcher.py:finish():402] scan save: /root/ltu-main/ltu-main/src/ltu_as/train_scripts/wandb/run-20250414_153553-wb7imiry/files/wandb-summary.json wandb-summary.json
2025-04-14 15:37:29,279 INFO    SenderThread:17909 [sender.py:transition_state():613] send defer: 10
2025-04-14 15:37:29,279 DEBUG   HandlerThread:17909 [handler.py:handle_request():146] handle_request: defer
2025-04-14 15:37:29,280 INFO    HandlerThread:17909 [handler.py:handle_request_defer():172] handle defer: 10
2025-04-14 15:37:29,282 DEBUG   SenderThread:17909 [sender.py:send_request():407] send_request: defer
2025-04-14 15:37:29,283 INFO    SenderThread:17909 [sender.py:send_request_defer():609] handle sender defer: 10
2025-04-14 15:37:29,283 INFO    SenderThread:17909 [file_pusher.py:finish():175] shutting down file pusher
2025-04-14 15:37:29,537 ERROR   wandb-upload_1:17909 [internal_api.py:upload_file():2556] upload_file exception https://storage.googleapis.com/wandb-production.appspot.com/2931823730-harbin-institute-of-technology/ltu-as/wb7imiry/config.yaml?X-Goog-Algorithm=GOOG4-RSA-SHA256&X-Goog-Credential=gorilla-files-url-signer-man%40wandb-production.iam.gserviceaccount.com%2F20250414%2Fauto%2Fstorage%2Fgoog4_request&X-Goog-Date=20250414T153729Z&X-Goog-Expires=86399&X-Goog-Signature=a02996e1ed2131fda4fb7952e5606feacdf720391cf03792afb2611b5f9f58bdc9090c6bcad8ee607c1e301ccb6ed889f68cc77c41d3bafcf148286820d3d6ad798b651c334fc9e1d4cf65ef5ae956d46c29992f6842a66215711898544b2b95c82578a21c3ddf3a1430a2c4aa08a8eb72201753525d7652ce9dbe20f65bd04635e4c8b72807a1fc339fbd1ccfec567b0a97c3b9d16ac32b48490d2c94832d917ff443cf6c0ed71f41dc80534d3f40af06d44040fd898814599a316115899bff507c09869a2bb6457f4d812ec335bbb14524239ed41ada4834b13078804faf5fc31e3e708582c255827b1f39895d45d3d9bf3f38ae1d476757d2ff30d5ed23c0&X-Goog-SignedHeaders=host&X-User=2931823730: HTTPSConnectionPool(host='storage.googleapis.com', port=443): Max retries exceeded with url: /wandb-production.appspot.com/2931823730-harbin-institute-of-technology/ltu-as/wb7imiry/config.yaml?X-Goog-Algorithm=GOOG4-RSA-SHA256&X-Goog-Credential=gorilla-files-url-signer-man%40wandb-production.iam.gserviceaccount.com%2F20250414%2Fauto%2Fstorage%2Fgoog4_request&X-Goog-Date=20250414T153729Z&X-Goog-Expires=86399&X-Goog-Signature=a02996e1ed2131fda4fb7952e5606feacdf720391cf03792afb2611b5f9f58bdc9090c6bcad8ee607c1e301ccb6ed889f68cc77c41d3bafcf148286820d3d6ad798b651c334fc9e1d4cf65ef5ae956d46c29992f6842a66215711898544b2b95c82578a21c3ddf3a1430a2c4aa08a8eb72201753525d7652ce9dbe20f65bd04635e4c8b72807a1fc339fbd1ccfec567b0a97c3b9d16ac32b48490d2c94832d917ff443cf6c0ed71f41dc80534d3f40af06d44040fd898814599a316115899bff507c09869a2bb6457f4d812ec335bbb14524239ed41ada4834b13078804faf5fc31e3e708582c255827b1f39895d45d3d9bf3f38ae1d476757d2ff30d5ed23c0&X-Goog-SignedHeaders=host&X-User=2931823730 (Caused by NewConnectionError('<urllib3.connection.HTTPSConnection object at 0x7fcf802ef4f0>: Failed to establish a new connection: [Errno 101] Network is unreachable'))
2025-04-14 15:37:29,537 ERROR   wandb-upload_1:17909 [internal_api.py:upload_file():2558] upload_file request headers: {'User-Agent': 'python-requests/2.32.3', 'Accept-Encoding': 'gzip, deflate, br', 'Accept': '*/*', 'Connection': 'keep-alive', 'Content-Length': '8685'}
2025-04-14 15:37:29,537 ERROR   wandb-upload_1:17909 [internal_api.py:upload_file():2560] upload_file response body: 
2025-04-14 15:37:29,708 ERROR   wandb-upload_4:17909 [internal_api.py:upload_file():2556] upload_file exception https://storage.googleapis.com/wandb-production.appspot.com/2931823730-harbin-institute-of-technology/ltu-as/wb7imiry/output.log?X-Goog-Algorithm=GOOG4-RSA-SHA256&X-Goog-Credential=gorilla-files-url-signer-man%40wandb-production.iam.gserviceaccount.com%2F20250414%2Fauto%2Fstorage%2Fgoog4_request&X-Goog-Date=20250414T153729Z&X-Goog-Expires=86399&X-Goog-Signature=a018e0af884588e1d3a33148b5c409078172b766de700f2c523030c0d79d97aea5cd34cc350cfba9b311b32eee5753bc272477d6666ce4861f0ed23a926ab89d25c6a23073daa76e9f8387701e15d24a56c54af4ac528cfc965be49ba1e2b4a7a466f81f1c2cf518bb1018a9cec3fc4dde6347533c2886b3655ef987f4348fa4ff1250d03a30d640c8137aab5a15ec0d7c0789799a5a4e27a90f8e6ce0b16cfb93d160dde33e90e29fc9ff7bb21f395fa5e9163e87bc7cd6a2a9aac4b8dd3913845941b64cf39c5ea0963f5760973859f10b28f6f9fe9ae28d014c0b0291bc3ddde0aabf8022d57033886a7136cb527c33ef8743a0e27199a04a4e90d3cd6190&X-Goog-SignedHeaders=host&X-User=2931823730: HTTPSConnectionPool(host='storage.googleapis.com', port=443): Max retries exceeded with url: /wandb-production.appspot.com/2931823730-harbin-institute-of-technology/ltu-as/wb7imiry/output.log?X-Goog-Algorithm=GOOG4-RSA-SHA256&X-Goog-Credential=gorilla-files-url-signer-man%40wandb-production.iam.gserviceaccount.com%2F20250414%2Fauto%2Fstorage%2Fgoog4_request&X-Goog-Date=20250414T153729Z&X-Goog-Expires=86399&X-Goog-Signature=a018e0af884588e1d3a33148b5c409078172b766de700f2c523030c0d79d97aea5cd34cc350cfba9b311b32eee5753bc272477d6666ce4861f0ed23a926ab89d25c6a23073daa76e9f8387701e15d24a56c54af4ac528cfc965be49ba1e2b4a7a466f81f1c2cf518bb1018a9cec3fc4dde6347533c2886b3655ef987f4348fa4ff1250d03a30d640c8137aab5a15ec0d7c0789799a5a4e27a90f8e6ce0b16cfb93d160dde33e90e29fc9ff7bb21f395fa5e9163e87bc7cd6a2a9aac4b8dd3913845941b64cf39c5ea0963f5760973859f10b28f6f9fe9ae28d014c0b0291bc3ddde0aabf8022d57033886a7136cb527c33ef8743a0e27199a04a4e90d3cd6190&X-Goog-SignedHeaders=host&X-User=2931823730 (Caused by NewConnectionError('<urllib3.connection.HTTPSConnection object at 0x7fcf802a2ad0>: Failed to establish a new connection: [Errno 101] Network is unreachable'))
2025-04-14 15:37:29,708 ERROR   wandb-upload_4:17909 [internal_api.py:upload_file():2558] upload_file request headers: {'User-Agent': 'python-requests/2.32.3', 'Accept-Encoding': 'gzip, deflate, br', 'Accept': '*/*', 'Connection': 'keep-alive', 'Content-Length': '2306'}
2025-04-14 15:37:29,708 ERROR   wandb-upload_4:17909 [internal_api.py:upload_file():2560] upload_file response body: 
2025-04-14 15:37:29,708 ERROR   wandb-upload_3:17909 [internal_api.py:upload_file():2556] upload_file exception https://storage.googleapis.com/wandb-production.appspot.com/2931823730-harbin-institute-of-technology/ltu-as/wb7imiry/conda-environment.yaml?X-Goog-Algorithm=GOOG4-RSA-SHA256&X-Goog-Credential=gorilla-files-url-signer-man%40wandb-production.iam.gserviceaccount.com%2F20250414%2Fauto%2Fstorage%2Fgoog4_request&X-Goog-Date=20250414T153729Z&X-Goog-Expires=86399&X-Goog-Signature=bac5dedc97f642fccac419ba44980b416e214710f27419cf169ce497d0c83a266f3eb17da544d1361107f46112f47bfe8c4195381f38e099eba215636e3222352e018db817c1ca65d45038b65e9a9e4a4a3f1f263094a647aa7d8e6a89b5b72d0ff7545d7255f616f6c8a2954a971f692736de265b332a5776aa934f7b1248f5e0264e80f8fffbc221a27a67263610ee275923e8978efdd395b6fe989928bbad87b051026409ff775e582c8dc5e0edb24cf4c3548d5a933005c8c8d4cf729061a0404a3f990768e3f6d129834cff02d1e90080b0551fef70db773f0ee6139561e152ca115f181341ab6e7f4ccc479ef8c3d6978314ab5465a2ac9799ff6b6fc1&X-Goog-SignedHeaders=host&X-User=2931823730: HTTPSConnectionPool(host='storage.googleapis.com', port=443): Max retries exceeded with url: /wandb-production.appspot.com/2931823730-harbin-institute-of-technology/ltu-as/wb7imiry/conda-environment.yaml?X-Goog-Algorithm=GOOG4-RSA-SHA256&X-Goog-Credential=gorilla-files-url-signer-man%40wandb-production.iam.gserviceaccount.com%2F20250414%2Fauto%2Fstorage%2Fgoog4_request&X-Goog-Date=20250414T153729Z&X-Goog-Expires=86399&X-Goog-Signature=bac5dedc97f642fccac419ba44980b416e214710f27419cf169ce497d0c83a266f3eb17da544d1361107f46112f47bfe8c4195381f38e099eba215636e3222352e018db817c1ca65d45038b65e9a9e4a4a3f1f263094a647aa7d8e6a89b5b72d0ff7545d7255f616f6c8a2954a971f692736de265b332a5776aa934f7b1248f5e0264e80f8fffbc221a27a67263610ee275923e8978efdd395b6fe989928bbad87b051026409ff775e582c8dc5e0edb24cf4c3548d5a933005c8c8d4cf729061a0404a3f990768e3f6d129834cff02d1e90080b0551fef70db773f0ee6139561e152ca115f181341ab6e7f4ccc479ef8c3d6978314ab5465a2ac9799ff6b6fc1&X-Goog-SignedHeaders=host&X-User=2931823730 (Caused by NewConnectionError('<urllib3.connection.HTTPSConnection object at 0x7fcf802a12d0>: Failed to establish a new connection: [Errno 101] Network is unreachable'))
2025-04-14 15:37:29,708 ERROR   wandb-upload_3:17909 [internal_api.py:upload_file():2558] upload_file request headers: {'User-Agent': 'python-requests/2.32.3', 'Accept-Encoding': 'gzip, deflate, br', 'Accept': '*/*', 'Connection': 'keep-alive', 'Content-Length': '12277'}
2025-04-14 15:37:29,709 ERROR   wandb-upload_3:17909 [internal_api.py:upload_file():2560] upload_file response body: 
2025-04-14 15:37:29,723 ERROR   wandb-upload_5:17909 [internal_api.py:upload_file():2556] upload_file exception https://storage.googleapis.com/wandb-production.appspot.com/2931823730-harbin-institute-of-technology/ltu-as/wb7imiry/wandb-summary.json?X-Goog-Algorithm=GOOG4-RSA-SHA256&X-Goog-Credential=gorilla-files-url-signer-man%40wandb-production.iam.gserviceaccount.com%2F20250414%2Fauto%2Fstorage%2Fgoog4_request&X-Goog-Date=20250414T153729Z&X-Goog-Expires=86399&X-Goog-Signature=8a24ed4c19410b50f5174dc1034836f3ec0389bd43b65cba44b743abab25ba0377ce388b4b45791bb7cf19f6b5564016d3ff0651308289d350a85b33ccda880557da038b7c1507d5a5837fa6e69e52300be33b61fea1ba1d6fc4fbbabdab94221953bd9a8fbde40a47b58b6e21d9279a543a5e3586f913d78bdc64809216274c849018c193701d0d7ba2da5a5005acecaf2ae1ca4ac15dc455113b4e407ae73db2966eddf9805d919dfb513f74f6048a8e31fe7d58ec0f123b63242e46309df35615b27589492562a7443ad855973fd6ec97c6b3a845e2defcd2a42767f707eb411538afd27d647577fe7537d2453bb803a787864e2f68d4e2885f52487e6246&X-Goog-SignedHeaders=host&X-User=2931823730: HTTPSConnectionPool(host='storage.googleapis.com', port=443): Max retries exceeded with url: /wandb-production.appspot.com/2931823730-harbin-institute-of-technology/ltu-as/wb7imiry/wandb-summary.json?X-Goog-Algorithm=GOOG4-RSA-SHA256&X-Goog-Credential=gorilla-files-url-signer-man%40wandb-production.iam.gserviceaccount.com%2F20250414%2Fauto%2Fstorage%2Fgoog4_request&X-Goog-Date=20250414T153729Z&X-Goog-Expires=86399&X-Goog-Signature=8a24ed4c19410b50f5174dc1034836f3ec0389bd43b65cba44b743abab25ba0377ce388b4b45791bb7cf19f6b5564016d3ff0651308289d350a85b33ccda880557da038b7c1507d5a5837fa6e69e52300be33b61fea1ba1d6fc4fbbabdab94221953bd9a8fbde40a47b58b6e21d9279a543a5e3586f913d78bdc64809216274c849018c193701d0d7ba2da5a5005acecaf2ae1ca4ac15dc455113b4e407ae73db2966eddf9805d919dfb513f74f6048a8e31fe7d58ec0f123b63242e46309df35615b27589492562a7443ad855973fd6ec97c6b3a845e2defcd2a42767f707eb411538afd27d647577fe7537d2453bb803a787864e2f68d4e2885f52487e6246&X-Goog-SignedHeaders=host&X-User=2931823730 (Caused by NewConnectionError('<urllib3.connection.HTTPSConnection object at 0x7fcf802ef700>: Failed to establish a new connection: [Errno 101] Network is unreachable'))
2025-04-14 15:37:29,723 ERROR   wandb-upload_5:17909 [internal_api.py:upload_file():2558] upload_file request headers: {'User-Agent': 'python-requests/2.32.3', 'Accept-Encoding': 'gzip, deflate, br', 'Accept': '*/*', 'Connection': 'keep-alive', 'Content-Length': '27'}
2025-04-14 15:37:29,723 ERROR   wandb-upload_5:17909 [internal_api.py:upload_file():2560] upload_file response body: 
2025-04-14 15:37:29,724 ERROR   wandb-upload_2:17909 [internal_api.py:upload_file():2556] upload_file exception https://storage.googleapis.com/wandb-production.appspot.com/2931823730-harbin-institute-of-technology/ltu-as/wb7imiry/requirements.txt?X-Goog-Algorithm=GOOG4-RSA-SHA256&X-Goog-Credential=gorilla-files-url-signer-man%40wandb-production.iam.gserviceaccount.com%2F20250414%2Fauto%2Fstorage%2Fgoog4_request&X-Goog-Date=20250414T153729Z&X-Goog-Expires=86399&X-Goog-Signature=0ff8dd74c9c27cc06df90315b3d1dcf7796a08432a70f517ce9dd69466b5a367f177b81e3ed2eb2d02477b7336eb52c9991b47a20a1e7f18af803351891c0fc9c3145a9e4209a7105c939164573ab21445d51970ec13c6e9d5ca103fae21e51712b2ac86a598e5c6b94d860197092f063dd0ca0d80273a74aa3a3b4870432c4fab3f22e694c5505b9cc35585be3e6591110957e8fa77c2b344e703561d6b36b5d97b5f52ccc81566ae5b0f3dd6e1cb9f45400fd56ea332118f71ee88a4ac0178e7795da7c47e26faee26f858d61ef33e6ce308d81a30075068eae3f728121a756aef941d2552d4c033eff7c393640d99bd90f3c5ca27f28ece55c6816f69f782&X-Goog-SignedHeaders=host&X-User=2931823730: HTTPSConnectionPool(host='storage.googleapis.com', port=443): Max retries exceeded with url: /wandb-production.appspot.com/2931823730-harbin-institute-of-technology/ltu-as/wb7imiry/requirements.txt?X-Goog-Algorithm=GOOG4-RSA-SHA256&X-Goog-Credential=gorilla-files-url-signer-man%40wandb-production.iam.gserviceaccount.com%2F20250414%2Fauto%2Fstorage%2Fgoog4_request&X-Goog-Date=20250414T153729Z&X-Goog-Expires=86399&X-Goog-Signature=0ff8dd74c9c27cc06df90315b3d1dcf7796a08432a70f517ce9dd69466b5a367f177b81e3ed2eb2d02477b7336eb52c9991b47a20a1e7f18af803351891c0fc9c3145a9e4209a7105c939164573ab21445d51970ec13c6e9d5ca103fae21e51712b2ac86a598e5c6b94d860197092f063dd0ca0d80273a74aa3a3b4870432c4fab3f22e694c5505b9cc35585be3e6591110957e8fa77c2b344e703561d6b36b5d97b5f52ccc81566ae5b0f3dd6e1cb9f45400fd56ea332118f71ee88a4ac0178e7795da7c47e26faee26f858d61ef33e6ce308d81a30075068eae3f728121a756aef941d2552d4c033eff7c393640d99bd90f3c5ca27f28ece55c6816f69f782&X-Goog-SignedHeaders=host&X-User=2931823730 (Caused by NewConnectionError('<urllib3.connection.HTTPSConnection object at 0x7fcf802edf00>: Failed to establish a new connection: [Errno 101] Network is unreachable'))
2025-04-14 15:37:29,725 ERROR   wandb-upload_2:17909 [internal_api.py:upload_file():2558] upload_file request headers: {'User-Agent': 'python-requests/2.32.3', 'Accept-Encoding': 'gzip, deflate, br', 'Accept': '*/*', 'Connection': 'keep-alive', 'Content-Length': '5836'}
2025-04-14 15:37:29,725 ERROR   wandb-upload_2:17909 [internal_api.py:upload_file():2560] upload_file response body: 
2025-04-14 15:37:30,453 WARNING StreamThr :17909 [internal.py:is_dead():414] Internal process exiting, parent pid 17662 disappeared
2025-04-14 15:37:30,453 ERROR   StreamThr :17909 [internal.py:wandb_internal():152] Internal process shutdown.
2025-04-14 15:37:30,596 ERROR   wandb-upload_1:17909 [internal_api.py:upload_file():2556] upload_file exception https://storage.googleapis.com/wandb-production.appspot.com/2931823730-harbin-institute-of-technology/ltu-as/wb7imiry/config.yaml?X-Goog-Algorithm=GOOG4-RSA-SHA256&X-Goog-Credential=gorilla-files-url-signer-man%40wandb-production.iam.gserviceaccount.com%2F20250414%2Fauto%2Fstorage%2Fgoog4_request&X-Goog-Date=20250414T153729Z&X-Goog-Expires=86399&X-Goog-Signature=a02996e1ed2131fda4fb7952e5606feacdf720391cf03792afb2611b5f9f58bdc9090c6bcad8ee607c1e301ccb6ed889f68cc77c41d3bafcf148286820d3d6ad798b651c334fc9e1d4cf65ef5ae956d46c29992f6842a66215711898544b2b95c82578a21c3ddf3a1430a2c4aa08a8eb72201753525d7652ce9dbe20f65bd04635e4c8b72807a1fc339fbd1ccfec567b0a97c3b9d16ac32b48490d2c94832d917ff443cf6c0ed71f41dc80534d3f40af06d44040fd898814599a316115899bff507c09869a2bb6457f4d812ec335bbb14524239ed41ada4834b13078804faf5fc31e3e708582c255827b1f39895d45d3d9bf3f38ae1d476757d2ff30d5ed23c0&X-Goog-SignedHeaders=host&X-User=2931823730: HTTPSConnectionPool(host='storage.googleapis.com', port=443): Max retries exceeded with url: /wandb-production.appspot.com/2931823730-harbin-institute-of-technology/ltu-as/wb7imiry/config.yaml?X-Goog-Algorithm=GOOG4-RSA-SHA256&X-Goog-Credential=gorilla-files-url-signer-man%40wandb-production.iam.gserviceaccount.com%2F20250414%2Fauto%2Fstorage%2Fgoog4_request&X-Goog-Date=20250414T153729Z&X-Goog-Expires=86399&X-Goog-Signature=a02996e1ed2131fda4fb7952e5606feacdf720391cf03792afb2611b5f9f58bdc9090c6bcad8ee607c1e301ccb6ed889f68cc77c41d3bafcf148286820d3d6ad798b651c334fc9e1d4cf65ef5ae956d46c29992f6842a66215711898544b2b95c82578a21c3ddf3a1430a2c4aa08a8eb72201753525d7652ce9dbe20f65bd04635e4c8b72807a1fc339fbd1ccfec567b0a97c3b9d16ac32b48490d2c94832d917ff443cf6c0ed71f41dc80534d3f40af06d44040fd898814599a316115899bff507c09869a2bb6457f4d812ec335bbb14524239ed41ada4834b13078804faf5fc31e3e708582c255827b1f39895d45d3d9bf3f38ae1d476757d2ff30d5ed23c0&X-Goog-SignedHeaders=host&X-User=2931823730 (Caused by NewConnectionError('<urllib3.connection.HTTPSConnection object at 0x7fcf802ec5b0>: Failed to establish a new connection: [Errno 101] Network is unreachable'))
2025-04-14 15:37:30,596 ERROR   wandb-upload_1:17909 [internal_api.py:upload_file():2558] upload_file request headers: {'User-Agent': 'python-requests/2.32.3', 'Accept-Encoding': 'gzip, deflate, br', 'Accept': '*/*', 'Connection': 'keep-alive', 'Content-Length': '8685'}
2025-04-14 15:37:30,596 ERROR   wandb-upload_1:17909 [internal_api.py:upload_file():2560] upload_file response body: 
2025-04-14 15:37:30,745 ERROR   wandb-upload_3:17909 [internal_api.py:upload_file():2556] upload_file exception https://storage.googleapis.com/wandb-production.appspot.com/2931823730-harbin-institute-of-technology/ltu-as/wb7imiry/conda-environment.yaml?X-Goog-Algorithm=GOOG4-RSA-SHA256&X-Goog-Credential=gorilla-files-url-signer-man%40wandb-production.iam.gserviceaccount.com%2F20250414%2Fauto%2Fstorage%2Fgoog4_request&X-Goog-Date=20250414T153729Z&X-Goog-Expires=86399&X-Goog-Signature=bac5dedc97f642fccac419ba44980b416e214710f27419cf169ce497d0c83a266f3eb17da544d1361107f46112f47bfe8c4195381f38e099eba215636e3222352e018db817c1ca65d45038b65e9a9e4a4a3f1f263094a647aa7d8e6a89b5b72d0ff7545d7255f616f6c8a2954a971f692736de265b332a5776aa934f7b1248f5e0264e80f8fffbc221a27a67263610ee275923e8978efdd395b6fe989928bbad87b051026409ff775e582c8dc5e0edb24cf4c3548d5a933005c8c8d4cf729061a0404a3f990768e3f6d129834cff02d1e90080b0551fef70db773f0ee6139561e152ca115f181341ab6e7f4ccc479ef8c3d6978314ab5465a2ac9799ff6b6fc1&X-Goog-SignedHeaders=host&X-User=2931823730: HTTPSConnectionPool(host='storage.googleapis.com', port=443): Max retries exceeded with url: /wandb-production.appspot.com/2931823730-harbin-institute-of-technology/ltu-as/wb7imiry/conda-environment.yaml?X-Goog-Algorithm=GOOG4-RSA-SHA256&X-Goog-Credential=gorilla-files-url-signer-man%40wandb-production.iam.gserviceaccount.com%2F20250414%2Fauto%2Fstorage%2Fgoog4_request&X-Goog-Date=20250414T153729Z&X-Goog-Expires=86399&X-Goog-Signature=bac5dedc97f642fccac419ba44980b416e214710f27419cf169ce497d0c83a266f3eb17da544d1361107f46112f47bfe8c4195381f38e099eba215636e3222352e018db817c1ca65d45038b65e9a9e4a4a3f1f263094a647aa7d8e6a89b5b72d0ff7545d7255f616f6c8a2954a971f692736de265b332a5776aa934f7b1248f5e0264e80f8fffbc221a27a67263610ee275923e8978efdd395b6fe989928bbad87b051026409ff775e582c8dc5e0edb24cf4c3548d5a933005c8c8d4cf729061a0404a3f990768e3f6d129834cff02d1e90080b0551fef70db773f0ee6139561e152ca115f181341ab6e7f4ccc479ef8c3d6978314ab5465a2ac9799ff6b6fc1&X-Goog-SignedHeaders=host&X-User=2931823730 (Caused by NewConnectionError('<urllib3.connection.HTTPSConnection object at 0x7fcf802eecb0>: Failed to establish a new connection: [Errno 101] Network is unreachable'))
2025-04-14 15:37:30,745 ERROR   wandb-upload_3:17909 [internal_api.py:upload_file():2558] upload_file request headers: {'User-Agent': 'python-requests/2.32.3', 'Accept-Encoding': 'gzip, deflate, br', 'Accept': '*/*', 'Connection': 'keep-alive', 'Content-Length': '12277'}
2025-04-14 15:37:30,745 ERROR   wandb-upload_3:17909 [internal_api.py:upload_file():2560] upload_file response body: 
2025-04-14 15:37:30,745 INFO    wandb-upload_3:17909 [retry.py:__call__():172] Retry attempt failed:
Traceback (most recent call last):
  File "/root/anaconda3/envs/venv_ltu/lib/python3.10/site-packages/urllib3/connection.py", line 198, in _new_conn
    sock = connection.create_connection(
  File "/root/anaconda3/envs/venv_ltu/lib/python3.10/site-packages/urllib3/util/connection.py", line 85, in create_connection
    raise err
  File "/root/anaconda3/envs/venv_ltu/lib/python3.10/site-packages/urllib3/util/connection.py", line 73, in create_connection
    sock.connect(sa)
OSError: [Errno 101] Network is unreachable

The above exception was the direct cause of the following exception:

Traceback (most recent call last):
  File "/root/anaconda3/envs/venv_ltu/lib/python3.10/site-packages/urllib3/connectionpool.py", line 793, in urlopen
    response = self._make_request(
  File "/root/anaconda3/envs/venv_ltu/lib/python3.10/site-packages/urllib3/connectionpool.py", line 491, in _make_request
    raise new_e
  File "/root/anaconda3/envs/venv_ltu/lib/python3.10/site-packages/urllib3/connectionpool.py", line 467, in _make_request
    self._validate_conn(conn)
  File "/root/anaconda3/envs/venv_ltu/lib/python3.10/site-packages/urllib3/connectionpool.py", line 1099, in _validate_conn
    conn.connect()
  File "/root/anaconda3/envs/venv_ltu/lib/python3.10/site-packages/urllib3/connection.py", line 616, in connect
    self.sock = sock = self._new_conn()
  File "/root/anaconda3/envs/venv_ltu/lib/python3.10/site-packages/urllib3/connection.py", line 213, in _new_conn
    raise NewConnectionError(
urllib3.exceptions.NewConnectionError: <urllib3.connection.HTTPSConnection object at 0x7fcf802eecb0>: Failed to establish a new connection: [Errno 101] Network is unreachable

The above exception was the direct cause of the following exception:

Traceback (most recent call last):
  File "/root/anaconda3/envs/venv_ltu/lib/python3.10/site-packages/requests/adapters.py", line 667, in send
    resp = conn.urlopen(
  File "/root/anaconda3/envs/venv_ltu/lib/python3.10/site-packages/urllib3/connectionpool.py", line 847, in urlopen
    retries = retries.increment(
  File "/root/anaconda3/envs/venv_ltu/lib/python3.10/site-packages/urllib3/util/retry.py", line 515, in increment
    raise MaxRetryError(_pool, url, reason) from reason  # type: ignore[arg-type]
urllib3.exceptions.MaxRetryError: HTTPSConnectionPool(host='storage.googleapis.com', port=443): Max retries exceeded with url: /wandb-production.appspot.com/2931823730-harbin-institute-of-technology/ltu-as/wb7imiry/conda-environment.yaml?X-Goog-Algorithm=GOOG4-RSA-SHA256&X-Goog-Credential=gorilla-files-url-signer-man%40wandb-production.iam.gserviceaccount.com%2F20250414%2Fauto%2Fstorage%2Fgoog4_request&X-Goog-Date=20250414T153729Z&X-Goog-Expires=86399&X-Goog-Signature=bac5dedc97f642fccac419ba44980b416e214710f27419cf169ce497d0c83a266f3eb17da544d1361107f46112f47bfe8c4195381f38e099eba215636e3222352e018db817c1ca65d45038b65e9a9e4a4a3f1f263094a647aa7d8e6a89b5b72d0ff7545d7255f616f6c8a2954a971f692736de265b332a5776aa934f7b1248f5e0264e80f8fffbc221a27a67263610ee275923e8978efdd395b6fe989928bbad87b051026409ff775e582c8dc5e0edb24cf4c3548d5a933005c8c8d4cf729061a0404a3f990768e3f6d129834cff02d1e90080b0551fef70db773f0ee6139561e152ca115f181341ab6e7f4ccc479ef8c3d6978314ab5465a2ac9799ff6b6fc1&X-Goog-SignedHeaders=host&X-User=2931823730 (Caused by NewConnectionError('<urllib3.connection.HTTPSConnection object at 0x7fcf802eecb0>: Failed to establish a new connection: [Errno 101] Network is unreachable'))

During handling of the above exception, another exception occurred:

Traceback (most recent call last):
  File "/root/anaconda3/envs/venv_ltu/lib/python3.10/site-packages/wandb/sdk/internal/internal_api.py", line 2549, in upload_file
    response = self._upload_file_session.put(
  File "/root/anaconda3/envs/venv_ltu/lib/python3.10/site-packages/requests/sessions.py", line 649, in put
    return self.request("PUT", url, data=data, **kwargs)
  File "/root/anaconda3/envs/venv_ltu/lib/python3.10/site-packages/requests/sessions.py", line 589, in request
    resp = self.send(prep, **send_kwargs)
  File "/root/anaconda3/envs/venv_ltu/lib/python3.10/site-packages/requests/sessions.py", line 703, in send
    r = adapter.send(request, **kwargs)
  File "/root/anaconda3/envs/venv_ltu/lib/python3.10/site-packages/requests/adapters.py", line 700, in send
    raise ConnectionError(e, request=request)
requests.exceptions.ConnectionError: HTTPSConnectionPool(host='storage.googleapis.com', port=443): Max retries exceeded with url: /wandb-production.appspot.com/2931823730-harbin-institute-of-technology/ltu-as/wb7imiry/conda-environment.yaml?X-Goog-Algorithm=GOOG4-RSA-SHA256&X-Goog-Credential=gorilla-files-url-signer-man%40wandb-production.iam.gserviceaccount.com%2F20250414%2Fauto%2Fstorage%2Fgoog4_request&X-Goog-Date=20250414T153729Z&X-Goog-Expires=86399&X-Goog-Signature=bac5dedc97f642fccac419ba44980b416e214710f27419cf169ce497d0c83a266f3eb17da544d1361107f46112f47bfe8c4195381f38e099eba215636e3222352e018db817c1ca65d45038b65e9a9e4a4a3f1f263094a647aa7d8e6a89b5b72d0ff7545d7255f616f6c8a2954a971f692736de265b332a5776aa934f7b1248f5e0264e80f8fffbc221a27a67263610ee275923e8978efdd395b6fe989928bbad87b051026409ff775e582c8dc5e0edb24cf4c3548d5a933005c8c8d4cf729061a0404a3f990768e3f6d129834cff02d1e90080b0551fef70db773f0ee6139561e152ca115f181341ab6e7f4ccc479ef8c3d6978314ab5465a2ac9799ff6b6fc1&X-Goog-SignedHeaders=host&X-User=2931823730 (Caused by NewConnectionError('<urllib3.connection.HTTPSConnection object at 0x7fcf802eecb0>: Failed to establish a new connection: [Errno 101] Network is unreachable'))

During handling of the above exception, another exception occurred:

Traceback (most recent call last):
  File "/root/anaconda3/envs/venv_ltu/lib/python3.10/site-packages/wandb/sdk/lib/retry.py", line 131, in __call__
    result = self._call_fn(*args, **kwargs)
  File "/root/anaconda3/envs/venv_ltu/lib/python3.10/site-packages/wandb/sdk/internal/internal_api.py", line 2580, in upload_file
    raise _e.with_traceback(sys.exc_info()[2])
  File "/root/anaconda3/envs/venv_ltu/lib/python3.10/site-packages/wandb/sdk/internal/internal_api.py", line 2549, in upload_file
    response = self._upload_file_session.put(
  File "/root/anaconda3/envs/venv_ltu/lib/python3.10/site-packages/requests/sessions.py", line 649, in put
    return self.request("PUT", url, data=data, **kwargs)
  File "/root/anaconda3/envs/venv_ltu/lib/python3.10/site-packages/requests/sessions.py", line 589, in request
    resp = self.send(prep, **send_kwargs)
  File "/root/anaconda3/envs/venv_ltu/lib/python3.10/site-packages/requests/sessions.py", line 703, in send
    r = adapter.send(request, **kwargs)
  File "/root/anaconda3/envs/venv_ltu/lib/python3.10/site-packages/requests/adapters.py", line 700, in send
    raise ConnectionError(e, request=request)
wandb.sdk.lib.retry.TransientError: None
2025-04-14 15:37:30,786 ERROR   wandb-upload_5:17909 [internal_api.py:upload_file():2556] upload_file exception https://storage.googleapis.com/wandb-production.appspot.com/2931823730-harbin-institute-of-technology/ltu-as/wb7imiry/wandb-summary.json?X-Goog-Algorithm=GOOG4-RSA-SHA256&X-Goog-Credential=gorilla-files-url-signer-man%40wandb-production.iam.gserviceaccount.com%2F20250414%2Fauto%2Fstorage%2Fgoog4_request&X-Goog-Date=20250414T153729Z&X-Goog-Expires=86399&X-Goog-Signature=8a24ed4c19410b50f5174dc1034836f3ec0389bd43b65cba44b743abab25ba0377ce388b4b45791bb7cf19f6b5564016d3ff0651308289d350a85b33ccda880557da038b7c1507d5a5837fa6e69e52300be33b61fea1ba1d6fc4fbbabdab94221953bd9a8fbde40a47b58b6e21d9279a543a5e3586f913d78bdc64809216274c849018c193701d0d7ba2da5a5005acecaf2ae1ca4ac15dc455113b4e407ae73db2966eddf9805d919dfb513f74f6048a8e31fe7d58ec0f123b63242e46309df35615b27589492562a7443ad855973fd6ec97c6b3a845e2defcd2a42767f707eb411538afd27d647577fe7537d2453bb803a787864e2f68d4e2885f52487e6246&X-Goog-SignedHeaders=host&X-User=2931823730: HTTPSConnectionPool(host='storage.googleapis.com', port=443): Max retries exceeded with url: /wandb-production.appspot.com/2931823730-harbin-institute-of-technology/ltu-as/wb7imiry/wandb-summary.json?X-Goog-Algorithm=GOOG4-RSA-SHA256&X-Goog-Credential=gorilla-files-url-signer-man%40wandb-production.iam.gserviceaccount.com%2F20250414%2Fauto%2Fstorage%2Fgoog4_request&X-Goog-Date=20250414T153729Z&X-Goog-Expires=86399&X-Goog-Signature=8a24ed4c19410b50f5174dc1034836f3ec0389bd43b65cba44b743abab25ba0377ce388b4b45791bb7cf19f6b5564016d3ff0651308289d350a85b33ccda880557da038b7c1507d5a5837fa6e69e52300be33b61fea1ba1d6fc4fbbabdab94221953bd9a8fbde40a47b58b6e21d9279a543a5e3586f913d78bdc64809216274c849018c193701d0d7ba2da5a5005acecaf2ae1ca4ac15dc455113b4e407ae73db2966eddf9805d919dfb513f74f6048a8e31fe7d58ec0f123b63242e46309df35615b27589492562a7443ad855973fd6ec97c6b3a845e2defcd2a42767f707eb411538afd27d647577fe7537d2453bb803a787864e2f68d4e2885f52487e6246&X-Goog-SignedHeaders=host&X-User=2931823730 (Caused by NewConnectionError('<urllib3.connection.HTTPSConnection object at 0x7fcf60b257b0>: Failed to establish a new connection: [Errno 101] Network is unreachable'))
2025-04-14 15:37:30,786 ERROR   wandb-upload_5:17909 [internal_api.py:upload_file():2558] upload_file request headers: {'User-Agent': 'python-requests/2.32.3', 'Accept-Encoding': 'gzip, deflate, br', 'Accept': '*/*', 'Connection': 'keep-alive', 'Content-Length': '27'}
2025-04-14 15:37:30,786 ERROR   wandb-upload_5:17909 [internal_api.py:upload_file():2560] upload_file response body: 
2025-04-14 15:37:30,820 ERROR   wandb-upload_4:17909 [internal_api.py:upload_file():2556] upload_file exception https://storage.googleapis.com/wandb-production.appspot.com/2931823730-harbin-institute-of-technology/ltu-as/wb7imiry/output.log?X-Goog-Algorithm=GOOG4-RSA-SHA256&X-Goog-Credential=gorilla-files-url-signer-man%40wandb-production.iam.gserviceaccount.com%2F20250414%2Fauto%2Fstorage%2Fgoog4_request&X-Goog-Date=20250414T153729Z&X-Goog-Expires=86399&X-Goog-Signature=a018e0af884588e1d3a33148b5c409078172b766de700f2c523030c0d79d97aea5cd34cc350cfba9b311b32eee5753bc272477d6666ce4861f0ed23a926ab89d25c6a23073daa76e9f8387701e15d24a56c54af4ac528cfc965be49ba1e2b4a7a466f81f1c2cf518bb1018a9cec3fc4dde6347533c2886b3655ef987f4348fa4ff1250d03a30d640c8137aab5a15ec0d7c0789799a5a4e27a90f8e6ce0b16cfb93d160dde33e90e29fc9ff7bb21f395fa5e9163e87bc7cd6a2a9aac4b8dd3913845941b64cf39c5ea0963f5760973859f10b28f6f9fe9ae28d014c0b0291bc3ddde0aabf8022d57033886a7136cb527c33ef8743a0e27199a04a4e90d3cd6190&X-Goog-SignedHeaders=host&X-User=2931823730: HTTPSConnectionPool(host='storage.googleapis.com', port=443): Max retries exceeded with url: /wandb-production.appspot.com/2931823730-harbin-institute-of-technology/ltu-as/wb7imiry/output.log?X-Goog-Algorithm=GOOG4-RSA-SHA256&X-Goog-Credential=gorilla-files-url-signer-man%40wandb-production.iam.gserviceaccount.com%2F20250414%2Fauto%2Fstorage%2Fgoog4_request&X-Goog-Date=20250414T153729Z&X-Goog-Expires=86399&X-Goog-Signature=a018e0af884588e1d3a33148b5c409078172b766de700f2c523030c0d79d97aea5cd34cc350cfba9b311b32eee5753bc272477d6666ce4861f0ed23a926ab89d25c6a23073daa76e9f8387701e15d24a56c54af4ac528cfc965be49ba1e2b4a7a466f81f1c2cf518bb1018a9cec3fc4dde6347533c2886b3655ef987f4348fa4ff1250d03a30d640c8137aab5a15ec0d7c0789799a5a4e27a90f8e6ce0b16cfb93d160dde33e90e29fc9ff7bb21f395fa5e9163e87bc7cd6a2a9aac4b8dd3913845941b64cf39c5ea0963f5760973859f10b28f6f9fe9ae28d014c0b0291bc3ddde0aabf8022d57033886a7136cb527c33ef8743a0e27199a04a4e90d3cd6190&X-Goog-SignedHeaders=host&X-User=2931823730 (Caused by NewConnectionError('<urllib3.connection.HTTPSConnection object at 0x7fcf60b25a50>: Failed to establish a new connection: [Errno 101] Network is unreachable'))
2025-04-14 15:37:30,820 ERROR   wandb-upload_4:17909 [internal_api.py:upload_file():2558] upload_file request headers: {'User-Agent': 'python-requests/2.32.3', 'Accept-Encoding': 'gzip, deflate, br', 'Accept': '*/*', 'Connection': 'keep-alive', 'Content-Length': '2306'}
2025-04-14 15:37:30,820 ERROR   wandb-upload_4:17909 [internal_api.py:upload_file():2560] upload_file response body: 
2025-04-14 15:37:30,909 ERROR   wandb-upload_2:17909 [internal_api.py:upload_file():2556] upload_file exception https://storage.googleapis.com/wandb-production.appspot.com/2931823730-harbin-institute-of-technology/ltu-as/wb7imiry/requirements.txt?X-Goog-Algorithm=GOOG4-RSA-SHA256&X-Goog-Credential=gorilla-files-url-signer-man%40wandb-production.iam.gserviceaccount.com%2F20250414%2Fauto%2Fstorage%2Fgoog4_request&X-Goog-Date=20250414T153729Z&X-Goog-Expires=86399&X-Goog-Signature=0ff8dd74c9c27cc06df90315b3d1dcf7796a08432a70f517ce9dd69466b5a367f177b81e3ed2eb2d02477b7336eb52c9991b47a20a1e7f18af803351891c0fc9c3145a9e4209a7105c939164573ab21445d51970ec13c6e9d5ca103fae21e51712b2ac86a598e5c6b94d860197092f063dd0ca0d80273a74aa3a3b4870432c4fab3f22e694c5505b9cc35585be3e6591110957e8fa77c2b344e703561d6b36b5d97b5f52ccc81566ae5b0f3dd6e1cb9f45400fd56ea332118f71ee88a4ac0178e7795da7c47e26faee26f858d61ef33e6ce308d81a30075068eae3f728121a756aef941d2552d4c033eff7c393640d99bd90f3c5ca27f28ece55c6816f69f782&X-Goog-SignedHeaders=host&X-User=2931823730: HTTPSConnectionPool(host='storage.googleapis.com', port=443): Max retries exceeded with url: /wandb-production.appspot.com/2931823730-harbin-institute-of-technology/ltu-as/wb7imiry/requirements.txt?X-Goog-Algorithm=GOOG4-RSA-SHA256&X-Goog-Credential=gorilla-files-url-signer-man%40wandb-production.iam.gserviceaccount.com%2F20250414%2Fauto%2Fstorage%2Fgoog4_request&X-Goog-Date=20250414T153729Z&X-Goog-Expires=86399&X-Goog-Signature=0ff8dd74c9c27cc06df90315b3d1dcf7796a08432a70f517ce9dd69466b5a367f177b81e3ed2eb2d02477b7336eb52c9991b47a20a1e7f18af803351891c0fc9c3145a9e4209a7105c939164573ab21445d51970ec13c6e9d5ca103fae21e51712b2ac86a598e5c6b94d860197092f063dd0ca0d80273a74aa3a3b4870432c4fab3f22e694c5505b9cc35585be3e6591110957e8fa77c2b344e703561d6b36b5d97b5f52ccc81566ae5b0f3dd6e1cb9f45400fd56ea332118f71ee88a4ac0178e7795da7c47e26faee26f858d61ef33e6ce308d81a30075068eae3f728121a756aef941d2552d4c033eff7c393640d99bd90f3c5ca27f28ece55c6816f69f782&X-Goog-SignedHeaders=host&X-User=2931823730 (Caused by NewConnectionError('<urllib3.connection.HTTPSConnection object at 0x7fcf60b25ff0>: Failed to establish a new connection: [Errno 101] Network is unreachable'))
2025-04-14 15:37:30,910 ERROR   wandb-upload_2:17909 [internal_api.py:upload_file():2558] upload_file request headers: {'User-Agent': 'python-requests/2.32.3', 'Accept-Encoding': 'gzip, deflate, br', 'Accept': '*/*', 'Connection': 'keep-alive', 'Content-Length': '5836'}
2025-04-14 15:37:30,910 ERROR   wandb-upload_2:17909 [internal_api.py:upload_file():2560] upload_file response body: 
2025-04-14 15:37:31,280 INFO    HandlerThread:17909 [handler.py:finish():866] shutting down handler
2025-04-14 15:37:31,282 INFO    WriterThread:17909 [datastore.py:close():294] close: /root/ltu-main/ltu-main/src/ltu_as/train_scripts/wandb/run-20250414_153553-wb7imiry/run-wb7imiry.wandb
2025-04-14 15:37:31,283 INFO    SenderThread:17909 [sender.py:finish():1534] shutting down sender
2025-04-14 15:37:31,283 INFO    SenderThread:17909 [file_pusher.py:finish():175] shutting down file pusher
2025-04-14 15:37:31,284 INFO    SenderThread:17909 [file_pusher.py:join():181] waiting for file pusher
2025-04-14 15:37:32,808 ERROR   wandb-upload_1:17909 [internal_api.py:upload_file():2556] upload_file exception https://storage.googleapis.com/wandb-production.appspot.com/2931823730-harbin-institute-of-technology/ltu-as/wb7imiry/config.yaml?X-Goog-Algorithm=GOOG4-RSA-SHA256&X-Goog-Credential=gorilla-files-url-signer-man%40wandb-production.iam.gserviceaccount.com%2F20250414%2Fauto%2Fstorage%2Fgoog4_request&X-Goog-Date=20250414T153729Z&X-Goog-Expires=86399&X-Goog-Signature=a02996e1ed2131fda4fb7952e5606feacdf720391cf03792afb2611b5f9f58bdc9090c6bcad8ee607c1e301ccb6ed889f68cc77c41d3bafcf148286820d3d6ad798b651c334fc9e1d4cf65ef5ae956d46c29992f6842a66215711898544b2b95c82578a21c3ddf3a1430a2c4aa08a8eb72201753525d7652ce9dbe20f65bd04635e4c8b72807a1fc339fbd1ccfec567b0a97c3b9d16ac32b48490d2c94832d917ff443cf6c0ed71f41dc80534d3f40af06d44040fd898814599a316115899bff507c09869a2bb6457f4d812ec335bbb14524239ed41ada4834b13078804faf5fc31e3e708582c255827b1f39895d45d3d9bf3f38ae1d476757d2ff30d5ed23c0&X-Goog-SignedHeaders=host&X-User=2931823730: HTTPSConnectionPool(host='storage.googleapis.com', port=443): Max retries exceeded with url: /wandb-production.appspot.com/2931823730-harbin-institute-of-technology/ltu-as/wb7imiry/config.yaml?X-Goog-Algorithm=GOOG4-RSA-SHA256&X-Goog-Credential=gorilla-files-url-signer-man%40wandb-production.iam.gserviceaccount.com%2F20250414%2Fauto%2Fstorage%2Fgoog4_request&X-Goog-Date=20250414T153729Z&X-Goog-Expires=86399&X-Goog-Signature=a02996e1ed2131fda4fb7952e5606feacdf720391cf03792afb2611b5f9f58bdc9090c6bcad8ee607c1e301ccb6ed889f68cc77c41d3bafcf148286820d3d6ad798b651c334fc9e1d4cf65ef5ae956d46c29992f6842a66215711898544b2b95c82578a21c3ddf3a1430a2c4aa08a8eb72201753525d7652ce9dbe20f65bd04635e4c8b72807a1fc339fbd1ccfec567b0a97c3b9d16ac32b48490d2c94832d917ff443cf6c0ed71f41dc80534d3f40af06d44040fd898814599a316115899bff507c09869a2bb6457f4d812ec335bbb14524239ed41ada4834b13078804faf5fc31e3e708582c255827b1f39895d45d3d9bf3f38ae1d476757d2ff30d5ed23c0&X-Goog-SignedHeaders=host&X-User=2931823730 (Caused by NewConnectionError('<urllib3.connection.HTTPSConnection object at 0x7fcf60b261a0>: Failed to establish a new connection: [Errno 101] Network is unreachable'))
2025-04-14 15:37:32,808 ERROR   wandb-upload_1:17909 [internal_api.py:upload_file():2558] upload_file request headers: {'User-Agent': 'python-requests/2.32.3', 'Accept-Encoding': 'gzip, deflate, br', 'Accept': '*/*', 'Connection': 'keep-alive', 'Content-Length': '8685'}
2025-04-14 15:37:32,808 ERROR   wandb-upload_1:17909 [internal_api.py:upload_file():2560] upload_file response body: 
2025-04-14 15:37:32,810 ERROR   wandb-upload_3:17909 [internal_api.py:upload_file():2556] upload_file exception https://storage.googleapis.com/wandb-production.appspot.com/2931823730-harbin-institute-of-technology/ltu-as/wb7imiry/conda-environment.yaml?X-Goog-Algorithm=GOOG4-RSA-SHA256&X-Goog-Credential=gorilla-files-url-signer-man%40wandb-production.iam.gserviceaccount.com%2F20250414%2Fauto%2Fstorage%2Fgoog4_request&X-Goog-Date=20250414T153729Z&X-Goog-Expires=86399&X-Goog-Signature=bac5dedc97f642fccac419ba44980b416e214710f27419cf169ce497d0c83a266f3eb17da544d1361107f46112f47bfe8c4195381f38e099eba215636e3222352e018db817c1ca65d45038b65e9a9e4a4a3f1f263094a647aa7d8e6a89b5b72d0ff7545d7255f616f6c8a2954a971f692736de265b332a5776aa934f7b1248f5e0264e80f8fffbc221a27a67263610ee275923e8978efdd395b6fe989928bbad87b051026409ff775e582c8dc5e0edb24cf4c3548d5a933005c8c8d4cf729061a0404a3f990768e3f6d129834cff02d1e90080b0551fef70db773f0ee6139561e152ca115f181341ab6e7f4ccc479ef8c3d6978314ab5465a2ac9799ff6b6fc1&X-Goog-SignedHeaders=host&X-User=2931823730: HTTPSConnectionPool(host='storage.googleapis.com', port=443): Max retries exceeded with url: /wandb-production.appspot.com/2931823730-harbin-institute-of-technology/ltu-as/wb7imiry/conda-environment.yaml?X-Goog-Algorithm=GOOG4-RSA-SHA256&X-Goog-Credential=gorilla-files-url-signer-man%40wandb-production.iam.gserviceaccount.com%2F20250414%2Fauto%2Fstorage%2Fgoog4_request&X-Goog-Date=20250414T153729Z&X-Goog-Expires=86399&X-Goog-Signature=bac5dedc97f642fccac419ba44980b416e214710f27419cf169ce497d0c83a266f3eb17da544d1361107f46112f47bfe8c4195381f38e099eba215636e3222352e018db817c1ca65d45038b65e9a9e4a4a3f1f263094a647aa7d8e6a89b5b72d0ff7545d7255f616f6c8a2954a971f692736de265b332a5776aa934f7b1248f5e0264e80f8fffbc221a27a67263610ee275923e8978efdd395b6fe989928bbad87b051026409ff775e582c8dc5e0edb24cf4c3548d5a933005c8c8d4cf729061a0404a3f990768e3f6d129834cff02d1e90080b0551fef70db773f0ee6139561e152ca115f181341ab6e7f4ccc479ef8c3d6978314ab5465a2ac9799ff6b6fc1&X-Goog-SignedHeaders=host&X-User=2931823730 (Caused by NewConnectionError('<urllib3.connection.HTTPSConnection object at 0x7fcf60b24af0>: Failed to establish a new connection: [Errno 101] Network is unreachable'))
2025-04-14 15:37:32,810 ERROR   wandb-upload_3:17909 [internal_api.py:upload_file():2558] upload_file request headers: {'User-Agent': 'python-requests/2.32.3', 'Accept-Encoding': 'gzip, deflate, br', 'Accept': '*/*', 'Connection': 'keep-alive', 'Content-Length': '12277'}
2025-04-14 15:37:32,810 ERROR   wandb-upload_3:17909 [internal_api.py:upload_file():2560] upload_file response body: 
2025-04-14 15:37:32,853 ERROR   wandb-upload_5:17909 [internal_api.py:upload_file():2556] upload_file exception https://storage.googleapis.com/wandb-production.appspot.com/2931823730-harbin-institute-of-technology/ltu-as/wb7imiry/wandb-summary.json?X-Goog-Algorithm=GOOG4-RSA-SHA256&X-Goog-Credential=gorilla-files-url-signer-man%40wandb-production.iam.gserviceaccount.com%2F20250414%2Fauto%2Fstorage%2Fgoog4_request&X-Goog-Date=20250414T153729Z&X-Goog-Expires=86399&X-Goog-Signature=8a24ed4c19410b50f5174dc1034836f3ec0389bd43b65cba44b743abab25ba0377ce388b4b45791bb7cf19f6b5564016d3ff0651308289d350a85b33ccda880557da038b7c1507d5a5837fa6e69e52300be33b61fea1ba1d6fc4fbbabdab94221953bd9a8fbde40a47b58b6e21d9279a543a5e3586f913d78bdc64809216274c849018c193701d0d7ba2da5a5005acecaf2ae1ca4ac15dc455113b4e407ae73db2966eddf9805d919dfb513f74f6048a8e31fe7d58ec0f123b63242e46309df35615b27589492562a7443ad855973fd6ec97c6b3a845e2defcd2a42767f707eb411538afd27d647577fe7537d2453bb803a787864e2f68d4e2885f52487e6246&X-Goog-SignedHeaders=host&X-User=2931823730: HTTPSConnectionPool(host='storage.googleapis.com', port=443): Max retries exceeded with url: /wandb-production.appspot.com/2931823730-harbin-institute-of-technology/ltu-as/wb7imiry/wandb-summary.json?X-Goog-Algorithm=GOOG4-RSA-SHA256&X-Goog-Credential=gorilla-files-url-signer-man%40wandb-production.iam.gserviceaccount.com%2F20250414%2Fauto%2Fstorage%2Fgoog4_request&X-Goog-Date=20250414T153729Z&X-Goog-Expires=86399&X-Goog-Signature=8a24ed4c19410b50f5174dc1034836f3ec0389bd43b65cba44b743abab25ba0377ce388b4b45791bb7cf19f6b5564016d3ff0651308289d350a85b33ccda880557da038b7c1507d5a5837fa6e69e52300be33b61fea1ba1d6fc4fbbabdab94221953bd9a8fbde40a47b58b6e21d9279a543a5e3586f913d78bdc64809216274c849018c193701d0d7ba2da5a5005acecaf2ae1ca4ac15dc455113b4e407ae73db2966eddf9805d919dfb513f74f6048a8e31fe7d58ec0f123b63242e46309df35615b27589492562a7443ad855973fd6ec97c6b3a845e2defcd2a42767f707eb411538afd27d647577fe7537d2453bb803a787864e2f68d4e2885f52487e6246&X-Goog-SignedHeaders=host&X-User=2931823730 (Caused by NewConnectionError('<urllib3.connection.HTTPSConnection object at 0x7fcf843f30d0>: Failed to establish a new connection: [Errno 101] Network is unreachable'))
2025-04-14 15:37:32,853 ERROR   wandb-upload_5:17909 [internal_api.py:upload_file():2558] upload_file request headers: {'User-Agent': 'python-requests/2.32.3', 'Accept-Encoding': 'gzip, deflate, br', 'Accept': '*/*', 'Connection': 'keep-alive', 'Content-Length': '27'}
2025-04-14 15:37:32,853 ERROR   wandb-upload_5:17909 [internal_api.py:upload_file():2560] upload_file response body: 
2025-04-14 15:37:32,996 ERROR   wandb-upload_2:17909 [internal_api.py:upload_file():2556] upload_file exception https://storage.googleapis.com/wandb-production.appspot.com/2931823730-harbin-institute-of-technology/ltu-as/wb7imiry/requirements.txt?X-Goog-Algorithm=GOOG4-RSA-SHA256&X-Goog-Credential=gorilla-files-url-signer-man%40wandb-production.iam.gserviceaccount.com%2F20250414%2Fauto%2Fstorage%2Fgoog4_request&X-Goog-Date=20250414T153729Z&X-Goog-Expires=86399&X-Goog-Signature=0ff8dd74c9c27cc06df90315b3d1dcf7796a08432a70f517ce9dd69466b5a367f177b81e3ed2eb2d02477b7336eb52c9991b47a20a1e7f18af803351891c0fc9c3145a9e4209a7105c939164573ab21445d51970ec13c6e9d5ca103fae21e51712b2ac86a598e5c6b94d860197092f063dd0ca0d80273a74aa3a3b4870432c4fab3f22e694c5505b9cc35585be3e6591110957e8fa77c2b344e703561d6b36b5d97b5f52ccc81566ae5b0f3dd6e1cb9f45400fd56ea332118f71ee88a4ac0178e7795da7c47e26faee26f858d61ef33e6ce308d81a30075068eae3f728121a756aef941d2552d4c033eff7c393640d99bd90f3c5ca27f28ece55c6816f69f782&X-Goog-SignedHeaders=host&X-User=2931823730: HTTPSConnectionPool(host='storage.googleapis.com', port=443): Max retries exceeded with url: /wandb-production.appspot.com/2931823730-harbin-institute-of-technology/ltu-as/wb7imiry/requirements.txt?X-Goog-Algorithm=GOOG4-RSA-SHA256&X-Goog-Credential=gorilla-files-url-signer-man%40wandb-production.iam.gserviceaccount.com%2F20250414%2Fauto%2Fstorage%2Fgoog4_request&X-Goog-Date=20250414T153729Z&X-Goog-Expires=86399&X-Goog-Signature=0ff8dd74c9c27cc06df90315b3d1dcf7796a08432a70f517ce9dd69466b5a367f177b81e3ed2eb2d02477b7336eb52c9991b47a20a1e7f18af803351891c0fc9c3145a9e4209a7105c939164573ab21445d51970ec13c6e9d5ca103fae21e51712b2ac86a598e5c6b94d860197092f063dd0ca0d80273a74aa3a3b4870432c4fab3f22e694c5505b9cc35585be3e6591110957e8fa77c2b344e703561d6b36b5d97b5f52ccc81566ae5b0f3dd6e1cb9f45400fd56ea332118f71ee88a4ac0178e7795da7c47e26faee26f858d61ef33e6ce308d81a30075068eae3f728121a756aef941d2552d4c033eff7c393640d99bd90f3c5ca27f28ece55c6816f69f782&X-Goog-SignedHeaders=host&X-User=2931823730 (Caused by NewConnectionError('<urllib3.connection.HTTPSConnection object at 0x7fcf802a31c0>: Failed to establish a new connection: [Errno 101] Network is unreachable'))
2025-04-14 15:37:32,996 ERROR   wandb-upload_2:17909 [internal_api.py:upload_file():2558] upload_file request headers: {'User-Agent': 'python-requests/2.32.3', 'Accept-Encoding': 'gzip, deflate, br', 'Accept': '*/*', 'Connection': 'keep-alive', 'Content-Length': '5836'}
2025-04-14 15:37:32,996 ERROR   wandb-upload_2:17909 [internal_api.py:upload_file():2560] upload_file response body: 
2025-04-14 15:37:33,176 ERROR   wandb-upload_4:17909 [internal_api.py:upload_file():2556] upload_file exception https://storage.googleapis.com/wandb-production.appspot.com/2931823730-harbin-institute-of-technology/ltu-as/wb7imiry/output.log?X-Goog-Algorithm=GOOG4-RSA-SHA256&X-Goog-Credential=gorilla-files-url-signer-man%40wandb-production.iam.gserviceaccount.com%2F20250414%2Fauto%2Fstorage%2Fgoog4_request&X-Goog-Date=20250414T153729Z&X-Goog-Expires=86399&X-Goog-Signature=a018e0af884588e1d3a33148b5c409078172b766de700f2c523030c0d79d97aea5cd34cc350cfba9b311b32eee5753bc272477d6666ce4861f0ed23a926ab89d25c6a23073daa76e9f8387701e15d24a56c54af4ac528cfc965be49ba1e2b4a7a466f81f1c2cf518bb1018a9cec3fc4dde6347533c2886b3655ef987f4348fa4ff1250d03a30d640c8137aab5a15ec0d7c0789799a5a4e27a90f8e6ce0b16cfb93d160dde33e90e29fc9ff7bb21f395fa5e9163e87bc7cd6a2a9aac4b8dd3913845941b64cf39c5ea0963f5760973859f10b28f6f9fe9ae28d014c0b0291bc3ddde0aabf8022d57033886a7136cb527c33ef8743a0e27199a04a4e90d3cd6190&X-Goog-SignedHeaders=host&X-User=2931823730: HTTPSConnectionPool(host='storage.googleapis.com', port=443): Max retries exceeded with url: /wandb-production.appspot.com/2931823730-harbin-institute-of-technology/ltu-as/wb7imiry/output.log?X-Goog-Algorithm=GOOG4-RSA-SHA256&X-Goog-Credential=gorilla-files-url-signer-man%40wandb-production.iam.gserviceaccount.com%2F20250414%2Fauto%2Fstorage%2Fgoog4_request&X-Goog-Date=20250414T153729Z&X-Goog-Expires=86399&X-Goog-Signature=a018e0af884588e1d3a33148b5c409078172b766de700f2c523030c0d79d97aea5cd34cc350cfba9b311b32eee5753bc272477d6666ce4861f0ed23a926ab89d25c6a23073daa76e9f8387701e15d24a56c54af4ac528cfc965be49ba1e2b4a7a466f81f1c2cf518bb1018a9cec3fc4dde6347533c2886b3655ef987f4348fa4ff1250d03a30d640c8137aab5a15ec0d7c0789799a5a4e27a90f8e6ce0b16cfb93d160dde33e90e29fc9ff7bb21f395fa5e9163e87bc7cd6a2a9aac4b8dd3913845941b64cf39c5ea0963f5760973859f10b28f6f9fe9ae28d014c0b0291bc3ddde0aabf8022d57033886a7136cb527c33ef8743a0e27199a04a4e90d3cd6190&X-Goog-SignedHeaders=host&X-User=2931823730 (Caused by NewConnectionError('<urllib3.connection.HTTPSConnection object at 0x7fcf802a11e0>: Failed to establish a new connection: [Errno 101] Network is unreachable'))
2025-04-14 15:37:33,176 ERROR   wandb-upload_4:17909 [internal_api.py:upload_file():2558] upload_file request headers: {'User-Agent': 'python-requests/2.32.3', 'Accept-Encoding': 'gzip, deflate, br', 'Accept': '*/*', 'Connection': 'keep-alive', 'Content-Length': '2306'}
2025-04-14 15:37:33,176 ERROR   wandb-upload_4:17909 [internal_api.py:upload_file():2560] upload_file response body: 
2025-04-14 15:37:36,167 ERROR   wandb-upload_0:17909 [internal_api.py:upload_file():2556] upload_file exception https://storage.googleapis.com/wandb-production.appspot.com/2931823730-harbin-institute-of-technology/ltu-as/wb7imiry/wandb-metadata.json?X-Goog-Algorithm=GOOG4-RSA-SHA256&X-Goog-Credential=gorilla-files-url-signer-man%40wandb-production.iam.gserviceaccount.com%2F20250414%2Fauto%2Fstorage%2Fgoog4_request&X-Goog-Date=20250414T153718Z&X-Goog-Expires=86399&X-Goog-Signature=133ce96984b25332e1c6ffbb9e47ac06b76e9be107576432f958a39307ee215044e48789fcd0afd74c7a07e46b6f7d048e68a2e61aaaf129526ffc11ccdcca23dacdcb877cf906889b08f6cd1678dc0ec1feb0cdc8bf78dd26f372b6fd1d718149884b5269ca33e6f40a1bcf89ade53be62765aa00625415b091b40c81324e83586558cf027a5feae64fe4294afd4e5560cedd85c1f2f0105f91c5a158600793fa3034b8240a7d2e379591474bd825c8c817e5da730178eda2015d4a1436f7cc9eec094ac820ec8ccb6644c4fb6de8ebf03ecd355bb1ccbf49eb060d221e5850113ad223708496b3b9462377d6f1a2fbca6ac238fb0d1d062afe377190c112a9&X-Goog-SignedHeaders=host&X-User=2931823730: HTTPSConnectionPool(host='storage.googleapis.com', port=443): Max retries exceeded with url: /wandb-production.appspot.com/2931823730-harbin-institute-of-technology/ltu-as/wb7imiry/wandb-metadata.json?X-Goog-Algorithm=GOOG4-RSA-SHA256&X-Goog-Credential=gorilla-files-url-signer-man%40wandb-production.iam.gserviceaccount.com%2F20250414%2Fauto%2Fstorage%2Fgoog4_request&X-Goog-Date=20250414T153718Z&X-Goog-Expires=86399&X-Goog-Signature=133ce96984b25332e1c6ffbb9e47ac06b76e9be107576432f958a39307ee215044e48789fcd0afd74c7a07e46b6f7d048e68a2e61aaaf129526ffc11ccdcca23dacdcb877cf906889b08f6cd1678dc0ec1feb0cdc8bf78dd26f372b6fd1d718149884b5269ca33e6f40a1bcf89ade53be62765aa00625415b091b40c81324e83586558cf027a5feae64fe4294afd4e5560cedd85c1f2f0105f91c5a158600793fa3034b8240a7d2e379591474bd825c8c817e5da730178eda2015d4a1436f7cc9eec094ac820ec8ccb6644c4fb6de8ebf03ecd355bb1ccbf49eb060d221e5850113ad223708496b3b9462377d6f1a2fbca6ac238fb0d1d062afe377190c112a9&X-Goog-SignedHeaders=host&X-User=2931823730 (Caused by NewConnectionError('<urllib3.connection.HTTPSConnection object at 0x7fcf802a1420>: Failed to establish a new connection: [Errno 101] Network is unreachable'))
2025-04-14 15:37:36,167 ERROR   wandb-upload_0:17909 [internal_api.py:upload_file():2558] upload_file request headers: {'User-Agent': 'python-requests/2.32.3', 'Accept-Encoding': 'gzip, deflate, br', 'Accept': '*/*', 'Connection': 'keep-alive', 'Content-Length': '2380'}
2025-04-14 15:37:36,167 ERROR   wandb-upload_0:17909 [internal_api.py:upload_file():2560] upload_file response body: 
2025-04-14 15:37:36,839 ERROR   wandb-upload_1:17909 [internal_api.py:upload_file():2556] upload_file exception https://storage.googleapis.com/wandb-production.appspot.com/2931823730-harbin-institute-of-technology/ltu-as/wb7imiry/config.yaml?X-Goog-Algorithm=GOOG4-RSA-SHA256&X-Goog-Credential=gorilla-files-url-signer-man%40wandb-production.iam.gserviceaccount.com%2F20250414%2Fauto%2Fstorage%2Fgoog4_request&X-Goog-Date=20250414T153729Z&X-Goog-Expires=86399&X-Goog-Signature=a02996e1ed2131fda4fb7952e5606feacdf720391cf03792afb2611b5f9f58bdc9090c6bcad8ee607c1e301ccb6ed889f68cc77c41d3bafcf148286820d3d6ad798b651c334fc9e1d4cf65ef5ae956d46c29992f6842a66215711898544b2b95c82578a21c3ddf3a1430a2c4aa08a8eb72201753525d7652ce9dbe20f65bd04635e4c8b72807a1fc339fbd1ccfec567b0a97c3b9d16ac32b48490d2c94832d917ff443cf6c0ed71f41dc80534d3f40af06d44040fd898814599a316115899bff507c09869a2bb6457f4d812ec335bbb14524239ed41ada4834b13078804faf5fc31e3e708582c255827b1f39895d45d3d9bf3f38ae1d476757d2ff30d5ed23c0&X-Goog-SignedHeaders=host&X-User=2931823730: HTTPSConnectionPool(host='storage.googleapis.com', port=443): Max retries exceeded with url: /wandb-production.appspot.com/2931823730-harbin-institute-of-technology/ltu-as/wb7imiry/config.yaml?X-Goog-Algorithm=GOOG4-RSA-SHA256&X-Goog-Credential=gorilla-files-url-signer-man%40wandb-production.iam.gserviceaccount.com%2F20250414%2Fauto%2Fstorage%2Fgoog4_request&X-Goog-Date=20250414T153729Z&X-Goog-Expires=86399&X-Goog-Signature=a02996e1ed2131fda4fb7952e5606feacdf720391cf03792afb2611b5f9f58bdc9090c6bcad8ee607c1e301ccb6ed889f68cc77c41d3bafcf148286820d3d6ad798b651c334fc9e1d4cf65ef5ae956d46c29992f6842a66215711898544b2b95c82578a21c3ddf3a1430a2c4aa08a8eb72201753525d7652ce9dbe20f65bd04635e4c8b72807a1fc339fbd1ccfec567b0a97c3b9d16ac32b48490d2c94832d917ff443cf6c0ed71f41dc80534d3f40af06d44040fd898814599a316115899bff507c09869a2bb6457f4d812ec335bbb14524239ed41ada4834b13078804faf5fc31e3e708582c255827b1f39895d45d3d9bf3f38ae1d476757d2ff30d5ed23c0&X-Goog-SignedHeaders=host&X-User=2931823730 (Caused by NewConnectionError('<urllib3.connection.HTTPSConnection object at 0x7fcf802efd90>: Failed to establish a new connection: [Errno 101] Network is unreachable'))
2025-04-14 15:37:36,839 ERROR   wandb-upload_1:17909 [internal_api.py:upload_file():2558] upload_file request headers: {'User-Agent': 'python-requests/2.32.3', 'Accept-Encoding': 'gzip, deflate, br', 'Accept': '*/*', 'Connection': 'keep-alive', 'Content-Length': '8685'}
2025-04-14 15:37:36,839 ERROR   wandb-upload_1:17909 [internal_api.py:upload_file():2560] upload_file response body: 
2025-04-14 15:37:36,872 ERROR   wandb-upload_3:17909 [internal_api.py:upload_file():2556] upload_file exception https://storage.googleapis.com/wandb-production.appspot.com/2931823730-harbin-institute-of-technology/ltu-as/wb7imiry/conda-environment.yaml?X-Goog-Algorithm=GOOG4-RSA-SHA256&X-Goog-Credential=gorilla-files-url-signer-man%40wandb-production.iam.gserviceaccount.com%2F20250414%2Fauto%2Fstorage%2Fgoog4_request&X-Goog-Date=20250414T153729Z&X-Goog-Expires=86399&X-Goog-Signature=bac5dedc97f642fccac419ba44980b416e214710f27419cf169ce497d0c83a266f3eb17da544d1361107f46112f47bfe8c4195381f38e099eba215636e3222352e018db817c1ca65d45038b65e9a9e4a4a3f1f263094a647aa7d8e6a89b5b72d0ff7545d7255f616f6c8a2954a971f692736de265b332a5776aa934f7b1248f5e0264e80f8fffbc221a27a67263610ee275923e8978efdd395b6fe989928bbad87b051026409ff775e582c8dc5e0edb24cf4c3548d5a933005c8c8d4cf729061a0404a3f990768e3f6d129834cff02d1e90080b0551fef70db773f0ee6139561e152ca115f181341ab6e7f4ccc479ef8c3d6978314ab5465a2ac9799ff6b6fc1&X-Goog-SignedHeaders=host&X-User=2931823730: HTTPSConnectionPool(host='storage.googleapis.com', port=443): Max retries exceeded with url: /wandb-production.appspot.com/2931823730-harbin-institute-of-technology/ltu-as/wb7imiry/conda-environment.yaml?X-Goog-Algorithm=GOOG4-RSA-SHA256&X-Goog-Credential=gorilla-files-url-signer-man%40wandb-production.iam.gserviceaccount.com%2F20250414%2Fauto%2Fstorage%2Fgoog4_request&X-Goog-Date=20250414T153729Z&X-Goog-Expires=86399&X-Goog-Signature=bac5dedc97f642fccac419ba44980b416e214710f27419cf169ce497d0c83a266f3eb17da544d1361107f46112f47bfe8c4195381f38e099eba215636e3222352e018db817c1ca65d45038b65e9a9e4a4a3f1f263094a647aa7d8e6a89b5b72d0ff7545d7255f616f6c8a2954a971f692736de265b332a5776aa934f7b1248f5e0264e80f8fffbc221a27a67263610ee275923e8978efdd395b6fe989928bbad87b051026409ff775e582c8dc5e0edb24cf4c3548d5a933005c8c8d4cf729061a0404a3f990768e3f6d129834cff02d1e90080b0551fef70db773f0ee6139561e152ca115f181341ab6e7f4ccc479ef8c3d6978314ab5465a2ac9799ff6b6fc1&X-Goog-SignedHeaders=host&X-User=2931823730 (Caused by NewConnectionError('<urllib3.connection.HTTPSConnection object at 0x7fcf802eeec0>: Failed to establish a new connection: [Errno 101] Network is unreachable'))
2025-04-14 15:37:36,873 ERROR   wandb-upload_3:17909 [internal_api.py:upload_file():2558] upload_file request headers: {'User-Agent': 'python-requests/2.32.3', 'Accept-Encoding': 'gzip, deflate, br', 'Accept': '*/*', 'Connection': 'keep-alive', 'Content-Length': '12277'}
2025-04-14 15:37:36,873 ERROR   wandb-upload_3:17909 [internal_api.py:upload_file():2560] upload_file response body: 
2025-04-14 15:37:36,961 ERROR   wandb-upload_5:17909 [internal_api.py:upload_file():2556] upload_file exception https://storage.googleapis.com/wandb-production.appspot.com/2931823730-harbin-institute-of-technology/ltu-as/wb7imiry/wandb-summary.json?X-Goog-Algorithm=GOOG4-RSA-SHA256&X-Goog-Credential=gorilla-files-url-signer-man%40wandb-production.iam.gserviceaccount.com%2F20250414%2Fauto%2Fstorage%2Fgoog4_request&X-Goog-Date=20250414T153729Z&X-Goog-Expires=86399&X-Goog-Signature=8a24ed4c19410b50f5174dc1034836f3ec0389bd43b65cba44b743abab25ba0377ce388b4b45791bb7cf19f6b5564016d3ff0651308289d350a85b33ccda880557da038b7c1507d5a5837fa6e69e52300be33b61fea1ba1d6fc4fbbabdab94221953bd9a8fbde40a47b58b6e21d9279a543a5e3586f913d78bdc64809216274c849018c193701d0d7ba2da5a5005acecaf2ae1ca4ac15dc455113b4e407ae73db2966eddf9805d919dfb513f74f6048a8e31fe7d58ec0f123b63242e46309df35615b27589492562a7443ad855973fd6ec97c6b3a845e2defcd2a42767f707eb411538afd27d647577fe7537d2453bb803a787864e2f68d4e2885f52487e6246&X-Goog-SignedHeaders=host&X-User=2931823730: HTTPSConnectionPool(host='storage.googleapis.com', port=443): Max retries exceeded with url: /wandb-production.appspot.com/2931823730-harbin-institute-of-technology/ltu-as/wb7imiry/wandb-summary.json?X-Goog-Algorithm=GOOG4-RSA-SHA256&X-Goog-Credential=gorilla-files-url-signer-man%40wandb-production.iam.gserviceaccount.com%2F20250414%2Fauto%2Fstorage%2Fgoog4_request&X-Goog-Date=20250414T153729Z&X-Goog-Expires=86399&X-Goog-Signature=8a24ed4c19410b50f5174dc1034836f3ec0389bd43b65cba44b743abab25ba0377ce388b4b45791bb7cf19f6b5564016d3ff0651308289d350a85b33ccda880557da038b7c1507d5a5837fa6e69e52300be33b61fea1ba1d6fc4fbbabdab94221953bd9a8fbde40a47b58b6e21d9279a543a5e3586f913d78bdc64809216274c849018c193701d0d7ba2da5a5005acecaf2ae1ca4ac15dc455113b4e407ae73db2966eddf9805d919dfb513f74f6048a8e31fe7d58ec0f123b63242e46309df35615b27589492562a7443ad855973fd6ec97c6b3a845e2defcd2a42767f707eb411538afd27d647577fe7537d2453bb803a787864e2f68d4e2885f52487e6246&X-Goog-SignedHeaders=host&X-User=2931823730 (Caused by NewConnectionError('<urllib3.connection.HTTPSConnection object at 0x7fcf802ef700>: Failed to establish a new connection: [Errno 101] Network is unreachable'))
2025-04-14 15:37:36,961 ERROR   wandb-upload_5:17909 [internal_api.py:upload_file():2558] upload_file request headers: {'User-Agent': 'python-requests/2.32.3', 'Accept-Encoding': 'gzip, deflate, br', 'Accept': '*/*', 'Connection': 'keep-alive', 'Content-Length': '27'}
2025-04-14 15:37:36,961 ERROR   wandb-upload_5:17909 [internal_api.py:upload_file():2560] upload_file response body: 
2025-04-14 15:37:37,126 ERROR   wandb-upload_2:17909 [internal_api.py:upload_file():2556] upload_file exception https://storage.googleapis.com/wandb-production.appspot.com/2931823730-harbin-institute-of-technology/ltu-as/wb7imiry/requirements.txt?X-Goog-Algorithm=GOOG4-RSA-SHA256&X-Goog-Credential=gorilla-files-url-signer-man%40wandb-production.iam.gserviceaccount.com%2F20250414%2Fauto%2Fstorage%2Fgoog4_request&X-Goog-Date=20250414T153729Z&X-Goog-Expires=86399&X-Goog-Signature=0ff8dd74c9c27cc06df90315b3d1dcf7796a08432a70f517ce9dd69466b5a367f177b81e3ed2eb2d02477b7336eb52c9991b47a20a1e7f18af803351891c0fc9c3145a9e4209a7105c939164573ab21445d51970ec13c6e9d5ca103fae21e51712b2ac86a598e5c6b94d860197092f063dd0ca0d80273a74aa3a3b4870432c4fab3f22e694c5505b9cc35585be3e6591110957e8fa77c2b344e703561d6b36b5d97b5f52ccc81566ae5b0f3dd6e1cb9f45400fd56ea332118f71ee88a4ac0178e7795da7c47e26faee26f858d61ef33e6ce308d81a30075068eae3f728121a756aef941d2552d4c033eff7c393640d99bd90f3c5ca27f28ece55c6816f69f782&X-Goog-SignedHeaders=host&X-User=2931823730: HTTPSConnectionPool(host='storage.googleapis.com', port=443): Max retries exceeded with url: /wandb-production.appspot.com/2931823730-harbin-institute-of-technology/ltu-as/wb7imiry/requirements.txt?X-Goog-Algorithm=GOOG4-RSA-SHA256&X-Goog-Credential=gorilla-files-url-signer-man%40wandb-production.iam.gserviceaccount.com%2F20250414%2Fauto%2Fstorage%2Fgoog4_request&X-Goog-Date=20250414T153729Z&X-Goog-Expires=86399&X-Goog-Signature=0ff8dd74c9c27cc06df90315b3d1dcf7796a08432a70f517ce9dd69466b5a367f177b81e3ed2eb2d02477b7336eb52c9991b47a20a1e7f18af803351891c0fc9c3145a9e4209a7105c939164573ab21445d51970ec13c6e9d5ca103fae21e51712b2ac86a598e5c6b94d860197092f063dd0ca0d80273a74aa3a3b4870432c4fab3f22e694c5505b9cc35585be3e6591110957e8fa77c2b344e703561d6b36b5d97b5f52ccc81566ae5b0f3dd6e1cb9f45400fd56ea332118f71ee88a4ac0178e7795da7c47e26faee26f858d61ef33e6ce308d81a30075068eae3f728121a756aef941d2552d4c033eff7c393640d99bd90f3c5ca27f28ece55c6816f69f782&X-Goog-SignedHeaders=host&X-User=2931823730 (Caused by NewConnectionError('<urllib3.connection.HTTPSConnection object at 0x7fcf802eec50>: Failed to establish a new connection: [Errno 101] Network is unreachable'))
2025-04-14 15:37:37,126 ERROR   wandb-upload_2:17909 [internal_api.py:upload_file():2558] upload_file request headers: {'User-Agent': 'python-requests/2.32.3', 'Accept-Encoding': 'gzip, deflate, br', 'Accept': '*/*', 'Connection': 'keep-alive', 'Content-Length': '5836'}
2025-04-14 15:37:37,126 ERROR   wandb-upload_2:17909 [internal_api.py:upload_file():2560] upload_file response body: 
2025-04-14 15:37:38,185 ERROR   wandb-upload_4:17909 [internal_api.py:upload_file():2556] upload_file exception https://storage.googleapis.com/wandb-production.appspot.com/2931823730-harbin-institute-of-technology/ltu-as/wb7imiry/output.log?X-Goog-Algorithm=GOOG4-RSA-SHA256&X-Goog-Credential=gorilla-files-url-signer-man%40wandb-production.iam.gserviceaccount.com%2F20250414%2Fauto%2Fstorage%2Fgoog4_request&X-Goog-Date=20250414T153729Z&X-Goog-Expires=86399&X-Goog-Signature=a018e0af884588e1d3a33148b5c409078172b766de700f2c523030c0d79d97aea5cd34cc350cfba9b311b32eee5753bc272477d6666ce4861f0ed23a926ab89d25c6a23073daa76e9f8387701e15d24a56c54af4ac528cfc965be49ba1e2b4a7a466f81f1c2cf518bb1018a9cec3fc4dde6347533c2886b3655ef987f4348fa4ff1250d03a30d640c8137aab5a15ec0d7c0789799a5a4e27a90f8e6ce0b16cfb93d160dde33e90e29fc9ff7bb21f395fa5e9163e87bc7cd6a2a9aac4b8dd3913845941b64cf39c5ea0963f5760973859f10b28f6f9fe9ae28d014c0b0291bc3ddde0aabf8022d57033886a7136cb527c33ef8743a0e27199a04a4e90d3cd6190&X-Goog-SignedHeaders=host&X-User=2931823730: HTTPSConnectionPool(host='storage.googleapis.com', port=443): Max retries exceeded with url: /wandb-production.appspot.com/2931823730-harbin-institute-of-technology/ltu-as/wb7imiry/output.log?X-Goog-Algorithm=GOOG4-RSA-SHA256&X-Goog-Credential=gorilla-files-url-signer-man%40wandb-production.iam.gserviceaccount.com%2F20250414%2Fauto%2Fstorage%2Fgoog4_request&X-Goog-Date=20250414T153729Z&X-Goog-Expires=86399&X-Goog-Signature=a018e0af884588e1d3a33148b5c409078172b766de700f2c523030c0d79d97aea5cd34cc350cfba9b311b32eee5753bc272477d6666ce4861f0ed23a926ab89d25c6a23073daa76e9f8387701e15d24a56c54af4ac528cfc965be49ba1e2b4a7a466f81f1c2cf518bb1018a9cec3fc4dde6347533c2886b3655ef987f4348fa4ff1250d03a30d640c8137aab5a15ec0d7c0789799a5a4e27a90f8e6ce0b16cfb93d160dde33e90e29fc9ff7bb21f395fa5e9163e87bc7cd6a2a9aac4b8dd3913845941b64cf39c5ea0963f5760973859f10b28f6f9fe9ae28d014c0b0291bc3ddde0aabf8022d57033886a7136cb527c33ef8743a0e27199a04a4e90d3cd6190&X-Goog-SignedHeaders=host&X-User=2931823730 (Caused by NewConnectionError('<urllib3.connection.HTTPSConnection object at 0x7fcf60b24d90>: Failed to establish a new connection: [Errno 101] Network is unreachable'))
2025-04-14 15:37:38,185 ERROR   wandb-upload_4:17909 [internal_api.py:upload_file():2558] upload_file request headers: {'User-Agent': 'python-requests/2.32.3', 'Accept-Encoding': 'gzip, deflate, br', 'Accept': '*/*', 'Connection': 'keep-alive', 'Content-Length': '2306'}
2025-04-14 15:37:38,185 ERROR   wandb-upload_4:17909 [internal_api.py:upload_file():2560] upload_file response body: 
