2025-04-11 15:12:53,321 INFO    StreamThr :23351 [internal.py:wandb_internal():86] W&B internal server running at pid: 23351, started at: 2025-04-11 15:12:53.320507
2025-04-11 15:12:53,327 DEBUG   HandlerThread:23351 [handler.py:handle_request():146] handle_request: status
2025-04-11 15:12:53,329 INFO    WriterThread:23351 [datastore.py:open_for_write():85] open: /root/ltu-main/ltu-main/src/ltu_as/train_scripts/wandb/run-20250411_151253-2p8m9dwe/run-2p8m9dwe.wandb
2025-04-11 15:12:53,330 DEBUG   SenderThread:23351 [sender.py:send():380] send: header
2025-04-11 15:12:53,330 DEBUG   SenderThread:23351 [sender.py:send():380] send: run
2025-04-11 15:12:54,112 INFO    SenderThread:23351 [dir_watcher.py:__init__():211] watching files in: /root/ltu-main/ltu-main/src/ltu_as/train_scripts/wandb/run-20250411_151253-2p8m9dwe/files
2025-04-11 15:12:54,112 DEBUG   HandlerThread:23351 [handler.py:handle_request():146] handle_request: check_version
2025-04-11 15:12:54,112 INFO    SenderThread:23351 [sender.py:_start_run_threads():1122] run started: 2p8m9dwe with start time 1744384373.322846
2025-04-11 15:12:54,112 DEBUG   SenderThread:23351 [sender.py:send_request():407] send_request: check_version
2025-04-11 15:12:54,978 DEBUG   HandlerThread:23351 [handler.py:handle_request():146] handle_request: run_start
2025-04-11 15:12:54,985 DEBUG   HandlerThread:23351 [system_info.py:__init__():32] System info init
2025-04-11 15:12:54,985 DEBUG   HandlerThread:23351 [system_info.py:__init__():47] System info init done
2025-04-11 15:12:54,985 INFO    HandlerThread:23351 [system_monitor.py:start():194] Starting system monitor
2025-04-11 15:12:54,986 INFO    SystemMonitor:23351 [system_monitor.py:_start():158] Starting system asset monitoring threads
2025-04-11 15:12:54,986 INFO    HandlerThread:23351 [system_monitor.py:probe():214] Collecting system info
2025-04-11 15:12:54,987 INFO    SystemMonitor:23351 [interfaces.py:start():190] Started cpu monitoring
2025-04-11 15:12:54,988 INFO    SystemMonitor:23351 [interfaces.py:start():190] Started disk monitoring
2025-04-11 15:12:54,988 INFO    SystemMonitor:23351 [interfaces.py:start():190] Started gpu monitoring
2025-04-11 15:12:54,990 INFO    SystemMonitor:23351 [interfaces.py:start():190] Started memory monitoring
2025-04-11 15:12:54,990 INFO    SystemMonitor:23351 [interfaces.py:start():190] Started network monitoring
2025-04-11 15:12:54,998 DEBUG   HandlerThread:23351 [system_info.py:probe():196] Probing system
2025-04-11 15:12:54,999 DEBUG   HandlerThread:23351 [gitlib.py:_init_repo():53] git repository is invalid
2025-04-11 15:12:54,999 DEBUG   HandlerThread:23351 [system_info.py:probe():244] Probing system done
2025-04-11 15:12:54,999 DEBUG   HandlerThread:23351 [system_monitor.py:probe():223] {'os': 'Linux-4.15.0-213-generic-x86_64-with-glibc2.27', 'python': '3.10.15', 'heartbeatAt': '2025-04-11T15:12:54.998587', 'startedAt': '2025-04-11T15:12:53.297452', 'docker': None, 'cuda': None, 'args': ('--base_model', '../../../pretrained_mdls/ltuas_long_noqa_a6.bin', '--data_path', '../../../openasqa/data/iemocap_preprocess_with_answers_updated.json', '--output_dir', '../exp/ltuas_ft_meld/', '--batch_size', '256', '--micro_batch_size', '1', '--num_epochs', '1', '--learning_rate', '2e-4', '--cutoff_len', '100', '--val_set_size', '0', '--lora_r', '8', '--lora_alpha', '16', '--lora_dropout', '0.05', '--lora_target_modules', '[q_proj,v_proj]', '--group_by_length', '--wandb_run_name', '../exp/ltuas_ft_meld/', '--save_steps', '30', '--trainable_params', 'all'), 'state': 'running', 'program': '/root/ltu-main/ltu-main/src/ltu_as/train_scripts/../finetune_low_resource.py', 'codePathLocal': None, 'host': 'ubuntu', 'username': 'root', 'executable': '/root/anaconda3/envs/venv_ltu/bin/python', 'cpu_count': 4, 'cpu_count_logical': 4, 'cpu_freq': {'current': 2294.598, 'min': 0.0, 'max': 0.0}, 'cpu_freq_per_core': [{'current': 2294.598, 'min': 0.0, 'max': 0.0}, {'current': 2294.598, 'min': 0.0, 'max': 0.0}, {'current': 2294.598, 'min': 0.0, 'max': 0.0}, {'current': 2294.598, 'min': 0.0, 'max': 0.0}], 'disk': {'/': {'total': 499.9882621765137, 'used': 333.59981536865234}}, 'gpu': 'NVIDIA A100-PCIE-40GB', 'gpu_count': 1, 'gpu_devices': [{'name': 'NVIDIA A100-PCIE-40GB', 'memory_total': 42949672960}], 'memory': {'total': 19.60204315185547}}
2025-04-11 15:12:54,999 INFO    HandlerThread:23351 [system_monitor.py:probe():224] Finished collecting system info
2025-04-11 15:12:54,999 INFO    HandlerThread:23351 [system_monitor.py:probe():227] Publishing system info
2025-04-11 15:12:54,999 DEBUG   HandlerThread:23351 [system_info.py:_save_pip():52] Saving list of pip packages installed into the current environment
2025-04-11 15:12:55,000 DEBUG   HandlerThread:23351 [system_info.py:_save_pip():68] Saving pip packages done
2025-04-11 15:12:55,000 DEBUG   HandlerThread:23351 [system_info.py:_save_conda():75] Saving list of conda packages installed into the current environment
2025-04-11 15:12:55,109 INFO    Thread-12 :23351 [dir_watcher.py:_on_file_created():271] file/dir created: /root/ltu-main/ltu-main/src/ltu_as/train_scripts/wandb/run-20250411_151253-2p8m9dwe/files/conda-environment.yaml
2025-04-11 15:12:55,110 INFO    Thread-12 :23351 [dir_watcher.py:_on_file_created():271] file/dir created: /root/ltu-main/ltu-main/src/ltu_as/train_scripts/wandb/run-20250411_151253-2p8m9dwe/files/requirements.txt
2025-04-11 15:13:03,111 INFO    Thread-12 :23351 [dir_watcher.py:_on_file_modified():288] file/dir modified: /root/ltu-main/ltu-main/src/ltu_as/train_scripts/wandb/run-20250411_151253-2p8m9dwe/files/conda-environment.yaml
2025-04-11 15:13:03,228 DEBUG   HandlerThread:23351 [system_info.py:_save_conda():87] Saving conda packages done
2025-04-11 15:13:03,229 INFO    HandlerThread:23351 [system_monitor.py:probe():229] Finished publishing system info
2025-04-11 15:13:03,233 DEBUG   HandlerThread:23351 [handler.py:handle_request():146] handle_request: status_report
2025-04-11 15:13:03,233 DEBUG   HandlerThread:23351 [handler.py:handle_request():146] handle_request: keepalive
2025-04-11 15:13:03,234 DEBUG   SenderThread:23351 [sender.py:send():380] send: files
2025-04-11 15:13:03,234 INFO    SenderThread:23351 [sender.py:_save_file():1378] saving file wandb-metadata.json with policy now
2025-04-11 15:13:03,240 DEBUG   HandlerThread:23351 [handler.py:handle_request():146] handle_request: stop_status
2025-04-11 15:13:03,240 DEBUG   SenderThread:23351 [sender.py:send_request():407] send_request: stop_status
2025-04-11 15:13:03,251 DEBUG   HandlerThread:23351 [handler.py:handle_request():146] handle_request: internal_messages
2025-04-11 15:13:03,756 DEBUG   SenderThread:23351 [sender.py:send():380] send: telemetry
2025-04-11 15:13:03,756 DEBUG   SenderThread:23351 [sender.py:send():380] send: config
2025-04-11 15:13:03,757 DEBUG   SenderThread:23351 [sender.py:send():380] send: metric
2025-04-11 15:13:03,757 DEBUG   SenderThread:23351 [sender.py:send():380] send: telemetry
2025-04-11 15:13:03,758 DEBUG   SenderThread:23351 [sender.py:send():380] send: metric
2025-04-11 15:13:03,758 WARNING SenderThread:23351 [sender.py:send_metric():1329] Seen metric with glob (shouldn't happen)
2025-04-11 15:13:03,786 ERROR   wandb-upload_0:23351 [internal_api.py:upload_file():2556] upload_file exception https://storage.googleapis.com/wandb-production.appspot.com/2931823730-harbin-institute-of-technology/ltu-as/2p8m9dwe/wandb-metadata.json?X-Goog-Algorithm=GOOG4-RSA-SHA256&X-Goog-Credential=gorilla-files-url-signer-man%40wandb-production.iam.gserviceaccount.com%2F20250411%2Fauto%2Fstorage%2Fgoog4_request&X-Goog-Date=20250411T151303Z&X-Goog-Expires=86399&X-Goog-Signature=66719b998233aaee17a4c8047f633f9fe8c63f2ec466add270a92770477da6400199adfcf00866c96f6dc05161138b1c975095d9af586d19c4562209061e30e08bd4d7219879f1feac9679910790a6a4a494f472525052bd9d37aeaaff7a12f35f7118d64e15d74671f5afe7e20c2f2af6267dcd02dfacf08492999956870cba51b7f137738b959ca68d5f32bf47c87a32c21d2290ba9f62f0ea73dad72b8e99354b2a6d270ef91250d93621c3f830ce0c27c31dea23aac750b4dee03cc9083a92e0bd447360d1936579a5c45636fc1f207d010be1f8dc4f70e7e88a488e18a3096ee433b3386152f113d1b1a754768b9e6991b7358300a7435738c0343fa5e1&X-Goog-SignedHeaders=host&X-User=2931823730: HTTPSConnectionPool(host='storage.googleapis.com', port=443): Max retries exceeded with url: /wandb-production.appspot.com/2931823730-harbin-institute-of-technology/ltu-as/2p8m9dwe/wandb-metadata.json?X-Goog-Algorithm=GOOG4-RSA-SHA256&X-Goog-Credential=gorilla-files-url-signer-man%40wandb-production.iam.gserviceaccount.com%2F20250411%2Fauto%2Fstorage%2Fgoog4_request&X-Goog-Date=20250411T151303Z&X-Goog-Expires=86399&X-Goog-Signature=66719b998233aaee17a4c8047f633f9fe8c63f2ec466add270a92770477da6400199adfcf00866c96f6dc05161138b1c975095d9af586d19c4562209061e30e08bd4d7219879f1feac9679910790a6a4a494f472525052bd9d37aeaaff7a12f35f7118d64e15d74671f5afe7e20c2f2af6267dcd02dfacf08492999956870cba51b7f137738b959ca68d5f32bf47c87a32c21d2290ba9f62f0ea73dad72b8e99354b2a6d270ef91250d93621c3f830ce0c27c31dea23aac750b4dee03cc9083a92e0bd447360d1936579a5c45636fc1f207d010be1f8dc4f70e7e88a488e18a3096ee433b3386152f113d1b1a754768b9e6991b7358300a7435738c0343fa5e1&X-Goog-SignedHeaders=host&X-User=2931823730 (Caused by NewConnectionError('<urllib3.connection.HTTPSConnection object at 0x7fcd90151600>: Failed to establish a new connection: [Errno 101] Network is unreachable'))
2025-04-11 15:13:03,786 ERROR   wandb-upload_0:23351 [internal_api.py:upload_file():2558] upload_file request headers: {'User-Agent': 'python-requests/2.32.3', 'Accept-Encoding': 'gzip, deflate, br', 'Accept': '*/*', 'Connection': 'keep-alive', 'Content-Length': '2274'}
2025-04-11 15:13:03,787 ERROR   wandb-upload_0:23351 [internal_api.py:upload_file():2560] upload_file response body: 
2025-04-11 15:13:04,111 INFO    Thread-12 :23351 [dir_watcher.py:_on_file_created():271] file/dir created: /root/ltu-main/ltu-main/src/ltu_as/train_scripts/wandb/run-20250411_151253-2p8m9dwe/files/wandb-metadata.json
2025-04-11 15:13:04,112 INFO    Thread-12 :23351 [dir_watcher.py:_on_file_created():271] file/dir created: /root/ltu-main/ltu-main/src/ltu_as/train_scripts/wandb/run-20250411_151253-2p8m9dwe/files/output.log
2025-04-11 15:13:04,759 DEBUG   HandlerThread:23351 [handler.py:handle_request():146] handle_request: status_report
2025-04-11 15:13:04,843 ERROR   wandb-upload_0:23351 [internal_api.py:upload_file():2556] upload_file exception https://storage.googleapis.com/wandb-production.appspot.com/2931823730-harbin-institute-of-technology/ltu-as/2p8m9dwe/wandb-metadata.json?X-Goog-Algorithm=GOOG4-RSA-SHA256&X-Goog-Credential=gorilla-files-url-signer-man%40wandb-production.iam.gserviceaccount.com%2F20250411%2Fauto%2Fstorage%2Fgoog4_request&X-Goog-Date=20250411T151303Z&X-Goog-Expires=86399&X-Goog-Signature=66719b998233aaee17a4c8047f633f9fe8c63f2ec466add270a92770477da6400199adfcf00866c96f6dc05161138b1c975095d9af586d19c4562209061e30e08bd4d7219879f1feac9679910790a6a4a494f472525052bd9d37aeaaff7a12f35f7118d64e15d74671f5afe7e20c2f2af6267dcd02dfacf08492999956870cba51b7f137738b959ca68d5f32bf47c87a32c21d2290ba9f62f0ea73dad72b8e99354b2a6d270ef91250d93621c3f830ce0c27c31dea23aac750b4dee03cc9083a92e0bd447360d1936579a5c45636fc1f207d010be1f8dc4f70e7e88a488e18a3096ee433b3386152f113d1b1a754768b9e6991b7358300a7435738c0343fa5e1&X-Goog-SignedHeaders=host&X-User=2931823730: HTTPSConnectionPool(host='storage.googleapis.com', port=443): Max retries exceeded with url: /wandb-production.appspot.com/2931823730-harbin-institute-of-technology/ltu-as/2p8m9dwe/wandb-metadata.json?X-Goog-Algorithm=GOOG4-RSA-SHA256&X-Goog-Credential=gorilla-files-url-signer-man%40wandb-production.iam.gserviceaccount.com%2F20250411%2Fauto%2Fstorage%2Fgoog4_request&X-Goog-Date=20250411T151303Z&X-Goog-Expires=86399&X-Goog-Signature=66719b998233aaee17a4c8047f633f9fe8c63f2ec466add270a92770477da6400199adfcf00866c96f6dc05161138b1c975095d9af586d19c4562209061e30e08bd4d7219879f1feac9679910790a6a4a494f472525052bd9d37aeaaff7a12f35f7118d64e15d74671f5afe7e20c2f2af6267dcd02dfacf08492999956870cba51b7f137738b959ca68d5f32bf47c87a32c21d2290ba9f62f0ea73dad72b8e99354b2a6d270ef91250d93621c3f830ce0c27c31dea23aac750b4dee03cc9083a92e0bd447360d1936579a5c45636fc1f207d010be1f8dc4f70e7e88a488e18a3096ee433b3386152f113d1b1a754768b9e6991b7358300a7435738c0343fa5e1&X-Goog-SignedHeaders=host&X-User=2931823730 (Caused by NewConnectionError('<urllib3.connection.HTTPSConnection object at 0x7fcd90151450>: Failed to establish a new connection: [Errno 101] Network is unreachable'))
2025-04-11 15:13:04,844 ERROR   wandb-upload_0:23351 [internal_api.py:upload_file():2558] upload_file request headers: {'User-Agent': 'python-requests/2.32.3', 'Accept-Encoding': 'gzip, deflate, br', 'Accept': '*/*', 'Connection': 'keep-alive', 'Content-Length': '2274'}
2025-04-11 15:13:04,844 ERROR   wandb-upload_0:23351 [internal_api.py:upload_file():2560] upload_file response body: 
2025-04-11 15:13:06,112 INFO    Thread-12 :23351 [dir_watcher.py:_on_file_modified():288] file/dir modified: /root/ltu-main/ltu-main/src/ltu_as/train_scripts/wandb/run-20250411_151253-2p8m9dwe/files/output.log
2025-04-11 15:13:07,056 ERROR   wandb-upload_0:23351 [internal_api.py:upload_file():2556] upload_file exception https://storage.googleapis.com/wandb-production.appspot.com/2931823730-harbin-institute-of-technology/ltu-as/2p8m9dwe/wandb-metadata.json?X-Goog-Algorithm=GOOG4-RSA-SHA256&X-Goog-Credential=gorilla-files-url-signer-man%40wandb-production.iam.gserviceaccount.com%2F20250411%2Fauto%2Fstorage%2Fgoog4_request&X-Goog-Date=20250411T151303Z&X-Goog-Expires=86399&X-Goog-Signature=66719b998233aaee17a4c8047f633f9fe8c63f2ec466add270a92770477da6400199adfcf00866c96f6dc05161138b1c975095d9af586d19c4562209061e30e08bd4d7219879f1feac9679910790a6a4a494f472525052bd9d37aeaaff7a12f35f7118d64e15d74671f5afe7e20c2f2af6267dcd02dfacf08492999956870cba51b7f137738b959ca68d5f32bf47c87a32c21d2290ba9f62f0ea73dad72b8e99354b2a6d270ef91250d93621c3f830ce0c27c31dea23aac750b4dee03cc9083a92e0bd447360d1936579a5c45636fc1f207d010be1f8dc4f70e7e88a488e18a3096ee433b3386152f113d1b1a754768b9e6991b7358300a7435738c0343fa5e1&X-Goog-SignedHeaders=host&X-User=2931823730: HTTPSConnectionPool(host='storage.googleapis.com', port=443): Max retries exceeded with url: /wandb-production.appspot.com/2931823730-harbin-institute-of-technology/ltu-as/2p8m9dwe/wandb-metadata.json?X-Goog-Algorithm=GOOG4-RSA-SHA256&X-Goog-Credential=gorilla-files-url-signer-man%40wandb-production.iam.gserviceaccount.com%2F20250411%2Fauto%2Fstorage%2Fgoog4_request&X-Goog-Date=20250411T151303Z&X-Goog-Expires=86399&X-Goog-Signature=66719b998233aaee17a4c8047f633f9fe8c63f2ec466add270a92770477da6400199adfcf00866c96f6dc05161138b1c975095d9af586d19c4562209061e30e08bd4d7219879f1feac9679910790a6a4a494f472525052bd9d37aeaaff7a12f35f7118d64e15d74671f5afe7e20c2f2af6267dcd02dfacf08492999956870cba51b7f137738b959ca68d5f32bf47c87a32c21d2290ba9f62f0ea73dad72b8e99354b2a6d270ef91250d93621c3f830ce0c27c31dea23aac750b4dee03cc9083a92e0bd447360d1936579a5c45636fc1f207d010be1f8dc4f70e7e88a488e18a3096ee433b3386152f113d1b1a754768b9e6991b7358300a7435738c0343fa5e1&X-Goog-SignedHeaders=host&X-User=2931823730 (Caused by NewConnectionError('<urllib3.connection.HTTPSConnection object at 0x7fcd90150040>: Failed to establish a new connection: [Errno 101] Network is unreachable'))
2025-04-11 15:13:07,056 ERROR   wandb-upload_0:23351 [internal_api.py:upload_file():2558] upload_file request headers: {'User-Agent': 'python-requests/2.32.3', 'Accept-Encoding': 'gzip, deflate, br', 'Accept': '*/*', 'Connection': 'keep-alive', 'Content-Length': '2274'}
2025-04-11 15:13:07,056 ERROR   wandb-upload_0:23351 [internal_api.py:upload_file():2560] upload_file response body: 
2025-04-11 15:13:07,056 INFO    wandb-upload_0:23351 [retry.py:__call__():172] Retry attempt failed:
Traceback (most recent call last):
  File "/root/anaconda3/envs/venv_ltu/lib/python3.10/site-packages/urllib3/connection.py", line 198, in _new_conn
    sock = connection.create_connection(
  File "/root/anaconda3/envs/venv_ltu/lib/python3.10/site-packages/urllib3/util/connection.py", line 85, in create_connection
    raise err
  File "/root/anaconda3/envs/venv_ltu/lib/python3.10/site-packages/urllib3/util/connection.py", line 73, in create_connection
    sock.connect(sa)
OSError: [Errno 101] Network is unreachable

The above exception was the direct cause of the following exception:

Traceback (most recent call last):
  File "/root/anaconda3/envs/venv_ltu/lib/python3.10/site-packages/urllib3/connectionpool.py", line 793, in urlopen
    response = self._make_request(
  File "/root/anaconda3/envs/venv_ltu/lib/python3.10/site-packages/urllib3/connectionpool.py", line 491, in _make_request
    raise new_e
  File "/root/anaconda3/envs/venv_ltu/lib/python3.10/site-packages/urllib3/connectionpool.py", line 467, in _make_request
    self._validate_conn(conn)
  File "/root/anaconda3/envs/venv_ltu/lib/python3.10/site-packages/urllib3/connectionpool.py", line 1099, in _validate_conn
    conn.connect()
  File "/root/anaconda3/envs/venv_ltu/lib/python3.10/site-packages/urllib3/connection.py", line 616, in connect
    self.sock = sock = self._new_conn()
  File "/root/anaconda3/envs/venv_ltu/lib/python3.10/site-packages/urllib3/connection.py", line 213, in _new_conn
    raise NewConnectionError(
urllib3.exceptions.NewConnectionError: <urllib3.connection.HTTPSConnection object at 0x7fcd90150040>: Failed to establish a new connection: [Errno 101] Network is unreachable

The above exception was the direct cause of the following exception:

Traceback (most recent call last):
  File "/root/anaconda3/envs/venv_ltu/lib/python3.10/site-packages/requests/adapters.py", line 667, in send
    resp = conn.urlopen(
  File "/root/anaconda3/envs/venv_ltu/lib/python3.10/site-packages/urllib3/connectionpool.py", line 847, in urlopen
    retries = retries.increment(
  File "/root/anaconda3/envs/venv_ltu/lib/python3.10/site-packages/urllib3/util/retry.py", line 515, in increment
    raise MaxRetryError(_pool, url, reason) from reason  # type: ignore[arg-type]
urllib3.exceptions.MaxRetryError: HTTPSConnectionPool(host='storage.googleapis.com', port=443): Max retries exceeded with url: /wandb-production.appspot.com/2931823730-harbin-institute-of-technology/ltu-as/2p8m9dwe/wandb-metadata.json?X-Goog-Algorithm=GOOG4-RSA-SHA256&X-Goog-Credential=gorilla-files-url-signer-man%40wandb-production.iam.gserviceaccount.com%2F20250411%2Fauto%2Fstorage%2Fgoog4_request&X-Goog-Date=20250411T151303Z&X-Goog-Expires=86399&X-Goog-Signature=66719b998233aaee17a4c8047f633f9fe8c63f2ec466add270a92770477da6400199adfcf00866c96f6dc05161138b1c975095d9af586d19c4562209061e30e08bd4d7219879f1feac9679910790a6a4a494f472525052bd9d37aeaaff7a12f35f7118d64e15d74671f5afe7e20c2f2af6267dcd02dfacf08492999956870cba51b7f137738b959ca68d5f32bf47c87a32c21d2290ba9f62f0ea73dad72b8e99354b2a6d270ef91250d93621c3f830ce0c27c31dea23aac750b4dee03cc9083a92e0bd447360d1936579a5c45636fc1f207d010be1f8dc4f70e7e88a488e18a3096ee433b3386152f113d1b1a754768b9e6991b7358300a7435738c0343fa5e1&X-Goog-SignedHeaders=host&X-User=2931823730 (Caused by NewConnectionError('<urllib3.connection.HTTPSConnection object at 0x7fcd90150040>: Failed to establish a new connection: [Errno 101] Network is unreachable'))

During handling of the above exception, another exception occurred:

Traceback (most recent call last):
  File "/root/anaconda3/envs/venv_ltu/lib/python3.10/site-packages/wandb/sdk/internal/internal_api.py", line 2549, in upload_file
    response = self._upload_file_session.put(
  File "/root/anaconda3/envs/venv_ltu/lib/python3.10/site-packages/requests/sessions.py", line 649, in put
    return self.request("PUT", url, data=data, **kwargs)
  File "/root/anaconda3/envs/venv_ltu/lib/python3.10/site-packages/requests/sessions.py", line 589, in request
    resp = self.send(prep, **send_kwargs)
  File "/root/anaconda3/envs/venv_ltu/lib/python3.10/site-packages/requests/sessions.py", line 703, in send
    r = adapter.send(request, **kwargs)
  File "/root/anaconda3/envs/venv_ltu/lib/python3.10/site-packages/requests/adapters.py", line 700, in send
    raise ConnectionError(e, request=request)
requests.exceptions.ConnectionError: HTTPSConnectionPool(host='storage.googleapis.com', port=443): Max retries exceeded with url: /wandb-production.appspot.com/2931823730-harbin-institute-of-technology/ltu-as/2p8m9dwe/wandb-metadata.json?X-Goog-Algorithm=GOOG4-RSA-SHA256&X-Goog-Credential=gorilla-files-url-signer-man%40wandb-production.iam.gserviceaccount.com%2F20250411%2Fauto%2Fstorage%2Fgoog4_request&X-Goog-Date=20250411T151303Z&X-Goog-Expires=86399&X-Goog-Signature=66719b998233aaee17a4c8047f633f9fe8c63f2ec466add270a92770477da6400199adfcf00866c96f6dc05161138b1c975095d9af586d19c4562209061e30e08bd4d7219879f1feac9679910790a6a4a494f472525052bd9d37aeaaff7a12f35f7118d64e15d74671f5afe7e20c2f2af6267dcd02dfacf08492999956870cba51b7f137738b959ca68d5f32bf47c87a32c21d2290ba9f62f0ea73dad72b8e99354b2a6d270ef91250d93621c3f830ce0c27c31dea23aac750b4dee03cc9083a92e0bd447360d1936579a5c45636fc1f207d010be1f8dc4f70e7e88a488e18a3096ee433b3386152f113d1b1a754768b9e6991b7358300a7435738c0343fa5e1&X-Goog-SignedHeaders=host&X-User=2931823730 (Caused by NewConnectionError('<urllib3.connection.HTTPSConnection object at 0x7fcd90150040>: Failed to establish a new connection: [Errno 101] Network is unreachable'))

During handling of the above exception, another exception occurred:

Traceback (most recent call last):
  File "/root/anaconda3/envs/venv_ltu/lib/python3.10/site-packages/wandb/sdk/lib/retry.py", line 131, in __call__
    result = self._call_fn(*args, **kwargs)
  File "/root/anaconda3/envs/venv_ltu/lib/python3.10/site-packages/wandb/sdk/internal/internal_api.py", line 2580, in upload_file
    raise _e.with_traceback(sys.exc_info()[2])
  File "/root/anaconda3/envs/venv_ltu/lib/python3.10/site-packages/wandb/sdk/internal/internal_api.py", line 2549, in upload_file
    response = self._upload_file_session.put(
  File "/root/anaconda3/envs/venv_ltu/lib/python3.10/site-packages/requests/sessions.py", line 649, in put
    return self.request("PUT", url, data=data, **kwargs)
  File "/root/anaconda3/envs/venv_ltu/lib/python3.10/site-packages/requests/sessions.py", line 589, in request
    resp = self.send(prep, **send_kwargs)
  File "/root/anaconda3/envs/venv_ltu/lib/python3.10/site-packages/requests/sessions.py", line 703, in send
    r = adapter.send(request, **kwargs)
  File "/root/anaconda3/envs/venv_ltu/lib/python3.10/site-packages/requests/adapters.py", line 700, in send
    raise ConnectionError(e, request=request)
wandb.sdk.lib.retry.TransientError: None
2025-04-11 15:13:09,763 DEBUG   HandlerThread:23351 [handler.py:handle_request():146] handle_request: status_report
2025-04-11 15:13:11,230 ERROR   wandb-upload_0:23351 [internal_api.py:upload_file():2556] upload_file exception https://storage.googleapis.com/wandb-production.appspot.com/2931823730-harbin-institute-of-technology/ltu-as/2p8m9dwe/wandb-metadata.json?X-Goog-Algorithm=GOOG4-RSA-SHA256&X-Goog-Credential=gorilla-files-url-signer-man%40wandb-production.iam.gserviceaccount.com%2F20250411%2Fauto%2Fstorage%2Fgoog4_request&X-Goog-Date=20250411T151303Z&X-Goog-Expires=86399&X-Goog-Signature=66719b998233aaee17a4c8047f633f9fe8c63f2ec466add270a92770477da6400199adfcf00866c96f6dc05161138b1c975095d9af586d19c4562209061e30e08bd4d7219879f1feac9679910790a6a4a494f472525052bd9d37aeaaff7a12f35f7118d64e15d74671f5afe7e20c2f2af6267dcd02dfacf08492999956870cba51b7f137738b959ca68d5f32bf47c87a32c21d2290ba9f62f0ea73dad72b8e99354b2a6d270ef91250d93621c3f830ce0c27c31dea23aac750b4dee03cc9083a92e0bd447360d1936579a5c45636fc1f207d010be1f8dc4f70e7e88a488e18a3096ee433b3386152f113d1b1a754768b9e6991b7358300a7435738c0343fa5e1&X-Goog-SignedHeaders=host&X-User=2931823730: HTTPSConnectionPool(host='storage.googleapis.com', port=443): Max retries exceeded with url: /wandb-production.appspot.com/2931823730-harbin-institute-of-technology/ltu-as/2p8m9dwe/wandb-metadata.json?X-Goog-Algorithm=GOOG4-RSA-SHA256&X-Goog-Credential=gorilla-files-url-signer-man%40wandb-production.iam.gserviceaccount.com%2F20250411%2Fauto%2Fstorage%2Fgoog4_request&X-Goog-Date=20250411T151303Z&X-Goog-Expires=86399&X-Goog-Signature=66719b998233aaee17a4c8047f633f9fe8c63f2ec466add270a92770477da6400199adfcf00866c96f6dc05161138b1c975095d9af586d19c4562209061e30e08bd4d7219879f1feac9679910790a6a4a494f472525052bd9d37aeaaff7a12f35f7118d64e15d74671f5afe7e20c2f2af6267dcd02dfacf08492999956870cba51b7f137738b959ca68d5f32bf47c87a32c21d2290ba9f62f0ea73dad72b8e99354b2a6d270ef91250d93621c3f830ce0c27c31dea23aac750b4dee03cc9083a92e0bd447360d1936579a5c45636fc1f207d010be1f8dc4f70e7e88a488e18a3096ee433b3386152f113d1b1a754768b9e6991b7358300a7435738c0343fa5e1&X-Goog-SignedHeaders=host&X-User=2931823730 (Caused by NewConnectionError('<urllib3.connection.HTTPSConnection object at 0x7fcd901524d0>: Failed to establish a new connection: [Errno 101] Network is unreachable'))
2025-04-11 15:13:11,230 ERROR   wandb-upload_0:23351 [internal_api.py:upload_file():2558] upload_file request headers: {'User-Agent': 'python-requests/2.32.3', 'Accept-Encoding': 'gzip, deflate, br', 'Accept': '*/*', 'Connection': 'keep-alive', 'Content-Length': '2274'}
2025-04-11 15:13:11,230 ERROR   wandb-upload_0:23351 [internal_api.py:upload_file():2560] upload_file response body: 
2025-04-11 15:13:12,550 DEBUG   SenderThread:23351 [sender.py:send():380] send: exit
2025-04-11 15:13:12,550 INFO    SenderThread:23351 [sender.py:send_exit():585] handling exit code: 1
2025-04-11 15:13:12,551 INFO    SenderThread:23351 [sender.py:send_exit():587] handling runtime: 17
2025-04-11 15:13:12,553 INFO    SenderThread:23351 [sender.py:_save_file():1378] saving file wandb-summary.json with policy end
2025-04-11 15:13:12,553 INFO    SenderThread:23351 [sender.py:send_exit():593] send defer
2025-04-11 15:13:12,554 DEBUG   HandlerThread:23351 [handler.py:handle_request():146] handle_request: defer
2025-04-11 15:13:12,554 INFO    HandlerThread:23351 [handler.py:handle_request_defer():172] handle defer: 0
2025-04-11 15:13:12,554 DEBUG   SenderThread:23351 [sender.py:send_request():407] send_request: defer
2025-04-11 15:13:12,554 INFO    SenderThread:23351 [sender.py:send_request_defer():609] handle sender defer: 0
2025-04-11 15:13:12,554 INFO    SenderThread:23351 [sender.py:transition_state():613] send defer: 1
2025-04-11 15:13:12,554 DEBUG   HandlerThread:23351 [handler.py:handle_request():146] handle_request: defer
2025-04-11 15:13:12,554 INFO    HandlerThread:23351 [handler.py:handle_request_defer():172] handle defer: 1
2025-04-11 15:13:12,555 DEBUG   SenderThread:23351 [sender.py:send_request():407] send_request: defer
2025-04-11 15:13:12,555 INFO    SenderThread:23351 [sender.py:send_request_defer():609] handle sender defer: 1
2025-04-11 15:13:12,555 INFO    SenderThread:23351 [sender.py:transition_state():613] send defer: 2
2025-04-11 15:13:12,555 DEBUG   HandlerThread:23351 [handler.py:handle_request():146] handle_request: defer
2025-04-11 15:13:12,555 INFO    HandlerThread:23351 [handler.py:handle_request_defer():172] handle defer: 2
2025-04-11 15:13:12,555 INFO    HandlerThread:23351 [system_monitor.py:finish():203] Stopping system monitor
2025-04-11 15:13:12,555 DEBUG   SystemMonitor:23351 [system_monitor.py:_start():172] Starting system metrics aggregation loop
2025-04-11 15:13:12,556 INFO    HandlerThread:23351 [interfaces.py:finish():202] Joined cpu monitor
2025-04-11 15:13:12,556 DEBUG   SystemMonitor:23351 [system_monitor.py:_start():179] Finished system metrics aggregation loop
2025-04-11 15:13:12,556 INFO    HandlerThread:23351 [interfaces.py:finish():202] Joined disk monitor
2025-04-11 15:13:12,557 DEBUG   SystemMonitor:23351 [system_monitor.py:_start():183] Publishing last batch of metrics
2025-04-11 15:13:12,578 INFO    HandlerThread:23351 [interfaces.py:finish():202] Joined gpu monitor
2025-04-11 15:13:12,578 INFO    HandlerThread:23351 [interfaces.py:finish():202] Joined memory monitor
2025-04-11 15:13:12,579 INFO    HandlerThread:23351 [interfaces.py:finish():202] Joined network monitor
2025-04-11 15:13:12,579 DEBUG   SenderThread:23351 [sender.py:send_request():407] send_request: defer
2025-04-11 15:13:12,579 INFO    SenderThread:23351 [sender.py:send_request_defer():609] handle sender defer: 2
2025-04-11 15:13:12,579 INFO    SenderThread:23351 [sender.py:transition_state():613] send defer: 3
2025-04-11 15:13:12,579 DEBUG   SenderThread:23351 [sender.py:send():380] send: stats
2025-04-11 15:13:12,580 DEBUG   HandlerThread:23351 [handler.py:handle_request():146] handle_request: defer
2025-04-11 15:13:12,580 INFO    HandlerThread:23351 [handler.py:handle_request_defer():172] handle defer: 3
2025-04-11 15:13:12,580 DEBUG   SenderThread:23351 [sender.py:send_request():407] send_request: defer
2025-04-11 15:13:12,580 INFO    SenderThread:23351 [sender.py:send_request_defer():609] handle sender defer: 3
2025-04-11 15:13:12,580 INFO    SenderThread:23351 [sender.py:transition_state():613] send defer: 4
2025-04-11 15:13:12,580 DEBUG   HandlerThread:23351 [handler.py:handle_request():146] handle_request: defer
2025-04-11 15:13:12,580 INFO    HandlerThread:23351 [handler.py:handle_request_defer():172] handle defer: 4
2025-04-11 15:13:12,581 DEBUG   SenderThread:23351 [sender.py:send_request():407] send_request: defer
2025-04-11 15:13:12,581 INFO    SenderThread:23351 [sender.py:send_request_defer():609] handle sender defer: 4
2025-04-11 15:13:12,581 INFO    SenderThread:23351 [sender.py:transition_state():613] send defer: 5
2025-04-11 15:13:12,581 DEBUG   HandlerThread:23351 [handler.py:handle_request():146] handle_request: defer
2025-04-11 15:13:12,581 INFO    HandlerThread:23351 [handler.py:handle_request_defer():172] handle defer: 5
2025-04-11 15:13:12,581 DEBUG   SenderThread:23351 [sender.py:send():380] send: summary
2025-04-11 15:13:12,655 INFO    SenderThread:23351 [sender.py:_save_file():1378] saving file wandb-summary.json with policy end
2025-04-11 15:13:12,656 DEBUG   SenderThread:23351 [sender.py:send_request():407] send_request: defer
2025-04-11 15:13:12,656 INFO    SenderThread:23351 [sender.py:send_request_defer():609] handle sender defer: 5
2025-04-11 15:13:12,656 INFO    SenderThread:23351 [sender.py:transition_state():613] send defer: 6
2025-04-11 15:13:12,657 DEBUG   HandlerThread:23351 [handler.py:handle_request():146] handle_request: defer
2025-04-11 15:13:12,657 INFO    HandlerThread:23351 [handler.py:handle_request_defer():172] handle defer: 6
2025-04-11 15:13:12,658 DEBUG   SenderThread:23351 [sender.py:send_request():407] send_request: defer
2025-04-11 15:13:12,658 INFO    SenderThread:23351 [sender.py:send_request_defer():609] handle sender defer: 6
2025-04-11 15:13:12,665 DEBUG   HandlerThread:23351 [handler.py:handle_request():146] handle_request: status_report
2025-04-11 15:13:13,014 INFO    SenderThread:23351 [sender.py:transition_state():613] send defer: 7
2025-04-11 15:13:13,014 DEBUG   HandlerThread:23351 [handler.py:handle_request():146] handle_request: defer
2025-04-11 15:13:13,014 INFO    HandlerThread:23351 [handler.py:handle_request_defer():172] handle defer: 7
2025-04-11 15:13:13,015 DEBUG   SenderThread:23351 [sender.py:send_request():407] send_request: defer
2025-04-11 15:13:13,015 INFO    SenderThread:23351 [sender.py:send_request_defer():609] handle sender defer: 7
2025-04-11 15:13:13,115 INFO    Thread-12 :23351 [dir_watcher.py:_on_file_modified():288] file/dir modified: /root/ltu-main/ltu-main/src/ltu_as/train_scripts/wandb/run-20250411_151253-2p8m9dwe/files/config.yaml
2025-04-11 15:13:13,116 INFO    Thread-12 :23351 [dir_watcher.py:_on_file_created():271] file/dir created: /root/ltu-main/ltu-main/src/ltu_as/train_scripts/wandb/run-20250411_151253-2p8m9dwe/files/wandb-summary.json
2025-04-11 15:13:13,550 DEBUG   HandlerThread:23351 [handler.py:handle_request():146] handle_request: poll_exit
2025-04-11 15:13:13,786 INFO    SenderThread:23351 [sender.py:transition_state():613] send defer: 8
2025-04-11 15:13:13,786 DEBUG   SenderThread:23351 [sender.py:send_request():407] send_request: poll_exit
2025-04-11 15:13:13,786 DEBUG   HandlerThread:23351 [handler.py:handle_request():146] handle_request: defer
2025-04-11 15:13:13,787 INFO    HandlerThread:23351 [handler.py:handle_request_defer():172] handle defer: 8
2025-04-11 15:13:13,787 DEBUG   SenderThread:23351 [sender.py:send_request():407] send_request: defer
2025-04-11 15:13:13,787 INFO    SenderThread:23351 [sender.py:send_request_defer():609] handle sender defer: 8
2025-04-11 15:13:13,787 INFO    SenderThread:23351 [job_builder.py:build():281] Attempting to build job artifact
2025-04-11 15:13:13,789 INFO    SenderThread:23351 [job_builder.py:_get_source_type():404] no source found
2025-04-11 15:13:13,789 INFO    SenderThread:23351 [sender.py:transition_state():613] send defer: 9
2025-04-11 15:13:13,790 DEBUG   HandlerThread:23351 [handler.py:handle_request():146] handle_request: defer
2025-04-11 15:13:13,790 INFO    HandlerThread:23351 [handler.py:handle_request_defer():172] handle defer: 9
2025-04-11 15:13:13,790 DEBUG   SenderThread:23351 [sender.py:send_request():407] send_request: defer
2025-04-11 15:13:13,790 INFO    SenderThread:23351 [sender.py:send_request_defer():609] handle sender defer: 9
2025-04-11 15:13:13,790 INFO    SenderThread:23351 [dir_watcher.py:finish():358] shutting down directory watcher
2025-04-11 15:13:14,116 INFO    Thread-12 :23351 [dir_watcher.py:_on_file_modified():288] file/dir modified: /root/ltu-main/ltu-main/src/ltu_as/train_scripts/wandb/run-20250411_151253-2p8m9dwe/files/output.log
2025-04-11 15:13:14,117 INFO    SenderThread:23351 [dir_watcher.py:finish():388] scan: /root/ltu-main/ltu-main/src/ltu_as/train_scripts/wandb/run-20250411_151253-2p8m9dwe/files
2025-04-11 15:13:14,118 INFO    SenderThread:23351 [dir_watcher.py:finish():402] scan save: /root/ltu-main/ltu-main/src/ltu_as/train_scripts/wandb/run-20250411_151253-2p8m9dwe/files/config.yaml config.yaml
2025-04-11 15:13:14,118 INFO    SenderThread:23351 [dir_watcher.py:finish():402] scan save: /root/ltu-main/ltu-main/src/ltu_as/train_scripts/wandb/run-20250411_151253-2p8m9dwe/files/requirements.txt requirements.txt
2025-04-11 15:13:14,122 INFO    SenderThread:23351 [dir_watcher.py:finish():402] scan save: /root/ltu-main/ltu-main/src/ltu_as/train_scripts/wandb/run-20250411_151253-2p8m9dwe/files/conda-environment.yaml conda-environment.yaml
2025-04-11 15:13:14,126 INFO    SenderThread:23351 [dir_watcher.py:finish():402] scan save: /root/ltu-main/ltu-main/src/ltu_as/train_scripts/wandb/run-20250411_151253-2p8m9dwe/files/wandb-metadata.json wandb-metadata.json
2025-04-11 15:13:14,127 INFO    SenderThread:23351 [dir_watcher.py:finish():402] scan save: /root/ltu-main/ltu-main/src/ltu_as/train_scripts/wandb/run-20250411_151253-2p8m9dwe/files/output.log output.log
2025-04-11 15:13:14,127 INFO    SenderThread:23351 [dir_watcher.py:finish():402] scan save: /root/ltu-main/ltu-main/src/ltu_as/train_scripts/wandb/run-20250411_151253-2p8m9dwe/files/wandb-summary.json wandb-summary.json
2025-04-11 15:13:14,129 INFO    SenderThread:23351 [sender.py:transition_state():613] send defer: 10
2025-04-11 15:13:14,130 DEBUG   HandlerThread:23351 [handler.py:handle_request():146] handle_request: defer
2025-04-11 15:13:14,130 INFO    HandlerThread:23351 [handler.py:handle_request_defer():172] handle defer: 10
2025-04-11 15:13:14,135 DEBUG   SenderThread:23351 [sender.py:send_request():407] send_request: defer
2025-04-11 15:13:14,135 INFO    SenderThread:23351 [sender.py:send_request_defer():609] handle sender defer: 10
2025-04-11 15:13:14,135 INFO    SenderThread:23351 [file_pusher.py:finish():175] shutting down file pusher
2025-04-11 15:13:14,406 ERROR   wandb-upload_1:23351 [internal_api.py:upload_file():2556] upload_file exception https://storage.googleapis.com/wandb-production.appspot.com/2931823730-harbin-institute-of-technology/ltu-as/2p8m9dwe/config.yaml?X-Goog-Algorithm=GOOG4-RSA-SHA256&X-Goog-Credential=gorilla-files-url-signer-man%40wandb-production.iam.gserviceaccount.com%2F20250411%2Fauto%2Fstorage%2Fgoog4_request&X-Goog-Date=20250411T151314Z&X-Goog-Expires=86399&X-Goog-Signature=c3f1c581a0bd73c6399672f1fac440187a0b07669ff4825ee30bf5e058c5a683d85c7b6a22215e3bb850b742c0d89df501576ca1866fd5534cc3429d481eba7e8d4f973e12d002b083ebdafce4bc036f519523a270ba6868dfa5551a4dacda47e4863088e75c0f9dd7ef57f5509215ac52373490cdb269dceabdf696d0c1b874b77f6e0064f27f0acc826c3bf3755682d9d80d1c2829fc57effdb94af0f0693ef6bbbf1e906d59b08d2ac9d8d8617261eea7f087f6d696d308a005cdbb07089b88ec998a31608527466034e5d8e1c405536f34bec132780342d5f14d57109d149db8d09c9a4b2d71228d28d56b512091008f600490c271953244785eda190976&X-Goog-SignedHeaders=host&X-User=2931823730: HTTPSConnectionPool(host='storage.googleapis.com', port=443): Max retries exceeded with url: /wandb-production.appspot.com/2931823730-harbin-institute-of-technology/ltu-as/2p8m9dwe/config.yaml?X-Goog-Algorithm=GOOG4-RSA-SHA256&X-Goog-Credential=gorilla-files-url-signer-man%40wandb-production.iam.gserviceaccount.com%2F20250411%2Fauto%2Fstorage%2Fgoog4_request&X-Goog-Date=20250411T151314Z&X-Goog-Expires=86399&X-Goog-Signature=c3f1c581a0bd73c6399672f1fac440187a0b07669ff4825ee30bf5e058c5a683d85c7b6a22215e3bb850b742c0d89df501576ca1866fd5534cc3429d481eba7e8d4f973e12d002b083ebdafce4bc036f519523a270ba6868dfa5551a4dacda47e4863088e75c0f9dd7ef57f5509215ac52373490cdb269dceabdf696d0c1b874b77f6e0064f27f0acc826c3bf3755682d9d80d1c2829fc57effdb94af0f0693ef6bbbf1e906d59b08d2ac9d8d8617261eea7f087f6d696d308a005cdbb07089b88ec998a31608527466034e5d8e1c405536f34bec132780342d5f14d57109d149db8d09c9a4b2d71228d28d56b512091008f600490c271953244785eda190976&X-Goog-SignedHeaders=host&X-User=2931823730 (Caused by NewConnectionError('<urllib3.connection.HTTPSConnection object at 0x7fcd901537f0>: Failed to establish a new connection: [Errno 101] Network is unreachable'))
2025-04-11 15:13:14,406 ERROR   wandb-upload_1:23351 [internal_api.py:upload_file():2558] upload_file request headers: {'User-Agent': 'python-requests/2.32.3', 'Accept-Encoding': 'gzip, deflate, br', 'Accept': '*/*', 'Connection': 'keep-alive', 'Content-Length': '8685'}
2025-04-11 15:13:14,406 ERROR   wandb-upload_1:23351 [internal_api.py:upload_file():2560] upload_file response body: 
2025-04-11 15:13:14,407 ERROR   wandb-upload_2:23351 [internal_api.py:upload_file():2556] upload_file exception https://storage.googleapis.com/wandb-production.appspot.com/2931823730-harbin-institute-of-technology/ltu-as/2p8m9dwe/requirements.txt?X-Goog-Algorithm=GOOG4-RSA-SHA256&X-Goog-Credential=gorilla-files-url-signer-man%40wandb-production.iam.gserviceaccount.com%2F20250411%2Fauto%2Fstorage%2Fgoog4_request&X-Goog-Date=20250411T151314Z&X-Goog-Expires=86399&X-Goog-Signature=596e10f29ae2cec75cbb1a5c0879360376523a72f892408b062c1c8ebab215b4abbad1df8da6bec541c89de6deec2c6eb2b6da8b279a8f2bf743c49dea4bc7e6e3ae10f36daa45d6c2e3fac141e6b670687c7233fa8373b04b2f2ded936d143be1302daec292448420869529e939bed8801a5287777bec29a946e96cd575116736d582b1f707a977a956003d465137e9d8705e50cad2a5d9a9bcb34fc432d91d692f7909aee691cef6f89d2eabdc170595373f228cb4586119d828afa412185bca4dcc7d703d9b2be5d7e28fb510bf2f95fcb6854a59c4d660327bd409ac87373f31aa2e1ff0ef593ee31c3901719e0db1cd03a2427023741ffddaec48f48a33&X-Goog-SignedHeaders=host&X-User=2931823730: HTTPSConnectionPool(host='storage.googleapis.com', port=443): Max retries exceeded with url: /wandb-production.appspot.com/2931823730-harbin-institute-of-technology/ltu-as/2p8m9dwe/requirements.txt?X-Goog-Algorithm=GOOG4-RSA-SHA256&X-Goog-Credential=gorilla-files-url-signer-man%40wandb-production.iam.gserviceaccount.com%2F20250411%2Fauto%2Fstorage%2Fgoog4_request&X-Goog-Date=20250411T151314Z&X-Goog-Expires=86399&X-Goog-Signature=596e10f29ae2cec75cbb1a5c0879360376523a72f892408b062c1c8ebab215b4abbad1df8da6bec541c89de6deec2c6eb2b6da8b279a8f2bf743c49dea4bc7e6e3ae10f36daa45d6c2e3fac141e6b670687c7233fa8373b04b2f2ded936d143be1302daec292448420869529e939bed8801a5287777bec29a946e96cd575116736d582b1f707a977a956003d465137e9d8705e50cad2a5d9a9bcb34fc432d91d692f7909aee691cef6f89d2eabdc170595373f228cb4586119d828afa412185bca4dcc7d703d9b2be5d7e28fb510bf2f95fcb6854a59c4d660327bd409ac87373f31aa2e1ff0ef593ee31c3901719e0db1cd03a2427023741ffddaec48f48a33&X-Goog-SignedHeaders=host&X-User=2931823730 (Caused by NewConnectionError('<urllib3.connection.HTTPSConnection object at 0x7fcd90152260>: Failed to establish a new connection: [Errno 101] Network is unreachable'))
2025-04-11 15:13:14,407 ERROR   wandb-upload_2:23351 [internal_api.py:upload_file():2558] upload_file request headers: {'User-Agent': 'python-requests/2.32.3', 'Accept-Encoding': 'gzip, deflate, br', 'Accept': '*/*', 'Connection': 'keep-alive', 'Content-Length': '4212'}
2025-04-11 15:13:14,407 ERROR   wandb-upload_2:23351 [internal_api.py:upload_file():2560] upload_file response body: 
2025-04-11 15:13:14,552 DEBUG   HandlerThread:23351 [handler.py:handle_request():146] handle_request: poll_exit
2025-04-11 15:13:14,552 DEBUG   SenderThread:23351 [sender.py:send_request():407] send_request: poll_exit
2025-04-11 15:13:14,615 ERROR   wandb-upload_4:23351 [internal_api.py:upload_file():2556] upload_file exception https://storage.googleapis.com/wandb-production.appspot.com/2931823730-harbin-institute-of-technology/ltu-as/2p8m9dwe/output.log?X-Goog-Algorithm=GOOG4-RSA-SHA256&X-Goog-Credential=gorilla-files-url-signer-man%40wandb-production.iam.gserviceaccount.com%2F20250411%2Fauto%2Fstorage%2Fgoog4_request&X-Goog-Date=20250411T151314Z&X-Goog-Expires=86399&X-Goog-Signature=c44716d15ea1c964086d12ca01197c8ce47394f84080ef2ac590732ab708d2de7ce5088a8dca5fff495f540400d7d9b1a33c277aa3ccacc835e260daadaa862ab277c9696b93258cd56a8316dfce8e36fa696f08f5ccb6508ad7eb9eef52ab7be3706ef92a52379cf3fbd94a8440c357a965492d496dd36a42cee1bacf58cb62b67f2717f8f904593a8b13fa947081c7e88f242c8e2f8f146a7201227a09cfb23de21fdce4ad87a30d7dc7c28a2a0003d48345aa44121352659dfb76c03b773d2ea153088306a1c7971177357224335ef293725c988742831aa40981183bc51e981aa30bece171962fc3b8e4ec2b3f5351a607cde081bc4989c17e4181577e3b&X-Goog-SignedHeaders=host&X-User=2931823730: HTTPSConnectionPool(host='storage.googleapis.com', port=443): Max retries exceeded with url: /wandb-production.appspot.com/2931823730-harbin-institute-of-technology/ltu-as/2p8m9dwe/output.log?X-Goog-Algorithm=GOOG4-RSA-SHA256&X-Goog-Credential=gorilla-files-url-signer-man%40wandb-production.iam.gserviceaccount.com%2F20250411%2Fauto%2Fstorage%2Fgoog4_request&X-Goog-Date=20250411T151314Z&X-Goog-Expires=86399&X-Goog-Signature=c44716d15ea1c964086d12ca01197c8ce47394f84080ef2ac590732ab708d2de7ce5088a8dca5fff495f540400d7d9b1a33c277aa3ccacc835e260daadaa862ab277c9696b93258cd56a8316dfce8e36fa696f08f5ccb6508ad7eb9eef52ab7be3706ef92a52379cf3fbd94a8440c357a965492d496dd36a42cee1bacf58cb62b67f2717f8f904593a8b13fa947081c7e88f242c8e2f8f146a7201227a09cfb23de21fdce4ad87a30d7dc7c28a2a0003d48345aa44121352659dfb76c03b773d2ea153088306a1c7971177357224335ef293725c988742831aa40981183bc51e981aa30bece171962fc3b8e4ec2b3f5351a607cde081bc4989c17e4181577e3b&X-Goog-SignedHeaders=host&X-User=2931823730 (Caused by NewConnectionError('<urllib3.connection.HTTPSConnection object at 0x7fcd90150460>: Failed to establish a new connection: [Errno 101] Network is unreachable'))
2025-04-11 15:13:14,615 ERROR   wandb-upload_4:23351 [internal_api.py:upload_file():2558] upload_file request headers: {'User-Agent': 'python-requests/2.32.3', 'Accept-Encoding': 'gzip, deflate, br', 'Accept': '*/*', 'Connection': 'keep-alive', 'Content-Length': '4566'}
2025-04-11 15:13:14,615 ERROR   wandb-upload_4:23351 [internal_api.py:upload_file():2560] upload_file response body: 
2025-04-11 15:13:14,616 ERROR   wandb-upload_3:23351 [internal_api.py:upload_file():2556] upload_file exception https://storage.googleapis.com/wandb-production.appspot.com/2931823730-harbin-institute-of-technology/ltu-as/2p8m9dwe/conda-environment.yaml?X-Goog-Algorithm=GOOG4-RSA-SHA256&X-Goog-Credential=gorilla-files-url-signer-man%40wandb-production.iam.gserviceaccount.com%2F20250411%2Fauto%2Fstorage%2Fgoog4_request&X-Goog-Date=20250411T151314Z&X-Goog-Expires=86399&X-Goog-Signature=7bccffe4b07a3cf7a72c89a7f9ce9c4d318e83ce8565b48d1c8f6ad1e28f0ebcdffbee0466a5b02680abb5917671b4a58a7489d0f31f20b248c65bd0c9f930a4644b19cc67ee38174f54216aa249142b3c30c57a2162d76288e12d623bc786f0e3bd70267e2f8b8b1f5fa86a79cd8d97967dbffbd58e690e13bcac89903c53b61dbb15aa9ec0292990c028cd3f04bee5811a98d7e05760e37f63577946aa5dad22ec10f762d7c7411768b61b1c77b04e59a142df620d4b91315c0493f25f0606e8c9fea31d10992830c7f64dcdb4e3fc94fe26697cc4229457f7aaf42229b62f52420cfe16878dd02e161d04f3bc30ec2bbed1840417b715e0c8fdf9316f1160&X-Goog-SignedHeaders=host&X-User=2931823730: HTTPSConnectionPool(host='storage.googleapis.com', port=443): Max retries exceeded with url: /wandb-production.appspot.com/2931823730-harbin-institute-of-technology/ltu-as/2p8m9dwe/conda-environment.yaml?X-Goog-Algorithm=GOOG4-RSA-SHA256&X-Goog-Credential=gorilla-files-url-signer-man%40wandb-production.iam.gserviceaccount.com%2F20250411%2Fauto%2Fstorage%2Fgoog4_request&X-Goog-Date=20250411T151314Z&X-Goog-Expires=86399&X-Goog-Signature=7bccffe4b07a3cf7a72c89a7f9ce9c4d318e83ce8565b48d1c8f6ad1e28f0ebcdffbee0466a5b02680abb5917671b4a58a7489d0f31f20b248c65bd0c9f930a4644b19cc67ee38174f54216aa249142b3c30c57a2162d76288e12d623bc786f0e3bd70267e2f8b8b1f5fa86a79cd8d97967dbffbd58e690e13bcac89903c53b61dbb15aa9ec0292990c028cd3f04bee5811a98d7e05760e37f63577946aa5dad22ec10f762d7c7411768b61b1c77b04e59a142df620d4b91315c0493f25f0606e8c9fea31d10992830c7f64dcdb4e3fc94fe26697cc4229457f7aaf42229b62f52420cfe16878dd02e161d04f3bc30ec2bbed1840417b715e0c8fdf9316f1160&X-Goog-SignedHeaders=host&X-User=2931823730 (Caused by NewConnectionError('<urllib3.connection.HTTPSConnection object at 0x7fcd90152710>: Failed to establish a new connection: [Errno 101] Network is unreachable'))
2025-04-11 15:13:14,616 ERROR   wandb-upload_3:23351 [internal_api.py:upload_file():2558] upload_file request headers: {'User-Agent': 'python-requests/2.32.3', 'Accept-Encoding': 'gzip, deflate, br', 'Accept': '*/*', 'Connection': 'keep-alive', 'Content-Length': '8281'}
2025-04-11 15:13:14,616 ERROR   wandb-upload_3:23351 [internal_api.py:upload_file():2560] upload_file response body: 
2025-04-11 15:13:14,630 ERROR   wandb-upload_5:23351 [internal_api.py:upload_file():2556] upload_file exception https://storage.googleapis.com/wandb-production.appspot.com/2931823730-harbin-institute-of-technology/ltu-as/2p8m9dwe/wandb-summary.json?X-Goog-Algorithm=GOOG4-RSA-SHA256&X-Goog-Credential=gorilla-files-url-signer-man%40wandb-production.iam.gserviceaccount.com%2F20250411%2Fauto%2Fstorage%2Fgoog4_request&X-Goog-Date=20250411T151314Z&X-Goog-Expires=86399&X-Goog-Signature=162b1e62deff7d3bad6004d3a39fdd84d0fb4788bdb8d01e0c9d67b6f7e728dcaea0cb69e08f91b69ed9b3ce33d56cc666da669ae6d0068246f6cfe4df6689494f83127a4e56dd1b441f107582348c20736d718f639c3a8d2bd9e625f42df04e9a9ed9ad2fc866f745d4f7f306562fe7caea0762bbcedcf2c997fcd631267f1f83aaa2c4a9a761d30d4e984f6072578157b87f3fcc47208dc31c3b3e3ac49acb79d5bb7979b389efcdee835c5d0824ea8d052021f53bde71af985a8540e33c788536fdf534fa19fbf6bacb0b506b1cb2c12a920d6c96bb96b6439ba7ab027e872a2d722014ee899f60088eaf28b44252c2e639ebb1bcf3709757d2dbb87847a2&X-Goog-SignedHeaders=host&X-User=2931823730: HTTPSConnectionPool(host='storage.googleapis.com', port=443): Max retries exceeded with url: /wandb-production.appspot.com/2931823730-harbin-institute-of-technology/ltu-as/2p8m9dwe/wandb-summary.json?X-Goog-Algorithm=GOOG4-RSA-SHA256&X-Goog-Credential=gorilla-files-url-signer-man%40wandb-production.iam.gserviceaccount.com%2F20250411%2Fauto%2Fstorage%2Fgoog4_request&X-Goog-Date=20250411T151314Z&X-Goog-Expires=86399&X-Goog-Signature=162b1e62deff7d3bad6004d3a39fdd84d0fb4788bdb8d01e0c9d67b6f7e728dcaea0cb69e08f91b69ed9b3ce33d56cc666da669ae6d0068246f6cfe4df6689494f83127a4e56dd1b441f107582348c20736d718f639c3a8d2bd9e625f42df04e9a9ed9ad2fc866f745d4f7f306562fe7caea0762bbcedcf2c997fcd631267f1f83aaa2c4a9a761d30d4e984f6072578157b87f3fcc47208dc31c3b3e3ac49acb79d5bb7979b389efcdee835c5d0824ea8d052021f53bde71af985a8540e33c788536fdf534fa19fbf6bacb0b506b1cb2c12a920d6c96bb96b6439ba7ab027e872a2d722014ee899f60088eaf28b44252c2e639ebb1bcf3709757d2dbb87847a2&X-Goog-SignedHeaders=host&X-User=2931823730 (Caused by NewConnectionError('<urllib3.connection.HTTPSConnection object at 0x7fcd90152530>: Failed to establish a new connection: [Errno 101] Network is unreachable'))
2025-04-11 15:13:14,630 ERROR   wandb-upload_5:23351 [internal_api.py:upload_file():2558] upload_file request headers: {'User-Agent': 'python-requests/2.32.3', 'Accept-Encoding': 'gzip, deflate, br', 'Accept': '*/*', 'Connection': 'keep-alive', 'Content-Length': '27'}
2025-04-11 15:13:14,630 ERROR   wandb-upload_5:23351 [internal_api.py:upload_file():2560] upload_file response body: 
2025-04-11 15:13:15,553 DEBUG   HandlerThread:23351 [handler.py:handle_request():146] handle_request: poll_exit
2025-04-11 15:13:15,554 DEBUG   SenderThread:23351 [sender.py:send_request():407] send_request: poll_exit
2025-04-11 15:13:15,583 ERROR   wandb-upload_2:23351 [internal_api.py:upload_file():2556] upload_file exception https://storage.googleapis.com/wandb-production.appspot.com/2931823730-harbin-institute-of-technology/ltu-as/2p8m9dwe/requirements.txt?X-Goog-Algorithm=GOOG4-RSA-SHA256&X-Goog-Credential=gorilla-files-url-signer-man%40wandb-production.iam.gserviceaccount.com%2F20250411%2Fauto%2Fstorage%2Fgoog4_request&X-Goog-Date=20250411T151314Z&X-Goog-Expires=86399&X-Goog-Signature=596e10f29ae2cec75cbb1a5c0879360376523a72f892408b062c1c8ebab215b4abbad1df8da6bec541c89de6deec2c6eb2b6da8b279a8f2bf743c49dea4bc7e6e3ae10f36daa45d6c2e3fac141e6b670687c7233fa8373b04b2f2ded936d143be1302daec292448420869529e939bed8801a5287777bec29a946e96cd575116736d582b1f707a977a956003d465137e9d8705e50cad2a5d9a9bcb34fc432d91d692f7909aee691cef6f89d2eabdc170595373f228cb4586119d828afa412185bca4dcc7d703d9b2be5d7e28fb510bf2f95fcb6854a59c4d660327bd409ac87373f31aa2e1ff0ef593ee31c3901719e0db1cd03a2427023741ffddaec48f48a33&X-Goog-SignedHeaders=host&X-User=2931823730: HTTPSConnectionPool(host='storage.googleapis.com', port=443): Max retries exceeded with url: /wandb-production.appspot.com/2931823730-harbin-institute-of-technology/ltu-as/2p8m9dwe/requirements.txt?X-Goog-Algorithm=GOOG4-RSA-SHA256&X-Goog-Credential=gorilla-files-url-signer-man%40wandb-production.iam.gserviceaccount.com%2F20250411%2Fauto%2Fstorage%2Fgoog4_request&X-Goog-Date=20250411T151314Z&X-Goog-Expires=86399&X-Goog-Signature=596e10f29ae2cec75cbb1a5c0879360376523a72f892408b062c1c8ebab215b4abbad1df8da6bec541c89de6deec2c6eb2b6da8b279a8f2bf743c49dea4bc7e6e3ae10f36daa45d6c2e3fac141e6b670687c7233fa8373b04b2f2ded936d143be1302daec292448420869529e939bed8801a5287777bec29a946e96cd575116736d582b1f707a977a956003d465137e9d8705e50cad2a5d9a9bcb34fc432d91d692f7909aee691cef6f89d2eabdc170595373f228cb4586119d828afa412185bca4dcc7d703d9b2be5d7e28fb510bf2f95fcb6854a59c4d660327bd409ac87373f31aa2e1ff0ef593ee31c3901719e0db1cd03a2427023741ffddaec48f48a33&X-Goog-SignedHeaders=host&X-User=2931823730 (Caused by NewConnectionError('<urllib3.connection.HTTPSConnection object at 0x7fcd785769b0>: Failed to establish a new connection: [Errno 101] Network is unreachable'))
2025-04-11 15:13:15,584 ERROR   wandb-upload_2:23351 [internal_api.py:upload_file():2558] upload_file request headers: {'User-Agent': 'python-requests/2.32.3', 'Accept-Encoding': 'gzip, deflate, br', 'Accept': '*/*', 'Connection': 'keep-alive', 'Content-Length': '4212'}
2025-04-11 15:13:15,584 ERROR   wandb-upload_2:23351 [internal_api.py:upload_file():2560] upload_file response body: 
2025-04-11 15:13:15,662 ERROR   wandb-upload_1:23351 [internal_api.py:upload_file():2556] upload_file exception https://storage.googleapis.com/wandb-production.appspot.com/2931823730-harbin-institute-of-technology/ltu-as/2p8m9dwe/config.yaml?X-Goog-Algorithm=GOOG4-RSA-SHA256&X-Goog-Credential=gorilla-files-url-signer-man%40wandb-production.iam.gserviceaccount.com%2F20250411%2Fauto%2Fstorage%2Fgoog4_request&X-Goog-Date=20250411T151314Z&X-Goog-Expires=86399&X-Goog-Signature=c3f1c581a0bd73c6399672f1fac440187a0b07669ff4825ee30bf5e058c5a683d85c7b6a22215e3bb850b742c0d89df501576ca1866fd5534cc3429d481eba7e8d4f973e12d002b083ebdafce4bc036f519523a270ba6868dfa5551a4dacda47e4863088e75c0f9dd7ef57f5509215ac52373490cdb269dceabdf696d0c1b874b77f6e0064f27f0acc826c3bf3755682d9d80d1c2829fc57effdb94af0f0693ef6bbbf1e906d59b08d2ac9d8d8617261eea7f087f6d696d308a005cdbb07089b88ec998a31608527466034e5d8e1c405536f34bec132780342d5f14d57109d149db8d09c9a4b2d71228d28d56b512091008f600490c271953244785eda190976&X-Goog-SignedHeaders=host&X-User=2931823730: HTTPSConnectionPool(host='storage.googleapis.com', port=443): Max retries exceeded with url: /wandb-production.appspot.com/2931823730-harbin-institute-of-technology/ltu-as/2p8m9dwe/config.yaml?X-Goog-Algorithm=GOOG4-RSA-SHA256&X-Goog-Credential=gorilla-files-url-signer-man%40wandb-production.iam.gserviceaccount.com%2F20250411%2Fauto%2Fstorage%2Fgoog4_request&X-Goog-Date=20250411T151314Z&X-Goog-Expires=86399&X-Goog-Signature=c3f1c581a0bd73c6399672f1fac440187a0b07669ff4825ee30bf5e058c5a683d85c7b6a22215e3bb850b742c0d89df501576ca1866fd5534cc3429d481eba7e8d4f973e12d002b083ebdafce4bc036f519523a270ba6868dfa5551a4dacda47e4863088e75c0f9dd7ef57f5509215ac52373490cdb269dceabdf696d0c1b874b77f6e0064f27f0acc826c3bf3755682d9d80d1c2829fc57effdb94af0f0693ef6bbbf1e906d59b08d2ac9d8d8617261eea7f087f6d696d308a005cdbb07089b88ec998a31608527466034e5d8e1c405536f34bec132780342d5f14d57109d149db8d09c9a4b2d71228d28d56b512091008f600490c271953244785eda190976&X-Goog-SignedHeaders=host&X-User=2931823730 (Caused by NewConnectionError('<urllib3.connection.HTTPSConnection object at 0x7fcd78576d10>: Failed to establish a new connection: [Errno 101] Network is unreachable'))
2025-04-11 15:13:15,662 ERROR   wandb-upload_1:23351 [internal_api.py:upload_file():2558] upload_file request headers: {'User-Agent': 'python-requests/2.32.3', 'Accept-Encoding': 'gzip, deflate, br', 'Accept': '*/*', 'Connection': 'keep-alive', 'Content-Length': '8685'}
2025-04-11 15:13:15,662 ERROR   wandb-upload_1:23351 [internal_api.py:upload_file():2560] upload_file response body: 
2025-04-11 15:13:15,663 INFO    wandb-upload_1:23351 [retry.py:__call__():172] Retry attempt failed:
Traceback (most recent call last):
  File "/root/anaconda3/envs/venv_ltu/lib/python3.10/site-packages/urllib3/connection.py", line 198, in _new_conn
    sock = connection.create_connection(
  File "/root/anaconda3/envs/venv_ltu/lib/python3.10/site-packages/urllib3/util/connection.py", line 85, in create_connection
    raise err
  File "/root/anaconda3/envs/venv_ltu/lib/python3.10/site-packages/urllib3/util/connection.py", line 73, in create_connection
    sock.connect(sa)
OSError: [Errno 101] Network is unreachable

The above exception was the direct cause of the following exception:

Traceback (most recent call last):
  File "/root/anaconda3/envs/venv_ltu/lib/python3.10/site-packages/urllib3/connectionpool.py", line 793, in urlopen
    response = self._make_request(
  File "/root/anaconda3/envs/venv_ltu/lib/python3.10/site-packages/urllib3/connectionpool.py", line 491, in _make_request
    raise new_e
  File "/root/anaconda3/envs/venv_ltu/lib/python3.10/site-packages/urllib3/connectionpool.py", line 467, in _make_request
    self._validate_conn(conn)
  File "/root/anaconda3/envs/venv_ltu/lib/python3.10/site-packages/urllib3/connectionpool.py", line 1099, in _validate_conn
    conn.connect()
  File "/root/anaconda3/envs/venv_ltu/lib/python3.10/site-packages/urllib3/connection.py", line 616, in connect
    self.sock = sock = self._new_conn()
  File "/root/anaconda3/envs/venv_ltu/lib/python3.10/site-packages/urllib3/connection.py", line 213, in _new_conn
    raise NewConnectionError(
urllib3.exceptions.NewConnectionError: <urllib3.connection.HTTPSConnection object at 0x7fcd78576d10>: Failed to establish a new connection: [Errno 101] Network is unreachable

The above exception was the direct cause of the following exception:

Traceback (most recent call last):
  File "/root/anaconda3/envs/venv_ltu/lib/python3.10/site-packages/requests/adapters.py", line 667, in send
    resp = conn.urlopen(
  File "/root/anaconda3/envs/venv_ltu/lib/python3.10/site-packages/urllib3/connectionpool.py", line 847, in urlopen
    retries = retries.increment(
  File "/root/anaconda3/envs/venv_ltu/lib/python3.10/site-packages/urllib3/util/retry.py", line 515, in increment
    raise MaxRetryError(_pool, url, reason) from reason  # type: ignore[arg-type]
urllib3.exceptions.MaxRetryError: HTTPSConnectionPool(host='storage.googleapis.com', port=443): Max retries exceeded with url: /wandb-production.appspot.com/2931823730-harbin-institute-of-technology/ltu-as/2p8m9dwe/config.yaml?X-Goog-Algorithm=GOOG4-RSA-SHA256&X-Goog-Credential=gorilla-files-url-signer-man%40wandb-production.iam.gserviceaccount.com%2F20250411%2Fauto%2Fstorage%2Fgoog4_request&X-Goog-Date=20250411T151314Z&X-Goog-Expires=86399&X-Goog-Signature=c3f1c581a0bd73c6399672f1fac440187a0b07669ff4825ee30bf5e058c5a683d85c7b6a22215e3bb850b742c0d89df501576ca1866fd5534cc3429d481eba7e8d4f973e12d002b083ebdafce4bc036f519523a270ba6868dfa5551a4dacda47e4863088e75c0f9dd7ef57f5509215ac52373490cdb269dceabdf696d0c1b874b77f6e0064f27f0acc826c3bf3755682d9d80d1c2829fc57effdb94af0f0693ef6bbbf1e906d59b08d2ac9d8d8617261eea7f087f6d696d308a005cdbb07089b88ec998a31608527466034e5d8e1c405536f34bec132780342d5f14d57109d149db8d09c9a4b2d71228d28d56b512091008f600490c271953244785eda190976&X-Goog-SignedHeaders=host&X-User=2931823730 (Caused by NewConnectionError('<urllib3.connection.HTTPSConnection object at 0x7fcd78576d10>: Failed to establish a new connection: [Errno 101] Network is unreachable'))

During handling of the above exception, another exception occurred:

Traceback (most recent call last):
  File "/root/anaconda3/envs/venv_ltu/lib/python3.10/site-packages/wandb/sdk/internal/internal_api.py", line 2549, in upload_file
    response = self._upload_file_session.put(
  File "/root/anaconda3/envs/venv_ltu/lib/python3.10/site-packages/requests/sessions.py", line 649, in put
    return self.request("PUT", url, data=data, **kwargs)
  File "/root/anaconda3/envs/venv_ltu/lib/python3.10/site-packages/requests/sessions.py", line 589, in request
    resp = self.send(prep, **send_kwargs)
  File "/root/anaconda3/envs/venv_ltu/lib/python3.10/site-packages/requests/sessions.py", line 703, in send
    r = adapter.send(request, **kwargs)
  File "/root/anaconda3/envs/venv_ltu/lib/python3.10/site-packages/requests/adapters.py", line 700, in send
    raise ConnectionError(e, request=request)
requests.exceptions.ConnectionError: HTTPSConnectionPool(host='storage.googleapis.com', port=443): Max retries exceeded with url: /wandb-production.appspot.com/2931823730-harbin-institute-of-technology/ltu-as/2p8m9dwe/config.yaml?X-Goog-Algorithm=GOOG4-RSA-SHA256&X-Goog-Credential=gorilla-files-url-signer-man%40wandb-production.iam.gserviceaccount.com%2F20250411%2Fauto%2Fstorage%2Fgoog4_request&X-Goog-Date=20250411T151314Z&X-Goog-Expires=86399&X-Goog-Signature=c3f1c581a0bd73c6399672f1fac440187a0b07669ff4825ee30bf5e058c5a683d85c7b6a22215e3bb850b742c0d89df501576ca1866fd5534cc3429d481eba7e8d4f973e12d002b083ebdafce4bc036f519523a270ba6868dfa5551a4dacda47e4863088e75c0f9dd7ef57f5509215ac52373490cdb269dceabdf696d0c1b874b77f6e0064f27f0acc826c3bf3755682d9d80d1c2829fc57effdb94af0f0693ef6bbbf1e906d59b08d2ac9d8d8617261eea7f087f6d696d308a005cdbb07089b88ec998a31608527466034e5d8e1c405536f34bec132780342d5f14d57109d149db8d09c9a4b2d71228d28d56b512091008f600490c271953244785eda190976&X-Goog-SignedHeaders=host&X-User=2931823730 (Caused by NewConnectionError('<urllib3.connection.HTTPSConnection object at 0x7fcd78576d10>: Failed to establish a new connection: [Errno 101] Network is unreachable'))

During handling of the above exception, another exception occurred:

Traceback (most recent call last):
  File "/root/anaconda3/envs/venv_ltu/lib/python3.10/site-packages/wandb/sdk/lib/retry.py", line 131, in __call__
    result = self._call_fn(*args, **kwargs)
  File "/root/anaconda3/envs/venv_ltu/lib/python3.10/site-packages/wandb/sdk/internal/internal_api.py", line 2580, in upload_file
    raise _e.with_traceback(sys.exc_info()[2])
  File "/root/anaconda3/envs/venv_ltu/lib/python3.10/site-packages/wandb/sdk/internal/internal_api.py", line 2549, in upload_file
    response = self._upload_file_session.put(
  File "/root/anaconda3/envs/venv_ltu/lib/python3.10/site-packages/requests/sessions.py", line 649, in put
    return self.request("PUT", url, data=data, **kwargs)
  File "/root/anaconda3/envs/venv_ltu/lib/python3.10/site-packages/requests/sessions.py", line 589, in request
    resp = self.send(prep, **send_kwargs)
  File "/root/anaconda3/envs/venv_ltu/lib/python3.10/site-packages/requests/sessions.py", line 703, in send
    r = adapter.send(request, **kwargs)
  File "/root/anaconda3/envs/venv_ltu/lib/python3.10/site-packages/requests/adapters.py", line 700, in send
    raise ConnectionError(e, request=request)
wandb.sdk.lib.retry.TransientError: None
2025-04-11 15:13:15,684 ERROR   wandb-upload_4:23351 [internal_api.py:upload_file():2556] upload_file exception https://storage.googleapis.com/wandb-production.appspot.com/2931823730-harbin-institute-of-technology/ltu-as/2p8m9dwe/output.log?X-Goog-Algorithm=GOOG4-RSA-SHA256&X-Goog-Credential=gorilla-files-url-signer-man%40wandb-production.iam.gserviceaccount.com%2F20250411%2Fauto%2Fstorage%2Fgoog4_request&X-Goog-Date=20250411T151314Z&X-Goog-Expires=86399&X-Goog-Signature=c44716d15ea1c964086d12ca01197c8ce47394f84080ef2ac590732ab708d2de7ce5088a8dca5fff495f540400d7d9b1a33c277aa3ccacc835e260daadaa862ab277c9696b93258cd56a8316dfce8e36fa696f08f5ccb6508ad7eb9eef52ab7be3706ef92a52379cf3fbd94a8440c357a965492d496dd36a42cee1bacf58cb62b67f2717f8f904593a8b13fa947081c7e88f242c8e2f8f146a7201227a09cfb23de21fdce4ad87a30d7dc7c28a2a0003d48345aa44121352659dfb76c03b773d2ea153088306a1c7971177357224335ef293725c988742831aa40981183bc51e981aa30bece171962fc3b8e4ec2b3f5351a607cde081bc4989c17e4181577e3b&X-Goog-SignedHeaders=host&X-User=2931823730: HTTPSConnectionPool(host='storage.googleapis.com', port=443): Max retries exceeded with url: /wandb-production.appspot.com/2931823730-harbin-institute-of-technology/ltu-as/2p8m9dwe/output.log?X-Goog-Algorithm=GOOG4-RSA-SHA256&X-Goog-Credential=gorilla-files-url-signer-man%40wandb-production.iam.gserviceaccount.com%2F20250411%2Fauto%2Fstorage%2Fgoog4_request&X-Goog-Date=20250411T151314Z&X-Goog-Expires=86399&X-Goog-Signature=c44716d15ea1c964086d12ca01197c8ce47394f84080ef2ac590732ab708d2de7ce5088a8dca5fff495f540400d7d9b1a33c277aa3ccacc835e260daadaa862ab277c9696b93258cd56a8316dfce8e36fa696f08f5ccb6508ad7eb9eef52ab7be3706ef92a52379cf3fbd94a8440c357a965492d496dd36a42cee1bacf58cb62b67f2717f8f904593a8b13fa947081c7e88f242c8e2f8f146a7201227a09cfb23de21fdce4ad87a30d7dc7c28a2a0003d48345aa44121352659dfb76c03b773d2ea153088306a1c7971177357224335ef293725c988742831aa40981183bc51e981aa30bece171962fc3b8e4ec2b3f5351a607cde081bc4989c17e4181577e3b&X-Goog-SignedHeaders=host&X-User=2931823730 (Caused by NewConnectionError('<urllib3.connection.HTTPSConnection object at 0x7fcd78577460>: Failed to establish a new connection: [Errno 101] Network is unreachable'))
2025-04-11 15:13:15,685 ERROR   wandb-upload_4:23351 [internal_api.py:upload_file():2558] upload_file request headers: {'User-Agent': 'python-requests/2.32.3', 'Accept-Encoding': 'gzip, deflate, br', 'Accept': '*/*', 'Connection': 'keep-alive', 'Content-Length': '4566'}
2025-04-11 15:13:15,685 ERROR   wandb-upload_4:23351 [internal_api.py:upload_file():2560] upload_file response body: 
2025-04-11 15:13:15,834 ERROR   wandb-upload_3:23351 [internal_api.py:upload_file():2556] upload_file exception https://storage.googleapis.com/wandb-production.appspot.com/2931823730-harbin-institute-of-technology/ltu-as/2p8m9dwe/conda-environment.yaml?X-Goog-Algorithm=GOOG4-RSA-SHA256&X-Goog-Credential=gorilla-files-url-signer-man%40wandb-production.iam.gserviceaccount.com%2F20250411%2Fauto%2Fstorage%2Fgoog4_request&X-Goog-Date=20250411T151314Z&X-Goog-Expires=86399&X-Goog-Signature=7bccffe4b07a3cf7a72c89a7f9ce9c4d318e83ce8565b48d1c8f6ad1e28f0ebcdffbee0466a5b02680abb5917671b4a58a7489d0f31f20b248c65bd0c9f930a4644b19cc67ee38174f54216aa249142b3c30c57a2162d76288e12d623bc786f0e3bd70267e2f8b8b1f5fa86a79cd8d97967dbffbd58e690e13bcac89903c53b61dbb15aa9ec0292990c028cd3f04bee5811a98d7e05760e37f63577946aa5dad22ec10f762d7c7411768b61b1c77b04e59a142df620d4b91315c0493f25f0606e8c9fea31d10992830c7f64dcdb4e3fc94fe26697cc4229457f7aaf42229b62f52420cfe16878dd02e161d04f3bc30ec2bbed1840417b715e0c8fdf9316f1160&X-Goog-SignedHeaders=host&X-User=2931823730: HTTPSConnectionPool(host='storage.googleapis.com', port=443): Max retries exceeded with url: /wandb-production.appspot.com/2931823730-harbin-institute-of-technology/ltu-as/2p8m9dwe/conda-environment.yaml?X-Goog-Algorithm=GOOG4-RSA-SHA256&X-Goog-Credential=gorilla-files-url-signer-man%40wandb-production.iam.gserviceaccount.com%2F20250411%2Fauto%2Fstorage%2Fgoog4_request&X-Goog-Date=20250411T151314Z&X-Goog-Expires=86399&X-Goog-Signature=7bccffe4b07a3cf7a72c89a7f9ce9c4d318e83ce8565b48d1c8f6ad1e28f0ebcdffbee0466a5b02680abb5917671b4a58a7489d0f31f20b248c65bd0c9f930a4644b19cc67ee38174f54216aa249142b3c30c57a2162d76288e12d623bc786f0e3bd70267e2f8b8b1f5fa86a79cd8d97967dbffbd58e690e13bcac89903c53b61dbb15aa9ec0292990c028cd3f04bee5811a98d7e05760e37f63577946aa5dad22ec10f762d7c7411768b61b1c77b04e59a142df620d4b91315c0493f25f0606e8c9fea31d10992830c7f64dcdb4e3fc94fe26697cc4229457f7aaf42229b62f52420cfe16878dd02e161d04f3bc30ec2bbed1840417b715e0c8fdf9316f1160&X-Goog-SignedHeaders=host&X-User=2931823730 (Caused by NewConnectionError('<urllib3.connection.HTTPSConnection object at 0x7fcd78576290>: Failed to establish a new connection: [Errno 101] Network is unreachable'))
2025-04-11 15:13:15,834 ERROR   wandb-upload_3:23351 [internal_api.py:upload_file():2558] upload_file request headers: {'User-Agent': 'python-requests/2.32.3', 'Accept-Encoding': 'gzip, deflate, br', 'Accept': '*/*', 'Connection': 'keep-alive', 'Content-Length': '8281'}
2025-04-11 15:13:15,834 ERROR   wandb-upload_3:23351 [internal_api.py:upload_file():2560] upload_file response body: 
2025-04-11 15:13:15,839 ERROR   wandb-upload_5:23351 [internal_api.py:upload_file():2556] upload_file exception https://storage.googleapis.com/wandb-production.appspot.com/2931823730-harbin-institute-of-technology/ltu-as/2p8m9dwe/wandb-summary.json?X-Goog-Algorithm=GOOG4-RSA-SHA256&X-Goog-Credential=gorilla-files-url-signer-man%40wandb-production.iam.gserviceaccount.com%2F20250411%2Fauto%2Fstorage%2Fgoog4_request&X-Goog-Date=20250411T151314Z&X-Goog-Expires=86399&X-Goog-Signature=162b1e62deff7d3bad6004d3a39fdd84d0fb4788bdb8d01e0c9d67b6f7e728dcaea0cb69e08f91b69ed9b3ce33d56cc666da669ae6d0068246f6cfe4df6689494f83127a4e56dd1b441f107582348c20736d718f639c3a8d2bd9e625f42df04e9a9ed9ad2fc866f745d4f7f306562fe7caea0762bbcedcf2c997fcd631267f1f83aaa2c4a9a761d30d4e984f6072578157b87f3fcc47208dc31c3b3e3ac49acb79d5bb7979b389efcdee835c5d0824ea8d052021f53bde71af985a8540e33c788536fdf534fa19fbf6bacb0b506b1cb2c12a920d6c96bb96b6439ba7ab027e872a2d722014ee899f60088eaf28b44252c2e639ebb1bcf3709757d2dbb87847a2&X-Goog-SignedHeaders=host&X-User=2931823730: HTTPSConnectionPool(host='storage.googleapis.com', port=443): Max retries exceeded with url: /wandb-production.appspot.com/2931823730-harbin-institute-of-technology/ltu-as/2p8m9dwe/wandb-summary.json?X-Goog-Algorithm=GOOG4-RSA-SHA256&X-Goog-Credential=gorilla-files-url-signer-man%40wandb-production.iam.gserviceaccount.com%2F20250411%2Fauto%2Fstorage%2Fgoog4_request&X-Goog-Date=20250411T151314Z&X-Goog-Expires=86399&X-Goog-Signature=162b1e62deff7d3bad6004d3a39fdd84d0fb4788bdb8d01e0c9d67b6f7e728dcaea0cb69e08f91b69ed9b3ce33d56cc666da669ae6d0068246f6cfe4df6689494f83127a4e56dd1b441f107582348c20736d718f639c3a8d2bd9e625f42df04e9a9ed9ad2fc866f745d4f7f306562fe7caea0762bbcedcf2c997fcd631267f1f83aaa2c4a9a761d30d4e984f6072578157b87f3fcc47208dc31c3b3e3ac49acb79d5bb7979b389efcdee835c5d0824ea8d052021f53bde71af985a8540e33c788536fdf534fa19fbf6bacb0b506b1cb2c12a920d6c96bb96b6439ba7ab027e872a2d722014ee899f60088eaf28b44252c2e639ebb1bcf3709757d2dbb87847a2&X-Goog-SignedHeaders=host&X-User=2931823730 (Caused by NewConnectionError('<urllib3.connection.HTTPSConnection object at 0x7fcd78575390>: Failed to establish a new connection: [Errno 101] Network is unreachable'))
2025-04-11 15:13:15,839 ERROR   wandb-upload_5:23351 [internal_api.py:upload_file():2558] upload_file request headers: {'User-Agent': 'python-requests/2.32.3', 'Accept-Encoding': 'gzip, deflate, br', 'Accept': '*/*', 'Connection': 'keep-alive', 'Content-Length': '27'}
2025-04-11 15:13:15,839 ERROR   wandb-upload_5:23351 [internal_api.py:upload_file():2560] upload_file response body: 
2025-04-11 15:13:16,555 DEBUG   HandlerThread:23351 [handler.py:handle_request():146] handle_request: poll_exit
2025-04-11 15:13:16,555 DEBUG   SenderThread:23351 [sender.py:send_request():407] send_request: poll_exit
2025-04-11 15:13:17,556 DEBUG   HandlerThread:23351 [handler.py:handle_request():146] handle_request: poll_exit
2025-04-11 15:13:17,558 DEBUG   SenderThread:23351 [sender.py:send_request():407] send_request: poll_exit
2025-04-11 15:13:17,746 ERROR   wandb-upload_1:23351 [internal_api.py:upload_file():2556] upload_file exception https://storage.googleapis.com/wandb-production.appspot.com/2931823730-harbin-institute-of-technology/ltu-as/2p8m9dwe/config.yaml?X-Goog-Algorithm=GOOG4-RSA-SHA256&X-Goog-Credential=gorilla-files-url-signer-man%40wandb-production.iam.gserviceaccount.com%2F20250411%2Fauto%2Fstorage%2Fgoog4_request&X-Goog-Date=20250411T151314Z&X-Goog-Expires=86399&X-Goog-Signature=c3f1c581a0bd73c6399672f1fac440187a0b07669ff4825ee30bf5e058c5a683d85c7b6a22215e3bb850b742c0d89df501576ca1866fd5534cc3429d481eba7e8d4f973e12d002b083ebdafce4bc036f519523a270ba6868dfa5551a4dacda47e4863088e75c0f9dd7ef57f5509215ac52373490cdb269dceabdf696d0c1b874b77f6e0064f27f0acc826c3bf3755682d9d80d1c2829fc57effdb94af0f0693ef6bbbf1e906d59b08d2ac9d8d8617261eea7f087f6d696d308a005cdbb07089b88ec998a31608527466034e5d8e1c405536f34bec132780342d5f14d57109d149db8d09c9a4b2d71228d28d56b512091008f600490c271953244785eda190976&X-Goog-SignedHeaders=host&X-User=2931823730: HTTPSConnectionPool(host='storage.googleapis.com', port=443): Max retries exceeded with url: /wandb-production.appspot.com/2931823730-harbin-institute-of-technology/ltu-as/2p8m9dwe/config.yaml?X-Goog-Algorithm=GOOG4-RSA-SHA256&X-Goog-Credential=gorilla-files-url-signer-man%40wandb-production.iam.gserviceaccount.com%2F20250411%2Fauto%2Fstorage%2Fgoog4_request&X-Goog-Date=20250411T151314Z&X-Goog-Expires=86399&X-Goog-Signature=c3f1c581a0bd73c6399672f1fac440187a0b07669ff4825ee30bf5e058c5a683d85c7b6a22215e3bb850b742c0d89df501576ca1866fd5534cc3429d481eba7e8d4f973e12d002b083ebdafce4bc036f519523a270ba6868dfa5551a4dacda47e4863088e75c0f9dd7ef57f5509215ac52373490cdb269dceabdf696d0c1b874b77f6e0064f27f0acc826c3bf3755682d9d80d1c2829fc57effdb94af0f0693ef6bbbf1e906d59b08d2ac9d8d8617261eea7f087f6d696d308a005cdbb07089b88ec998a31608527466034e5d8e1c405536f34bec132780342d5f14d57109d149db8d09c9a4b2d71228d28d56b512091008f600490c271953244785eda190976&X-Goog-SignedHeaders=host&X-User=2931823730 (Caused by NewConnectionError('<urllib3.connection.HTTPSConnection object at 0x7fcd78574b50>: Failed to establish a new connection: [Errno 101] Network is unreachable'))
2025-04-11 15:13:17,746 ERROR   wandb-upload_1:23351 [internal_api.py:upload_file():2558] upload_file request headers: {'User-Agent': 'python-requests/2.32.3', 'Accept-Encoding': 'gzip, deflate, br', 'Accept': '*/*', 'Connection': 'keep-alive', 'Content-Length': '8685'}
2025-04-11 15:13:17,746 ERROR   wandb-upload_1:23351 [internal_api.py:upload_file():2560] upload_file response body: 
2025-04-11 15:13:17,757 ERROR   wandb-upload_2:23351 [internal_api.py:upload_file():2556] upload_file exception https://storage.googleapis.com/wandb-production.appspot.com/2931823730-harbin-institute-of-technology/ltu-as/2p8m9dwe/requirements.txt?X-Goog-Algorithm=GOOG4-RSA-SHA256&X-Goog-Credential=gorilla-files-url-signer-man%40wandb-production.iam.gserviceaccount.com%2F20250411%2Fauto%2Fstorage%2Fgoog4_request&X-Goog-Date=20250411T151314Z&X-Goog-Expires=86399&X-Goog-Signature=596e10f29ae2cec75cbb1a5c0879360376523a72f892408b062c1c8ebab215b4abbad1df8da6bec541c89de6deec2c6eb2b6da8b279a8f2bf743c49dea4bc7e6e3ae10f36daa45d6c2e3fac141e6b670687c7233fa8373b04b2f2ded936d143be1302daec292448420869529e939bed8801a5287777bec29a946e96cd575116736d582b1f707a977a956003d465137e9d8705e50cad2a5d9a9bcb34fc432d91d692f7909aee691cef6f89d2eabdc170595373f228cb4586119d828afa412185bca4dcc7d703d9b2be5d7e28fb510bf2f95fcb6854a59c4d660327bd409ac87373f31aa2e1ff0ef593ee31c3901719e0db1cd03a2427023741ffddaec48f48a33&X-Goog-SignedHeaders=host&X-User=2931823730: HTTPSConnectionPool(host='storage.googleapis.com', port=443): Max retries exceeded with url: /wandb-production.appspot.com/2931823730-harbin-institute-of-technology/ltu-as/2p8m9dwe/requirements.txt?X-Goog-Algorithm=GOOG4-RSA-SHA256&X-Goog-Credential=gorilla-files-url-signer-man%40wandb-production.iam.gserviceaccount.com%2F20250411%2Fauto%2Fstorage%2Fgoog4_request&X-Goog-Date=20250411T151314Z&X-Goog-Expires=86399&X-Goog-Signature=596e10f29ae2cec75cbb1a5c0879360376523a72f892408b062c1c8ebab215b4abbad1df8da6bec541c89de6deec2c6eb2b6da8b279a8f2bf743c49dea4bc7e6e3ae10f36daa45d6c2e3fac141e6b670687c7233fa8373b04b2f2ded936d143be1302daec292448420869529e939bed8801a5287777bec29a946e96cd575116736d582b1f707a977a956003d465137e9d8705e50cad2a5d9a9bcb34fc432d91d692f7909aee691cef6f89d2eabdc170595373f228cb4586119d828afa412185bca4dcc7d703d9b2be5d7e28fb510bf2f95fcb6854a59c4d660327bd409ac87373f31aa2e1ff0ef593ee31c3901719e0db1cd03a2427023741ffddaec48f48a33&X-Goog-SignedHeaders=host&X-User=2931823730 (Caused by NewConnectionError('<urllib3.connection.HTTPSConnection object at 0x7fcd78574f70>: Failed to establish a new connection: [Errno 101] Network is unreachable'))
2025-04-11 15:13:17,757 ERROR   wandb-upload_2:23351 [internal_api.py:upload_file():2558] upload_file request headers: {'User-Agent': 'python-requests/2.32.3', 'Accept-Encoding': 'gzip, deflate, br', 'Accept': '*/*', 'Connection': 'keep-alive', 'Content-Length': '4212'}
2025-04-11 15:13:17,757 ERROR   wandb-upload_2:23351 [internal_api.py:upload_file():2560] upload_file response body: 
2025-04-11 15:13:18,120 ERROR   wandb-upload_5:23351 [internal_api.py:upload_file():2556] upload_file exception https://storage.googleapis.com/wandb-production.appspot.com/2931823730-harbin-institute-of-technology/ltu-as/2p8m9dwe/wandb-summary.json?X-Goog-Algorithm=GOOG4-RSA-SHA256&X-Goog-Credential=gorilla-files-url-signer-man%40wandb-production.iam.gserviceaccount.com%2F20250411%2Fauto%2Fstorage%2Fgoog4_request&X-Goog-Date=20250411T151314Z&X-Goog-Expires=86399&X-Goog-Signature=162b1e62deff7d3bad6004d3a39fdd84d0fb4788bdb8d01e0c9d67b6f7e728dcaea0cb69e08f91b69ed9b3ce33d56cc666da669ae6d0068246f6cfe4df6689494f83127a4e56dd1b441f107582348c20736d718f639c3a8d2bd9e625f42df04e9a9ed9ad2fc866f745d4f7f306562fe7caea0762bbcedcf2c997fcd631267f1f83aaa2c4a9a761d30d4e984f6072578157b87f3fcc47208dc31c3b3e3ac49acb79d5bb7979b389efcdee835c5d0824ea8d052021f53bde71af985a8540e33c788536fdf534fa19fbf6bacb0b506b1cb2c12a920d6c96bb96b6439ba7ab027e872a2d722014ee899f60088eaf28b44252c2e639ebb1bcf3709757d2dbb87847a2&X-Goog-SignedHeaders=host&X-User=2931823730: HTTPSConnectionPool(host='storage.googleapis.com', port=443): Max retries exceeded with url: /wandb-production.appspot.com/2931823730-harbin-institute-of-technology/ltu-as/2p8m9dwe/wandb-summary.json?X-Goog-Algorithm=GOOG4-RSA-SHA256&X-Goog-Credential=gorilla-files-url-signer-man%40wandb-production.iam.gserviceaccount.com%2F20250411%2Fauto%2Fstorage%2Fgoog4_request&X-Goog-Date=20250411T151314Z&X-Goog-Expires=86399&X-Goog-Signature=162b1e62deff7d3bad6004d3a39fdd84d0fb4788bdb8d01e0c9d67b6f7e728dcaea0cb69e08f91b69ed9b3ce33d56cc666da669ae6d0068246f6cfe4df6689494f83127a4e56dd1b441f107582348c20736d718f639c3a8d2bd9e625f42df04e9a9ed9ad2fc866f745d4f7f306562fe7caea0762bbcedcf2c997fcd631267f1f83aaa2c4a9a761d30d4e984f6072578157b87f3fcc47208dc31c3b3e3ac49acb79d5bb7979b389efcdee835c5d0824ea8d052021f53bde71af985a8540e33c788536fdf534fa19fbf6bacb0b506b1cb2c12a920d6c96bb96b6439ba7ab027e872a2d722014ee899f60088eaf28b44252c2e639ebb1bcf3709757d2dbb87847a2&X-Goog-SignedHeaders=host&X-User=2931823730 (Caused by NewConnectionError('<urllib3.connection.HTTPSConnection object at 0x7fcd901525c0>: Failed to establish a new connection: [Errno 101] Network is unreachable'))
2025-04-11 15:13:18,120 ERROR   wandb-upload_5:23351 [internal_api.py:upload_file():2558] upload_file request headers: {'User-Agent': 'python-requests/2.32.3', 'Accept-Encoding': 'gzip, deflate, br', 'Accept': '*/*', 'Connection': 'keep-alive', 'Content-Length': '27'}
2025-04-11 15:13:18,121 ERROR   wandb-upload_5:23351 [internal_api.py:upload_file():2560] upload_file response body: 
2025-04-11 15:13:18,164 ERROR   wandb-upload_4:23351 [internal_api.py:upload_file():2556] upload_file exception https://storage.googleapis.com/wandb-production.appspot.com/2931823730-harbin-institute-of-technology/ltu-as/2p8m9dwe/output.log?X-Goog-Algorithm=GOOG4-RSA-SHA256&X-Goog-Credential=gorilla-files-url-signer-man%40wandb-production.iam.gserviceaccount.com%2F20250411%2Fauto%2Fstorage%2Fgoog4_request&X-Goog-Date=20250411T151314Z&X-Goog-Expires=86399&X-Goog-Signature=c44716d15ea1c964086d12ca01197c8ce47394f84080ef2ac590732ab708d2de7ce5088a8dca5fff495f540400d7d9b1a33c277aa3ccacc835e260daadaa862ab277c9696b93258cd56a8316dfce8e36fa696f08f5ccb6508ad7eb9eef52ab7be3706ef92a52379cf3fbd94a8440c357a965492d496dd36a42cee1bacf58cb62b67f2717f8f904593a8b13fa947081c7e88f242c8e2f8f146a7201227a09cfb23de21fdce4ad87a30d7dc7c28a2a0003d48345aa44121352659dfb76c03b773d2ea153088306a1c7971177357224335ef293725c988742831aa40981183bc51e981aa30bece171962fc3b8e4ec2b3f5351a607cde081bc4989c17e4181577e3b&X-Goog-SignedHeaders=host&X-User=2931823730: HTTPSConnectionPool(host='storage.googleapis.com', port=443): Max retries exceeded with url: /wandb-production.appspot.com/2931823730-harbin-institute-of-technology/ltu-as/2p8m9dwe/output.log?X-Goog-Algorithm=GOOG4-RSA-SHA256&X-Goog-Credential=gorilla-files-url-signer-man%40wandb-production.iam.gserviceaccount.com%2F20250411%2Fauto%2Fstorage%2Fgoog4_request&X-Goog-Date=20250411T151314Z&X-Goog-Expires=86399&X-Goog-Signature=c44716d15ea1c964086d12ca01197c8ce47394f84080ef2ac590732ab708d2de7ce5088a8dca5fff495f540400d7d9b1a33c277aa3ccacc835e260daadaa862ab277c9696b93258cd56a8316dfce8e36fa696f08f5ccb6508ad7eb9eef52ab7be3706ef92a52379cf3fbd94a8440c357a965492d496dd36a42cee1bacf58cb62b67f2717f8f904593a8b13fa947081c7e88f242c8e2f8f146a7201227a09cfb23de21fdce4ad87a30d7dc7c28a2a0003d48345aa44121352659dfb76c03b773d2ea153088306a1c7971177357224335ef293725c988742831aa40981183bc51e981aa30bece171962fc3b8e4ec2b3f5351a607cde081bc4989c17e4181577e3b&X-Goog-SignedHeaders=host&X-User=2931823730 (Caused by NewConnectionError('<urllib3.connection.HTTPSConnection object at 0x7fcd90153880>: Failed to establish a new connection: [Errno 101] Network is unreachable'))
2025-04-11 15:13:18,164 ERROR   wandb-upload_4:23351 [internal_api.py:upload_file():2558] upload_file request headers: {'User-Agent': 'python-requests/2.32.3', 'Accept-Encoding': 'gzip, deflate, br', 'Accept': '*/*', 'Connection': 'keep-alive', 'Content-Length': '4566'}
2025-04-11 15:13:18,164 ERROR   wandb-upload_4:23351 [internal_api.py:upload_file():2560] upload_file response body: 
2025-04-11 15:13:18,211 ERROR   wandb-upload_3:23351 [internal_api.py:upload_file():2556] upload_file exception https://storage.googleapis.com/wandb-production.appspot.com/2931823730-harbin-institute-of-technology/ltu-as/2p8m9dwe/conda-environment.yaml?X-Goog-Algorithm=GOOG4-RSA-SHA256&X-Goog-Credential=gorilla-files-url-signer-man%40wandb-production.iam.gserviceaccount.com%2F20250411%2Fauto%2Fstorage%2Fgoog4_request&X-Goog-Date=20250411T151314Z&X-Goog-Expires=86399&X-Goog-Signature=7bccffe4b07a3cf7a72c89a7f9ce9c4d318e83ce8565b48d1c8f6ad1e28f0ebcdffbee0466a5b02680abb5917671b4a58a7489d0f31f20b248c65bd0c9f930a4644b19cc67ee38174f54216aa249142b3c30c57a2162d76288e12d623bc786f0e3bd70267e2f8b8b1f5fa86a79cd8d97967dbffbd58e690e13bcac89903c53b61dbb15aa9ec0292990c028cd3f04bee5811a98d7e05760e37f63577946aa5dad22ec10f762d7c7411768b61b1c77b04e59a142df620d4b91315c0493f25f0606e8c9fea31d10992830c7f64dcdb4e3fc94fe26697cc4229457f7aaf42229b62f52420cfe16878dd02e161d04f3bc30ec2bbed1840417b715e0c8fdf9316f1160&X-Goog-SignedHeaders=host&X-User=2931823730: HTTPSConnectionPool(host='storage.googleapis.com', port=443): Max retries exceeded with url: /wandb-production.appspot.com/2931823730-harbin-institute-of-technology/ltu-as/2p8m9dwe/conda-environment.yaml?X-Goog-Algorithm=GOOG4-RSA-SHA256&X-Goog-Credential=gorilla-files-url-signer-man%40wandb-production.iam.gserviceaccount.com%2F20250411%2Fauto%2Fstorage%2Fgoog4_request&X-Goog-Date=20250411T151314Z&X-Goog-Expires=86399&X-Goog-Signature=7bccffe4b07a3cf7a72c89a7f9ce9c4d318e83ce8565b48d1c8f6ad1e28f0ebcdffbee0466a5b02680abb5917671b4a58a7489d0f31f20b248c65bd0c9f930a4644b19cc67ee38174f54216aa249142b3c30c57a2162d76288e12d623bc786f0e3bd70267e2f8b8b1f5fa86a79cd8d97967dbffbd58e690e13bcac89903c53b61dbb15aa9ec0292990c028cd3f04bee5811a98d7e05760e37f63577946aa5dad22ec10f762d7c7411768b61b1c77b04e59a142df620d4b91315c0493f25f0606e8c9fea31d10992830c7f64dcdb4e3fc94fe26697cc4229457f7aaf42229b62f52420cfe16878dd02e161d04f3bc30ec2bbed1840417b715e0c8fdf9316f1160&X-Goog-SignedHeaders=host&X-User=2931823730 (Caused by NewConnectionError('<urllib3.connection.HTTPSConnection object at 0x7fcd90150160>: Failed to establish a new connection: [Errno 101] Network is unreachable'))
2025-04-11 15:13:18,211 ERROR   wandb-upload_3:23351 [internal_api.py:upload_file():2558] upload_file request headers: {'User-Agent': 'python-requests/2.32.3', 'Accept-Encoding': 'gzip, deflate, br', 'Accept': '*/*', 'Connection': 'keep-alive', 'Content-Length': '8281'}
2025-04-11 15:13:18,212 ERROR   wandb-upload_3:23351 [internal_api.py:upload_file():2560] upload_file response body: 
2025-04-11 15:13:18,559 DEBUG   HandlerThread:23351 [handler.py:handle_request():146] handle_request: poll_exit
2025-04-11 15:13:18,559 DEBUG   SenderThread:23351 [sender.py:send_request():407] send_request: poll_exit
2025-04-11 15:13:19,559 DEBUG   HandlerThread:23351 [handler.py:handle_request():146] handle_request: poll_exit
2025-04-11 15:13:19,560 DEBUG   SenderThread:23351 [sender.py:send_request():407] send_request: poll_exit
2025-04-11 15:13:20,561 DEBUG   HandlerThread:23351 [handler.py:handle_request():146] handle_request: poll_exit
2025-04-11 15:13:20,562 DEBUG   HandlerThread:23351 [handler.py:handle_request():146] handle_request: status_report
2025-04-11 15:13:20,562 DEBUG   SenderThread:23351 [sender.py:send_request():407] send_request: poll_exit
2025-04-11 15:13:20,804 ERROR   wandb-upload_0:23351 [internal_api.py:upload_file():2556] upload_file exception https://storage.googleapis.com/wandb-production.appspot.com/2931823730-harbin-institute-of-technology/ltu-as/2p8m9dwe/wandb-metadata.json?X-Goog-Algorithm=GOOG4-RSA-SHA256&X-Goog-Credential=gorilla-files-url-signer-man%40wandb-production.iam.gserviceaccount.com%2F20250411%2Fauto%2Fstorage%2Fgoog4_request&X-Goog-Date=20250411T151303Z&X-Goog-Expires=86399&X-Goog-Signature=66719b998233aaee17a4c8047f633f9fe8c63f2ec466add270a92770477da6400199adfcf00866c96f6dc05161138b1c975095d9af586d19c4562209061e30e08bd4d7219879f1feac9679910790a6a4a494f472525052bd9d37aeaaff7a12f35f7118d64e15d74671f5afe7e20c2f2af6267dcd02dfacf08492999956870cba51b7f137738b959ca68d5f32bf47c87a32c21d2290ba9f62f0ea73dad72b8e99354b2a6d270ef91250d93621c3f830ce0c27c31dea23aac750b4dee03cc9083a92e0bd447360d1936579a5c45636fc1f207d010be1f8dc4f70e7e88a488e18a3096ee433b3386152f113d1b1a754768b9e6991b7358300a7435738c0343fa5e1&X-Goog-SignedHeaders=host&X-User=2931823730: HTTPSConnectionPool(host='storage.googleapis.com', port=443): Max retries exceeded with url: /wandb-production.appspot.com/2931823730-harbin-institute-of-technology/ltu-as/2p8m9dwe/wandb-metadata.json?X-Goog-Algorithm=GOOG4-RSA-SHA256&X-Goog-Credential=gorilla-files-url-signer-man%40wandb-production.iam.gserviceaccount.com%2F20250411%2Fauto%2Fstorage%2Fgoog4_request&X-Goog-Date=20250411T151303Z&X-Goog-Expires=86399&X-Goog-Signature=66719b998233aaee17a4c8047f633f9fe8c63f2ec466add270a92770477da6400199adfcf00866c96f6dc05161138b1c975095d9af586d19c4562209061e30e08bd4d7219879f1feac9679910790a6a4a494f472525052bd9d37aeaaff7a12f35f7118d64e15d74671f5afe7e20c2f2af6267dcd02dfacf08492999956870cba51b7f137738b959ca68d5f32bf47c87a32c21d2290ba9f62f0ea73dad72b8e99354b2a6d270ef91250d93621c3f830ce0c27c31dea23aac750b4dee03cc9083a92e0bd447360d1936579a5c45636fc1f207d010be1f8dc4f70e7e88a488e18a3096ee433b3386152f113d1b1a754768b9e6991b7358300a7435738c0343fa5e1&X-Goog-SignedHeaders=host&X-User=2931823730 (Caused by NewConnectionError('<urllib3.connection.HTTPSConnection object at 0x7fcd901513f0>: Failed to establish a new connection: [Errno 101] Network is unreachable'))
2025-04-11 15:13:20,804 ERROR   wandb-upload_0:23351 [internal_api.py:upload_file():2558] upload_file request headers: {'User-Agent': 'python-requests/2.32.3', 'Accept-Encoding': 'gzip, deflate, br', 'Accept': '*/*', 'Connection': 'keep-alive', 'Content-Length': '2274'}
2025-04-11 15:13:20,804 ERROR   wandb-upload_0:23351 [internal_api.py:upload_file():2560] upload_file response body: 
2025-04-11 15:13:21,562 DEBUG   HandlerThread:23351 [handler.py:handle_request():146] handle_request: poll_exit
2025-04-11 15:13:21,563 DEBUG   SenderThread:23351 [sender.py:send_request():407] send_request: poll_exit
2025-04-11 15:13:22,128 ERROR   wandb-upload_2:23351 [internal_api.py:upload_file():2556] upload_file exception https://storage.googleapis.com/wandb-production.appspot.com/2931823730-harbin-institute-of-technology/ltu-as/2p8m9dwe/requirements.txt?X-Goog-Algorithm=GOOG4-RSA-SHA256&X-Goog-Credential=gorilla-files-url-signer-man%40wandb-production.iam.gserviceaccount.com%2F20250411%2Fauto%2Fstorage%2Fgoog4_request&X-Goog-Date=20250411T151314Z&X-Goog-Expires=86399&X-Goog-Signature=596e10f29ae2cec75cbb1a5c0879360376523a72f892408b062c1c8ebab215b4abbad1df8da6bec541c89de6deec2c6eb2b6da8b279a8f2bf743c49dea4bc7e6e3ae10f36daa45d6c2e3fac141e6b670687c7233fa8373b04b2f2ded936d143be1302daec292448420869529e939bed8801a5287777bec29a946e96cd575116736d582b1f707a977a956003d465137e9d8705e50cad2a5d9a9bcb34fc432d91d692f7909aee691cef6f89d2eabdc170595373f228cb4586119d828afa412185bca4dcc7d703d9b2be5d7e28fb510bf2f95fcb6854a59c4d660327bd409ac87373f31aa2e1ff0ef593ee31c3901719e0db1cd03a2427023741ffddaec48f48a33&X-Goog-SignedHeaders=host&X-User=2931823730: HTTPSConnectionPool(host='storage.googleapis.com', port=443): Max retries exceeded with url: /wandb-production.appspot.com/2931823730-harbin-institute-of-technology/ltu-as/2p8m9dwe/requirements.txt?X-Goog-Algorithm=GOOG4-RSA-SHA256&X-Goog-Credential=gorilla-files-url-signer-man%40wandb-production.iam.gserviceaccount.com%2F20250411%2Fauto%2Fstorage%2Fgoog4_request&X-Goog-Date=20250411T151314Z&X-Goog-Expires=86399&X-Goog-Signature=596e10f29ae2cec75cbb1a5c0879360376523a72f892408b062c1c8ebab215b4abbad1df8da6bec541c89de6deec2c6eb2b6da8b279a8f2bf743c49dea4bc7e6e3ae10f36daa45d6c2e3fac141e6b670687c7233fa8373b04b2f2ded936d143be1302daec292448420869529e939bed8801a5287777bec29a946e96cd575116736d582b1f707a977a956003d465137e9d8705e50cad2a5d9a9bcb34fc432d91d692f7909aee691cef6f89d2eabdc170595373f228cb4586119d828afa412185bca4dcc7d703d9b2be5d7e28fb510bf2f95fcb6854a59c4d660327bd409ac87373f31aa2e1ff0ef593ee31c3901719e0db1cd03a2427023741ffddaec48f48a33&X-Goog-SignedHeaders=host&X-User=2931823730 (Caused by NewConnectionError('<urllib3.connection.HTTPSConnection object at 0x7fcd901534f0>: Failed to establish a new connection: [Errno 101] Network is unreachable'))
2025-04-11 15:13:22,128 ERROR   wandb-upload_2:23351 [internal_api.py:upload_file():2558] upload_file request headers: {'User-Agent': 'python-requests/2.32.3', 'Accept-Encoding': 'gzip, deflate, br', 'Accept': '*/*', 'Connection': 'keep-alive', 'Content-Length': '4212'}
2025-04-11 15:13:22,128 ERROR   wandb-upload_2:23351 [internal_api.py:upload_file():2560] upload_file response body: 
2025-04-11 15:13:22,510 ERROR   wandb-upload_1:23351 [internal_api.py:upload_file():2556] upload_file exception https://storage.googleapis.com/wandb-production.appspot.com/2931823730-harbin-institute-of-technology/ltu-as/2p8m9dwe/config.yaml?X-Goog-Algorithm=GOOG4-RSA-SHA256&X-Goog-Credential=gorilla-files-url-signer-man%40wandb-production.iam.gserviceaccount.com%2F20250411%2Fauto%2Fstorage%2Fgoog4_request&X-Goog-Date=20250411T151314Z&X-Goog-Expires=86399&X-Goog-Signature=c3f1c581a0bd73c6399672f1fac440187a0b07669ff4825ee30bf5e058c5a683d85c7b6a22215e3bb850b742c0d89df501576ca1866fd5534cc3429d481eba7e8d4f973e12d002b083ebdafce4bc036f519523a270ba6868dfa5551a4dacda47e4863088e75c0f9dd7ef57f5509215ac52373490cdb269dceabdf696d0c1b874b77f6e0064f27f0acc826c3bf3755682d9d80d1c2829fc57effdb94af0f0693ef6bbbf1e906d59b08d2ac9d8d8617261eea7f087f6d696d308a005cdbb07089b88ec998a31608527466034e5d8e1c405536f34bec132780342d5f14d57109d149db8d09c9a4b2d71228d28d56b512091008f600490c271953244785eda190976&X-Goog-SignedHeaders=host&X-User=2931823730: HTTPSConnectionPool(host='storage.googleapis.com', port=443): Max retries exceeded with url: /wandb-production.appspot.com/2931823730-harbin-institute-of-technology/ltu-as/2p8m9dwe/config.yaml?X-Goog-Algorithm=GOOG4-RSA-SHA256&X-Goog-Credential=gorilla-files-url-signer-man%40wandb-production.iam.gserviceaccount.com%2F20250411%2Fauto%2Fstorage%2Fgoog4_request&X-Goog-Date=20250411T151314Z&X-Goog-Expires=86399&X-Goog-Signature=c3f1c581a0bd73c6399672f1fac440187a0b07669ff4825ee30bf5e058c5a683d85c7b6a22215e3bb850b742c0d89df501576ca1866fd5534cc3429d481eba7e8d4f973e12d002b083ebdafce4bc036f519523a270ba6868dfa5551a4dacda47e4863088e75c0f9dd7ef57f5509215ac52373490cdb269dceabdf696d0c1b874b77f6e0064f27f0acc826c3bf3755682d9d80d1c2829fc57effdb94af0f0693ef6bbbf1e906d59b08d2ac9d8d8617261eea7f087f6d696d308a005cdbb07089b88ec998a31608527466034e5d8e1c405536f34bec132780342d5f14d57109d149db8d09c9a4b2d71228d28d56b512091008f600490c271953244785eda190976&X-Goog-SignedHeaders=host&X-User=2931823730 (Caused by NewConnectionError('<urllib3.connection.HTTPSConnection object at 0x7fcd785764a0>: Failed to establish a new connection: [Errno 101] Network is unreachable'))
2025-04-11 15:13:22,510 ERROR   wandb-upload_1:23351 [internal_api.py:upload_file():2558] upload_file request headers: {'User-Agent': 'python-requests/2.32.3', 'Accept-Encoding': 'gzip, deflate, br', 'Accept': '*/*', 'Connection': 'keep-alive', 'Content-Length': '8685'}
2025-04-11 15:13:22,510 ERROR   wandb-upload_1:23351 [internal_api.py:upload_file():2560] upload_file response body: 
2025-04-11 15:13:22,563 DEBUG   HandlerThread:23351 [handler.py:handle_request():146] handle_request: poll_exit
2025-04-11 15:13:22,564 DEBUG   SenderThread:23351 [sender.py:send_request():407] send_request: poll_exit
2025-04-11 15:13:22,620 ERROR   wandb-upload_5:23351 [internal_api.py:upload_file():2556] upload_file exception https://storage.googleapis.com/wandb-production.appspot.com/2931823730-harbin-institute-of-technology/ltu-as/2p8m9dwe/wandb-summary.json?X-Goog-Algorithm=GOOG4-RSA-SHA256&X-Goog-Credential=gorilla-files-url-signer-man%40wandb-production.iam.gserviceaccount.com%2F20250411%2Fauto%2Fstorage%2Fgoog4_request&X-Goog-Date=20250411T151314Z&X-Goog-Expires=86399&X-Goog-Signature=162b1e62deff7d3bad6004d3a39fdd84d0fb4788bdb8d01e0c9d67b6f7e728dcaea0cb69e08f91b69ed9b3ce33d56cc666da669ae6d0068246f6cfe4df6689494f83127a4e56dd1b441f107582348c20736d718f639c3a8d2bd9e625f42df04e9a9ed9ad2fc866f745d4f7f306562fe7caea0762bbcedcf2c997fcd631267f1f83aaa2c4a9a761d30d4e984f6072578157b87f3fcc47208dc31c3b3e3ac49acb79d5bb7979b389efcdee835c5d0824ea8d052021f53bde71af985a8540e33c788536fdf534fa19fbf6bacb0b506b1cb2c12a920d6c96bb96b6439ba7ab027e872a2d722014ee899f60088eaf28b44252c2e639ebb1bcf3709757d2dbb87847a2&X-Goog-SignedHeaders=host&X-User=2931823730: HTTPSConnectionPool(host='storage.googleapis.com', port=443): Max retries exceeded with url: /wandb-production.appspot.com/2931823730-harbin-institute-of-technology/ltu-as/2p8m9dwe/wandb-summary.json?X-Goog-Algorithm=GOOG4-RSA-SHA256&X-Goog-Credential=gorilla-files-url-signer-man%40wandb-production.iam.gserviceaccount.com%2F20250411%2Fauto%2Fstorage%2Fgoog4_request&X-Goog-Date=20250411T151314Z&X-Goog-Expires=86399&X-Goog-Signature=162b1e62deff7d3bad6004d3a39fdd84d0fb4788bdb8d01e0c9d67b6f7e728dcaea0cb69e08f91b69ed9b3ce33d56cc666da669ae6d0068246f6cfe4df6689494f83127a4e56dd1b441f107582348c20736d718f639c3a8d2bd9e625f42df04e9a9ed9ad2fc866f745d4f7f306562fe7caea0762bbcedcf2c997fcd631267f1f83aaa2c4a9a761d30d4e984f6072578157b87f3fcc47208dc31c3b3e3ac49acb79d5bb7979b389efcdee835c5d0824ea8d052021f53bde71af985a8540e33c788536fdf534fa19fbf6bacb0b506b1cb2c12a920d6c96bb96b6439ba7ab027e872a2d722014ee899f60088eaf28b44252c2e639ebb1bcf3709757d2dbb87847a2&X-Goog-SignedHeaders=host&X-User=2931823730 (Caused by NewConnectionError('<urllib3.connection.HTTPSConnection object at 0x7fcd78575000>: Failed to establish a new connection: [Errno 101] Network is unreachable'))
2025-04-11 15:13:22,620 ERROR   wandb-upload_5:23351 [internal_api.py:upload_file():2558] upload_file request headers: {'User-Agent': 'python-requests/2.32.3', 'Accept-Encoding': 'gzip, deflate, br', 'Accept': '*/*', 'Connection': 'keep-alive', 'Content-Length': '27'}
2025-04-11 15:13:22,620 ERROR   wandb-upload_5:23351 [internal_api.py:upload_file():2560] upload_file response body: 
2025-04-11 15:13:22,786 ERROR   wandb-upload_3:23351 [internal_api.py:upload_file():2556] upload_file exception https://storage.googleapis.com/wandb-production.appspot.com/2931823730-harbin-institute-of-technology/ltu-as/2p8m9dwe/conda-environment.yaml?X-Goog-Algorithm=GOOG4-RSA-SHA256&X-Goog-Credential=gorilla-files-url-signer-man%40wandb-production.iam.gserviceaccount.com%2F20250411%2Fauto%2Fstorage%2Fgoog4_request&X-Goog-Date=20250411T151314Z&X-Goog-Expires=86399&X-Goog-Signature=7bccffe4b07a3cf7a72c89a7f9ce9c4d318e83ce8565b48d1c8f6ad1e28f0ebcdffbee0466a5b02680abb5917671b4a58a7489d0f31f20b248c65bd0c9f930a4644b19cc67ee38174f54216aa249142b3c30c57a2162d76288e12d623bc786f0e3bd70267e2f8b8b1f5fa86a79cd8d97967dbffbd58e690e13bcac89903c53b61dbb15aa9ec0292990c028cd3f04bee5811a98d7e05760e37f63577946aa5dad22ec10f762d7c7411768b61b1c77b04e59a142df620d4b91315c0493f25f0606e8c9fea31d10992830c7f64dcdb4e3fc94fe26697cc4229457f7aaf42229b62f52420cfe16878dd02e161d04f3bc30ec2bbed1840417b715e0c8fdf9316f1160&X-Goog-SignedHeaders=host&X-User=2931823730: HTTPSConnectionPool(host='storage.googleapis.com', port=443): Max retries exceeded with url: /wandb-production.appspot.com/2931823730-harbin-institute-of-technology/ltu-as/2p8m9dwe/conda-environment.yaml?X-Goog-Algorithm=GOOG4-RSA-SHA256&X-Goog-Credential=gorilla-files-url-signer-man%40wandb-production.iam.gserviceaccount.com%2F20250411%2Fauto%2Fstorage%2Fgoog4_request&X-Goog-Date=20250411T151314Z&X-Goog-Expires=86399&X-Goog-Signature=7bccffe4b07a3cf7a72c89a7f9ce9c4d318e83ce8565b48d1c8f6ad1e28f0ebcdffbee0466a5b02680abb5917671b4a58a7489d0f31f20b248c65bd0c9f930a4644b19cc67ee38174f54216aa249142b3c30c57a2162d76288e12d623bc786f0e3bd70267e2f8b8b1f5fa86a79cd8d97967dbffbd58e690e13bcac89903c53b61dbb15aa9ec0292990c028cd3f04bee5811a98d7e05760e37f63577946aa5dad22ec10f762d7c7411768b61b1c77b04e59a142df620d4b91315c0493f25f0606e8c9fea31d10992830c7f64dcdb4e3fc94fe26697cc4229457f7aaf42229b62f52420cfe16878dd02e161d04f3bc30ec2bbed1840417b715e0c8fdf9316f1160&X-Goog-SignedHeaders=host&X-User=2931823730 (Caused by NewConnectionError('<urllib3.connection.HTTPSConnection object at 0x7fcd78576110>: Failed to establish a new connection: [Errno 101] Network is unreachable'))
2025-04-11 15:13:22,786 ERROR   wandb-upload_3:23351 [internal_api.py:upload_file():2558] upload_file request headers: {'User-Agent': 'python-requests/2.32.3', 'Accept-Encoding': 'gzip, deflate, br', 'Accept': '*/*', 'Connection': 'keep-alive', 'Content-Length': '8281'}
2025-04-11 15:13:22,786 ERROR   wandb-upload_3:23351 [internal_api.py:upload_file():2560] upload_file response body: 
2025-04-11 15:13:23,142 ERROR   wandb-upload_4:23351 [internal_api.py:upload_file():2556] upload_file exception https://storage.googleapis.com/wandb-production.appspot.com/2931823730-harbin-institute-of-technology/ltu-as/2p8m9dwe/output.log?X-Goog-Algorithm=GOOG4-RSA-SHA256&X-Goog-Credential=gorilla-files-url-signer-man%40wandb-production.iam.gserviceaccount.com%2F20250411%2Fauto%2Fstorage%2Fgoog4_request&X-Goog-Date=20250411T151314Z&X-Goog-Expires=86399&X-Goog-Signature=c44716d15ea1c964086d12ca01197c8ce47394f84080ef2ac590732ab708d2de7ce5088a8dca5fff495f540400d7d9b1a33c277aa3ccacc835e260daadaa862ab277c9696b93258cd56a8316dfce8e36fa696f08f5ccb6508ad7eb9eef52ab7be3706ef92a52379cf3fbd94a8440c357a965492d496dd36a42cee1bacf58cb62b67f2717f8f904593a8b13fa947081c7e88f242c8e2f8f146a7201227a09cfb23de21fdce4ad87a30d7dc7c28a2a0003d48345aa44121352659dfb76c03b773d2ea153088306a1c7971177357224335ef293725c988742831aa40981183bc51e981aa30bece171962fc3b8e4ec2b3f5351a607cde081bc4989c17e4181577e3b&X-Goog-SignedHeaders=host&X-User=2931823730: HTTPSConnectionPool(host='storage.googleapis.com', port=443): Max retries exceeded with url: /wandb-production.appspot.com/2931823730-harbin-institute-of-technology/ltu-as/2p8m9dwe/output.log?X-Goog-Algorithm=GOOG4-RSA-SHA256&X-Goog-Credential=gorilla-files-url-signer-man%40wandb-production.iam.gserviceaccount.com%2F20250411%2Fauto%2Fstorage%2Fgoog4_request&X-Goog-Date=20250411T151314Z&X-Goog-Expires=86399&X-Goog-Signature=c44716d15ea1c964086d12ca01197c8ce47394f84080ef2ac590732ab708d2de7ce5088a8dca5fff495f540400d7d9b1a33c277aa3ccacc835e260daadaa862ab277c9696b93258cd56a8316dfce8e36fa696f08f5ccb6508ad7eb9eef52ab7be3706ef92a52379cf3fbd94a8440c357a965492d496dd36a42cee1bacf58cb62b67f2717f8f904593a8b13fa947081c7e88f242c8e2f8f146a7201227a09cfb23de21fdce4ad87a30d7dc7c28a2a0003d48345aa44121352659dfb76c03b773d2ea153088306a1c7971177357224335ef293725c988742831aa40981183bc51e981aa30bece171962fc3b8e4ec2b3f5351a607cde081bc4989c17e4181577e3b&X-Goog-SignedHeaders=host&X-User=2931823730 (Caused by NewConnectionError('<urllib3.connection.HTTPSConnection object at 0x7fcd78575c60>: Failed to establish a new connection: [Errno 101] Network is unreachable'))
2025-04-11 15:13:23,142 ERROR   wandb-upload_4:23351 [internal_api.py:upload_file():2558] upload_file request headers: {'User-Agent': 'python-requests/2.32.3', 'Accept-Encoding': 'gzip, deflate, br', 'Accept': '*/*', 'Connection': 'keep-alive', 'Content-Length': '4566'}
2025-04-11 15:13:23,142 ERROR   wandb-upload_4:23351 [internal_api.py:upload_file():2560] upload_file response body: 
2025-04-11 15:13:23,564 DEBUG   HandlerThread:23351 [handler.py:handle_request():146] handle_request: poll_exit
2025-04-11 15:13:23,565 DEBUG   SenderThread:23351 [sender.py:send_request():407] send_request: poll_exit
2025-04-11 15:13:24,565 DEBUG   HandlerThread:23351 [handler.py:handle_request():146] handle_request: poll_exit
2025-04-11 15:13:24,566 DEBUG   SenderThread:23351 [sender.py:send_request():407] send_request: poll_exit
2025-04-11 15:13:25,566 DEBUG   HandlerThread:23351 [handler.py:handle_request():146] handle_request: poll_exit
2025-04-11 15:13:25,567 DEBUG   SenderThread:23351 [sender.py:send_request():407] send_request: poll_exit
2025-04-11 15:13:25,568 DEBUG   HandlerThread:23351 [handler.py:handle_request():146] handle_request: status_report
2025-04-11 15:13:26,569 DEBUG   HandlerThread:23351 [handler.py:handle_request():146] handle_request: poll_exit
2025-04-11 15:13:26,570 DEBUG   SenderThread:23351 [sender.py:send_request():407] send_request: poll_exit
2025-04-11 15:13:27,571 DEBUG   HandlerThread:23351 [handler.py:handle_request():146] handle_request: poll_exit
2025-04-11 15:13:27,571 DEBUG   SenderThread:23351 [sender.py:send_request():407] send_request: poll_exit
2025-04-11 15:13:28,573 DEBUG   HandlerThread:23351 [handler.py:handle_request():146] handle_request: poll_exit
2025-04-11 15:13:28,574 DEBUG   SenderThread:23351 [sender.py:send_request():407] send_request: poll_exit
2025-04-11 15:13:29,574 DEBUG   HandlerThread:23351 [handler.py:handle_request():146] handle_request: poll_exit
2025-04-11 15:13:29,575 DEBUG   SenderThread:23351 [sender.py:send_request():407] send_request: poll_exit
2025-04-11 15:13:30,575 DEBUG   HandlerThread:23351 [handler.py:handle_request():146] handle_request: poll_exit
2025-04-11 15:13:30,576 DEBUG   HandlerThread:23351 [handler.py:handle_request():146] handle_request: status_report
2025-04-11 15:13:30,577 DEBUG   SenderThread:23351 [sender.py:send_request():407] send_request: poll_exit
2025-04-11 15:13:31,028 ERROR   wandb-upload_1:23351 [internal_api.py:upload_file():2556] upload_file exception https://storage.googleapis.com/wandb-production.appspot.com/2931823730-harbin-institute-of-technology/ltu-as/2p8m9dwe/config.yaml?X-Goog-Algorithm=GOOG4-RSA-SHA256&X-Goog-Credential=gorilla-files-url-signer-man%40wandb-production.iam.gserviceaccount.com%2F20250411%2Fauto%2Fstorage%2Fgoog4_request&X-Goog-Date=20250411T151314Z&X-Goog-Expires=86399&X-Goog-Signature=c3f1c581a0bd73c6399672f1fac440187a0b07669ff4825ee30bf5e058c5a683d85c7b6a22215e3bb850b742c0d89df501576ca1866fd5534cc3429d481eba7e8d4f973e12d002b083ebdafce4bc036f519523a270ba6868dfa5551a4dacda47e4863088e75c0f9dd7ef57f5509215ac52373490cdb269dceabdf696d0c1b874b77f6e0064f27f0acc826c3bf3755682d9d80d1c2829fc57effdb94af0f0693ef6bbbf1e906d59b08d2ac9d8d8617261eea7f087f6d696d308a005cdbb07089b88ec998a31608527466034e5d8e1c405536f34bec132780342d5f14d57109d149db8d09c9a4b2d71228d28d56b512091008f600490c271953244785eda190976&X-Goog-SignedHeaders=host&X-User=2931823730: HTTPSConnectionPool(host='storage.googleapis.com', port=443): Max retries exceeded with url: /wandb-production.appspot.com/2931823730-harbin-institute-of-technology/ltu-as/2p8m9dwe/config.yaml?X-Goog-Algorithm=GOOG4-RSA-SHA256&X-Goog-Credential=gorilla-files-url-signer-man%40wandb-production.iam.gserviceaccount.com%2F20250411%2Fauto%2Fstorage%2Fgoog4_request&X-Goog-Date=20250411T151314Z&X-Goog-Expires=86399&X-Goog-Signature=c3f1c581a0bd73c6399672f1fac440187a0b07669ff4825ee30bf5e058c5a683d85c7b6a22215e3bb850b742c0d89df501576ca1866fd5534cc3429d481eba7e8d4f973e12d002b083ebdafce4bc036f519523a270ba6868dfa5551a4dacda47e4863088e75c0f9dd7ef57f5509215ac52373490cdb269dceabdf696d0c1b874b77f6e0064f27f0acc826c3bf3755682d9d80d1c2829fc57effdb94af0f0693ef6bbbf1e906d59b08d2ac9d8d8617261eea7f087f6d696d308a005cdbb07089b88ec998a31608527466034e5d8e1c405536f34bec132780342d5f14d57109d149db8d09c9a4b2d71228d28d56b512091008f600490c271953244785eda190976&X-Goog-SignedHeaders=host&X-User=2931823730 (Caused by NewConnectionError('<urllib3.connection.HTTPSConnection object at 0x7fcd78575f60>: Failed to establish a new connection: [Errno 101] Network is unreachable'))
2025-04-11 15:13:31,029 ERROR   wandb-upload_1:23351 [internal_api.py:upload_file():2558] upload_file request headers: {'User-Agent': 'python-requests/2.32.3', 'Accept-Encoding': 'gzip, deflate, br', 'Accept': '*/*', 'Connection': 'keep-alive', 'Content-Length': '8685'}
2025-04-11 15:13:31,029 ERROR   wandb-upload_1:23351 [internal_api.py:upload_file():2560] upload_file response body: 
2025-04-11 15:13:31,290 ERROR   wandb-upload_4:23351 [internal_api.py:upload_file():2556] upload_file exception https://storage.googleapis.com/wandb-production.appspot.com/2931823730-harbin-institute-of-technology/ltu-as/2p8m9dwe/output.log?X-Goog-Algorithm=GOOG4-RSA-SHA256&X-Goog-Credential=gorilla-files-url-signer-man%40wandb-production.iam.gserviceaccount.com%2F20250411%2Fauto%2Fstorage%2Fgoog4_request&X-Goog-Date=20250411T151314Z&X-Goog-Expires=86399&X-Goog-Signature=c44716d15ea1c964086d12ca01197c8ce47394f84080ef2ac590732ab708d2de7ce5088a8dca5fff495f540400d7d9b1a33c277aa3ccacc835e260daadaa862ab277c9696b93258cd56a8316dfce8e36fa696f08f5ccb6508ad7eb9eef52ab7be3706ef92a52379cf3fbd94a8440c357a965492d496dd36a42cee1bacf58cb62b67f2717f8f904593a8b13fa947081c7e88f242c8e2f8f146a7201227a09cfb23de21fdce4ad87a30d7dc7c28a2a0003d48345aa44121352659dfb76c03b773d2ea153088306a1c7971177357224335ef293725c988742831aa40981183bc51e981aa30bece171962fc3b8e4ec2b3f5351a607cde081bc4989c17e4181577e3b&X-Goog-SignedHeaders=host&X-User=2931823730: HTTPSConnectionPool(host='storage.googleapis.com', port=443): Max retries exceeded with url: /wandb-production.appspot.com/2931823730-harbin-institute-of-technology/ltu-as/2p8m9dwe/output.log?X-Goog-Algorithm=GOOG4-RSA-SHA256&X-Goog-Credential=gorilla-files-url-signer-man%40wandb-production.iam.gserviceaccount.com%2F20250411%2Fauto%2Fstorage%2Fgoog4_request&X-Goog-Date=20250411T151314Z&X-Goog-Expires=86399&X-Goog-Signature=c44716d15ea1c964086d12ca01197c8ce47394f84080ef2ac590732ab708d2de7ce5088a8dca5fff495f540400d7d9b1a33c277aa3ccacc835e260daadaa862ab277c9696b93258cd56a8316dfce8e36fa696f08f5ccb6508ad7eb9eef52ab7be3706ef92a52379cf3fbd94a8440c357a965492d496dd36a42cee1bacf58cb62b67f2717f8f904593a8b13fa947081c7e88f242c8e2f8f146a7201227a09cfb23de21fdce4ad87a30d7dc7c28a2a0003d48345aa44121352659dfb76c03b773d2ea153088306a1c7971177357224335ef293725c988742831aa40981183bc51e981aa30bece171962fc3b8e4ec2b3f5351a607cde081bc4989c17e4181577e3b&X-Goog-SignedHeaders=host&X-User=2931823730 (Caused by NewConnectionError('<urllib3.connection.HTTPSConnection object at 0x7fcd901527a0>: Failed to establish a new connection: [Errno 101] Network is unreachable'))
2025-04-11 15:13:31,290 ERROR   wandb-upload_4:23351 [internal_api.py:upload_file():2558] upload_file request headers: {'User-Agent': 'python-requests/2.32.3', 'Accept-Encoding': 'gzip, deflate, br', 'Accept': '*/*', 'Connection': 'keep-alive', 'Content-Length': '4566'}
2025-04-11 15:13:31,290 ERROR   wandb-upload_4:23351 [internal_api.py:upload_file():2560] upload_file response body: 
2025-04-11 15:13:31,396 ERROR   wandb-upload_2:23351 [internal_api.py:upload_file():2556] upload_file exception https://storage.googleapis.com/wandb-production.appspot.com/2931823730-harbin-institute-of-technology/ltu-as/2p8m9dwe/requirements.txt?X-Goog-Algorithm=GOOG4-RSA-SHA256&X-Goog-Credential=gorilla-files-url-signer-man%40wandb-production.iam.gserviceaccount.com%2F20250411%2Fauto%2Fstorage%2Fgoog4_request&X-Goog-Date=20250411T151314Z&X-Goog-Expires=86399&X-Goog-Signature=596e10f29ae2cec75cbb1a5c0879360376523a72f892408b062c1c8ebab215b4abbad1df8da6bec541c89de6deec2c6eb2b6da8b279a8f2bf743c49dea4bc7e6e3ae10f36daa45d6c2e3fac141e6b670687c7233fa8373b04b2f2ded936d143be1302daec292448420869529e939bed8801a5287777bec29a946e96cd575116736d582b1f707a977a956003d465137e9d8705e50cad2a5d9a9bcb34fc432d91d692f7909aee691cef6f89d2eabdc170595373f228cb4586119d828afa412185bca4dcc7d703d9b2be5d7e28fb510bf2f95fcb6854a59c4d660327bd409ac87373f31aa2e1ff0ef593ee31c3901719e0db1cd03a2427023741ffddaec48f48a33&X-Goog-SignedHeaders=host&X-User=2931823730: HTTPSConnectionPool(host='storage.googleapis.com', port=443): Max retries exceeded with url: /wandb-production.appspot.com/2931823730-harbin-institute-of-technology/ltu-as/2p8m9dwe/requirements.txt?X-Goog-Algorithm=GOOG4-RSA-SHA256&X-Goog-Credential=gorilla-files-url-signer-man%40wandb-production.iam.gserviceaccount.com%2F20250411%2Fauto%2Fstorage%2Fgoog4_request&X-Goog-Date=20250411T151314Z&X-Goog-Expires=86399&X-Goog-Signature=596e10f29ae2cec75cbb1a5c0879360376523a72f892408b062c1c8ebab215b4abbad1df8da6bec541c89de6deec2c6eb2b6da8b279a8f2bf743c49dea4bc7e6e3ae10f36daa45d6c2e3fac141e6b670687c7233fa8373b04b2f2ded936d143be1302daec292448420869529e939bed8801a5287777bec29a946e96cd575116736d582b1f707a977a956003d465137e9d8705e50cad2a5d9a9bcb34fc432d91d692f7909aee691cef6f89d2eabdc170595373f228cb4586119d828afa412185bca4dcc7d703d9b2be5d7e28fb510bf2f95fcb6854a59c4d660327bd409ac87373f31aa2e1ff0ef593ee31c3901719e0db1cd03a2427023741ffddaec48f48a33&X-Goog-SignedHeaders=host&X-User=2931823730 (Caused by NewConnectionError('<urllib3.connection.HTTPSConnection object at 0x7fcd90150670>: Failed to establish a new connection: [Errno 101] Network is unreachable'))
2025-04-11 15:13:31,396 ERROR   wandb-upload_2:23351 [internal_api.py:upload_file():2558] upload_file request headers: {'User-Agent': 'python-requests/2.32.3', 'Accept-Encoding': 'gzip, deflate, br', 'Accept': '*/*', 'Connection': 'keep-alive', 'Content-Length': '4212'}
2025-04-11 15:13:31,397 ERROR   wandb-upload_2:23351 [internal_api.py:upload_file():2560] upload_file response body: 
2025-04-11 15:13:31,577 DEBUG   HandlerThread:23351 [handler.py:handle_request():146] handle_request: poll_exit
2025-04-11 15:13:31,578 DEBUG   SenderThread:23351 [sender.py:send_request():407] send_request: poll_exit
2025-04-11 15:13:31,642 ERROR   wandb-upload_5:23351 [internal_api.py:upload_file():2556] upload_file exception https://storage.googleapis.com/wandb-production.appspot.com/2931823730-harbin-institute-of-technology/ltu-as/2p8m9dwe/wandb-summary.json?X-Goog-Algorithm=GOOG4-RSA-SHA256&X-Goog-Credential=gorilla-files-url-signer-man%40wandb-production.iam.gserviceaccount.com%2F20250411%2Fauto%2Fstorage%2Fgoog4_request&X-Goog-Date=20250411T151314Z&X-Goog-Expires=86399&X-Goog-Signature=162b1e62deff7d3bad6004d3a39fdd84d0fb4788bdb8d01e0c9d67b6f7e728dcaea0cb69e08f91b69ed9b3ce33d56cc666da669ae6d0068246f6cfe4df6689494f83127a4e56dd1b441f107582348c20736d718f639c3a8d2bd9e625f42df04e9a9ed9ad2fc866f745d4f7f306562fe7caea0762bbcedcf2c997fcd631267f1f83aaa2c4a9a761d30d4e984f6072578157b87f3fcc47208dc31c3b3e3ac49acb79d5bb7979b389efcdee835c5d0824ea8d052021f53bde71af985a8540e33c788536fdf534fa19fbf6bacb0b506b1cb2c12a920d6c96bb96b6439ba7ab027e872a2d722014ee899f60088eaf28b44252c2e639ebb1bcf3709757d2dbb87847a2&X-Goog-SignedHeaders=host&X-User=2931823730: HTTPSConnectionPool(host='storage.googleapis.com', port=443): Max retries exceeded with url: /wandb-production.appspot.com/2931823730-harbin-institute-of-technology/ltu-as/2p8m9dwe/wandb-summary.json?X-Goog-Algorithm=GOOG4-RSA-SHA256&X-Goog-Credential=gorilla-files-url-signer-man%40wandb-production.iam.gserviceaccount.com%2F20250411%2Fauto%2Fstorage%2Fgoog4_request&X-Goog-Date=20250411T151314Z&X-Goog-Expires=86399&X-Goog-Signature=162b1e62deff7d3bad6004d3a39fdd84d0fb4788bdb8d01e0c9d67b6f7e728dcaea0cb69e08f91b69ed9b3ce33d56cc666da669ae6d0068246f6cfe4df6689494f83127a4e56dd1b441f107582348c20736d718f639c3a8d2bd9e625f42df04e9a9ed9ad2fc866f745d4f7f306562fe7caea0762bbcedcf2c997fcd631267f1f83aaa2c4a9a761d30d4e984f6072578157b87f3fcc47208dc31c3b3e3ac49acb79d5bb7979b389efcdee835c5d0824ea8d052021f53bde71af985a8540e33c788536fdf534fa19fbf6bacb0b506b1cb2c12a920d6c96bb96b6439ba7ab027e872a2d722014ee899f60088eaf28b44252c2e639ebb1bcf3709757d2dbb87847a2&X-Goog-SignedHeaders=host&X-User=2931823730 (Caused by NewConnectionError('<urllib3.connection.HTTPSConnection object at 0x7fcd90153700>: Failed to establish a new connection: [Errno 101] Network is unreachable'))
2025-04-11 15:13:31,642 ERROR   wandb-upload_5:23351 [internal_api.py:upload_file():2558] upload_file request headers: {'User-Agent': 'python-requests/2.32.3', 'Accept-Encoding': 'gzip, deflate, br', 'Accept': '*/*', 'Connection': 'keep-alive', 'Content-Length': '27'}
2025-04-11 15:13:31,642 ERROR   wandb-upload_5:23351 [internal_api.py:upload_file():2560] upload_file response body: 
2025-04-11 15:13:32,579 DEBUG   HandlerThread:23351 [handler.py:handle_request():146] handle_request: poll_exit
2025-04-11 15:13:32,580 DEBUG   SenderThread:23351 [sender.py:send_request():407] send_request: poll_exit
2025-04-11 15:13:32,760 ERROR   wandb-upload_3:23351 [internal_api.py:upload_file():2556] upload_file exception https://storage.googleapis.com/wandb-production.appspot.com/2931823730-harbin-institute-of-technology/ltu-as/2p8m9dwe/conda-environment.yaml?X-Goog-Algorithm=GOOG4-RSA-SHA256&X-Goog-Credential=gorilla-files-url-signer-man%40wandb-production.iam.gserviceaccount.com%2F20250411%2Fauto%2Fstorage%2Fgoog4_request&X-Goog-Date=20250411T151314Z&X-Goog-Expires=86399&X-Goog-Signature=7bccffe4b07a3cf7a72c89a7f9ce9c4d318e83ce8565b48d1c8f6ad1e28f0ebcdffbee0466a5b02680abb5917671b4a58a7489d0f31f20b248c65bd0c9f930a4644b19cc67ee38174f54216aa249142b3c30c57a2162d76288e12d623bc786f0e3bd70267e2f8b8b1f5fa86a79cd8d97967dbffbd58e690e13bcac89903c53b61dbb15aa9ec0292990c028cd3f04bee5811a98d7e05760e37f63577946aa5dad22ec10f762d7c7411768b61b1c77b04e59a142df620d4b91315c0493f25f0606e8c9fea31d10992830c7f64dcdb4e3fc94fe26697cc4229457f7aaf42229b62f52420cfe16878dd02e161d04f3bc30ec2bbed1840417b715e0c8fdf9316f1160&X-Goog-SignedHeaders=host&X-User=2931823730: HTTPSConnectionPool(host='storage.googleapis.com', port=443): Max retries exceeded with url: /wandb-production.appspot.com/2931823730-harbin-institute-of-technology/ltu-as/2p8m9dwe/conda-environment.yaml?X-Goog-Algorithm=GOOG4-RSA-SHA256&X-Goog-Credential=gorilla-files-url-signer-man%40wandb-production.iam.gserviceaccount.com%2F20250411%2Fauto%2Fstorage%2Fgoog4_request&X-Goog-Date=20250411T151314Z&X-Goog-Expires=86399&X-Goog-Signature=7bccffe4b07a3cf7a72c89a7f9ce9c4d318e83ce8565b48d1c8f6ad1e28f0ebcdffbee0466a5b02680abb5917671b4a58a7489d0f31f20b248c65bd0c9f930a4644b19cc67ee38174f54216aa249142b3c30c57a2162d76288e12d623bc786f0e3bd70267e2f8b8b1f5fa86a79cd8d97967dbffbd58e690e13bcac89903c53b61dbb15aa9ec0292990c028cd3f04bee5811a98d7e05760e37f63577946aa5dad22ec10f762d7c7411768b61b1c77b04e59a142df620d4b91315c0493f25f0606e8c9fea31d10992830c7f64dcdb4e3fc94fe26697cc4229457f7aaf42229b62f52420cfe16878dd02e161d04f3bc30ec2bbed1840417b715e0c8fdf9316f1160&X-Goog-SignedHeaders=host&X-User=2931823730 (Caused by NewConnectionError('<urllib3.connection.HTTPSConnection object at 0x7fcd90152470>: Failed to establish a new connection: [Errno 101] Network is unreachable'))
2025-04-11 15:13:32,760 ERROR   wandb-upload_3:23351 [internal_api.py:upload_file():2558] upload_file request headers: {'User-Agent': 'python-requests/2.32.3', 'Accept-Encoding': 'gzip, deflate, br', 'Accept': '*/*', 'Connection': 'keep-alive', 'Content-Length': '8281'}
2025-04-11 15:13:32,761 ERROR   wandb-upload_3:23351 [internal_api.py:upload_file():2560] upload_file response body: 
2025-04-11 15:13:33,581 DEBUG   HandlerThread:23351 [handler.py:handle_request():146] handle_request: poll_exit
2025-04-11 15:13:33,582 DEBUG   SenderThread:23351 [sender.py:send_request():407] send_request: poll_exit
2025-04-11 15:13:34,583 DEBUG   HandlerThread:23351 [handler.py:handle_request():146] handle_request: poll_exit
2025-04-11 15:13:34,584 DEBUG   SenderThread:23351 [sender.py:send_request():407] send_request: poll_exit
