2025-04-11 15:16:24,472 INFO    StreamThr :24150 [internal.py:wandb_internal():86] W&B internal server running at pid: 24150, started at: 2025-04-11 15:16:24.471661
2025-04-11 15:16:24,474 DEBUG   HandlerThread:24150 [handler.py:handle_request():146] handle_request: status
2025-04-11 15:16:24,475 INFO    WriterThread:24150 [datastore.py:open_for_write():85] open: /root/ltu-main/ltu-main/src/ltu_as/train_scripts/wandb/run-20250411_151624-gs2gbnar/run-gs2gbnar.wandb
2025-04-11 15:16:24,477 DEBUG   SenderThread:24150 [sender.py:send():380] send: header
2025-04-11 15:16:24,477 DEBUG   SenderThread:24150 [sender.py:send():380] send: run
2025-04-11 15:16:25,245 DEBUG   HandlerThread:24150 [handler.py:handle_request():146] handle_request: check_version
2025-04-11 15:16:25,303 INFO    SenderThread:24150 [dir_watcher.py:__init__():211] watching files in: /root/ltu-main/ltu-main/src/ltu_as/train_scripts/wandb/run-20250411_151624-gs2gbnar/files
2025-04-11 15:16:25,304 INFO    SenderThread:24150 [sender.py:_start_run_threads():1122] run started: gs2gbnar with start time 1744384584.468246
2025-04-11 15:16:25,304 DEBUG   SenderThread:24150 [sender.py:send_request():407] send_request: check_version
2025-04-11 15:16:25,911 DEBUG   HandlerThread:24150 [handler.py:handle_request():146] handle_request: run_start
2025-04-11 15:16:25,957 DEBUG   HandlerThread:24150 [system_info.py:__init__():32] System info init
2025-04-11 15:16:25,957 DEBUG   HandlerThread:24150 [system_info.py:__init__():47] System info init done
2025-04-11 15:16:25,957 INFO    HandlerThread:24150 [system_monitor.py:start():194] Starting system monitor
2025-04-11 15:16:25,957 INFO    SystemMonitor:24150 [system_monitor.py:_start():158] Starting system asset monitoring threads
2025-04-11 15:16:25,957 INFO    HandlerThread:24150 [system_monitor.py:probe():214] Collecting system info
2025-04-11 15:16:25,959 INFO    SystemMonitor:24150 [interfaces.py:start():190] Started cpu monitoring
2025-04-11 15:16:25,960 INFO    SystemMonitor:24150 [interfaces.py:start():190] Started disk monitoring
2025-04-11 15:16:25,961 INFO    SystemMonitor:24150 [interfaces.py:start():190] Started gpu monitoring
2025-04-11 15:16:25,962 INFO    SystemMonitor:24150 [interfaces.py:start():190] Started memory monitoring
2025-04-11 15:16:25,964 INFO    SystemMonitor:24150 [interfaces.py:start():190] Started network monitoring
2025-04-11 15:16:25,989 DEBUG   HandlerThread:24150 [system_info.py:probe():196] Probing system
2025-04-11 15:16:25,992 DEBUG   HandlerThread:24150 [gitlib.py:_init_repo():53] git repository is invalid
2025-04-11 15:16:25,992 DEBUG   HandlerThread:24150 [system_info.py:probe():244] Probing system done
2025-04-11 15:16:25,992 DEBUG   HandlerThread:24150 [system_monitor.py:probe():223] {'os': 'Linux-4.15.0-213-generic-x86_64-with-glibc2.27', 'python': '3.10.15', 'heartbeatAt': '2025-04-11T15:16:25.989909', 'startedAt': '2025-04-11T15:16:24.357528', 'docker': None, 'cuda': None, 'args': ('--base_model', '../../../pretrained_mdls/ltuas_long_noqa_a6.bin', '--data_path', '../../../openasqa/data/iemocap_preprocess_with_answers_updated.json', '--output_dir', '../exp/ltuas_ft_meld/', '--batch_size', '256', '--micro_batch_size', '1', '--num_epochs', '1', '--learning_rate', '2e-4', '--cutoff_len', '100', '--val_set_size', '0', '--lora_r', '8', '--lora_alpha', '16', '--lora_dropout', '0.05', '--lora_target_modules', '[q_proj,v_proj]', '--group_by_length', '--wandb_run_name', '../exp/ltuas_ft_meld/', '--save_steps', '30', '--trainable_params', 'all'), 'state': 'running', 'program': '/root/ltu-main/ltu-main/src/ltu_as/train_scripts/../finetune_low_resource.py', 'codePathLocal': None, 'host': 'ubuntu', 'username': 'root', 'executable': '/root/anaconda3/envs/venv_ltu/bin/python', 'cpu_count': 4, 'cpu_count_logical': 4, 'cpu_freq': {'current': 2294.598, 'min': 0.0, 'max': 0.0}, 'cpu_freq_per_core': [{'current': 2294.598, 'min': 0.0, 'max': 0.0}, {'current': 2294.598, 'min': 0.0, 'max': 0.0}, {'current': 2294.598, 'min': 0.0, 'max': 0.0}, {'current': 2294.598, 'min': 0.0, 'max': 0.0}], 'disk': {'/': {'total': 499.9882621765137, 'used': 333.62137603759766}}, 'gpu': 'NVIDIA A100-PCIE-40GB', 'gpu_count': 1, 'gpu_devices': [{'name': 'NVIDIA A100-PCIE-40GB', 'memory_total': 42949672960}], 'memory': {'total': 19.60204315185547}}
2025-04-11 15:16:25,992 INFO    HandlerThread:24150 [system_monitor.py:probe():224] Finished collecting system info
2025-04-11 15:16:25,992 INFO    HandlerThread:24150 [system_monitor.py:probe():227] Publishing system info
2025-04-11 15:16:25,992 DEBUG   HandlerThread:24150 [system_info.py:_save_pip():52] Saving list of pip packages installed into the current environment
2025-04-11 15:16:25,993 DEBUG   HandlerThread:24150 [system_info.py:_save_pip():68] Saving pip packages done
2025-04-11 15:16:25,993 DEBUG   HandlerThread:24150 [system_info.py:_save_conda():75] Saving list of conda packages installed into the current environment
2025-04-11 15:16:26,306 INFO    Thread-12 :24150 [dir_watcher.py:_on_file_created():271] file/dir created: /root/ltu-main/ltu-main/src/ltu_as/train_scripts/wandb/run-20250411_151624-gs2gbnar/files/conda-environment.yaml
2025-04-11 15:16:26,307 INFO    Thread-12 :24150 [dir_watcher.py:_on_file_created():271] file/dir created: /root/ltu-main/ltu-main/src/ltu_as/train_scripts/wandb/run-20250411_151624-gs2gbnar/files/requirements.txt
2025-04-11 15:16:38,765 DEBUG   HandlerThread:24150 [system_info.py:_save_conda():87] Saving conda packages done
2025-04-11 15:16:38,766 INFO    HandlerThread:24150 [system_monitor.py:probe():229] Finished publishing system info
2025-04-11 15:16:38,773 DEBUG   HandlerThread:24150 [handler.py:handle_request():146] handle_request: status_report
2025-04-11 15:16:38,773 DEBUG   HandlerThread:24150 [handler.py:handle_request():146] handle_request: keepalive
2025-04-11 15:16:38,773 DEBUG   HandlerThread:24150 [handler.py:handle_request():146] handle_request: status_report
2025-04-11 15:16:38,773 DEBUG   HandlerThread:24150 [handler.py:handle_request():146] handle_request: keepalive
2025-04-11 15:16:38,774 DEBUG   SenderThread:24150 [sender.py:send():380] send: files
2025-04-11 15:16:38,775 INFO    SenderThread:24150 [sender.py:_save_file():1378] saving file wandb-metadata.json with policy now
2025-04-11 15:16:38,784 DEBUG   HandlerThread:24150 [handler.py:handle_request():146] handle_request: stop_status
2025-04-11 15:16:38,784 DEBUG   SenderThread:24150 [sender.py:send_request():407] send_request: stop_status
2025-04-11 15:16:38,789 DEBUG   HandlerThread:24150 [handler.py:handle_request():146] handle_request: internal_messages
2025-04-11 15:16:39,265 DEBUG   SenderThread:24150 [sender.py:send():380] send: telemetry
2025-04-11 15:16:39,266 DEBUG   SenderThread:24150 [sender.py:send():380] send: config
2025-04-11 15:16:39,267 DEBUG   SenderThread:24150 [sender.py:send():380] send: metric
2025-04-11 15:16:39,267 DEBUG   SenderThread:24150 [sender.py:send():380] send: telemetry
2025-04-11 15:16:39,267 DEBUG   SenderThread:24150 [sender.py:send():380] send: metric
2025-04-11 15:16:39,267 WARNING SenderThread:24150 [sender.py:send_metric():1329] Seen metric with glob (shouldn't happen)
2025-04-11 15:16:39,310 INFO    Thread-12 :24150 [dir_watcher.py:_on_file_modified():288] file/dir modified: /root/ltu-main/ltu-main/src/ltu_as/train_scripts/wandb/run-20250411_151624-gs2gbnar/files/conda-environment.yaml
2025-04-11 15:16:39,310 INFO    Thread-12 :24150 [dir_watcher.py:_on_file_created():271] file/dir created: /root/ltu-main/ltu-main/src/ltu_as/train_scripts/wandb/run-20250411_151624-gs2gbnar/files/wandb-metadata.json
2025-04-11 15:16:39,311 INFO    Thread-12 :24150 [dir_watcher.py:_on_file_created():271] file/dir created: /root/ltu-main/ltu-main/src/ltu_as/train_scripts/wandb/run-20250411_151624-gs2gbnar/files/output.log
2025-04-11 15:16:39,311 ERROR   wandb-upload_0:24150 [internal_api.py:upload_file():2556] upload_file exception https://storage.googleapis.com/wandb-production.appspot.com/2931823730-harbin-institute-of-technology/ltu-as/gs2gbnar/wandb-metadata.json?X-Goog-Algorithm=GOOG4-RSA-SHA256&X-Goog-Credential=gorilla-files-url-signer-man%40wandb-production.iam.gserviceaccount.com%2F20250411%2Fauto%2Fstorage%2Fgoog4_request&X-Goog-Date=20250411T151639Z&X-Goog-Expires=86399&X-Goog-Signature=5358ca8dd9178c4042e124f62db7893b63346358194f1da9a4d617801f22a15ce1898e415c6bc81a291800b9d1fba488090f88e72655d7a708641f38364f2c188d57866d5c8f035bec72fa5a8c6637e6f20c39a4c0878b4e2b2b22a4792d1274965eab5aacfe5862afa85396edfccc273305e9880d4297a63a1a09c769628ae6c103adcbb85b62b16db6738d7f84d84b22fd45e872a4668482bfa764cfbe74bb81128a0611ed2a4b218b06e200dc688d1b08120e942417d07a985bac42313c6daca9c94b9c3fcce9e59ac6b7c25bfdccb587b8a9496765bc766ed3e50c88534ad6970afd5ee5195f27724e38d72c90202a619e2a34a4c7f9a434fdbf76d5918d&X-Goog-SignedHeaders=host&X-User=2931823730: HTTPSConnectionPool(host='storage.googleapis.com', port=443): Max retries exceeded with url: /wandb-production.appspot.com/2931823730-harbin-institute-of-technology/ltu-as/gs2gbnar/wandb-metadata.json?X-Goog-Algorithm=GOOG4-RSA-SHA256&X-Goog-Credential=gorilla-files-url-signer-man%40wandb-production.iam.gserviceaccount.com%2F20250411%2Fauto%2Fstorage%2Fgoog4_request&X-Goog-Date=20250411T151639Z&X-Goog-Expires=86399&X-Goog-Signature=5358ca8dd9178c4042e124f62db7893b63346358194f1da9a4d617801f22a15ce1898e415c6bc81a291800b9d1fba488090f88e72655d7a708641f38364f2c188d57866d5c8f035bec72fa5a8c6637e6f20c39a4c0878b4e2b2b22a4792d1274965eab5aacfe5862afa85396edfccc273305e9880d4297a63a1a09c769628ae6c103adcbb85b62b16db6738d7f84d84b22fd45e872a4668482bfa764cfbe74bb81128a0611ed2a4b218b06e200dc688d1b08120e942417d07a985bac42313c6daca9c94b9c3fcce9e59ac6b7c25bfdccb587b8a9496765bc766ed3e50c88534ad6970afd5ee5195f27724e38d72c90202a619e2a34a4c7f9a434fdbf76d5918d&X-Goog-SignedHeaders=host&X-User=2931823730 (Caused by NewConnectionError('<urllib3.connection.HTTPSConnection object at 0x7faf0c101900>: Failed to establish a new connection: [Errno 101] Network is unreachable'))
2025-04-11 15:16:39,311 ERROR   wandb-upload_0:24150 [internal_api.py:upload_file():2558] upload_file request headers: {'User-Agent': 'python-requests/2.32.3', 'Accept-Encoding': 'gzip, deflate, br', 'Accept': '*/*', 'Connection': 'keep-alive', 'Content-Length': '2274'}
2025-04-11 15:16:39,311 ERROR   wandb-upload_0:24150 [internal_api.py:upload_file():2560] upload_file response body: 
2025-04-11 15:16:40,268 DEBUG   HandlerThread:24150 [handler.py:handle_request():146] handle_request: status_report
2025-04-11 15:16:40,499 ERROR   wandb-upload_0:24150 [internal_api.py:upload_file():2556] upload_file exception https://storage.googleapis.com/wandb-production.appspot.com/2931823730-harbin-institute-of-technology/ltu-as/gs2gbnar/wandb-metadata.json?X-Goog-Algorithm=GOOG4-RSA-SHA256&X-Goog-Credential=gorilla-files-url-signer-man%40wandb-production.iam.gserviceaccount.com%2F20250411%2Fauto%2Fstorage%2Fgoog4_request&X-Goog-Date=20250411T151639Z&X-Goog-Expires=86399&X-Goog-Signature=5358ca8dd9178c4042e124f62db7893b63346358194f1da9a4d617801f22a15ce1898e415c6bc81a291800b9d1fba488090f88e72655d7a708641f38364f2c188d57866d5c8f035bec72fa5a8c6637e6f20c39a4c0878b4e2b2b22a4792d1274965eab5aacfe5862afa85396edfccc273305e9880d4297a63a1a09c769628ae6c103adcbb85b62b16db6738d7f84d84b22fd45e872a4668482bfa764cfbe74bb81128a0611ed2a4b218b06e200dc688d1b08120e942417d07a985bac42313c6daca9c94b9c3fcce9e59ac6b7c25bfdccb587b8a9496765bc766ed3e50c88534ad6970afd5ee5195f27724e38d72c90202a619e2a34a4c7f9a434fdbf76d5918d&X-Goog-SignedHeaders=host&X-User=2931823730: HTTPSConnectionPool(host='storage.googleapis.com', port=443): Max retries exceeded with url: /wandb-production.appspot.com/2931823730-harbin-institute-of-technology/ltu-as/gs2gbnar/wandb-metadata.json?X-Goog-Algorithm=GOOG4-RSA-SHA256&X-Goog-Credential=gorilla-files-url-signer-man%40wandb-production.iam.gserviceaccount.com%2F20250411%2Fauto%2Fstorage%2Fgoog4_request&X-Goog-Date=20250411T151639Z&X-Goog-Expires=86399&X-Goog-Signature=5358ca8dd9178c4042e124f62db7893b63346358194f1da9a4d617801f22a15ce1898e415c6bc81a291800b9d1fba488090f88e72655d7a708641f38364f2c188d57866d5c8f035bec72fa5a8c6637e6f20c39a4c0878b4e2b2b22a4792d1274965eab5aacfe5862afa85396edfccc273305e9880d4297a63a1a09c769628ae6c103adcbb85b62b16db6738d7f84d84b22fd45e872a4668482bfa764cfbe74bb81128a0611ed2a4b218b06e200dc688d1b08120e942417d07a985bac42313c6daca9c94b9c3fcce9e59ac6b7c25bfdccb587b8a9496765bc766ed3e50c88534ad6970afd5ee5195f27724e38d72c90202a619e2a34a4c7f9a434fdbf76d5918d&X-Goog-SignedHeaders=host&X-User=2931823730 (Caused by NewConnectionError('<urllib3.connection.HTTPSConnection object at 0x7faf0c100670>: Failed to establish a new connection: [Errno 101] Network is unreachable'))
2025-04-11 15:16:40,499 ERROR   wandb-upload_0:24150 [internal_api.py:upload_file():2558] upload_file request headers: {'User-Agent': 'python-requests/2.32.3', 'Accept-Encoding': 'gzip, deflate, br', 'Accept': '*/*', 'Connection': 'keep-alive', 'Content-Length': '2274'}
2025-04-11 15:16:40,499 ERROR   wandb-upload_0:24150 [internal_api.py:upload_file():2560] upload_file response body: 
2025-04-11 15:16:41,310 INFO    Thread-12 :24150 [dir_watcher.py:_on_file_modified():288] file/dir modified: /root/ltu-main/ltu-main/src/ltu_as/train_scripts/wandb/run-20250411_151624-gs2gbnar/files/output.log
2025-04-11 15:16:42,762 ERROR   wandb-upload_0:24150 [internal_api.py:upload_file():2556] upload_file exception https://storage.googleapis.com/wandb-production.appspot.com/2931823730-harbin-institute-of-technology/ltu-as/gs2gbnar/wandb-metadata.json?X-Goog-Algorithm=GOOG4-RSA-SHA256&X-Goog-Credential=gorilla-files-url-signer-man%40wandb-production.iam.gserviceaccount.com%2F20250411%2Fauto%2Fstorage%2Fgoog4_request&X-Goog-Date=20250411T151639Z&X-Goog-Expires=86399&X-Goog-Signature=5358ca8dd9178c4042e124f62db7893b63346358194f1da9a4d617801f22a15ce1898e415c6bc81a291800b9d1fba488090f88e72655d7a708641f38364f2c188d57866d5c8f035bec72fa5a8c6637e6f20c39a4c0878b4e2b2b22a4792d1274965eab5aacfe5862afa85396edfccc273305e9880d4297a63a1a09c769628ae6c103adcbb85b62b16db6738d7f84d84b22fd45e872a4668482bfa764cfbe74bb81128a0611ed2a4b218b06e200dc688d1b08120e942417d07a985bac42313c6daca9c94b9c3fcce9e59ac6b7c25bfdccb587b8a9496765bc766ed3e50c88534ad6970afd5ee5195f27724e38d72c90202a619e2a34a4c7f9a434fdbf76d5918d&X-Goog-SignedHeaders=host&X-User=2931823730: HTTPSConnectionPool(host='storage.googleapis.com', port=443): Max retries exceeded with url: /wandb-production.appspot.com/2931823730-harbin-institute-of-technology/ltu-as/gs2gbnar/wandb-metadata.json?X-Goog-Algorithm=GOOG4-RSA-SHA256&X-Goog-Credential=gorilla-files-url-signer-man%40wandb-production.iam.gserviceaccount.com%2F20250411%2Fauto%2Fstorage%2Fgoog4_request&X-Goog-Date=20250411T151639Z&X-Goog-Expires=86399&X-Goog-Signature=5358ca8dd9178c4042e124f62db7893b63346358194f1da9a4d617801f22a15ce1898e415c6bc81a291800b9d1fba488090f88e72655d7a708641f38364f2c188d57866d5c8f035bec72fa5a8c6637e6f20c39a4c0878b4e2b2b22a4792d1274965eab5aacfe5862afa85396edfccc273305e9880d4297a63a1a09c769628ae6c103adcbb85b62b16db6738d7f84d84b22fd45e872a4668482bfa764cfbe74bb81128a0611ed2a4b218b06e200dc688d1b08120e942417d07a985bac42313c6daca9c94b9c3fcce9e59ac6b7c25bfdccb587b8a9496765bc766ed3e50c88534ad6970afd5ee5195f27724e38d72c90202a619e2a34a4c7f9a434fdbf76d5918d&X-Goog-SignedHeaders=host&X-User=2931823730 (Caused by NewConnectionError('<urllib3.connection.HTTPSConnection object at 0x7faf0c102500>: Failed to establish a new connection: [Errno 101] Network is unreachable'))
2025-04-11 15:16:42,762 ERROR   wandb-upload_0:24150 [internal_api.py:upload_file():2558] upload_file request headers: {'User-Agent': 'python-requests/2.32.3', 'Accept-Encoding': 'gzip, deflate, br', 'Accept': '*/*', 'Connection': 'keep-alive', 'Content-Length': '2274'}
2025-04-11 15:16:42,762 ERROR   wandb-upload_0:24150 [internal_api.py:upload_file():2560] upload_file response body: 
2025-04-11 15:16:42,762 INFO    wandb-upload_0:24150 [retry.py:__call__():172] Retry attempt failed:
Traceback (most recent call last):
  File "/root/anaconda3/envs/venv_ltu/lib/python3.10/site-packages/urllib3/connection.py", line 198, in _new_conn
    sock = connection.create_connection(
  File "/root/anaconda3/envs/venv_ltu/lib/python3.10/site-packages/urllib3/util/connection.py", line 85, in create_connection
    raise err
  File "/root/anaconda3/envs/venv_ltu/lib/python3.10/site-packages/urllib3/util/connection.py", line 73, in create_connection
    sock.connect(sa)
OSError: [Errno 101] Network is unreachable

The above exception was the direct cause of the following exception:

Traceback (most recent call last):
  File "/root/anaconda3/envs/venv_ltu/lib/python3.10/site-packages/urllib3/connectionpool.py", line 793, in urlopen
    response = self._make_request(
  File "/root/anaconda3/envs/venv_ltu/lib/python3.10/site-packages/urllib3/connectionpool.py", line 491, in _make_request
    raise new_e
  File "/root/anaconda3/envs/venv_ltu/lib/python3.10/site-packages/urllib3/connectionpool.py", line 467, in _make_request
    self._validate_conn(conn)
  File "/root/anaconda3/envs/venv_ltu/lib/python3.10/site-packages/urllib3/connectionpool.py", line 1099, in _validate_conn
    conn.connect()
  File "/root/anaconda3/envs/venv_ltu/lib/python3.10/site-packages/urllib3/connection.py", line 616, in connect
    self.sock = sock = self._new_conn()
  File "/root/anaconda3/envs/venv_ltu/lib/python3.10/site-packages/urllib3/connection.py", line 213, in _new_conn
    raise NewConnectionError(
urllib3.exceptions.NewConnectionError: <urllib3.connection.HTTPSConnection object at 0x7faf0c102500>: Failed to establish a new connection: [Errno 101] Network is unreachable

The above exception was the direct cause of the following exception:

Traceback (most recent call last):
  File "/root/anaconda3/envs/venv_ltu/lib/python3.10/site-packages/requests/adapters.py", line 667, in send
    resp = conn.urlopen(
  File "/root/anaconda3/envs/venv_ltu/lib/python3.10/site-packages/urllib3/connectionpool.py", line 847, in urlopen
    retries = retries.increment(
  File "/root/anaconda3/envs/venv_ltu/lib/python3.10/site-packages/urllib3/util/retry.py", line 515, in increment
    raise MaxRetryError(_pool, url, reason) from reason  # type: ignore[arg-type]
urllib3.exceptions.MaxRetryError: HTTPSConnectionPool(host='storage.googleapis.com', port=443): Max retries exceeded with url: /wandb-production.appspot.com/2931823730-harbin-institute-of-technology/ltu-as/gs2gbnar/wandb-metadata.json?X-Goog-Algorithm=GOOG4-RSA-SHA256&X-Goog-Credential=gorilla-files-url-signer-man%40wandb-production.iam.gserviceaccount.com%2F20250411%2Fauto%2Fstorage%2Fgoog4_request&X-Goog-Date=20250411T151639Z&X-Goog-Expires=86399&X-Goog-Signature=5358ca8dd9178c4042e124f62db7893b63346358194f1da9a4d617801f22a15ce1898e415c6bc81a291800b9d1fba488090f88e72655d7a708641f38364f2c188d57866d5c8f035bec72fa5a8c6637e6f20c39a4c0878b4e2b2b22a4792d1274965eab5aacfe5862afa85396edfccc273305e9880d4297a63a1a09c769628ae6c103adcbb85b62b16db6738d7f84d84b22fd45e872a4668482bfa764cfbe74bb81128a0611ed2a4b218b06e200dc688d1b08120e942417d07a985bac42313c6daca9c94b9c3fcce9e59ac6b7c25bfdccb587b8a9496765bc766ed3e50c88534ad6970afd5ee5195f27724e38d72c90202a619e2a34a4c7f9a434fdbf76d5918d&X-Goog-SignedHeaders=host&X-User=2931823730 (Caused by NewConnectionError('<urllib3.connection.HTTPSConnection object at 0x7faf0c102500>: Failed to establish a new connection: [Errno 101] Network is unreachable'))

During handling of the above exception, another exception occurred:

Traceback (most recent call last):
  File "/root/anaconda3/envs/venv_ltu/lib/python3.10/site-packages/wandb/sdk/internal/internal_api.py", line 2549, in upload_file
    response = self._upload_file_session.put(
  File "/root/anaconda3/envs/venv_ltu/lib/python3.10/site-packages/requests/sessions.py", line 649, in put
    return self.request("PUT", url, data=data, **kwargs)
  File "/root/anaconda3/envs/venv_ltu/lib/python3.10/site-packages/requests/sessions.py", line 589, in request
    resp = self.send(prep, **send_kwargs)
  File "/root/anaconda3/envs/venv_ltu/lib/python3.10/site-packages/requests/sessions.py", line 703, in send
    r = adapter.send(request, **kwargs)
  File "/root/anaconda3/envs/venv_ltu/lib/python3.10/site-packages/requests/adapters.py", line 700, in send
    raise ConnectionError(e, request=request)
requests.exceptions.ConnectionError: HTTPSConnectionPool(host='storage.googleapis.com', port=443): Max retries exceeded with url: /wandb-production.appspot.com/2931823730-harbin-institute-of-technology/ltu-as/gs2gbnar/wandb-metadata.json?X-Goog-Algorithm=GOOG4-RSA-SHA256&X-Goog-Credential=gorilla-files-url-signer-man%40wandb-production.iam.gserviceaccount.com%2F20250411%2Fauto%2Fstorage%2Fgoog4_request&X-Goog-Date=20250411T151639Z&X-Goog-Expires=86399&X-Goog-Signature=5358ca8dd9178c4042e124f62db7893b63346358194f1da9a4d617801f22a15ce1898e415c6bc81a291800b9d1fba488090f88e72655d7a708641f38364f2c188d57866d5c8f035bec72fa5a8c6637e6f20c39a4c0878b4e2b2b22a4792d1274965eab5aacfe5862afa85396edfccc273305e9880d4297a63a1a09c769628ae6c103adcbb85b62b16db6738d7f84d84b22fd45e872a4668482bfa764cfbe74bb81128a0611ed2a4b218b06e200dc688d1b08120e942417d07a985bac42313c6daca9c94b9c3fcce9e59ac6b7c25bfdccb587b8a9496765bc766ed3e50c88534ad6970afd5ee5195f27724e38d72c90202a619e2a34a4c7f9a434fdbf76d5918d&X-Goog-SignedHeaders=host&X-User=2931823730 (Caused by NewConnectionError('<urllib3.connection.HTTPSConnection object at 0x7faf0c102500>: Failed to establish a new connection: [Errno 101] Network is unreachable'))

During handling of the above exception, another exception occurred:

Traceback (most recent call last):
  File "/root/anaconda3/envs/venv_ltu/lib/python3.10/site-packages/wandb/sdk/lib/retry.py", line 131, in __call__
    result = self._call_fn(*args, **kwargs)
  File "/root/anaconda3/envs/venv_ltu/lib/python3.10/site-packages/wandb/sdk/internal/internal_api.py", line 2580, in upload_file
    raise _e.with_traceback(sys.exc_info()[2])
  File "/root/anaconda3/envs/venv_ltu/lib/python3.10/site-packages/wandb/sdk/internal/internal_api.py", line 2549, in upload_file
    response = self._upload_file_session.put(
  File "/root/anaconda3/envs/venv_ltu/lib/python3.10/site-packages/requests/sessions.py", line 649, in put
    return self.request("PUT", url, data=data, **kwargs)
  File "/root/anaconda3/envs/venv_ltu/lib/python3.10/site-packages/requests/sessions.py", line 589, in request
    resp = self.send(prep, **send_kwargs)
  File "/root/anaconda3/envs/venv_ltu/lib/python3.10/site-packages/requests/sessions.py", line 703, in send
    r = adapter.send(request, **kwargs)
  File "/root/anaconda3/envs/venv_ltu/lib/python3.10/site-packages/requests/adapters.py", line 700, in send
    raise ConnectionError(e, request=request)
wandb.sdk.lib.retry.TransientError: None
2025-04-11 15:16:45,269 DEBUG   HandlerThread:24150 [handler.py:handle_request():146] handle_request: status_report
2025-04-11 15:16:47,893 ERROR   wandb-upload_0:24150 [internal_api.py:upload_file():2556] upload_file exception https://storage.googleapis.com/wandb-production.appspot.com/2931823730-harbin-institute-of-technology/ltu-as/gs2gbnar/wandb-metadata.json?X-Goog-Algorithm=GOOG4-RSA-SHA256&X-Goog-Credential=gorilla-files-url-signer-man%40wandb-production.iam.gserviceaccount.com%2F20250411%2Fauto%2Fstorage%2Fgoog4_request&X-Goog-Date=20250411T151639Z&X-Goog-Expires=86399&X-Goog-Signature=5358ca8dd9178c4042e124f62db7893b63346358194f1da9a4d617801f22a15ce1898e415c6bc81a291800b9d1fba488090f88e72655d7a708641f38364f2c188d57866d5c8f035bec72fa5a8c6637e6f20c39a4c0878b4e2b2b22a4792d1274965eab5aacfe5862afa85396edfccc273305e9880d4297a63a1a09c769628ae6c103adcbb85b62b16db6738d7f84d84b22fd45e872a4668482bfa764cfbe74bb81128a0611ed2a4b218b06e200dc688d1b08120e942417d07a985bac42313c6daca9c94b9c3fcce9e59ac6b7c25bfdccb587b8a9496765bc766ed3e50c88534ad6970afd5ee5195f27724e38d72c90202a619e2a34a4c7f9a434fdbf76d5918d&X-Goog-SignedHeaders=host&X-User=2931823730: HTTPSConnectionPool(host='storage.googleapis.com', port=443): Max retries exceeded with url: /wandb-production.appspot.com/2931823730-harbin-institute-of-technology/ltu-as/gs2gbnar/wandb-metadata.json?X-Goog-Algorithm=GOOG4-RSA-SHA256&X-Goog-Credential=gorilla-files-url-signer-man%40wandb-production.iam.gserviceaccount.com%2F20250411%2Fauto%2Fstorage%2Fgoog4_request&X-Goog-Date=20250411T151639Z&X-Goog-Expires=86399&X-Goog-Signature=5358ca8dd9178c4042e124f62db7893b63346358194f1da9a4d617801f22a15ce1898e415c6bc81a291800b9d1fba488090f88e72655d7a708641f38364f2c188d57866d5c8f035bec72fa5a8c6637e6f20c39a4c0878b4e2b2b22a4792d1274965eab5aacfe5862afa85396edfccc273305e9880d4297a63a1a09c769628ae6c103adcbb85b62b16db6738d7f84d84b22fd45e872a4668482bfa764cfbe74bb81128a0611ed2a4b218b06e200dc688d1b08120e942417d07a985bac42313c6daca9c94b9c3fcce9e59ac6b7c25bfdccb587b8a9496765bc766ed3e50c88534ad6970afd5ee5195f27724e38d72c90202a619e2a34a4c7f9a434fdbf76d5918d&X-Goog-SignedHeaders=host&X-User=2931823730 (Caused by NewConnectionError('<urllib3.connection.HTTPSConnection object at 0x7faf0c101cf0>: Failed to establish a new connection: [Errno 101] Network is unreachable'))
2025-04-11 15:16:47,893 ERROR   wandb-upload_0:24150 [internal_api.py:upload_file():2558] upload_file request headers: {'User-Agent': 'python-requests/2.32.3', 'Accept-Encoding': 'gzip, deflate, br', 'Accept': '*/*', 'Connection': 'keep-alive', 'Content-Length': '2274'}
2025-04-11 15:16:47,893 ERROR   wandb-upload_0:24150 [internal_api.py:upload_file():2560] upload_file response body: 
2025-04-11 15:16:50,275 DEBUG   HandlerThread:24150 [handler.py:handle_request():146] handle_request: status_report
2025-04-11 15:16:50,277 DEBUG   SenderThread:24150 [sender.py:send():380] send: exit
2025-04-11 15:16:50,277 INFO    SenderThread:24150 [sender.py:send_exit():585] handling exit code: 1
2025-04-11 15:16:50,277 INFO    SenderThread:24150 [sender.py:send_exit():587] handling runtime: 24
2025-04-11 15:16:50,277 INFO    SenderThread:24150 [sender.py:_save_file():1378] saving file wandb-summary.json with policy end
2025-04-11 15:16:50,277 INFO    SenderThread:24150 [sender.py:send_exit():593] send defer
2025-04-11 15:16:50,279 DEBUG   HandlerThread:24150 [handler.py:handle_request():146] handle_request: defer
2025-04-11 15:16:50,279 INFO    HandlerThread:24150 [handler.py:handle_request_defer():172] handle defer: 0
2025-04-11 15:16:50,280 DEBUG   SenderThread:24150 [sender.py:send_request():407] send_request: defer
2025-04-11 15:16:50,280 INFO    SenderThread:24150 [sender.py:send_request_defer():609] handle sender defer: 0
2025-04-11 15:16:50,280 INFO    SenderThread:24150 [sender.py:transition_state():613] send defer: 1
2025-04-11 15:16:50,280 DEBUG   HandlerThread:24150 [handler.py:handle_request():146] handle_request: defer
2025-04-11 15:16:50,280 INFO    HandlerThread:24150 [handler.py:handle_request_defer():172] handle defer: 1
2025-04-11 15:16:50,281 DEBUG   SenderThread:24150 [sender.py:send_request():407] send_request: defer
2025-04-11 15:16:50,281 INFO    SenderThread:24150 [sender.py:send_request_defer():609] handle sender defer: 1
2025-04-11 15:16:50,281 INFO    SenderThread:24150 [sender.py:transition_state():613] send defer: 2
2025-04-11 15:16:50,281 DEBUG   HandlerThread:24150 [handler.py:handle_request():146] handle_request: defer
2025-04-11 15:16:50,281 INFO    HandlerThread:24150 [handler.py:handle_request_defer():172] handle defer: 2
2025-04-11 15:16:50,281 INFO    HandlerThread:24150 [system_monitor.py:finish():203] Stopping system monitor
2025-04-11 15:16:50,281 DEBUG   SystemMonitor:24150 [system_monitor.py:_start():172] Starting system metrics aggregation loop
2025-04-11 15:16:50,282 INFO    HandlerThread:24150 [interfaces.py:finish():202] Joined cpu monitor
2025-04-11 15:16:50,282 DEBUG   SystemMonitor:24150 [system_monitor.py:_start():179] Finished system metrics aggregation loop
2025-04-11 15:16:50,282 DEBUG   SystemMonitor:24150 [system_monitor.py:_start():183] Publishing last batch of metrics
2025-04-11 15:16:50,282 INFO    HandlerThread:24150 [interfaces.py:finish():202] Joined disk monitor
2025-04-11 15:16:50,314 INFO    Thread-12 :24150 [dir_watcher.py:_on_file_created():271] file/dir created: /root/ltu-main/ltu-main/src/ltu_as/train_scripts/wandb/run-20250411_151624-gs2gbnar/files/wandb-summary.json
2025-04-11 15:16:50,318 INFO    HandlerThread:24150 [interfaces.py:finish():202] Joined gpu monitor
2025-04-11 15:16:50,319 INFO    HandlerThread:24150 [interfaces.py:finish():202] Joined memory monitor
2025-04-11 15:16:50,319 INFO    HandlerThread:24150 [interfaces.py:finish():202] Joined network monitor
2025-04-11 15:16:50,320 DEBUG   SenderThread:24150 [sender.py:send_request():407] send_request: defer
2025-04-11 15:16:50,320 INFO    SenderThread:24150 [sender.py:send_request_defer():609] handle sender defer: 2
2025-04-11 15:16:50,320 INFO    SenderThread:24150 [sender.py:transition_state():613] send defer: 3
2025-04-11 15:16:50,320 DEBUG   SenderThread:24150 [sender.py:send():380] send: stats
2025-04-11 15:16:50,321 DEBUG   HandlerThread:24150 [handler.py:handle_request():146] handle_request: defer
2025-04-11 15:16:50,321 INFO    HandlerThread:24150 [handler.py:handle_request_defer():172] handle defer: 3
2025-04-11 15:16:50,321 DEBUG   SenderThread:24150 [sender.py:send_request():407] send_request: defer
2025-04-11 15:16:50,321 INFO    SenderThread:24150 [sender.py:send_request_defer():609] handle sender defer: 3
2025-04-11 15:16:50,321 INFO    SenderThread:24150 [sender.py:transition_state():613] send defer: 4
2025-04-11 15:16:50,322 DEBUG   HandlerThread:24150 [handler.py:handle_request():146] handle_request: defer
2025-04-11 15:16:50,322 INFO    HandlerThread:24150 [handler.py:handle_request_defer():172] handle defer: 4
2025-04-11 15:16:50,322 DEBUG   SenderThread:24150 [sender.py:send_request():407] send_request: defer
2025-04-11 15:16:50,322 INFO    SenderThread:24150 [sender.py:send_request_defer():609] handle sender defer: 4
2025-04-11 15:16:50,322 INFO    SenderThread:24150 [sender.py:transition_state():613] send defer: 5
2025-04-11 15:16:50,323 DEBUG   HandlerThread:24150 [handler.py:handle_request():146] handle_request: defer
2025-04-11 15:16:50,323 INFO    HandlerThread:24150 [handler.py:handle_request_defer():172] handle defer: 5
2025-04-11 15:16:50,323 DEBUG   SenderThread:24150 [sender.py:send():380] send: summary
2025-04-11 15:16:50,359 INFO    SenderThread:24150 [sender.py:_save_file():1378] saving file wandb-summary.json with policy end
2025-04-11 15:16:50,359 DEBUG   SenderThread:24150 [sender.py:send_request():407] send_request: defer
2025-04-11 15:16:50,359 INFO    SenderThread:24150 [sender.py:send_request_defer():609] handle sender defer: 5
2025-04-11 15:16:50,359 INFO    SenderThread:24150 [sender.py:transition_state():613] send defer: 6
2025-04-11 15:16:50,360 DEBUG   HandlerThread:24150 [handler.py:handle_request():146] handle_request: defer
2025-04-11 15:16:50,360 INFO    HandlerThread:24150 [handler.py:handle_request_defer():172] handle defer: 6
2025-04-11 15:16:50,360 DEBUG   SenderThread:24150 [sender.py:send_request():407] send_request: defer
2025-04-11 15:16:50,360 INFO    SenderThread:24150 [sender.py:send_request_defer():609] handle sender defer: 6
2025-04-11 15:16:50,366 DEBUG   HandlerThread:24150 [handler.py:handle_request():146] handle_request: status_report
2025-04-11 15:16:50,761 INFO    SenderThread:24150 [sender.py:transition_state():613] send defer: 7
2025-04-11 15:16:50,761 DEBUG   HandlerThread:24150 [handler.py:handle_request():146] handle_request: defer
2025-04-11 15:16:50,761 INFO    HandlerThread:24150 [handler.py:handle_request_defer():172] handle defer: 7
2025-04-11 15:16:50,762 DEBUG   SenderThread:24150 [sender.py:send_request():407] send_request: defer
2025-04-11 15:16:50,762 INFO    SenderThread:24150 [sender.py:send_request_defer():609] handle sender defer: 7
2025-04-11 15:16:51,275 DEBUG   HandlerThread:24150 [handler.py:handle_request():146] handle_request: poll_exit
2025-04-11 15:16:51,295 INFO    SenderThread:24150 [sender.py:transition_state():613] send defer: 8
2025-04-11 15:16:51,295 DEBUG   SenderThread:24150 [sender.py:send_request():407] send_request: poll_exit
2025-04-11 15:16:51,295 DEBUG   HandlerThread:24150 [handler.py:handle_request():146] handle_request: defer
2025-04-11 15:16:51,296 INFO    HandlerThread:24150 [handler.py:handle_request_defer():172] handle defer: 8
2025-04-11 15:16:51,296 DEBUG   SenderThread:24150 [sender.py:send_request():407] send_request: defer
2025-04-11 15:16:51,296 INFO    SenderThread:24150 [sender.py:send_request_defer():609] handle sender defer: 8
2025-04-11 15:16:51,296 INFO    SenderThread:24150 [job_builder.py:build():281] Attempting to build job artifact
2025-04-11 15:16:51,297 INFO    SenderThread:24150 [job_builder.py:_get_source_type():404] no source found
2025-04-11 15:16:51,297 INFO    SenderThread:24150 [sender.py:transition_state():613] send defer: 9
2025-04-11 15:16:51,297 DEBUG   HandlerThread:24150 [handler.py:handle_request():146] handle_request: defer
2025-04-11 15:16:51,297 INFO    HandlerThread:24150 [handler.py:handle_request_defer():172] handle defer: 9
2025-04-11 15:16:51,298 DEBUG   SenderThread:24150 [sender.py:send_request():407] send_request: defer
2025-04-11 15:16:51,298 INFO    SenderThread:24150 [sender.py:send_request_defer():609] handle sender defer: 9
2025-04-11 15:16:51,298 INFO    SenderThread:24150 [dir_watcher.py:finish():358] shutting down directory watcher
2025-04-11 15:16:51,314 INFO    Thread-12 :24150 [dir_watcher.py:_on_file_modified():288] file/dir modified: /root/ltu-main/ltu-main/src/ltu_as/train_scripts/wandb/run-20250411_151624-gs2gbnar/files/wandb-summary.json
2025-04-11 15:16:51,315 INFO    SenderThread:24150 [dir_watcher.py:_on_file_modified():288] file/dir modified: /root/ltu-main/ltu-main/src/ltu_as/train_scripts/wandb/run-20250411_151624-gs2gbnar/files/config.yaml
2025-04-11 15:16:51,315 INFO    SenderThread:24150 [dir_watcher.py:_on_file_modified():288] file/dir modified: /root/ltu-main/ltu-main/src/ltu_as/train_scripts/wandb/run-20250411_151624-gs2gbnar/files/output.log
2025-04-11 15:16:51,315 INFO    SenderThread:24150 [dir_watcher.py:finish():388] scan: /root/ltu-main/ltu-main/src/ltu_as/train_scripts/wandb/run-20250411_151624-gs2gbnar/files
2025-04-11 15:16:51,315 INFO    SenderThread:24150 [dir_watcher.py:finish():402] scan save: /root/ltu-main/ltu-main/src/ltu_as/train_scripts/wandb/run-20250411_151624-gs2gbnar/files/config.yaml config.yaml
2025-04-11 15:16:51,316 INFO    SenderThread:24150 [dir_watcher.py:finish():402] scan save: /root/ltu-main/ltu-main/src/ltu_as/train_scripts/wandb/run-20250411_151624-gs2gbnar/files/requirements.txt requirements.txt
2025-04-11 15:16:51,319 INFO    SenderThread:24150 [dir_watcher.py:finish():402] scan save: /root/ltu-main/ltu-main/src/ltu_as/train_scripts/wandb/run-20250411_151624-gs2gbnar/files/conda-environment.yaml conda-environment.yaml
2025-04-11 15:16:51,323 INFO    SenderThread:24150 [dir_watcher.py:finish():402] scan save: /root/ltu-main/ltu-main/src/ltu_as/train_scripts/wandb/run-20250411_151624-gs2gbnar/files/wandb-metadata.json wandb-metadata.json
2025-04-11 15:16:51,323 INFO    SenderThread:24150 [dir_watcher.py:finish():402] scan save: /root/ltu-main/ltu-main/src/ltu_as/train_scripts/wandb/run-20250411_151624-gs2gbnar/files/output.log output.log
2025-04-11 15:16:51,327 INFO    SenderThread:24150 [dir_watcher.py:finish():402] scan save: /root/ltu-main/ltu-main/src/ltu_as/train_scripts/wandb/run-20250411_151624-gs2gbnar/files/wandb-summary.json wandb-summary.json
2025-04-11 15:16:51,329 INFO    SenderThread:24150 [sender.py:transition_state():613] send defer: 10
2025-04-11 15:16:51,331 DEBUG   HandlerThread:24150 [handler.py:handle_request():146] handle_request: defer
2025-04-11 15:16:51,331 INFO    HandlerThread:24150 [handler.py:handle_request_defer():172] handle defer: 10
2025-04-11 15:16:51,332 DEBUG   SenderThread:24150 [sender.py:send_request():407] send_request: defer
2025-04-11 15:16:51,332 INFO    SenderThread:24150 [sender.py:send_request_defer():609] handle sender defer: 10
2025-04-11 15:16:51,332 INFO    SenderThread:24150 [file_pusher.py:finish():175] shutting down file pusher
2025-04-11 15:16:51,601 ERROR   wandb-upload_2:24150 [internal_api.py:upload_file():2556] upload_file exception https://storage.googleapis.com/wandb-production.appspot.com/2931823730-harbin-institute-of-technology/ltu-as/gs2gbnar/requirements.txt?X-Goog-Algorithm=GOOG4-RSA-SHA256&X-Goog-Credential=gorilla-files-url-signer-man%40wandb-production.iam.gserviceaccount.com%2F20250411%2Fauto%2Fstorage%2Fgoog4_request&X-Goog-Date=20250411T151651Z&X-Goog-Expires=86399&X-Goog-Signature=abe2767048a665ae692f042124a97fcaab2586fd27692787eae806db284e475580ee0a12dacc4f8c249c8fa01108de939fea9731e921583f5d759548cc605e67740521dc4b8e1747a7414e648b5653b9fbc1c06ec67ec6b4e64d0264d440d3638e45ae3c3c06ac040c5cd8185b6699856ce0631553cfc99cf32e0c4e28746bf95038df96fddc4af2947ed5270d32abc379aa7dc9f494894612ebac60b3fb9ca8f1070ec8abfc84531a916a32e9c9b558ab565519332033e79d24602a77ff6219c45b5940c48fd3d22edf7675d51eb9b8d81bbef3383707c861521ded9c97e05550161527ff961a00782fc508f2cd7a84d4b5cca95f89d511f396237dc4d9d2f9&X-Goog-SignedHeaders=host&X-User=2931823730: HTTPSConnectionPool(host='storage.googleapis.com', port=443): Max retries exceeded with url: /wandb-production.appspot.com/2931823730-harbin-institute-of-technology/ltu-as/gs2gbnar/requirements.txt?X-Goog-Algorithm=GOOG4-RSA-SHA256&X-Goog-Credential=gorilla-files-url-signer-man%40wandb-production.iam.gserviceaccount.com%2F20250411%2Fauto%2Fstorage%2Fgoog4_request&X-Goog-Date=20250411T151651Z&X-Goog-Expires=86399&X-Goog-Signature=abe2767048a665ae692f042124a97fcaab2586fd27692787eae806db284e475580ee0a12dacc4f8c249c8fa01108de939fea9731e921583f5d759548cc605e67740521dc4b8e1747a7414e648b5653b9fbc1c06ec67ec6b4e64d0264d440d3638e45ae3c3c06ac040c5cd8185b6699856ce0631553cfc99cf32e0c4e28746bf95038df96fddc4af2947ed5270d32abc379aa7dc9f494894612ebac60b3fb9ca8f1070ec8abfc84531a916a32e9c9b558ab565519332033e79d24602a77ff6219c45b5940c48fd3d22edf7675d51eb9b8d81bbef3383707c861521ded9c97e05550161527ff961a00782fc508f2cd7a84d4b5cca95f89d511f396237dc4d9d2f9&X-Goog-SignedHeaders=host&X-User=2931823730 (Caused by NewConnectionError('<urllib3.connection.HTTPSConnection object at 0x7faf0c1007c0>: Failed to establish a new connection: [Errno 101] Network is unreachable'))
2025-04-11 15:16:51,601 ERROR   wandb-upload_2:24150 [internal_api.py:upload_file():2558] upload_file request headers: {'User-Agent': 'python-requests/2.32.3', 'Accept-Encoding': 'gzip, deflate, br', 'Accept': '*/*', 'Connection': 'keep-alive', 'Content-Length': '4212'}
2025-04-11 15:16:51,602 ERROR   wandb-upload_2:24150 [internal_api.py:upload_file():2560] upload_file response body: 
2025-04-11 15:16:51,610 ERROR   wandb-upload_1:24150 [internal_api.py:upload_file():2556] upload_file exception https://storage.googleapis.com/wandb-production.appspot.com/2931823730-harbin-institute-of-technology/ltu-as/gs2gbnar/config.yaml?X-Goog-Algorithm=GOOG4-RSA-SHA256&X-Goog-Credential=gorilla-files-url-signer-man%40wandb-production.iam.gserviceaccount.com%2F20250411%2Fauto%2Fstorage%2Fgoog4_request&X-Goog-Date=20250411T151651Z&X-Goog-Expires=86399&X-Goog-Signature=9fd08e30d0369f66f38480ba3844f8be9ab3600cf43707967b3f8fe30d0af9c9e39fa4eb7707d79aa262b44896ecc27365c2319d8fe1934f98e30e1a2a3bd2e64e9a908bbc60a11fac5f728d295a53415a462a424edee2fab42c0284fd8c59c2450f01957c7ab0c08deba7e0cb6f83a07cfc2ad5f54c7fdd94d4ea42cd86d2cf32caba7fc97c0c15c3d42d9a3c2c548b4074a300757f592ffba91b47a568270aa548b5273023389360dab014e78c145aacfc65f5bb70c392542a65b70d02dac6dd0099df5a06150f6e6fc932d73cf4946811e59987789d2f32a9beeac4eeac5fbd3c34c0911a5076eee8c93be646ffd58565265af4fc60b22d4e632137d18560&X-Goog-SignedHeaders=host&X-User=2931823730: HTTPSConnectionPool(host='storage.googleapis.com', port=443): Max retries exceeded with url: /wandb-production.appspot.com/2931823730-harbin-institute-of-technology/ltu-as/gs2gbnar/config.yaml?X-Goog-Algorithm=GOOG4-RSA-SHA256&X-Goog-Credential=gorilla-files-url-signer-man%40wandb-production.iam.gserviceaccount.com%2F20250411%2Fauto%2Fstorage%2Fgoog4_request&X-Goog-Date=20250411T151651Z&X-Goog-Expires=86399&X-Goog-Signature=9fd08e30d0369f66f38480ba3844f8be9ab3600cf43707967b3f8fe30d0af9c9e39fa4eb7707d79aa262b44896ecc27365c2319d8fe1934f98e30e1a2a3bd2e64e9a908bbc60a11fac5f728d295a53415a462a424edee2fab42c0284fd8c59c2450f01957c7ab0c08deba7e0cb6f83a07cfc2ad5f54c7fdd94d4ea42cd86d2cf32caba7fc97c0c15c3d42d9a3c2c548b4074a300757f592ffba91b47a568270aa548b5273023389360dab014e78c145aacfc65f5bb70c392542a65b70d02dac6dd0099df5a06150f6e6fc932d73cf4946811e59987789d2f32a9beeac4eeac5fbd3c34c0911a5076eee8c93be646ffd58565265af4fc60b22d4e632137d18560&X-Goog-SignedHeaders=host&X-User=2931823730 (Caused by NewConnectionError('<urllib3.connection.HTTPSConnection object at 0x7faf0c1027a0>: Failed to establish a new connection: [Errno 101] Network is unreachable'))
2025-04-11 15:16:51,610 ERROR   wandb-upload_1:24150 [internal_api.py:upload_file():2558] upload_file request headers: {'User-Agent': 'python-requests/2.32.3', 'Accept-Encoding': 'gzip, deflate, br', 'Accept': '*/*', 'Connection': 'keep-alive', 'Content-Length': '8685'}
2025-04-11 15:16:51,610 ERROR   wandb-upload_1:24150 [internal_api.py:upload_file():2560] upload_file response body: 
2025-04-11 15:16:51,766 ERROR   wandb-upload_5:24150 [internal_api.py:upload_file():2556] upload_file exception https://storage.googleapis.com/wandb-production.appspot.com/2931823730-harbin-institute-of-technology/ltu-as/gs2gbnar/wandb-summary.json?X-Goog-Algorithm=GOOG4-RSA-SHA256&X-Goog-Credential=gorilla-files-url-signer-man%40wandb-production.iam.gserviceaccount.com%2F20250411%2Fauto%2Fstorage%2Fgoog4_request&X-Goog-Date=20250411T151651Z&X-Goog-Expires=86399&X-Goog-Signature=93c831021585447783f056f8e81670116275f90fdeb1754acbe627713f9f562c04a881285011c6c9a9577af09140a02a695646a3e1dfb77a614c8a69b24f4efdb86486f1397df7f39f34fee7a853d786e203d04b9908cad7641c636b0594299e32acbf08556dcd75e46fb0d4df8dd193e2a4f5be1930d444e25a59c32b35b84afe7db688f525422405b488275044af3579cffeea9cb0511dda59c41b7838af9cbdb28868e03bec46f8b0e923f274ca0939980f83c4e2680b8f522ac7b79d47c50ab43d18c07914f31f6eaf2312f6cee550a61b47d849e7e6eafe48d9cff3eb45972df4e25f5d3e553d249e46810ea15de431400330ecb65f7e9e96033812ce23&X-Goog-SignedHeaders=host&X-User=2931823730: HTTPSConnectionPool(host='storage.googleapis.com', port=443): Max retries exceeded with url: /wandb-production.appspot.com/2931823730-harbin-institute-of-technology/ltu-as/gs2gbnar/wandb-summary.json?X-Goog-Algorithm=GOOG4-RSA-SHA256&X-Goog-Credential=gorilla-files-url-signer-man%40wandb-production.iam.gserviceaccount.com%2F20250411%2Fauto%2Fstorage%2Fgoog4_request&X-Goog-Date=20250411T151651Z&X-Goog-Expires=86399&X-Goog-Signature=93c831021585447783f056f8e81670116275f90fdeb1754acbe627713f9f562c04a881285011c6c9a9577af09140a02a695646a3e1dfb77a614c8a69b24f4efdb86486f1397df7f39f34fee7a853d786e203d04b9908cad7641c636b0594299e32acbf08556dcd75e46fb0d4df8dd193e2a4f5be1930d444e25a59c32b35b84afe7db688f525422405b488275044af3579cffeea9cb0511dda59c41b7838af9cbdb28868e03bec46f8b0e923f274ca0939980f83c4e2680b8f522ac7b79d47c50ab43d18c07914f31f6eaf2312f6cee550a61b47d849e7e6eafe48d9cff3eb45972df4e25f5d3e553d249e46810ea15de431400330ecb65f7e9e96033812ce23&X-Goog-SignedHeaders=host&X-User=2931823730 (Caused by NewConnectionError('<urllib3.connection.HTTPSConnection object at 0x7faf0c1005e0>: Failed to establish a new connection: [Errno 101] Network is unreachable'))
2025-04-11 15:16:51,766 ERROR   wandb-upload_4:24150 [internal_api.py:upload_file():2556] upload_file exception https://storage.googleapis.com/wandb-production.appspot.com/2931823730-harbin-institute-of-technology/ltu-as/gs2gbnar/output.log?X-Goog-Algorithm=GOOG4-RSA-SHA256&X-Goog-Credential=gorilla-files-url-signer-man%40wandb-production.iam.gserviceaccount.com%2F20250411%2Fauto%2Fstorage%2Fgoog4_request&X-Goog-Date=20250411T151651Z&X-Goog-Expires=86399&X-Goog-Signature=ba30f58c1368feee04b8096176a5f2e244167cb273cbeb464b2d54c1d7a74754d10d41baa2225c252e8f1ca8cae03cf7bdbc20126ea319c1a5a5073527bc69e705b985f3542972a3e346e67670267c3c825106e581fe7e66fb1bd28d2792403abe0b0670e4e9a435c897d99fb1d856e848bdf9fb247073360e828f32dd3e2c616076e6778a85204fe1163367bd13091f7c890a8d9294fddbcc4c491aeeb3d4b12338b4933b39b8dc2b8cf7102ad7e2e6abbd201b99725b11eae47d53b86f3ea5ea37930f830b62dd767fd9e7b87b2d477c88515df3677a129a835968a66b2ed747074e2194ac0bc169283a7591e086f9ce8e9c91647db7ea2de92c455dd56da5&X-Goog-SignedHeaders=host&X-User=2931823730: HTTPSConnectionPool(host='storage.googleapis.com', port=443): Max retries exceeded with url: /wandb-production.appspot.com/2931823730-harbin-institute-of-technology/ltu-as/gs2gbnar/output.log?X-Goog-Algorithm=GOOG4-RSA-SHA256&X-Goog-Credential=gorilla-files-url-signer-man%40wandb-production.iam.gserviceaccount.com%2F20250411%2Fauto%2Fstorage%2Fgoog4_request&X-Goog-Date=20250411T151651Z&X-Goog-Expires=86399&X-Goog-Signature=ba30f58c1368feee04b8096176a5f2e244167cb273cbeb464b2d54c1d7a74754d10d41baa2225c252e8f1ca8cae03cf7bdbc20126ea319c1a5a5073527bc69e705b985f3542972a3e346e67670267c3c825106e581fe7e66fb1bd28d2792403abe0b0670e4e9a435c897d99fb1d856e848bdf9fb247073360e828f32dd3e2c616076e6778a85204fe1163367bd13091f7c890a8d9294fddbcc4c491aeeb3d4b12338b4933b39b8dc2b8cf7102ad7e2e6abbd201b99725b11eae47d53b86f3ea5ea37930f830b62dd767fd9e7b87b2d477c88515df3677a129a835968a66b2ed747074e2194ac0bc169283a7591e086f9ce8e9c91647db7ea2de92c455dd56da5&X-Goog-SignedHeaders=host&X-User=2931823730 (Caused by NewConnectionError('<urllib3.connection.HTTPSConnection object at 0x7faf0c103f10>: Failed to establish a new connection: [Errno 101] Network is unreachable'))
2025-04-11 15:16:51,766 ERROR   wandb-upload_4:24150 [internal_api.py:upload_file():2558] upload_file request headers: {'User-Agent': 'python-requests/2.32.3', 'Accept-Encoding': 'gzip, deflate, br', 'Accept': '*/*', 'Connection': 'keep-alive', 'Content-Length': '4566'}
2025-04-11 15:16:51,766 ERROR   wandb-upload_4:24150 [internal_api.py:upload_file():2560] upload_file response body: 
2025-04-11 15:16:51,766 ERROR   wandb-upload_5:24150 [internal_api.py:upload_file():2558] upload_file request headers: {'User-Agent': 'python-requests/2.32.3', 'Accept-Encoding': 'gzip, deflate, br', 'Accept': '*/*', 'Connection': 'keep-alive', 'Content-Length': '27'}
2025-04-11 15:16:51,767 ERROR   wandb-upload_5:24150 [internal_api.py:upload_file():2560] upload_file response body: 
2025-04-11 15:16:51,767 ERROR   wandb-upload_3:24150 [internal_api.py:upload_file():2556] upload_file exception https://storage.googleapis.com/wandb-production.appspot.com/2931823730-harbin-institute-of-technology/ltu-as/gs2gbnar/conda-environment.yaml?X-Goog-Algorithm=GOOG4-RSA-SHA256&X-Goog-Credential=gorilla-files-url-signer-man%40wandb-production.iam.gserviceaccount.com%2F20250411%2Fauto%2Fstorage%2Fgoog4_request&X-Goog-Date=20250411T151651Z&X-Goog-Expires=86399&X-Goog-Signature=85b9174dbccf3057b27c769b2124d9e2e31fadf45d140126242875f8f9469036c29e78351e743d684ffc8acc9f7ccadeb7c6dbd23e4610dc318200a163b8f50a29cc704d1dc3bb33b276d506c72c98b21ff15706aec1a0327d0057e384eab219125527850b2b1544e786a3097a857229407e129578bcabb2e236d17cb57c40308e363182d23cd6a7bf911cee0bcf78e729172bd77fb7e00616353ca94eb47dd74dc041d97ebeb2fc5dd032e4f34b6083b05fff6927c97e66d59f0ea1f380c4d88456b8a037fe3e1f4771a0498ac0e977602029bab9eabd553492643d78e70fbf699a7f9c934cc0fc7ab68a095ef564548136d546195da2890a10ee96c96bdd83&X-Goog-SignedHeaders=host&X-User=2931823730: HTTPSConnectionPool(host='storage.googleapis.com', port=443): Max retries exceeded with url: /wandb-production.appspot.com/2931823730-harbin-institute-of-technology/ltu-as/gs2gbnar/conda-environment.yaml?X-Goog-Algorithm=GOOG4-RSA-SHA256&X-Goog-Credential=gorilla-files-url-signer-man%40wandb-production.iam.gserviceaccount.com%2F20250411%2Fauto%2Fstorage%2Fgoog4_request&X-Goog-Date=20250411T151651Z&X-Goog-Expires=86399&X-Goog-Signature=85b9174dbccf3057b27c769b2124d9e2e31fadf45d140126242875f8f9469036c29e78351e743d684ffc8acc9f7ccadeb7c6dbd23e4610dc318200a163b8f50a29cc704d1dc3bb33b276d506c72c98b21ff15706aec1a0327d0057e384eab219125527850b2b1544e786a3097a857229407e129578bcabb2e236d17cb57c40308e363182d23cd6a7bf911cee0bcf78e729172bd77fb7e00616353ca94eb47dd74dc041d97ebeb2fc5dd032e4f34b6083b05fff6927c97e66d59f0ea1f380c4d88456b8a037fe3e1f4771a0498ac0e977602029bab9eabd553492643d78e70fbf699a7f9c934cc0fc7ab68a095ef564548136d546195da2890a10ee96c96bdd83&X-Goog-SignedHeaders=host&X-User=2931823730 (Caused by NewConnectionError('<urllib3.connection.HTTPSConnection object at 0x7faf0c102230>: Failed to establish a new connection: [Errno 101] Network is unreachable'))
2025-04-11 15:16:51,767 ERROR   wandb-upload_3:24150 [internal_api.py:upload_file():2558] upload_file request headers: {'User-Agent': 'python-requests/2.32.3', 'Accept-Encoding': 'gzip, deflate, br', 'Accept': '*/*', 'Connection': 'keep-alive', 'Content-Length': '8281'}
2025-04-11 15:16:51,767 ERROR   wandb-upload_3:24150 [internal_api.py:upload_file():2560] upload_file response body: 
2025-04-11 15:16:52,275 DEBUG   HandlerThread:24150 [handler.py:handle_request():146] handle_request: poll_exit
2025-04-11 15:16:52,276 DEBUG   SenderThread:24150 [sender.py:send_request():407] send_request: poll_exit
2025-04-11 15:16:52,633 ERROR   wandb-upload_2:24150 [internal_api.py:upload_file():2556] upload_file exception https://storage.googleapis.com/wandb-production.appspot.com/2931823730-harbin-institute-of-technology/ltu-as/gs2gbnar/requirements.txt?X-Goog-Algorithm=GOOG4-RSA-SHA256&X-Goog-Credential=gorilla-files-url-signer-man%40wandb-production.iam.gserviceaccount.com%2F20250411%2Fauto%2Fstorage%2Fgoog4_request&X-Goog-Date=20250411T151651Z&X-Goog-Expires=86399&X-Goog-Signature=abe2767048a665ae692f042124a97fcaab2586fd27692787eae806db284e475580ee0a12dacc4f8c249c8fa01108de939fea9731e921583f5d759548cc605e67740521dc4b8e1747a7414e648b5653b9fbc1c06ec67ec6b4e64d0264d440d3638e45ae3c3c06ac040c5cd8185b6699856ce0631553cfc99cf32e0c4e28746bf95038df96fddc4af2947ed5270d32abc379aa7dc9f494894612ebac60b3fb9ca8f1070ec8abfc84531a916a32e9c9b558ab565519332033e79d24602a77ff6219c45b5940c48fd3d22edf7675d51eb9b8d81bbef3383707c861521ded9c97e05550161527ff961a00782fc508f2cd7a84d4b5cca95f89d511f396237dc4d9d2f9&X-Goog-SignedHeaders=host&X-User=2931823730: HTTPSConnectionPool(host='storage.googleapis.com', port=443): Max retries exceeded with url: /wandb-production.appspot.com/2931823730-harbin-institute-of-technology/ltu-as/gs2gbnar/requirements.txt?X-Goog-Algorithm=GOOG4-RSA-SHA256&X-Goog-Credential=gorilla-files-url-signer-man%40wandb-production.iam.gserviceaccount.com%2F20250411%2Fauto%2Fstorage%2Fgoog4_request&X-Goog-Date=20250411T151651Z&X-Goog-Expires=86399&X-Goog-Signature=abe2767048a665ae692f042124a97fcaab2586fd27692787eae806db284e475580ee0a12dacc4f8c249c8fa01108de939fea9731e921583f5d759548cc605e67740521dc4b8e1747a7414e648b5653b9fbc1c06ec67ec6b4e64d0264d440d3638e45ae3c3c06ac040c5cd8185b6699856ce0631553cfc99cf32e0c4e28746bf95038df96fddc4af2947ed5270d32abc379aa7dc9f494894612ebac60b3fb9ca8f1070ec8abfc84531a916a32e9c9b558ab565519332033e79d24602a77ff6219c45b5940c48fd3d22edf7675d51eb9b8d81bbef3383707c861521ded9c97e05550161527ff961a00782fc508f2cd7a84d4b5cca95f89d511f396237dc4d9d2f9&X-Goog-SignedHeaders=host&X-User=2931823730 (Caused by NewConnectionError('<urllib3.connection.HTTPSConnection object at 0x7faef45759c0>: Failed to establish a new connection: [Errno 101] Network is unreachable'))
2025-04-11 15:16:52,633 ERROR   wandb-upload_2:24150 [internal_api.py:upload_file():2558] upload_file request headers: {'User-Agent': 'python-requests/2.32.3', 'Accept-Encoding': 'gzip, deflate, br', 'Accept': '*/*', 'Connection': 'keep-alive', 'Content-Length': '4212'}
2025-04-11 15:16:52,633 ERROR   wandb-upload_2:24150 [internal_api.py:upload_file():2560] upload_file response body: 
2025-04-11 15:16:52,710 ERROR   wandb-upload_1:24150 [internal_api.py:upload_file():2556] upload_file exception https://storage.googleapis.com/wandb-production.appspot.com/2931823730-harbin-institute-of-technology/ltu-as/gs2gbnar/config.yaml?X-Goog-Algorithm=GOOG4-RSA-SHA256&X-Goog-Credential=gorilla-files-url-signer-man%40wandb-production.iam.gserviceaccount.com%2F20250411%2Fauto%2Fstorage%2Fgoog4_request&X-Goog-Date=20250411T151651Z&X-Goog-Expires=86399&X-Goog-Signature=9fd08e30d0369f66f38480ba3844f8be9ab3600cf43707967b3f8fe30d0af9c9e39fa4eb7707d79aa262b44896ecc27365c2319d8fe1934f98e30e1a2a3bd2e64e9a908bbc60a11fac5f728d295a53415a462a424edee2fab42c0284fd8c59c2450f01957c7ab0c08deba7e0cb6f83a07cfc2ad5f54c7fdd94d4ea42cd86d2cf32caba7fc97c0c15c3d42d9a3c2c548b4074a300757f592ffba91b47a568270aa548b5273023389360dab014e78c145aacfc65f5bb70c392542a65b70d02dac6dd0099df5a06150f6e6fc932d73cf4946811e59987789d2f32a9beeac4eeac5fbd3c34c0911a5076eee8c93be646ffd58565265af4fc60b22d4e632137d18560&X-Goog-SignedHeaders=host&X-User=2931823730: HTTPSConnectionPool(host='storage.googleapis.com', port=443): Max retries exceeded with url: /wandb-production.appspot.com/2931823730-harbin-institute-of-technology/ltu-as/gs2gbnar/config.yaml?X-Goog-Algorithm=GOOG4-RSA-SHA256&X-Goog-Credential=gorilla-files-url-signer-man%40wandb-production.iam.gserviceaccount.com%2F20250411%2Fauto%2Fstorage%2Fgoog4_request&X-Goog-Date=20250411T151651Z&X-Goog-Expires=86399&X-Goog-Signature=9fd08e30d0369f66f38480ba3844f8be9ab3600cf43707967b3f8fe30d0af9c9e39fa4eb7707d79aa262b44896ecc27365c2319d8fe1934f98e30e1a2a3bd2e64e9a908bbc60a11fac5f728d295a53415a462a424edee2fab42c0284fd8c59c2450f01957c7ab0c08deba7e0cb6f83a07cfc2ad5f54c7fdd94d4ea42cd86d2cf32caba7fc97c0c15c3d42d9a3c2c548b4074a300757f592ffba91b47a568270aa548b5273023389360dab014e78c145aacfc65f5bb70c392542a65b70d02dac6dd0099df5a06150f6e6fc932d73cf4946811e59987789d2f32a9beeac4eeac5fbd3c34c0911a5076eee8c93be646ffd58565265af4fc60b22d4e632137d18560&X-Goog-SignedHeaders=host&X-User=2931823730 (Caused by NewConnectionError('<urllib3.connection.HTTPSConnection object at 0x7faef45756c0>: Failed to establish a new connection: [Errno 101] Network is unreachable'))
2025-04-11 15:16:52,710 ERROR   wandb-upload_1:24150 [internal_api.py:upload_file():2558] upload_file request headers: {'User-Agent': 'python-requests/2.32.3', 'Accept-Encoding': 'gzip, deflate, br', 'Accept': '*/*', 'Connection': 'keep-alive', 'Content-Length': '8685'}
2025-04-11 15:16:52,711 ERROR   wandb-upload_1:24150 [internal_api.py:upload_file():2560] upload_file response body: 
2025-04-11 15:16:52,711 INFO    wandb-upload_1:24150 [retry.py:__call__():172] Retry attempt failed:
Traceback (most recent call last):
  File "/root/anaconda3/envs/venv_ltu/lib/python3.10/site-packages/urllib3/connection.py", line 198, in _new_conn
    sock = connection.create_connection(
  File "/root/anaconda3/envs/venv_ltu/lib/python3.10/site-packages/urllib3/util/connection.py", line 85, in create_connection
    raise err
  File "/root/anaconda3/envs/venv_ltu/lib/python3.10/site-packages/urllib3/util/connection.py", line 73, in create_connection
    sock.connect(sa)
OSError: [Errno 101] Network is unreachable

The above exception was the direct cause of the following exception:

Traceback (most recent call last):
  File "/root/anaconda3/envs/venv_ltu/lib/python3.10/site-packages/urllib3/connectionpool.py", line 793, in urlopen
    response = self._make_request(
  File "/root/anaconda3/envs/venv_ltu/lib/python3.10/site-packages/urllib3/connectionpool.py", line 491, in _make_request
    raise new_e
  File "/root/anaconda3/envs/venv_ltu/lib/python3.10/site-packages/urllib3/connectionpool.py", line 467, in _make_request
    self._validate_conn(conn)
  File "/root/anaconda3/envs/venv_ltu/lib/python3.10/site-packages/urllib3/connectionpool.py", line 1099, in _validate_conn
    conn.connect()
  File "/root/anaconda3/envs/venv_ltu/lib/python3.10/site-packages/urllib3/connection.py", line 616, in connect
    self.sock = sock = self._new_conn()
  File "/root/anaconda3/envs/venv_ltu/lib/python3.10/site-packages/urllib3/connection.py", line 213, in _new_conn
    raise NewConnectionError(
urllib3.exceptions.NewConnectionError: <urllib3.connection.HTTPSConnection object at 0x7faef45756c0>: Failed to establish a new connection: [Errno 101] Network is unreachable

The above exception was the direct cause of the following exception:

Traceback (most recent call last):
  File "/root/anaconda3/envs/venv_ltu/lib/python3.10/site-packages/requests/adapters.py", line 667, in send
    resp = conn.urlopen(
  File "/root/anaconda3/envs/venv_ltu/lib/python3.10/site-packages/urllib3/connectionpool.py", line 847, in urlopen
    retries = retries.increment(
  File "/root/anaconda3/envs/venv_ltu/lib/python3.10/site-packages/urllib3/util/retry.py", line 515, in increment
    raise MaxRetryError(_pool, url, reason) from reason  # type: ignore[arg-type]
urllib3.exceptions.MaxRetryError: HTTPSConnectionPool(host='storage.googleapis.com', port=443): Max retries exceeded with url: /wandb-production.appspot.com/2931823730-harbin-institute-of-technology/ltu-as/gs2gbnar/config.yaml?X-Goog-Algorithm=GOOG4-RSA-SHA256&X-Goog-Credential=gorilla-files-url-signer-man%40wandb-production.iam.gserviceaccount.com%2F20250411%2Fauto%2Fstorage%2Fgoog4_request&X-Goog-Date=20250411T151651Z&X-Goog-Expires=86399&X-Goog-Signature=9fd08e30d0369f66f38480ba3844f8be9ab3600cf43707967b3f8fe30d0af9c9e39fa4eb7707d79aa262b44896ecc27365c2319d8fe1934f98e30e1a2a3bd2e64e9a908bbc60a11fac5f728d295a53415a462a424edee2fab42c0284fd8c59c2450f01957c7ab0c08deba7e0cb6f83a07cfc2ad5f54c7fdd94d4ea42cd86d2cf32caba7fc97c0c15c3d42d9a3c2c548b4074a300757f592ffba91b47a568270aa548b5273023389360dab014e78c145aacfc65f5bb70c392542a65b70d02dac6dd0099df5a06150f6e6fc932d73cf4946811e59987789d2f32a9beeac4eeac5fbd3c34c0911a5076eee8c93be646ffd58565265af4fc60b22d4e632137d18560&X-Goog-SignedHeaders=host&X-User=2931823730 (Caused by NewConnectionError('<urllib3.connection.HTTPSConnection object at 0x7faef45756c0>: Failed to establish a new connection: [Errno 101] Network is unreachable'))

During handling of the above exception, another exception occurred:

Traceback (most recent call last):
  File "/root/anaconda3/envs/venv_ltu/lib/python3.10/site-packages/wandb/sdk/internal/internal_api.py", line 2549, in upload_file
    response = self._upload_file_session.put(
  File "/root/anaconda3/envs/venv_ltu/lib/python3.10/site-packages/requests/sessions.py", line 649, in put
    return self.request("PUT", url, data=data, **kwargs)
  File "/root/anaconda3/envs/venv_ltu/lib/python3.10/site-packages/requests/sessions.py", line 589, in request
    resp = self.send(prep, **send_kwargs)
  File "/root/anaconda3/envs/venv_ltu/lib/python3.10/site-packages/requests/sessions.py", line 703, in send
    r = adapter.send(request, **kwargs)
  File "/root/anaconda3/envs/venv_ltu/lib/python3.10/site-packages/requests/adapters.py", line 700, in send
    raise ConnectionError(e, request=request)
requests.exceptions.ConnectionError: HTTPSConnectionPool(host='storage.googleapis.com', port=443): Max retries exceeded with url: /wandb-production.appspot.com/2931823730-harbin-institute-of-technology/ltu-as/gs2gbnar/config.yaml?X-Goog-Algorithm=GOOG4-RSA-SHA256&X-Goog-Credential=gorilla-files-url-signer-man%40wandb-production.iam.gserviceaccount.com%2F20250411%2Fauto%2Fstorage%2Fgoog4_request&X-Goog-Date=20250411T151651Z&X-Goog-Expires=86399&X-Goog-Signature=9fd08e30d0369f66f38480ba3844f8be9ab3600cf43707967b3f8fe30d0af9c9e39fa4eb7707d79aa262b44896ecc27365c2319d8fe1934f98e30e1a2a3bd2e64e9a908bbc60a11fac5f728d295a53415a462a424edee2fab42c0284fd8c59c2450f01957c7ab0c08deba7e0cb6f83a07cfc2ad5f54c7fdd94d4ea42cd86d2cf32caba7fc97c0c15c3d42d9a3c2c548b4074a300757f592ffba91b47a568270aa548b5273023389360dab014e78c145aacfc65f5bb70c392542a65b70d02dac6dd0099df5a06150f6e6fc932d73cf4946811e59987789d2f32a9beeac4eeac5fbd3c34c0911a5076eee8c93be646ffd58565265af4fc60b22d4e632137d18560&X-Goog-SignedHeaders=host&X-User=2931823730 (Caused by NewConnectionError('<urllib3.connection.HTTPSConnection object at 0x7faef45756c0>: Failed to establish a new connection: [Errno 101] Network is unreachable'))

During handling of the above exception, another exception occurred:

Traceback (most recent call last):
  File "/root/anaconda3/envs/venv_ltu/lib/python3.10/site-packages/wandb/sdk/lib/retry.py", line 131, in __call__
    result = self._call_fn(*args, **kwargs)
  File "/root/anaconda3/envs/venv_ltu/lib/python3.10/site-packages/wandb/sdk/internal/internal_api.py", line 2580, in upload_file
    raise _e.with_traceback(sys.exc_info()[2])
  File "/root/anaconda3/envs/venv_ltu/lib/python3.10/site-packages/wandb/sdk/internal/internal_api.py", line 2549, in upload_file
    response = self._upload_file_session.put(
  File "/root/anaconda3/envs/venv_ltu/lib/python3.10/site-packages/requests/sessions.py", line 649, in put
    return self.request("PUT", url, data=data, **kwargs)
  File "/root/anaconda3/envs/venv_ltu/lib/python3.10/site-packages/requests/sessions.py", line 589, in request
    resp = self.send(prep, **send_kwargs)
  File "/root/anaconda3/envs/venv_ltu/lib/python3.10/site-packages/requests/sessions.py", line 703, in send
    r = adapter.send(request, **kwargs)
  File "/root/anaconda3/envs/venv_ltu/lib/python3.10/site-packages/requests/adapters.py", line 700, in send
    raise ConnectionError(e, request=request)
wandb.sdk.lib.retry.TransientError: None
2025-04-11 15:16:52,819 ERROR   wandb-upload_4:24150 [internal_api.py:upload_file():2556] upload_file exception https://storage.googleapis.com/wandb-production.appspot.com/2931823730-harbin-institute-of-technology/ltu-as/gs2gbnar/output.log?X-Goog-Algorithm=GOOG4-RSA-SHA256&X-Goog-Credential=gorilla-files-url-signer-man%40wandb-production.iam.gserviceaccount.com%2F20250411%2Fauto%2Fstorage%2Fgoog4_request&X-Goog-Date=20250411T151651Z&X-Goog-Expires=86399&X-Goog-Signature=ba30f58c1368feee04b8096176a5f2e244167cb273cbeb464b2d54c1d7a74754d10d41baa2225c252e8f1ca8cae03cf7bdbc20126ea319c1a5a5073527bc69e705b985f3542972a3e346e67670267c3c825106e581fe7e66fb1bd28d2792403abe0b0670e4e9a435c897d99fb1d856e848bdf9fb247073360e828f32dd3e2c616076e6778a85204fe1163367bd13091f7c890a8d9294fddbcc4c491aeeb3d4b12338b4933b39b8dc2b8cf7102ad7e2e6abbd201b99725b11eae47d53b86f3ea5ea37930f830b62dd767fd9e7b87b2d477c88515df3677a129a835968a66b2ed747074e2194ac0bc169283a7591e086f9ce8e9c91647db7ea2de92c455dd56da5&X-Goog-SignedHeaders=host&X-User=2931823730: HTTPSConnectionPool(host='storage.googleapis.com', port=443): Max retries exceeded with url: /wandb-production.appspot.com/2931823730-harbin-institute-of-technology/ltu-as/gs2gbnar/output.log?X-Goog-Algorithm=GOOG4-RSA-SHA256&X-Goog-Credential=gorilla-files-url-signer-man%40wandb-production.iam.gserviceaccount.com%2F20250411%2Fauto%2Fstorage%2Fgoog4_request&X-Goog-Date=20250411T151651Z&X-Goog-Expires=86399&X-Goog-Signature=ba30f58c1368feee04b8096176a5f2e244167cb273cbeb464b2d54c1d7a74754d10d41baa2225c252e8f1ca8cae03cf7bdbc20126ea319c1a5a5073527bc69e705b985f3542972a3e346e67670267c3c825106e581fe7e66fb1bd28d2792403abe0b0670e4e9a435c897d99fb1d856e848bdf9fb247073360e828f32dd3e2c616076e6778a85204fe1163367bd13091f7c890a8d9294fddbcc4c491aeeb3d4b12338b4933b39b8dc2b8cf7102ad7e2e6abbd201b99725b11eae47d53b86f3ea5ea37930f830b62dd767fd9e7b87b2d477c88515df3677a129a835968a66b2ed747074e2194ac0bc169283a7591e086f9ce8e9c91647db7ea2de92c455dd56da5&X-Goog-SignedHeaders=host&X-User=2931823730 (Caused by NewConnectionError('<urllib3.connection.HTTPSConnection object at 0x7faef4576380>: Failed to establish a new connection: [Errno 101] Network is unreachable'))
2025-04-11 15:16:52,819 ERROR   wandb-upload_4:24150 [internal_api.py:upload_file():2558] upload_file request headers: {'User-Agent': 'python-requests/2.32.3', 'Accept-Encoding': 'gzip, deflate, br', 'Accept': '*/*', 'Connection': 'keep-alive', 'Content-Length': '4566'}
2025-04-11 15:16:52,820 ERROR   wandb-upload_4:24150 [internal_api.py:upload_file():2560] upload_file response body: 
2025-04-11 15:16:52,870 ERROR   wandb-upload_3:24150 [internal_api.py:upload_file():2556] upload_file exception https://storage.googleapis.com/wandb-production.appspot.com/2931823730-harbin-institute-of-technology/ltu-as/gs2gbnar/conda-environment.yaml?X-Goog-Algorithm=GOOG4-RSA-SHA256&X-Goog-Credential=gorilla-files-url-signer-man%40wandb-production.iam.gserviceaccount.com%2F20250411%2Fauto%2Fstorage%2Fgoog4_request&X-Goog-Date=20250411T151651Z&X-Goog-Expires=86399&X-Goog-Signature=85b9174dbccf3057b27c769b2124d9e2e31fadf45d140126242875f8f9469036c29e78351e743d684ffc8acc9f7ccadeb7c6dbd23e4610dc318200a163b8f50a29cc704d1dc3bb33b276d506c72c98b21ff15706aec1a0327d0057e384eab219125527850b2b1544e786a3097a857229407e129578bcabb2e236d17cb57c40308e363182d23cd6a7bf911cee0bcf78e729172bd77fb7e00616353ca94eb47dd74dc041d97ebeb2fc5dd032e4f34b6083b05fff6927c97e66d59f0ea1f380c4d88456b8a037fe3e1f4771a0498ac0e977602029bab9eabd553492643d78e70fbf699a7f9c934cc0fc7ab68a095ef564548136d546195da2890a10ee96c96bdd83&X-Goog-SignedHeaders=host&X-User=2931823730: HTTPSConnectionPool(host='storage.googleapis.com', port=443): Max retries exceeded with url: /wandb-production.appspot.com/2931823730-harbin-institute-of-technology/ltu-as/gs2gbnar/conda-environment.yaml?X-Goog-Algorithm=GOOG4-RSA-SHA256&X-Goog-Credential=gorilla-files-url-signer-man%40wandb-production.iam.gserviceaccount.com%2F20250411%2Fauto%2Fstorage%2Fgoog4_request&X-Goog-Date=20250411T151651Z&X-Goog-Expires=86399&X-Goog-Signature=85b9174dbccf3057b27c769b2124d9e2e31fadf45d140126242875f8f9469036c29e78351e743d684ffc8acc9f7ccadeb7c6dbd23e4610dc318200a163b8f50a29cc704d1dc3bb33b276d506c72c98b21ff15706aec1a0327d0057e384eab219125527850b2b1544e786a3097a857229407e129578bcabb2e236d17cb57c40308e363182d23cd6a7bf911cee0bcf78e729172bd77fb7e00616353ca94eb47dd74dc041d97ebeb2fc5dd032e4f34b6083b05fff6927c97e66d59f0ea1f380c4d88456b8a037fe3e1f4771a0498ac0e977602029bab9eabd553492643d78e70fbf699a7f9c934cc0fc7ab68a095ef564548136d546195da2890a10ee96c96bdd83&X-Goog-SignedHeaders=host&X-User=2931823730 (Caused by NewConnectionError('<urllib3.connection.HTTPSConnection object at 0x7faef4576bc0>: Failed to establish a new connection: [Errno 101] Network is unreachable'))
2025-04-11 15:16:52,871 ERROR   wandb-upload_3:24150 [internal_api.py:upload_file():2558] upload_file request headers: {'User-Agent': 'python-requests/2.32.3', 'Accept-Encoding': 'gzip, deflate, br', 'Accept': '*/*', 'Connection': 'keep-alive', 'Content-Length': '8281'}
2025-04-11 15:16:52,871 ERROR   wandb-upload_3:24150 [internal_api.py:upload_file():2560] upload_file response body: 
2025-04-11 15:16:52,906 ERROR   wandb-upload_5:24150 [internal_api.py:upload_file():2556] upload_file exception https://storage.googleapis.com/wandb-production.appspot.com/2931823730-harbin-institute-of-technology/ltu-as/gs2gbnar/wandb-summary.json?X-Goog-Algorithm=GOOG4-RSA-SHA256&X-Goog-Credential=gorilla-files-url-signer-man%40wandb-production.iam.gserviceaccount.com%2F20250411%2Fauto%2Fstorage%2Fgoog4_request&X-Goog-Date=20250411T151651Z&X-Goog-Expires=86399&X-Goog-Signature=93c831021585447783f056f8e81670116275f90fdeb1754acbe627713f9f562c04a881285011c6c9a9577af09140a02a695646a3e1dfb77a614c8a69b24f4efdb86486f1397df7f39f34fee7a853d786e203d04b9908cad7641c636b0594299e32acbf08556dcd75e46fb0d4df8dd193e2a4f5be1930d444e25a59c32b35b84afe7db688f525422405b488275044af3579cffeea9cb0511dda59c41b7838af9cbdb28868e03bec46f8b0e923f274ca0939980f83c4e2680b8f522ac7b79d47c50ab43d18c07914f31f6eaf2312f6cee550a61b47d849e7e6eafe48d9cff3eb45972df4e25f5d3e553d249e46810ea15de431400330ecb65f7e9e96033812ce23&X-Goog-SignedHeaders=host&X-User=2931823730: HTTPSConnectionPool(host='storage.googleapis.com', port=443): Max retries exceeded with url: /wandb-production.appspot.com/2931823730-harbin-institute-of-technology/ltu-as/gs2gbnar/wandb-summary.json?X-Goog-Algorithm=GOOG4-RSA-SHA256&X-Goog-Credential=gorilla-files-url-signer-man%40wandb-production.iam.gserviceaccount.com%2F20250411%2Fauto%2Fstorage%2Fgoog4_request&X-Goog-Date=20250411T151651Z&X-Goog-Expires=86399&X-Goog-Signature=93c831021585447783f056f8e81670116275f90fdeb1754acbe627713f9f562c04a881285011c6c9a9577af09140a02a695646a3e1dfb77a614c8a69b24f4efdb86486f1397df7f39f34fee7a853d786e203d04b9908cad7641c636b0594299e32acbf08556dcd75e46fb0d4df8dd193e2a4f5be1930d444e25a59c32b35b84afe7db688f525422405b488275044af3579cffeea9cb0511dda59c41b7838af9cbdb28868e03bec46f8b0e923f274ca0939980f83c4e2680b8f522ac7b79d47c50ab43d18c07914f31f6eaf2312f6cee550a61b47d849e7e6eafe48d9cff3eb45972df4e25f5d3e553d249e46810ea15de431400330ecb65f7e9e96033812ce23&X-Goog-SignedHeaders=host&X-User=2931823730 (Caused by NewConnectionError('<urllib3.connection.HTTPSConnection object at 0x7faef4576a10>: Failed to establish a new connection: [Errno 101] Network is unreachable'))
2025-04-11 15:16:52,906 ERROR   wandb-upload_5:24150 [internal_api.py:upload_file():2558] upload_file request headers: {'User-Agent': 'python-requests/2.32.3', 'Accept-Encoding': 'gzip, deflate, br', 'Accept': '*/*', 'Connection': 'keep-alive', 'Content-Length': '27'}
2025-04-11 15:16:52,906 ERROR   wandb-upload_5:24150 [internal_api.py:upload_file():2560] upload_file response body: 
2025-04-11 15:16:53,277 DEBUG   HandlerThread:24150 [handler.py:handle_request():146] handle_request: poll_exit
2025-04-11 15:16:53,277 DEBUG   SenderThread:24150 [sender.py:send_request():407] send_request: poll_exit
2025-04-11 15:16:54,279 DEBUG   HandlerThread:24150 [handler.py:handle_request():146] handle_request: poll_exit
2025-04-11 15:16:54,280 DEBUG   SenderThread:24150 [sender.py:send_request():407] send_request: poll_exit
2025-04-11 15:16:54,776 ERROR   wandb-upload_1:24150 [internal_api.py:upload_file():2556] upload_file exception https://storage.googleapis.com/wandb-production.appspot.com/2931823730-harbin-institute-of-technology/ltu-as/gs2gbnar/config.yaml?X-Goog-Algorithm=GOOG4-RSA-SHA256&X-Goog-Credential=gorilla-files-url-signer-man%40wandb-production.iam.gserviceaccount.com%2F20250411%2Fauto%2Fstorage%2Fgoog4_request&X-Goog-Date=20250411T151651Z&X-Goog-Expires=86399&X-Goog-Signature=9fd08e30d0369f66f38480ba3844f8be9ab3600cf43707967b3f8fe30d0af9c9e39fa4eb7707d79aa262b44896ecc27365c2319d8fe1934f98e30e1a2a3bd2e64e9a908bbc60a11fac5f728d295a53415a462a424edee2fab42c0284fd8c59c2450f01957c7ab0c08deba7e0cb6f83a07cfc2ad5f54c7fdd94d4ea42cd86d2cf32caba7fc97c0c15c3d42d9a3c2c548b4074a300757f592ffba91b47a568270aa548b5273023389360dab014e78c145aacfc65f5bb70c392542a65b70d02dac6dd0099df5a06150f6e6fc932d73cf4946811e59987789d2f32a9beeac4eeac5fbd3c34c0911a5076eee8c93be646ffd58565265af4fc60b22d4e632137d18560&X-Goog-SignedHeaders=host&X-User=2931823730: HTTPSConnectionPool(host='storage.googleapis.com', port=443): Max retries exceeded with url: /wandb-production.appspot.com/2931823730-harbin-institute-of-technology/ltu-as/gs2gbnar/config.yaml?X-Goog-Algorithm=GOOG4-RSA-SHA256&X-Goog-Credential=gorilla-files-url-signer-man%40wandb-production.iam.gserviceaccount.com%2F20250411%2Fauto%2Fstorage%2Fgoog4_request&X-Goog-Date=20250411T151651Z&X-Goog-Expires=86399&X-Goog-Signature=9fd08e30d0369f66f38480ba3844f8be9ab3600cf43707967b3f8fe30d0af9c9e39fa4eb7707d79aa262b44896ecc27365c2319d8fe1934f98e30e1a2a3bd2e64e9a908bbc60a11fac5f728d295a53415a462a424edee2fab42c0284fd8c59c2450f01957c7ab0c08deba7e0cb6f83a07cfc2ad5f54c7fdd94d4ea42cd86d2cf32caba7fc97c0c15c3d42d9a3c2c548b4074a300757f592ffba91b47a568270aa548b5273023389360dab014e78c145aacfc65f5bb70c392542a65b70d02dac6dd0099df5a06150f6e6fc932d73cf4946811e59987789d2f32a9beeac4eeac5fbd3c34c0911a5076eee8c93be646ffd58565265af4fc60b22d4e632137d18560&X-Goog-SignedHeaders=host&X-User=2931823730 (Caused by NewConnectionError('<urllib3.connection.HTTPSConnection object at 0x7faef4575cc0>: Failed to establish a new connection: [Errno 101] Network is unreachable'))
2025-04-11 15:16:54,776 ERROR   wandb-upload_1:24150 [internal_api.py:upload_file():2558] upload_file request headers: {'User-Agent': 'python-requests/2.32.3', 'Accept-Encoding': 'gzip, deflate, br', 'Accept': '*/*', 'Connection': 'keep-alive', 'Content-Length': '8685'}
2025-04-11 15:16:54,776 ERROR   wandb-upload_1:24150 [internal_api.py:upload_file():2560] upload_file response body: 
2025-04-11 15:16:54,932 ERROR   wandb-upload_4:24150 [internal_api.py:upload_file():2556] upload_file exception https://storage.googleapis.com/wandb-production.appspot.com/2931823730-harbin-institute-of-technology/ltu-as/gs2gbnar/output.log?X-Goog-Algorithm=GOOG4-RSA-SHA256&X-Goog-Credential=gorilla-files-url-signer-man%40wandb-production.iam.gserviceaccount.com%2F20250411%2Fauto%2Fstorage%2Fgoog4_request&X-Goog-Date=20250411T151651Z&X-Goog-Expires=86399&X-Goog-Signature=ba30f58c1368feee04b8096176a5f2e244167cb273cbeb464b2d54c1d7a74754d10d41baa2225c252e8f1ca8cae03cf7bdbc20126ea319c1a5a5073527bc69e705b985f3542972a3e346e67670267c3c825106e581fe7e66fb1bd28d2792403abe0b0670e4e9a435c897d99fb1d856e848bdf9fb247073360e828f32dd3e2c616076e6778a85204fe1163367bd13091f7c890a8d9294fddbcc4c491aeeb3d4b12338b4933b39b8dc2b8cf7102ad7e2e6abbd201b99725b11eae47d53b86f3ea5ea37930f830b62dd767fd9e7b87b2d477c88515df3677a129a835968a66b2ed747074e2194ac0bc169283a7591e086f9ce8e9c91647db7ea2de92c455dd56da5&X-Goog-SignedHeaders=host&X-User=2931823730: HTTPSConnectionPool(host='storage.googleapis.com', port=443): Max retries exceeded with url: /wandb-production.appspot.com/2931823730-harbin-institute-of-technology/ltu-as/gs2gbnar/output.log?X-Goog-Algorithm=GOOG4-RSA-SHA256&X-Goog-Credential=gorilla-files-url-signer-man%40wandb-production.iam.gserviceaccount.com%2F20250411%2Fauto%2Fstorage%2Fgoog4_request&X-Goog-Date=20250411T151651Z&X-Goog-Expires=86399&X-Goog-Signature=ba30f58c1368feee04b8096176a5f2e244167cb273cbeb464b2d54c1d7a74754d10d41baa2225c252e8f1ca8cae03cf7bdbc20126ea319c1a5a5073527bc69e705b985f3542972a3e346e67670267c3c825106e581fe7e66fb1bd28d2792403abe0b0670e4e9a435c897d99fb1d856e848bdf9fb247073360e828f32dd3e2c616076e6778a85204fe1163367bd13091f7c890a8d9294fddbcc4c491aeeb3d4b12338b4933b39b8dc2b8cf7102ad7e2e6abbd201b99725b11eae47d53b86f3ea5ea37930f830b62dd767fd9e7b87b2d477c88515df3677a129a835968a66b2ed747074e2194ac0bc169283a7591e086f9ce8e9c91647db7ea2de92c455dd56da5&X-Goog-SignedHeaders=host&X-User=2931823730 (Caused by NewConnectionError('<urllib3.connection.HTTPSConnection object at 0x7faef4574160>: Failed to establish a new connection: [Errno 101] Network is unreachable'))
2025-04-11 15:16:54,932 ERROR   wandb-upload_4:24150 [internal_api.py:upload_file():2558] upload_file request headers: {'User-Agent': 'python-requests/2.32.3', 'Accept-Encoding': 'gzip, deflate, br', 'Accept': '*/*', 'Connection': 'keep-alive', 'Content-Length': '4566'}
2025-04-11 15:16:54,932 ERROR   wandb-upload_4:24150 [internal_api.py:upload_file():2560] upload_file response body: 
2025-04-11 15:16:55,035 ERROR   wandb-upload_2:24150 [internal_api.py:upload_file():2556] upload_file exception https://storage.googleapis.com/wandb-production.appspot.com/2931823730-harbin-institute-of-technology/ltu-as/gs2gbnar/requirements.txt?X-Goog-Algorithm=GOOG4-RSA-SHA256&X-Goog-Credential=gorilla-files-url-signer-man%40wandb-production.iam.gserviceaccount.com%2F20250411%2Fauto%2Fstorage%2Fgoog4_request&X-Goog-Date=20250411T151651Z&X-Goog-Expires=86399&X-Goog-Signature=abe2767048a665ae692f042124a97fcaab2586fd27692787eae806db284e475580ee0a12dacc4f8c249c8fa01108de939fea9731e921583f5d759548cc605e67740521dc4b8e1747a7414e648b5653b9fbc1c06ec67ec6b4e64d0264d440d3638e45ae3c3c06ac040c5cd8185b6699856ce0631553cfc99cf32e0c4e28746bf95038df96fddc4af2947ed5270d32abc379aa7dc9f494894612ebac60b3fb9ca8f1070ec8abfc84531a916a32e9c9b558ab565519332033e79d24602a77ff6219c45b5940c48fd3d22edf7675d51eb9b8d81bbef3383707c861521ded9c97e05550161527ff961a00782fc508f2cd7a84d4b5cca95f89d511f396237dc4d9d2f9&X-Goog-SignedHeaders=host&X-User=2931823730: HTTPSConnectionPool(host='storage.googleapis.com', port=443): Max retries exceeded with url: /wandb-production.appspot.com/2931823730-harbin-institute-of-technology/ltu-as/gs2gbnar/requirements.txt?X-Goog-Algorithm=GOOG4-RSA-SHA256&X-Goog-Credential=gorilla-files-url-signer-man%40wandb-production.iam.gserviceaccount.com%2F20250411%2Fauto%2Fstorage%2Fgoog4_request&X-Goog-Date=20250411T151651Z&X-Goog-Expires=86399&X-Goog-Signature=abe2767048a665ae692f042124a97fcaab2586fd27692787eae806db284e475580ee0a12dacc4f8c249c8fa01108de939fea9731e921583f5d759548cc605e67740521dc4b8e1747a7414e648b5653b9fbc1c06ec67ec6b4e64d0264d440d3638e45ae3c3c06ac040c5cd8185b6699856ce0631553cfc99cf32e0c4e28746bf95038df96fddc4af2947ed5270d32abc379aa7dc9f494894612ebac60b3fb9ca8f1070ec8abfc84531a916a32e9c9b558ab565519332033e79d24602a77ff6219c45b5940c48fd3d22edf7675d51eb9b8d81bbef3383707c861521ded9c97e05550161527ff961a00782fc508f2cd7a84d4b5cca95f89d511f396237dc4d9d2f9&X-Goog-SignedHeaders=host&X-User=2931823730 (Caused by NewConnectionError('<urllib3.connection.HTTPSConnection object at 0x7faf0c100880>: Failed to establish a new connection: [Errno 101] Network is unreachable'))
2025-04-11 15:16:55,036 ERROR   wandb-upload_2:24150 [internal_api.py:upload_file():2558] upload_file request headers: {'User-Agent': 'python-requests/2.32.3', 'Accept-Encoding': 'gzip, deflate, br', 'Accept': '*/*', 'Connection': 'keep-alive', 'Content-Length': '4212'}
2025-04-11 15:16:55,036 ERROR   wandb-upload_2:24150 [internal_api.py:upload_file():2560] upload_file response body: 
2025-04-11 15:16:55,054 ERROR   wandb-upload_3:24150 [internal_api.py:upload_file():2556] upload_file exception https://storage.googleapis.com/wandb-production.appspot.com/2931823730-harbin-institute-of-technology/ltu-as/gs2gbnar/conda-environment.yaml?X-Goog-Algorithm=GOOG4-RSA-SHA256&X-Goog-Credential=gorilla-files-url-signer-man%40wandb-production.iam.gserviceaccount.com%2F20250411%2Fauto%2Fstorage%2Fgoog4_request&X-Goog-Date=20250411T151651Z&X-Goog-Expires=86399&X-Goog-Signature=85b9174dbccf3057b27c769b2124d9e2e31fadf45d140126242875f8f9469036c29e78351e743d684ffc8acc9f7ccadeb7c6dbd23e4610dc318200a163b8f50a29cc704d1dc3bb33b276d506c72c98b21ff15706aec1a0327d0057e384eab219125527850b2b1544e786a3097a857229407e129578bcabb2e236d17cb57c40308e363182d23cd6a7bf911cee0bcf78e729172bd77fb7e00616353ca94eb47dd74dc041d97ebeb2fc5dd032e4f34b6083b05fff6927c97e66d59f0ea1f380c4d88456b8a037fe3e1f4771a0498ac0e977602029bab9eabd553492643d78e70fbf699a7f9c934cc0fc7ab68a095ef564548136d546195da2890a10ee96c96bdd83&X-Goog-SignedHeaders=host&X-User=2931823730: HTTPSConnectionPool(host='storage.googleapis.com', port=443): Max retries exceeded with url: /wandb-production.appspot.com/2931823730-harbin-institute-of-technology/ltu-as/gs2gbnar/conda-environment.yaml?X-Goog-Algorithm=GOOG4-RSA-SHA256&X-Goog-Credential=gorilla-files-url-signer-man%40wandb-production.iam.gserviceaccount.com%2F20250411%2Fauto%2Fstorage%2Fgoog4_request&X-Goog-Date=20250411T151651Z&X-Goog-Expires=86399&X-Goog-Signature=85b9174dbccf3057b27c769b2124d9e2e31fadf45d140126242875f8f9469036c29e78351e743d684ffc8acc9f7ccadeb7c6dbd23e4610dc318200a163b8f50a29cc704d1dc3bb33b276d506c72c98b21ff15706aec1a0327d0057e384eab219125527850b2b1544e786a3097a857229407e129578bcabb2e236d17cb57c40308e363182d23cd6a7bf911cee0bcf78e729172bd77fb7e00616353ca94eb47dd74dc041d97ebeb2fc5dd032e4f34b6083b05fff6927c97e66d59f0ea1f380c4d88456b8a037fe3e1f4771a0498ac0e977602029bab9eabd553492643d78e70fbf699a7f9c934cc0fc7ab68a095ef564548136d546195da2890a10ee96c96bdd83&X-Goog-SignedHeaders=host&X-User=2931823730 (Caused by NewConnectionError('<urllib3.connection.HTTPSConnection object at 0x7faf0c1000a0>: Failed to establish a new connection: [Errno 101] Network is unreachable'))
2025-04-11 15:16:55,054 ERROR   wandb-upload_3:24150 [internal_api.py:upload_file():2558] upload_file request headers: {'User-Agent': 'python-requests/2.32.3', 'Accept-Encoding': 'gzip, deflate, br', 'Accept': '*/*', 'Connection': 'keep-alive', 'Content-Length': '8281'}
2025-04-11 15:16:55,054 ERROR   wandb-upload_3:24150 [internal_api.py:upload_file():2560] upload_file response body: 
2025-04-11 15:16:55,282 DEBUG   HandlerThread:24150 [handler.py:handle_request():146] handle_request: poll_exit
2025-04-11 15:16:55,283 DEBUG   SenderThread:24150 [sender.py:send_request():407] send_request: poll_exit
2025-04-11 15:16:55,314 ERROR   wandb-upload_5:24150 [internal_api.py:upload_file():2556] upload_file exception https://storage.googleapis.com/wandb-production.appspot.com/2931823730-harbin-institute-of-technology/ltu-as/gs2gbnar/wandb-summary.json?X-Goog-Algorithm=GOOG4-RSA-SHA256&X-Goog-Credential=gorilla-files-url-signer-man%40wandb-production.iam.gserviceaccount.com%2F20250411%2Fauto%2Fstorage%2Fgoog4_request&X-Goog-Date=20250411T151651Z&X-Goog-Expires=86399&X-Goog-Signature=93c831021585447783f056f8e81670116275f90fdeb1754acbe627713f9f562c04a881285011c6c9a9577af09140a02a695646a3e1dfb77a614c8a69b24f4efdb86486f1397df7f39f34fee7a853d786e203d04b9908cad7641c636b0594299e32acbf08556dcd75e46fb0d4df8dd193e2a4f5be1930d444e25a59c32b35b84afe7db688f525422405b488275044af3579cffeea9cb0511dda59c41b7838af9cbdb28868e03bec46f8b0e923f274ca0939980f83c4e2680b8f522ac7b79d47c50ab43d18c07914f31f6eaf2312f6cee550a61b47d849e7e6eafe48d9cff3eb45972df4e25f5d3e553d249e46810ea15de431400330ecb65f7e9e96033812ce23&X-Goog-SignedHeaders=host&X-User=2931823730: HTTPSConnectionPool(host='storage.googleapis.com', port=443): Max retries exceeded with url: /wandb-production.appspot.com/2931823730-harbin-institute-of-technology/ltu-as/gs2gbnar/wandb-summary.json?X-Goog-Algorithm=GOOG4-RSA-SHA256&X-Goog-Credential=gorilla-files-url-signer-man%40wandb-production.iam.gserviceaccount.com%2F20250411%2Fauto%2Fstorage%2Fgoog4_request&X-Goog-Date=20250411T151651Z&X-Goog-Expires=86399&X-Goog-Signature=93c831021585447783f056f8e81670116275f90fdeb1754acbe627713f9f562c04a881285011c6c9a9577af09140a02a695646a3e1dfb77a614c8a69b24f4efdb86486f1397df7f39f34fee7a853d786e203d04b9908cad7641c636b0594299e32acbf08556dcd75e46fb0d4df8dd193e2a4f5be1930d444e25a59c32b35b84afe7db688f525422405b488275044af3579cffeea9cb0511dda59c41b7838af9cbdb28868e03bec46f8b0e923f274ca0939980f83c4e2680b8f522ac7b79d47c50ab43d18c07914f31f6eaf2312f6cee550a61b47d849e7e6eafe48d9cff3eb45972df4e25f5d3e553d249e46810ea15de431400330ecb65f7e9e96033812ce23&X-Goog-SignedHeaders=host&X-User=2931823730 (Caused by NewConnectionError('<urllib3.connection.HTTPSConnection object at 0x7faf0c100790>: Failed to establish a new connection: [Errno 101] Network is unreachable'))
2025-04-11 15:16:55,314 ERROR   wandb-upload_5:24150 [internal_api.py:upload_file():2558] upload_file request headers: {'User-Agent': 'python-requests/2.32.3', 'Accept-Encoding': 'gzip, deflate, br', 'Accept': '*/*', 'Connection': 'keep-alive', 'Content-Length': '27'}
2025-04-11 15:16:55,314 ERROR   wandb-upload_5:24150 [internal_api.py:upload_file():2560] upload_file response body: 
2025-04-11 15:16:56,262 ERROR   wandb-upload_0:24150 [internal_api.py:upload_file():2556] upload_file exception https://storage.googleapis.com/wandb-production.appspot.com/2931823730-harbin-institute-of-technology/ltu-as/gs2gbnar/wandb-metadata.json?X-Goog-Algorithm=GOOG4-RSA-SHA256&X-Goog-Credential=gorilla-files-url-signer-man%40wandb-production.iam.gserviceaccount.com%2F20250411%2Fauto%2Fstorage%2Fgoog4_request&X-Goog-Date=20250411T151639Z&X-Goog-Expires=86399&X-Goog-Signature=5358ca8dd9178c4042e124f62db7893b63346358194f1da9a4d617801f22a15ce1898e415c6bc81a291800b9d1fba488090f88e72655d7a708641f38364f2c188d57866d5c8f035bec72fa5a8c6637e6f20c39a4c0878b4e2b2b22a4792d1274965eab5aacfe5862afa85396edfccc273305e9880d4297a63a1a09c769628ae6c103adcbb85b62b16db6738d7f84d84b22fd45e872a4668482bfa764cfbe74bb81128a0611ed2a4b218b06e200dc688d1b08120e942417d07a985bac42313c6daca9c94b9c3fcce9e59ac6b7c25bfdccb587b8a9496765bc766ed3e50c88534ad6970afd5ee5195f27724e38d72c90202a619e2a34a4c7f9a434fdbf76d5918d&X-Goog-SignedHeaders=host&X-User=2931823730: HTTPSConnectionPool(host='storage.googleapis.com', port=443): Max retries exceeded with url: /wandb-production.appspot.com/2931823730-harbin-institute-of-technology/ltu-as/gs2gbnar/wandb-metadata.json?X-Goog-Algorithm=GOOG4-RSA-SHA256&X-Goog-Credential=gorilla-files-url-signer-man%40wandb-production.iam.gserviceaccount.com%2F20250411%2Fauto%2Fstorage%2Fgoog4_request&X-Goog-Date=20250411T151639Z&X-Goog-Expires=86399&X-Goog-Signature=5358ca8dd9178c4042e124f62db7893b63346358194f1da9a4d617801f22a15ce1898e415c6bc81a291800b9d1fba488090f88e72655d7a708641f38364f2c188d57866d5c8f035bec72fa5a8c6637e6f20c39a4c0878b4e2b2b22a4792d1274965eab5aacfe5862afa85396edfccc273305e9880d4297a63a1a09c769628ae6c103adcbb85b62b16db6738d7f84d84b22fd45e872a4668482bfa764cfbe74bb81128a0611ed2a4b218b06e200dc688d1b08120e942417d07a985bac42313c6daca9c94b9c3fcce9e59ac6b7c25bfdccb587b8a9496765bc766ed3e50c88534ad6970afd5ee5195f27724e38d72c90202a619e2a34a4c7f9a434fdbf76d5918d&X-Goog-SignedHeaders=host&X-User=2931823730 (Caused by NewConnectionError('<urllib3.connection.HTTPSConnection object at 0x7faf0c1006d0>: Failed to establish a new connection: [Errno 101] Network is unreachable'))
2025-04-11 15:16:56,262 ERROR   wandb-upload_0:24150 [internal_api.py:upload_file():2558] upload_file request headers: {'User-Agent': 'python-requests/2.32.3', 'Accept-Encoding': 'gzip, deflate, br', 'Accept': '*/*', 'Connection': 'keep-alive', 'Content-Length': '2274'}
2025-04-11 15:16:56,262 ERROR   wandb-upload_0:24150 [internal_api.py:upload_file():2560] upload_file response body: 
2025-04-11 15:16:56,283 DEBUG   HandlerThread:24150 [handler.py:handle_request():146] handle_request: poll_exit
2025-04-11 15:16:56,284 DEBUG   SenderThread:24150 [sender.py:send_request():407] send_request: poll_exit
2025-04-11 15:16:57,285 DEBUG   HandlerThread:24150 [handler.py:handle_request():146] handle_request: poll_exit
2025-04-11 15:16:57,285 DEBUG   SenderThread:24150 [sender.py:send_request():407] send_request: poll_exit
2025-04-11 15:16:58,286 DEBUG   HandlerThread:24150 [handler.py:handle_request():146] handle_request: poll_exit
2025-04-11 15:16:58,287 DEBUG   SenderThread:24150 [sender.py:send_request():407] send_request: poll_exit
2025-04-11 15:16:59,288 DEBUG   HandlerThread:24150 [handler.py:handle_request():146] handle_request: poll_exit
2025-04-11 15:16:59,289 DEBUG   SenderThread:24150 [sender.py:send_request():407] send_request: poll_exit
2025-04-11 15:16:59,331 ERROR   wandb-upload_4:24150 [internal_api.py:upload_file():2556] upload_file exception https://storage.googleapis.com/wandb-production.appspot.com/2931823730-harbin-institute-of-technology/ltu-as/gs2gbnar/output.log?X-Goog-Algorithm=GOOG4-RSA-SHA256&X-Goog-Credential=gorilla-files-url-signer-man%40wandb-production.iam.gserviceaccount.com%2F20250411%2Fauto%2Fstorage%2Fgoog4_request&X-Goog-Date=20250411T151651Z&X-Goog-Expires=86399&X-Goog-Signature=ba30f58c1368feee04b8096176a5f2e244167cb273cbeb464b2d54c1d7a74754d10d41baa2225c252e8f1ca8cae03cf7bdbc20126ea319c1a5a5073527bc69e705b985f3542972a3e346e67670267c3c825106e581fe7e66fb1bd28d2792403abe0b0670e4e9a435c897d99fb1d856e848bdf9fb247073360e828f32dd3e2c616076e6778a85204fe1163367bd13091f7c890a8d9294fddbcc4c491aeeb3d4b12338b4933b39b8dc2b8cf7102ad7e2e6abbd201b99725b11eae47d53b86f3ea5ea37930f830b62dd767fd9e7b87b2d477c88515df3677a129a835968a66b2ed747074e2194ac0bc169283a7591e086f9ce8e9c91647db7ea2de92c455dd56da5&X-Goog-SignedHeaders=host&X-User=2931823730: HTTPSConnectionPool(host='storage.googleapis.com', port=443): Max retries exceeded with url: /wandb-production.appspot.com/2931823730-harbin-institute-of-technology/ltu-as/gs2gbnar/output.log?X-Goog-Algorithm=GOOG4-RSA-SHA256&X-Goog-Credential=gorilla-files-url-signer-man%40wandb-production.iam.gserviceaccount.com%2F20250411%2Fauto%2Fstorage%2Fgoog4_request&X-Goog-Date=20250411T151651Z&X-Goog-Expires=86399&X-Goog-Signature=ba30f58c1368feee04b8096176a5f2e244167cb273cbeb464b2d54c1d7a74754d10d41baa2225c252e8f1ca8cae03cf7bdbc20126ea319c1a5a5073527bc69e705b985f3542972a3e346e67670267c3c825106e581fe7e66fb1bd28d2792403abe0b0670e4e9a435c897d99fb1d856e848bdf9fb247073360e828f32dd3e2c616076e6778a85204fe1163367bd13091f7c890a8d9294fddbcc4c491aeeb3d4b12338b4933b39b8dc2b8cf7102ad7e2e6abbd201b99725b11eae47d53b86f3ea5ea37930f830b62dd767fd9e7b87b2d477c88515df3677a129a835968a66b2ed747074e2194ac0bc169283a7591e086f9ce8e9c91647db7ea2de92c455dd56da5&X-Goog-SignedHeaders=host&X-User=2931823730 (Caused by NewConnectionError('<urllib3.connection.HTTPSConnection object at 0x7faf0c102530>: Failed to establish a new connection: [Errno 101] Network is unreachable'))
2025-04-11 15:16:59,331 ERROR   wandb-upload_4:24150 [internal_api.py:upload_file():2558] upload_file request headers: {'User-Agent': 'python-requests/2.32.3', 'Accept-Encoding': 'gzip, deflate, br', 'Accept': '*/*', 'Connection': 'keep-alive', 'Content-Length': '4566'}
2025-04-11 15:16:59,331 ERROR   wandb-upload_4:24150 [internal_api.py:upload_file():2560] upload_file response body: 
2025-04-11 15:16:59,504 ERROR   wandb-upload_2:24150 [internal_api.py:upload_file():2556] upload_file exception https://storage.googleapis.com/wandb-production.appspot.com/2931823730-harbin-institute-of-technology/ltu-as/gs2gbnar/requirements.txt?X-Goog-Algorithm=GOOG4-RSA-SHA256&X-Goog-Credential=gorilla-files-url-signer-man%40wandb-production.iam.gserviceaccount.com%2F20250411%2Fauto%2Fstorage%2Fgoog4_request&X-Goog-Date=20250411T151651Z&X-Goog-Expires=86399&X-Goog-Signature=abe2767048a665ae692f042124a97fcaab2586fd27692787eae806db284e475580ee0a12dacc4f8c249c8fa01108de939fea9731e921583f5d759548cc605e67740521dc4b8e1747a7414e648b5653b9fbc1c06ec67ec6b4e64d0264d440d3638e45ae3c3c06ac040c5cd8185b6699856ce0631553cfc99cf32e0c4e28746bf95038df96fddc4af2947ed5270d32abc379aa7dc9f494894612ebac60b3fb9ca8f1070ec8abfc84531a916a32e9c9b558ab565519332033e79d24602a77ff6219c45b5940c48fd3d22edf7675d51eb9b8d81bbef3383707c861521ded9c97e05550161527ff961a00782fc508f2cd7a84d4b5cca95f89d511f396237dc4d9d2f9&X-Goog-SignedHeaders=host&X-User=2931823730: HTTPSConnectionPool(host='storage.googleapis.com', port=443): Max retries exceeded with url: /wandb-production.appspot.com/2931823730-harbin-institute-of-technology/ltu-as/gs2gbnar/requirements.txt?X-Goog-Algorithm=GOOG4-RSA-SHA256&X-Goog-Credential=gorilla-files-url-signer-man%40wandb-production.iam.gserviceaccount.com%2F20250411%2Fauto%2Fstorage%2Fgoog4_request&X-Goog-Date=20250411T151651Z&X-Goog-Expires=86399&X-Goog-Signature=abe2767048a665ae692f042124a97fcaab2586fd27692787eae806db284e475580ee0a12dacc4f8c249c8fa01108de939fea9731e921583f5d759548cc605e67740521dc4b8e1747a7414e648b5653b9fbc1c06ec67ec6b4e64d0264d440d3638e45ae3c3c06ac040c5cd8185b6699856ce0631553cfc99cf32e0c4e28746bf95038df96fddc4af2947ed5270d32abc379aa7dc9f494894612ebac60b3fb9ca8f1070ec8abfc84531a916a32e9c9b558ab565519332033e79d24602a77ff6219c45b5940c48fd3d22edf7675d51eb9b8d81bbef3383707c861521ded9c97e05550161527ff961a00782fc508f2cd7a84d4b5cca95f89d511f396237dc4d9d2f9&X-Goog-SignedHeaders=host&X-User=2931823730 (Caused by NewConnectionError('<urllib3.connection.HTTPSConnection object at 0x7faef45747c0>: Failed to establish a new connection: [Errno 101] Network is unreachable'))
2025-04-11 15:16:59,504 ERROR   wandb-upload_2:24150 [internal_api.py:upload_file():2558] upload_file request headers: {'User-Agent': 'python-requests/2.32.3', 'Accept-Encoding': 'gzip, deflate, br', 'Accept': '*/*', 'Connection': 'keep-alive', 'Content-Length': '4212'}
2025-04-11 15:16:59,504 ERROR   wandb-upload_2:24150 [internal_api.py:upload_file():2560] upload_file response body: 
2025-04-11 15:16:59,602 ERROR   wandb-upload_1:24150 [internal_api.py:upload_file():2556] upload_file exception https://storage.googleapis.com/wandb-production.appspot.com/2931823730-harbin-institute-of-technology/ltu-as/gs2gbnar/config.yaml?X-Goog-Algorithm=GOOG4-RSA-SHA256&X-Goog-Credential=gorilla-files-url-signer-man%40wandb-production.iam.gserviceaccount.com%2F20250411%2Fauto%2Fstorage%2Fgoog4_request&X-Goog-Date=20250411T151651Z&X-Goog-Expires=86399&X-Goog-Signature=9fd08e30d0369f66f38480ba3844f8be9ab3600cf43707967b3f8fe30d0af9c9e39fa4eb7707d79aa262b44896ecc27365c2319d8fe1934f98e30e1a2a3bd2e64e9a908bbc60a11fac5f728d295a53415a462a424edee2fab42c0284fd8c59c2450f01957c7ab0c08deba7e0cb6f83a07cfc2ad5f54c7fdd94d4ea42cd86d2cf32caba7fc97c0c15c3d42d9a3c2c548b4074a300757f592ffba91b47a568270aa548b5273023389360dab014e78c145aacfc65f5bb70c392542a65b70d02dac6dd0099df5a06150f6e6fc932d73cf4946811e59987789d2f32a9beeac4eeac5fbd3c34c0911a5076eee8c93be646ffd58565265af4fc60b22d4e632137d18560&X-Goog-SignedHeaders=host&X-User=2931823730: HTTPSConnectionPool(host='storage.googleapis.com', port=443): Max retries exceeded with url: /wandb-production.appspot.com/2931823730-harbin-institute-of-technology/ltu-as/gs2gbnar/config.yaml?X-Goog-Algorithm=GOOG4-RSA-SHA256&X-Goog-Credential=gorilla-files-url-signer-man%40wandb-production.iam.gserviceaccount.com%2F20250411%2Fauto%2Fstorage%2Fgoog4_request&X-Goog-Date=20250411T151651Z&X-Goog-Expires=86399&X-Goog-Signature=9fd08e30d0369f66f38480ba3844f8be9ab3600cf43707967b3f8fe30d0af9c9e39fa4eb7707d79aa262b44896ecc27365c2319d8fe1934f98e30e1a2a3bd2e64e9a908bbc60a11fac5f728d295a53415a462a424edee2fab42c0284fd8c59c2450f01957c7ab0c08deba7e0cb6f83a07cfc2ad5f54c7fdd94d4ea42cd86d2cf32caba7fc97c0c15c3d42d9a3c2c548b4074a300757f592ffba91b47a568270aa548b5273023389360dab014e78c145aacfc65f5bb70c392542a65b70d02dac6dd0099df5a06150f6e6fc932d73cf4946811e59987789d2f32a9beeac4eeac5fbd3c34c0911a5076eee8c93be646ffd58565265af4fc60b22d4e632137d18560&X-Goog-SignedHeaders=host&X-User=2931823730 (Caused by NewConnectionError('<urllib3.connection.HTTPSConnection object at 0x7faef4576320>: Failed to establish a new connection: [Errno 101] Network is unreachable'))
2025-04-11 15:16:59,603 ERROR   wandb-upload_1:24150 [internal_api.py:upload_file():2558] upload_file request headers: {'User-Agent': 'python-requests/2.32.3', 'Accept-Encoding': 'gzip, deflate, br', 'Accept': '*/*', 'Connection': 'keep-alive', 'Content-Length': '8685'}
2025-04-11 15:16:59,603 ERROR   wandb-upload_1:24150 [internal_api.py:upload_file():2560] upload_file response body: 
2025-04-11 15:16:59,609 ERROR   wandb-upload_5:24150 [internal_api.py:upload_file():2556] upload_file exception https://storage.googleapis.com/wandb-production.appspot.com/2931823730-harbin-institute-of-technology/ltu-as/gs2gbnar/wandb-summary.json?X-Goog-Algorithm=GOOG4-RSA-SHA256&X-Goog-Credential=gorilla-files-url-signer-man%40wandb-production.iam.gserviceaccount.com%2F20250411%2Fauto%2Fstorage%2Fgoog4_request&X-Goog-Date=20250411T151651Z&X-Goog-Expires=86399&X-Goog-Signature=93c831021585447783f056f8e81670116275f90fdeb1754acbe627713f9f562c04a881285011c6c9a9577af09140a02a695646a3e1dfb77a614c8a69b24f4efdb86486f1397df7f39f34fee7a853d786e203d04b9908cad7641c636b0594299e32acbf08556dcd75e46fb0d4df8dd193e2a4f5be1930d444e25a59c32b35b84afe7db688f525422405b488275044af3579cffeea9cb0511dda59c41b7838af9cbdb28868e03bec46f8b0e923f274ca0939980f83c4e2680b8f522ac7b79d47c50ab43d18c07914f31f6eaf2312f6cee550a61b47d849e7e6eafe48d9cff3eb45972df4e25f5d3e553d249e46810ea15de431400330ecb65f7e9e96033812ce23&X-Goog-SignedHeaders=host&X-User=2931823730: HTTPSConnectionPool(host='storage.googleapis.com', port=443): Max retries exceeded with url: /wandb-production.appspot.com/2931823730-harbin-institute-of-technology/ltu-as/gs2gbnar/wandb-summary.json?X-Goog-Algorithm=GOOG4-RSA-SHA256&X-Goog-Credential=gorilla-files-url-signer-man%40wandb-production.iam.gserviceaccount.com%2F20250411%2Fauto%2Fstorage%2Fgoog4_request&X-Goog-Date=20250411T151651Z&X-Goog-Expires=86399&X-Goog-Signature=93c831021585447783f056f8e81670116275f90fdeb1754acbe627713f9f562c04a881285011c6c9a9577af09140a02a695646a3e1dfb77a614c8a69b24f4efdb86486f1397df7f39f34fee7a853d786e203d04b9908cad7641c636b0594299e32acbf08556dcd75e46fb0d4df8dd193e2a4f5be1930d444e25a59c32b35b84afe7db688f525422405b488275044af3579cffeea9cb0511dda59c41b7838af9cbdb28868e03bec46f8b0e923f274ca0939980f83c4e2680b8f522ac7b79d47c50ab43d18c07914f31f6eaf2312f6cee550a61b47d849e7e6eafe48d9cff3eb45972df4e25f5d3e553d249e46810ea15de431400330ecb65f7e9e96033812ce23&X-Goog-SignedHeaders=host&X-User=2931823730 (Caused by NewConnectionError('<urllib3.connection.HTTPSConnection object at 0x7faef4576b00>: Failed to establish a new connection: [Errno 101] Network is unreachable'))
2025-04-11 15:16:59,610 ERROR   wandb-upload_5:24150 [internal_api.py:upload_file():2558] upload_file request headers: {'User-Agent': 'python-requests/2.32.3', 'Accept-Encoding': 'gzip, deflate, br', 'Accept': '*/*', 'Connection': 'keep-alive', 'Content-Length': '27'}
2025-04-11 15:16:59,610 ERROR   wandb-upload_5:24150 [internal_api.py:upload_file():2560] upload_file response body: 
2025-04-11 15:16:59,685 ERROR   wandb-upload_3:24150 [internal_api.py:upload_file():2556] upload_file exception https://storage.googleapis.com/wandb-production.appspot.com/2931823730-harbin-institute-of-technology/ltu-as/gs2gbnar/conda-environment.yaml?X-Goog-Algorithm=GOOG4-RSA-SHA256&X-Goog-Credential=gorilla-files-url-signer-man%40wandb-production.iam.gserviceaccount.com%2F20250411%2Fauto%2Fstorage%2Fgoog4_request&X-Goog-Date=20250411T151651Z&X-Goog-Expires=86399&X-Goog-Signature=85b9174dbccf3057b27c769b2124d9e2e31fadf45d140126242875f8f9469036c29e78351e743d684ffc8acc9f7ccadeb7c6dbd23e4610dc318200a163b8f50a29cc704d1dc3bb33b276d506c72c98b21ff15706aec1a0327d0057e384eab219125527850b2b1544e786a3097a857229407e129578bcabb2e236d17cb57c40308e363182d23cd6a7bf911cee0bcf78e729172bd77fb7e00616353ca94eb47dd74dc041d97ebeb2fc5dd032e4f34b6083b05fff6927c97e66d59f0ea1f380c4d88456b8a037fe3e1f4771a0498ac0e977602029bab9eabd553492643d78e70fbf699a7f9c934cc0fc7ab68a095ef564548136d546195da2890a10ee96c96bdd83&X-Goog-SignedHeaders=host&X-User=2931823730: HTTPSConnectionPool(host='storage.googleapis.com', port=443): Max retries exceeded with url: /wandb-production.appspot.com/2931823730-harbin-institute-of-technology/ltu-as/gs2gbnar/conda-environment.yaml?X-Goog-Algorithm=GOOG4-RSA-SHA256&X-Goog-Credential=gorilla-files-url-signer-man%40wandb-production.iam.gserviceaccount.com%2F20250411%2Fauto%2Fstorage%2Fgoog4_request&X-Goog-Date=20250411T151651Z&X-Goog-Expires=86399&X-Goog-Signature=85b9174dbccf3057b27c769b2124d9e2e31fadf45d140126242875f8f9469036c29e78351e743d684ffc8acc9f7ccadeb7c6dbd23e4610dc318200a163b8f50a29cc704d1dc3bb33b276d506c72c98b21ff15706aec1a0327d0057e384eab219125527850b2b1544e786a3097a857229407e129578bcabb2e236d17cb57c40308e363182d23cd6a7bf911cee0bcf78e729172bd77fb7e00616353ca94eb47dd74dc041d97ebeb2fc5dd032e4f34b6083b05fff6927c97e66d59f0ea1f380c4d88456b8a037fe3e1f4771a0498ac0e977602029bab9eabd553492643d78e70fbf699a7f9c934cc0fc7ab68a095ef564548136d546195da2890a10ee96c96bdd83&X-Goog-SignedHeaders=host&X-User=2931823730 (Caused by NewConnectionError('<urllib3.connection.HTTPSConnection object at 0x7faef4576c50>: Failed to establish a new connection: [Errno 101] Network is unreachable'))
2025-04-11 15:16:59,685 ERROR   wandb-upload_3:24150 [internal_api.py:upload_file():2558] upload_file request headers: {'User-Agent': 'python-requests/2.32.3', 'Accept-Encoding': 'gzip, deflate, br', 'Accept': '*/*', 'Connection': 'keep-alive', 'Content-Length': '8281'}
2025-04-11 15:16:59,685 ERROR   wandb-upload_3:24150 [internal_api.py:upload_file():2560] upload_file response body: 
2025-04-11 15:17:00,289 DEBUG   HandlerThread:24150 [handler.py:handle_request():146] handle_request: poll_exit
2025-04-11 15:17:00,290 DEBUG   HandlerThread:24150 [handler.py:handle_request():146] handle_request: status_report
2025-04-11 15:17:00,291 DEBUG   SenderThread:24150 [sender.py:send_request():407] send_request: poll_exit
2025-04-11 15:17:01,290 DEBUG   HandlerThread:24150 [handler.py:handle_request():146] handle_request: poll_exit
2025-04-11 15:17:01,291 DEBUG   SenderThread:24150 [sender.py:send_request():407] send_request: poll_exit
2025-04-11 15:17:02,291 DEBUG   HandlerThread:24150 [handler.py:handle_request():146] handle_request: poll_exit
2025-04-11 15:17:02,292 DEBUG   SenderThread:24150 [sender.py:send_request():407] send_request: poll_exit
2025-04-11 15:17:03,293 DEBUG   HandlerThread:24150 [handler.py:handle_request():146] handle_request: poll_exit
2025-04-11 15:17:03,294 DEBUG   SenderThread:24150 [sender.py:send_request():407] send_request: poll_exit
2025-04-11 15:17:04,296 DEBUG   HandlerThread:24150 [handler.py:handle_request():146] handle_request: poll_exit
2025-04-11 15:17:04,298 DEBUG   SenderThread:24150 [sender.py:send_request():407] send_request: poll_exit
2025-04-11 15:17:05,297 DEBUG   HandlerThread:24150 [handler.py:handle_request():146] handle_request: poll_exit
2025-04-11 15:17:05,298 DEBUG   SenderThread:24150 [sender.py:send_request():407] send_request: poll_exit
2025-04-11 15:17:05,299 DEBUG   HandlerThread:24150 [handler.py:handle_request():146] handle_request: status_report
2025-04-11 15:17:06,298 DEBUG   HandlerThread:24150 [handler.py:handle_request():146] handle_request: poll_exit
2025-04-11 15:17:06,300 DEBUG   SenderThread:24150 [sender.py:send_request():407] send_request: poll_exit
2025-04-11 15:17:07,300 DEBUG   HandlerThread:24150 [handler.py:handle_request():146] handle_request: poll_exit
2025-04-11 15:17:07,301 DEBUG   SenderThread:24150 [sender.py:send_request():407] send_request: poll_exit
2025-04-11 15:17:07,521 ERROR   wandb-upload_4:24150 [internal_api.py:upload_file():2556] upload_file exception https://storage.googleapis.com/wandb-production.appspot.com/2931823730-harbin-institute-of-technology/ltu-as/gs2gbnar/output.log?X-Goog-Algorithm=GOOG4-RSA-SHA256&X-Goog-Credential=gorilla-files-url-signer-man%40wandb-production.iam.gserviceaccount.com%2F20250411%2Fauto%2Fstorage%2Fgoog4_request&X-Goog-Date=20250411T151651Z&X-Goog-Expires=86399&X-Goog-Signature=ba30f58c1368feee04b8096176a5f2e244167cb273cbeb464b2d54c1d7a74754d10d41baa2225c252e8f1ca8cae03cf7bdbc20126ea319c1a5a5073527bc69e705b985f3542972a3e346e67670267c3c825106e581fe7e66fb1bd28d2792403abe0b0670e4e9a435c897d99fb1d856e848bdf9fb247073360e828f32dd3e2c616076e6778a85204fe1163367bd13091f7c890a8d9294fddbcc4c491aeeb3d4b12338b4933b39b8dc2b8cf7102ad7e2e6abbd201b99725b11eae47d53b86f3ea5ea37930f830b62dd767fd9e7b87b2d477c88515df3677a129a835968a66b2ed747074e2194ac0bc169283a7591e086f9ce8e9c91647db7ea2de92c455dd56da5&X-Goog-SignedHeaders=host&X-User=2931823730: HTTPSConnectionPool(host='storage.googleapis.com', port=443): Max retries exceeded with url: /wandb-production.appspot.com/2931823730-harbin-institute-of-technology/ltu-as/gs2gbnar/output.log?X-Goog-Algorithm=GOOG4-RSA-SHA256&X-Goog-Credential=gorilla-files-url-signer-man%40wandb-production.iam.gserviceaccount.com%2F20250411%2Fauto%2Fstorage%2Fgoog4_request&X-Goog-Date=20250411T151651Z&X-Goog-Expires=86399&X-Goog-Signature=ba30f58c1368feee04b8096176a5f2e244167cb273cbeb464b2d54c1d7a74754d10d41baa2225c252e8f1ca8cae03cf7bdbc20126ea319c1a5a5073527bc69e705b985f3542972a3e346e67670267c3c825106e581fe7e66fb1bd28d2792403abe0b0670e4e9a435c897d99fb1d856e848bdf9fb247073360e828f32dd3e2c616076e6778a85204fe1163367bd13091f7c890a8d9294fddbcc4c491aeeb3d4b12338b4933b39b8dc2b8cf7102ad7e2e6abbd201b99725b11eae47d53b86f3ea5ea37930f830b62dd767fd9e7b87b2d477c88515df3677a129a835968a66b2ed747074e2194ac0bc169283a7591e086f9ce8e9c91647db7ea2de92c455dd56da5&X-Goog-SignedHeaders=host&X-User=2931823730 (Caused by NewConnectionError('<urllib3.connection.HTTPSConnection object at 0x7faef45757e0>: Failed to establish a new connection: [Errno 101] Network is unreachable'))
2025-04-11 15:17:07,521 ERROR   wandb-upload_4:24150 [internal_api.py:upload_file():2558] upload_file request headers: {'User-Agent': 'python-requests/2.32.3', 'Accept-Encoding': 'gzip, deflate, br', 'Accept': '*/*', 'Connection': 'keep-alive', 'Content-Length': '4566'}
2025-04-11 15:17:07,521 ERROR   wandb-upload_4:24150 [internal_api.py:upload_file():2560] upload_file response body: 
2025-04-11 15:17:08,018 ERROR   wandb-upload_2:24150 [internal_api.py:upload_file():2556] upload_file exception https://storage.googleapis.com/wandb-production.appspot.com/2931823730-harbin-institute-of-technology/ltu-as/gs2gbnar/requirements.txt?X-Goog-Algorithm=GOOG4-RSA-SHA256&X-Goog-Credential=gorilla-files-url-signer-man%40wandb-production.iam.gserviceaccount.com%2F20250411%2Fauto%2Fstorage%2Fgoog4_request&X-Goog-Date=20250411T151651Z&X-Goog-Expires=86399&X-Goog-Signature=abe2767048a665ae692f042124a97fcaab2586fd27692787eae806db284e475580ee0a12dacc4f8c249c8fa01108de939fea9731e921583f5d759548cc605e67740521dc4b8e1747a7414e648b5653b9fbc1c06ec67ec6b4e64d0264d440d3638e45ae3c3c06ac040c5cd8185b6699856ce0631553cfc99cf32e0c4e28746bf95038df96fddc4af2947ed5270d32abc379aa7dc9f494894612ebac60b3fb9ca8f1070ec8abfc84531a916a32e9c9b558ab565519332033e79d24602a77ff6219c45b5940c48fd3d22edf7675d51eb9b8d81bbef3383707c861521ded9c97e05550161527ff961a00782fc508f2cd7a84d4b5cca95f89d511f396237dc4d9d2f9&X-Goog-SignedHeaders=host&X-User=2931823730: HTTPSConnectionPool(host='storage.googleapis.com', port=443): Max retries exceeded with url: /wandb-production.appspot.com/2931823730-harbin-institute-of-technology/ltu-as/gs2gbnar/requirements.txt?X-Goog-Algorithm=GOOG4-RSA-SHA256&X-Goog-Credential=gorilla-files-url-signer-man%40wandb-production.iam.gserviceaccount.com%2F20250411%2Fauto%2Fstorage%2Fgoog4_request&X-Goog-Date=20250411T151651Z&X-Goog-Expires=86399&X-Goog-Signature=abe2767048a665ae692f042124a97fcaab2586fd27692787eae806db284e475580ee0a12dacc4f8c249c8fa01108de939fea9731e921583f5d759548cc605e67740521dc4b8e1747a7414e648b5653b9fbc1c06ec67ec6b4e64d0264d440d3638e45ae3c3c06ac040c5cd8185b6699856ce0631553cfc99cf32e0c4e28746bf95038df96fddc4af2947ed5270d32abc379aa7dc9f494894612ebac60b3fb9ca8f1070ec8abfc84531a916a32e9c9b558ab565519332033e79d24602a77ff6219c45b5940c48fd3d22edf7675d51eb9b8d81bbef3383707c861521ded9c97e05550161527ff961a00782fc508f2cd7a84d4b5cca95f89d511f396237dc4d9d2f9&X-Goog-SignedHeaders=host&X-User=2931823730 (Caused by NewConnectionError('<urllib3.connection.HTTPSConnection object at 0x7faf0c102140>: Failed to establish a new connection: [Errno 101] Network is unreachable'))
2025-04-11 15:17:08,019 ERROR   wandb-upload_2:24150 [internal_api.py:upload_file():2558] upload_file request headers: {'User-Agent': 'python-requests/2.32.3', 'Accept-Encoding': 'gzip, deflate, br', 'Accept': '*/*', 'Connection': 'keep-alive', 'Content-Length': '4212'}
2025-04-11 15:17:08,019 ERROR   wandb-upload_2:24150 [internal_api.py:upload_file():2560] upload_file response body: 
2025-04-11 15:17:08,099 ERROR   wandb-upload_5:24150 [internal_api.py:upload_file():2556] upload_file exception https://storage.googleapis.com/wandb-production.appspot.com/2931823730-harbin-institute-of-technology/ltu-as/gs2gbnar/wandb-summary.json?X-Goog-Algorithm=GOOG4-RSA-SHA256&X-Goog-Credential=gorilla-files-url-signer-man%40wandb-production.iam.gserviceaccount.com%2F20250411%2Fauto%2Fstorage%2Fgoog4_request&X-Goog-Date=20250411T151651Z&X-Goog-Expires=86399&X-Goog-Signature=93c831021585447783f056f8e81670116275f90fdeb1754acbe627713f9f562c04a881285011c6c9a9577af09140a02a695646a3e1dfb77a614c8a69b24f4efdb86486f1397df7f39f34fee7a853d786e203d04b9908cad7641c636b0594299e32acbf08556dcd75e46fb0d4df8dd193e2a4f5be1930d444e25a59c32b35b84afe7db688f525422405b488275044af3579cffeea9cb0511dda59c41b7838af9cbdb28868e03bec46f8b0e923f274ca0939980f83c4e2680b8f522ac7b79d47c50ab43d18c07914f31f6eaf2312f6cee550a61b47d849e7e6eafe48d9cff3eb45972df4e25f5d3e553d249e46810ea15de431400330ecb65f7e9e96033812ce23&X-Goog-SignedHeaders=host&X-User=2931823730: HTTPSConnectionPool(host='storage.googleapis.com', port=443): Max retries exceeded with url: /wandb-production.appspot.com/2931823730-harbin-institute-of-technology/ltu-as/gs2gbnar/wandb-summary.json?X-Goog-Algorithm=GOOG4-RSA-SHA256&X-Goog-Credential=gorilla-files-url-signer-man%40wandb-production.iam.gserviceaccount.com%2F20250411%2Fauto%2Fstorage%2Fgoog4_request&X-Goog-Date=20250411T151651Z&X-Goog-Expires=86399&X-Goog-Signature=93c831021585447783f056f8e81670116275f90fdeb1754acbe627713f9f562c04a881285011c6c9a9577af09140a02a695646a3e1dfb77a614c8a69b24f4efdb86486f1397df7f39f34fee7a853d786e203d04b9908cad7641c636b0594299e32acbf08556dcd75e46fb0d4df8dd193e2a4f5be1930d444e25a59c32b35b84afe7db688f525422405b488275044af3579cffeea9cb0511dda59c41b7838af9cbdb28868e03bec46f8b0e923f274ca0939980f83c4e2680b8f522ac7b79d47c50ab43d18c07914f31f6eaf2312f6cee550a61b47d849e7e6eafe48d9cff3eb45972df4e25f5d3e553d249e46810ea15de431400330ecb65f7e9e96033812ce23&X-Goog-SignedHeaders=host&X-User=2931823730 (Caused by NewConnectionError('<urllib3.connection.HTTPSConnection object at 0x7faf0c103fa0>: Failed to establish a new connection: [Errno 101] Network is unreachable'))
2025-04-11 15:17:08,099 ERROR   wandb-upload_5:24150 [internal_api.py:upload_file():2558] upload_file request headers: {'User-Agent': 'python-requests/2.32.3', 'Accept-Encoding': 'gzip, deflate, br', 'Accept': '*/*', 'Connection': 'keep-alive', 'Content-Length': '27'}
2025-04-11 15:17:08,099 ERROR   wandb-upload_5:24150 [internal_api.py:upload_file():2560] upload_file response body: 
2025-04-11 15:17:08,300 DEBUG   HandlerThread:24150 [handler.py:handle_request():146] handle_request: poll_exit
2025-04-11 15:17:08,302 DEBUG   SenderThread:24150 [sender.py:send_request():407] send_request: poll_exit
2025-04-11 15:17:08,545 ERROR   wandb-upload_1:24150 [internal_api.py:upload_file():2556] upload_file exception https://storage.googleapis.com/wandb-production.appspot.com/2931823730-harbin-institute-of-technology/ltu-as/gs2gbnar/config.yaml?X-Goog-Algorithm=GOOG4-RSA-SHA256&X-Goog-Credential=gorilla-files-url-signer-man%40wandb-production.iam.gserviceaccount.com%2F20250411%2Fauto%2Fstorage%2Fgoog4_request&X-Goog-Date=20250411T151651Z&X-Goog-Expires=86399&X-Goog-Signature=9fd08e30d0369f66f38480ba3844f8be9ab3600cf43707967b3f8fe30d0af9c9e39fa4eb7707d79aa262b44896ecc27365c2319d8fe1934f98e30e1a2a3bd2e64e9a908bbc60a11fac5f728d295a53415a462a424edee2fab42c0284fd8c59c2450f01957c7ab0c08deba7e0cb6f83a07cfc2ad5f54c7fdd94d4ea42cd86d2cf32caba7fc97c0c15c3d42d9a3c2c548b4074a300757f592ffba91b47a568270aa548b5273023389360dab014e78c145aacfc65f5bb70c392542a65b70d02dac6dd0099df5a06150f6e6fc932d73cf4946811e59987789d2f32a9beeac4eeac5fbd3c34c0911a5076eee8c93be646ffd58565265af4fc60b22d4e632137d18560&X-Goog-SignedHeaders=host&X-User=2931823730: HTTPSConnectionPool(host='storage.googleapis.com', port=443): Max retries exceeded with url: /wandb-production.appspot.com/2931823730-harbin-institute-of-technology/ltu-as/gs2gbnar/config.yaml?X-Goog-Algorithm=GOOG4-RSA-SHA256&X-Goog-Credential=gorilla-files-url-signer-man%40wandb-production.iam.gserviceaccount.com%2F20250411%2Fauto%2Fstorage%2Fgoog4_request&X-Goog-Date=20250411T151651Z&X-Goog-Expires=86399&X-Goog-Signature=9fd08e30d0369f66f38480ba3844f8be9ab3600cf43707967b3f8fe30d0af9c9e39fa4eb7707d79aa262b44896ecc27365c2319d8fe1934f98e30e1a2a3bd2e64e9a908bbc60a11fac5f728d295a53415a462a424edee2fab42c0284fd8c59c2450f01957c7ab0c08deba7e0cb6f83a07cfc2ad5f54c7fdd94d4ea42cd86d2cf32caba7fc97c0c15c3d42d9a3c2c548b4074a300757f592ffba91b47a568270aa548b5273023389360dab014e78c145aacfc65f5bb70c392542a65b70d02dac6dd0099df5a06150f6e6fc932d73cf4946811e59987789d2f32a9beeac4eeac5fbd3c34c0911a5076eee8c93be646ffd58565265af4fc60b22d4e632137d18560&X-Goog-SignedHeaders=host&X-User=2931823730 (Caused by NewConnectionError('<urllib3.connection.HTTPSConnection object at 0x7faf0c102c50>: Failed to establish a new connection: [Errno 101] Network is unreachable'))
2025-04-11 15:17:08,545 ERROR   wandb-upload_1:24150 [internal_api.py:upload_file():2558] upload_file request headers: {'User-Agent': 'python-requests/2.32.3', 'Accept-Encoding': 'gzip, deflate, br', 'Accept': '*/*', 'Connection': 'keep-alive', 'Content-Length': '8685'}
2025-04-11 15:17:08,546 ERROR   wandb-upload_1:24150 [internal_api.py:upload_file():2560] upload_file response body: 
2025-04-11 15:17:09,301 DEBUG   HandlerThread:24150 [handler.py:handle_request():146] handle_request: poll_exit
2025-04-11 15:17:09,302 DEBUG   SenderThread:24150 [sender.py:send_request():407] send_request: poll_exit
2025-04-11 15:17:09,681 ERROR   wandb-upload_3:24150 [internal_api.py:upload_file():2556] upload_file exception https://storage.googleapis.com/wandb-production.appspot.com/2931823730-harbin-institute-of-technology/ltu-as/gs2gbnar/conda-environment.yaml?X-Goog-Algorithm=GOOG4-RSA-SHA256&X-Goog-Credential=gorilla-files-url-signer-man%40wandb-production.iam.gserviceaccount.com%2F20250411%2Fauto%2Fstorage%2Fgoog4_request&X-Goog-Date=20250411T151651Z&X-Goog-Expires=86399&X-Goog-Signature=85b9174dbccf3057b27c769b2124d9e2e31fadf45d140126242875f8f9469036c29e78351e743d684ffc8acc9f7ccadeb7c6dbd23e4610dc318200a163b8f50a29cc704d1dc3bb33b276d506c72c98b21ff15706aec1a0327d0057e384eab219125527850b2b1544e786a3097a857229407e129578bcabb2e236d17cb57c40308e363182d23cd6a7bf911cee0bcf78e729172bd77fb7e00616353ca94eb47dd74dc041d97ebeb2fc5dd032e4f34b6083b05fff6927c97e66d59f0ea1f380c4d88456b8a037fe3e1f4771a0498ac0e977602029bab9eabd553492643d78e70fbf699a7f9c934cc0fc7ab68a095ef564548136d546195da2890a10ee96c96bdd83&X-Goog-SignedHeaders=host&X-User=2931823730: HTTPSConnectionPool(host='storage.googleapis.com', port=443): Max retries exceeded with url: /wandb-production.appspot.com/2931823730-harbin-institute-of-technology/ltu-as/gs2gbnar/conda-environment.yaml?X-Goog-Algorithm=GOOG4-RSA-SHA256&X-Goog-Credential=gorilla-files-url-signer-man%40wandb-production.iam.gserviceaccount.com%2F20250411%2Fauto%2Fstorage%2Fgoog4_request&X-Goog-Date=20250411T151651Z&X-Goog-Expires=86399&X-Goog-Signature=85b9174dbccf3057b27c769b2124d9e2e31fadf45d140126242875f8f9469036c29e78351e743d684ffc8acc9f7ccadeb7c6dbd23e4610dc318200a163b8f50a29cc704d1dc3bb33b276d506c72c98b21ff15706aec1a0327d0057e384eab219125527850b2b1544e786a3097a857229407e129578bcabb2e236d17cb57c40308e363182d23cd6a7bf911cee0bcf78e729172bd77fb7e00616353ca94eb47dd74dc041d97ebeb2fc5dd032e4f34b6083b05fff6927c97e66d59f0ea1f380c4d88456b8a037fe3e1f4771a0498ac0e977602029bab9eabd553492643d78e70fbf699a7f9c934cc0fc7ab68a095ef564548136d546195da2890a10ee96c96bdd83&X-Goog-SignedHeaders=host&X-User=2931823730 (Caused by NewConnectionError('<urllib3.connection.HTTPSConnection object at 0x7faf0c103f10>: Failed to establish a new connection: [Errno 101] Network is unreachable'))
2025-04-11 15:17:09,681 ERROR   wandb-upload_3:24150 [internal_api.py:upload_file():2558] upload_file request headers: {'User-Agent': 'python-requests/2.32.3', 'Accept-Encoding': 'gzip, deflate, br', 'Accept': '*/*', 'Connection': 'keep-alive', 'Content-Length': '8281'}
2025-04-11 15:17:09,682 ERROR   wandb-upload_3:24150 [internal_api.py:upload_file():2560] upload_file response body: 
2025-04-11 15:17:10,302 DEBUG   HandlerThread:24150 [handler.py:handle_request():146] handle_request: poll_exit
2025-04-11 15:17:10,303 DEBUG   HandlerThread:24150 [handler.py:handle_request():146] handle_request: status_report
2025-04-11 15:17:10,304 DEBUG   SenderThread:24150 [sender.py:send_request():407] send_request: poll_exit
2025-04-11 15:17:11,304 DEBUG   HandlerThread:24150 [handler.py:handle_request():146] handle_request: poll_exit
2025-04-11 15:17:11,304 DEBUG   SenderThread:24150 [sender.py:send_request():407] send_request: poll_exit
2025-04-11 15:17:12,304 DEBUG   HandlerThread:24150 [handler.py:handle_request():146] handle_request: poll_exit
2025-04-11 15:17:12,305 DEBUG   SenderThread:24150 [sender.py:send_request():407] send_request: poll_exit
2025-04-11 15:17:13,306 DEBUG   HandlerThread:24150 [handler.py:handle_request():146] handle_request: poll_exit
2025-04-11 15:17:13,307 DEBUG   SenderThread:24150 [sender.py:send_request():407] send_request: poll_exit
2025-04-11 15:17:14,307 DEBUG   HandlerThread:24150 [handler.py:handle_request():146] handle_request: poll_exit
2025-04-11 15:17:14,308 DEBUG   SenderThread:24150 [sender.py:send_request():407] send_request: poll_exit
2025-04-11 15:17:15,308 DEBUG   HandlerThread:24150 [handler.py:handle_request():146] handle_request: status_report
2025-04-11 15:17:15,310 DEBUG   HandlerThread:24150 [handler.py:handle_request():146] handle_request: poll_exit
2025-04-11 15:17:15,310 DEBUG   SenderThread:24150 [sender.py:send_request():407] send_request: poll_exit
2025-04-11 15:17:15,446 ERROR   wandb-upload_0:24150 [internal_api.py:upload_file():2556] upload_file exception https://storage.googleapis.com/wandb-production.appspot.com/2931823730-harbin-institute-of-technology/ltu-as/gs2gbnar/wandb-metadata.json?X-Goog-Algorithm=GOOG4-RSA-SHA256&X-Goog-Credential=gorilla-files-url-signer-man%40wandb-production.iam.gserviceaccount.com%2F20250411%2Fauto%2Fstorage%2Fgoog4_request&X-Goog-Date=20250411T151639Z&X-Goog-Expires=86399&X-Goog-Signature=5358ca8dd9178c4042e124f62db7893b63346358194f1da9a4d617801f22a15ce1898e415c6bc81a291800b9d1fba488090f88e72655d7a708641f38364f2c188d57866d5c8f035bec72fa5a8c6637e6f20c39a4c0878b4e2b2b22a4792d1274965eab5aacfe5862afa85396edfccc273305e9880d4297a63a1a09c769628ae6c103adcbb85b62b16db6738d7f84d84b22fd45e872a4668482bfa764cfbe74bb81128a0611ed2a4b218b06e200dc688d1b08120e942417d07a985bac42313c6daca9c94b9c3fcce9e59ac6b7c25bfdccb587b8a9496765bc766ed3e50c88534ad6970afd5ee5195f27724e38d72c90202a619e2a34a4c7f9a434fdbf76d5918d&X-Goog-SignedHeaders=host&X-User=2931823730: HTTPSConnectionPool(host='storage.googleapis.com', port=443): Max retries exceeded with url: /wandb-production.appspot.com/2931823730-harbin-institute-of-technology/ltu-as/gs2gbnar/wandb-metadata.json?X-Goog-Algorithm=GOOG4-RSA-SHA256&X-Goog-Credential=gorilla-files-url-signer-man%40wandb-production.iam.gserviceaccount.com%2F20250411%2Fauto%2Fstorage%2Fgoog4_request&X-Goog-Date=20250411T151639Z&X-Goog-Expires=86399&X-Goog-Signature=5358ca8dd9178c4042e124f62db7893b63346358194f1da9a4d617801f22a15ce1898e415c6bc81a291800b9d1fba488090f88e72655d7a708641f38364f2c188d57866d5c8f035bec72fa5a8c6637e6f20c39a4c0878b4e2b2b22a4792d1274965eab5aacfe5862afa85396edfccc273305e9880d4297a63a1a09c769628ae6c103adcbb85b62b16db6738d7f84d84b22fd45e872a4668482bfa764cfbe74bb81128a0611ed2a4b218b06e200dc688d1b08120e942417d07a985bac42313c6daca9c94b9c3fcce9e59ac6b7c25bfdccb587b8a9496765bc766ed3e50c88534ad6970afd5ee5195f27724e38d72c90202a619e2a34a4c7f9a434fdbf76d5918d&X-Goog-SignedHeaders=host&X-User=2931823730 (Caused by NewConnectionError('<urllib3.connection.HTTPSConnection object at 0x7faef4575720>: Failed to establish a new connection: [Errno 101] Network is unreachable'))
2025-04-11 15:17:15,446 ERROR   wandb-upload_0:24150 [internal_api.py:upload_file():2558] upload_file request headers: {'User-Agent': 'python-requests/2.32.3', 'Accept-Encoding': 'gzip, deflate, br', 'Accept': '*/*', 'Connection': 'keep-alive', 'Content-Length': '2274'}
2025-04-11 15:17:15,446 ERROR   wandb-upload_0:24150 [internal_api.py:upload_file():2560] upload_file response body: 
2025-04-11 15:17:16,311 DEBUG   HandlerThread:24150 [handler.py:handle_request():146] handle_request: poll_exit
2025-04-11 15:17:16,312 DEBUG   SenderThread:24150 [sender.py:send_request():407] send_request: poll_exit
2025-04-11 15:17:17,313 DEBUG   HandlerThread:24150 [handler.py:handle_request():146] handle_request: poll_exit
2025-04-11 15:17:17,313 DEBUG   SenderThread:24150 [sender.py:send_request():407] send_request: poll_exit
2025-04-11 15:17:18,314 DEBUG   HandlerThread:24150 [handler.py:handle_request():146] handle_request: poll_exit
2025-04-11 15:17:18,315 DEBUG   SenderThread:24150 [sender.py:send_request():407] send_request: poll_exit
2025-04-11 15:17:19,317 DEBUG   HandlerThread:24150 [handler.py:handle_request():146] handle_request: poll_exit
2025-04-11 15:17:19,317 DEBUG   SenderThread:24150 [sender.py:send_request():407] send_request: poll_exit
2025-04-11 15:17:20,318 DEBUG   HandlerThread:24150 [handler.py:handle_request():146] handle_request: status_report
2025-04-11 15:17:20,319 DEBUG   HandlerThread:24150 [handler.py:handle_request():146] handle_request: poll_exit
2025-04-11 15:17:20,320 DEBUG   SenderThread:24150 [sender.py:send_request():407] send_request: poll_exit
2025-04-11 15:17:21,322 DEBUG   HandlerThread:24150 [handler.py:handle_request():146] handle_request: poll_exit
2025-04-11 15:17:21,322 DEBUG   SenderThread:24150 [sender.py:send_request():407] send_request: poll_exit
2025-04-11 15:17:22,322 DEBUG   HandlerThread:24150 [handler.py:handle_request():146] handle_request: poll_exit
2025-04-11 15:17:22,323 DEBUG   SenderThread:24150 [sender.py:send_request():407] send_request: poll_exit
2025-04-11 15:17:23,325 DEBUG   HandlerThread:24150 [handler.py:handle_request():146] handle_request: poll_exit
2025-04-11 15:17:23,325 DEBUG   SenderThread:24150 [sender.py:send_request():407] send_request: poll_exit
2025-04-11 15:17:23,824 ERROR   wandb-upload_4:24150 [internal_api.py:upload_file():2556] upload_file exception https://storage.googleapis.com/wandb-production.appspot.com/2931823730-harbin-institute-of-technology/ltu-as/gs2gbnar/output.log?X-Goog-Algorithm=GOOG4-RSA-SHA256&X-Goog-Credential=gorilla-files-url-signer-man%40wandb-production.iam.gserviceaccount.com%2F20250411%2Fauto%2Fstorage%2Fgoog4_request&X-Goog-Date=20250411T151651Z&X-Goog-Expires=86399&X-Goog-Signature=ba30f58c1368feee04b8096176a5f2e244167cb273cbeb464b2d54c1d7a74754d10d41baa2225c252e8f1ca8cae03cf7bdbc20126ea319c1a5a5073527bc69e705b985f3542972a3e346e67670267c3c825106e581fe7e66fb1bd28d2792403abe0b0670e4e9a435c897d99fb1d856e848bdf9fb247073360e828f32dd3e2c616076e6778a85204fe1163367bd13091f7c890a8d9294fddbcc4c491aeeb3d4b12338b4933b39b8dc2b8cf7102ad7e2e6abbd201b99725b11eae47d53b86f3ea5ea37930f830b62dd767fd9e7b87b2d477c88515df3677a129a835968a66b2ed747074e2194ac0bc169283a7591e086f9ce8e9c91647db7ea2de92c455dd56da5&X-Goog-SignedHeaders=host&X-User=2931823730: HTTPSConnectionPool(host='storage.googleapis.com', port=443): Max retries exceeded with url: /wandb-production.appspot.com/2931823730-harbin-institute-of-technology/ltu-as/gs2gbnar/output.log?X-Goog-Algorithm=GOOG4-RSA-SHA256&X-Goog-Credential=gorilla-files-url-signer-man%40wandb-production.iam.gserviceaccount.com%2F20250411%2Fauto%2Fstorage%2Fgoog4_request&X-Goog-Date=20250411T151651Z&X-Goog-Expires=86399&X-Goog-Signature=ba30f58c1368feee04b8096176a5f2e244167cb273cbeb464b2d54c1d7a74754d10d41baa2225c252e8f1ca8cae03cf7bdbc20126ea319c1a5a5073527bc69e705b985f3542972a3e346e67670267c3c825106e581fe7e66fb1bd28d2792403abe0b0670e4e9a435c897d99fb1d856e848bdf9fb247073360e828f32dd3e2c616076e6778a85204fe1163367bd13091f7c890a8d9294fddbcc4c491aeeb3d4b12338b4933b39b8dc2b8cf7102ad7e2e6abbd201b99725b11eae47d53b86f3ea5ea37930f830b62dd767fd9e7b87b2d477c88515df3677a129a835968a66b2ed747074e2194ac0bc169283a7591e086f9ce8e9c91647db7ea2de92c455dd56da5&X-Goog-SignedHeaders=host&X-User=2931823730 (Caused by NewConnectionError('<urllib3.connection.HTTPSConnection object at 0x7faef45766e0>: Failed to establish a new connection: [Errno 101] Network is unreachable'))
2025-04-11 15:17:23,824 ERROR   wandb-upload_4:24150 [internal_api.py:upload_file():2558] upload_file request headers: {'User-Agent': 'python-requests/2.32.3', 'Accept-Encoding': 'gzip, deflate, br', 'Accept': '*/*', 'Connection': 'keep-alive', 'Content-Length': '4566'}
2025-04-11 15:17:23,824 ERROR   wandb-upload_4:24150 [internal_api.py:upload_file():2560] upload_file response body: 
2025-04-11 15:17:24,327 DEBUG   HandlerThread:24150 [handler.py:handle_request():146] handle_request: poll_exit
2025-04-11 15:17:24,328 DEBUG   SenderThread:24150 [sender.py:send_request():407] send_request: poll_exit
2025-04-11 15:17:25,328 DEBUG   HandlerThread:24150 [handler.py:handle_request():146] handle_request: status_report
2025-04-11 15:17:25,330 DEBUG   HandlerThread:24150 [handler.py:handle_request():146] handle_request: poll_exit
2025-04-11 15:17:25,331 DEBUG   SenderThread:24150 [sender.py:send_request():407] send_request: poll_exit
2025-04-11 15:17:26,331 DEBUG   HandlerThread:24150 [handler.py:handle_request():146] handle_request: poll_exit
2025-04-11 15:17:26,332 DEBUG   SenderThread:24150 [sender.py:send_request():407] send_request: poll_exit
2025-04-11 15:17:26,939 ERROR   wandb-upload_5:24150 [internal_api.py:upload_file():2556] upload_file exception https://storage.googleapis.com/wandb-production.appspot.com/2931823730-harbin-institute-of-technology/ltu-as/gs2gbnar/wandb-summary.json?X-Goog-Algorithm=GOOG4-RSA-SHA256&X-Goog-Credential=gorilla-files-url-signer-man%40wandb-production.iam.gserviceaccount.com%2F20250411%2Fauto%2Fstorage%2Fgoog4_request&X-Goog-Date=20250411T151651Z&X-Goog-Expires=86399&X-Goog-Signature=93c831021585447783f056f8e81670116275f90fdeb1754acbe627713f9f562c04a881285011c6c9a9577af09140a02a695646a3e1dfb77a614c8a69b24f4efdb86486f1397df7f39f34fee7a853d786e203d04b9908cad7641c636b0594299e32acbf08556dcd75e46fb0d4df8dd193e2a4f5be1930d444e25a59c32b35b84afe7db688f525422405b488275044af3579cffeea9cb0511dda59c41b7838af9cbdb28868e03bec46f8b0e923f274ca0939980f83c4e2680b8f522ac7b79d47c50ab43d18c07914f31f6eaf2312f6cee550a61b47d849e7e6eafe48d9cff3eb45972df4e25f5d3e553d249e46810ea15de431400330ecb65f7e9e96033812ce23&X-Goog-SignedHeaders=host&X-User=2931823730: HTTPSConnectionPool(host='storage.googleapis.com', port=443): Max retries exceeded with url: /wandb-production.appspot.com/2931823730-harbin-institute-of-technology/ltu-as/gs2gbnar/wandb-summary.json?X-Goog-Algorithm=GOOG4-RSA-SHA256&X-Goog-Credential=gorilla-files-url-signer-man%40wandb-production.iam.gserviceaccount.com%2F20250411%2Fauto%2Fstorage%2Fgoog4_request&X-Goog-Date=20250411T151651Z&X-Goog-Expires=86399&X-Goog-Signature=93c831021585447783f056f8e81670116275f90fdeb1754acbe627713f9f562c04a881285011c6c9a9577af09140a02a695646a3e1dfb77a614c8a69b24f4efdb86486f1397df7f39f34fee7a853d786e203d04b9908cad7641c636b0594299e32acbf08556dcd75e46fb0d4df8dd193e2a4f5be1930d444e25a59c32b35b84afe7db688f525422405b488275044af3579cffeea9cb0511dda59c41b7838af9cbdb28868e03bec46f8b0e923f274ca0939980f83c4e2680b8f522ac7b79d47c50ab43d18c07914f31f6eaf2312f6cee550a61b47d849e7e6eafe48d9cff3eb45972df4e25f5d3e553d249e46810ea15de431400330ecb65f7e9e96033812ce23&X-Goog-SignedHeaders=host&X-User=2931823730 (Caused by NewConnectionError('<urllib3.connection.HTTPSConnection object at 0x7faef4576470>: Failed to establish a new connection: [Errno 101] Network is unreachable'))
2025-04-11 15:17:26,940 ERROR   wandb-upload_5:24150 [internal_api.py:upload_file():2558] upload_file request headers: {'User-Agent': 'python-requests/2.32.3', 'Accept-Encoding': 'gzip, deflate, br', 'Accept': '*/*', 'Connection': 'keep-alive', 'Content-Length': '27'}
2025-04-11 15:17:26,940 ERROR   wandb-upload_5:24150 [internal_api.py:upload_file():2560] upload_file response body: 
2025-04-11 15:17:27,332 DEBUG   HandlerThread:24150 [handler.py:handle_request():146] handle_request: poll_exit
2025-04-11 15:17:27,332 DEBUG   SenderThread:24150 [sender.py:send_request():407] send_request: poll_exit
2025-04-11 15:17:27,359 ERROR   wandb-upload_2:24150 [internal_api.py:upload_file():2556] upload_file exception https://storage.googleapis.com/wandb-production.appspot.com/2931823730-harbin-institute-of-technology/ltu-as/gs2gbnar/requirements.txt?X-Goog-Algorithm=GOOG4-RSA-SHA256&X-Goog-Credential=gorilla-files-url-signer-man%40wandb-production.iam.gserviceaccount.com%2F20250411%2Fauto%2Fstorage%2Fgoog4_request&X-Goog-Date=20250411T151651Z&X-Goog-Expires=86399&X-Goog-Signature=abe2767048a665ae692f042124a97fcaab2586fd27692787eae806db284e475580ee0a12dacc4f8c249c8fa01108de939fea9731e921583f5d759548cc605e67740521dc4b8e1747a7414e648b5653b9fbc1c06ec67ec6b4e64d0264d440d3638e45ae3c3c06ac040c5cd8185b6699856ce0631553cfc99cf32e0c4e28746bf95038df96fddc4af2947ed5270d32abc379aa7dc9f494894612ebac60b3fb9ca8f1070ec8abfc84531a916a32e9c9b558ab565519332033e79d24602a77ff6219c45b5940c48fd3d22edf7675d51eb9b8d81bbef3383707c861521ded9c97e05550161527ff961a00782fc508f2cd7a84d4b5cca95f89d511f396237dc4d9d2f9&X-Goog-SignedHeaders=host&X-User=2931823730: HTTPSConnectionPool(host='storage.googleapis.com', port=443): Max retries exceeded with url: /wandb-production.appspot.com/2931823730-harbin-institute-of-technology/ltu-as/gs2gbnar/requirements.txt?X-Goog-Algorithm=GOOG4-RSA-SHA256&X-Goog-Credential=gorilla-files-url-signer-man%40wandb-production.iam.gserviceaccount.com%2F20250411%2Fauto%2Fstorage%2Fgoog4_request&X-Goog-Date=20250411T151651Z&X-Goog-Expires=86399&X-Goog-Signature=abe2767048a665ae692f042124a97fcaab2586fd27692787eae806db284e475580ee0a12dacc4f8c249c8fa01108de939fea9731e921583f5d759548cc605e67740521dc4b8e1747a7414e648b5653b9fbc1c06ec67ec6b4e64d0264d440d3638e45ae3c3c06ac040c5cd8185b6699856ce0631553cfc99cf32e0c4e28746bf95038df96fddc4af2947ed5270d32abc379aa7dc9f494894612ebac60b3fb9ca8f1070ec8abfc84531a916a32e9c9b558ab565519332033e79d24602a77ff6219c45b5940c48fd3d22edf7675d51eb9b8d81bbef3383707c861521ded9c97e05550161527ff961a00782fc508f2cd7a84d4b5cca95f89d511f396237dc4d9d2f9&X-Goog-SignedHeaders=host&X-User=2931823730 (Caused by NewConnectionError('<urllib3.connection.HTTPSConnection object at 0x7faef4576350>: Failed to establish a new connection: [Errno 101] Network is unreachable'))
2025-04-11 15:17:27,359 ERROR   wandb-upload_2:24150 [internal_api.py:upload_file():2558] upload_file request headers: {'User-Agent': 'python-requests/2.32.3', 'Accept-Encoding': 'gzip, deflate, br', 'Accept': '*/*', 'Connection': 'keep-alive', 'Content-Length': '4212'}
2025-04-11 15:17:27,359 ERROR   wandb-upload_2:24150 [internal_api.py:upload_file():2560] upload_file response body: 
2025-04-11 15:17:28,054 ERROR   wandb-upload_1:24150 [internal_api.py:upload_file():2556] upload_file exception https://storage.googleapis.com/wandb-production.appspot.com/2931823730-harbin-institute-of-technology/ltu-as/gs2gbnar/config.yaml?X-Goog-Algorithm=GOOG4-RSA-SHA256&X-Goog-Credential=gorilla-files-url-signer-man%40wandb-production.iam.gserviceaccount.com%2F20250411%2Fauto%2Fstorage%2Fgoog4_request&X-Goog-Date=20250411T151651Z&X-Goog-Expires=86399&X-Goog-Signature=9fd08e30d0369f66f38480ba3844f8be9ab3600cf43707967b3f8fe30d0af9c9e39fa4eb7707d79aa262b44896ecc27365c2319d8fe1934f98e30e1a2a3bd2e64e9a908bbc60a11fac5f728d295a53415a462a424edee2fab42c0284fd8c59c2450f01957c7ab0c08deba7e0cb6f83a07cfc2ad5f54c7fdd94d4ea42cd86d2cf32caba7fc97c0c15c3d42d9a3c2c548b4074a300757f592ffba91b47a568270aa548b5273023389360dab014e78c145aacfc65f5bb70c392542a65b70d02dac6dd0099df5a06150f6e6fc932d73cf4946811e59987789d2f32a9beeac4eeac5fbd3c34c0911a5076eee8c93be646ffd58565265af4fc60b22d4e632137d18560&X-Goog-SignedHeaders=host&X-User=2931823730: HTTPSConnectionPool(host='storage.googleapis.com', port=443): Max retries exceeded with url: /wandb-production.appspot.com/2931823730-harbin-institute-of-technology/ltu-as/gs2gbnar/config.yaml?X-Goog-Algorithm=GOOG4-RSA-SHA256&X-Goog-Credential=gorilla-files-url-signer-man%40wandb-production.iam.gserviceaccount.com%2F20250411%2Fauto%2Fstorage%2Fgoog4_request&X-Goog-Date=20250411T151651Z&X-Goog-Expires=86399&X-Goog-Signature=9fd08e30d0369f66f38480ba3844f8be9ab3600cf43707967b3f8fe30d0af9c9e39fa4eb7707d79aa262b44896ecc27365c2319d8fe1934f98e30e1a2a3bd2e64e9a908bbc60a11fac5f728d295a53415a462a424edee2fab42c0284fd8c59c2450f01957c7ab0c08deba7e0cb6f83a07cfc2ad5f54c7fdd94d4ea42cd86d2cf32caba7fc97c0c15c3d42d9a3c2c548b4074a300757f592ffba91b47a568270aa548b5273023389360dab014e78c145aacfc65f5bb70c392542a65b70d02dac6dd0099df5a06150f6e6fc932d73cf4946811e59987789d2f32a9beeac4eeac5fbd3c34c0911a5076eee8c93be646ffd58565265af4fc60b22d4e632137d18560&X-Goog-SignedHeaders=host&X-User=2931823730 (Caused by NewConnectionError('<urllib3.connection.HTTPSConnection object at 0x7faef45747f0>: Failed to establish a new connection: [Errno 101] Network is unreachable'))
2025-04-11 15:17:28,055 ERROR   wandb-upload_1:24150 [internal_api.py:upload_file():2558] upload_file request headers: {'User-Agent': 'python-requests/2.32.3', 'Accept-Encoding': 'gzip, deflate, br', 'Accept': '*/*', 'Connection': 'keep-alive', 'Content-Length': '8685'}
2025-04-11 15:17:28,055 ERROR   wandb-upload_1:24150 [internal_api.py:upload_file():2560] upload_file response body: 
2025-04-11 15:17:28,333 DEBUG   HandlerThread:24150 [handler.py:handle_request():146] handle_request: poll_exit
2025-04-11 15:17:28,334 DEBUG   SenderThread:24150 [sender.py:send_request():407] send_request: poll_exit
2025-04-11 15:17:29,334 DEBUG   HandlerThread:24150 [handler.py:handle_request():146] handle_request: poll_exit
2025-04-11 15:17:29,334 DEBUG   SenderThread:24150 [sender.py:send_request():407] send_request: poll_exit
2025-04-11 15:17:29,383 ERROR   wandb-upload_3:24150 [internal_api.py:upload_file():2556] upload_file exception https://storage.googleapis.com/wandb-production.appspot.com/2931823730-harbin-institute-of-technology/ltu-as/gs2gbnar/conda-environment.yaml?X-Goog-Algorithm=GOOG4-RSA-SHA256&X-Goog-Credential=gorilla-files-url-signer-man%40wandb-production.iam.gserviceaccount.com%2F20250411%2Fauto%2Fstorage%2Fgoog4_request&X-Goog-Date=20250411T151651Z&X-Goog-Expires=86399&X-Goog-Signature=85b9174dbccf3057b27c769b2124d9e2e31fadf45d140126242875f8f9469036c29e78351e743d684ffc8acc9f7ccadeb7c6dbd23e4610dc318200a163b8f50a29cc704d1dc3bb33b276d506c72c98b21ff15706aec1a0327d0057e384eab219125527850b2b1544e786a3097a857229407e129578bcabb2e236d17cb57c40308e363182d23cd6a7bf911cee0bcf78e729172bd77fb7e00616353ca94eb47dd74dc041d97ebeb2fc5dd032e4f34b6083b05fff6927c97e66d59f0ea1f380c4d88456b8a037fe3e1f4771a0498ac0e977602029bab9eabd553492643d78e70fbf699a7f9c934cc0fc7ab68a095ef564548136d546195da2890a10ee96c96bdd83&X-Goog-SignedHeaders=host&X-User=2931823730: HTTPSConnectionPool(host='storage.googleapis.com', port=443): Max retries exceeded with url: /wandb-production.appspot.com/2931823730-harbin-institute-of-technology/ltu-as/gs2gbnar/conda-environment.yaml?X-Goog-Algorithm=GOOG4-RSA-SHA256&X-Goog-Credential=gorilla-files-url-signer-man%40wandb-production.iam.gserviceaccount.com%2F20250411%2Fauto%2Fstorage%2Fgoog4_request&X-Goog-Date=20250411T151651Z&X-Goog-Expires=86399&X-Goog-Signature=85b9174dbccf3057b27c769b2124d9e2e31fadf45d140126242875f8f9469036c29e78351e743d684ffc8acc9f7ccadeb7c6dbd23e4610dc318200a163b8f50a29cc704d1dc3bb33b276d506c72c98b21ff15706aec1a0327d0057e384eab219125527850b2b1544e786a3097a857229407e129578bcabb2e236d17cb57c40308e363182d23cd6a7bf911cee0bcf78e729172bd77fb7e00616353ca94eb47dd74dc041d97ebeb2fc5dd032e4f34b6083b05fff6927c97e66d59f0ea1f380c4d88456b8a037fe3e1f4771a0498ac0e977602029bab9eabd553492643d78e70fbf699a7f9c934cc0fc7ab68a095ef564548136d546195da2890a10ee96c96bdd83&X-Goog-SignedHeaders=host&X-User=2931823730 (Caused by NewConnectionError('<urllib3.connection.HTTPSConnection object at 0x7faef45749a0>: Failed to establish a new connection: [Errno 101] Network is unreachable'))
2025-04-11 15:17:29,383 ERROR   wandb-upload_3:24150 [internal_api.py:upload_file():2558] upload_file request headers: {'User-Agent': 'python-requests/2.32.3', 'Accept-Encoding': 'gzip, deflate, br', 'Accept': '*/*', 'Connection': 'keep-alive', 'Content-Length': '8281'}
2025-04-11 15:17:29,383 ERROR   wandb-upload_3:24150 [internal_api.py:upload_file():2560] upload_file response body: 
2025-04-11 15:17:30,335 DEBUG   HandlerThread:24150 [handler.py:handle_request():146] handle_request: poll_exit
2025-04-11 15:17:30,336 DEBUG   HandlerThread:24150 [handler.py:handle_request():146] handle_request: status_report
2025-04-11 15:17:30,337 DEBUG   SenderThread:24150 [sender.py:send_request():407] send_request: poll_exit
2025-04-11 15:17:31,336 DEBUG   HandlerThread:24150 [handler.py:handle_request():146] handle_request: poll_exit
2025-04-11 15:17:31,337 DEBUG   SenderThread:24150 [sender.py:send_request():407] send_request: poll_exit
2025-04-11 15:17:32,338 DEBUG   HandlerThread:24150 [handler.py:handle_request():146] handle_request: poll_exit
2025-04-11 15:17:32,339 DEBUG   SenderThread:24150 [sender.py:send_request():407] send_request: poll_exit
2025-04-11 15:17:33,338 DEBUG   HandlerThread:24150 [handler.py:handle_request():146] handle_request: poll_exit
2025-04-11 15:17:33,340 DEBUG   SenderThread:24150 [sender.py:send_request():407] send_request: poll_exit
2025-04-11 15:17:34,340 DEBUG   HandlerThread:24150 [handler.py:handle_request():146] handle_request: poll_exit
2025-04-11 15:17:34,341 DEBUG   SenderThread:24150 [sender.py:send_request():407] send_request: poll_exit
2025-04-11 15:17:35,341 DEBUG   HandlerThread:24150 [handler.py:handle_request():146] handle_request: poll_exit
2025-04-11 15:17:35,342 DEBUG   HandlerThread:24150 [handler.py:handle_request():146] handle_request: status_report
2025-04-11 15:17:35,342 DEBUG   SenderThread:24150 [sender.py:send_request():407] send_request: poll_exit
2025-04-11 15:17:36,342 DEBUG   HandlerThread:24150 [handler.py:handle_request():146] handle_request: poll_exit
2025-04-11 15:17:36,343 DEBUG   SenderThread:24150 [sender.py:send_request():407] send_request: poll_exit
2025-04-11 15:17:37,345 DEBUG   HandlerThread:24150 [handler.py:handle_request():146] handle_request: poll_exit
2025-04-11 15:17:37,345 DEBUG   SenderThread:24150 [sender.py:send_request():407] send_request: poll_exit
2025-04-11 15:17:38,346 DEBUG   HandlerThread:24150 [handler.py:handle_request():146] handle_request: poll_exit
2025-04-11 15:17:38,347 DEBUG   SenderThread:24150 [sender.py:send_request():407] send_request: poll_exit
2025-04-11 15:17:39,349 DEBUG   HandlerThread:24150 [handler.py:handle_request():146] handle_request: poll_exit
2025-04-11 15:17:39,349 DEBUG   SenderThread:24150 [sender.py:send_request():407] send_request: poll_exit
2025-04-11 15:17:40,350 DEBUG   HandlerThread:24150 [handler.py:handle_request():146] handle_request: poll_exit
2025-04-11 15:17:40,351 DEBUG   SenderThread:24150 [sender.py:send_request():407] send_request: poll_exit
2025-04-11 15:17:40,353 DEBUG   HandlerThread:24150 [handler.py:handle_request():146] handle_request: status_report
2025-04-11 15:17:41,353 DEBUG   HandlerThread:24150 [handler.py:handle_request():146] handle_request: poll_exit
2025-04-11 15:17:41,354 DEBUG   SenderThread:24150 [sender.py:send_request():407] send_request: poll_exit
2025-04-11 15:17:42,354 DEBUG   HandlerThread:24150 [handler.py:handle_request():146] handle_request: poll_exit
2025-04-11 15:17:42,355 DEBUG   SenderThread:24150 [sender.py:send_request():407] send_request: poll_exit
2025-04-11 15:17:43,355 DEBUG   HandlerThread:24150 [handler.py:handle_request():146] handle_request: poll_exit
2025-04-11 15:17:43,356 DEBUG   SenderThread:24150 [sender.py:send_request():407] send_request: poll_exit
2025-04-11 15:17:44,356 DEBUG   HandlerThread:24150 [handler.py:handle_request():146] handle_request: poll_exit
2025-04-11 15:17:44,357 DEBUG   SenderThread:24150 [sender.py:send_request():407] send_request: poll_exit
2025-04-11 15:17:45,358 DEBUG   HandlerThread:24150 [handler.py:handle_request():146] handle_request: poll_exit
2025-04-11 15:17:45,358 DEBUG   HandlerThread:24150 [handler.py:handle_request():146] handle_request: status_report
2025-04-11 15:17:45,359 DEBUG   SenderThread:24150 [sender.py:send_request():407] send_request: poll_exit
2025-04-11 15:17:46,359 DEBUG   HandlerThread:24150 [handler.py:handle_request():146] handle_request: poll_exit
2025-04-11 15:17:46,360 DEBUG   SenderThread:24150 [sender.py:send_request():407] send_request: poll_exit
2025-04-11 15:17:47,361 DEBUG   HandlerThread:24150 [handler.py:handle_request():146] handle_request: poll_exit
2025-04-11 15:17:47,362 DEBUG   SenderThread:24150 [sender.py:send_request():407] send_request: poll_exit
2025-04-11 15:17:48,362 DEBUG   HandlerThread:24150 [handler.py:handle_request():146] handle_request: poll_exit
2025-04-11 15:17:48,363 DEBUG   SenderThread:24150 [sender.py:send_request():407] send_request: poll_exit
2025-04-11 15:17:49,364 DEBUG   HandlerThread:24150 [handler.py:handle_request():146] handle_request: poll_exit
2025-04-11 15:17:49,365 DEBUG   SenderThread:24150 [sender.py:send_request():407] send_request: poll_exit
2025-04-11 15:17:50,365 DEBUG   HandlerThread:24150 [handler.py:handle_request():146] handle_request: poll_exit
2025-04-11 15:17:50,366 DEBUG   SenderThread:24150 [sender.py:send_request():407] send_request: poll_exit
2025-04-11 15:17:50,366 DEBUG   HandlerThread:24150 [handler.py:handle_request():146] handle_request: status_report
2025-04-11 15:17:51,367 DEBUG   HandlerThread:24150 [handler.py:handle_request():146] handle_request: poll_exit
2025-04-11 15:17:51,369 DEBUG   SenderThread:24150 [sender.py:send_request():407] send_request: poll_exit
2025-04-11 15:17:52,163 ERROR   wandb-upload_0:24150 [internal_api.py:upload_file():2556] upload_file exception https://storage.googleapis.com/wandb-production.appspot.com/2931823730-harbin-institute-of-technology/ltu-as/gs2gbnar/wandb-metadata.json?X-Goog-Algorithm=GOOG4-RSA-SHA256&X-Goog-Credential=gorilla-files-url-signer-man%40wandb-production.iam.gserviceaccount.com%2F20250411%2Fauto%2Fstorage%2Fgoog4_request&X-Goog-Date=20250411T151639Z&X-Goog-Expires=86399&X-Goog-Signature=5358ca8dd9178c4042e124f62db7893b63346358194f1da9a4d617801f22a15ce1898e415c6bc81a291800b9d1fba488090f88e72655d7a708641f38364f2c188d57866d5c8f035bec72fa5a8c6637e6f20c39a4c0878b4e2b2b22a4792d1274965eab5aacfe5862afa85396edfccc273305e9880d4297a63a1a09c769628ae6c103adcbb85b62b16db6738d7f84d84b22fd45e872a4668482bfa764cfbe74bb81128a0611ed2a4b218b06e200dc688d1b08120e942417d07a985bac42313c6daca9c94b9c3fcce9e59ac6b7c25bfdccb587b8a9496765bc766ed3e50c88534ad6970afd5ee5195f27724e38d72c90202a619e2a34a4c7f9a434fdbf76d5918d&X-Goog-SignedHeaders=host&X-User=2931823730: HTTPSConnectionPool(host='storage.googleapis.com', port=443): Max retries exceeded with url: /wandb-production.appspot.com/2931823730-harbin-institute-of-technology/ltu-as/gs2gbnar/wandb-metadata.json?X-Goog-Algorithm=GOOG4-RSA-SHA256&X-Goog-Credential=gorilla-files-url-signer-man%40wandb-production.iam.gserviceaccount.com%2F20250411%2Fauto%2Fstorage%2Fgoog4_request&X-Goog-Date=20250411T151639Z&X-Goog-Expires=86399&X-Goog-Signature=5358ca8dd9178c4042e124f62db7893b63346358194f1da9a4d617801f22a15ce1898e415c6bc81a291800b9d1fba488090f88e72655d7a708641f38364f2c188d57866d5c8f035bec72fa5a8c6637e6f20c39a4c0878b4e2b2b22a4792d1274965eab5aacfe5862afa85396edfccc273305e9880d4297a63a1a09c769628ae6c103adcbb85b62b16db6738d7f84d84b22fd45e872a4668482bfa764cfbe74bb81128a0611ed2a4b218b06e200dc688d1b08120e942417d07a985bac42313c6daca9c94b9c3fcce9e59ac6b7c25bfdccb587b8a9496765bc766ed3e50c88534ad6970afd5ee5195f27724e38d72c90202a619e2a34a4c7f9a434fdbf76d5918d&X-Goog-SignedHeaders=host&X-User=2931823730 (Caused by NewConnectionError('<urllib3.connection.HTTPSConnection object at 0x7faf0c100400>: Failed to establish a new connection: [Errno 101] Network is unreachable'))
2025-04-11 15:17:52,163 ERROR   wandb-upload_0:24150 [internal_api.py:upload_file():2558] upload_file request headers: {'User-Agent': 'python-requests/2.32.3', 'Accept-Encoding': 'gzip, deflate, br', 'Accept': '*/*', 'Connection': 'keep-alive', 'Content-Length': '2274'}
2025-04-11 15:17:52,163 ERROR   wandb-upload_0:24150 [internal_api.py:upload_file():2560] upload_file response body: 
2025-04-11 15:17:52,368 DEBUG   HandlerThread:24150 [handler.py:handle_request():146] handle_request: poll_exit
2025-04-11 15:17:52,369 DEBUG   SenderThread:24150 [sender.py:send_request():407] send_request: poll_exit
2025-04-11 15:17:53,371 DEBUG   HandlerThread:24150 [handler.py:handle_request():146] handle_request: poll_exit
2025-04-11 15:17:53,372 DEBUG   SenderThread:24150 [sender.py:send_request():407] send_request: poll_exit
2025-04-11 15:17:54,372 DEBUG   HandlerThread:24150 [handler.py:handle_request():146] handle_request: poll_exit
2025-04-11 15:17:54,373 DEBUG   SenderThread:24150 [sender.py:send_request():407] send_request: poll_exit
2025-04-11 15:17:55,373 DEBUG   HandlerThread:24150 [handler.py:handle_request():146] handle_request: status_report
2025-04-11 15:17:55,374 DEBUG   HandlerThread:24150 [handler.py:handle_request():146] handle_request: poll_exit
2025-04-11 15:17:55,375 DEBUG   SenderThread:24150 [sender.py:send_request():407] send_request: poll_exit
2025-04-11 15:17:55,885 ERROR   wandb-upload_4:24150 [internal_api.py:upload_file():2556] upload_file exception https://storage.googleapis.com/wandb-production.appspot.com/2931823730-harbin-institute-of-technology/ltu-as/gs2gbnar/output.log?X-Goog-Algorithm=GOOG4-RSA-SHA256&X-Goog-Credential=gorilla-files-url-signer-man%40wandb-production.iam.gserviceaccount.com%2F20250411%2Fauto%2Fstorage%2Fgoog4_request&X-Goog-Date=20250411T151651Z&X-Goog-Expires=86399&X-Goog-Signature=ba30f58c1368feee04b8096176a5f2e244167cb273cbeb464b2d54c1d7a74754d10d41baa2225c252e8f1ca8cae03cf7bdbc20126ea319c1a5a5073527bc69e705b985f3542972a3e346e67670267c3c825106e581fe7e66fb1bd28d2792403abe0b0670e4e9a435c897d99fb1d856e848bdf9fb247073360e828f32dd3e2c616076e6778a85204fe1163367bd13091f7c890a8d9294fddbcc4c491aeeb3d4b12338b4933b39b8dc2b8cf7102ad7e2e6abbd201b99725b11eae47d53b86f3ea5ea37930f830b62dd767fd9e7b87b2d477c88515df3677a129a835968a66b2ed747074e2194ac0bc169283a7591e086f9ce8e9c91647db7ea2de92c455dd56da5&X-Goog-SignedHeaders=host&X-User=2931823730: HTTPSConnectionPool(host='storage.googleapis.com', port=443): Max retries exceeded with url: /wandb-production.appspot.com/2931823730-harbin-institute-of-technology/ltu-as/gs2gbnar/output.log?X-Goog-Algorithm=GOOG4-RSA-SHA256&X-Goog-Credential=gorilla-files-url-signer-man%40wandb-production.iam.gserviceaccount.com%2F20250411%2Fauto%2Fstorage%2Fgoog4_request&X-Goog-Date=20250411T151651Z&X-Goog-Expires=86399&X-Goog-Signature=ba30f58c1368feee04b8096176a5f2e244167cb273cbeb464b2d54c1d7a74754d10d41baa2225c252e8f1ca8cae03cf7bdbc20126ea319c1a5a5073527bc69e705b985f3542972a3e346e67670267c3c825106e581fe7e66fb1bd28d2792403abe0b0670e4e9a435c897d99fb1d856e848bdf9fb247073360e828f32dd3e2c616076e6778a85204fe1163367bd13091f7c890a8d9294fddbcc4c491aeeb3d4b12338b4933b39b8dc2b8cf7102ad7e2e6abbd201b99725b11eae47d53b86f3ea5ea37930f830b62dd767fd9e7b87b2d477c88515df3677a129a835968a66b2ed747074e2194ac0bc169283a7591e086f9ce8e9c91647db7ea2de92c455dd56da5&X-Goog-SignedHeaders=host&X-User=2931823730 (Caused by NewConnectionError('<urllib3.connection.HTTPSConnection object at 0x7faf0c1027d0>: Failed to establish a new connection: [Errno 101] Network is unreachable'))
2025-04-11 15:17:55,886 ERROR   wandb-upload_4:24150 [internal_api.py:upload_file():2558] upload_file request headers: {'User-Agent': 'python-requests/2.32.3', 'Accept-Encoding': 'gzip, deflate, br', 'Accept': '*/*', 'Connection': 'keep-alive', 'Content-Length': '4566'}
2025-04-11 15:17:55,886 ERROR   wandb-upload_4:24150 [internal_api.py:upload_file():2560] upload_file response body: 
2025-04-11 15:17:56,375 DEBUG   HandlerThread:24150 [handler.py:handle_request():146] handle_request: poll_exit
2025-04-11 15:17:56,376 DEBUG   SenderThread:24150 [sender.py:send_request():407] send_request: poll_exit
