2025-04-11 15:24:21,289 INFO    StreamThr :24989 [internal.py:wandb_internal():86] W&B internal server running at pid: 24989, started at: 2025-04-11 15:24:21.286282
2025-04-11 15:24:21,292 DEBUG   HandlerThread:24989 [handler.py:handle_request():146] handle_request: status
2025-04-11 15:24:21,296 INFO    WriterThread:24989 [datastore.py:open_for_write():85] open: /root/ltu-main/ltu-main/src/ltu_as/train_scripts/wandb/run-20250411_152421-k2h266f7/run-k2h266f7.wandb
2025-04-11 15:24:21,296 DEBUG   SenderThread:24989 [sender.py:send():380] send: header
2025-04-11 15:24:21,296 DEBUG   SenderThread:24989 [sender.py:send():380] send: run
2025-04-11 15:24:22,077 INFO    SenderThread:24989 [dir_watcher.py:__init__():211] watching files in: /root/ltu-main/ltu-main/src/ltu_as/train_scripts/wandb/run-20250411_152421-k2h266f7/files
2025-04-11 15:24:22,078 INFO    SenderThread:24989 [sender.py:_start_run_threads():1122] run started: k2h266f7 with start time 1744385061.28697
2025-04-11 15:24:22,080 DEBUG   HandlerThread:24989 [handler.py:handle_request():146] handle_request: check_version
2025-04-11 15:24:22,080 DEBUG   SenderThread:24989 [sender.py:send_request():407] send_request: check_version
2025-04-11 15:24:22,498 DEBUG   HandlerThread:24989 [handler.py:handle_request():146] handle_request: run_start
2025-04-11 15:24:22,512 DEBUG   HandlerThread:24989 [system_info.py:__init__():32] System info init
2025-04-11 15:24:22,512 DEBUG   HandlerThread:24989 [system_info.py:__init__():47] System info init done
2025-04-11 15:24:22,512 INFO    HandlerThread:24989 [system_monitor.py:start():194] Starting system monitor
2025-04-11 15:24:22,512 INFO    SystemMonitor:24989 [system_monitor.py:_start():158] Starting system asset monitoring threads
2025-04-11 15:24:22,513 INFO    HandlerThread:24989 [system_monitor.py:probe():214] Collecting system info
2025-04-11 15:24:22,514 INFO    SystemMonitor:24989 [interfaces.py:start():190] Started cpu monitoring
2025-04-11 15:24:22,516 INFO    SystemMonitor:24989 [interfaces.py:start():190] Started disk monitoring
2025-04-11 15:24:22,516 INFO    SystemMonitor:24989 [interfaces.py:start():190] Started gpu monitoring
2025-04-11 15:24:22,517 INFO    SystemMonitor:24989 [interfaces.py:start():190] Started memory monitoring
2025-04-11 15:24:22,518 INFO    SystemMonitor:24989 [interfaces.py:start():190] Started network monitoring
2025-04-11 15:24:22,528 DEBUG   HandlerThread:24989 [system_info.py:probe():196] Probing system
2025-04-11 15:24:22,529 DEBUG   HandlerThread:24989 [gitlib.py:_init_repo():53] git repository is invalid
2025-04-11 15:24:22,529 DEBUG   HandlerThread:24989 [system_info.py:probe():244] Probing system done
2025-04-11 15:24:22,529 DEBUG   HandlerThread:24989 [system_monitor.py:probe():223] {'os': 'Linux-4.15.0-213-generic-x86_64-with-glibc2.27', 'python': '3.10.15', 'heartbeatAt': '2025-04-11T15:24:22.528125', 'startedAt': '2025-04-11T15:24:21.268394', 'docker': None, 'cuda': None, 'args': ('--base_model', '../../../pretrained_mdls/ltuas_long_noqa_a6.bin', '--data_path', '../../../openasqa/data/iemocap_preprocess_with_answers_updated.json', '--output_dir', '../exp/ltuas_ft_meld/', '--batch_size', '256', '--micro_batch_size', '1', '--num_epochs', '1', '--learning_rate', '2e-4', '--cutoff_len', '100', '--val_set_size', '0', '--lora_r', '8', '--lora_alpha', '16', '--lora_dropout', '0.05', '--lora_target_modules', '[q_proj,v_proj]', '--group_by_length', '--wandb_run_name', '../exp/ltuas_ft_meld/', '--save_steps', '30', '--trainable_params', 'all'), 'state': 'running', 'program': '/root/ltu-main/ltu-main/src/ltu_as/train_scripts/../finetune_low_resource.py', 'codePathLocal': None, 'host': 'ubuntu', 'username': 'root', 'executable': '/root/anaconda3/envs/venv_ltu/bin/python', 'cpu_count': 4, 'cpu_count_logical': 4, 'cpu_freq': {'current': 2294.598, 'min': 0.0, 'max': 0.0}, 'cpu_freq_per_core': [{'current': 2294.598, 'min': 0.0, 'max': 0.0}, {'current': 2294.598, 'min': 0.0, 'max': 0.0}, {'current': 2294.598, 'min': 0.0, 'max': 0.0}, {'current': 2294.598, 'min': 0.0, 'max': 0.0}], 'disk': {'/': {'total': 499.9882621765137, 'used': 333.63414001464844}}, 'gpu': 'NVIDIA A100-PCIE-40GB', 'gpu_count': 1, 'gpu_devices': [{'name': 'NVIDIA A100-PCIE-40GB', 'memory_total': 42949672960}], 'memory': {'total': 19.60204315185547}}
2025-04-11 15:24:22,529 INFO    HandlerThread:24989 [system_monitor.py:probe():224] Finished collecting system info
2025-04-11 15:24:22,529 INFO    HandlerThread:24989 [system_monitor.py:probe():227] Publishing system info
2025-04-11 15:24:22,529 DEBUG   HandlerThread:24989 [system_info.py:_save_pip():52] Saving list of pip packages installed into the current environment
2025-04-11 15:24:22,529 DEBUG   HandlerThread:24989 [system_info.py:_save_pip():68] Saving pip packages done
2025-04-11 15:24:22,529 DEBUG   HandlerThread:24989 [system_info.py:_save_conda():75] Saving list of conda packages installed into the current environment
2025-04-11 15:24:23,079 INFO    Thread-12 :24989 [dir_watcher.py:_on_file_created():271] file/dir created: /root/ltu-main/ltu-main/src/ltu_as/train_scripts/wandb/run-20250411_152421-k2h266f7/files/requirements.txt
2025-04-11 15:24:23,079 INFO    Thread-12 :24989 [dir_watcher.py:_on_file_created():271] file/dir created: /root/ltu-main/ltu-main/src/ltu_as/train_scripts/wandb/run-20250411_152421-k2h266f7/files/conda-environment.yaml
2025-04-11 15:24:28,940 DEBUG   HandlerThread:24989 [system_info.py:_save_conda():87] Saving conda packages done
2025-04-11 15:24:28,941 INFO    HandlerThread:24989 [system_monitor.py:probe():229] Finished publishing system info
2025-04-11 15:24:28,949 DEBUG   HandlerThread:24989 [handler.py:handle_request():146] handle_request: status_report
2025-04-11 15:24:28,949 DEBUG   HandlerThread:24989 [handler.py:handle_request():146] handle_request: keepalive
2025-04-11 15:24:28,950 DEBUG   SenderThread:24989 [sender.py:send():380] send: files
2025-04-11 15:24:28,950 INFO    SenderThread:24989 [sender.py:_save_file():1378] saving file wandb-metadata.json with policy now
2025-04-11 15:24:28,958 DEBUG   HandlerThread:24989 [handler.py:handle_request():146] handle_request: stop_status
2025-04-11 15:24:28,958 DEBUG   SenderThread:24989 [sender.py:send_request():407] send_request: stop_status
2025-04-11 15:24:28,999 DEBUG   HandlerThread:24989 [handler.py:handle_request():146] handle_request: internal_messages
2025-04-11 15:24:29,078 INFO    Thread-12 :24989 [dir_watcher.py:_on_file_modified():288] file/dir modified: /root/ltu-main/ltu-main/src/ltu_as/train_scripts/wandb/run-20250411_152421-k2h266f7/files/conda-environment.yaml
2025-04-11 15:24:29,079 INFO    Thread-12 :24989 [dir_watcher.py:_on_file_created():271] file/dir created: /root/ltu-main/ltu-main/src/ltu_as/train_scripts/wandb/run-20250411_152421-k2h266f7/files/wandb-metadata.json
2025-04-11 15:24:29,426 DEBUG   SenderThread:24989 [sender.py:send():380] send: telemetry
2025-04-11 15:24:29,429 DEBUG   SenderThread:24989 [sender.py:send():380] send: config
2025-04-11 15:24:29,429 DEBUG   SenderThread:24989 [sender.py:send():380] send: metric
2025-04-11 15:24:29,430 DEBUG   SenderThread:24989 [sender.py:send():380] send: telemetry
2025-04-11 15:24:29,430 DEBUG   SenderThread:24989 [sender.py:send():380] send: metric
2025-04-11 15:24:29,430 WARNING SenderThread:24989 [sender.py:send_metric():1329] Seen metric with glob (shouldn't happen)
2025-04-11 15:24:29,487 ERROR   wandb-upload_0:24989 [internal_api.py:upload_file():2556] upload_file exception https://storage.googleapis.com/wandb-production.appspot.com/2931823730-harbin-institute-of-technology/ltu-as/k2h266f7/wandb-metadata.json?X-Goog-Algorithm=GOOG4-RSA-SHA256&X-Goog-Credential=gorilla-files-url-signer-man%40wandb-production.iam.gserviceaccount.com%2F20250411%2Fauto%2Fstorage%2Fgoog4_request&X-Goog-Date=20250411T152429Z&X-Goog-Expires=86399&X-Goog-Signature=6ec798b561c3cb2395a17d429f72d1bb4186851438f563ecf78bf1f9dc2b5bcff133f9ad0475c60bc1ab0d97e844cfdca95eea98e9242d5bf6414f8e893f8c9577b7d4e5ba040eac31d4c1ffe28a810db3a0375ebce266ce826f2d61a7ce843ce3aa0da775b6b1919247a6583dd5f1d0227acd04d455d3cfcb80912a63a7b14bce8e34d6e2781b78339658e7dce006bdbba3224c717bcf1d18f836de545d1e6c16702f349810a661b2a29d0ae54da42347dba9ed341ea4b3f3f4ed023a50b3b3ce4284ac11e6b286f8a5b6d9a51b608bb69c415180e91a2d9daecb65f3eb6a052385bd58ce99a59a48bc6ea91e078394af4f45f97ca37e771309c400847715f7&X-Goog-SignedHeaders=host&X-User=2931823730: HTTPSConnectionPool(host='storage.googleapis.com', port=443): Max retries exceeded with url: /wandb-production.appspot.com/2931823730-harbin-institute-of-technology/ltu-as/k2h266f7/wandb-metadata.json?X-Goog-Algorithm=GOOG4-RSA-SHA256&X-Goog-Credential=gorilla-files-url-signer-man%40wandb-production.iam.gserviceaccount.com%2F20250411%2Fauto%2Fstorage%2Fgoog4_request&X-Goog-Date=20250411T152429Z&X-Goog-Expires=86399&X-Goog-Signature=6ec798b561c3cb2395a17d429f72d1bb4186851438f563ecf78bf1f9dc2b5bcff133f9ad0475c60bc1ab0d97e844cfdca95eea98e9242d5bf6414f8e893f8c9577b7d4e5ba040eac31d4c1ffe28a810db3a0375ebce266ce826f2d61a7ce843ce3aa0da775b6b1919247a6583dd5f1d0227acd04d455d3cfcb80912a63a7b14bce8e34d6e2781b78339658e7dce006bdbba3224c717bcf1d18f836de545d1e6c16702f349810a661b2a29d0ae54da42347dba9ed341ea4b3f3f4ed023a50b3b3ce4284ac11e6b286f8a5b6d9a51b608bb69c415180e91a2d9daecb65f3eb6a052385bd58ce99a59a48bc6ea91e078394af4f45f97ca37e771309c400847715f7&X-Goog-SignedHeaders=host&X-User=2931823730 (Caused by NewConnectionError('<urllib3.connection.HTTPSConnection object at 0x7f6f435d14e0>: Failed to establish a new connection: [Errno 101] Network is unreachable'))
2025-04-11 15:24:29,487 ERROR   wandb-upload_0:24989 [internal_api.py:upload_file():2558] upload_file request headers: {'User-Agent': 'python-requests/2.32.3', 'Accept-Encoding': 'gzip, deflate, br', 'Accept': '*/*', 'Connection': 'keep-alive', 'Content-Length': '2274'}
2025-04-11 15:24:29,487 ERROR   wandb-upload_0:24989 [internal_api.py:upload_file():2560] upload_file response body: 
2025-04-11 15:24:30,079 INFO    Thread-12 :24989 [dir_watcher.py:_on_file_created():271] file/dir created: /root/ltu-main/ltu-main/src/ltu_as/train_scripts/wandb/run-20250411_152421-k2h266f7/files/output.log
2025-04-11 15:24:30,551 ERROR   wandb-upload_0:24989 [internal_api.py:upload_file():2556] upload_file exception https://storage.googleapis.com/wandb-production.appspot.com/2931823730-harbin-institute-of-technology/ltu-as/k2h266f7/wandb-metadata.json?X-Goog-Algorithm=GOOG4-RSA-SHA256&X-Goog-Credential=gorilla-files-url-signer-man%40wandb-production.iam.gserviceaccount.com%2F20250411%2Fauto%2Fstorage%2Fgoog4_request&X-Goog-Date=20250411T152429Z&X-Goog-Expires=86399&X-Goog-Signature=6ec798b561c3cb2395a17d429f72d1bb4186851438f563ecf78bf1f9dc2b5bcff133f9ad0475c60bc1ab0d97e844cfdca95eea98e9242d5bf6414f8e893f8c9577b7d4e5ba040eac31d4c1ffe28a810db3a0375ebce266ce826f2d61a7ce843ce3aa0da775b6b1919247a6583dd5f1d0227acd04d455d3cfcb80912a63a7b14bce8e34d6e2781b78339658e7dce006bdbba3224c717bcf1d18f836de545d1e6c16702f349810a661b2a29d0ae54da42347dba9ed341ea4b3f3f4ed023a50b3b3ce4284ac11e6b286f8a5b6d9a51b608bb69c415180e91a2d9daecb65f3eb6a052385bd58ce99a59a48bc6ea91e078394af4f45f97ca37e771309c400847715f7&X-Goog-SignedHeaders=host&X-User=2931823730: HTTPSConnectionPool(host='storage.googleapis.com', port=443): Max retries exceeded with url: /wandb-production.appspot.com/2931823730-harbin-institute-of-technology/ltu-as/k2h266f7/wandb-metadata.json?X-Goog-Algorithm=GOOG4-RSA-SHA256&X-Goog-Credential=gorilla-files-url-signer-man%40wandb-production.iam.gserviceaccount.com%2F20250411%2Fauto%2Fstorage%2Fgoog4_request&X-Goog-Date=20250411T152429Z&X-Goog-Expires=86399&X-Goog-Signature=6ec798b561c3cb2395a17d429f72d1bb4186851438f563ecf78bf1f9dc2b5bcff133f9ad0475c60bc1ab0d97e844cfdca95eea98e9242d5bf6414f8e893f8c9577b7d4e5ba040eac31d4c1ffe28a810db3a0375ebce266ce826f2d61a7ce843ce3aa0da775b6b1919247a6583dd5f1d0227acd04d455d3cfcb80912a63a7b14bce8e34d6e2781b78339658e7dce006bdbba3224c717bcf1d18f836de545d1e6c16702f349810a661b2a29d0ae54da42347dba9ed341ea4b3f3f4ed023a50b3b3ce4284ac11e6b286f8a5b6d9a51b608bb69c415180e91a2d9daecb65f3eb6a052385bd58ce99a59a48bc6ea91e078394af4f45f97ca37e771309c400847715f7&X-Goog-SignedHeaders=host&X-User=2931823730 (Caused by NewConnectionError('<urllib3.connection.HTTPSConnection object at 0x7f6f435d0460>: Failed to establish a new connection: [Errno 101] Network is unreachable'))
2025-04-11 15:24:30,551 ERROR   wandb-upload_0:24989 [internal_api.py:upload_file():2558] upload_file request headers: {'User-Agent': 'python-requests/2.32.3', 'Accept-Encoding': 'gzip, deflate, br', 'Accept': '*/*', 'Connection': 'keep-alive', 'Content-Length': '2274'}
2025-04-11 15:24:30,551 ERROR   wandb-upload_0:24989 [internal_api.py:upload_file():2560] upload_file response body: 
2025-04-11 15:24:32,080 INFO    Thread-12 :24989 [dir_watcher.py:_on_file_modified():288] file/dir modified: /root/ltu-main/ltu-main/src/ltu_as/train_scripts/wandb/run-20250411_152421-k2h266f7/files/output.log
2025-04-11 15:24:32,431 DEBUG   HandlerThread:24989 [handler.py:handle_request():146] handle_request: status_report
2025-04-11 15:24:32,937 ERROR   wandb-upload_0:24989 [internal_api.py:upload_file():2556] upload_file exception https://storage.googleapis.com/wandb-production.appspot.com/2931823730-harbin-institute-of-technology/ltu-as/k2h266f7/wandb-metadata.json?X-Goog-Algorithm=GOOG4-RSA-SHA256&X-Goog-Credential=gorilla-files-url-signer-man%40wandb-production.iam.gserviceaccount.com%2F20250411%2Fauto%2Fstorage%2Fgoog4_request&X-Goog-Date=20250411T152429Z&X-Goog-Expires=86399&X-Goog-Signature=6ec798b561c3cb2395a17d429f72d1bb4186851438f563ecf78bf1f9dc2b5bcff133f9ad0475c60bc1ab0d97e844cfdca95eea98e9242d5bf6414f8e893f8c9577b7d4e5ba040eac31d4c1ffe28a810db3a0375ebce266ce826f2d61a7ce843ce3aa0da775b6b1919247a6583dd5f1d0227acd04d455d3cfcb80912a63a7b14bce8e34d6e2781b78339658e7dce006bdbba3224c717bcf1d18f836de545d1e6c16702f349810a661b2a29d0ae54da42347dba9ed341ea4b3f3f4ed023a50b3b3ce4284ac11e6b286f8a5b6d9a51b608bb69c415180e91a2d9daecb65f3eb6a052385bd58ce99a59a48bc6ea91e078394af4f45f97ca37e771309c400847715f7&X-Goog-SignedHeaders=host&X-User=2931823730: HTTPSConnectionPool(host='storage.googleapis.com', port=443): Max retries exceeded with url: /wandb-production.appspot.com/2931823730-harbin-institute-of-technology/ltu-as/k2h266f7/wandb-metadata.json?X-Goog-Algorithm=GOOG4-RSA-SHA256&X-Goog-Credential=gorilla-files-url-signer-man%40wandb-production.iam.gserviceaccount.com%2F20250411%2Fauto%2Fstorage%2Fgoog4_request&X-Goog-Date=20250411T152429Z&X-Goog-Expires=86399&X-Goog-Signature=6ec798b561c3cb2395a17d429f72d1bb4186851438f563ecf78bf1f9dc2b5bcff133f9ad0475c60bc1ab0d97e844cfdca95eea98e9242d5bf6414f8e893f8c9577b7d4e5ba040eac31d4c1ffe28a810db3a0375ebce266ce826f2d61a7ce843ce3aa0da775b6b1919247a6583dd5f1d0227acd04d455d3cfcb80912a63a7b14bce8e34d6e2781b78339658e7dce006bdbba3224c717bcf1d18f836de545d1e6c16702f349810a661b2a29d0ae54da42347dba9ed341ea4b3f3f4ed023a50b3b3ce4284ac11e6b286f8a5b6d9a51b608bb69c415180e91a2d9daecb65f3eb6a052385bd58ce99a59a48bc6ea91e078394af4f45f97ca37e771309c400847715f7&X-Goog-SignedHeaders=host&X-User=2931823730 (Caused by NewConnectionError('<urllib3.connection.HTTPSConnection object at 0x7f6f435d23e0>: Failed to establish a new connection: [Errno 101] Network is unreachable'))
2025-04-11 15:24:32,937 ERROR   wandb-upload_0:24989 [internal_api.py:upload_file():2558] upload_file request headers: {'User-Agent': 'python-requests/2.32.3', 'Accept-Encoding': 'gzip, deflate, br', 'Accept': '*/*', 'Connection': 'keep-alive', 'Content-Length': '2274'}
2025-04-11 15:24:32,937 ERROR   wandb-upload_0:24989 [internal_api.py:upload_file():2560] upload_file response body: 
2025-04-11 15:24:32,937 INFO    wandb-upload_0:24989 [retry.py:__call__():172] Retry attempt failed:
Traceback (most recent call last):
  File "/root/anaconda3/envs/venv_ltu/lib/python3.10/site-packages/urllib3/connection.py", line 198, in _new_conn
    sock = connection.create_connection(
  File "/root/anaconda3/envs/venv_ltu/lib/python3.10/site-packages/urllib3/util/connection.py", line 85, in create_connection
    raise err
  File "/root/anaconda3/envs/venv_ltu/lib/python3.10/site-packages/urllib3/util/connection.py", line 73, in create_connection
    sock.connect(sa)
OSError: [Errno 101] Network is unreachable

The above exception was the direct cause of the following exception:

Traceback (most recent call last):
  File "/root/anaconda3/envs/venv_ltu/lib/python3.10/site-packages/urllib3/connectionpool.py", line 793, in urlopen
    response = self._make_request(
  File "/root/anaconda3/envs/venv_ltu/lib/python3.10/site-packages/urllib3/connectionpool.py", line 491, in _make_request
    raise new_e
  File "/root/anaconda3/envs/venv_ltu/lib/python3.10/site-packages/urllib3/connectionpool.py", line 467, in _make_request
    self._validate_conn(conn)
  File "/root/anaconda3/envs/venv_ltu/lib/python3.10/site-packages/urllib3/connectionpool.py", line 1099, in _validate_conn
    conn.connect()
  File "/root/anaconda3/envs/venv_ltu/lib/python3.10/site-packages/urllib3/connection.py", line 616, in connect
    self.sock = sock = self._new_conn()
  File "/root/anaconda3/envs/venv_ltu/lib/python3.10/site-packages/urllib3/connection.py", line 213, in _new_conn
    raise NewConnectionError(
urllib3.exceptions.NewConnectionError: <urllib3.connection.HTTPSConnection object at 0x7f6f435d23e0>: Failed to establish a new connection: [Errno 101] Network is unreachable

The above exception was the direct cause of the following exception:

Traceback (most recent call last):
  File "/root/anaconda3/envs/venv_ltu/lib/python3.10/site-packages/requests/adapters.py", line 667, in send
    resp = conn.urlopen(
  File "/root/anaconda3/envs/venv_ltu/lib/python3.10/site-packages/urllib3/connectionpool.py", line 847, in urlopen
    retries = retries.increment(
  File "/root/anaconda3/envs/venv_ltu/lib/python3.10/site-packages/urllib3/util/retry.py", line 515, in increment
    raise MaxRetryError(_pool, url, reason) from reason  # type: ignore[arg-type]
urllib3.exceptions.MaxRetryError: HTTPSConnectionPool(host='storage.googleapis.com', port=443): Max retries exceeded with url: /wandb-production.appspot.com/2931823730-harbin-institute-of-technology/ltu-as/k2h266f7/wandb-metadata.json?X-Goog-Algorithm=GOOG4-RSA-SHA256&X-Goog-Credential=gorilla-files-url-signer-man%40wandb-production.iam.gserviceaccount.com%2F20250411%2Fauto%2Fstorage%2Fgoog4_request&X-Goog-Date=20250411T152429Z&X-Goog-Expires=86399&X-Goog-Signature=6ec798b561c3cb2395a17d429f72d1bb4186851438f563ecf78bf1f9dc2b5bcff133f9ad0475c60bc1ab0d97e844cfdca95eea98e9242d5bf6414f8e893f8c9577b7d4e5ba040eac31d4c1ffe28a810db3a0375ebce266ce826f2d61a7ce843ce3aa0da775b6b1919247a6583dd5f1d0227acd04d455d3cfcb80912a63a7b14bce8e34d6e2781b78339658e7dce006bdbba3224c717bcf1d18f836de545d1e6c16702f349810a661b2a29d0ae54da42347dba9ed341ea4b3f3f4ed023a50b3b3ce4284ac11e6b286f8a5b6d9a51b608bb69c415180e91a2d9daecb65f3eb6a052385bd58ce99a59a48bc6ea91e078394af4f45f97ca37e771309c400847715f7&X-Goog-SignedHeaders=host&X-User=2931823730 (Caused by NewConnectionError('<urllib3.connection.HTTPSConnection object at 0x7f6f435d23e0>: Failed to establish a new connection: [Errno 101] Network is unreachable'))

During handling of the above exception, another exception occurred:

Traceback (most recent call last):
  File "/root/anaconda3/envs/venv_ltu/lib/python3.10/site-packages/wandb/sdk/internal/internal_api.py", line 2549, in upload_file
    response = self._upload_file_session.put(
  File "/root/anaconda3/envs/venv_ltu/lib/python3.10/site-packages/requests/sessions.py", line 649, in put
    return self.request("PUT", url, data=data, **kwargs)
  File "/root/anaconda3/envs/venv_ltu/lib/python3.10/site-packages/requests/sessions.py", line 589, in request
    resp = self.send(prep, **send_kwargs)
  File "/root/anaconda3/envs/venv_ltu/lib/python3.10/site-packages/requests/sessions.py", line 703, in send
    r = adapter.send(request, **kwargs)
  File "/root/anaconda3/envs/venv_ltu/lib/python3.10/site-packages/requests/adapters.py", line 700, in send
    raise ConnectionError(e, request=request)
requests.exceptions.ConnectionError: HTTPSConnectionPool(host='storage.googleapis.com', port=443): Max retries exceeded with url: /wandb-production.appspot.com/2931823730-harbin-institute-of-technology/ltu-as/k2h266f7/wandb-metadata.json?X-Goog-Algorithm=GOOG4-RSA-SHA256&X-Goog-Credential=gorilla-files-url-signer-man%40wandb-production.iam.gserviceaccount.com%2F20250411%2Fauto%2Fstorage%2Fgoog4_request&X-Goog-Date=20250411T152429Z&X-Goog-Expires=86399&X-Goog-Signature=6ec798b561c3cb2395a17d429f72d1bb4186851438f563ecf78bf1f9dc2b5bcff133f9ad0475c60bc1ab0d97e844cfdca95eea98e9242d5bf6414f8e893f8c9577b7d4e5ba040eac31d4c1ffe28a810db3a0375ebce266ce826f2d61a7ce843ce3aa0da775b6b1919247a6583dd5f1d0227acd04d455d3cfcb80912a63a7b14bce8e34d6e2781b78339658e7dce006bdbba3224c717bcf1d18f836de545d1e6c16702f349810a661b2a29d0ae54da42347dba9ed341ea4b3f3f4ed023a50b3b3ce4284ac11e6b286f8a5b6d9a51b608bb69c415180e91a2d9daecb65f3eb6a052385bd58ce99a59a48bc6ea91e078394af4f45f97ca37e771309c400847715f7&X-Goog-SignedHeaders=host&X-User=2931823730 (Caused by NewConnectionError('<urllib3.connection.HTTPSConnection object at 0x7f6f435d23e0>: Failed to establish a new connection: [Errno 101] Network is unreachable'))

During handling of the above exception, another exception occurred:

Traceback (most recent call last):
  File "/root/anaconda3/envs/venv_ltu/lib/python3.10/site-packages/wandb/sdk/lib/retry.py", line 131, in __call__
    result = self._call_fn(*args, **kwargs)
  File "/root/anaconda3/envs/venv_ltu/lib/python3.10/site-packages/wandb/sdk/internal/internal_api.py", line 2580, in upload_file
    raise _e.with_traceback(sys.exc_info()[2])
  File "/root/anaconda3/envs/venv_ltu/lib/python3.10/site-packages/wandb/sdk/internal/internal_api.py", line 2549, in upload_file
    response = self._upload_file_session.put(
  File "/root/anaconda3/envs/venv_ltu/lib/python3.10/site-packages/requests/sessions.py", line 649, in put
    return self.request("PUT", url, data=data, **kwargs)
  File "/root/anaconda3/envs/venv_ltu/lib/python3.10/site-packages/requests/sessions.py", line 589, in request
    resp = self.send(prep, **send_kwargs)
  File "/root/anaconda3/envs/venv_ltu/lib/python3.10/site-packages/requests/sessions.py", line 703, in send
    r = adapter.send(request, **kwargs)
  File "/root/anaconda3/envs/venv_ltu/lib/python3.10/site-packages/requests/adapters.py", line 700, in send
    raise ConnectionError(e, request=request)
wandb.sdk.lib.retry.TransientError: None
2025-04-11 15:24:33,701 DEBUG   SenderThread:24989 [sender.py:send():380] send: exit
2025-04-11 15:24:33,701 INFO    SenderThread:24989 [sender.py:send_exit():585] handling exit code: 1
2025-04-11 15:24:33,701 INFO    SenderThread:24989 [sender.py:send_exit():587] handling runtime: 11
2025-04-11 15:24:33,704 INFO    SenderThread:24989 [sender.py:_save_file():1378] saving file wandb-summary.json with policy end
2025-04-11 15:24:33,705 INFO    SenderThread:24989 [sender.py:send_exit():593] send defer
2025-04-11 15:24:33,705 DEBUG   HandlerThread:24989 [handler.py:handle_request():146] handle_request: defer
2025-04-11 15:24:33,705 INFO    HandlerThread:24989 [handler.py:handle_request_defer():172] handle defer: 0
2025-04-11 15:24:33,705 DEBUG   SenderThread:24989 [sender.py:send_request():407] send_request: defer
2025-04-11 15:24:33,705 INFO    SenderThread:24989 [sender.py:send_request_defer():609] handle sender defer: 0
2025-04-11 15:24:33,705 INFO    SenderThread:24989 [sender.py:transition_state():613] send defer: 1
2025-04-11 15:24:33,706 DEBUG   HandlerThread:24989 [handler.py:handle_request():146] handle_request: defer
2025-04-11 15:24:33,706 INFO    HandlerThread:24989 [handler.py:handle_request_defer():172] handle defer: 1
2025-04-11 15:24:33,706 DEBUG   SenderThread:24989 [sender.py:send_request():407] send_request: defer
2025-04-11 15:24:33,706 INFO    SenderThread:24989 [sender.py:send_request_defer():609] handle sender defer: 1
2025-04-11 15:24:33,706 INFO    SenderThread:24989 [sender.py:transition_state():613] send defer: 2
2025-04-11 15:24:33,706 DEBUG   HandlerThread:24989 [handler.py:handle_request():146] handle_request: defer
2025-04-11 15:24:33,706 INFO    HandlerThread:24989 [handler.py:handle_request_defer():172] handle defer: 2
2025-04-11 15:24:33,706 INFO    HandlerThread:24989 [system_monitor.py:finish():203] Stopping system monitor
2025-04-11 15:24:33,706 DEBUG   SystemMonitor:24989 [system_monitor.py:_start():172] Starting system metrics aggregation loop
2025-04-11 15:24:33,706 DEBUG   SystemMonitor:24989 [system_monitor.py:_start():179] Finished system metrics aggregation loop
2025-04-11 15:24:33,707 DEBUG   SystemMonitor:24989 [system_monitor.py:_start():183] Publishing last batch of metrics
2025-04-11 15:24:33,707 INFO    HandlerThread:24989 [interfaces.py:finish():202] Joined cpu monitor
2025-04-11 15:24:33,707 INFO    HandlerThread:24989 [interfaces.py:finish():202] Joined disk monitor
2025-04-11 15:24:33,729 INFO    HandlerThread:24989 [interfaces.py:finish():202] Joined gpu monitor
2025-04-11 15:24:33,729 INFO    HandlerThread:24989 [interfaces.py:finish():202] Joined memory monitor
2025-04-11 15:24:33,729 INFO    HandlerThread:24989 [interfaces.py:finish():202] Joined network monitor
2025-04-11 15:24:33,730 DEBUG   SenderThread:24989 [sender.py:send_request():407] send_request: defer
2025-04-11 15:24:33,730 INFO    SenderThread:24989 [sender.py:send_request_defer():609] handle sender defer: 2
2025-04-11 15:24:33,730 INFO    SenderThread:24989 [sender.py:transition_state():613] send defer: 3
2025-04-11 15:24:33,730 DEBUG   HandlerThread:24989 [handler.py:handle_request():146] handle_request: defer
2025-04-11 15:24:33,730 INFO    HandlerThread:24989 [handler.py:handle_request_defer():172] handle defer: 3
2025-04-11 15:24:33,731 DEBUG   SenderThread:24989 [sender.py:send_request():407] send_request: defer
2025-04-11 15:24:33,731 INFO    SenderThread:24989 [sender.py:send_request_defer():609] handle sender defer: 3
2025-04-11 15:24:33,731 INFO    SenderThread:24989 [sender.py:transition_state():613] send defer: 4
2025-04-11 15:24:33,731 DEBUG   HandlerThread:24989 [handler.py:handle_request():146] handle_request: defer
2025-04-11 15:24:33,731 INFO    HandlerThread:24989 [handler.py:handle_request_defer():172] handle defer: 4
2025-04-11 15:24:33,731 DEBUG   SenderThread:24989 [sender.py:send_request():407] send_request: defer
2025-04-11 15:24:33,731 INFO    SenderThread:24989 [sender.py:send_request_defer():609] handle sender defer: 4
2025-04-11 15:24:33,731 INFO    SenderThread:24989 [sender.py:transition_state():613] send defer: 5
2025-04-11 15:24:33,731 DEBUG   HandlerThread:24989 [handler.py:handle_request():146] handle_request: defer
2025-04-11 15:24:33,731 INFO    HandlerThread:24989 [handler.py:handle_request_defer():172] handle defer: 5
2025-04-11 15:24:33,732 DEBUG   SenderThread:24989 [sender.py:send():380] send: summary
2025-04-11 15:24:33,737 INFO    SenderThread:24989 [sender.py:_save_file():1378] saving file wandb-summary.json with policy end
2025-04-11 15:24:33,737 DEBUG   SenderThread:24989 [sender.py:send_request():407] send_request: defer
2025-04-11 15:24:33,737 INFO    SenderThread:24989 [sender.py:send_request_defer():609] handle sender defer: 5
2025-04-11 15:24:33,737 INFO    SenderThread:24989 [sender.py:transition_state():613] send defer: 6
2025-04-11 15:24:33,737 DEBUG   HandlerThread:24989 [handler.py:handle_request():146] handle_request: defer
2025-04-11 15:24:33,738 INFO    HandlerThread:24989 [handler.py:handle_request_defer():172] handle defer: 6
2025-04-11 15:24:33,738 DEBUG   SenderThread:24989 [sender.py:send_request():407] send_request: defer
2025-04-11 15:24:33,738 INFO    SenderThread:24989 [sender.py:send_request_defer():609] handle sender defer: 6
2025-04-11 15:24:33,744 DEBUG   HandlerThread:24989 [handler.py:handle_request():146] handle_request: status_report
2025-04-11 15:24:34,081 INFO    Thread-12 :24989 [dir_watcher.py:_on_file_created():271] file/dir created: /root/ltu-main/ltu-main/src/ltu_as/train_scripts/wandb/run-20250411_152421-k2h266f7/files/wandb-summary.json
2025-04-11 15:24:34,083 INFO    SenderThread:24989 [sender.py:transition_state():613] send defer: 7
2025-04-11 15:24:34,083 DEBUG   HandlerThread:24989 [handler.py:handle_request():146] handle_request: defer
2025-04-11 15:24:34,083 INFO    HandlerThread:24989 [handler.py:handle_request_defer():172] handle defer: 7
2025-04-11 15:24:34,084 DEBUG   SenderThread:24989 [sender.py:send_request():407] send_request: defer
2025-04-11 15:24:34,084 INFO    SenderThread:24989 [sender.py:send_request_defer():609] handle sender defer: 7
2025-04-11 15:24:34,697 DEBUG   HandlerThread:24989 [handler.py:handle_request():146] handle_request: poll_exit
2025-04-11 15:24:35,082 INFO    Thread-12 :24989 [dir_watcher.py:_on_file_modified():288] file/dir modified: /root/ltu-main/ltu-main/src/ltu_as/train_scripts/wandb/run-20250411_152421-k2h266f7/files/config.yaml
2025-04-11 15:24:35,456 INFO    SenderThread:24989 [sender.py:transition_state():613] send defer: 8
2025-04-11 15:24:35,456 DEBUG   SenderThread:24989 [sender.py:send_request():407] send_request: poll_exit
2025-04-11 15:24:35,456 DEBUG   HandlerThread:24989 [handler.py:handle_request():146] handle_request: defer
2025-04-11 15:24:35,456 INFO    HandlerThread:24989 [handler.py:handle_request_defer():172] handle defer: 8
2025-04-11 15:24:35,457 DEBUG   SenderThread:24989 [sender.py:send_request():407] send_request: defer
2025-04-11 15:24:35,457 INFO    SenderThread:24989 [sender.py:send_request_defer():609] handle sender defer: 8
2025-04-11 15:24:35,457 INFO    SenderThread:24989 [job_builder.py:build():281] Attempting to build job artifact
2025-04-11 15:24:35,457 INFO    SenderThread:24989 [job_builder.py:_get_source_type():404] no source found
2025-04-11 15:24:35,458 INFO    SenderThread:24989 [sender.py:transition_state():613] send defer: 9
2025-04-11 15:24:35,458 DEBUG   HandlerThread:24989 [handler.py:handle_request():146] handle_request: defer
2025-04-11 15:24:35,458 INFO    HandlerThread:24989 [handler.py:handle_request_defer():172] handle defer: 9
2025-04-11 15:24:35,458 DEBUG   SenderThread:24989 [sender.py:send_request():407] send_request: defer
2025-04-11 15:24:35,458 INFO    SenderThread:24989 [sender.py:send_request_defer():609] handle sender defer: 9
2025-04-11 15:24:35,458 INFO    SenderThread:24989 [dir_watcher.py:finish():358] shutting down directory watcher
2025-04-11 15:24:35,698 DEBUG   HandlerThread:24989 [handler.py:handle_request():146] handle_request: poll_exit
2025-04-11 15:24:36,082 INFO    Thread-12 :24989 [dir_watcher.py:_on_file_modified():288] file/dir modified: /root/ltu-main/ltu-main/src/ltu_as/train_scripts/wandb/run-20250411_152421-k2h266f7/files/output.log
2025-04-11 15:24:36,083 INFO    SenderThread:24989 [dir_watcher.py:finish():388] scan: /root/ltu-main/ltu-main/src/ltu_as/train_scripts/wandb/run-20250411_152421-k2h266f7/files
2025-04-11 15:24:36,084 INFO    SenderThread:24989 [dir_watcher.py:finish():402] scan save: /root/ltu-main/ltu-main/src/ltu_as/train_scripts/wandb/run-20250411_152421-k2h266f7/files/config.yaml config.yaml
2025-04-11 15:24:36,084 INFO    SenderThread:24989 [dir_watcher.py:finish():402] scan save: /root/ltu-main/ltu-main/src/ltu_as/train_scripts/wandb/run-20250411_152421-k2h266f7/files/requirements.txt requirements.txt
2025-04-11 15:24:36,089 INFO    SenderThread:24989 [dir_watcher.py:finish():402] scan save: /root/ltu-main/ltu-main/src/ltu_as/train_scripts/wandb/run-20250411_152421-k2h266f7/files/conda-environment.yaml conda-environment.yaml
2025-04-11 15:24:36,094 INFO    SenderThread:24989 [dir_watcher.py:finish():402] scan save: /root/ltu-main/ltu-main/src/ltu_as/train_scripts/wandb/run-20250411_152421-k2h266f7/files/wandb-metadata.json wandb-metadata.json
2025-04-11 15:24:36,094 INFO    SenderThread:24989 [dir_watcher.py:finish():402] scan save: /root/ltu-main/ltu-main/src/ltu_as/train_scripts/wandb/run-20250411_152421-k2h266f7/files/output.log output.log
2025-04-11 15:24:36,094 INFO    SenderThread:24989 [dir_watcher.py:finish():402] scan save: /root/ltu-main/ltu-main/src/ltu_as/train_scripts/wandb/run-20250411_152421-k2h266f7/files/wandb-summary.json wandb-summary.json
2025-04-11 15:24:36,094 INFO    SenderThread:24989 [sender.py:transition_state():613] send defer: 10
2025-04-11 15:24:36,094 DEBUG   SenderThread:24989 [sender.py:send_request():407] send_request: poll_exit
2025-04-11 15:24:36,099 DEBUG   HandlerThread:24989 [handler.py:handle_request():146] handle_request: defer
2025-04-11 15:24:36,099 INFO    HandlerThread:24989 [handler.py:handle_request_defer():172] handle defer: 10
2025-04-11 15:24:36,101 DEBUG   SenderThread:24989 [sender.py:send_request():407] send_request: defer
2025-04-11 15:24:36,101 INFO    SenderThread:24989 [sender.py:send_request_defer():609] handle sender defer: 10
2025-04-11 15:24:36,101 INFO    SenderThread:24989 [file_pusher.py:finish():175] shutting down file pusher
2025-04-11 15:24:36,376 ERROR   wandb-upload_2:24989 [internal_api.py:upload_file():2556] upload_file exception https://storage.googleapis.com/wandb-production.appspot.com/2931823730-harbin-institute-of-technology/ltu-as/k2h266f7/requirements.txt?X-Goog-Algorithm=GOOG4-RSA-SHA256&X-Goog-Credential=gorilla-files-url-signer-man%40wandb-production.iam.gserviceaccount.com%2F20250411%2Fauto%2Fstorage%2Fgoog4_request&X-Goog-Date=20250411T152436Z&X-Goog-Expires=86399&X-Goog-Signature=4a6841c32e79f12bad7f7960d80c3a4defca087c4ba31bd508a9619c23f0b4950a6d4a0f226cc30c34bf8494bd41a909310909b3197103fe0cc1349bdcadb6228660d9a773f72b7beb613e325b71c1dffa163fbc7c39c4201f53af1cbb25ee5cc0b9e09e731beafc678143e692fd480268c65439b3c7b480de3dd6f7c279ed05312555ef86ea1a19ecaeeab786b36a2e5da6414126a6f06c7efda4be419d88955ba2983d3bfe7b794300d27a9592dc4548adf6c5aa9c5a324eec7ef5d607a40bf325ca0a2df0b2ee24a44391f76159361287ec1bbf89c6f8411e01a546b49b999e0b59dda8422f8206bce1ceb1a02e7fbe9603dc7ebf9aa50d821c370c2bc794&X-Goog-SignedHeaders=host&X-User=2931823730: HTTPSConnectionPool(host='storage.googleapis.com', port=443): Max retries exceeded with url: /wandb-production.appspot.com/2931823730-harbin-institute-of-technology/ltu-as/k2h266f7/requirements.txt?X-Goog-Algorithm=GOOG4-RSA-SHA256&X-Goog-Credential=gorilla-files-url-signer-man%40wandb-production.iam.gserviceaccount.com%2F20250411%2Fauto%2Fstorage%2Fgoog4_request&X-Goog-Date=20250411T152436Z&X-Goog-Expires=86399&X-Goog-Signature=4a6841c32e79f12bad7f7960d80c3a4defca087c4ba31bd508a9619c23f0b4950a6d4a0f226cc30c34bf8494bd41a909310909b3197103fe0cc1349bdcadb6228660d9a773f72b7beb613e325b71c1dffa163fbc7c39c4201f53af1cbb25ee5cc0b9e09e731beafc678143e692fd480268c65439b3c7b480de3dd6f7c279ed05312555ef86ea1a19ecaeeab786b36a2e5da6414126a6f06c7efda4be419d88955ba2983d3bfe7b794300d27a9592dc4548adf6c5aa9c5a324eec7ef5d607a40bf325ca0a2df0b2ee24a44391f76159361287ec1bbf89c6f8411e01a546b49b999e0b59dda8422f8206bce1ceb1a02e7fbe9603dc7ebf9aa50d821c370c2bc794&X-Goog-SignedHeaders=host&X-User=2931823730 (Caused by NewConnectionError('<urllib3.connection.HTTPSConnection object at 0x7f6f435d2f80>: Failed to establish a new connection: [Errno 101] Network is unreachable'))
2025-04-11 15:24:36,377 ERROR   wandb-upload_2:24989 [internal_api.py:upload_file():2558] upload_file request headers: {'User-Agent': 'python-requests/2.32.3', 'Accept-Encoding': 'gzip, deflate, br', 'Accept': '*/*', 'Connection': 'keep-alive', 'Content-Length': '4212'}
2025-04-11 15:24:36,377 ERROR   wandb-upload_2:24989 [internal_api.py:upload_file():2560] upload_file response body: 
2025-04-11 15:24:36,383 ERROR   wandb-upload_1:24989 [internal_api.py:upload_file():2556] upload_file exception https://storage.googleapis.com/wandb-production.appspot.com/2931823730-harbin-institute-of-technology/ltu-as/k2h266f7/config.yaml?X-Goog-Algorithm=GOOG4-RSA-SHA256&X-Goog-Credential=gorilla-files-url-signer-man%40wandb-production.iam.gserviceaccount.com%2F20250411%2Fauto%2Fstorage%2Fgoog4_request&X-Goog-Date=20250411T152436Z&X-Goog-Expires=86399&X-Goog-Signature=a2bd9fa79d8f7fff9ac0e7c9263d1d19c6df2bf6806a808a78bada2eba939d69029cac8e041fc4f10cfb94a32017362c65f40f77b4e98a602593050d831b31398d5afa352dcb097f0ee80e078e39f3f2091c46e1df073526f3b6fe27d748e0ec91d2dc7a51c4379df843d0c7f77779463189d1ef5c0e80adb4d5e2ed14f0878906a02e8118c71d8d946705fccdfc2503e9c8b09a725e225fc761f9981aa5f980ef1cd60ea69d46c763b37527f65837001084a213bad97d33b669eb765f3813c4674c741cb9bc962b69f30bc5b8f8a957a65f1a0c0ef23eaf27f0ebe43ccc6a5cfb5133ae52514b51b5c807491799f9c99d8f33c5405130373b7d096b117f1448&X-Goog-SignedHeaders=host&X-User=2931823730: HTTPSConnectionPool(host='storage.googleapis.com', port=443): Max retries exceeded with url: /wandb-production.appspot.com/2931823730-harbin-institute-of-technology/ltu-as/k2h266f7/config.yaml?X-Goog-Algorithm=GOOG4-RSA-SHA256&X-Goog-Credential=gorilla-files-url-signer-man%40wandb-production.iam.gserviceaccount.com%2F20250411%2Fauto%2Fstorage%2Fgoog4_request&X-Goog-Date=20250411T152436Z&X-Goog-Expires=86399&X-Goog-Signature=a2bd9fa79d8f7fff9ac0e7c9263d1d19c6df2bf6806a808a78bada2eba939d69029cac8e041fc4f10cfb94a32017362c65f40f77b4e98a602593050d831b31398d5afa352dcb097f0ee80e078e39f3f2091c46e1df073526f3b6fe27d748e0ec91d2dc7a51c4379df843d0c7f77779463189d1ef5c0e80adb4d5e2ed14f0878906a02e8118c71d8d946705fccdfc2503e9c8b09a725e225fc761f9981aa5f980ef1cd60ea69d46c763b37527f65837001084a213bad97d33b669eb765f3813c4674c741cb9bc962b69f30bc5b8f8a957a65f1a0c0ef23eaf27f0ebe43ccc6a5cfb5133ae52514b51b5c807491799f9c99d8f33c5405130373b7d096b117f1448&X-Goog-SignedHeaders=host&X-User=2931823730 (Caused by NewConnectionError('<urllib3.connection.HTTPSConnection object at 0x7f6f435d3a00>: Failed to establish a new connection: [Errno 101] Network is unreachable'))
2025-04-11 15:24:36,383 ERROR   wandb-upload_1:24989 [internal_api.py:upload_file():2558] upload_file request headers: {'User-Agent': 'python-requests/2.32.3', 'Accept-Encoding': 'gzip, deflate, br', 'Accept': '*/*', 'Connection': 'keep-alive', 'Content-Length': '8684'}
2025-04-11 15:24:36,383 ERROR   wandb-upload_1:24989 [internal_api.py:upload_file():2560] upload_file response body: 
2025-04-11 15:24:36,529 ERROR   wandb-upload_4:24989 [internal_api.py:upload_file():2556] upload_file exception https://storage.googleapis.com/wandb-production.appspot.com/2931823730-harbin-institute-of-technology/ltu-as/k2h266f7/output.log?X-Goog-Algorithm=GOOG4-RSA-SHA256&X-Goog-Credential=gorilla-files-url-signer-man%40wandb-production.iam.gserviceaccount.com%2F20250411%2Fauto%2Fstorage%2Fgoog4_request&X-Goog-Date=20250411T152436Z&X-Goog-Expires=86399&X-Goog-Signature=a218415934127a9773405e8afb2110dac28c657fba4bf7ad82709f7ccf62bc41a6a9c1870e685e9db1affbee0f87c63f4ed0e43699ee398f5f908c84ba86197cad94e679f2747a40046a617e4dc1dd6bfb92e8e2a014d79d6271fac065a6636ff1cf7c4fd172825dcc5a6157baa4c0b45c5cbc1deaf60489dbb4270b941944dccbd3108e420938da346c60b9fdce78528c202dd0a73d5955acfb43955d7de10fe5407f38272c47f352ddd220ca07fb06aa05f1f7f082a06b42a3fb42c5cbd5a10e126312923e2501ab93e890ca9e8067379fbfdb01c0a304864f2fa973a34b0526edae7c710d275d1eed9431006376c89c0ffd0794291f3e192728c29ad49274&X-Goog-SignedHeaders=host&X-User=2931823730: HTTPSConnectionPool(host='storage.googleapis.com', port=443): Max retries exceeded with url: /wandb-production.appspot.com/2931823730-harbin-institute-of-technology/ltu-as/k2h266f7/output.log?X-Goog-Algorithm=GOOG4-RSA-SHA256&X-Goog-Credential=gorilla-files-url-signer-man%40wandb-production.iam.gserviceaccount.com%2F20250411%2Fauto%2Fstorage%2Fgoog4_request&X-Goog-Date=20250411T152436Z&X-Goog-Expires=86399&X-Goog-Signature=a218415934127a9773405e8afb2110dac28c657fba4bf7ad82709f7ccf62bc41a6a9c1870e685e9db1affbee0f87c63f4ed0e43699ee398f5f908c84ba86197cad94e679f2747a40046a617e4dc1dd6bfb92e8e2a014d79d6271fac065a6636ff1cf7c4fd172825dcc5a6157baa4c0b45c5cbc1deaf60489dbb4270b941944dccbd3108e420938da346c60b9fdce78528c202dd0a73d5955acfb43955d7de10fe5407f38272c47f352ddd220ca07fb06aa05f1f7f082a06b42a3fb42c5cbd5a10e126312923e2501ab93e890ca9e8067379fbfdb01c0a304864f2fa973a34b0526edae7c710d275d1eed9431006376c89c0ffd0794291f3e192728c29ad49274&X-Goog-SignedHeaders=host&X-User=2931823730 (Caused by NewConnectionError('<urllib3.connection.HTTPSConnection object at 0x7f6f435d01c0>: Failed to establish a new connection: [Errno 101] Network is unreachable'))
2025-04-11 15:24:36,530 ERROR   wandb-upload_4:24989 [internal_api.py:upload_file():2558] upload_file request headers: {'User-Agent': 'python-requests/2.32.3', 'Accept-Encoding': 'gzip, deflate, br', 'Accept': '*/*', 'Connection': 'keep-alive', 'Content-Length': '4566'}
2025-04-11 15:24:36,530 ERROR   wandb-upload_4:24989 [internal_api.py:upload_file():2560] upload_file response body: 
2025-04-11 15:24:36,531 ERROR   wandb-upload_3:24989 [internal_api.py:upload_file():2556] upload_file exception https://storage.googleapis.com/wandb-production.appspot.com/2931823730-harbin-institute-of-technology/ltu-as/k2h266f7/conda-environment.yaml?X-Goog-Algorithm=GOOG4-RSA-SHA256&X-Goog-Credential=gorilla-files-url-signer-man%40wandb-production.iam.gserviceaccount.com%2F20250411%2Fauto%2Fstorage%2Fgoog4_request&X-Goog-Date=20250411T152436Z&X-Goog-Expires=86399&X-Goog-Signature=8fbfa3d461267490826dd69292f21407adfcbf793e9fa345a3b7b4018ec226da5c44488fa6adc0f2daccdf584c6af602fab6fe9efea9d71b3bb7df3159a431edec7ab06f7174dd864c90757977e38c4bace544e0edc03cc4e70976fb41c203c5f8596c01f178cb10181c426a2a56f239e6110ab6bf2adc812aa0269b2418a0bd0cd567b788814d1669a6c95582b5b8106d05d998fd6d30997b6e1330b41cc53e3b299f47892fb4e78e24b066306886ad187965483b03ab277169a7a354ae4fdf3911fcd770110f2fca767c5e3ebc31830cbe064865d88bb44d4daefd7c6530fc49c8085295a1f62a5f1ebcf75dac4f5f7baf3ce2f265c6d580249feb731f1235&X-Goog-SignedHeaders=host&X-User=2931823730: HTTPSConnectionPool(host='storage.googleapis.com', port=443): Max retries exceeded with url: /wandb-production.appspot.com/2931823730-harbin-institute-of-technology/ltu-as/k2h266f7/conda-environment.yaml?X-Goog-Algorithm=GOOG4-RSA-SHA256&X-Goog-Credential=gorilla-files-url-signer-man%40wandb-production.iam.gserviceaccount.com%2F20250411%2Fauto%2Fstorage%2Fgoog4_request&X-Goog-Date=20250411T152436Z&X-Goog-Expires=86399&X-Goog-Signature=8fbfa3d461267490826dd69292f21407adfcbf793e9fa345a3b7b4018ec226da5c44488fa6adc0f2daccdf584c6af602fab6fe9efea9d71b3bb7df3159a431edec7ab06f7174dd864c90757977e38c4bace544e0edc03cc4e70976fb41c203c5f8596c01f178cb10181c426a2a56f239e6110ab6bf2adc812aa0269b2418a0bd0cd567b788814d1669a6c95582b5b8106d05d998fd6d30997b6e1330b41cc53e3b299f47892fb4e78e24b066306886ad187965483b03ab277169a7a354ae4fdf3911fcd770110f2fca767c5e3ebc31830cbe064865d88bb44d4daefd7c6530fc49c8085295a1f62a5f1ebcf75dac4f5f7baf3ce2f265c6d580249feb731f1235&X-Goog-SignedHeaders=host&X-User=2931823730 (Caused by NewConnectionError('<urllib3.connection.HTTPSConnection object at 0x7f6f435d36d0>: Failed to establish a new connection: [Errno 101] Network is unreachable'))
2025-04-11 15:24:36,531 ERROR   wandb-upload_3:24989 [internal_api.py:upload_file():2558] upload_file request headers: {'User-Agent': 'python-requests/2.32.3', 'Accept-Encoding': 'gzip, deflate, br', 'Accept': '*/*', 'Connection': 'keep-alive', 'Content-Length': '8281'}
2025-04-11 15:24:36,531 ERROR   wandb-upload_3:24989 [internal_api.py:upload_file():2560] upload_file response body: 
2025-04-11 15:24:36,532 ERROR   wandb-upload_5:24989 [internal_api.py:upload_file():2556] upload_file exception https://storage.googleapis.com/wandb-production.appspot.com/2931823730-harbin-institute-of-technology/ltu-as/k2h266f7/wandb-summary.json?X-Goog-Algorithm=GOOG4-RSA-SHA256&X-Goog-Credential=gorilla-files-url-signer-man%40wandb-production.iam.gserviceaccount.com%2F20250411%2Fauto%2Fstorage%2Fgoog4_request&X-Goog-Date=20250411T152436Z&X-Goog-Expires=86399&X-Goog-Signature=00c243920d22b412664d1162c1e021970b55b5517d3aab32c839c3d9a4226399433bcd764e107c3e966f9f00c18ae14da84d7f5161f9a32e27758e3a5420e90623727c1429f7d9d019322414e3fec0182afbdbd19fc57be827135d7e5fe0e7d4b79f08f580b792211b08ef9a825b1bbc74c67cc8cc40022dffc55ea4410b383f0430b397b2d1bb314cd66c4f0ec1da7ae9565e24ea5913e08d55c8193c8dc84c7c3783e5cded7fe8ccf664daa5bd139021e55f427ec8d75a5b34dafa339af877f635a5e19b92a9f4b107eeefae2a44c443b6f6a6bcfb2e802aa3ea43d5450ebcd299e0e9efbb5f10ecd2652158324710bc8c8ae9086cb6bebbf9c7fddf8d683d&X-Goog-SignedHeaders=host&X-User=2931823730: HTTPSConnectionPool(host='storage.googleapis.com', port=443): Max retries exceeded with url: /wandb-production.appspot.com/2931823730-harbin-institute-of-technology/ltu-as/k2h266f7/wandb-summary.json?X-Goog-Algorithm=GOOG4-RSA-SHA256&X-Goog-Credential=gorilla-files-url-signer-man%40wandb-production.iam.gserviceaccount.com%2F20250411%2Fauto%2Fstorage%2Fgoog4_request&X-Goog-Date=20250411T152436Z&X-Goog-Expires=86399&X-Goog-Signature=00c243920d22b412664d1162c1e021970b55b5517d3aab32c839c3d9a4226399433bcd764e107c3e966f9f00c18ae14da84d7f5161f9a32e27758e3a5420e90623727c1429f7d9d019322414e3fec0182afbdbd19fc57be827135d7e5fe0e7d4b79f08f580b792211b08ef9a825b1bbc74c67cc8cc40022dffc55ea4410b383f0430b397b2d1bb314cd66c4f0ec1da7ae9565e24ea5913e08d55c8193c8dc84c7c3783e5cded7fe8ccf664daa5bd139021e55f427ec8d75a5b34dafa339af877f635a5e19b92a9f4b107eeefae2a44c443b6f6a6bcfb2e802aa3ea43d5450ebcd299e0e9efbb5f10ecd2652158324710bc8c8ae9086cb6bebbf9c7fddf8d683d&X-Goog-SignedHeaders=host&X-User=2931823730 (Caused by NewConnectionError('<urllib3.connection.HTTPSConnection object at 0x7f6f435d28f0>: Failed to establish a new connection: [Errno 101] Network is unreachable'))
2025-04-11 15:24:36,532 ERROR   wandb-upload_5:24989 [internal_api.py:upload_file():2558] upload_file request headers: {'User-Agent': 'python-requests/2.32.3', 'Accept-Encoding': 'gzip, deflate, br', 'Accept': '*/*', 'Connection': 'keep-alive', 'Content-Length': '27'}
2025-04-11 15:24:36,532 ERROR   wandb-upload_5:24989 [internal_api.py:upload_file():2560] upload_file response body: 
2025-04-11 15:24:36,699 DEBUG   HandlerThread:24989 [handler.py:handle_request():146] handle_request: poll_exit
2025-04-11 15:24:36,699 DEBUG   SenderThread:24989 [sender.py:send_request():407] send_request: poll_exit
2025-04-11 15:24:37,160 ERROR   wandb-upload_0:24989 [internal_api.py:upload_file():2556] upload_file exception https://storage.googleapis.com/wandb-production.appspot.com/2931823730-harbin-institute-of-technology/ltu-as/k2h266f7/wandb-metadata.json?X-Goog-Algorithm=GOOG4-RSA-SHA256&X-Goog-Credential=gorilla-files-url-signer-man%40wandb-production.iam.gserviceaccount.com%2F20250411%2Fauto%2Fstorage%2Fgoog4_request&X-Goog-Date=20250411T152429Z&X-Goog-Expires=86399&X-Goog-Signature=6ec798b561c3cb2395a17d429f72d1bb4186851438f563ecf78bf1f9dc2b5bcff133f9ad0475c60bc1ab0d97e844cfdca95eea98e9242d5bf6414f8e893f8c9577b7d4e5ba040eac31d4c1ffe28a810db3a0375ebce266ce826f2d61a7ce843ce3aa0da775b6b1919247a6583dd5f1d0227acd04d455d3cfcb80912a63a7b14bce8e34d6e2781b78339658e7dce006bdbba3224c717bcf1d18f836de545d1e6c16702f349810a661b2a29d0ae54da42347dba9ed341ea4b3f3f4ed023a50b3b3ce4284ac11e6b286f8a5b6d9a51b608bb69c415180e91a2d9daecb65f3eb6a052385bd58ce99a59a48bc6ea91e078394af4f45f97ca37e771309c400847715f7&X-Goog-SignedHeaders=host&X-User=2931823730: HTTPSConnectionPool(host='storage.googleapis.com', port=443): Max retries exceeded with url: /wandb-production.appspot.com/2931823730-harbin-institute-of-technology/ltu-as/k2h266f7/wandb-metadata.json?X-Goog-Algorithm=GOOG4-RSA-SHA256&X-Goog-Credential=gorilla-files-url-signer-man%40wandb-production.iam.gserviceaccount.com%2F20250411%2Fauto%2Fstorage%2Fgoog4_request&X-Goog-Date=20250411T152429Z&X-Goog-Expires=86399&X-Goog-Signature=6ec798b561c3cb2395a17d429f72d1bb4186851438f563ecf78bf1f9dc2b5bcff133f9ad0475c60bc1ab0d97e844cfdca95eea98e9242d5bf6414f8e893f8c9577b7d4e5ba040eac31d4c1ffe28a810db3a0375ebce266ce826f2d61a7ce843ce3aa0da775b6b1919247a6583dd5f1d0227acd04d455d3cfcb80912a63a7b14bce8e34d6e2781b78339658e7dce006bdbba3224c717bcf1d18f836de545d1e6c16702f349810a661b2a29d0ae54da42347dba9ed341ea4b3f3f4ed023a50b3b3ce4284ac11e6b286f8a5b6d9a51b608bb69c415180e91a2d9daecb65f3eb6a052385bd58ce99a59a48bc6ea91e078394af4f45f97ca37e771309c400847715f7&X-Goog-SignedHeaders=host&X-User=2931823730 (Caused by NewConnectionError('<urllib3.connection.HTTPSConnection object at 0x7f6f40c02f80>: Failed to establish a new connection: [Errno 101] Network is unreachable'))
2025-04-11 15:24:37,160 ERROR   wandb-upload_0:24989 [internal_api.py:upload_file():2558] upload_file request headers: {'User-Agent': 'python-requests/2.32.3', 'Accept-Encoding': 'gzip, deflate, br', 'Accept': '*/*', 'Connection': 'keep-alive', 'Content-Length': '2274'}
2025-04-11 15:24:37,160 ERROR   wandb-upload_0:24989 [internal_api.py:upload_file():2560] upload_file response body: 
2025-04-11 15:24:37,431 ERROR   wandb-upload_2:24989 [internal_api.py:upload_file():2556] upload_file exception https://storage.googleapis.com/wandb-production.appspot.com/2931823730-harbin-institute-of-technology/ltu-as/k2h266f7/requirements.txt?X-Goog-Algorithm=GOOG4-RSA-SHA256&X-Goog-Credential=gorilla-files-url-signer-man%40wandb-production.iam.gserviceaccount.com%2F20250411%2Fauto%2Fstorage%2Fgoog4_request&X-Goog-Date=20250411T152436Z&X-Goog-Expires=86399&X-Goog-Signature=4a6841c32e79f12bad7f7960d80c3a4defca087c4ba31bd508a9619c23f0b4950a6d4a0f226cc30c34bf8494bd41a909310909b3197103fe0cc1349bdcadb6228660d9a773f72b7beb613e325b71c1dffa163fbc7c39c4201f53af1cbb25ee5cc0b9e09e731beafc678143e692fd480268c65439b3c7b480de3dd6f7c279ed05312555ef86ea1a19ecaeeab786b36a2e5da6414126a6f06c7efda4be419d88955ba2983d3bfe7b794300d27a9592dc4548adf6c5aa9c5a324eec7ef5d607a40bf325ca0a2df0b2ee24a44391f76159361287ec1bbf89c6f8411e01a546b49b999e0b59dda8422f8206bce1ceb1a02e7fbe9603dc7ebf9aa50d821c370c2bc794&X-Goog-SignedHeaders=host&X-User=2931823730: HTTPSConnectionPool(host='storage.googleapis.com', port=443): Max retries exceeded with url: /wandb-production.appspot.com/2931823730-harbin-institute-of-technology/ltu-as/k2h266f7/requirements.txt?X-Goog-Algorithm=GOOG4-RSA-SHA256&X-Goog-Credential=gorilla-files-url-signer-man%40wandb-production.iam.gserviceaccount.com%2F20250411%2Fauto%2Fstorage%2Fgoog4_request&X-Goog-Date=20250411T152436Z&X-Goog-Expires=86399&X-Goog-Signature=4a6841c32e79f12bad7f7960d80c3a4defca087c4ba31bd508a9619c23f0b4950a6d4a0f226cc30c34bf8494bd41a909310909b3197103fe0cc1349bdcadb6228660d9a773f72b7beb613e325b71c1dffa163fbc7c39c4201f53af1cbb25ee5cc0b9e09e731beafc678143e692fd480268c65439b3c7b480de3dd6f7c279ed05312555ef86ea1a19ecaeeab786b36a2e5da6414126a6f06c7efda4be419d88955ba2983d3bfe7b794300d27a9592dc4548adf6c5aa9c5a324eec7ef5d607a40bf325ca0a2df0b2ee24a44391f76159361287ec1bbf89c6f8411e01a546b49b999e0b59dda8422f8206bce1ceb1a02e7fbe9603dc7ebf9aa50d821c370c2bc794&X-Goog-SignedHeaders=host&X-User=2931823730 (Caused by NewConnectionError('<urllib3.connection.HTTPSConnection object at 0x7f6f40c03100>: Failed to establish a new connection: [Errno 101] Network is unreachable'))
2025-04-11 15:24:37,431 ERROR   wandb-upload_2:24989 [internal_api.py:upload_file():2558] upload_file request headers: {'User-Agent': 'python-requests/2.32.3', 'Accept-Encoding': 'gzip, deflate, br', 'Accept': '*/*', 'Connection': 'keep-alive', 'Content-Length': '4212'}
2025-04-11 15:24:37,431 ERROR   wandb-upload_2:24989 [internal_api.py:upload_file():2560] upload_file response body: 
2025-04-11 15:24:37,431 INFO    wandb-upload_2:24989 [retry.py:__call__():172] Retry attempt failed:
Traceback (most recent call last):
  File "/root/anaconda3/envs/venv_ltu/lib/python3.10/site-packages/urllib3/connection.py", line 198, in _new_conn
    sock = connection.create_connection(
  File "/root/anaconda3/envs/venv_ltu/lib/python3.10/site-packages/urllib3/util/connection.py", line 85, in create_connection
    raise err
  File "/root/anaconda3/envs/venv_ltu/lib/python3.10/site-packages/urllib3/util/connection.py", line 73, in create_connection
    sock.connect(sa)
OSError: [Errno 101] Network is unreachable

The above exception was the direct cause of the following exception:

Traceback (most recent call last):
  File "/root/anaconda3/envs/venv_ltu/lib/python3.10/site-packages/urllib3/connectionpool.py", line 793, in urlopen
    response = self._make_request(
  File "/root/anaconda3/envs/venv_ltu/lib/python3.10/site-packages/urllib3/connectionpool.py", line 491, in _make_request
    raise new_e
  File "/root/anaconda3/envs/venv_ltu/lib/python3.10/site-packages/urllib3/connectionpool.py", line 467, in _make_request
    self._validate_conn(conn)
  File "/root/anaconda3/envs/venv_ltu/lib/python3.10/site-packages/urllib3/connectionpool.py", line 1099, in _validate_conn
    conn.connect()
  File "/root/anaconda3/envs/venv_ltu/lib/python3.10/site-packages/urllib3/connection.py", line 616, in connect
    self.sock = sock = self._new_conn()
  File "/root/anaconda3/envs/venv_ltu/lib/python3.10/site-packages/urllib3/connection.py", line 213, in _new_conn
    raise NewConnectionError(
urllib3.exceptions.NewConnectionError: <urllib3.connection.HTTPSConnection object at 0x7f6f40c03100>: Failed to establish a new connection: [Errno 101] Network is unreachable

The above exception was the direct cause of the following exception:

Traceback (most recent call last):
  File "/root/anaconda3/envs/venv_ltu/lib/python3.10/site-packages/requests/adapters.py", line 667, in send
    resp = conn.urlopen(
  File "/root/anaconda3/envs/venv_ltu/lib/python3.10/site-packages/urllib3/connectionpool.py", line 847, in urlopen
    retries = retries.increment(
  File "/root/anaconda3/envs/venv_ltu/lib/python3.10/site-packages/urllib3/util/retry.py", line 515, in increment
    raise MaxRetryError(_pool, url, reason) from reason  # type: ignore[arg-type]
urllib3.exceptions.MaxRetryError: HTTPSConnectionPool(host='storage.googleapis.com', port=443): Max retries exceeded with url: /wandb-production.appspot.com/2931823730-harbin-institute-of-technology/ltu-as/k2h266f7/requirements.txt?X-Goog-Algorithm=GOOG4-RSA-SHA256&X-Goog-Credential=gorilla-files-url-signer-man%40wandb-production.iam.gserviceaccount.com%2F20250411%2Fauto%2Fstorage%2Fgoog4_request&X-Goog-Date=20250411T152436Z&X-Goog-Expires=86399&X-Goog-Signature=4a6841c32e79f12bad7f7960d80c3a4defca087c4ba31bd508a9619c23f0b4950a6d4a0f226cc30c34bf8494bd41a909310909b3197103fe0cc1349bdcadb6228660d9a773f72b7beb613e325b71c1dffa163fbc7c39c4201f53af1cbb25ee5cc0b9e09e731beafc678143e692fd480268c65439b3c7b480de3dd6f7c279ed05312555ef86ea1a19ecaeeab786b36a2e5da6414126a6f06c7efda4be419d88955ba2983d3bfe7b794300d27a9592dc4548adf6c5aa9c5a324eec7ef5d607a40bf325ca0a2df0b2ee24a44391f76159361287ec1bbf89c6f8411e01a546b49b999e0b59dda8422f8206bce1ceb1a02e7fbe9603dc7ebf9aa50d821c370c2bc794&X-Goog-SignedHeaders=host&X-User=2931823730 (Caused by NewConnectionError('<urllib3.connection.HTTPSConnection object at 0x7f6f40c03100>: Failed to establish a new connection: [Errno 101] Network is unreachable'))

During handling of the above exception, another exception occurred:

Traceback (most recent call last):
  File "/root/anaconda3/envs/venv_ltu/lib/python3.10/site-packages/wandb/sdk/internal/internal_api.py", line 2549, in upload_file
    response = self._upload_file_session.put(
  File "/root/anaconda3/envs/venv_ltu/lib/python3.10/site-packages/requests/sessions.py", line 649, in put
    return self.request("PUT", url, data=data, **kwargs)
  File "/root/anaconda3/envs/venv_ltu/lib/python3.10/site-packages/requests/sessions.py", line 589, in request
    resp = self.send(prep, **send_kwargs)
  File "/root/anaconda3/envs/venv_ltu/lib/python3.10/site-packages/requests/sessions.py", line 703, in send
    r = adapter.send(request, **kwargs)
  File "/root/anaconda3/envs/venv_ltu/lib/python3.10/site-packages/requests/adapters.py", line 700, in send
    raise ConnectionError(e, request=request)
requests.exceptions.ConnectionError: HTTPSConnectionPool(host='storage.googleapis.com', port=443): Max retries exceeded with url: /wandb-production.appspot.com/2931823730-harbin-institute-of-technology/ltu-as/k2h266f7/requirements.txt?X-Goog-Algorithm=GOOG4-RSA-SHA256&X-Goog-Credential=gorilla-files-url-signer-man%40wandb-production.iam.gserviceaccount.com%2F20250411%2Fauto%2Fstorage%2Fgoog4_request&X-Goog-Date=20250411T152436Z&X-Goog-Expires=86399&X-Goog-Signature=4a6841c32e79f12bad7f7960d80c3a4defca087c4ba31bd508a9619c23f0b4950a6d4a0f226cc30c34bf8494bd41a909310909b3197103fe0cc1349bdcadb6228660d9a773f72b7beb613e325b71c1dffa163fbc7c39c4201f53af1cbb25ee5cc0b9e09e731beafc678143e692fd480268c65439b3c7b480de3dd6f7c279ed05312555ef86ea1a19ecaeeab786b36a2e5da6414126a6f06c7efda4be419d88955ba2983d3bfe7b794300d27a9592dc4548adf6c5aa9c5a324eec7ef5d607a40bf325ca0a2df0b2ee24a44391f76159361287ec1bbf89c6f8411e01a546b49b999e0b59dda8422f8206bce1ceb1a02e7fbe9603dc7ebf9aa50d821c370c2bc794&X-Goog-SignedHeaders=host&X-User=2931823730 (Caused by NewConnectionError('<urllib3.connection.HTTPSConnection object at 0x7f6f40c03100>: Failed to establish a new connection: [Errno 101] Network is unreachable'))

During handling of the above exception, another exception occurred:

Traceback (most recent call last):
  File "/root/anaconda3/envs/venv_ltu/lib/python3.10/site-packages/wandb/sdk/lib/retry.py", line 131, in __call__
    result = self._call_fn(*args, **kwargs)
  File "/root/anaconda3/envs/venv_ltu/lib/python3.10/site-packages/wandb/sdk/internal/internal_api.py", line 2580, in upload_file
    raise _e.with_traceback(sys.exc_info()[2])
  File "/root/anaconda3/envs/venv_ltu/lib/python3.10/site-packages/wandb/sdk/internal/internal_api.py", line 2549, in upload_file
    response = self._upload_file_session.put(
  File "/root/anaconda3/envs/venv_ltu/lib/python3.10/site-packages/requests/sessions.py", line 649, in put
    return self.request("PUT", url, data=data, **kwargs)
  File "/root/anaconda3/envs/venv_ltu/lib/python3.10/site-packages/requests/sessions.py", line 589, in request
    resp = self.send(prep, **send_kwargs)
  File "/root/anaconda3/envs/venv_ltu/lib/python3.10/site-packages/requests/sessions.py", line 703, in send
    r = adapter.send(request, **kwargs)
  File "/root/anaconda3/envs/venv_ltu/lib/python3.10/site-packages/requests/adapters.py", line 700, in send
    raise ConnectionError(e, request=request)
wandb.sdk.lib.retry.TransientError: None
2025-04-11 15:24:37,619 ERROR   wandb-upload_3:24989 [internal_api.py:upload_file():2556] upload_file exception https://storage.googleapis.com/wandb-production.appspot.com/2931823730-harbin-institute-of-technology/ltu-as/k2h266f7/conda-environment.yaml?X-Goog-Algorithm=GOOG4-RSA-SHA256&X-Goog-Credential=gorilla-files-url-signer-man%40wandb-production.iam.gserviceaccount.com%2F20250411%2Fauto%2Fstorage%2Fgoog4_request&X-Goog-Date=20250411T152436Z&X-Goog-Expires=86399&X-Goog-Signature=8fbfa3d461267490826dd69292f21407adfcbf793e9fa345a3b7b4018ec226da5c44488fa6adc0f2daccdf584c6af602fab6fe9efea9d71b3bb7df3159a431edec7ab06f7174dd864c90757977e38c4bace544e0edc03cc4e70976fb41c203c5f8596c01f178cb10181c426a2a56f239e6110ab6bf2adc812aa0269b2418a0bd0cd567b788814d1669a6c95582b5b8106d05d998fd6d30997b6e1330b41cc53e3b299f47892fb4e78e24b066306886ad187965483b03ab277169a7a354ae4fdf3911fcd770110f2fca767c5e3ebc31830cbe064865d88bb44d4daefd7c6530fc49c8085295a1f62a5f1ebcf75dac4f5f7baf3ce2f265c6d580249feb731f1235&X-Goog-SignedHeaders=host&X-User=2931823730: HTTPSConnectionPool(host='storage.googleapis.com', port=443): Max retries exceeded with url: /wandb-production.appspot.com/2931823730-harbin-institute-of-technology/ltu-as/k2h266f7/conda-environment.yaml?X-Goog-Algorithm=GOOG4-RSA-SHA256&X-Goog-Credential=gorilla-files-url-signer-man%40wandb-production.iam.gserviceaccount.com%2F20250411%2Fauto%2Fstorage%2Fgoog4_request&X-Goog-Date=20250411T152436Z&X-Goog-Expires=86399&X-Goog-Signature=8fbfa3d461267490826dd69292f21407adfcbf793e9fa345a3b7b4018ec226da5c44488fa6adc0f2daccdf584c6af602fab6fe9efea9d71b3bb7df3159a431edec7ab06f7174dd864c90757977e38c4bace544e0edc03cc4e70976fb41c203c5f8596c01f178cb10181c426a2a56f239e6110ab6bf2adc812aa0269b2418a0bd0cd567b788814d1669a6c95582b5b8106d05d998fd6d30997b6e1330b41cc53e3b299f47892fb4e78e24b066306886ad187965483b03ab277169a7a354ae4fdf3911fcd770110f2fca767c5e3ebc31830cbe064865d88bb44d4daefd7c6530fc49c8085295a1f62a5f1ebcf75dac4f5f7baf3ce2f265c6d580249feb731f1235&X-Goog-SignedHeaders=host&X-User=2931823730 (Caused by NewConnectionError('<urllib3.connection.HTTPSConnection object at 0x7f6f40c01ea0>: Failed to establish a new connection: [Errno 101] Network is unreachable'))
2025-04-11 15:24:37,619 ERROR   wandb-upload_3:24989 [internal_api.py:upload_file():2558] upload_file request headers: {'User-Agent': 'python-requests/2.32.3', 'Accept-Encoding': 'gzip, deflate, br', 'Accept': '*/*', 'Connection': 'keep-alive', 'Content-Length': '8281'}
2025-04-11 15:24:37,619 ERROR   wandb-upload_3:24989 [internal_api.py:upload_file():2560] upload_file response body: 
2025-04-11 15:24:37,633 ERROR   wandb-upload_1:24989 [internal_api.py:upload_file():2556] upload_file exception https://storage.googleapis.com/wandb-production.appspot.com/2931823730-harbin-institute-of-technology/ltu-as/k2h266f7/config.yaml?X-Goog-Algorithm=GOOG4-RSA-SHA256&X-Goog-Credential=gorilla-files-url-signer-man%40wandb-production.iam.gserviceaccount.com%2F20250411%2Fauto%2Fstorage%2Fgoog4_request&X-Goog-Date=20250411T152436Z&X-Goog-Expires=86399&X-Goog-Signature=a2bd9fa79d8f7fff9ac0e7c9263d1d19c6df2bf6806a808a78bada2eba939d69029cac8e041fc4f10cfb94a32017362c65f40f77b4e98a602593050d831b31398d5afa352dcb097f0ee80e078e39f3f2091c46e1df073526f3b6fe27d748e0ec91d2dc7a51c4379df843d0c7f77779463189d1ef5c0e80adb4d5e2ed14f0878906a02e8118c71d8d946705fccdfc2503e9c8b09a725e225fc761f9981aa5f980ef1cd60ea69d46c763b37527f65837001084a213bad97d33b669eb765f3813c4674c741cb9bc962b69f30bc5b8f8a957a65f1a0c0ef23eaf27f0ebe43ccc6a5cfb5133ae52514b51b5c807491799f9c99d8f33c5405130373b7d096b117f1448&X-Goog-SignedHeaders=host&X-User=2931823730: HTTPSConnectionPool(host='storage.googleapis.com', port=443): Max retries exceeded with url: /wandb-production.appspot.com/2931823730-harbin-institute-of-technology/ltu-as/k2h266f7/config.yaml?X-Goog-Algorithm=GOOG4-RSA-SHA256&X-Goog-Credential=gorilla-files-url-signer-man%40wandb-production.iam.gserviceaccount.com%2F20250411%2Fauto%2Fstorage%2Fgoog4_request&X-Goog-Date=20250411T152436Z&X-Goog-Expires=86399&X-Goog-Signature=a2bd9fa79d8f7fff9ac0e7c9263d1d19c6df2bf6806a808a78bada2eba939d69029cac8e041fc4f10cfb94a32017362c65f40f77b4e98a602593050d831b31398d5afa352dcb097f0ee80e078e39f3f2091c46e1df073526f3b6fe27d748e0ec91d2dc7a51c4379df843d0c7f77779463189d1ef5c0e80adb4d5e2ed14f0878906a02e8118c71d8d946705fccdfc2503e9c8b09a725e225fc761f9981aa5f980ef1cd60ea69d46c763b37527f65837001084a213bad97d33b669eb765f3813c4674c741cb9bc962b69f30bc5b8f8a957a65f1a0c0ef23eaf27f0ebe43ccc6a5cfb5133ae52514b51b5c807491799f9c99d8f33c5405130373b7d096b117f1448&X-Goog-SignedHeaders=host&X-User=2931823730 (Caused by NewConnectionError('<urllib3.connection.HTTPSConnection object at 0x7f6f40c024d0>: Failed to establish a new connection: [Errno 101] Network is unreachable'))
2025-04-11 15:24:37,634 ERROR   wandb-upload_1:24989 [internal_api.py:upload_file():2558] upload_file request headers: {'User-Agent': 'python-requests/2.32.3', 'Accept-Encoding': 'gzip, deflate, br', 'Accept': '*/*', 'Connection': 'keep-alive', 'Content-Length': '8684'}
2025-04-11 15:24:37,634 ERROR   wandb-upload_1:24989 [internal_api.py:upload_file():2560] upload_file response body: 
2025-04-11 15:24:37,701 DEBUG   HandlerThread:24989 [handler.py:handle_request():146] handle_request: poll_exit
2025-04-11 15:24:37,701 DEBUG   SenderThread:24989 [sender.py:send_request():407] send_request: poll_exit
2025-04-11 15:24:37,720 ERROR   wandb-upload_5:24989 [internal_api.py:upload_file():2556] upload_file exception https://storage.googleapis.com/wandb-production.appspot.com/2931823730-harbin-institute-of-technology/ltu-as/k2h266f7/wandb-summary.json?X-Goog-Algorithm=GOOG4-RSA-SHA256&X-Goog-Credential=gorilla-files-url-signer-man%40wandb-production.iam.gserviceaccount.com%2F20250411%2Fauto%2Fstorage%2Fgoog4_request&X-Goog-Date=20250411T152436Z&X-Goog-Expires=86399&X-Goog-Signature=00c243920d22b412664d1162c1e021970b55b5517d3aab32c839c3d9a4226399433bcd764e107c3e966f9f00c18ae14da84d7f5161f9a32e27758e3a5420e90623727c1429f7d9d019322414e3fec0182afbdbd19fc57be827135d7e5fe0e7d4b79f08f580b792211b08ef9a825b1bbc74c67cc8cc40022dffc55ea4410b383f0430b397b2d1bb314cd66c4f0ec1da7ae9565e24ea5913e08d55c8193c8dc84c7c3783e5cded7fe8ccf664daa5bd139021e55f427ec8d75a5b34dafa339af877f635a5e19b92a9f4b107eeefae2a44c443b6f6a6bcfb2e802aa3ea43d5450ebcd299e0e9efbb5f10ecd2652158324710bc8c8ae9086cb6bebbf9c7fddf8d683d&X-Goog-SignedHeaders=host&X-User=2931823730: HTTPSConnectionPool(host='storage.googleapis.com', port=443): Max retries exceeded with url: /wandb-production.appspot.com/2931823730-harbin-institute-of-technology/ltu-as/k2h266f7/wandb-summary.json?X-Goog-Algorithm=GOOG4-RSA-SHA256&X-Goog-Credential=gorilla-files-url-signer-man%40wandb-production.iam.gserviceaccount.com%2F20250411%2Fauto%2Fstorage%2Fgoog4_request&X-Goog-Date=20250411T152436Z&X-Goog-Expires=86399&X-Goog-Signature=00c243920d22b412664d1162c1e021970b55b5517d3aab32c839c3d9a4226399433bcd764e107c3e966f9f00c18ae14da84d7f5161f9a32e27758e3a5420e90623727c1429f7d9d019322414e3fec0182afbdbd19fc57be827135d7e5fe0e7d4b79f08f580b792211b08ef9a825b1bbc74c67cc8cc40022dffc55ea4410b383f0430b397b2d1bb314cd66c4f0ec1da7ae9565e24ea5913e08d55c8193c8dc84c7c3783e5cded7fe8ccf664daa5bd139021e55f427ec8d75a5b34dafa339af877f635a5e19b92a9f4b107eeefae2a44c443b6f6a6bcfb2e802aa3ea43d5450ebcd299e0e9efbb5f10ecd2652158324710bc8c8ae9086cb6bebbf9c7fddf8d683d&X-Goog-SignedHeaders=host&X-User=2931823730 (Caused by NewConnectionError('<urllib3.connection.HTTPSConnection object at 0x7f6f40c01030>: Failed to establish a new connection: [Errno 101] Network is unreachable'))
2025-04-11 15:24:37,720 ERROR   wandb-upload_5:24989 [internal_api.py:upload_file():2558] upload_file request headers: {'User-Agent': 'python-requests/2.32.3', 'Accept-Encoding': 'gzip, deflate, br', 'Accept': '*/*', 'Connection': 'keep-alive', 'Content-Length': '27'}
2025-04-11 15:24:37,720 ERROR   wandb-upload_5:24989 [internal_api.py:upload_file():2560] upload_file response body: 
2025-04-11 15:24:37,770 ERROR   wandb-upload_4:24989 [internal_api.py:upload_file():2556] upload_file exception https://storage.googleapis.com/wandb-production.appspot.com/2931823730-harbin-institute-of-technology/ltu-as/k2h266f7/output.log?X-Goog-Algorithm=GOOG4-RSA-SHA256&X-Goog-Credential=gorilla-files-url-signer-man%40wandb-production.iam.gserviceaccount.com%2F20250411%2Fauto%2Fstorage%2Fgoog4_request&X-Goog-Date=20250411T152436Z&X-Goog-Expires=86399&X-Goog-Signature=a218415934127a9773405e8afb2110dac28c657fba4bf7ad82709f7ccf62bc41a6a9c1870e685e9db1affbee0f87c63f4ed0e43699ee398f5f908c84ba86197cad94e679f2747a40046a617e4dc1dd6bfb92e8e2a014d79d6271fac065a6636ff1cf7c4fd172825dcc5a6157baa4c0b45c5cbc1deaf60489dbb4270b941944dccbd3108e420938da346c60b9fdce78528c202dd0a73d5955acfb43955d7de10fe5407f38272c47f352ddd220ca07fb06aa05f1f7f082a06b42a3fb42c5cbd5a10e126312923e2501ab93e890ca9e8067379fbfdb01c0a304864f2fa973a34b0526edae7c710d275d1eed9431006376c89c0ffd0794291f3e192728c29ad49274&X-Goog-SignedHeaders=host&X-User=2931823730: HTTPSConnectionPool(host='storage.googleapis.com', port=443): Max retries exceeded with url: /wandb-production.appspot.com/2931823730-harbin-institute-of-technology/ltu-as/k2h266f7/output.log?X-Goog-Algorithm=GOOG4-RSA-SHA256&X-Goog-Credential=gorilla-files-url-signer-man%40wandb-production.iam.gserviceaccount.com%2F20250411%2Fauto%2Fstorage%2Fgoog4_request&X-Goog-Date=20250411T152436Z&X-Goog-Expires=86399&X-Goog-Signature=a218415934127a9773405e8afb2110dac28c657fba4bf7ad82709f7ccf62bc41a6a9c1870e685e9db1affbee0f87c63f4ed0e43699ee398f5f908c84ba86197cad94e679f2747a40046a617e4dc1dd6bfb92e8e2a014d79d6271fac065a6636ff1cf7c4fd172825dcc5a6157baa4c0b45c5cbc1deaf60489dbb4270b941944dccbd3108e420938da346c60b9fdce78528c202dd0a73d5955acfb43955d7de10fe5407f38272c47f352ddd220ca07fb06aa05f1f7f082a06b42a3fb42c5cbd5a10e126312923e2501ab93e890ca9e8067379fbfdb01c0a304864f2fa973a34b0526edae7c710d275d1eed9431006376c89c0ffd0794291f3e192728c29ad49274&X-Goog-SignedHeaders=host&X-User=2931823730 (Caused by NewConnectionError('<urllib3.connection.HTTPSConnection object at 0x7f6f40c010c0>: Failed to establish a new connection: [Errno 101] Network is unreachable'))
2025-04-11 15:24:37,771 ERROR   wandb-upload_4:24989 [internal_api.py:upload_file():2558] upload_file request headers: {'User-Agent': 'python-requests/2.32.3', 'Accept-Encoding': 'gzip, deflate, br', 'Accept': '*/*', 'Connection': 'keep-alive', 'Content-Length': '4566'}
2025-04-11 15:24:37,771 ERROR   wandb-upload_4:24989 [internal_api.py:upload_file():2560] upload_file response body: 
2025-04-11 15:24:38,703 DEBUG   HandlerThread:24989 [handler.py:handle_request():146] handle_request: poll_exit
2025-04-11 15:24:38,704 DEBUG   SenderThread:24989 [sender.py:send_request():407] send_request: poll_exit
2025-04-11 15:24:39,704 DEBUG   HandlerThread:24989 [handler.py:handle_request():146] handle_request: poll_exit
2025-04-11 15:24:39,706 DEBUG   SenderThread:24989 [sender.py:send_request():407] send_request: poll_exit
2025-04-11 15:24:39,819 ERROR   wandb-upload_1:24989 [internal_api.py:upload_file():2556] upload_file exception https://storage.googleapis.com/wandb-production.appspot.com/2931823730-harbin-institute-of-technology/ltu-as/k2h266f7/config.yaml?X-Goog-Algorithm=GOOG4-RSA-SHA256&X-Goog-Credential=gorilla-files-url-signer-man%40wandb-production.iam.gserviceaccount.com%2F20250411%2Fauto%2Fstorage%2Fgoog4_request&X-Goog-Date=20250411T152436Z&X-Goog-Expires=86399&X-Goog-Signature=a2bd9fa79d8f7fff9ac0e7c9263d1d19c6df2bf6806a808a78bada2eba939d69029cac8e041fc4f10cfb94a32017362c65f40f77b4e98a602593050d831b31398d5afa352dcb097f0ee80e078e39f3f2091c46e1df073526f3b6fe27d748e0ec91d2dc7a51c4379df843d0c7f77779463189d1ef5c0e80adb4d5e2ed14f0878906a02e8118c71d8d946705fccdfc2503e9c8b09a725e225fc761f9981aa5f980ef1cd60ea69d46c763b37527f65837001084a213bad97d33b669eb765f3813c4674c741cb9bc962b69f30bc5b8f8a957a65f1a0c0ef23eaf27f0ebe43ccc6a5cfb5133ae52514b51b5c807491799f9c99d8f33c5405130373b7d096b117f1448&X-Goog-SignedHeaders=host&X-User=2931823730: HTTPSConnectionPool(host='storage.googleapis.com', port=443): Max retries exceeded with url: /wandb-production.appspot.com/2931823730-harbin-institute-of-technology/ltu-as/k2h266f7/config.yaml?X-Goog-Algorithm=GOOG4-RSA-SHA256&X-Goog-Credential=gorilla-files-url-signer-man%40wandb-production.iam.gserviceaccount.com%2F20250411%2Fauto%2Fstorage%2Fgoog4_request&X-Goog-Date=20250411T152436Z&X-Goog-Expires=86399&X-Goog-Signature=a2bd9fa79d8f7fff9ac0e7c9263d1d19c6df2bf6806a808a78bada2eba939d69029cac8e041fc4f10cfb94a32017362c65f40f77b4e98a602593050d831b31398d5afa352dcb097f0ee80e078e39f3f2091c46e1df073526f3b6fe27d748e0ec91d2dc7a51c4379df843d0c7f77779463189d1ef5c0e80adb4d5e2ed14f0878906a02e8118c71d8d946705fccdfc2503e9c8b09a725e225fc761f9981aa5f980ef1cd60ea69d46c763b37527f65837001084a213bad97d33b669eb765f3813c4674c741cb9bc962b69f30bc5b8f8a957a65f1a0c0ef23eaf27f0ebe43ccc6a5cfb5133ae52514b51b5c807491799f9c99d8f33c5405130373b7d096b117f1448&X-Goog-SignedHeaders=host&X-User=2931823730 (Caused by NewConnectionError('<urllib3.connection.HTTPSConnection object at 0x7f6f435d3e80>: Failed to establish a new connection: [Errno 101] Network is unreachable'))
2025-04-11 15:24:39,819 ERROR   wandb-upload_1:24989 [internal_api.py:upload_file():2558] upload_file request headers: {'User-Agent': 'python-requests/2.32.3', 'Accept-Encoding': 'gzip, deflate, br', 'Accept': '*/*', 'Connection': 'keep-alive', 'Content-Length': '8684'}
2025-04-11 15:24:39,819 ERROR   wandb-upload_1:24989 [internal_api.py:upload_file():2560] upload_file response body: 
2025-04-11 15:24:39,839 ERROR   wandb-upload_2:24989 [internal_api.py:upload_file():2556] upload_file exception https://storage.googleapis.com/wandb-production.appspot.com/2931823730-harbin-institute-of-technology/ltu-as/k2h266f7/requirements.txt?X-Goog-Algorithm=GOOG4-RSA-SHA256&X-Goog-Credential=gorilla-files-url-signer-man%40wandb-production.iam.gserviceaccount.com%2F20250411%2Fauto%2Fstorage%2Fgoog4_request&X-Goog-Date=20250411T152436Z&X-Goog-Expires=86399&X-Goog-Signature=4a6841c32e79f12bad7f7960d80c3a4defca087c4ba31bd508a9619c23f0b4950a6d4a0f226cc30c34bf8494bd41a909310909b3197103fe0cc1349bdcadb6228660d9a773f72b7beb613e325b71c1dffa163fbc7c39c4201f53af1cbb25ee5cc0b9e09e731beafc678143e692fd480268c65439b3c7b480de3dd6f7c279ed05312555ef86ea1a19ecaeeab786b36a2e5da6414126a6f06c7efda4be419d88955ba2983d3bfe7b794300d27a9592dc4548adf6c5aa9c5a324eec7ef5d607a40bf325ca0a2df0b2ee24a44391f76159361287ec1bbf89c6f8411e01a546b49b999e0b59dda8422f8206bce1ceb1a02e7fbe9603dc7ebf9aa50d821c370c2bc794&X-Goog-SignedHeaders=host&X-User=2931823730: HTTPSConnectionPool(host='storage.googleapis.com', port=443): Max retries exceeded with url: /wandb-production.appspot.com/2931823730-harbin-institute-of-technology/ltu-as/k2h266f7/requirements.txt?X-Goog-Algorithm=GOOG4-RSA-SHA256&X-Goog-Credential=gorilla-files-url-signer-man%40wandb-production.iam.gserviceaccount.com%2F20250411%2Fauto%2Fstorage%2Fgoog4_request&X-Goog-Date=20250411T152436Z&X-Goog-Expires=86399&X-Goog-Signature=4a6841c32e79f12bad7f7960d80c3a4defca087c4ba31bd508a9619c23f0b4950a6d4a0f226cc30c34bf8494bd41a909310909b3197103fe0cc1349bdcadb6228660d9a773f72b7beb613e325b71c1dffa163fbc7c39c4201f53af1cbb25ee5cc0b9e09e731beafc678143e692fd480268c65439b3c7b480de3dd6f7c279ed05312555ef86ea1a19ecaeeab786b36a2e5da6414126a6f06c7efda4be419d88955ba2983d3bfe7b794300d27a9592dc4548adf6c5aa9c5a324eec7ef5d607a40bf325ca0a2df0b2ee24a44391f76159361287ec1bbf89c6f8411e01a546b49b999e0b59dda8422f8206bce1ceb1a02e7fbe9603dc7ebf9aa50d821c370c2bc794&X-Goog-SignedHeaders=host&X-User=2931823730 (Caused by NewConnectionError('<urllib3.connection.HTTPSConnection object at 0x7f6f435d1840>: Failed to establish a new connection: [Errno 101] Network is unreachable'))
2025-04-11 15:24:39,839 ERROR   wandb-upload_2:24989 [internal_api.py:upload_file():2558] upload_file request headers: {'User-Agent': 'python-requests/2.32.3', 'Accept-Encoding': 'gzip, deflate, br', 'Accept': '*/*', 'Connection': 'keep-alive', 'Content-Length': '4212'}
2025-04-11 15:24:39,839 ERROR   wandb-upload_2:24989 [internal_api.py:upload_file():2560] upload_file response body: 
2025-04-11 15:24:40,025 ERROR   wandb-upload_4:24989 [internal_api.py:upload_file():2556] upload_file exception https://storage.googleapis.com/wandb-production.appspot.com/2931823730-harbin-institute-of-technology/ltu-as/k2h266f7/output.log?X-Goog-Algorithm=GOOG4-RSA-SHA256&X-Goog-Credential=gorilla-files-url-signer-man%40wandb-production.iam.gserviceaccount.com%2F20250411%2Fauto%2Fstorage%2Fgoog4_request&X-Goog-Date=20250411T152436Z&X-Goog-Expires=86399&X-Goog-Signature=a218415934127a9773405e8afb2110dac28c657fba4bf7ad82709f7ccf62bc41a6a9c1870e685e9db1affbee0f87c63f4ed0e43699ee398f5f908c84ba86197cad94e679f2747a40046a617e4dc1dd6bfb92e8e2a014d79d6271fac065a6636ff1cf7c4fd172825dcc5a6157baa4c0b45c5cbc1deaf60489dbb4270b941944dccbd3108e420938da346c60b9fdce78528c202dd0a73d5955acfb43955d7de10fe5407f38272c47f352ddd220ca07fb06aa05f1f7f082a06b42a3fb42c5cbd5a10e126312923e2501ab93e890ca9e8067379fbfdb01c0a304864f2fa973a34b0526edae7c710d275d1eed9431006376c89c0ffd0794291f3e192728c29ad49274&X-Goog-SignedHeaders=host&X-User=2931823730: HTTPSConnectionPool(host='storage.googleapis.com', port=443): Max retries exceeded with url: /wandb-production.appspot.com/2931823730-harbin-institute-of-technology/ltu-as/k2h266f7/output.log?X-Goog-Algorithm=GOOG4-RSA-SHA256&X-Goog-Credential=gorilla-files-url-signer-man%40wandb-production.iam.gserviceaccount.com%2F20250411%2Fauto%2Fstorage%2Fgoog4_request&X-Goog-Date=20250411T152436Z&X-Goog-Expires=86399&X-Goog-Signature=a218415934127a9773405e8afb2110dac28c657fba4bf7ad82709f7ccf62bc41a6a9c1870e685e9db1affbee0f87c63f4ed0e43699ee398f5f908c84ba86197cad94e679f2747a40046a617e4dc1dd6bfb92e8e2a014d79d6271fac065a6636ff1cf7c4fd172825dcc5a6157baa4c0b45c5cbc1deaf60489dbb4270b941944dccbd3108e420938da346c60b9fdce78528c202dd0a73d5955acfb43955d7de10fe5407f38272c47f352ddd220ca07fb06aa05f1f7f082a06b42a3fb42c5cbd5a10e126312923e2501ab93e890ca9e8067379fbfdb01c0a304864f2fa973a34b0526edae7c710d275d1eed9431006376c89c0ffd0794291f3e192728c29ad49274&X-Goog-SignedHeaders=host&X-User=2931823730 (Caused by NewConnectionError('<urllib3.connection.HTTPSConnection object at 0x7f6f435d36a0>: Failed to establish a new connection: [Errno 101] Network is unreachable'))
2025-04-11 15:24:40,025 ERROR   wandb-upload_4:24989 [internal_api.py:upload_file():2558] upload_file request headers: {'User-Agent': 'python-requests/2.32.3', 'Accept-Encoding': 'gzip, deflate, br', 'Accept': '*/*', 'Connection': 'keep-alive', 'Content-Length': '4566'}
2025-04-11 15:24:40,026 ERROR   wandb-upload_4:24989 [internal_api.py:upload_file():2560] upload_file response body: 
2025-04-11 15:24:40,039 ERROR   wandb-upload_3:24989 [internal_api.py:upload_file():2556] upload_file exception https://storage.googleapis.com/wandb-production.appspot.com/2931823730-harbin-institute-of-technology/ltu-as/k2h266f7/conda-environment.yaml?X-Goog-Algorithm=GOOG4-RSA-SHA256&X-Goog-Credential=gorilla-files-url-signer-man%40wandb-production.iam.gserviceaccount.com%2F20250411%2Fauto%2Fstorage%2Fgoog4_request&X-Goog-Date=20250411T152436Z&X-Goog-Expires=86399&X-Goog-Signature=8fbfa3d461267490826dd69292f21407adfcbf793e9fa345a3b7b4018ec226da5c44488fa6adc0f2daccdf584c6af602fab6fe9efea9d71b3bb7df3159a431edec7ab06f7174dd864c90757977e38c4bace544e0edc03cc4e70976fb41c203c5f8596c01f178cb10181c426a2a56f239e6110ab6bf2adc812aa0269b2418a0bd0cd567b788814d1669a6c95582b5b8106d05d998fd6d30997b6e1330b41cc53e3b299f47892fb4e78e24b066306886ad187965483b03ab277169a7a354ae4fdf3911fcd770110f2fca767c5e3ebc31830cbe064865d88bb44d4daefd7c6530fc49c8085295a1f62a5f1ebcf75dac4f5f7baf3ce2f265c6d580249feb731f1235&X-Goog-SignedHeaders=host&X-User=2931823730: HTTPSConnectionPool(host='storage.googleapis.com', port=443): Max retries exceeded with url: /wandb-production.appspot.com/2931823730-harbin-institute-of-technology/ltu-as/k2h266f7/conda-environment.yaml?X-Goog-Algorithm=GOOG4-RSA-SHA256&X-Goog-Credential=gorilla-files-url-signer-man%40wandb-production.iam.gserviceaccount.com%2F20250411%2Fauto%2Fstorage%2Fgoog4_request&X-Goog-Date=20250411T152436Z&X-Goog-Expires=86399&X-Goog-Signature=8fbfa3d461267490826dd69292f21407adfcbf793e9fa345a3b7b4018ec226da5c44488fa6adc0f2daccdf584c6af602fab6fe9efea9d71b3bb7df3159a431edec7ab06f7174dd864c90757977e38c4bace544e0edc03cc4e70976fb41c203c5f8596c01f178cb10181c426a2a56f239e6110ab6bf2adc812aa0269b2418a0bd0cd567b788814d1669a6c95582b5b8106d05d998fd6d30997b6e1330b41cc53e3b299f47892fb4e78e24b066306886ad187965483b03ab277169a7a354ae4fdf3911fcd770110f2fca767c5e3ebc31830cbe064865d88bb44d4daefd7c6530fc49c8085295a1f62a5f1ebcf75dac4f5f7baf3ce2f265c6d580249feb731f1235&X-Goog-SignedHeaders=host&X-User=2931823730 (Caused by NewConnectionError('<urllib3.connection.HTTPSConnection object at 0x7f6f435d2d70>: Failed to establish a new connection: [Errno 101] Network is unreachable'))
2025-04-11 15:24:40,039 ERROR   wandb-upload_3:24989 [internal_api.py:upload_file():2558] upload_file request headers: {'User-Agent': 'python-requests/2.32.3', 'Accept-Encoding': 'gzip, deflate, br', 'Accept': '*/*', 'Connection': 'keep-alive', 'Content-Length': '8281'}
2025-04-11 15:24:40,039 ERROR   wandb-upload_3:24989 [internal_api.py:upload_file():2560] upload_file response body: 
2025-04-11 15:24:40,145 ERROR   wandb-upload_5:24989 [internal_api.py:upload_file():2556] upload_file exception https://storage.googleapis.com/wandb-production.appspot.com/2931823730-harbin-institute-of-technology/ltu-as/k2h266f7/wandb-summary.json?X-Goog-Algorithm=GOOG4-RSA-SHA256&X-Goog-Credential=gorilla-files-url-signer-man%40wandb-production.iam.gserviceaccount.com%2F20250411%2Fauto%2Fstorage%2Fgoog4_request&X-Goog-Date=20250411T152436Z&X-Goog-Expires=86399&X-Goog-Signature=00c243920d22b412664d1162c1e021970b55b5517d3aab32c839c3d9a4226399433bcd764e107c3e966f9f00c18ae14da84d7f5161f9a32e27758e3a5420e90623727c1429f7d9d019322414e3fec0182afbdbd19fc57be827135d7e5fe0e7d4b79f08f580b792211b08ef9a825b1bbc74c67cc8cc40022dffc55ea4410b383f0430b397b2d1bb314cd66c4f0ec1da7ae9565e24ea5913e08d55c8193c8dc84c7c3783e5cded7fe8ccf664daa5bd139021e55f427ec8d75a5b34dafa339af877f635a5e19b92a9f4b107eeefae2a44c443b6f6a6bcfb2e802aa3ea43d5450ebcd299e0e9efbb5f10ecd2652158324710bc8c8ae9086cb6bebbf9c7fddf8d683d&X-Goog-SignedHeaders=host&X-User=2931823730: HTTPSConnectionPool(host='storage.googleapis.com', port=443): Max retries exceeded with url: /wandb-production.appspot.com/2931823730-harbin-institute-of-technology/ltu-as/k2h266f7/wandb-summary.json?X-Goog-Algorithm=GOOG4-RSA-SHA256&X-Goog-Credential=gorilla-files-url-signer-man%40wandb-production.iam.gserviceaccount.com%2F20250411%2Fauto%2Fstorage%2Fgoog4_request&X-Goog-Date=20250411T152436Z&X-Goog-Expires=86399&X-Goog-Signature=00c243920d22b412664d1162c1e021970b55b5517d3aab32c839c3d9a4226399433bcd764e107c3e966f9f00c18ae14da84d7f5161f9a32e27758e3a5420e90623727c1429f7d9d019322414e3fec0182afbdbd19fc57be827135d7e5fe0e7d4b79f08f580b792211b08ef9a825b1bbc74c67cc8cc40022dffc55ea4410b383f0430b397b2d1bb314cd66c4f0ec1da7ae9565e24ea5913e08d55c8193c8dc84c7c3783e5cded7fe8ccf664daa5bd139021e55f427ec8d75a5b34dafa339af877f635a5e19b92a9f4b107eeefae2a44c443b6f6a6bcfb2e802aa3ea43d5450ebcd299e0e9efbb5f10ecd2652158324710bc8c8ae9086cb6bebbf9c7fddf8d683d&X-Goog-SignedHeaders=host&X-User=2931823730 (Caused by NewConnectionError('<urllib3.connection.HTTPSConnection object at 0x7f6f40c024a0>: Failed to establish a new connection: [Errno 101] Network is unreachable'))
2025-04-11 15:24:40,145 ERROR   wandb-upload_5:24989 [internal_api.py:upload_file():2558] upload_file request headers: {'User-Agent': 'python-requests/2.32.3', 'Accept-Encoding': 'gzip, deflate, br', 'Accept': '*/*', 'Connection': 'keep-alive', 'Content-Length': '27'}
2025-04-11 15:24:40,146 ERROR   wandb-upload_5:24989 [internal_api.py:upload_file():2560] upload_file response body: 
2025-04-11 15:24:40,707 DEBUG   HandlerThread:24989 [handler.py:handle_request():146] handle_request: poll_exit
2025-04-11 15:24:40,708 DEBUG   SenderThread:24989 [sender.py:send_request():407] send_request: poll_exit
2025-04-11 15:24:41,709 DEBUG   HandlerThread:24989 [handler.py:handle_request():146] handle_request: poll_exit
2025-04-11 15:24:41,710 DEBUG   SenderThread:24989 [sender.py:send_request():407] send_request: poll_exit
2025-04-11 15:24:42,710 DEBUG   HandlerThread:24989 [handler.py:handle_request():146] handle_request: poll_exit
2025-04-11 15:24:42,711 DEBUG   HandlerThread:24989 [handler.py:handle_request():146] handle_request: status_report
2025-04-11 15:24:42,712 DEBUG   SenderThread:24989 [sender.py:send_request():407] send_request: poll_exit
2025-04-11 15:24:43,711 DEBUG   HandlerThread:24989 [handler.py:handle_request():146] handle_request: poll_exit
2025-04-11 15:24:43,712 DEBUG   SenderThread:24989 [sender.py:send_request():407] send_request: poll_exit
2025-04-11 15:24:43,836 ERROR   wandb-upload_1:24989 [internal_api.py:upload_file():2556] upload_file exception https://storage.googleapis.com/wandb-production.appspot.com/2931823730-harbin-institute-of-technology/ltu-as/k2h266f7/config.yaml?X-Goog-Algorithm=GOOG4-RSA-SHA256&X-Goog-Credential=gorilla-files-url-signer-man%40wandb-production.iam.gserviceaccount.com%2F20250411%2Fauto%2Fstorage%2Fgoog4_request&X-Goog-Date=20250411T152436Z&X-Goog-Expires=86399&X-Goog-Signature=a2bd9fa79d8f7fff9ac0e7c9263d1d19c6df2bf6806a808a78bada2eba939d69029cac8e041fc4f10cfb94a32017362c65f40f77b4e98a602593050d831b31398d5afa352dcb097f0ee80e078e39f3f2091c46e1df073526f3b6fe27d748e0ec91d2dc7a51c4379df843d0c7f77779463189d1ef5c0e80adb4d5e2ed14f0878906a02e8118c71d8d946705fccdfc2503e9c8b09a725e225fc761f9981aa5f980ef1cd60ea69d46c763b37527f65837001084a213bad97d33b669eb765f3813c4674c741cb9bc962b69f30bc5b8f8a957a65f1a0c0ef23eaf27f0ebe43ccc6a5cfb5133ae52514b51b5c807491799f9c99d8f33c5405130373b7d096b117f1448&X-Goog-SignedHeaders=host&X-User=2931823730: HTTPSConnectionPool(host='storage.googleapis.com', port=443): Max retries exceeded with url: /wandb-production.appspot.com/2931823730-harbin-institute-of-technology/ltu-as/k2h266f7/config.yaml?X-Goog-Algorithm=GOOG4-RSA-SHA256&X-Goog-Credential=gorilla-files-url-signer-man%40wandb-production.iam.gserviceaccount.com%2F20250411%2Fauto%2Fstorage%2Fgoog4_request&X-Goog-Date=20250411T152436Z&X-Goog-Expires=86399&X-Goog-Signature=a2bd9fa79d8f7fff9ac0e7c9263d1d19c6df2bf6806a808a78bada2eba939d69029cac8e041fc4f10cfb94a32017362c65f40f77b4e98a602593050d831b31398d5afa352dcb097f0ee80e078e39f3f2091c46e1df073526f3b6fe27d748e0ec91d2dc7a51c4379df843d0c7f77779463189d1ef5c0e80adb4d5e2ed14f0878906a02e8118c71d8d946705fccdfc2503e9c8b09a725e225fc761f9981aa5f980ef1cd60ea69d46c763b37527f65837001084a213bad97d33b669eb765f3813c4674c741cb9bc962b69f30bc5b8f8a957a65f1a0c0ef23eaf27f0ebe43ccc6a5cfb5133ae52514b51b5c807491799f9c99d8f33c5405130373b7d096b117f1448&X-Goog-SignedHeaders=host&X-User=2931823730 (Caused by NewConnectionError('<urllib3.connection.HTTPSConnection object at 0x7f6f40c01030>: Failed to establish a new connection: [Errno 101] Network is unreachable'))
2025-04-11 15:24:43,836 ERROR   wandb-upload_1:24989 [internal_api.py:upload_file():2558] upload_file request headers: {'User-Agent': 'python-requests/2.32.3', 'Accept-Encoding': 'gzip, deflate, br', 'Accept': '*/*', 'Connection': 'keep-alive', 'Content-Length': '8684'}
2025-04-11 15:24:43,837 ERROR   wandb-upload_1:24989 [internal_api.py:upload_file():2560] upload_file response body: 
2025-04-11 15:24:44,065 ERROR   wandb-upload_3:24989 [internal_api.py:upload_file():2556] upload_file exception https://storage.googleapis.com/wandb-production.appspot.com/2931823730-harbin-institute-of-technology/ltu-as/k2h266f7/conda-environment.yaml?X-Goog-Algorithm=GOOG4-RSA-SHA256&X-Goog-Credential=gorilla-files-url-signer-man%40wandb-production.iam.gserviceaccount.com%2F20250411%2Fauto%2Fstorage%2Fgoog4_request&X-Goog-Date=20250411T152436Z&X-Goog-Expires=86399&X-Goog-Signature=8fbfa3d461267490826dd69292f21407adfcbf793e9fa345a3b7b4018ec226da5c44488fa6adc0f2daccdf584c6af602fab6fe9efea9d71b3bb7df3159a431edec7ab06f7174dd864c90757977e38c4bace544e0edc03cc4e70976fb41c203c5f8596c01f178cb10181c426a2a56f239e6110ab6bf2adc812aa0269b2418a0bd0cd567b788814d1669a6c95582b5b8106d05d998fd6d30997b6e1330b41cc53e3b299f47892fb4e78e24b066306886ad187965483b03ab277169a7a354ae4fdf3911fcd770110f2fca767c5e3ebc31830cbe064865d88bb44d4daefd7c6530fc49c8085295a1f62a5f1ebcf75dac4f5f7baf3ce2f265c6d580249feb731f1235&X-Goog-SignedHeaders=host&X-User=2931823730: HTTPSConnectionPool(host='storage.googleapis.com', port=443): Max retries exceeded with url: /wandb-production.appspot.com/2931823730-harbin-institute-of-technology/ltu-as/k2h266f7/conda-environment.yaml?X-Goog-Algorithm=GOOG4-RSA-SHA256&X-Goog-Credential=gorilla-files-url-signer-man%40wandb-production.iam.gserviceaccount.com%2F20250411%2Fauto%2Fstorage%2Fgoog4_request&X-Goog-Date=20250411T152436Z&X-Goog-Expires=86399&X-Goog-Signature=8fbfa3d461267490826dd69292f21407adfcbf793e9fa345a3b7b4018ec226da5c44488fa6adc0f2daccdf584c6af602fab6fe9efea9d71b3bb7df3159a431edec7ab06f7174dd864c90757977e38c4bace544e0edc03cc4e70976fb41c203c5f8596c01f178cb10181c426a2a56f239e6110ab6bf2adc812aa0269b2418a0bd0cd567b788814d1669a6c95582b5b8106d05d998fd6d30997b6e1330b41cc53e3b299f47892fb4e78e24b066306886ad187965483b03ab277169a7a354ae4fdf3911fcd770110f2fca767c5e3ebc31830cbe064865d88bb44d4daefd7c6530fc49c8085295a1f62a5f1ebcf75dac4f5f7baf3ce2f265c6d580249feb731f1235&X-Goog-SignedHeaders=host&X-User=2931823730 (Caused by NewConnectionError('<urllib3.connection.HTTPSConnection object at 0x7f6f40c024d0>: Failed to establish a new connection: [Errno 101] Network is unreachable'))
2025-04-11 15:24:44,065 ERROR   wandb-upload_3:24989 [internal_api.py:upload_file():2558] upload_file request headers: {'User-Agent': 'python-requests/2.32.3', 'Accept-Encoding': 'gzip, deflate, br', 'Accept': '*/*', 'Connection': 'keep-alive', 'Content-Length': '8281'}
2025-04-11 15:24:44,066 ERROR   wandb-upload_3:24989 [internal_api.py:upload_file():2560] upload_file response body: 
2025-04-11 15:24:44,409 ERROR   wandb-upload_4:24989 [internal_api.py:upload_file():2556] upload_file exception https://storage.googleapis.com/wandb-production.appspot.com/2931823730-harbin-institute-of-technology/ltu-as/k2h266f7/output.log?X-Goog-Algorithm=GOOG4-RSA-SHA256&X-Goog-Credential=gorilla-files-url-signer-man%40wandb-production.iam.gserviceaccount.com%2F20250411%2Fauto%2Fstorage%2Fgoog4_request&X-Goog-Date=20250411T152436Z&X-Goog-Expires=86399&X-Goog-Signature=a218415934127a9773405e8afb2110dac28c657fba4bf7ad82709f7ccf62bc41a6a9c1870e685e9db1affbee0f87c63f4ed0e43699ee398f5f908c84ba86197cad94e679f2747a40046a617e4dc1dd6bfb92e8e2a014d79d6271fac065a6636ff1cf7c4fd172825dcc5a6157baa4c0b45c5cbc1deaf60489dbb4270b941944dccbd3108e420938da346c60b9fdce78528c202dd0a73d5955acfb43955d7de10fe5407f38272c47f352ddd220ca07fb06aa05f1f7f082a06b42a3fb42c5cbd5a10e126312923e2501ab93e890ca9e8067379fbfdb01c0a304864f2fa973a34b0526edae7c710d275d1eed9431006376c89c0ffd0794291f3e192728c29ad49274&X-Goog-SignedHeaders=host&X-User=2931823730: HTTPSConnectionPool(host='storage.googleapis.com', port=443): Max retries exceeded with url: /wandb-production.appspot.com/2931823730-harbin-institute-of-technology/ltu-as/k2h266f7/output.log?X-Goog-Algorithm=GOOG4-RSA-SHA256&X-Goog-Credential=gorilla-files-url-signer-man%40wandb-production.iam.gserviceaccount.com%2F20250411%2Fauto%2Fstorage%2Fgoog4_request&X-Goog-Date=20250411T152436Z&X-Goog-Expires=86399&X-Goog-Signature=a218415934127a9773405e8afb2110dac28c657fba4bf7ad82709f7ccf62bc41a6a9c1870e685e9db1affbee0f87c63f4ed0e43699ee398f5f908c84ba86197cad94e679f2747a40046a617e4dc1dd6bfb92e8e2a014d79d6271fac065a6636ff1cf7c4fd172825dcc5a6157baa4c0b45c5cbc1deaf60489dbb4270b941944dccbd3108e420938da346c60b9fdce78528c202dd0a73d5955acfb43955d7de10fe5407f38272c47f352ddd220ca07fb06aa05f1f7f082a06b42a3fb42c5cbd5a10e126312923e2501ab93e890ca9e8067379fbfdb01c0a304864f2fa973a34b0526edae7c710d275d1eed9431006376c89c0ffd0794291f3e192728c29ad49274&X-Goog-SignedHeaders=host&X-User=2931823730 (Caused by NewConnectionError('<urllib3.connection.HTTPSConnection object at 0x7f6f40c01ea0>: Failed to establish a new connection: [Errno 101] Network is unreachable'))
2025-04-11 15:24:44,409 ERROR   wandb-upload_4:24989 [internal_api.py:upload_file():2558] upload_file request headers: {'User-Agent': 'python-requests/2.32.3', 'Accept-Encoding': 'gzip, deflate, br', 'Accept': '*/*', 'Connection': 'keep-alive', 'Content-Length': '4566'}
2025-04-11 15:24:44,409 ERROR   wandb-upload_4:24989 [internal_api.py:upload_file():2560] upload_file response body: 
2025-04-11 15:24:44,512 ERROR   wandb-upload_2:24989 [internal_api.py:upload_file():2556] upload_file exception https://storage.googleapis.com/wandb-production.appspot.com/2931823730-harbin-institute-of-technology/ltu-as/k2h266f7/requirements.txt?X-Goog-Algorithm=GOOG4-RSA-SHA256&X-Goog-Credential=gorilla-files-url-signer-man%40wandb-production.iam.gserviceaccount.com%2F20250411%2Fauto%2Fstorage%2Fgoog4_request&X-Goog-Date=20250411T152436Z&X-Goog-Expires=86399&X-Goog-Signature=4a6841c32e79f12bad7f7960d80c3a4defca087c4ba31bd508a9619c23f0b4950a6d4a0f226cc30c34bf8494bd41a909310909b3197103fe0cc1349bdcadb6228660d9a773f72b7beb613e325b71c1dffa163fbc7c39c4201f53af1cbb25ee5cc0b9e09e731beafc678143e692fd480268c65439b3c7b480de3dd6f7c279ed05312555ef86ea1a19ecaeeab786b36a2e5da6414126a6f06c7efda4be419d88955ba2983d3bfe7b794300d27a9592dc4548adf6c5aa9c5a324eec7ef5d607a40bf325ca0a2df0b2ee24a44391f76159361287ec1bbf89c6f8411e01a546b49b999e0b59dda8422f8206bce1ceb1a02e7fbe9603dc7ebf9aa50d821c370c2bc794&X-Goog-SignedHeaders=host&X-User=2931823730: HTTPSConnectionPool(host='storage.googleapis.com', port=443): Max retries exceeded with url: /wandb-production.appspot.com/2931823730-harbin-institute-of-technology/ltu-as/k2h266f7/requirements.txt?X-Goog-Algorithm=GOOG4-RSA-SHA256&X-Goog-Credential=gorilla-files-url-signer-man%40wandb-production.iam.gserviceaccount.com%2F20250411%2Fauto%2Fstorage%2Fgoog4_request&X-Goog-Date=20250411T152436Z&X-Goog-Expires=86399&X-Goog-Signature=4a6841c32e79f12bad7f7960d80c3a4defca087c4ba31bd508a9619c23f0b4950a6d4a0f226cc30c34bf8494bd41a909310909b3197103fe0cc1349bdcadb6228660d9a773f72b7beb613e325b71c1dffa163fbc7c39c4201f53af1cbb25ee5cc0b9e09e731beafc678143e692fd480268c65439b3c7b480de3dd6f7c279ed05312555ef86ea1a19ecaeeab786b36a2e5da6414126a6f06c7efda4be419d88955ba2983d3bfe7b794300d27a9592dc4548adf6c5aa9c5a324eec7ef5d607a40bf325ca0a2df0b2ee24a44391f76159361287ec1bbf89c6f8411e01a546b49b999e0b59dda8422f8206bce1ceb1a02e7fbe9603dc7ebf9aa50d821c370c2bc794&X-Goog-SignedHeaders=host&X-User=2931823730 (Caused by NewConnectionError('<urllib3.connection.HTTPSConnection object at 0x7f6f40c03100>: Failed to establish a new connection: [Errno 101] Network is unreachable'))
2025-04-11 15:24:44,512 ERROR   wandb-upload_2:24989 [internal_api.py:upload_file():2558] upload_file request headers: {'User-Agent': 'python-requests/2.32.3', 'Accept-Encoding': 'gzip, deflate, br', 'Accept': '*/*', 'Connection': 'keep-alive', 'Content-Length': '4212'}
2025-04-11 15:24:44,512 ERROR   wandb-upload_2:24989 [internal_api.py:upload_file():2560] upload_file response body: 
2025-04-11 15:24:44,541 ERROR   wandb-upload_5:24989 [internal_api.py:upload_file():2556] upload_file exception https://storage.googleapis.com/wandb-production.appspot.com/2931823730-harbin-institute-of-technology/ltu-as/k2h266f7/wandb-summary.json?X-Goog-Algorithm=GOOG4-RSA-SHA256&X-Goog-Credential=gorilla-files-url-signer-man%40wandb-production.iam.gserviceaccount.com%2F20250411%2Fauto%2Fstorage%2Fgoog4_request&X-Goog-Date=20250411T152436Z&X-Goog-Expires=86399&X-Goog-Signature=00c243920d22b412664d1162c1e021970b55b5517d3aab32c839c3d9a4226399433bcd764e107c3e966f9f00c18ae14da84d7f5161f9a32e27758e3a5420e90623727c1429f7d9d019322414e3fec0182afbdbd19fc57be827135d7e5fe0e7d4b79f08f580b792211b08ef9a825b1bbc74c67cc8cc40022dffc55ea4410b383f0430b397b2d1bb314cd66c4f0ec1da7ae9565e24ea5913e08d55c8193c8dc84c7c3783e5cded7fe8ccf664daa5bd139021e55f427ec8d75a5b34dafa339af877f635a5e19b92a9f4b107eeefae2a44c443b6f6a6bcfb2e802aa3ea43d5450ebcd299e0e9efbb5f10ecd2652158324710bc8c8ae9086cb6bebbf9c7fddf8d683d&X-Goog-SignedHeaders=host&X-User=2931823730: HTTPSConnectionPool(host='storage.googleapis.com', port=443): Max retries exceeded with url: /wandb-production.appspot.com/2931823730-harbin-institute-of-technology/ltu-as/k2h266f7/wandb-summary.json?X-Goog-Algorithm=GOOG4-RSA-SHA256&X-Goog-Credential=gorilla-files-url-signer-man%40wandb-production.iam.gserviceaccount.com%2F20250411%2Fauto%2Fstorage%2Fgoog4_request&X-Goog-Date=20250411T152436Z&X-Goog-Expires=86399&X-Goog-Signature=00c243920d22b412664d1162c1e021970b55b5517d3aab32c839c3d9a4226399433bcd764e107c3e966f9f00c18ae14da84d7f5161f9a32e27758e3a5420e90623727c1429f7d9d019322414e3fec0182afbdbd19fc57be827135d7e5fe0e7d4b79f08f580b792211b08ef9a825b1bbc74c67cc8cc40022dffc55ea4410b383f0430b397b2d1bb314cd66c4f0ec1da7ae9565e24ea5913e08d55c8193c8dc84c7c3783e5cded7fe8ccf664daa5bd139021e55f427ec8d75a5b34dafa339af877f635a5e19b92a9f4b107eeefae2a44c443b6f6a6bcfb2e802aa3ea43d5450ebcd299e0e9efbb5f10ecd2652158324710bc8c8ae9086cb6bebbf9c7fddf8d683d&X-Goog-SignedHeaders=host&X-User=2931823730 (Caused by NewConnectionError('<urllib3.connection.HTTPSConnection object at 0x7f6f40c02f20>: Failed to establish a new connection: [Errno 101] Network is unreachable'))
2025-04-11 15:24:44,541 ERROR   wandb-upload_5:24989 [internal_api.py:upload_file():2558] upload_file request headers: {'User-Agent': 'python-requests/2.32.3', 'Accept-Encoding': 'gzip, deflate, br', 'Accept': '*/*', 'Connection': 'keep-alive', 'Content-Length': '27'}
2025-04-11 15:24:44,541 ERROR   wandb-upload_5:24989 [internal_api.py:upload_file():2560] upload_file response body: 
2025-04-11 15:24:44,714 DEBUG   HandlerThread:24989 [handler.py:handle_request():146] handle_request: poll_exit
2025-04-11 15:24:44,714 DEBUG   SenderThread:24989 [sender.py:send_request():407] send_request: poll_exit
2025-04-11 15:24:45,715 DEBUG   HandlerThread:24989 [handler.py:handle_request():146] handle_request: poll_exit
2025-04-11 15:24:45,716 DEBUG   SenderThread:24989 [sender.py:send_request():407] send_request: poll_exit
2025-04-11 15:24:45,936 ERROR   wandb-upload_0:24989 [internal_api.py:upload_file():2556] upload_file exception https://storage.googleapis.com/wandb-production.appspot.com/2931823730-harbin-institute-of-technology/ltu-as/k2h266f7/wandb-metadata.json?X-Goog-Algorithm=GOOG4-RSA-SHA256&X-Goog-Credential=gorilla-files-url-signer-man%40wandb-production.iam.gserviceaccount.com%2F20250411%2Fauto%2Fstorage%2Fgoog4_request&X-Goog-Date=20250411T152429Z&X-Goog-Expires=86399&X-Goog-Signature=6ec798b561c3cb2395a17d429f72d1bb4186851438f563ecf78bf1f9dc2b5bcff133f9ad0475c60bc1ab0d97e844cfdca95eea98e9242d5bf6414f8e893f8c9577b7d4e5ba040eac31d4c1ffe28a810db3a0375ebce266ce826f2d61a7ce843ce3aa0da775b6b1919247a6583dd5f1d0227acd04d455d3cfcb80912a63a7b14bce8e34d6e2781b78339658e7dce006bdbba3224c717bcf1d18f836de545d1e6c16702f349810a661b2a29d0ae54da42347dba9ed341ea4b3f3f4ed023a50b3b3ce4284ac11e6b286f8a5b6d9a51b608bb69c415180e91a2d9daecb65f3eb6a052385bd58ce99a59a48bc6ea91e078394af4f45f97ca37e771309c400847715f7&X-Goog-SignedHeaders=host&X-User=2931823730: HTTPSConnectionPool(host='storage.googleapis.com', port=443): Max retries exceeded with url: /wandb-production.appspot.com/2931823730-harbin-institute-of-technology/ltu-as/k2h266f7/wandb-metadata.json?X-Goog-Algorithm=GOOG4-RSA-SHA256&X-Goog-Credential=gorilla-files-url-signer-man%40wandb-production.iam.gserviceaccount.com%2F20250411%2Fauto%2Fstorage%2Fgoog4_request&X-Goog-Date=20250411T152429Z&X-Goog-Expires=86399&X-Goog-Signature=6ec798b561c3cb2395a17d429f72d1bb4186851438f563ecf78bf1f9dc2b5bcff133f9ad0475c60bc1ab0d97e844cfdca95eea98e9242d5bf6414f8e893f8c9577b7d4e5ba040eac31d4c1ffe28a810db3a0375ebce266ce826f2d61a7ce843ce3aa0da775b6b1919247a6583dd5f1d0227acd04d455d3cfcb80912a63a7b14bce8e34d6e2781b78339658e7dce006bdbba3224c717bcf1d18f836de545d1e6c16702f349810a661b2a29d0ae54da42347dba9ed341ea4b3f3f4ed023a50b3b3ce4284ac11e6b286f8a5b6d9a51b608bb69c415180e91a2d9daecb65f3eb6a052385bd58ce99a59a48bc6ea91e078394af4f45f97ca37e771309c400847715f7&X-Goog-SignedHeaders=host&X-User=2931823730 (Caused by NewConnectionError('<urllib3.connection.HTTPSConnection object at 0x7f6f435d3370>: Failed to establish a new connection: [Errno 101] Network is unreachable'))
2025-04-11 15:24:45,936 ERROR   wandb-upload_0:24989 [internal_api.py:upload_file():2558] upload_file request headers: {'User-Agent': 'python-requests/2.32.3', 'Accept-Encoding': 'gzip, deflate, br', 'Accept': '*/*', 'Connection': 'keep-alive', 'Content-Length': '2274'}
2025-04-11 15:24:45,936 ERROR   wandb-upload_0:24989 [internal_api.py:upload_file():2560] upload_file response body: 
2025-04-11 15:24:46,717 DEBUG   HandlerThread:24989 [handler.py:handle_request():146] handle_request: poll_exit
2025-04-11 15:24:46,718 DEBUG   SenderThread:24989 [sender.py:send_request():407] send_request: poll_exit
2025-04-11 15:24:47,718 DEBUG   HandlerThread:24989 [handler.py:handle_request():146] handle_request: poll_exit
2025-04-11 15:24:47,720 DEBUG   HandlerThread:24989 [handler.py:handle_request():146] handle_request: status_report
2025-04-11 15:24:47,720 DEBUG   SenderThread:24989 [sender.py:send_request():407] send_request: poll_exit
2025-04-11 15:24:48,720 DEBUG   HandlerThread:24989 [handler.py:handle_request():146] handle_request: poll_exit
2025-04-11 15:24:48,722 DEBUG   SenderThread:24989 [sender.py:send_request():407] send_request: poll_exit
2025-04-11 15:24:49,722 DEBUG   HandlerThread:24989 [handler.py:handle_request():146] handle_request: poll_exit
2025-04-11 15:24:49,723 DEBUG   SenderThread:24989 [sender.py:send_request():407] send_request: poll_exit
2025-04-11 15:24:50,724 DEBUG   HandlerThread:24989 [handler.py:handle_request():146] handle_request: poll_exit
2025-04-11 15:24:50,725 DEBUG   SenderThread:24989 [sender.py:send_request():407] send_request: poll_exit
2025-04-11 15:24:51,726 DEBUG   HandlerThread:24989 [handler.py:handle_request():146] handle_request: poll_exit
2025-04-11 15:24:51,727 DEBUG   SenderThread:24989 [sender.py:send_request():407] send_request: poll_exit
2025-04-11 15:24:52,381 ERROR   wandb-upload_3:24989 [internal_api.py:upload_file():2556] upload_file exception https://storage.googleapis.com/wandb-production.appspot.com/2931823730-harbin-institute-of-technology/ltu-as/k2h266f7/conda-environment.yaml?X-Goog-Algorithm=GOOG4-RSA-SHA256&X-Goog-Credential=gorilla-files-url-signer-man%40wandb-production.iam.gserviceaccount.com%2F20250411%2Fauto%2Fstorage%2Fgoog4_request&X-Goog-Date=20250411T152436Z&X-Goog-Expires=86399&X-Goog-Signature=8fbfa3d461267490826dd69292f21407adfcbf793e9fa345a3b7b4018ec226da5c44488fa6adc0f2daccdf584c6af602fab6fe9efea9d71b3bb7df3159a431edec7ab06f7174dd864c90757977e38c4bace544e0edc03cc4e70976fb41c203c5f8596c01f178cb10181c426a2a56f239e6110ab6bf2adc812aa0269b2418a0bd0cd567b788814d1669a6c95582b5b8106d05d998fd6d30997b6e1330b41cc53e3b299f47892fb4e78e24b066306886ad187965483b03ab277169a7a354ae4fdf3911fcd770110f2fca767c5e3ebc31830cbe064865d88bb44d4daefd7c6530fc49c8085295a1f62a5f1ebcf75dac4f5f7baf3ce2f265c6d580249feb731f1235&X-Goog-SignedHeaders=host&X-User=2931823730: HTTPSConnectionPool(host='storage.googleapis.com', port=443): Max retries exceeded with url: /wandb-production.appspot.com/2931823730-harbin-institute-of-technology/ltu-as/k2h266f7/conda-environment.yaml?X-Goog-Algorithm=GOOG4-RSA-SHA256&X-Goog-Credential=gorilla-files-url-signer-man%40wandb-production.iam.gserviceaccount.com%2F20250411%2Fauto%2Fstorage%2Fgoog4_request&X-Goog-Date=20250411T152436Z&X-Goog-Expires=86399&X-Goog-Signature=8fbfa3d461267490826dd69292f21407adfcbf793e9fa345a3b7b4018ec226da5c44488fa6adc0f2daccdf584c6af602fab6fe9efea9d71b3bb7df3159a431edec7ab06f7174dd864c90757977e38c4bace544e0edc03cc4e70976fb41c203c5f8596c01f178cb10181c426a2a56f239e6110ab6bf2adc812aa0269b2418a0bd0cd567b788814d1669a6c95582b5b8106d05d998fd6d30997b6e1330b41cc53e3b299f47892fb4e78e24b066306886ad187965483b03ab277169a7a354ae4fdf3911fcd770110f2fca767c5e3ebc31830cbe064865d88bb44d4daefd7c6530fc49c8085295a1f62a5f1ebcf75dac4f5f7baf3ce2f265c6d580249feb731f1235&X-Goog-SignedHeaders=host&X-User=2931823730 (Caused by NewConnectionError('<urllib3.connection.HTTPSConnection object at 0x7f6f435d0550>: Failed to establish a new connection: [Errno 101] Network is unreachable'))
2025-04-11 15:24:52,381 ERROR   wandb-upload_3:24989 [internal_api.py:upload_file():2558] upload_file request headers: {'User-Agent': 'python-requests/2.32.3', 'Accept-Encoding': 'gzip, deflate, br', 'Accept': '*/*', 'Connection': 'keep-alive', 'Content-Length': '8281'}
2025-04-11 15:24:52,381 ERROR   wandb-upload_3:24989 [internal_api.py:upload_file():2560] upload_file response body: 
2025-04-11 15:24:52,448 ERROR   wandb-upload_4:24989 [internal_api.py:upload_file():2556] upload_file exception https://storage.googleapis.com/wandb-production.appspot.com/2931823730-harbin-institute-of-technology/ltu-as/k2h266f7/output.log?X-Goog-Algorithm=GOOG4-RSA-SHA256&X-Goog-Credential=gorilla-files-url-signer-man%40wandb-production.iam.gserviceaccount.com%2F20250411%2Fauto%2Fstorage%2Fgoog4_request&X-Goog-Date=20250411T152436Z&X-Goog-Expires=86399&X-Goog-Signature=a218415934127a9773405e8afb2110dac28c657fba4bf7ad82709f7ccf62bc41a6a9c1870e685e9db1affbee0f87c63f4ed0e43699ee398f5f908c84ba86197cad94e679f2747a40046a617e4dc1dd6bfb92e8e2a014d79d6271fac065a6636ff1cf7c4fd172825dcc5a6157baa4c0b45c5cbc1deaf60489dbb4270b941944dccbd3108e420938da346c60b9fdce78528c202dd0a73d5955acfb43955d7de10fe5407f38272c47f352ddd220ca07fb06aa05f1f7f082a06b42a3fb42c5cbd5a10e126312923e2501ab93e890ca9e8067379fbfdb01c0a304864f2fa973a34b0526edae7c710d275d1eed9431006376c89c0ffd0794291f3e192728c29ad49274&X-Goog-SignedHeaders=host&X-User=2931823730: HTTPSConnectionPool(host='storage.googleapis.com', port=443): Max retries exceeded with url: /wandb-production.appspot.com/2931823730-harbin-institute-of-technology/ltu-as/k2h266f7/output.log?X-Goog-Algorithm=GOOG4-RSA-SHA256&X-Goog-Credential=gorilla-files-url-signer-man%40wandb-production.iam.gserviceaccount.com%2F20250411%2Fauto%2Fstorage%2Fgoog4_request&X-Goog-Date=20250411T152436Z&X-Goog-Expires=86399&X-Goog-Signature=a218415934127a9773405e8afb2110dac28c657fba4bf7ad82709f7ccf62bc41a6a9c1870e685e9db1affbee0f87c63f4ed0e43699ee398f5f908c84ba86197cad94e679f2747a40046a617e4dc1dd6bfb92e8e2a014d79d6271fac065a6636ff1cf7c4fd172825dcc5a6157baa4c0b45c5cbc1deaf60489dbb4270b941944dccbd3108e420938da346c60b9fdce78528c202dd0a73d5955acfb43955d7de10fe5407f38272c47f352ddd220ca07fb06aa05f1f7f082a06b42a3fb42c5cbd5a10e126312923e2501ab93e890ca9e8067379fbfdb01c0a304864f2fa973a34b0526edae7c710d275d1eed9431006376c89c0ffd0794291f3e192728c29ad49274&X-Goog-SignedHeaders=host&X-User=2931823730 (Caused by NewConnectionError('<urllib3.connection.HTTPSConnection object at 0x7f6f435d3550>: Failed to establish a new connection: [Errno 101] Network is unreachable'))
2025-04-11 15:24:52,448 ERROR   wandb-upload_4:24989 [internal_api.py:upload_file():2558] upload_file request headers: {'User-Agent': 'python-requests/2.32.3', 'Accept-Encoding': 'gzip, deflate, br', 'Accept': '*/*', 'Connection': 'keep-alive', 'Content-Length': '4566'}
2025-04-11 15:24:52,448 ERROR   wandb-upload_4:24989 [internal_api.py:upload_file():2560] upload_file response body: 
2025-04-11 15:24:52,574 ERROR   wandb-upload_1:24989 [internal_api.py:upload_file():2556] upload_file exception https://storage.googleapis.com/wandb-production.appspot.com/2931823730-harbin-institute-of-technology/ltu-as/k2h266f7/config.yaml?X-Goog-Algorithm=GOOG4-RSA-SHA256&X-Goog-Credential=gorilla-files-url-signer-man%40wandb-production.iam.gserviceaccount.com%2F20250411%2Fauto%2Fstorage%2Fgoog4_request&X-Goog-Date=20250411T152436Z&X-Goog-Expires=86399&X-Goog-Signature=a2bd9fa79d8f7fff9ac0e7c9263d1d19c6df2bf6806a808a78bada2eba939d69029cac8e041fc4f10cfb94a32017362c65f40f77b4e98a602593050d831b31398d5afa352dcb097f0ee80e078e39f3f2091c46e1df073526f3b6fe27d748e0ec91d2dc7a51c4379df843d0c7f77779463189d1ef5c0e80adb4d5e2ed14f0878906a02e8118c71d8d946705fccdfc2503e9c8b09a725e225fc761f9981aa5f980ef1cd60ea69d46c763b37527f65837001084a213bad97d33b669eb765f3813c4674c741cb9bc962b69f30bc5b8f8a957a65f1a0c0ef23eaf27f0ebe43ccc6a5cfb5133ae52514b51b5c807491799f9c99d8f33c5405130373b7d096b117f1448&X-Goog-SignedHeaders=host&X-User=2931823730: HTTPSConnectionPool(host='storage.googleapis.com', port=443): Max retries exceeded with url: /wandb-production.appspot.com/2931823730-harbin-institute-of-technology/ltu-as/k2h266f7/config.yaml?X-Goog-Algorithm=GOOG4-RSA-SHA256&X-Goog-Credential=gorilla-files-url-signer-man%40wandb-production.iam.gserviceaccount.com%2F20250411%2Fauto%2Fstorage%2Fgoog4_request&X-Goog-Date=20250411T152436Z&X-Goog-Expires=86399&X-Goog-Signature=a2bd9fa79d8f7fff9ac0e7c9263d1d19c6df2bf6806a808a78bada2eba939d69029cac8e041fc4f10cfb94a32017362c65f40f77b4e98a602593050d831b31398d5afa352dcb097f0ee80e078e39f3f2091c46e1df073526f3b6fe27d748e0ec91d2dc7a51c4379df843d0c7f77779463189d1ef5c0e80adb4d5e2ed14f0878906a02e8118c71d8d946705fccdfc2503e9c8b09a725e225fc761f9981aa5f980ef1cd60ea69d46c763b37527f65837001084a213bad97d33b669eb765f3813c4674c741cb9bc962b69f30bc5b8f8a957a65f1a0c0ef23eaf27f0ebe43ccc6a5cfb5133ae52514b51b5c807491799f9c99d8f33c5405130373b7d096b117f1448&X-Goog-SignedHeaders=host&X-User=2931823730 (Caused by NewConnectionError('<urllib3.connection.HTTPSConnection object at 0x7f6f435d39a0>: Failed to establish a new connection: [Errno 101] Network is unreachable'))
2025-04-11 15:24:52,574 ERROR   wandb-upload_1:24989 [internal_api.py:upload_file():2558] upload_file request headers: {'User-Agent': 'python-requests/2.32.3', 'Accept-Encoding': 'gzip, deflate, br', 'Accept': '*/*', 'Connection': 'keep-alive', 'Content-Length': '8684'}
2025-04-11 15:24:52,575 ERROR   wandb-upload_1:24989 [internal_api.py:upload_file():2560] upload_file response body: 
2025-04-11 15:24:52,728 DEBUG   HandlerThread:24989 [handler.py:handle_request():146] handle_request: poll_exit
2025-04-11 15:24:52,728 DEBUG   HandlerThread:24989 [handler.py:handle_request():146] handle_request: status_report
2025-04-11 15:24:52,729 DEBUG   SenderThread:24989 [sender.py:send_request():407] send_request: poll_exit
2025-04-11 15:24:52,816 ERROR   wandb-upload_2:24989 [internal_api.py:upload_file():2556] upload_file exception https://storage.googleapis.com/wandb-production.appspot.com/2931823730-harbin-institute-of-technology/ltu-as/k2h266f7/requirements.txt?X-Goog-Algorithm=GOOG4-RSA-SHA256&X-Goog-Credential=gorilla-files-url-signer-man%40wandb-production.iam.gserviceaccount.com%2F20250411%2Fauto%2Fstorage%2Fgoog4_request&X-Goog-Date=20250411T152436Z&X-Goog-Expires=86399&X-Goog-Signature=4a6841c32e79f12bad7f7960d80c3a4defca087c4ba31bd508a9619c23f0b4950a6d4a0f226cc30c34bf8494bd41a909310909b3197103fe0cc1349bdcadb6228660d9a773f72b7beb613e325b71c1dffa163fbc7c39c4201f53af1cbb25ee5cc0b9e09e731beafc678143e692fd480268c65439b3c7b480de3dd6f7c279ed05312555ef86ea1a19ecaeeab786b36a2e5da6414126a6f06c7efda4be419d88955ba2983d3bfe7b794300d27a9592dc4548adf6c5aa9c5a324eec7ef5d607a40bf325ca0a2df0b2ee24a44391f76159361287ec1bbf89c6f8411e01a546b49b999e0b59dda8422f8206bce1ceb1a02e7fbe9603dc7ebf9aa50d821c370c2bc794&X-Goog-SignedHeaders=host&X-User=2931823730: HTTPSConnectionPool(host='storage.googleapis.com', port=443): Max retries exceeded with url: /wandb-production.appspot.com/2931823730-harbin-institute-of-technology/ltu-as/k2h266f7/requirements.txt?X-Goog-Algorithm=GOOG4-RSA-SHA256&X-Goog-Credential=gorilla-files-url-signer-man%40wandb-production.iam.gserviceaccount.com%2F20250411%2Fauto%2Fstorage%2Fgoog4_request&X-Goog-Date=20250411T152436Z&X-Goog-Expires=86399&X-Goog-Signature=4a6841c32e79f12bad7f7960d80c3a4defca087c4ba31bd508a9619c23f0b4950a6d4a0f226cc30c34bf8494bd41a909310909b3197103fe0cc1349bdcadb6228660d9a773f72b7beb613e325b71c1dffa163fbc7c39c4201f53af1cbb25ee5cc0b9e09e731beafc678143e692fd480268c65439b3c7b480de3dd6f7c279ed05312555ef86ea1a19ecaeeab786b36a2e5da6414126a6f06c7efda4be419d88955ba2983d3bfe7b794300d27a9592dc4548adf6c5aa9c5a324eec7ef5d607a40bf325ca0a2df0b2ee24a44391f76159361287ec1bbf89c6f8411e01a546b49b999e0b59dda8422f8206bce1ceb1a02e7fbe9603dc7ebf9aa50d821c370c2bc794&X-Goog-SignedHeaders=host&X-User=2931823730 (Caused by NewConnectionError('<urllib3.connection.HTTPSConnection object at 0x7f6f40c03100>: Failed to establish a new connection: [Errno 101] Network is unreachable'))
2025-04-11 15:24:52,816 ERROR   wandb-upload_2:24989 [internal_api.py:upload_file():2558] upload_file request headers: {'User-Agent': 'python-requests/2.32.3', 'Accept-Encoding': 'gzip, deflate, br', 'Accept': '*/*', 'Connection': 'keep-alive', 'Content-Length': '4212'}
2025-04-11 15:24:52,817 ERROR   wandb-upload_2:24989 [internal_api.py:upload_file():2560] upload_file response body: 
2025-04-11 15:24:52,919 ERROR   wandb-upload_5:24989 [internal_api.py:upload_file():2556] upload_file exception https://storage.googleapis.com/wandb-production.appspot.com/2931823730-harbin-institute-of-technology/ltu-as/k2h266f7/wandb-summary.json?X-Goog-Algorithm=GOOG4-RSA-SHA256&X-Goog-Credential=gorilla-files-url-signer-man%40wandb-production.iam.gserviceaccount.com%2F20250411%2Fauto%2Fstorage%2Fgoog4_request&X-Goog-Date=20250411T152436Z&X-Goog-Expires=86399&X-Goog-Signature=00c243920d22b412664d1162c1e021970b55b5517d3aab32c839c3d9a4226399433bcd764e107c3e966f9f00c18ae14da84d7f5161f9a32e27758e3a5420e90623727c1429f7d9d019322414e3fec0182afbdbd19fc57be827135d7e5fe0e7d4b79f08f580b792211b08ef9a825b1bbc74c67cc8cc40022dffc55ea4410b383f0430b397b2d1bb314cd66c4f0ec1da7ae9565e24ea5913e08d55c8193c8dc84c7c3783e5cded7fe8ccf664daa5bd139021e55f427ec8d75a5b34dafa339af877f635a5e19b92a9f4b107eeefae2a44c443b6f6a6bcfb2e802aa3ea43d5450ebcd299e0e9efbb5f10ecd2652158324710bc8c8ae9086cb6bebbf9c7fddf8d683d&X-Goog-SignedHeaders=host&X-User=2931823730: HTTPSConnectionPool(host='storage.googleapis.com', port=443): Max retries exceeded with url: /wandb-production.appspot.com/2931823730-harbin-institute-of-technology/ltu-as/k2h266f7/wandb-summary.json?X-Goog-Algorithm=GOOG4-RSA-SHA256&X-Goog-Credential=gorilla-files-url-signer-man%40wandb-production.iam.gserviceaccount.com%2F20250411%2Fauto%2Fstorage%2Fgoog4_request&X-Goog-Date=20250411T152436Z&X-Goog-Expires=86399&X-Goog-Signature=00c243920d22b412664d1162c1e021970b55b5517d3aab32c839c3d9a4226399433bcd764e107c3e966f9f00c18ae14da84d7f5161f9a32e27758e3a5420e90623727c1429f7d9d019322414e3fec0182afbdbd19fc57be827135d7e5fe0e7d4b79f08f580b792211b08ef9a825b1bbc74c67cc8cc40022dffc55ea4410b383f0430b397b2d1bb314cd66c4f0ec1da7ae9565e24ea5913e08d55c8193c8dc84c7c3783e5cded7fe8ccf664daa5bd139021e55f427ec8d75a5b34dafa339af877f635a5e19b92a9f4b107eeefae2a44c443b6f6a6bcfb2e802aa3ea43d5450ebcd299e0e9efbb5f10ecd2652158324710bc8c8ae9086cb6bebbf9c7fddf8d683d&X-Goog-SignedHeaders=host&X-User=2931823730 (Caused by NewConnectionError('<urllib3.connection.HTTPSConnection object at 0x7f6f40c01ea0>: Failed to establish a new connection: [Errno 101] Network is unreachable'))
2025-04-11 15:24:52,920 ERROR   wandb-upload_5:24989 [internal_api.py:upload_file():2558] upload_file request headers: {'User-Agent': 'python-requests/2.32.3', 'Accept-Encoding': 'gzip, deflate, br', 'Accept': '*/*', 'Connection': 'keep-alive', 'Content-Length': '27'}
2025-04-11 15:24:52,920 ERROR   wandb-upload_5:24989 [internal_api.py:upload_file():2560] upload_file response body: 
2025-04-11 15:24:53,729 DEBUG   HandlerThread:24989 [handler.py:handle_request():146] handle_request: poll_exit
2025-04-11 15:24:53,730 DEBUG   SenderThread:24989 [sender.py:send_request():407] send_request: poll_exit
2025-04-11 15:24:54,731 DEBUG   HandlerThread:24989 [handler.py:handle_request():146] handle_request: poll_exit
2025-04-11 15:24:54,732 DEBUG   SenderThread:24989 [sender.py:send_request():407] send_request: poll_exit
2025-04-11 15:24:55,732 DEBUG   HandlerThread:24989 [handler.py:handle_request():146] handle_request: poll_exit
2025-04-11 15:24:55,734 DEBUG   SenderThread:24989 [sender.py:send_request():407] send_request: poll_exit
2025-04-11 15:24:56,735 DEBUG   HandlerThread:24989 [handler.py:handle_request():146] handle_request: poll_exit
2025-04-11 15:24:56,736 DEBUG   SenderThread:24989 [sender.py:send_request():407] send_request: poll_exit
2025-04-11 15:24:57,736 DEBUG   HandlerThread:24989 [handler.py:handle_request():146] handle_request: poll_exit
2025-04-11 15:24:57,737 DEBUG   HandlerThread:24989 [handler.py:handle_request():146] handle_request: status_report
2025-04-11 15:24:57,738 DEBUG   SenderThread:24989 [sender.py:send_request():407] send_request: poll_exit
2025-04-11 15:24:58,739 DEBUG   HandlerThread:24989 [handler.py:handle_request():146] handle_request: poll_exit
2025-04-11 15:24:58,740 DEBUG   SenderThread:24989 [sender.py:send_request():407] send_request: poll_exit
2025-04-11 15:24:59,740 DEBUG   HandlerThread:24989 [handler.py:handle_request():146] handle_request: poll_exit
2025-04-11 15:24:59,742 DEBUG   SenderThread:24989 [sender.py:send_request():407] send_request: poll_exit
2025-04-11 15:25:00,743 DEBUG   HandlerThread:24989 [handler.py:handle_request():146] handle_request: poll_exit
2025-04-11 15:25:00,744 DEBUG   SenderThread:24989 [sender.py:send_request():407] send_request: poll_exit
2025-04-11 15:25:01,745 DEBUG   HandlerThread:24989 [handler.py:handle_request():146] handle_request: poll_exit
2025-04-11 15:25:01,746 DEBUG   SenderThread:24989 [sender.py:send_request():407] send_request: poll_exit
2025-04-11 15:25:02,747 DEBUG   HandlerThread:24989 [handler.py:handle_request():146] handle_request: status_report
2025-04-11 15:25:02,748 DEBUG   HandlerThread:24989 [handler.py:handle_request():146] handle_request: poll_exit
2025-04-11 15:25:02,749 DEBUG   SenderThread:24989 [sender.py:send_request():407] send_request: poll_exit
2025-04-11 15:25:03,749 DEBUG   HandlerThread:24989 [handler.py:handle_request():146] handle_request: poll_exit
2025-04-11 15:25:03,750 DEBUG   SenderThread:24989 [sender.py:send_request():407] send_request: poll_exit
2025-04-11 15:25:04,751 DEBUG   HandlerThread:24989 [handler.py:handle_request():146] handle_request: poll_exit
2025-04-11 15:25:04,752 DEBUG   SenderThread:24989 [sender.py:send_request():407] send_request: poll_exit
2025-04-11 15:25:05,453 ERROR   wandb-upload_0:24989 [internal_api.py:upload_file():2556] upload_file exception https://storage.googleapis.com/wandb-production.appspot.com/2931823730-harbin-institute-of-technology/ltu-as/k2h266f7/wandb-metadata.json?X-Goog-Algorithm=GOOG4-RSA-SHA256&X-Goog-Credential=gorilla-files-url-signer-man%40wandb-production.iam.gserviceaccount.com%2F20250411%2Fauto%2Fstorage%2Fgoog4_request&X-Goog-Date=20250411T152429Z&X-Goog-Expires=86399&X-Goog-Signature=6ec798b561c3cb2395a17d429f72d1bb4186851438f563ecf78bf1f9dc2b5bcff133f9ad0475c60bc1ab0d97e844cfdca95eea98e9242d5bf6414f8e893f8c9577b7d4e5ba040eac31d4c1ffe28a810db3a0375ebce266ce826f2d61a7ce843ce3aa0da775b6b1919247a6583dd5f1d0227acd04d455d3cfcb80912a63a7b14bce8e34d6e2781b78339658e7dce006bdbba3224c717bcf1d18f836de545d1e6c16702f349810a661b2a29d0ae54da42347dba9ed341ea4b3f3f4ed023a50b3b3ce4284ac11e6b286f8a5b6d9a51b608bb69c415180e91a2d9daecb65f3eb6a052385bd58ce99a59a48bc6ea91e078394af4f45f97ca37e771309c400847715f7&X-Goog-SignedHeaders=host&X-User=2931823730: HTTPSConnectionPool(host='storage.googleapis.com', port=443): Max retries exceeded with url: /wandb-production.appspot.com/2931823730-harbin-institute-of-technology/ltu-as/k2h266f7/wandb-metadata.json?X-Goog-Algorithm=GOOG4-RSA-SHA256&X-Goog-Credential=gorilla-files-url-signer-man%40wandb-production.iam.gserviceaccount.com%2F20250411%2Fauto%2Fstorage%2Fgoog4_request&X-Goog-Date=20250411T152429Z&X-Goog-Expires=86399&X-Goog-Signature=6ec798b561c3cb2395a17d429f72d1bb4186851438f563ecf78bf1f9dc2b5bcff133f9ad0475c60bc1ab0d97e844cfdca95eea98e9242d5bf6414f8e893f8c9577b7d4e5ba040eac31d4c1ffe28a810db3a0375ebce266ce826f2d61a7ce843ce3aa0da775b6b1919247a6583dd5f1d0227acd04d455d3cfcb80912a63a7b14bce8e34d6e2781b78339658e7dce006bdbba3224c717bcf1d18f836de545d1e6c16702f349810a661b2a29d0ae54da42347dba9ed341ea4b3f3f4ed023a50b3b3ce4284ac11e6b286f8a5b6d9a51b608bb69c415180e91a2d9daecb65f3eb6a052385bd58ce99a59a48bc6ea91e078394af4f45f97ca37e771309c400847715f7&X-Goog-SignedHeaders=host&X-User=2931823730 (Caused by NewConnectionError('<urllib3.connection.HTTPSConnection object at 0x7f6f40c024d0>: Failed to establish a new connection: [Errno 101] Network is unreachable'))
2025-04-11 15:25:05,453 ERROR   wandb-upload_0:24989 [internal_api.py:upload_file():2558] upload_file request headers: {'User-Agent': 'python-requests/2.32.3', 'Accept-Encoding': 'gzip, deflate, br', 'Accept': '*/*', 'Connection': 'keep-alive', 'Content-Length': '2274'}
2025-04-11 15:25:05,453 ERROR   wandb-upload_0:24989 [internal_api.py:upload_file():2560] upload_file response body: 
2025-04-11 15:25:05,752 DEBUG   HandlerThread:24989 [handler.py:handle_request():146] handle_request: poll_exit
2025-04-11 15:25:05,753 DEBUG   SenderThread:24989 [sender.py:send_request():407] send_request: poll_exit
2025-04-11 15:25:06,754 DEBUG   HandlerThread:24989 [handler.py:handle_request():146] handle_request: poll_exit
2025-04-11 15:25:06,756 DEBUG   SenderThread:24989 [sender.py:send_request():407] send_request: poll_exit
2025-04-11 15:25:07,757 DEBUG   HandlerThread:24989 [handler.py:handle_request():146] handle_request: poll_exit
2025-04-11 15:25:07,757 DEBUG   HandlerThread:24989 [handler.py:handle_request():146] handle_request: status_report
2025-04-11 15:25:07,758 DEBUG   SenderThread:24989 [sender.py:send_request():407] send_request: poll_exit
2025-04-11 15:25:08,760 DEBUG   HandlerThread:24989 [handler.py:handle_request():146] handle_request: poll_exit
2025-04-11 15:25:08,760 DEBUG   SenderThread:24989 [sender.py:send_request():407] send_request: poll_exit
2025-04-11 15:25:08,944 ERROR   wandb-upload_1:24989 [internal_api.py:upload_file():2556] upload_file exception https://storage.googleapis.com/wandb-production.appspot.com/2931823730-harbin-institute-of-technology/ltu-as/k2h266f7/config.yaml?X-Goog-Algorithm=GOOG4-RSA-SHA256&X-Goog-Credential=gorilla-files-url-signer-man%40wandb-production.iam.gserviceaccount.com%2F20250411%2Fauto%2Fstorage%2Fgoog4_request&X-Goog-Date=20250411T152436Z&X-Goog-Expires=86399&X-Goog-Signature=a2bd9fa79d8f7fff9ac0e7c9263d1d19c6df2bf6806a808a78bada2eba939d69029cac8e041fc4f10cfb94a32017362c65f40f77b4e98a602593050d831b31398d5afa352dcb097f0ee80e078e39f3f2091c46e1df073526f3b6fe27d748e0ec91d2dc7a51c4379df843d0c7f77779463189d1ef5c0e80adb4d5e2ed14f0878906a02e8118c71d8d946705fccdfc2503e9c8b09a725e225fc761f9981aa5f980ef1cd60ea69d46c763b37527f65837001084a213bad97d33b669eb765f3813c4674c741cb9bc962b69f30bc5b8f8a957a65f1a0c0ef23eaf27f0ebe43ccc6a5cfb5133ae52514b51b5c807491799f9c99d8f33c5405130373b7d096b117f1448&X-Goog-SignedHeaders=host&X-User=2931823730: HTTPSConnectionPool(host='storage.googleapis.com', port=443): Max retries exceeded with url: /wandb-production.appspot.com/2931823730-harbin-institute-of-technology/ltu-as/k2h266f7/config.yaml?X-Goog-Algorithm=GOOG4-RSA-SHA256&X-Goog-Credential=gorilla-files-url-signer-man%40wandb-production.iam.gserviceaccount.com%2F20250411%2Fauto%2Fstorage%2Fgoog4_request&X-Goog-Date=20250411T152436Z&X-Goog-Expires=86399&X-Goog-Signature=a2bd9fa79d8f7fff9ac0e7c9263d1d19c6df2bf6806a808a78bada2eba939d69029cac8e041fc4f10cfb94a32017362c65f40f77b4e98a602593050d831b31398d5afa352dcb097f0ee80e078e39f3f2091c46e1df073526f3b6fe27d748e0ec91d2dc7a51c4379df843d0c7f77779463189d1ef5c0e80adb4d5e2ed14f0878906a02e8118c71d8d946705fccdfc2503e9c8b09a725e225fc761f9981aa5f980ef1cd60ea69d46c763b37527f65837001084a213bad97d33b669eb765f3813c4674c741cb9bc962b69f30bc5b8f8a957a65f1a0c0ef23eaf27f0ebe43ccc6a5cfb5133ae52514b51b5c807491799f9c99d8f33c5405130373b7d096b117f1448&X-Goog-SignedHeaders=host&X-User=2931823730 (Caused by NewConnectionError('<urllib3.connection.HTTPSConnection object at 0x7f6f40c02aa0>: Failed to establish a new connection: [Errno 101] Network is unreachable'))
2025-04-11 15:25:08,944 ERROR   wandb-upload_1:24989 [internal_api.py:upload_file():2558] upload_file request headers: {'User-Agent': 'python-requests/2.32.3', 'Accept-Encoding': 'gzip, deflate, br', 'Accept': '*/*', 'Connection': 'keep-alive', 'Content-Length': '8684'}
2025-04-11 15:25:08,944 ERROR   wandb-upload_1:24989 [internal_api.py:upload_file():2560] upload_file response body: 
2025-04-11 15:25:09,736 ERROR   wandb-upload_3:24989 [internal_api.py:upload_file():2556] upload_file exception https://storage.googleapis.com/wandb-production.appspot.com/2931823730-harbin-institute-of-technology/ltu-as/k2h266f7/conda-environment.yaml?X-Goog-Algorithm=GOOG4-RSA-SHA256&X-Goog-Credential=gorilla-files-url-signer-man%40wandb-production.iam.gserviceaccount.com%2F20250411%2Fauto%2Fstorage%2Fgoog4_request&X-Goog-Date=20250411T152436Z&X-Goog-Expires=86399&X-Goog-Signature=8fbfa3d461267490826dd69292f21407adfcbf793e9fa345a3b7b4018ec226da5c44488fa6adc0f2daccdf584c6af602fab6fe9efea9d71b3bb7df3159a431edec7ab06f7174dd864c90757977e38c4bace544e0edc03cc4e70976fb41c203c5f8596c01f178cb10181c426a2a56f239e6110ab6bf2adc812aa0269b2418a0bd0cd567b788814d1669a6c95582b5b8106d05d998fd6d30997b6e1330b41cc53e3b299f47892fb4e78e24b066306886ad187965483b03ab277169a7a354ae4fdf3911fcd770110f2fca767c5e3ebc31830cbe064865d88bb44d4daefd7c6530fc49c8085295a1f62a5f1ebcf75dac4f5f7baf3ce2f265c6d580249feb731f1235&X-Goog-SignedHeaders=host&X-User=2931823730: HTTPSConnectionPool(host='storage.googleapis.com', port=443): Max retries exceeded with url: /wandb-production.appspot.com/2931823730-harbin-institute-of-technology/ltu-as/k2h266f7/conda-environment.yaml?X-Goog-Algorithm=GOOG4-RSA-SHA256&X-Goog-Credential=gorilla-files-url-signer-man%40wandb-production.iam.gserviceaccount.com%2F20250411%2Fauto%2Fstorage%2Fgoog4_request&X-Goog-Date=20250411T152436Z&X-Goog-Expires=86399&X-Goog-Signature=8fbfa3d461267490826dd69292f21407adfcbf793e9fa345a3b7b4018ec226da5c44488fa6adc0f2daccdf584c6af602fab6fe9efea9d71b3bb7df3159a431edec7ab06f7174dd864c90757977e38c4bace544e0edc03cc4e70976fb41c203c5f8596c01f178cb10181c426a2a56f239e6110ab6bf2adc812aa0269b2418a0bd0cd567b788814d1669a6c95582b5b8106d05d998fd6d30997b6e1330b41cc53e3b299f47892fb4e78e24b066306886ad187965483b03ab277169a7a354ae4fdf3911fcd770110f2fca767c5e3ebc31830cbe064865d88bb44d4daefd7c6530fc49c8085295a1f62a5f1ebcf75dac4f5f7baf3ce2f265c6d580249feb731f1235&X-Goog-SignedHeaders=host&X-User=2931823730 (Caused by NewConnectionError('<urllib3.connection.HTTPSConnection object at 0x7f6f40c03520>: Failed to establish a new connection: [Errno 101] Network is unreachable'))
2025-04-11 15:25:09,737 ERROR   wandb-upload_3:24989 [internal_api.py:upload_file():2558] upload_file request headers: {'User-Agent': 'python-requests/2.32.3', 'Accept-Encoding': 'gzip, deflate, br', 'Accept': '*/*', 'Connection': 'keep-alive', 'Content-Length': '8281'}
2025-04-11 15:25:09,737 ERROR   wandb-upload_3:24989 [internal_api.py:upload_file():2560] upload_file response body: 
2025-04-11 15:25:09,761 DEBUG   HandlerThread:24989 [handler.py:handle_request():146] handle_request: poll_exit
2025-04-11 15:25:09,762 DEBUG   SenderThread:24989 [sender.py:send_request():407] send_request: poll_exit
2025-04-11 15:25:10,764 DEBUG   HandlerThread:24989 [handler.py:handle_request():146] handle_request: poll_exit
2025-04-11 15:25:10,765 DEBUG   SenderThread:24989 [sender.py:send_request():407] send_request: poll_exit
2025-04-11 15:25:10,917 ERROR   wandb-upload_2:24989 [internal_api.py:upload_file():2556] upload_file exception https://storage.googleapis.com/wandb-production.appspot.com/2931823730-harbin-institute-of-technology/ltu-as/k2h266f7/requirements.txt?X-Goog-Algorithm=GOOG4-RSA-SHA256&X-Goog-Credential=gorilla-files-url-signer-man%40wandb-production.iam.gserviceaccount.com%2F20250411%2Fauto%2Fstorage%2Fgoog4_request&X-Goog-Date=20250411T152436Z&X-Goog-Expires=86399&X-Goog-Signature=4a6841c32e79f12bad7f7960d80c3a4defca087c4ba31bd508a9619c23f0b4950a6d4a0f226cc30c34bf8494bd41a909310909b3197103fe0cc1349bdcadb6228660d9a773f72b7beb613e325b71c1dffa163fbc7c39c4201f53af1cbb25ee5cc0b9e09e731beafc678143e692fd480268c65439b3c7b480de3dd6f7c279ed05312555ef86ea1a19ecaeeab786b36a2e5da6414126a6f06c7efda4be419d88955ba2983d3bfe7b794300d27a9592dc4548adf6c5aa9c5a324eec7ef5d607a40bf325ca0a2df0b2ee24a44391f76159361287ec1bbf89c6f8411e01a546b49b999e0b59dda8422f8206bce1ceb1a02e7fbe9603dc7ebf9aa50d821c370c2bc794&X-Goog-SignedHeaders=host&X-User=2931823730: HTTPSConnectionPool(host='storage.googleapis.com', port=443): Max retries exceeded with url: /wandb-production.appspot.com/2931823730-harbin-institute-of-technology/ltu-as/k2h266f7/requirements.txt?X-Goog-Algorithm=GOOG4-RSA-SHA256&X-Goog-Credential=gorilla-files-url-signer-man%40wandb-production.iam.gserviceaccount.com%2F20250411%2Fauto%2Fstorage%2Fgoog4_request&X-Goog-Date=20250411T152436Z&X-Goog-Expires=86399&X-Goog-Signature=4a6841c32e79f12bad7f7960d80c3a4defca087c4ba31bd508a9619c23f0b4950a6d4a0f226cc30c34bf8494bd41a909310909b3197103fe0cc1349bdcadb6228660d9a773f72b7beb613e325b71c1dffa163fbc7c39c4201f53af1cbb25ee5cc0b9e09e731beafc678143e692fd480268c65439b3c7b480de3dd6f7c279ed05312555ef86ea1a19ecaeeab786b36a2e5da6414126a6f06c7efda4be419d88955ba2983d3bfe7b794300d27a9592dc4548adf6c5aa9c5a324eec7ef5d607a40bf325ca0a2df0b2ee24a44391f76159361287ec1bbf89c6f8411e01a546b49b999e0b59dda8422f8206bce1ceb1a02e7fbe9603dc7ebf9aa50d821c370c2bc794&X-Goog-SignedHeaders=host&X-User=2931823730 (Caused by NewConnectionError('<urllib3.connection.HTTPSConnection object at 0x7f6f40c013c0>: Failed to establish a new connection: [Errno 101] Network is unreachable'))
2025-04-11 15:25:10,917 ERROR   wandb-upload_2:24989 [internal_api.py:upload_file():2558] upload_file request headers: {'User-Agent': 'python-requests/2.32.3', 'Accept-Encoding': 'gzip, deflate, br', 'Accept': '*/*', 'Connection': 'keep-alive', 'Content-Length': '4212'}
2025-04-11 15:25:10,917 ERROR   wandb-upload_2:24989 [internal_api.py:upload_file():2560] upload_file response body: 
2025-04-11 15:25:11,184 ERROR   wandb-upload_5:24989 [internal_api.py:upload_file():2556] upload_file exception https://storage.googleapis.com/wandb-production.appspot.com/2931823730-harbin-institute-of-technology/ltu-as/k2h266f7/wandb-summary.json?X-Goog-Algorithm=GOOG4-RSA-SHA256&X-Goog-Credential=gorilla-files-url-signer-man%40wandb-production.iam.gserviceaccount.com%2F20250411%2Fauto%2Fstorage%2Fgoog4_request&X-Goog-Date=20250411T152436Z&X-Goog-Expires=86399&X-Goog-Signature=00c243920d22b412664d1162c1e021970b55b5517d3aab32c839c3d9a4226399433bcd764e107c3e966f9f00c18ae14da84d7f5161f9a32e27758e3a5420e90623727c1429f7d9d019322414e3fec0182afbdbd19fc57be827135d7e5fe0e7d4b79f08f580b792211b08ef9a825b1bbc74c67cc8cc40022dffc55ea4410b383f0430b397b2d1bb314cd66c4f0ec1da7ae9565e24ea5913e08d55c8193c8dc84c7c3783e5cded7fe8ccf664daa5bd139021e55f427ec8d75a5b34dafa339af877f635a5e19b92a9f4b107eeefae2a44c443b6f6a6bcfb2e802aa3ea43d5450ebcd299e0e9efbb5f10ecd2652158324710bc8c8ae9086cb6bebbf9c7fddf8d683d&X-Goog-SignedHeaders=host&X-User=2931823730: HTTPSConnectionPool(host='storage.googleapis.com', port=443): Max retries exceeded with url: /wandb-production.appspot.com/2931823730-harbin-institute-of-technology/ltu-as/k2h266f7/wandb-summary.json?X-Goog-Algorithm=GOOG4-RSA-SHA256&X-Goog-Credential=gorilla-files-url-signer-man%40wandb-production.iam.gserviceaccount.com%2F20250411%2Fauto%2Fstorage%2Fgoog4_request&X-Goog-Date=20250411T152436Z&X-Goog-Expires=86399&X-Goog-Signature=00c243920d22b412664d1162c1e021970b55b5517d3aab32c839c3d9a4226399433bcd764e107c3e966f9f00c18ae14da84d7f5161f9a32e27758e3a5420e90623727c1429f7d9d019322414e3fec0182afbdbd19fc57be827135d7e5fe0e7d4b79f08f580b792211b08ef9a825b1bbc74c67cc8cc40022dffc55ea4410b383f0430b397b2d1bb314cd66c4f0ec1da7ae9565e24ea5913e08d55c8193c8dc84c7c3783e5cded7fe8ccf664daa5bd139021e55f427ec8d75a5b34dafa339af877f635a5e19b92a9f4b107eeefae2a44c443b6f6a6bcfb2e802aa3ea43d5450ebcd299e0e9efbb5f10ecd2652158324710bc8c8ae9086cb6bebbf9c7fddf8d683d&X-Goog-SignedHeaders=host&X-User=2931823730 (Caused by NewConnectionError('<urllib3.connection.HTTPSConnection object at 0x7f6f435d0370>: Failed to establish a new connection: [Errno 101] Network is unreachable'))
2025-04-11 15:25:11,184 ERROR   wandb-upload_5:24989 [internal_api.py:upload_file():2558] upload_file request headers: {'User-Agent': 'python-requests/2.32.3', 'Accept-Encoding': 'gzip, deflate, br', 'Accept': '*/*', 'Connection': 'keep-alive', 'Content-Length': '27'}
2025-04-11 15:25:11,184 ERROR   wandb-upload_5:24989 [internal_api.py:upload_file():2560] upload_file response body: 
2025-04-11 15:25:11,765 DEBUG   HandlerThread:24989 [handler.py:handle_request():146] handle_request: poll_exit
2025-04-11 15:25:11,766 DEBUG   SenderThread:24989 [sender.py:send_request():407] send_request: poll_exit
2025-04-11 15:25:12,193 ERROR   wandb-upload_4:24989 [internal_api.py:upload_file():2556] upload_file exception https://storage.googleapis.com/wandb-production.appspot.com/2931823730-harbin-institute-of-technology/ltu-as/k2h266f7/output.log?X-Goog-Algorithm=GOOG4-RSA-SHA256&X-Goog-Credential=gorilla-files-url-signer-man%40wandb-production.iam.gserviceaccount.com%2F20250411%2Fauto%2Fstorage%2Fgoog4_request&X-Goog-Date=20250411T152436Z&X-Goog-Expires=86399&X-Goog-Signature=a218415934127a9773405e8afb2110dac28c657fba4bf7ad82709f7ccf62bc41a6a9c1870e685e9db1affbee0f87c63f4ed0e43699ee398f5f908c84ba86197cad94e679f2747a40046a617e4dc1dd6bfb92e8e2a014d79d6271fac065a6636ff1cf7c4fd172825dcc5a6157baa4c0b45c5cbc1deaf60489dbb4270b941944dccbd3108e420938da346c60b9fdce78528c202dd0a73d5955acfb43955d7de10fe5407f38272c47f352ddd220ca07fb06aa05f1f7f082a06b42a3fb42c5cbd5a10e126312923e2501ab93e890ca9e8067379fbfdb01c0a304864f2fa973a34b0526edae7c710d275d1eed9431006376c89c0ffd0794291f3e192728c29ad49274&X-Goog-SignedHeaders=host&X-User=2931823730: HTTPSConnectionPool(host='storage.googleapis.com', port=443): Max retries exceeded with url: /wandb-production.appspot.com/2931823730-harbin-institute-of-technology/ltu-as/k2h266f7/output.log?X-Goog-Algorithm=GOOG4-RSA-SHA256&X-Goog-Credential=gorilla-files-url-signer-man%40wandb-production.iam.gserviceaccount.com%2F20250411%2Fauto%2Fstorage%2Fgoog4_request&X-Goog-Date=20250411T152436Z&X-Goog-Expires=86399&X-Goog-Signature=a218415934127a9773405e8afb2110dac28c657fba4bf7ad82709f7ccf62bc41a6a9c1870e685e9db1affbee0f87c63f4ed0e43699ee398f5f908c84ba86197cad94e679f2747a40046a617e4dc1dd6bfb92e8e2a014d79d6271fac065a6636ff1cf7c4fd172825dcc5a6157baa4c0b45c5cbc1deaf60489dbb4270b941944dccbd3108e420938da346c60b9fdce78528c202dd0a73d5955acfb43955d7de10fe5407f38272c47f352ddd220ca07fb06aa05f1f7f082a06b42a3fb42c5cbd5a10e126312923e2501ab93e890ca9e8067379fbfdb01c0a304864f2fa973a34b0526edae7c710d275d1eed9431006376c89c0ffd0794291f3e192728c29ad49274&X-Goog-SignedHeaders=host&X-User=2931823730 (Caused by NewConnectionError('<urllib3.connection.HTTPSConnection object at 0x7f6f435d1750>: Failed to establish a new connection: [Errno 101] Network is unreachable'))
2025-04-11 15:25:12,193 ERROR   wandb-upload_4:24989 [internal_api.py:upload_file():2558] upload_file request headers: {'User-Agent': 'python-requests/2.32.3', 'Accept-Encoding': 'gzip, deflate, br', 'Accept': '*/*', 'Connection': 'keep-alive', 'Content-Length': '4566'}
2025-04-11 15:25:12,193 ERROR   wandb-upload_4:24989 [internal_api.py:upload_file():2560] upload_file response body: 
2025-04-11 15:25:12,767 DEBUG   HandlerThread:24989 [handler.py:handle_request():146] handle_request: status_report
2025-04-11 15:25:12,769 DEBUG   HandlerThread:24989 [handler.py:handle_request():146] handle_request: poll_exit
2025-04-11 15:25:12,770 DEBUG   SenderThread:24989 [sender.py:send_request():407] send_request: poll_exit
2025-04-11 15:25:13,770 DEBUG   HandlerThread:24989 [handler.py:handle_request():146] handle_request: poll_exit
2025-04-11 15:25:13,771 DEBUG   SenderThread:24989 [sender.py:send_request():407] send_request: poll_exit
2025-04-11 15:25:14,772 DEBUG   HandlerThread:24989 [handler.py:handle_request():146] handle_request: poll_exit
2025-04-11 15:25:14,773 DEBUG   SenderThread:24989 [sender.py:send_request():407] send_request: poll_exit
2025-04-11 15:25:15,774 DEBUG   HandlerThread:24989 [handler.py:handle_request():146] handle_request: poll_exit
2025-04-11 15:25:15,775 DEBUG   SenderThread:24989 [sender.py:send_request():407] send_request: poll_exit
2025-04-11 15:25:16,776 DEBUG   HandlerThread:24989 [handler.py:handle_request():146] handle_request: poll_exit
2025-04-11 15:25:16,777 DEBUG   SenderThread:24989 [sender.py:send_request():407] send_request: poll_exit
2025-04-11 15:25:17,777 DEBUG   HandlerThread:24989 [handler.py:handle_request():146] handle_request: poll_exit
2025-04-11 15:25:17,778 DEBUG   HandlerThread:24989 [handler.py:handle_request():146] handle_request: status_report
2025-04-11 15:25:17,779 DEBUG   SenderThread:24989 [sender.py:send_request():407] send_request: poll_exit
2025-04-11 15:25:18,778 DEBUG   HandlerThread:24989 [handler.py:handle_request():146] handle_request: poll_exit
2025-04-11 15:25:18,780 DEBUG   SenderThread:24989 [sender.py:send_request():407] send_request: poll_exit
2025-04-11 15:25:19,780 DEBUG   HandlerThread:24989 [handler.py:handle_request():146] handle_request: poll_exit
2025-04-11 15:25:19,782 DEBUG   SenderThread:24989 [sender.py:send_request():407] send_request: poll_exit
2025-04-11 15:25:20,782 DEBUG   HandlerThread:24989 [handler.py:handle_request():146] handle_request: poll_exit
2025-04-11 15:25:20,783 DEBUG   SenderThread:24989 [sender.py:send_request():407] send_request: poll_exit
2025-04-11 15:25:21,783 DEBUG   HandlerThread:24989 [handler.py:handle_request():146] handle_request: poll_exit
2025-04-11 15:25:21,785 DEBUG   SenderThread:24989 [sender.py:send_request():407] send_request: poll_exit
2025-04-11 15:25:22,786 DEBUG   HandlerThread:24989 [handler.py:handle_request():146] handle_request: status_report
2025-04-11 15:25:22,787 DEBUG   HandlerThread:24989 [handler.py:handle_request():146] handle_request: poll_exit
2025-04-11 15:25:22,788 DEBUG   SenderThread:24989 [sender.py:send_request():407] send_request: poll_exit
2025-04-11 15:25:23,788 DEBUG   HandlerThread:24989 [handler.py:handle_request():146] handle_request: poll_exit
2025-04-11 15:25:23,790 DEBUG   SenderThread:24989 [sender.py:send_request():407] send_request: poll_exit
2025-04-11 15:25:24,791 DEBUG   HandlerThread:24989 [handler.py:handle_request():146] handle_request: poll_exit
2025-04-11 15:25:24,792 DEBUG   SenderThread:24989 [sender.py:send_request():407] send_request: poll_exit
2025-04-11 15:25:25,793 DEBUG   HandlerThread:24989 [handler.py:handle_request():146] handle_request: poll_exit
2025-04-11 15:25:25,794 DEBUG   SenderThread:24989 [sender.py:send_request():407] send_request: poll_exit
2025-04-11 15:25:26,795 DEBUG   HandlerThread:24989 [handler.py:handle_request():146] handle_request: poll_exit
2025-04-11 15:25:26,796 DEBUG   SenderThread:24989 [sender.py:send_request():407] send_request: poll_exit
2025-04-11 15:25:27,796 DEBUG   HandlerThread:24989 [handler.py:handle_request():146] handle_request: poll_exit
2025-04-11 15:25:27,797 DEBUG   SenderThread:24989 [sender.py:send_request():407] send_request: poll_exit
2025-04-11 15:25:27,798 DEBUG   HandlerThread:24989 [handler.py:handle_request():146] handle_request: status_report
2025-04-11 15:25:28,799 DEBUG   HandlerThread:24989 [handler.py:handle_request():146] handle_request: poll_exit
2025-04-11 15:25:28,800 DEBUG   SenderThread:24989 [sender.py:send_request():407] send_request: poll_exit
2025-04-11 15:25:29,800 DEBUG   HandlerThread:24989 [handler.py:handle_request():146] handle_request: poll_exit
2025-04-11 15:25:29,801 DEBUG   SenderThread:24989 [sender.py:send_request():407] send_request: poll_exit
2025-04-11 15:25:30,802 DEBUG   HandlerThread:24989 [handler.py:handle_request():146] handle_request: poll_exit
2025-04-11 15:25:30,803 DEBUG   SenderThread:24989 [sender.py:send_request():407] send_request: poll_exit
2025-04-11 15:25:31,804 DEBUG   HandlerThread:24989 [handler.py:handle_request():146] handle_request: poll_exit
2025-04-11 15:25:31,805 DEBUG   SenderThread:24989 [sender.py:send_request():407] send_request: poll_exit
2025-04-11 15:25:32,806 DEBUG   HandlerThread:24989 [handler.py:handle_request():146] handle_request: poll_exit
2025-04-11 15:25:32,807 DEBUG   HandlerThread:24989 [handler.py:handle_request():146] handle_request: status_report
2025-04-11 15:25:32,808 DEBUG   SenderThread:24989 [sender.py:send_request():407] send_request: poll_exit
2025-04-11 15:25:33,807 DEBUG   HandlerThread:24989 [handler.py:handle_request():146] handle_request: poll_exit
2025-04-11 15:25:33,808 DEBUG   SenderThread:24989 [sender.py:send_request():407] send_request: poll_exit
2025-04-11 15:25:34,809 DEBUG   HandlerThread:24989 [handler.py:handle_request():146] handle_request: poll_exit
2025-04-11 15:25:34,810 DEBUG   SenderThread:24989 [sender.py:send_request():407] send_request: poll_exit
