2025-04-11 13:45:58,985 INFO    StreamThr :5729 [internal.py:wandb_internal():86] W&B internal server running at pid: 5729, started at: 2025-04-11 13:45:58.983477
2025-04-11 13:45:58,990 DEBUG   HandlerThread:5729 [handler.py:handle_request():146] handle_request: status
2025-04-11 13:45:58,990 INFO    WriterThread:5729 [datastore.py:open_for_write():85] open: /root/ltu-main/ltu-main/src/ltu_as/train_scripts/wandb/run-20250411_134558-e1rp2dmj/run-e1rp2dmj.wandb
2025-04-11 13:45:58,992 DEBUG   SenderThread:5729 [sender.py:send():380] send: header
2025-04-11 13:45:58,992 DEBUG   SenderThread:5729 [sender.py:send():380] send: run
2025-04-11 13:45:59,783 DEBUG   HandlerThread:5729 [handler.py:handle_request():146] handle_request: check_version
2025-04-11 13:45:59,855 INFO    SenderThread:5729 [dir_watcher.py:__init__():211] watching files in: /root/ltu-main/ltu-main/src/ltu_as/train_scripts/wandb/run-20250411_134558-e1rp2dmj/files
2025-04-11 13:45:59,856 INFO    SenderThread:5729 [sender.py:_start_run_threads():1122] run started: e1rp2dmj with start time 1744379158.986853
2025-04-11 13:45:59,856 DEBUG   SenderThread:5729 [sender.py:send_request():407] send_request: check_version
2025-04-11 13:46:00,461 DEBUG   HandlerThread:5729 [handler.py:handle_request():146] handle_request: run_start
2025-04-11 13:46:00,508 DEBUG   HandlerThread:5729 [system_info.py:__init__():32] System info init
2025-04-11 13:46:00,508 DEBUG   HandlerThread:5729 [system_info.py:__init__():47] System info init done
2025-04-11 13:46:00,509 INFO    HandlerThread:5729 [system_monitor.py:start():194] Starting system monitor
2025-04-11 13:46:00,509 INFO    SystemMonitor:5729 [system_monitor.py:_start():158] Starting system asset monitoring threads
2025-04-11 13:46:00,509 INFO    HandlerThread:5729 [system_monitor.py:probe():214] Collecting system info
2025-04-11 13:46:00,510 INFO    SystemMonitor:5729 [interfaces.py:start():190] Started cpu monitoring
2025-04-11 13:46:00,511 INFO    SystemMonitor:5729 [interfaces.py:start():190] Started disk monitoring
2025-04-11 13:46:00,519 INFO    SystemMonitor:5729 [interfaces.py:start():190] Started gpu monitoring
2025-04-11 13:46:00,520 DEBUG   HandlerThread:5729 [system_info.py:probe():196] Probing system
2025-04-11 13:46:00,521 INFO    SystemMonitor:5729 [interfaces.py:start():190] Started memory monitoring
2025-04-11 13:46:00,522 DEBUG   HandlerThread:5729 [gitlib.py:_init_repo():53] git repository is invalid
2025-04-11 13:46:00,522 DEBUG   HandlerThread:5729 [system_info.py:probe():244] Probing system done
2025-04-11 13:46:00,522 DEBUG   HandlerThread:5729 [system_monitor.py:probe():223] {'os': 'Linux-4.15.0-213-generic-x86_64-with-glibc2.27', 'python': '3.10.15', 'heartbeatAt': '2025-04-11T13:46:00.520767', 'startedAt': '2025-04-11T13:45:58.867091', 'docker': None, 'cuda': None, 'args': ('--base_model', '../../../pretrained_mdls/ltuas_long_noqa_a6.bin', '--data_path', '/root/ltu-main/ltu-main/openasqa/data/meld_data.json', '--output_dir', '../exp/ltuas_ft_meld/', '--batch_size', '64', '--micro_batch_size', '1', '--num_epochs', '1', '--learning_rate', '2e-4', '--cutoff_len', '100', '--val_set_size', '0', '--lora_r', '8', '--lora_alpha', '16', '--lora_dropout', '0.05', '--lora_target_modules', '[q_proj,v_proj]', '--group_by_length', '--wandb_run_name', '../exp/ltuas_ft_meld/', '--save_steps', '30', '--trainable_params', 'all'), 'state': 'running', 'program': '/root/ltu-main/ltu-main/src/ltu_as/train_scripts/../finetune_low_resource.py', 'codePathLocal': None, 'host': 'ubuntu', 'username': 'root', 'executable': '/root/anaconda3/envs/venv_ltu/bin/python', 'cpu_count': 4, 'cpu_count_logical': 4, 'cpu_freq': {'current': 2294.598, 'min': 0.0, 'max': 0.0}, 'cpu_freq_per_core': [{'current': 2294.598, 'min': 0.0, 'max': 0.0}, {'current': 2294.598, 'min': 0.0, 'max': 0.0}, {'current': 2294.598, 'min': 0.0, 'max': 0.0}, {'current': 2294.598, 'min': 0.0, 'max': 0.0}], 'disk': {'/': {'total': 499.9882621765137, 'used': 333.2399787902832}}, 'gpu': 'NVIDIA A100-PCIE-40GB', 'gpu_count': 1, 'gpu_devices': [{'name': 'NVIDIA A100-PCIE-40GB', 'memory_total': 42949672960}], 'memory': {'total': 19.60204315185547}}
2025-04-11 13:46:00,522 INFO    HandlerThread:5729 [system_monitor.py:probe():224] Finished collecting system info
2025-04-11 13:46:00,522 INFO    HandlerThread:5729 [system_monitor.py:probe():227] Publishing system info
2025-04-11 13:46:00,522 DEBUG   HandlerThread:5729 [system_info.py:_save_pip():52] Saving list of pip packages installed into the current environment
2025-04-11 13:46:00,522 DEBUG   HandlerThread:5729 [system_info.py:_save_pip():68] Saving pip packages done
2025-04-11 13:46:00,523 DEBUG   HandlerThread:5729 [system_info.py:_save_conda():75] Saving list of conda packages installed into the current environment
2025-04-11 13:46:00,538 INFO    SystemMonitor:5729 [interfaces.py:start():190] Started network monitoring
2025-04-11 13:46:00,859 INFO    Thread-12 :5729 [dir_watcher.py:_on_file_created():271] file/dir created: /root/ltu-main/ltu-main/src/ltu_as/train_scripts/wandb/run-20250411_134558-e1rp2dmj/files/requirements.txt
2025-04-11 13:46:00,860 INFO    Thread-12 :5729 [dir_watcher.py:_on_file_created():271] file/dir created: /root/ltu-main/ltu-main/src/ltu_as/train_scripts/wandb/run-20250411_134558-e1rp2dmj/files/conda-environment.yaml
2025-04-11 13:46:18,761 DEBUG   HandlerThread:5729 [system_info.py:_save_conda():87] Saving conda packages done
2025-04-11 13:46:18,761 INFO    HandlerThread:5729 [system_monitor.py:probe():229] Finished publishing system info
2025-04-11 13:46:18,767 DEBUG   HandlerThread:5729 [handler.py:handle_request():146] handle_request: status_report
2025-04-11 13:46:18,767 DEBUG   HandlerThread:5729 [handler.py:handle_request():146] handle_request: keepalive
2025-04-11 13:46:18,767 DEBUG   HandlerThread:5729 [handler.py:handle_request():146] handle_request: status_report
2025-04-11 13:46:18,767 DEBUG   HandlerThread:5729 [handler.py:handle_request():146] handle_request: keepalive
2025-04-11 13:46:18,767 DEBUG   HandlerThread:5729 [handler.py:handle_request():146] handle_request: status_report
2025-04-11 13:46:18,767 DEBUG   HandlerThread:5729 [handler.py:handle_request():146] handle_request: keepalive
2025-04-11 13:46:18,768 DEBUG   SenderThread:5729 [sender.py:send():380] send: files
2025-04-11 13:46:18,768 INFO    SenderThread:5729 [sender.py:_save_file():1378] saving file wandb-metadata.json with policy now
2025-04-11 13:46:18,775 DEBUG   HandlerThread:5729 [handler.py:handle_request():146] handle_request: stop_status
2025-04-11 13:46:18,776 DEBUG   SenderThread:5729 [sender.py:send_request():407] send_request: stop_status
2025-04-11 13:46:18,795 DEBUG   HandlerThread:5729 [handler.py:handle_request():146] handle_request: internal_messages
2025-04-11 13:46:18,862 INFO    Thread-12 :5729 [dir_watcher.py:_on_file_modified():288] file/dir modified: /root/ltu-main/ltu-main/src/ltu_as/train_scripts/wandb/run-20250411_134558-e1rp2dmj/files/conda-environment.yaml
2025-04-11 13:46:18,863 INFO    Thread-12 :5729 [dir_watcher.py:_on_file_created():271] file/dir created: /root/ltu-main/ltu-main/src/ltu_as/train_scripts/wandb/run-20250411_134558-e1rp2dmj/files/wandb-metadata.json
2025-04-11 13:46:19,228 DEBUG   SenderThread:5729 [sender.py:send():380] send: telemetry
2025-04-11 13:46:19,228 DEBUG   SenderThread:5729 [sender.py:send():380] send: config
2025-04-11 13:46:19,230 DEBUG   SenderThread:5729 [sender.py:send():380] send: metric
2025-04-11 13:46:19,230 DEBUG   SenderThread:5729 [sender.py:send():380] send: telemetry
2025-04-11 13:46:19,230 DEBUG   SenderThread:5729 [sender.py:send():380] send: metric
2025-04-11 13:46:19,230 WARNING SenderThread:5729 [sender.py:send_metric():1329] Seen metric with glob (shouldn't happen)
2025-04-11 13:46:19,288 ERROR   wandb-upload_0:5729 [internal_api.py:upload_file():2556] upload_file exception https://storage.googleapis.com/wandb-production.appspot.com/2931823730-harbin-institute-of-technology/ltu-as/e1rp2dmj/wandb-metadata.json?X-Goog-Algorithm=GOOG4-RSA-SHA256&X-Goog-Credential=gorilla-files-url-signer-man%40wandb-production.iam.gserviceaccount.com%2F20250411%2Fauto%2Fstorage%2Fgoog4_request&X-Goog-Date=20250411T134619Z&X-Goog-Expires=86399&X-Goog-Signature=af0857f67295574884cf2db9abaaccdaaa96b9ef6a6a5bf495355e0bb2cca3709042f1692f52e7c08335e841d771aa914c48aa2d4228797d3d3e27acc636f79795f401e523ff4840008fc280c934439fd7c669288912ffab1d06e6ea6d7178eef4a61385fb1b24d3b9ac99da5340314e08ce8c06f8ab6fc2b7722cd8b0bc6a8f980aa88ef5ab732b624d921cbc59f22107f1b87637d0b0d91a19dde3c63e2ec50bc1158b56888eaa60741932e5fe7f1c0a48b3a5054cb708ce8ca292f7be8005701d9db2893045106437f669bf301dc965b7f38a319f96b5ca65834a568cba009c6f0e70bec1637f97f4c2ffddca24309dbe47014f789317908c2e7990427d8d&X-Goog-SignedHeaders=host&X-User=2931823730: HTTPSConnectionPool(host='storage.googleapis.com', port=443): Max retries exceeded with url: /wandb-production.appspot.com/2931823730-harbin-institute-of-technology/ltu-as/e1rp2dmj/wandb-metadata.json?X-Goog-Algorithm=GOOG4-RSA-SHA256&X-Goog-Credential=gorilla-files-url-signer-man%40wandb-production.iam.gserviceaccount.com%2F20250411%2Fauto%2Fstorage%2Fgoog4_request&X-Goog-Date=20250411T134619Z&X-Goog-Expires=86399&X-Goog-Signature=af0857f67295574884cf2db9abaaccdaaa96b9ef6a6a5bf495355e0bb2cca3709042f1692f52e7c08335e841d771aa914c48aa2d4228797d3d3e27acc636f79795f401e523ff4840008fc280c934439fd7c669288912ffab1d06e6ea6d7178eef4a61385fb1b24d3b9ac99da5340314e08ce8c06f8ab6fc2b7722cd8b0bc6a8f980aa88ef5ab732b624d921cbc59f22107f1b87637d0b0d91a19dde3c63e2ec50bc1158b56888eaa60741932e5fe7f1c0a48b3a5054cb708ce8ca292f7be8005701d9db2893045106437f669bf301dc965b7f38a319f96b5ca65834a568cba009c6f0e70bec1637f97f4c2ffddca24309dbe47014f789317908c2e7990427d8d&X-Goog-SignedHeaders=host&X-User=2931823730 (Caused by NewConnectionError('<urllib3.connection.HTTPSConnection object at 0x7f78a9fc89d0>: Failed to establish a new connection: [Errno 101] Network is unreachable'))
2025-04-11 13:46:19,288 ERROR   wandb-upload_0:5729 [internal_api.py:upload_file():2558] upload_file request headers: {'User-Agent': 'python-requests/2.32.3', 'Accept-Encoding': 'gzip, deflate, br', 'Accept': '*/*', 'Connection': 'keep-alive', 'Content-Length': '2257'}
2025-04-11 13:46:19,288 ERROR   wandb-upload_0:5729 [internal_api.py:upload_file():2560] upload_file response body: 
2025-04-11 13:46:19,863 INFO    Thread-12 :5729 [dir_watcher.py:_on_file_created():271] file/dir created: /root/ltu-main/ltu-main/src/ltu_as/train_scripts/wandb/run-20250411_134558-e1rp2dmj/files/output.log
2025-04-11 13:46:20,232 DEBUG   HandlerThread:5729 [handler.py:handle_request():146] handle_request: status_report
2025-04-11 13:46:20,336 ERROR   wandb-upload_0:5729 [internal_api.py:upload_file():2556] upload_file exception https://storage.googleapis.com/wandb-production.appspot.com/2931823730-harbin-institute-of-technology/ltu-as/e1rp2dmj/wandb-metadata.json?X-Goog-Algorithm=GOOG4-RSA-SHA256&X-Goog-Credential=gorilla-files-url-signer-man%40wandb-production.iam.gserviceaccount.com%2F20250411%2Fauto%2Fstorage%2Fgoog4_request&X-Goog-Date=20250411T134619Z&X-Goog-Expires=86399&X-Goog-Signature=af0857f67295574884cf2db9abaaccdaaa96b9ef6a6a5bf495355e0bb2cca3709042f1692f52e7c08335e841d771aa914c48aa2d4228797d3d3e27acc636f79795f401e523ff4840008fc280c934439fd7c669288912ffab1d06e6ea6d7178eef4a61385fb1b24d3b9ac99da5340314e08ce8c06f8ab6fc2b7722cd8b0bc6a8f980aa88ef5ab732b624d921cbc59f22107f1b87637d0b0d91a19dde3c63e2ec50bc1158b56888eaa60741932e5fe7f1c0a48b3a5054cb708ce8ca292f7be8005701d9db2893045106437f669bf301dc965b7f38a319f96b5ca65834a568cba009c6f0e70bec1637f97f4c2ffddca24309dbe47014f789317908c2e7990427d8d&X-Goog-SignedHeaders=host&X-User=2931823730: HTTPSConnectionPool(host='storage.googleapis.com', port=443): Max retries exceeded with url: /wandb-production.appspot.com/2931823730-harbin-institute-of-technology/ltu-as/e1rp2dmj/wandb-metadata.json?X-Goog-Algorithm=GOOG4-RSA-SHA256&X-Goog-Credential=gorilla-files-url-signer-man%40wandb-production.iam.gserviceaccount.com%2F20250411%2Fauto%2Fstorage%2Fgoog4_request&X-Goog-Date=20250411T134619Z&X-Goog-Expires=86399&X-Goog-Signature=af0857f67295574884cf2db9abaaccdaaa96b9ef6a6a5bf495355e0bb2cca3709042f1692f52e7c08335e841d771aa914c48aa2d4228797d3d3e27acc636f79795f401e523ff4840008fc280c934439fd7c669288912ffab1d06e6ea6d7178eef4a61385fb1b24d3b9ac99da5340314e08ce8c06f8ab6fc2b7722cd8b0bc6a8f980aa88ef5ab732b624d921cbc59f22107f1b87637d0b0d91a19dde3c63e2ec50bc1158b56888eaa60741932e5fe7f1c0a48b3a5054cb708ce8ca292f7be8005701d9db2893045106437f669bf301dc965b7f38a319f96b5ca65834a568cba009c6f0e70bec1637f97f4c2ffddca24309dbe47014f789317908c2e7990427d8d&X-Goog-SignedHeaders=host&X-User=2931823730 (Caused by NewConnectionError('<urllib3.connection.HTTPSConnection object at 0x7f78a9fca020>: Failed to establish a new connection: [Errno 101] Network is unreachable'))
2025-04-11 13:46:20,336 ERROR   wandb-upload_0:5729 [internal_api.py:upload_file():2558] upload_file request headers: {'User-Agent': 'python-requests/2.32.3', 'Accept-Encoding': 'gzip, deflate, br', 'Accept': '*/*', 'Connection': 'keep-alive', 'Content-Length': '2257'}
2025-04-11 13:46:20,336 ERROR   wandb-upload_0:5729 [internal_api.py:upload_file():2560] upload_file response body: 
2025-04-11 13:46:21,864 INFO    Thread-12 :5729 [dir_watcher.py:_on_file_modified():288] file/dir modified: /root/ltu-main/ltu-main/src/ltu_as/train_scripts/wandb/run-20250411_134558-e1rp2dmj/files/output.log
2025-04-11 13:46:22,456 ERROR   wandb-upload_0:5729 [internal_api.py:upload_file():2556] upload_file exception https://storage.googleapis.com/wandb-production.appspot.com/2931823730-harbin-institute-of-technology/ltu-as/e1rp2dmj/wandb-metadata.json?X-Goog-Algorithm=GOOG4-RSA-SHA256&X-Goog-Credential=gorilla-files-url-signer-man%40wandb-production.iam.gserviceaccount.com%2F20250411%2Fauto%2Fstorage%2Fgoog4_request&X-Goog-Date=20250411T134619Z&X-Goog-Expires=86399&X-Goog-Signature=af0857f67295574884cf2db9abaaccdaaa96b9ef6a6a5bf495355e0bb2cca3709042f1692f52e7c08335e841d771aa914c48aa2d4228797d3d3e27acc636f79795f401e523ff4840008fc280c934439fd7c669288912ffab1d06e6ea6d7178eef4a61385fb1b24d3b9ac99da5340314e08ce8c06f8ab6fc2b7722cd8b0bc6a8f980aa88ef5ab732b624d921cbc59f22107f1b87637d0b0d91a19dde3c63e2ec50bc1158b56888eaa60741932e5fe7f1c0a48b3a5054cb708ce8ca292f7be8005701d9db2893045106437f669bf301dc965b7f38a319f96b5ca65834a568cba009c6f0e70bec1637f97f4c2ffddca24309dbe47014f789317908c2e7990427d8d&X-Goog-SignedHeaders=host&X-User=2931823730: HTTPSConnectionPool(host='storage.googleapis.com', port=443): Max retries exceeded with url: /wandb-production.appspot.com/2931823730-harbin-institute-of-technology/ltu-as/e1rp2dmj/wandb-metadata.json?X-Goog-Algorithm=GOOG4-RSA-SHA256&X-Goog-Credential=gorilla-files-url-signer-man%40wandb-production.iam.gserviceaccount.com%2F20250411%2Fauto%2Fstorage%2Fgoog4_request&X-Goog-Date=20250411T134619Z&X-Goog-Expires=86399&X-Goog-Signature=af0857f67295574884cf2db9abaaccdaaa96b9ef6a6a5bf495355e0bb2cca3709042f1692f52e7c08335e841d771aa914c48aa2d4228797d3d3e27acc636f79795f401e523ff4840008fc280c934439fd7c669288912ffab1d06e6ea6d7178eef4a61385fb1b24d3b9ac99da5340314e08ce8c06f8ab6fc2b7722cd8b0bc6a8f980aa88ef5ab732b624d921cbc59f22107f1b87637d0b0d91a19dde3c63e2ec50bc1158b56888eaa60741932e5fe7f1c0a48b3a5054cb708ce8ca292f7be8005701d9db2893045106437f669bf301dc965b7f38a319f96b5ca65834a568cba009c6f0e70bec1637f97f4c2ffddca24309dbe47014f789317908c2e7990427d8d&X-Goog-SignedHeaders=host&X-User=2931823730 (Caused by NewConnectionError('<urllib3.connection.HTTPSConnection object at 0x7f78a9fc9e10>: Failed to establish a new connection: [Errno 101] Network is unreachable'))
2025-04-11 13:46:22,457 ERROR   wandb-upload_0:5729 [internal_api.py:upload_file():2558] upload_file request headers: {'User-Agent': 'python-requests/2.32.3', 'Accept-Encoding': 'gzip, deflate, br', 'Accept': '*/*', 'Connection': 'keep-alive', 'Content-Length': '2257'}
2025-04-11 13:46:22,457 ERROR   wandb-upload_0:5729 [internal_api.py:upload_file():2560] upload_file response body: 
2025-04-11 13:46:22,457 INFO    wandb-upload_0:5729 [retry.py:__call__():172] Retry attempt failed:
Traceback (most recent call last):
  File "/root/anaconda3/envs/venv_ltu/lib/python3.10/site-packages/urllib3/connection.py", line 198, in _new_conn
    sock = connection.create_connection(
  File "/root/anaconda3/envs/venv_ltu/lib/python3.10/site-packages/urllib3/util/connection.py", line 85, in create_connection
    raise err
  File "/root/anaconda3/envs/venv_ltu/lib/python3.10/site-packages/urllib3/util/connection.py", line 73, in create_connection
    sock.connect(sa)
OSError: [Errno 101] Network is unreachable

The above exception was the direct cause of the following exception:

Traceback (most recent call last):
  File "/root/anaconda3/envs/venv_ltu/lib/python3.10/site-packages/urllib3/connectionpool.py", line 793, in urlopen
    response = self._make_request(
  File "/root/anaconda3/envs/venv_ltu/lib/python3.10/site-packages/urllib3/connectionpool.py", line 491, in _make_request
    raise new_e
  File "/root/anaconda3/envs/venv_ltu/lib/python3.10/site-packages/urllib3/connectionpool.py", line 467, in _make_request
    self._validate_conn(conn)
  File "/root/anaconda3/envs/venv_ltu/lib/python3.10/site-packages/urllib3/connectionpool.py", line 1099, in _validate_conn
    conn.connect()
  File "/root/anaconda3/envs/venv_ltu/lib/python3.10/site-packages/urllib3/connection.py", line 616, in connect
    self.sock = sock = self._new_conn()
  File "/root/anaconda3/envs/venv_ltu/lib/python3.10/site-packages/urllib3/connection.py", line 213, in _new_conn
    raise NewConnectionError(
urllib3.exceptions.NewConnectionError: <urllib3.connection.HTTPSConnection object at 0x7f78a9fc9e10>: Failed to establish a new connection: [Errno 101] Network is unreachable

The above exception was the direct cause of the following exception:

Traceback (most recent call last):
  File "/root/anaconda3/envs/venv_ltu/lib/python3.10/site-packages/requests/adapters.py", line 667, in send
    resp = conn.urlopen(
  File "/root/anaconda3/envs/venv_ltu/lib/python3.10/site-packages/urllib3/connectionpool.py", line 847, in urlopen
    retries = retries.increment(
  File "/root/anaconda3/envs/venv_ltu/lib/python3.10/site-packages/urllib3/util/retry.py", line 515, in increment
    raise MaxRetryError(_pool, url, reason) from reason  # type: ignore[arg-type]
urllib3.exceptions.MaxRetryError: HTTPSConnectionPool(host='storage.googleapis.com', port=443): Max retries exceeded with url: /wandb-production.appspot.com/2931823730-harbin-institute-of-technology/ltu-as/e1rp2dmj/wandb-metadata.json?X-Goog-Algorithm=GOOG4-RSA-SHA256&X-Goog-Credential=gorilla-files-url-signer-man%40wandb-production.iam.gserviceaccount.com%2F20250411%2Fauto%2Fstorage%2Fgoog4_request&X-Goog-Date=20250411T134619Z&X-Goog-Expires=86399&X-Goog-Signature=af0857f67295574884cf2db9abaaccdaaa96b9ef6a6a5bf495355e0bb2cca3709042f1692f52e7c08335e841d771aa914c48aa2d4228797d3d3e27acc636f79795f401e523ff4840008fc280c934439fd7c669288912ffab1d06e6ea6d7178eef4a61385fb1b24d3b9ac99da5340314e08ce8c06f8ab6fc2b7722cd8b0bc6a8f980aa88ef5ab732b624d921cbc59f22107f1b87637d0b0d91a19dde3c63e2ec50bc1158b56888eaa60741932e5fe7f1c0a48b3a5054cb708ce8ca292f7be8005701d9db2893045106437f669bf301dc965b7f38a319f96b5ca65834a568cba009c6f0e70bec1637f97f4c2ffddca24309dbe47014f789317908c2e7990427d8d&X-Goog-SignedHeaders=host&X-User=2931823730 (Caused by NewConnectionError('<urllib3.connection.HTTPSConnection object at 0x7f78a9fc9e10>: Failed to establish a new connection: [Errno 101] Network is unreachable'))

During handling of the above exception, another exception occurred:

Traceback (most recent call last):
  File "/root/anaconda3/envs/venv_ltu/lib/python3.10/site-packages/wandb/sdk/internal/internal_api.py", line 2549, in upload_file
    response = self._upload_file_session.put(
  File "/root/anaconda3/envs/venv_ltu/lib/python3.10/site-packages/requests/sessions.py", line 649, in put
    return self.request("PUT", url, data=data, **kwargs)
  File "/root/anaconda3/envs/venv_ltu/lib/python3.10/site-packages/requests/sessions.py", line 589, in request
    resp = self.send(prep, **send_kwargs)
  File "/root/anaconda3/envs/venv_ltu/lib/python3.10/site-packages/requests/sessions.py", line 703, in send
    r = adapter.send(request, **kwargs)
  File "/root/anaconda3/envs/venv_ltu/lib/python3.10/site-packages/requests/adapters.py", line 700, in send
    raise ConnectionError(e, request=request)
requests.exceptions.ConnectionError: HTTPSConnectionPool(host='storage.googleapis.com', port=443): Max retries exceeded with url: /wandb-production.appspot.com/2931823730-harbin-institute-of-technology/ltu-as/e1rp2dmj/wandb-metadata.json?X-Goog-Algorithm=GOOG4-RSA-SHA256&X-Goog-Credential=gorilla-files-url-signer-man%40wandb-production.iam.gserviceaccount.com%2F20250411%2Fauto%2Fstorage%2Fgoog4_request&X-Goog-Date=20250411T134619Z&X-Goog-Expires=86399&X-Goog-Signature=af0857f67295574884cf2db9abaaccdaaa96b9ef6a6a5bf495355e0bb2cca3709042f1692f52e7c08335e841d771aa914c48aa2d4228797d3d3e27acc636f79795f401e523ff4840008fc280c934439fd7c669288912ffab1d06e6ea6d7178eef4a61385fb1b24d3b9ac99da5340314e08ce8c06f8ab6fc2b7722cd8b0bc6a8f980aa88ef5ab732b624d921cbc59f22107f1b87637d0b0d91a19dde3c63e2ec50bc1158b56888eaa60741932e5fe7f1c0a48b3a5054cb708ce8ca292f7be8005701d9db2893045106437f669bf301dc965b7f38a319f96b5ca65834a568cba009c6f0e70bec1637f97f4c2ffddca24309dbe47014f789317908c2e7990427d8d&X-Goog-SignedHeaders=host&X-User=2931823730 (Caused by NewConnectionError('<urllib3.connection.HTTPSConnection object at 0x7f78a9fc9e10>: Failed to establish a new connection: [Errno 101] Network is unreachable'))

During handling of the above exception, another exception occurred:

Traceback (most recent call last):
  File "/root/anaconda3/envs/venv_ltu/lib/python3.10/site-packages/wandb/sdk/lib/retry.py", line 131, in __call__
    result = self._call_fn(*args, **kwargs)
  File "/root/anaconda3/envs/venv_ltu/lib/python3.10/site-packages/wandb/sdk/internal/internal_api.py", line 2580, in upload_file
    raise _e.with_traceback(sys.exc_info()[2])
  File "/root/anaconda3/envs/venv_ltu/lib/python3.10/site-packages/wandb/sdk/internal/internal_api.py", line 2549, in upload_file
    response = self._upload_file_session.put(
  File "/root/anaconda3/envs/venv_ltu/lib/python3.10/site-packages/requests/sessions.py", line 649, in put
    return self.request("PUT", url, data=data, **kwargs)
  File "/root/anaconda3/envs/venv_ltu/lib/python3.10/site-packages/requests/sessions.py", line 589, in request
    resp = self.send(prep, **send_kwargs)
  File "/root/anaconda3/envs/venv_ltu/lib/python3.10/site-packages/requests/sessions.py", line 703, in send
    r = adapter.send(request, **kwargs)
  File "/root/anaconda3/envs/venv_ltu/lib/python3.10/site-packages/requests/adapters.py", line 700, in send
    raise ConnectionError(e, request=request)
wandb.sdk.lib.retry.TransientError: None
2025-04-11 13:46:25,237 DEBUG   HandlerThread:5729 [handler.py:handle_request():146] handle_request: status_report
2025-04-11 13:46:27,503 ERROR   wandb-upload_0:5729 [internal_api.py:upload_file():2556] upload_file exception https://storage.googleapis.com/wandb-production.appspot.com/2931823730-harbin-institute-of-technology/ltu-as/e1rp2dmj/wandb-metadata.json?X-Goog-Algorithm=GOOG4-RSA-SHA256&X-Goog-Credential=gorilla-files-url-signer-man%40wandb-production.iam.gserviceaccount.com%2F20250411%2Fauto%2Fstorage%2Fgoog4_request&X-Goog-Date=20250411T134619Z&X-Goog-Expires=86399&X-Goog-Signature=af0857f67295574884cf2db9abaaccdaaa96b9ef6a6a5bf495355e0bb2cca3709042f1692f52e7c08335e841d771aa914c48aa2d4228797d3d3e27acc636f79795f401e523ff4840008fc280c934439fd7c669288912ffab1d06e6ea6d7178eef4a61385fb1b24d3b9ac99da5340314e08ce8c06f8ab6fc2b7722cd8b0bc6a8f980aa88ef5ab732b624d921cbc59f22107f1b87637d0b0d91a19dde3c63e2ec50bc1158b56888eaa60741932e5fe7f1c0a48b3a5054cb708ce8ca292f7be8005701d9db2893045106437f669bf301dc965b7f38a319f96b5ca65834a568cba009c6f0e70bec1637f97f4c2ffddca24309dbe47014f789317908c2e7990427d8d&X-Goog-SignedHeaders=host&X-User=2931823730: HTTPSConnectionPool(host='storage.googleapis.com', port=443): Max retries exceeded with url: /wandb-production.appspot.com/2931823730-harbin-institute-of-technology/ltu-as/e1rp2dmj/wandb-metadata.json?X-Goog-Algorithm=GOOG4-RSA-SHA256&X-Goog-Credential=gorilla-files-url-signer-man%40wandb-production.iam.gserviceaccount.com%2F20250411%2Fauto%2Fstorage%2Fgoog4_request&X-Goog-Date=20250411T134619Z&X-Goog-Expires=86399&X-Goog-Signature=af0857f67295574884cf2db9abaaccdaaa96b9ef6a6a5bf495355e0bb2cca3709042f1692f52e7c08335e841d771aa914c48aa2d4228797d3d3e27acc636f79795f401e523ff4840008fc280c934439fd7c669288912ffab1d06e6ea6d7178eef4a61385fb1b24d3b9ac99da5340314e08ce8c06f8ab6fc2b7722cd8b0bc6a8f980aa88ef5ab732b624d921cbc59f22107f1b87637d0b0d91a19dde3c63e2ec50bc1158b56888eaa60741932e5fe7f1c0a48b3a5054cb708ce8ca292f7be8005701d9db2893045106437f669bf301dc965b7f38a319f96b5ca65834a568cba009c6f0e70bec1637f97f4c2ffddca24309dbe47014f789317908c2e7990427d8d&X-Goog-SignedHeaders=host&X-User=2931823730 (Caused by NewConnectionError('<urllib3.connection.HTTPSConnection object at 0x7f78a9fc82b0>: Failed to establish a new connection: [Errno 101] Network is unreachable'))
2025-04-11 13:46:27,503 ERROR   wandb-upload_0:5729 [internal_api.py:upload_file():2558] upload_file request headers: {'User-Agent': 'python-requests/2.32.3', 'Accept-Encoding': 'gzip, deflate, br', 'Accept': '*/*', 'Connection': 'keep-alive', 'Content-Length': '2257'}
2025-04-11 13:46:27,503 ERROR   wandb-upload_0:5729 [internal_api.py:upload_file():2560] upload_file response body: 
2025-04-11 13:46:30,243 DEBUG   HandlerThread:5729 [handler.py:handle_request():146] handle_request: status_report
2025-04-11 13:46:31,201 DEBUG   SenderThread:5729 [sender.py:send():380] send: exit
2025-04-11 13:46:31,202 INFO    SenderThread:5729 [sender.py:send_exit():585] handling exit code: 1
2025-04-11 13:46:31,202 INFO    SenderThread:5729 [sender.py:send_exit():587] handling runtime: 30
2025-04-11 13:46:31,202 INFO    SenderThread:5729 [sender.py:_save_file():1378] saving file wandb-summary.json with policy end
2025-04-11 13:46:31,202 INFO    SenderThread:5729 [sender.py:send_exit():593] send defer
2025-04-11 13:46:31,203 DEBUG   HandlerThread:5729 [handler.py:handle_request():146] handle_request: defer
2025-04-11 13:46:31,203 INFO    HandlerThread:5729 [handler.py:handle_request_defer():172] handle defer: 0
2025-04-11 13:46:31,204 DEBUG   SenderThread:5729 [sender.py:send_request():407] send_request: defer
2025-04-11 13:46:31,204 INFO    SenderThread:5729 [sender.py:send_request_defer():609] handle sender defer: 0
2025-04-11 13:46:31,204 INFO    SenderThread:5729 [sender.py:transition_state():613] send defer: 1
2025-04-11 13:46:31,204 DEBUG   HandlerThread:5729 [handler.py:handle_request():146] handle_request: defer
2025-04-11 13:46:31,204 INFO    HandlerThread:5729 [handler.py:handle_request_defer():172] handle defer: 1
2025-04-11 13:46:31,204 DEBUG   SenderThread:5729 [sender.py:send_request():407] send_request: defer
2025-04-11 13:46:31,204 INFO    SenderThread:5729 [sender.py:send_request_defer():609] handle sender defer: 1
2025-04-11 13:46:31,204 INFO    SenderThread:5729 [sender.py:transition_state():613] send defer: 2
2025-04-11 13:46:31,204 DEBUG   HandlerThread:5729 [handler.py:handle_request():146] handle_request: defer
2025-04-11 13:46:31,204 INFO    HandlerThread:5729 [handler.py:handle_request_defer():172] handle defer: 2
2025-04-11 13:46:31,204 INFO    HandlerThread:5729 [system_monitor.py:finish():203] Stopping system monitor
2025-04-11 13:46:31,204 DEBUG   SystemMonitor:5729 [system_monitor.py:_start():172] Starting system metrics aggregation loop
2025-04-11 13:46:31,205 INFO    HandlerThread:5729 [interfaces.py:finish():202] Joined cpu monitor
2025-04-11 13:46:31,205 DEBUG   SystemMonitor:5729 [system_monitor.py:_start():179] Finished system metrics aggregation loop
2025-04-11 13:46:31,205 INFO    HandlerThread:5729 [interfaces.py:finish():202] Joined disk monitor
2025-04-11 13:46:31,205 DEBUG   SystemMonitor:5729 [system_monitor.py:_start():183] Publishing last batch of metrics
2025-04-11 13:46:31,223 INFO    HandlerThread:5729 [interfaces.py:finish():202] Joined gpu monitor
2025-04-11 13:46:31,223 INFO    HandlerThread:5729 [interfaces.py:finish():202] Joined memory monitor
2025-04-11 13:46:31,224 INFO    HandlerThread:5729 [interfaces.py:finish():202] Joined network monitor
2025-04-11 13:46:31,224 DEBUG   SenderThread:5729 [sender.py:send_request():407] send_request: defer
2025-04-11 13:46:31,224 INFO    SenderThread:5729 [sender.py:send_request_defer():609] handle sender defer: 2
2025-04-11 13:46:31,225 INFO    SenderThread:5729 [sender.py:transition_state():613] send defer: 3
2025-04-11 13:46:31,225 DEBUG   SenderThread:5729 [sender.py:send():380] send: stats
2025-04-11 13:46:31,225 DEBUG   HandlerThread:5729 [handler.py:handle_request():146] handle_request: defer
2025-04-11 13:46:31,226 INFO    HandlerThread:5729 [handler.py:handle_request_defer():172] handle defer: 3
2025-04-11 13:46:31,226 DEBUG   SenderThread:5729 [sender.py:send_request():407] send_request: defer
2025-04-11 13:46:31,226 INFO    SenderThread:5729 [sender.py:send_request_defer():609] handle sender defer: 3
2025-04-11 13:46:31,226 INFO    SenderThread:5729 [sender.py:transition_state():613] send defer: 4
2025-04-11 13:46:31,226 DEBUG   HandlerThread:5729 [handler.py:handle_request():146] handle_request: defer
2025-04-11 13:46:31,226 INFO    HandlerThread:5729 [handler.py:handle_request_defer():172] handle defer: 4
2025-04-11 13:46:31,227 DEBUG   SenderThread:5729 [sender.py:send_request():407] send_request: defer
2025-04-11 13:46:31,227 INFO    SenderThread:5729 [sender.py:send_request_defer():609] handle sender defer: 4
2025-04-11 13:46:31,227 INFO    SenderThread:5729 [sender.py:transition_state():613] send defer: 5
2025-04-11 13:46:31,227 DEBUG   HandlerThread:5729 [handler.py:handle_request():146] handle_request: defer
2025-04-11 13:46:31,227 INFO    HandlerThread:5729 [handler.py:handle_request_defer():172] handle defer: 5
2025-04-11 13:46:31,227 DEBUG   SenderThread:5729 [sender.py:send():380] send: summary
2025-04-11 13:46:31,230 INFO    SenderThread:5729 [sender.py:_save_file():1378] saving file wandb-summary.json with policy end
2025-04-11 13:46:31,230 DEBUG   SenderThread:5729 [sender.py:send_request():407] send_request: defer
2025-04-11 13:46:31,230 INFO    SenderThread:5729 [sender.py:send_request_defer():609] handle sender defer: 5
2025-04-11 13:46:31,230 INFO    SenderThread:5729 [sender.py:transition_state():613] send defer: 6
2025-04-11 13:46:31,230 DEBUG   HandlerThread:5729 [handler.py:handle_request():146] handle_request: defer
2025-04-11 13:46:31,231 INFO    HandlerThread:5729 [handler.py:handle_request_defer():172] handle defer: 6
2025-04-11 13:46:31,231 DEBUG   SenderThread:5729 [sender.py:send_request():407] send_request: defer
2025-04-11 13:46:31,231 INFO    SenderThread:5729 [sender.py:send_request_defer():609] handle sender defer: 6
2025-04-11 13:46:31,231 INFO    SenderThread:5729 [sender.py:transition_state():613] send defer: 7
2025-04-11 13:46:31,231 DEBUG   HandlerThread:5729 [handler.py:handle_request():146] handle_request: status_report
2025-04-11 13:46:31,232 DEBUG   HandlerThread:5729 [handler.py:handle_request():146] handle_request: defer
2025-04-11 13:46:31,232 INFO    HandlerThread:5729 [handler.py:handle_request_defer():172] handle defer: 7
2025-04-11 13:46:31,232 DEBUG   SenderThread:5729 [sender.py:send_request():407] send_request: defer
2025-04-11 13:46:31,232 INFO    SenderThread:5729 [sender.py:send_request_defer():609] handle sender defer: 7
2025-04-11 13:46:31,869 INFO    Thread-12 :5729 [dir_watcher.py:_on_file_modified():288] file/dir modified: /root/ltu-main/ltu-main/src/ltu_as/train_scripts/wandb/run-20250411_134558-e1rp2dmj/files/config.yaml
2025-04-11 13:46:31,870 INFO    Thread-12 :5729 [dir_watcher.py:_on_file_created():271] file/dir created: /root/ltu-main/ltu-main/src/ltu_as/train_scripts/wandb/run-20250411_134558-e1rp2dmj/files/wandb-summary.json
2025-04-11 13:46:32,202 DEBUG   HandlerThread:5729 [handler.py:handle_request():146] handle_request: poll_exit
2025-04-11 13:46:33,263 INFO    SenderThread:5729 [sender.py:transition_state():613] send defer: 8
2025-04-11 13:46:33,263 DEBUG   SenderThread:5729 [sender.py:send_request():407] send_request: poll_exit
2025-04-11 13:46:33,264 DEBUG   HandlerThread:5729 [handler.py:handle_request():146] handle_request: defer
2025-04-11 13:46:33,264 INFO    HandlerThread:5729 [handler.py:handle_request_defer():172] handle defer: 8
2025-04-11 13:46:33,264 DEBUG   SenderThread:5729 [sender.py:send_request():407] send_request: defer
2025-04-11 13:46:33,265 INFO    SenderThread:5729 [sender.py:send_request_defer():609] handle sender defer: 8
2025-04-11 13:46:33,265 INFO    SenderThread:5729 [job_builder.py:build():281] Attempting to build job artifact
2025-04-11 13:46:33,266 INFO    SenderThread:5729 [job_builder.py:_get_source_type():404] no source found
2025-04-11 13:46:33,266 INFO    SenderThread:5729 [sender.py:transition_state():613] send defer: 9
2025-04-11 13:46:33,266 DEBUG   HandlerThread:5729 [handler.py:handle_request():146] handle_request: defer
2025-04-11 13:46:33,266 INFO    HandlerThread:5729 [handler.py:handle_request_defer():172] handle defer: 9
2025-04-11 13:46:33,266 DEBUG   SenderThread:5729 [sender.py:send_request():407] send_request: defer
2025-04-11 13:46:33,266 INFO    SenderThread:5729 [sender.py:send_request_defer():609] handle sender defer: 9
2025-04-11 13:46:33,266 INFO    SenderThread:5729 [dir_watcher.py:finish():358] shutting down directory watcher
2025-04-11 13:46:33,870 INFO    Thread-12 :5729 [dir_watcher.py:_on_file_modified():288] file/dir modified: /root/ltu-main/ltu-main/src/ltu_as/train_scripts/wandb/run-20250411_134558-e1rp2dmj/files/output.log
2025-04-11 13:46:33,871 INFO    SenderThread:5729 [dir_watcher.py:finish():388] scan: /root/ltu-main/ltu-main/src/ltu_as/train_scripts/wandb/run-20250411_134558-e1rp2dmj/files
2025-04-11 13:46:33,871 INFO    SenderThread:5729 [dir_watcher.py:finish():402] scan save: /root/ltu-main/ltu-main/src/ltu_as/train_scripts/wandb/run-20250411_134558-e1rp2dmj/files/config.yaml config.yaml
2025-04-11 13:46:33,872 INFO    SenderThread:5729 [dir_watcher.py:finish():402] scan save: /root/ltu-main/ltu-main/src/ltu_as/train_scripts/wandb/run-20250411_134558-e1rp2dmj/files/requirements.txt requirements.txt
2025-04-11 13:46:33,877 INFO    SenderThread:5729 [dir_watcher.py:finish():402] scan save: /root/ltu-main/ltu-main/src/ltu_as/train_scripts/wandb/run-20250411_134558-e1rp2dmj/files/conda-environment.yaml conda-environment.yaml
2025-04-11 13:46:33,882 INFO    SenderThread:5729 [dir_watcher.py:finish():402] scan save: /root/ltu-main/ltu-main/src/ltu_as/train_scripts/wandb/run-20250411_134558-e1rp2dmj/files/wandb-metadata.json wandb-metadata.json
2025-04-11 13:46:33,882 INFO    SenderThread:5729 [dir_watcher.py:finish():402] scan save: /root/ltu-main/ltu-main/src/ltu_as/train_scripts/wandb/run-20250411_134558-e1rp2dmj/files/output.log output.log
2025-04-11 13:46:33,882 INFO    SenderThread:5729 [dir_watcher.py:finish():402] scan save: /root/ltu-main/ltu-main/src/ltu_as/train_scripts/wandb/run-20250411_134558-e1rp2dmj/files/wandb-summary.json wandb-summary.json
2025-04-11 13:46:33,882 INFO    SenderThread:5729 [sender.py:transition_state():613] send defer: 10
2025-04-11 13:46:33,883 DEBUG   HandlerThread:5729 [handler.py:handle_request():146] handle_request: defer
2025-04-11 13:46:33,887 INFO    HandlerThread:5729 [handler.py:handle_request_defer():172] handle defer: 10
2025-04-11 13:46:33,893 DEBUG   SenderThread:5729 [sender.py:send_request():407] send_request: defer
2025-04-11 13:46:33,893 INFO    SenderThread:5729 [sender.py:send_request_defer():609] handle sender defer: 10
2025-04-11 13:46:33,893 INFO    SenderThread:5729 [file_pusher.py:finish():175] shutting down file pusher
2025-04-11 13:46:34,155 ERROR   wandb-upload_2:5729 [internal_api.py:upload_file():2556] upload_file exception https://storage.googleapis.com/wandb-production.appspot.com/2931823730-harbin-institute-of-technology/ltu-as/e1rp2dmj/requirements.txt?X-Goog-Algorithm=GOOG4-RSA-SHA256&X-Goog-Credential=gorilla-files-url-signer-man%40wandb-production.iam.gserviceaccount.com%2F20250411%2Fauto%2Fstorage%2Fgoog4_request&X-Goog-Date=20250411T134634Z&X-Goog-Expires=86399&X-Goog-Signature=3dfde56506a5eb961db089deed7db6aa48f193bc474ae614780e50f5da53dcad1ceb7b36dacc62c9ba2f21a8b3906e3591e27a1bd626d9c92a37b52c1a3a887ec2cc1e37639eb16971e4ed5e87ad2f243861a2fd54b4baab595fa20f3083675b58d7cba3143227443b1fdd03afbf5a03e6931eba414d96f4dbb387b685789045ce2ef0aadfb6f24c2b11b9e2ddba77726489ca36828d76c037fd3115c31241f3da27efd940eb562db1ac7affe47bc6cc8db3526bcefb0f030f2407394d1964bca766bbd1314ea5301db1ec85783aa70e6fe219f7c078906511102594baca5f8df23782c0692dd52f41467d465590ca5b32b230ff1554c23fd76e79fdadc28df4&X-Goog-SignedHeaders=host&X-User=2931823730: HTTPSConnectionPool(host='storage.googleapis.com', port=443): Max retries exceeded with url: /wandb-production.appspot.com/2931823730-harbin-institute-of-technology/ltu-as/e1rp2dmj/requirements.txt?X-Goog-Algorithm=GOOG4-RSA-SHA256&X-Goog-Credential=gorilla-files-url-signer-man%40wandb-production.iam.gserviceaccount.com%2F20250411%2Fauto%2Fstorage%2Fgoog4_request&X-Goog-Date=20250411T134634Z&X-Goog-Expires=86399&X-Goog-Signature=3dfde56506a5eb961db089deed7db6aa48f193bc474ae614780e50f5da53dcad1ceb7b36dacc62c9ba2f21a8b3906e3591e27a1bd626d9c92a37b52c1a3a887ec2cc1e37639eb16971e4ed5e87ad2f243861a2fd54b4baab595fa20f3083675b58d7cba3143227443b1fdd03afbf5a03e6931eba414d96f4dbb387b685789045ce2ef0aadfb6f24c2b11b9e2ddba77726489ca36828d76c037fd3115c31241f3da27efd940eb562db1ac7affe47bc6cc8db3526bcefb0f030f2407394d1964bca766bbd1314ea5301db1ec85783aa70e6fe219f7c078906511102594baca5f8df23782c0692dd52f41467d465590ca5b32b230ff1554c23fd76e79fdadc28df4&X-Goog-SignedHeaders=host&X-User=2931823730 (Caused by NewConnectionError('<urllib3.connection.HTTPSConnection object at 0x7f78a9fca530>: Failed to establish a new connection: [Errno 101] Network is unreachable'))
2025-04-11 13:46:34,155 ERROR   wandb-upload_2:5729 [internal_api.py:upload_file():2558] upload_file request headers: {'User-Agent': 'python-requests/2.32.3', 'Accept-Encoding': 'gzip, deflate, br', 'Accept': '*/*', 'Connection': 'keep-alive', 'Content-Length': '4212'}
2025-04-11 13:46:34,155 ERROR   wandb-upload_2:5729 [internal_api.py:upload_file():2560] upload_file response body: 
2025-04-11 13:46:34,156 ERROR   wandb-upload_1:5729 [internal_api.py:upload_file():2556] upload_file exception https://storage.googleapis.com/wandb-production.appspot.com/2931823730-harbin-institute-of-technology/ltu-as/e1rp2dmj/config.yaml?X-Goog-Algorithm=GOOG4-RSA-SHA256&X-Goog-Credential=gorilla-files-url-signer-man%40wandb-production.iam.gserviceaccount.com%2F20250411%2Fauto%2Fstorage%2Fgoog4_request&X-Goog-Date=20250411T134634Z&X-Goog-Expires=86399&X-Goog-Signature=4cd10bd589b82e59e27f62a38c7bb859f6315c8a3069f8c95f2b591b6d3a6f96f6cd958040991552a4208cd0e515ea04482dcb1ca32f1ee8f112a9b042da67ef144cb108a105d48d05bdbb86727c5c582615c7931ca7875be77f1e227f3cfbbbabc8417731c4b82ab6769881ee62e375155669ebec4934959856d4a8a2e6fdeaeab1cb06373c7866934a72235500ff61608d04e6a4e6447283f4046d87760e7658444706049c275c8f2fc043498682ac8fbdca5f494b43bd9838f8d8cb8009ffb7896ffb5c219b1f6a8fc992a9df4b59754e5d93a80dafdecf9a6b991c4defa8dc75553a784dcdc6ae3d13b2b7dd71a715a1f70a81feac5341924b175293b18a&X-Goog-SignedHeaders=host&X-User=2931823730: HTTPSConnectionPool(host='storage.googleapis.com', port=443): Max retries exceeded with url: /wandb-production.appspot.com/2931823730-harbin-institute-of-technology/ltu-as/e1rp2dmj/config.yaml?X-Goog-Algorithm=GOOG4-RSA-SHA256&X-Goog-Credential=gorilla-files-url-signer-man%40wandb-production.iam.gserviceaccount.com%2F20250411%2Fauto%2Fstorage%2Fgoog4_request&X-Goog-Date=20250411T134634Z&X-Goog-Expires=86399&X-Goog-Signature=4cd10bd589b82e59e27f62a38c7bb859f6315c8a3069f8c95f2b591b6d3a6f96f6cd958040991552a4208cd0e515ea04482dcb1ca32f1ee8f112a9b042da67ef144cb108a105d48d05bdbb86727c5c582615c7931ca7875be77f1e227f3cfbbbabc8417731c4b82ab6769881ee62e375155669ebec4934959856d4a8a2e6fdeaeab1cb06373c7866934a72235500ff61608d04e6a4e6447283f4046d87760e7658444706049c275c8f2fc043498682ac8fbdca5f494b43bd9838f8d8cb8009ffb7896ffb5c219b1f6a8fc992a9df4b59754e5d93a80dafdecf9a6b991c4defa8dc75553a784dcdc6ae3d13b2b7dd71a715a1f70a81feac5341924b175293b18a&X-Goog-SignedHeaders=host&X-User=2931823730 (Caused by NewConnectionError('<urllib3.connection.HTTPSConnection object at 0x7f78a9fc8820>: Failed to establish a new connection: [Errno 101] Network is unreachable'))
2025-04-11 13:46:34,156 ERROR   wandb-upload_1:5729 [internal_api.py:upload_file():2558] upload_file request headers: {'User-Agent': 'python-requests/2.32.3', 'Accept-Encoding': 'gzip, deflate, br', 'Accept': '*/*', 'Connection': 'keep-alive', 'Content-Length': '8684'}
2025-04-11 13:46:34,156 ERROR   wandb-upload_1:5729 [internal_api.py:upload_file():2560] upload_file response body: 
2025-04-11 13:46:34,308 ERROR   wandb-upload_5:5729 [internal_api.py:upload_file():2556] upload_file exception https://storage.googleapis.com/wandb-production.appspot.com/2931823730-harbin-institute-of-technology/ltu-as/e1rp2dmj/wandb-summary.json?X-Goog-Algorithm=GOOG4-RSA-SHA256&X-Goog-Credential=gorilla-files-url-signer-man%40wandb-production.iam.gserviceaccount.com%2F20250411%2Fauto%2Fstorage%2Fgoog4_request&X-Goog-Date=20250411T134634Z&X-Goog-Expires=86399&X-Goog-Signature=ac5e445aae328ee3ae9946dd2ab55fbf6f673f45f548df81577386d8397df42b9cec8bc5e03d7769bcf073b2b1aaf22a28439cb78c2913d462a812b518f0c77dc74ea5b3ff300544c40e4e06f62e863a922a5fd4736bb164c2a3dbed5d8ac771e3d73c275377bf6d644b25e54e374105fae21c754a7d00451e6f4b9bdb8eef6d007da49a984adb31101ff795c71ff81bfae958b73af8919398e18a58f6835c41d1d8b808f4dcfb20fa53b90aed702ce33dd3a843c72139afeadd14489fd191a910b1f046a684e2d5ec5d4548d93932e2ac3b57577beb5db408798c4892a905cf5ef8ecf5f2a91ed8d3d9bd832fd9a08889d3ec1ad786378a3ba3a8af22b6d471&X-Goog-SignedHeaders=host&X-User=2931823730: HTTPSConnectionPool(host='storage.googleapis.com', port=443): Max retries exceeded with url: /wandb-production.appspot.com/2931823730-harbin-institute-of-technology/ltu-as/e1rp2dmj/wandb-summary.json?X-Goog-Algorithm=GOOG4-RSA-SHA256&X-Goog-Credential=gorilla-files-url-signer-man%40wandb-production.iam.gserviceaccount.com%2F20250411%2Fauto%2Fstorage%2Fgoog4_request&X-Goog-Date=20250411T134634Z&X-Goog-Expires=86399&X-Goog-Signature=ac5e445aae328ee3ae9946dd2ab55fbf6f673f45f548df81577386d8397df42b9cec8bc5e03d7769bcf073b2b1aaf22a28439cb78c2913d462a812b518f0c77dc74ea5b3ff300544c40e4e06f62e863a922a5fd4736bb164c2a3dbed5d8ac771e3d73c275377bf6d644b25e54e374105fae21c754a7d00451e6f4b9bdb8eef6d007da49a984adb31101ff795c71ff81bfae958b73af8919398e18a58f6835c41d1d8b808f4dcfb20fa53b90aed702ce33dd3a843c72139afeadd14489fd191a910b1f046a684e2d5ec5d4548d93932e2ac3b57577beb5db408798c4892a905cf5ef8ecf5f2a91ed8d3d9bd832fd9a08889d3ec1ad786378a3ba3a8af22b6d471&X-Goog-SignedHeaders=host&X-User=2931823730 (Caused by NewConnectionError('<urllib3.connection.HTTPSConnection object at 0x7f78a9fca890>: Failed to establish a new connection: [Errno 101] Network is unreachable'))
2025-04-11 13:46:34,308 ERROR   wandb-upload_5:5729 [internal_api.py:upload_file():2558] upload_file request headers: {'User-Agent': 'python-requests/2.32.3', 'Accept-Encoding': 'gzip, deflate, br', 'Accept': '*/*', 'Connection': 'keep-alive', 'Content-Length': '27'}
2025-04-11 13:46:34,309 ERROR   wandb-upload_5:5729 [internal_api.py:upload_file():2560] upload_file response body: 
2025-04-11 13:46:34,329 ERROR   wandb-upload_3:5729 [internal_api.py:upload_file():2556] upload_file exception https://storage.googleapis.com/wandb-production.appspot.com/2931823730-harbin-institute-of-technology/ltu-as/e1rp2dmj/conda-environment.yaml?X-Goog-Algorithm=GOOG4-RSA-SHA256&X-Goog-Credential=gorilla-files-url-signer-man%40wandb-production.iam.gserviceaccount.com%2F20250411%2Fauto%2Fstorage%2Fgoog4_request&X-Goog-Date=20250411T134634Z&X-Goog-Expires=86399&X-Goog-Signature=265e438ee1e70b800d8a7fecfc5ad7df5c6466d860f091f7203140cddce9cf7c92daef52f7ce3e701a0c43e1f92589bbf32fcf34e3491bd34b94e81bf4d369c1acaad089236cab81b7188596c894dc002373a96c6f456f16feb1cf4fc97ba6c918c66221de710c322f624fc3beafa22a0e6267b0d3e03a930092368d7bd298205cfb04835e4b98073b7419be36903de0a53256ad826c162ab35548a4b743df5a7f158aa3ba83515129d2bc120a7668d5f6ba72729786d61f070b892b4caae0f489a444d306207d8845ddfaf36cb07c97e8491db8a6cd464df6b44b458fd31bfb7aec6900e7bce07aa5d7d06f66942850410ced96674f6d13dbde8735c065b758&X-Goog-SignedHeaders=host&X-User=2931823730: HTTPSConnectionPool(host='storage.googleapis.com', port=443): Max retries exceeded with url: /wandb-production.appspot.com/2931823730-harbin-institute-of-technology/ltu-as/e1rp2dmj/conda-environment.yaml?X-Goog-Algorithm=GOOG4-RSA-SHA256&X-Goog-Credential=gorilla-files-url-signer-man%40wandb-production.iam.gserviceaccount.com%2F20250411%2Fauto%2Fstorage%2Fgoog4_request&X-Goog-Date=20250411T134634Z&X-Goog-Expires=86399&X-Goog-Signature=265e438ee1e70b800d8a7fecfc5ad7df5c6466d860f091f7203140cddce9cf7c92daef52f7ce3e701a0c43e1f92589bbf32fcf34e3491bd34b94e81bf4d369c1acaad089236cab81b7188596c894dc002373a96c6f456f16feb1cf4fc97ba6c918c66221de710c322f624fc3beafa22a0e6267b0d3e03a930092368d7bd298205cfb04835e4b98073b7419be36903de0a53256ad826c162ab35548a4b743df5a7f158aa3ba83515129d2bc120a7668d5f6ba72729786d61f070b892b4caae0f489a444d306207d8845ddfaf36cb07c97e8491db8a6cd464df6b44b458fd31bfb7aec6900e7bce07aa5d7d06f66942850410ced96674f6d13dbde8735c065b758&X-Goog-SignedHeaders=host&X-User=2931823730 (Caused by NewConnectionError('<urllib3.connection.HTTPSConnection object at 0x7f78ba749150>: Failed to establish a new connection: [Errno 101] Network is unreachable'))
2025-04-11 13:46:34,329 ERROR   wandb-upload_3:5729 [internal_api.py:upload_file():2558] upload_file request headers: {'User-Agent': 'python-requests/2.32.3', 'Accept-Encoding': 'gzip, deflate, br', 'Accept': '*/*', 'Connection': 'keep-alive', 'Content-Length': '8281'}
2025-04-11 13:46:34,329 ERROR   wandb-upload_3:5729 [internal_api.py:upload_file():2560] upload_file response body: 
2025-04-11 13:46:34,330 ERROR   wandb-upload_4:5729 [internal_api.py:upload_file():2556] upload_file exception https://storage.googleapis.com/wandb-production.appspot.com/2931823730-harbin-institute-of-technology/ltu-as/e1rp2dmj/output.log?X-Goog-Algorithm=GOOG4-RSA-SHA256&X-Goog-Credential=gorilla-files-url-signer-man%40wandb-production.iam.gserviceaccount.com%2F20250411%2Fauto%2Fstorage%2Fgoog4_request&X-Goog-Date=20250411T134634Z&X-Goog-Expires=86399&X-Goog-Signature=1128654687b0bf6a676feb1b3994c67f90d4d5ad203efb1db55a64de90d2e137a92e4605a00647015e03b194032e4403003e9fa8121264c1d3fec46eff90feac3c3cffb282d22451c5c6acb440a025e6ed761bf74b5259a8e5e079edcfa55a2cb62cae67f6be3e484d87677dfd925fed1422544e6d25665d96085dab9beb1aba7f0074d9632139baf8e19153ba1bd3f3833ab064bcdd45f81fc55148a4ea0e4c3b3e9d308644abc1ba92aee0756638463b58ca487c63f3ef2b21a51c344d3e9827d9c479edcffa4422015eebc1612fe497273ae11d9a40dc95b6ecf080a596c4206a01011244acfe3450e296dc68077ded4fb723f67f357914c5c7890a257fef&X-Goog-SignedHeaders=host&X-User=2931823730: HTTPSConnectionPool(host='storage.googleapis.com', port=443): Max retries exceeded with url: /wandb-production.appspot.com/2931823730-harbin-institute-of-technology/ltu-as/e1rp2dmj/output.log?X-Goog-Algorithm=GOOG4-RSA-SHA256&X-Goog-Credential=gorilla-files-url-signer-man%40wandb-production.iam.gserviceaccount.com%2F20250411%2Fauto%2Fstorage%2Fgoog4_request&X-Goog-Date=20250411T134634Z&X-Goog-Expires=86399&X-Goog-Signature=1128654687b0bf6a676feb1b3994c67f90d4d5ad203efb1db55a64de90d2e137a92e4605a00647015e03b194032e4403003e9fa8121264c1d3fec46eff90feac3c3cffb282d22451c5c6acb440a025e6ed761bf74b5259a8e5e079edcfa55a2cb62cae67f6be3e484d87677dfd925fed1422544e6d25665d96085dab9beb1aba7f0074d9632139baf8e19153ba1bd3f3833ab064bcdd45f81fc55148a4ea0e4c3b3e9d308644abc1ba92aee0756638463b58ca487c63f3ef2b21a51c344d3e9827d9c479edcffa4422015eebc1612fe497273ae11d9a40dc95b6ecf080a596c4206a01011244acfe3450e296dc68077ded4fb723f67f357914c5c7890a257fef&X-Goog-SignedHeaders=host&X-User=2931823730 (Caused by NewConnectionError('<urllib3.connection.HTTPSConnection object at 0x7f78ba74acb0>: Failed to establish a new connection: [Errno 101] Network is unreachable'))
2025-04-11 13:46:34,330 ERROR   wandb-upload_4:5729 [internal_api.py:upload_file():2558] upload_file request headers: {'User-Agent': 'python-requests/2.32.3', 'Accept-Encoding': 'gzip, deflate, br', 'Accept': '*/*', 'Connection': 'keep-alive', 'Content-Length': '5068'}
2025-04-11 13:46:34,330 ERROR   wandb-upload_4:5729 [internal_api.py:upload_file():2560] upload_file response body: 
2025-04-11 13:46:35,287 ERROR   wandb-upload_1:5729 [internal_api.py:upload_file():2556] upload_file exception https://storage.googleapis.com/wandb-production.appspot.com/2931823730-harbin-institute-of-technology/ltu-as/e1rp2dmj/config.yaml?X-Goog-Algorithm=GOOG4-RSA-SHA256&X-Goog-Credential=gorilla-files-url-signer-man%40wandb-production.iam.gserviceaccount.com%2F20250411%2Fauto%2Fstorage%2Fgoog4_request&X-Goog-Date=20250411T134634Z&X-Goog-Expires=86399&X-Goog-Signature=4cd10bd589b82e59e27f62a38c7bb859f6315c8a3069f8c95f2b591b6d3a6f96f6cd958040991552a4208cd0e515ea04482dcb1ca32f1ee8f112a9b042da67ef144cb108a105d48d05bdbb86727c5c582615c7931ca7875be77f1e227f3cfbbbabc8417731c4b82ab6769881ee62e375155669ebec4934959856d4a8a2e6fdeaeab1cb06373c7866934a72235500ff61608d04e6a4e6447283f4046d87760e7658444706049c275c8f2fc043498682ac8fbdca5f494b43bd9838f8d8cb8009ffb7896ffb5c219b1f6a8fc992a9df4b59754e5d93a80dafdecf9a6b991c4defa8dc75553a784dcdc6ae3d13b2b7dd71a715a1f70a81feac5341924b175293b18a&X-Goog-SignedHeaders=host&X-User=2931823730: HTTPSConnectionPool(host='storage.googleapis.com', port=443): Max retries exceeded with url: /wandb-production.appspot.com/2931823730-harbin-institute-of-technology/ltu-as/e1rp2dmj/config.yaml?X-Goog-Algorithm=GOOG4-RSA-SHA256&X-Goog-Credential=gorilla-files-url-signer-man%40wandb-production.iam.gserviceaccount.com%2F20250411%2Fauto%2Fstorage%2Fgoog4_request&X-Goog-Date=20250411T134634Z&X-Goog-Expires=86399&X-Goog-Signature=4cd10bd589b82e59e27f62a38c7bb859f6315c8a3069f8c95f2b591b6d3a6f96f6cd958040991552a4208cd0e515ea04482dcb1ca32f1ee8f112a9b042da67ef144cb108a105d48d05bdbb86727c5c582615c7931ca7875be77f1e227f3cfbbbabc8417731c4b82ab6769881ee62e375155669ebec4934959856d4a8a2e6fdeaeab1cb06373c7866934a72235500ff61608d04e6a4e6447283f4046d87760e7658444706049c275c8f2fc043498682ac8fbdca5f494b43bd9838f8d8cb8009ffb7896ffb5c219b1f6a8fc992a9df4b59754e5d93a80dafdecf9a6b991c4defa8dc75553a784dcdc6ae3d13b2b7dd71a715a1f70a81feac5341924b175293b18a&X-Goog-SignedHeaders=host&X-User=2931823730 (Caused by NewConnectionError('<urllib3.connection.HTTPSConnection object at 0x7f78a9fcb280>: Failed to establish a new connection: [Errno 101] Network is unreachable'))
2025-04-11 13:46:35,287 ERROR   wandb-upload_1:5729 [internal_api.py:upload_file():2558] upload_file request headers: {'User-Agent': 'python-requests/2.32.3', 'Accept-Encoding': 'gzip, deflate, br', 'Accept': '*/*', 'Connection': 'keep-alive', 'Content-Length': '8684'}
2025-04-11 13:46:35,287 ERROR   wandb-upload_1:5729 [internal_api.py:upload_file():2560] upload_file response body: 
2025-04-11 13:46:35,339 ERROR   wandb-upload_2:5729 [internal_api.py:upload_file():2556] upload_file exception https://storage.googleapis.com/wandb-production.appspot.com/2931823730-harbin-institute-of-technology/ltu-as/e1rp2dmj/requirements.txt?X-Goog-Algorithm=GOOG4-RSA-SHA256&X-Goog-Credential=gorilla-files-url-signer-man%40wandb-production.iam.gserviceaccount.com%2F20250411%2Fauto%2Fstorage%2Fgoog4_request&X-Goog-Date=20250411T134634Z&X-Goog-Expires=86399&X-Goog-Signature=3dfde56506a5eb961db089deed7db6aa48f193bc474ae614780e50f5da53dcad1ceb7b36dacc62c9ba2f21a8b3906e3591e27a1bd626d9c92a37b52c1a3a887ec2cc1e37639eb16971e4ed5e87ad2f243861a2fd54b4baab595fa20f3083675b58d7cba3143227443b1fdd03afbf5a03e6931eba414d96f4dbb387b685789045ce2ef0aadfb6f24c2b11b9e2ddba77726489ca36828d76c037fd3115c31241f3da27efd940eb562db1ac7affe47bc6cc8db3526bcefb0f030f2407394d1964bca766bbd1314ea5301db1ec85783aa70e6fe219f7c078906511102594baca5f8df23782c0692dd52f41467d465590ca5b32b230ff1554c23fd76e79fdadc28df4&X-Goog-SignedHeaders=host&X-User=2931823730: HTTPSConnectionPool(host='storage.googleapis.com', port=443): Max retries exceeded with url: /wandb-production.appspot.com/2931823730-harbin-institute-of-technology/ltu-as/e1rp2dmj/requirements.txt?X-Goog-Algorithm=GOOG4-RSA-SHA256&X-Goog-Credential=gorilla-files-url-signer-man%40wandb-production.iam.gserviceaccount.com%2F20250411%2Fauto%2Fstorage%2Fgoog4_request&X-Goog-Date=20250411T134634Z&X-Goog-Expires=86399&X-Goog-Signature=3dfde56506a5eb961db089deed7db6aa48f193bc474ae614780e50f5da53dcad1ceb7b36dacc62c9ba2f21a8b3906e3591e27a1bd626d9c92a37b52c1a3a887ec2cc1e37639eb16971e4ed5e87ad2f243861a2fd54b4baab595fa20f3083675b58d7cba3143227443b1fdd03afbf5a03e6931eba414d96f4dbb387b685789045ce2ef0aadfb6f24c2b11b9e2ddba77726489ca36828d76c037fd3115c31241f3da27efd940eb562db1ac7affe47bc6cc8db3526bcefb0f030f2407394d1964bca766bbd1314ea5301db1ec85783aa70e6fe219f7c078906511102594baca5f8df23782c0692dd52f41467d465590ca5b32b230ff1554c23fd76e79fdadc28df4&X-Goog-SignedHeaders=host&X-User=2931823730 (Caused by NewConnectionError('<urllib3.connection.HTTPSConnection object at 0x7f78a9fcb7c0>: Failed to establish a new connection: [Errno 101] Network is unreachable'))
2025-04-11 13:46:35,339 ERROR   wandb-upload_2:5729 [internal_api.py:upload_file():2558] upload_file request headers: {'User-Agent': 'python-requests/2.32.3', 'Accept-Encoding': 'gzip, deflate, br', 'Accept': '*/*', 'Connection': 'keep-alive', 'Content-Length': '4212'}
2025-04-11 13:46:35,339 ERROR   wandb-upload_2:5729 [internal_api.py:upload_file():2560] upload_file response body: 
2025-04-11 13:46:35,339 INFO    wandb-upload_2:5729 [retry.py:__call__():172] Retry attempt failed:
Traceback (most recent call last):
  File "/root/anaconda3/envs/venv_ltu/lib/python3.10/site-packages/urllib3/connection.py", line 198, in _new_conn
    sock = connection.create_connection(
  File "/root/anaconda3/envs/venv_ltu/lib/python3.10/site-packages/urllib3/util/connection.py", line 85, in create_connection
    raise err
  File "/root/anaconda3/envs/venv_ltu/lib/python3.10/site-packages/urllib3/util/connection.py", line 73, in create_connection
    sock.connect(sa)
OSError: [Errno 101] Network is unreachable

The above exception was the direct cause of the following exception:

Traceback (most recent call last):
  File "/root/anaconda3/envs/venv_ltu/lib/python3.10/site-packages/urllib3/connectionpool.py", line 793, in urlopen
    response = self._make_request(
  File "/root/anaconda3/envs/venv_ltu/lib/python3.10/site-packages/urllib3/connectionpool.py", line 491, in _make_request
    raise new_e
  File "/root/anaconda3/envs/venv_ltu/lib/python3.10/site-packages/urllib3/connectionpool.py", line 467, in _make_request
    self._validate_conn(conn)
  File "/root/anaconda3/envs/venv_ltu/lib/python3.10/site-packages/urllib3/connectionpool.py", line 1099, in _validate_conn
    conn.connect()
  File "/root/anaconda3/envs/venv_ltu/lib/python3.10/site-packages/urllib3/connection.py", line 616, in connect
    self.sock = sock = self._new_conn()
  File "/root/anaconda3/envs/venv_ltu/lib/python3.10/site-packages/urllib3/connection.py", line 213, in _new_conn
    raise NewConnectionError(
urllib3.exceptions.NewConnectionError: <urllib3.connection.HTTPSConnection object at 0x7f78a9fcb7c0>: Failed to establish a new connection: [Errno 101] Network is unreachable

The above exception was the direct cause of the following exception:

Traceback (most recent call last):
  File "/root/anaconda3/envs/venv_ltu/lib/python3.10/site-packages/requests/adapters.py", line 667, in send
    resp = conn.urlopen(
  File "/root/anaconda3/envs/venv_ltu/lib/python3.10/site-packages/urllib3/connectionpool.py", line 847, in urlopen
    retries = retries.increment(
  File "/root/anaconda3/envs/venv_ltu/lib/python3.10/site-packages/urllib3/util/retry.py", line 515, in increment
    raise MaxRetryError(_pool, url, reason) from reason  # type: ignore[arg-type]
urllib3.exceptions.MaxRetryError: HTTPSConnectionPool(host='storage.googleapis.com', port=443): Max retries exceeded with url: /wandb-production.appspot.com/2931823730-harbin-institute-of-technology/ltu-as/e1rp2dmj/requirements.txt?X-Goog-Algorithm=GOOG4-RSA-SHA256&X-Goog-Credential=gorilla-files-url-signer-man%40wandb-production.iam.gserviceaccount.com%2F20250411%2Fauto%2Fstorage%2Fgoog4_request&X-Goog-Date=20250411T134634Z&X-Goog-Expires=86399&X-Goog-Signature=3dfde56506a5eb961db089deed7db6aa48f193bc474ae614780e50f5da53dcad1ceb7b36dacc62c9ba2f21a8b3906e3591e27a1bd626d9c92a37b52c1a3a887ec2cc1e37639eb16971e4ed5e87ad2f243861a2fd54b4baab595fa20f3083675b58d7cba3143227443b1fdd03afbf5a03e6931eba414d96f4dbb387b685789045ce2ef0aadfb6f24c2b11b9e2ddba77726489ca36828d76c037fd3115c31241f3da27efd940eb562db1ac7affe47bc6cc8db3526bcefb0f030f2407394d1964bca766bbd1314ea5301db1ec85783aa70e6fe219f7c078906511102594baca5f8df23782c0692dd52f41467d465590ca5b32b230ff1554c23fd76e79fdadc28df4&X-Goog-SignedHeaders=host&X-User=2931823730 (Caused by NewConnectionError('<urllib3.connection.HTTPSConnection object at 0x7f78a9fcb7c0>: Failed to establish a new connection: [Errno 101] Network is unreachable'))

During handling of the above exception, another exception occurred:

Traceback (most recent call last):
  File "/root/anaconda3/envs/venv_ltu/lib/python3.10/site-packages/wandb/sdk/internal/internal_api.py", line 2549, in upload_file
    response = self._upload_file_session.put(
  File "/root/anaconda3/envs/venv_ltu/lib/python3.10/site-packages/requests/sessions.py", line 649, in put
    return self.request("PUT", url, data=data, **kwargs)
  File "/root/anaconda3/envs/venv_ltu/lib/python3.10/site-packages/requests/sessions.py", line 589, in request
    resp = self.send(prep, **send_kwargs)
  File "/root/anaconda3/envs/venv_ltu/lib/python3.10/site-packages/requests/sessions.py", line 703, in send
    r = adapter.send(request, **kwargs)
  File "/root/anaconda3/envs/venv_ltu/lib/python3.10/site-packages/requests/adapters.py", line 700, in send
    raise ConnectionError(e, request=request)
requests.exceptions.ConnectionError: HTTPSConnectionPool(host='storage.googleapis.com', port=443): Max retries exceeded with url: /wandb-production.appspot.com/2931823730-harbin-institute-of-technology/ltu-as/e1rp2dmj/requirements.txt?X-Goog-Algorithm=GOOG4-RSA-SHA256&X-Goog-Credential=gorilla-files-url-signer-man%40wandb-production.iam.gserviceaccount.com%2F20250411%2Fauto%2Fstorage%2Fgoog4_request&X-Goog-Date=20250411T134634Z&X-Goog-Expires=86399&X-Goog-Signature=3dfde56506a5eb961db089deed7db6aa48f193bc474ae614780e50f5da53dcad1ceb7b36dacc62c9ba2f21a8b3906e3591e27a1bd626d9c92a37b52c1a3a887ec2cc1e37639eb16971e4ed5e87ad2f243861a2fd54b4baab595fa20f3083675b58d7cba3143227443b1fdd03afbf5a03e6931eba414d96f4dbb387b685789045ce2ef0aadfb6f24c2b11b9e2ddba77726489ca36828d76c037fd3115c31241f3da27efd940eb562db1ac7affe47bc6cc8db3526bcefb0f030f2407394d1964bca766bbd1314ea5301db1ec85783aa70e6fe219f7c078906511102594baca5f8df23782c0692dd52f41467d465590ca5b32b230ff1554c23fd76e79fdadc28df4&X-Goog-SignedHeaders=host&X-User=2931823730 (Caused by NewConnectionError('<urllib3.connection.HTTPSConnection object at 0x7f78a9fcb7c0>: Failed to establish a new connection: [Errno 101] Network is unreachable'))

During handling of the above exception, another exception occurred:

Traceback (most recent call last):
  File "/root/anaconda3/envs/venv_ltu/lib/python3.10/site-packages/wandb/sdk/lib/retry.py", line 131, in __call__
    result = self._call_fn(*args, **kwargs)
  File "/root/anaconda3/envs/venv_ltu/lib/python3.10/site-packages/wandb/sdk/internal/internal_api.py", line 2580, in upload_file
    raise _e.with_traceback(sys.exc_info()[2])
  File "/root/anaconda3/envs/venv_ltu/lib/python3.10/site-packages/wandb/sdk/internal/internal_api.py", line 2549, in upload_file
    response = self._upload_file_session.put(
  File "/root/anaconda3/envs/venv_ltu/lib/python3.10/site-packages/requests/sessions.py", line 649, in put
    return self.request("PUT", url, data=data, **kwargs)
  File "/root/anaconda3/envs/venv_ltu/lib/python3.10/site-packages/requests/sessions.py", line 589, in request
    resp = self.send(prep, **send_kwargs)
  File "/root/anaconda3/envs/venv_ltu/lib/python3.10/site-packages/requests/sessions.py", line 703, in send
    r = adapter.send(request, **kwargs)
  File "/root/anaconda3/envs/venv_ltu/lib/python3.10/site-packages/requests/adapters.py", line 700, in send
    raise ConnectionError(e, request=request)
wandb.sdk.lib.retry.TransientError: None
2025-04-11 13:46:35,413 ERROR   wandb-upload_5:5729 [internal_api.py:upload_file():2556] upload_file exception https://storage.googleapis.com/wandb-production.appspot.com/2931823730-harbin-institute-of-technology/ltu-as/e1rp2dmj/wandb-summary.json?X-Goog-Algorithm=GOOG4-RSA-SHA256&X-Goog-Credential=gorilla-files-url-signer-man%40wandb-production.iam.gserviceaccount.com%2F20250411%2Fauto%2Fstorage%2Fgoog4_request&X-Goog-Date=20250411T134634Z&X-Goog-Expires=86399&X-Goog-Signature=ac5e445aae328ee3ae9946dd2ab55fbf6f673f45f548df81577386d8397df42b9cec8bc5e03d7769bcf073b2b1aaf22a28439cb78c2913d462a812b518f0c77dc74ea5b3ff300544c40e4e06f62e863a922a5fd4736bb164c2a3dbed5d8ac771e3d73c275377bf6d644b25e54e374105fae21c754a7d00451e6f4b9bdb8eef6d007da49a984adb31101ff795c71ff81bfae958b73af8919398e18a58f6835c41d1d8b808f4dcfb20fa53b90aed702ce33dd3a843c72139afeadd14489fd191a910b1f046a684e2d5ec5d4548d93932e2ac3b57577beb5db408798c4892a905cf5ef8ecf5f2a91ed8d3d9bd832fd9a08889d3ec1ad786378a3ba3a8af22b6d471&X-Goog-SignedHeaders=host&X-User=2931823730: HTTPSConnectionPool(host='storage.googleapis.com', port=443): Max retries exceeded with url: /wandb-production.appspot.com/2931823730-harbin-institute-of-technology/ltu-as/e1rp2dmj/wandb-summary.json?X-Goog-Algorithm=GOOG4-RSA-SHA256&X-Goog-Credential=gorilla-files-url-signer-man%40wandb-production.iam.gserviceaccount.com%2F20250411%2Fauto%2Fstorage%2Fgoog4_request&X-Goog-Date=20250411T134634Z&X-Goog-Expires=86399&X-Goog-Signature=ac5e445aae328ee3ae9946dd2ab55fbf6f673f45f548df81577386d8397df42b9cec8bc5e03d7769bcf073b2b1aaf22a28439cb78c2913d462a812b518f0c77dc74ea5b3ff300544c40e4e06f62e863a922a5fd4736bb164c2a3dbed5d8ac771e3d73c275377bf6d644b25e54e374105fae21c754a7d00451e6f4b9bdb8eef6d007da49a984adb31101ff795c71ff81bfae958b73af8919398e18a58f6835c41d1d8b808f4dcfb20fa53b90aed702ce33dd3a843c72139afeadd14489fd191a910b1f046a684e2d5ec5d4548d93932e2ac3b57577beb5db408798c4892a905cf5ef8ecf5f2a91ed8d3d9bd832fd9a08889d3ec1ad786378a3ba3a8af22b6d471&X-Goog-SignedHeaders=host&X-User=2931823730 (Caused by NewConnectionError('<urllib3.connection.HTTPSConnection object at 0x7f78a860d930>: Failed to establish a new connection: [Errno 101] Network is unreachable'))
2025-04-11 13:46:35,414 ERROR   wandb-upload_5:5729 [internal_api.py:upload_file():2558] upload_file request headers: {'User-Agent': 'python-requests/2.32.3', 'Accept-Encoding': 'gzip, deflate, br', 'Accept': '*/*', 'Connection': 'keep-alive', 'Content-Length': '27'}
2025-04-11 13:46:35,414 ERROR   wandb-upload_5:5729 [internal_api.py:upload_file():2560] upload_file response body: 
2025-04-11 13:46:35,439 ERROR   wandb-upload_4:5729 [internal_api.py:upload_file():2556] upload_file exception https://storage.googleapis.com/wandb-production.appspot.com/2931823730-harbin-institute-of-technology/ltu-as/e1rp2dmj/output.log?X-Goog-Algorithm=GOOG4-RSA-SHA256&X-Goog-Credential=gorilla-files-url-signer-man%40wandb-production.iam.gserviceaccount.com%2F20250411%2Fauto%2Fstorage%2Fgoog4_request&X-Goog-Date=20250411T134634Z&X-Goog-Expires=86399&X-Goog-Signature=1128654687b0bf6a676feb1b3994c67f90d4d5ad203efb1db55a64de90d2e137a92e4605a00647015e03b194032e4403003e9fa8121264c1d3fec46eff90feac3c3cffb282d22451c5c6acb440a025e6ed761bf74b5259a8e5e079edcfa55a2cb62cae67f6be3e484d87677dfd925fed1422544e6d25665d96085dab9beb1aba7f0074d9632139baf8e19153ba1bd3f3833ab064bcdd45f81fc55148a4ea0e4c3b3e9d308644abc1ba92aee0756638463b58ca487c63f3ef2b21a51c344d3e9827d9c479edcffa4422015eebc1612fe497273ae11d9a40dc95b6ecf080a596c4206a01011244acfe3450e296dc68077ded4fb723f67f357914c5c7890a257fef&X-Goog-SignedHeaders=host&X-User=2931823730: HTTPSConnectionPool(host='storage.googleapis.com', port=443): Max retries exceeded with url: /wandb-production.appspot.com/2931823730-harbin-institute-of-technology/ltu-as/e1rp2dmj/output.log?X-Goog-Algorithm=GOOG4-RSA-SHA256&X-Goog-Credential=gorilla-files-url-signer-man%40wandb-production.iam.gserviceaccount.com%2F20250411%2Fauto%2Fstorage%2Fgoog4_request&X-Goog-Date=20250411T134634Z&X-Goog-Expires=86399&X-Goog-Signature=1128654687b0bf6a676feb1b3994c67f90d4d5ad203efb1db55a64de90d2e137a92e4605a00647015e03b194032e4403003e9fa8121264c1d3fec46eff90feac3c3cffb282d22451c5c6acb440a025e6ed761bf74b5259a8e5e079edcfa55a2cb62cae67f6be3e484d87677dfd925fed1422544e6d25665d96085dab9beb1aba7f0074d9632139baf8e19153ba1bd3f3833ab064bcdd45f81fc55148a4ea0e4c3b3e9d308644abc1ba92aee0756638463b58ca487c63f3ef2b21a51c344d3e9827d9c479edcffa4422015eebc1612fe497273ae11d9a40dc95b6ecf080a596c4206a01011244acfe3450e296dc68077ded4fb723f67f357914c5c7890a257fef&X-Goog-SignedHeaders=host&X-User=2931823730 (Caused by NewConnectionError('<urllib3.connection.HTTPSConnection object at 0x7f78a860d060>: Failed to establish a new connection: [Errno 101] Network is unreachable'))
2025-04-11 13:46:35,439 ERROR   wandb-upload_4:5729 [internal_api.py:upload_file():2558] upload_file request headers: {'User-Agent': 'python-requests/2.32.3', 'Accept-Encoding': 'gzip, deflate, br', 'Accept': '*/*', 'Connection': 'keep-alive', 'Content-Length': '5068'}
2025-04-11 13:46:35,439 ERROR   wandb-upload_4:5729 [internal_api.py:upload_file():2560] upload_file response body: 
2025-04-11 13:46:35,467 ERROR   wandb-upload_3:5729 [internal_api.py:upload_file():2556] upload_file exception https://storage.googleapis.com/wandb-production.appspot.com/2931823730-harbin-institute-of-technology/ltu-as/e1rp2dmj/conda-environment.yaml?X-Goog-Algorithm=GOOG4-RSA-SHA256&X-Goog-Credential=gorilla-files-url-signer-man%40wandb-production.iam.gserviceaccount.com%2F20250411%2Fauto%2Fstorage%2Fgoog4_request&X-Goog-Date=20250411T134634Z&X-Goog-Expires=86399&X-Goog-Signature=265e438ee1e70b800d8a7fecfc5ad7df5c6466d860f091f7203140cddce9cf7c92daef52f7ce3e701a0c43e1f92589bbf32fcf34e3491bd34b94e81bf4d369c1acaad089236cab81b7188596c894dc002373a96c6f456f16feb1cf4fc97ba6c918c66221de710c322f624fc3beafa22a0e6267b0d3e03a930092368d7bd298205cfb04835e4b98073b7419be36903de0a53256ad826c162ab35548a4b743df5a7f158aa3ba83515129d2bc120a7668d5f6ba72729786d61f070b892b4caae0f489a444d306207d8845ddfaf36cb07c97e8491db8a6cd464df6b44b458fd31bfb7aec6900e7bce07aa5d7d06f66942850410ced96674f6d13dbde8735c065b758&X-Goog-SignedHeaders=host&X-User=2931823730: HTTPSConnectionPool(host='storage.googleapis.com', port=443): Max retries exceeded with url: /wandb-production.appspot.com/2931823730-harbin-institute-of-technology/ltu-as/e1rp2dmj/conda-environment.yaml?X-Goog-Algorithm=GOOG4-RSA-SHA256&X-Goog-Credential=gorilla-files-url-signer-man%40wandb-production.iam.gserviceaccount.com%2F20250411%2Fauto%2Fstorage%2Fgoog4_request&X-Goog-Date=20250411T134634Z&X-Goog-Expires=86399&X-Goog-Signature=265e438ee1e70b800d8a7fecfc5ad7df5c6466d860f091f7203140cddce9cf7c92daef52f7ce3e701a0c43e1f92589bbf32fcf34e3491bd34b94e81bf4d369c1acaad089236cab81b7188596c894dc002373a96c6f456f16feb1cf4fc97ba6c918c66221de710c322f624fc3beafa22a0e6267b0d3e03a930092368d7bd298205cfb04835e4b98073b7419be36903de0a53256ad826c162ab35548a4b743df5a7f158aa3ba83515129d2bc120a7668d5f6ba72729786d61f070b892b4caae0f489a444d306207d8845ddfaf36cb07c97e8491db8a6cd464df6b44b458fd31bfb7aec6900e7bce07aa5d7d06f66942850410ced96674f6d13dbde8735c065b758&X-Goog-SignedHeaders=host&X-User=2931823730 (Caused by NewConnectionError('<urllib3.connection.HTTPSConnection object at 0x7f78a860d210>: Failed to establish a new connection: [Errno 101] Network is unreachable'))
2025-04-11 13:46:35,467 ERROR   wandb-upload_3:5729 [internal_api.py:upload_file():2558] upload_file request headers: {'User-Agent': 'python-requests/2.32.3', 'Accept-Encoding': 'gzip, deflate, br', 'Accept': '*/*', 'Connection': 'keep-alive', 'Content-Length': '8281'}
2025-04-11 13:46:35,467 ERROR   wandb-upload_3:5729 [internal_api.py:upload_file():2560] upload_file response body: 
2025-04-11 13:46:36,093 ERROR   wandb-upload_0:5729 [internal_api.py:upload_file():2556] upload_file exception https://storage.googleapis.com/wandb-production.appspot.com/2931823730-harbin-institute-of-technology/ltu-as/e1rp2dmj/wandb-metadata.json?X-Goog-Algorithm=GOOG4-RSA-SHA256&X-Goog-Credential=gorilla-files-url-signer-man%40wandb-production.iam.gserviceaccount.com%2F20250411%2Fauto%2Fstorage%2Fgoog4_request&X-Goog-Date=20250411T134619Z&X-Goog-Expires=86399&X-Goog-Signature=af0857f67295574884cf2db9abaaccdaaa96b9ef6a6a5bf495355e0bb2cca3709042f1692f52e7c08335e841d771aa914c48aa2d4228797d3d3e27acc636f79795f401e523ff4840008fc280c934439fd7c669288912ffab1d06e6ea6d7178eef4a61385fb1b24d3b9ac99da5340314e08ce8c06f8ab6fc2b7722cd8b0bc6a8f980aa88ef5ab732b624d921cbc59f22107f1b87637d0b0d91a19dde3c63e2ec50bc1158b56888eaa60741932e5fe7f1c0a48b3a5054cb708ce8ca292f7be8005701d9db2893045106437f669bf301dc965b7f38a319f96b5ca65834a568cba009c6f0e70bec1637f97f4c2ffddca24309dbe47014f789317908c2e7990427d8d&X-Goog-SignedHeaders=host&X-User=2931823730: HTTPSConnectionPool(host='storage.googleapis.com', port=443): Max retries exceeded with url: /wandb-production.appspot.com/2931823730-harbin-institute-of-technology/ltu-as/e1rp2dmj/wandb-metadata.json?X-Goog-Algorithm=GOOG4-RSA-SHA256&X-Goog-Credential=gorilla-files-url-signer-man%40wandb-production.iam.gserviceaccount.com%2F20250411%2Fauto%2Fstorage%2Fgoog4_request&X-Goog-Date=20250411T134619Z&X-Goog-Expires=86399&X-Goog-Signature=af0857f67295574884cf2db9abaaccdaaa96b9ef6a6a5bf495355e0bb2cca3709042f1692f52e7c08335e841d771aa914c48aa2d4228797d3d3e27acc636f79795f401e523ff4840008fc280c934439fd7c669288912ffab1d06e6ea6d7178eef4a61385fb1b24d3b9ac99da5340314e08ce8c06f8ab6fc2b7722cd8b0bc6a8f980aa88ef5ab732b624d921cbc59f22107f1b87637d0b0d91a19dde3c63e2ec50bc1158b56888eaa60741932e5fe7f1c0a48b3a5054cb708ce8ca292f7be8005701d9db2893045106437f669bf301dc965b7f38a319f96b5ca65834a568cba009c6f0e70bec1637f97f4c2ffddca24309dbe47014f789317908c2e7990427d8d&X-Goog-SignedHeaders=host&X-User=2931823730 (Caused by NewConnectionError('<urllib3.connection.HTTPSConnection object at 0x7f78a860c220>: Failed to establish a new connection: [Errno 101] Network is unreachable'))
2025-04-11 13:46:36,093 ERROR   wandb-upload_0:5729 [internal_api.py:upload_file():2558] upload_file request headers: {'User-Agent': 'python-requests/2.32.3', 'Accept-Encoding': 'gzip, deflate, br', 'Accept': '*/*', 'Connection': 'keep-alive', 'Content-Length': '2257'}
2025-04-11 13:46:36,093 ERROR   wandb-upload_0:5729 [internal_api.py:upload_file():2560] upload_file response body: 
2025-04-11 13:46:36,894 DEBUG   HandlerThread:5729 [handler.py:handle_request():146] handle_request: status_report
2025-04-11 13:46:37,203 DEBUG   HandlerThread:5729 [handler.py:handle_request():146] handle_request: keepalive
2025-04-11 13:46:37,504 ERROR   wandb-upload_3:5729 [internal_api.py:upload_file():2556] upload_file exception https://storage.googleapis.com/wandb-production.appspot.com/2931823730-harbin-institute-of-technology/ltu-as/e1rp2dmj/conda-environment.yaml?X-Goog-Algorithm=GOOG4-RSA-SHA256&X-Goog-Credential=gorilla-files-url-signer-man%40wandb-production.iam.gserviceaccount.com%2F20250411%2Fauto%2Fstorage%2Fgoog4_request&X-Goog-Date=20250411T134634Z&X-Goog-Expires=86399&X-Goog-Signature=265e438ee1e70b800d8a7fecfc5ad7df5c6466d860f091f7203140cddce9cf7c92daef52f7ce3e701a0c43e1f92589bbf32fcf34e3491bd34b94e81bf4d369c1acaad089236cab81b7188596c894dc002373a96c6f456f16feb1cf4fc97ba6c918c66221de710c322f624fc3beafa22a0e6267b0d3e03a930092368d7bd298205cfb04835e4b98073b7419be36903de0a53256ad826c162ab35548a4b743df5a7f158aa3ba83515129d2bc120a7668d5f6ba72729786d61f070b892b4caae0f489a444d306207d8845ddfaf36cb07c97e8491db8a6cd464df6b44b458fd31bfb7aec6900e7bce07aa5d7d06f66942850410ced96674f6d13dbde8735c065b758&X-Goog-SignedHeaders=host&X-User=2931823730: HTTPSConnectionPool(host='storage.googleapis.com', port=443): Max retries exceeded with url: /wandb-production.appspot.com/2931823730-harbin-institute-of-technology/ltu-as/e1rp2dmj/conda-environment.yaml?X-Goog-Algorithm=GOOG4-RSA-SHA256&X-Goog-Credential=gorilla-files-url-signer-man%40wandb-production.iam.gserviceaccount.com%2F20250411%2Fauto%2Fstorage%2Fgoog4_request&X-Goog-Date=20250411T134634Z&X-Goog-Expires=86399&X-Goog-Signature=265e438ee1e70b800d8a7fecfc5ad7df5c6466d860f091f7203140cddce9cf7c92daef52f7ce3e701a0c43e1f92589bbf32fcf34e3491bd34b94e81bf4d369c1acaad089236cab81b7188596c894dc002373a96c6f456f16feb1cf4fc97ba6c918c66221de710c322f624fc3beafa22a0e6267b0d3e03a930092368d7bd298205cfb04835e4b98073b7419be36903de0a53256ad826c162ab35548a4b743df5a7f158aa3ba83515129d2bc120a7668d5f6ba72729786d61f070b892b4caae0f489a444d306207d8845ddfaf36cb07c97e8491db8a6cd464df6b44b458fd31bfb7aec6900e7bce07aa5d7d06f66942850410ced96674f6d13dbde8735c065b758&X-Goog-SignedHeaders=host&X-User=2931823730 (Caused by NewConnectionError('<urllib3.connection.HTTPSConnection object at 0x7f78a860c4c0>: Failed to establish a new connection: [Errno 101] Network is unreachable'))
2025-04-11 13:46:37,505 ERROR   wandb-upload_3:5729 [internal_api.py:upload_file():2558] upload_file request headers: {'User-Agent': 'python-requests/2.32.3', 'Accept-Encoding': 'gzip, deflate, br', 'Accept': '*/*', 'Connection': 'keep-alive', 'Content-Length': '8281'}
2025-04-11 13:46:37,505 ERROR   wandb-upload_3:5729 [internal_api.py:upload_file():2560] upload_file response body: 
2025-04-11 13:46:37,576 ERROR   wandb-upload_2:5729 [internal_api.py:upload_file():2556] upload_file exception https://storage.googleapis.com/wandb-production.appspot.com/2931823730-harbin-institute-of-technology/ltu-as/e1rp2dmj/requirements.txt?X-Goog-Algorithm=GOOG4-RSA-SHA256&X-Goog-Credential=gorilla-files-url-signer-man%40wandb-production.iam.gserviceaccount.com%2F20250411%2Fauto%2Fstorage%2Fgoog4_request&X-Goog-Date=20250411T134634Z&X-Goog-Expires=86399&X-Goog-Signature=3dfde56506a5eb961db089deed7db6aa48f193bc474ae614780e50f5da53dcad1ceb7b36dacc62c9ba2f21a8b3906e3591e27a1bd626d9c92a37b52c1a3a887ec2cc1e37639eb16971e4ed5e87ad2f243861a2fd54b4baab595fa20f3083675b58d7cba3143227443b1fdd03afbf5a03e6931eba414d96f4dbb387b685789045ce2ef0aadfb6f24c2b11b9e2ddba77726489ca36828d76c037fd3115c31241f3da27efd940eb562db1ac7affe47bc6cc8db3526bcefb0f030f2407394d1964bca766bbd1314ea5301db1ec85783aa70e6fe219f7c078906511102594baca5f8df23782c0692dd52f41467d465590ca5b32b230ff1554c23fd76e79fdadc28df4&X-Goog-SignedHeaders=host&X-User=2931823730: HTTPSConnectionPool(host='storage.googleapis.com', port=443): Max retries exceeded with url: /wandb-production.appspot.com/2931823730-harbin-institute-of-technology/ltu-as/e1rp2dmj/requirements.txt?X-Goog-Algorithm=GOOG4-RSA-SHA256&X-Goog-Credential=gorilla-files-url-signer-man%40wandb-production.iam.gserviceaccount.com%2F20250411%2Fauto%2Fstorage%2Fgoog4_request&X-Goog-Date=20250411T134634Z&X-Goog-Expires=86399&X-Goog-Signature=3dfde56506a5eb961db089deed7db6aa48f193bc474ae614780e50f5da53dcad1ceb7b36dacc62c9ba2f21a8b3906e3591e27a1bd626d9c92a37b52c1a3a887ec2cc1e37639eb16971e4ed5e87ad2f243861a2fd54b4baab595fa20f3083675b58d7cba3143227443b1fdd03afbf5a03e6931eba414d96f4dbb387b685789045ce2ef0aadfb6f24c2b11b9e2ddba77726489ca36828d76c037fd3115c31241f3da27efd940eb562db1ac7affe47bc6cc8db3526bcefb0f030f2407394d1964bca766bbd1314ea5301db1ec85783aa70e6fe219f7c078906511102594baca5f8df23782c0692dd52f41467d465590ca5b32b230ff1554c23fd76e79fdadc28df4&X-Goog-SignedHeaders=host&X-User=2931823730 (Caused by NewConnectionError('<urllib3.connection.HTTPSConnection object at 0x7f78ba74beb0>: Failed to establish a new connection: [Errno 101] Network is unreachable'))
2025-04-11 13:46:37,576 ERROR   wandb-upload_2:5729 [internal_api.py:upload_file():2558] upload_file request headers: {'User-Agent': 'python-requests/2.32.3', 'Accept-Encoding': 'gzip, deflate, br', 'Accept': '*/*', 'Connection': 'keep-alive', 'Content-Length': '4212'}
2025-04-11 13:46:37,576 ERROR   wandb-upload_2:5729 [internal_api.py:upload_file():2560] upload_file response body: 
2025-04-11 13:46:37,722 ERROR   wandb-upload_1:5729 [internal_api.py:upload_file():2556] upload_file exception https://storage.googleapis.com/wandb-production.appspot.com/2931823730-harbin-institute-of-technology/ltu-as/e1rp2dmj/config.yaml?X-Goog-Algorithm=GOOG4-RSA-SHA256&X-Goog-Credential=gorilla-files-url-signer-man%40wandb-production.iam.gserviceaccount.com%2F20250411%2Fauto%2Fstorage%2Fgoog4_request&X-Goog-Date=20250411T134634Z&X-Goog-Expires=86399&X-Goog-Signature=4cd10bd589b82e59e27f62a38c7bb859f6315c8a3069f8c95f2b591b6d3a6f96f6cd958040991552a4208cd0e515ea04482dcb1ca32f1ee8f112a9b042da67ef144cb108a105d48d05bdbb86727c5c582615c7931ca7875be77f1e227f3cfbbbabc8417731c4b82ab6769881ee62e375155669ebec4934959856d4a8a2e6fdeaeab1cb06373c7866934a72235500ff61608d04e6a4e6447283f4046d87760e7658444706049c275c8f2fc043498682ac8fbdca5f494b43bd9838f8d8cb8009ffb7896ffb5c219b1f6a8fc992a9df4b59754e5d93a80dafdecf9a6b991c4defa8dc75553a784dcdc6ae3d13b2b7dd71a715a1f70a81feac5341924b175293b18a&X-Goog-SignedHeaders=host&X-User=2931823730: HTTPSConnectionPool(host='storage.googleapis.com', port=443): Max retries exceeded with url: /wandb-production.appspot.com/2931823730-harbin-institute-of-technology/ltu-as/e1rp2dmj/config.yaml?X-Goog-Algorithm=GOOG4-RSA-SHA256&X-Goog-Credential=gorilla-files-url-signer-man%40wandb-production.iam.gserviceaccount.com%2F20250411%2Fauto%2Fstorage%2Fgoog4_request&X-Goog-Date=20250411T134634Z&X-Goog-Expires=86399&X-Goog-Signature=4cd10bd589b82e59e27f62a38c7bb859f6315c8a3069f8c95f2b591b6d3a6f96f6cd958040991552a4208cd0e515ea04482dcb1ca32f1ee8f112a9b042da67ef144cb108a105d48d05bdbb86727c5c582615c7931ca7875be77f1e227f3cfbbbabc8417731c4b82ab6769881ee62e375155669ebec4934959856d4a8a2e6fdeaeab1cb06373c7866934a72235500ff61608d04e6a4e6447283f4046d87760e7658444706049c275c8f2fc043498682ac8fbdca5f494b43bd9838f8d8cb8009ffb7896ffb5c219b1f6a8fc992a9df4b59754e5d93a80dafdecf9a6b991c4defa8dc75553a784dcdc6ae3d13b2b7dd71a715a1f70a81feac5341924b175293b18a&X-Goog-SignedHeaders=host&X-User=2931823730 (Caused by NewConnectionError('<urllib3.connection.HTTPSConnection object at 0x7f78ba748eb0>: Failed to establish a new connection: [Errno 101] Network is unreachable'))
2025-04-11 13:46:37,722 ERROR   wandb-upload_1:5729 [internal_api.py:upload_file():2558] upload_file request headers: {'User-Agent': 'python-requests/2.32.3', 'Accept-Encoding': 'gzip, deflate, br', 'Accept': '*/*', 'Connection': 'keep-alive', 'Content-Length': '8684'}
2025-04-11 13:46:37,722 ERROR   wandb-upload_1:5729 [internal_api.py:upload_file():2560] upload_file response body: 
2025-04-11 13:46:37,745 ERROR   wandb-upload_4:5729 [internal_api.py:upload_file():2556] upload_file exception https://storage.googleapis.com/wandb-production.appspot.com/2931823730-harbin-institute-of-technology/ltu-as/e1rp2dmj/output.log?X-Goog-Algorithm=GOOG4-RSA-SHA256&X-Goog-Credential=gorilla-files-url-signer-man%40wandb-production.iam.gserviceaccount.com%2F20250411%2Fauto%2Fstorage%2Fgoog4_request&X-Goog-Date=20250411T134634Z&X-Goog-Expires=86399&X-Goog-Signature=1128654687b0bf6a676feb1b3994c67f90d4d5ad203efb1db55a64de90d2e137a92e4605a00647015e03b194032e4403003e9fa8121264c1d3fec46eff90feac3c3cffb282d22451c5c6acb440a025e6ed761bf74b5259a8e5e079edcfa55a2cb62cae67f6be3e484d87677dfd925fed1422544e6d25665d96085dab9beb1aba7f0074d9632139baf8e19153ba1bd3f3833ab064bcdd45f81fc55148a4ea0e4c3b3e9d308644abc1ba92aee0756638463b58ca487c63f3ef2b21a51c344d3e9827d9c479edcffa4422015eebc1612fe497273ae11d9a40dc95b6ecf080a596c4206a01011244acfe3450e296dc68077ded4fb723f67f357914c5c7890a257fef&X-Goog-SignedHeaders=host&X-User=2931823730: HTTPSConnectionPool(host='storage.googleapis.com', port=443): Max retries exceeded with url: /wandb-production.appspot.com/2931823730-harbin-institute-of-technology/ltu-as/e1rp2dmj/output.log?X-Goog-Algorithm=GOOG4-RSA-SHA256&X-Goog-Credential=gorilla-files-url-signer-man%40wandb-production.iam.gserviceaccount.com%2F20250411%2Fauto%2Fstorage%2Fgoog4_request&X-Goog-Date=20250411T134634Z&X-Goog-Expires=86399&X-Goog-Signature=1128654687b0bf6a676feb1b3994c67f90d4d5ad203efb1db55a64de90d2e137a92e4605a00647015e03b194032e4403003e9fa8121264c1d3fec46eff90feac3c3cffb282d22451c5c6acb440a025e6ed761bf74b5259a8e5e079edcfa55a2cb62cae67f6be3e484d87677dfd925fed1422544e6d25665d96085dab9beb1aba7f0074d9632139baf8e19153ba1bd3f3833ab064bcdd45f81fc55148a4ea0e4c3b3e9d308644abc1ba92aee0756638463b58ca487c63f3ef2b21a51c344d3e9827d9c479edcffa4422015eebc1612fe497273ae11d9a40dc95b6ecf080a596c4206a01011244acfe3450e296dc68077ded4fb723f67f357914c5c7890a257fef&X-Goog-SignedHeaders=host&X-User=2931823730 (Caused by NewConnectionError('<urllib3.connection.HTTPSConnection object at 0x7f78a9fc8ac0>: Failed to establish a new connection: [Errno 101] Network is unreachable'))
2025-04-11 13:46:37,745 ERROR   wandb-upload_4:5729 [internal_api.py:upload_file():2558] upload_file request headers: {'User-Agent': 'python-requests/2.32.3', 'Accept-Encoding': 'gzip, deflate, br', 'Accept': '*/*', 'Connection': 'keep-alive', 'Content-Length': '5068'}
2025-04-11 13:46:37,745 ERROR   wandb-upload_4:5729 [internal_api.py:upload_file():2560] upload_file response body: 
2025-04-11 13:46:37,830 ERROR   wandb-upload_5:5729 [internal_api.py:upload_file():2556] upload_file exception https://storage.googleapis.com/wandb-production.appspot.com/2931823730-harbin-institute-of-technology/ltu-as/e1rp2dmj/wandb-summary.json?X-Goog-Algorithm=GOOG4-RSA-SHA256&X-Goog-Credential=gorilla-files-url-signer-man%40wandb-production.iam.gserviceaccount.com%2F20250411%2Fauto%2Fstorage%2Fgoog4_request&X-Goog-Date=20250411T134634Z&X-Goog-Expires=86399&X-Goog-Signature=ac5e445aae328ee3ae9946dd2ab55fbf6f673f45f548df81577386d8397df42b9cec8bc5e03d7769bcf073b2b1aaf22a28439cb78c2913d462a812b518f0c77dc74ea5b3ff300544c40e4e06f62e863a922a5fd4736bb164c2a3dbed5d8ac771e3d73c275377bf6d644b25e54e374105fae21c754a7d00451e6f4b9bdb8eef6d007da49a984adb31101ff795c71ff81bfae958b73af8919398e18a58f6835c41d1d8b808f4dcfb20fa53b90aed702ce33dd3a843c72139afeadd14489fd191a910b1f046a684e2d5ec5d4548d93932e2ac3b57577beb5db408798c4892a905cf5ef8ecf5f2a91ed8d3d9bd832fd9a08889d3ec1ad786378a3ba3a8af22b6d471&X-Goog-SignedHeaders=host&X-User=2931823730: HTTPSConnectionPool(host='storage.googleapis.com', port=443): Max retries exceeded with url: /wandb-production.appspot.com/2931823730-harbin-institute-of-technology/ltu-as/e1rp2dmj/wandb-summary.json?X-Goog-Algorithm=GOOG4-RSA-SHA256&X-Goog-Credential=gorilla-files-url-signer-man%40wandb-production.iam.gserviceaccount.com%2F20250411%2Fauto%2Fstorage%2Fgoog4_request&X-Goog-Date=20250411T134634Z&X-Goog-Expires=86399&X-Goog-Signature=ac5e445aae328ee3ae9946dd2ab55fbf6f673f45f548df81577386d8397df42b9cec8bc5e03d7769bcf073b2b1aaf22a28439cb78c2913d462a812b518f0c77dc74ea5b3ff300544c40e4e06f62e863a922a5fd4736bb164c2a3dbed5d8ac771e3d73c275377bf6d644b25e54e374105fae21c754a7d00451e6f4b9bdb8eef6d007da49a984adb31101ff795c71ff81bfae958b73af8919398e18a58f6835c41d1d8b808f4dcfb20fa53b90aed702ce33dd3a843c72139afeadd14489fd191a910b1f046a684e2d5ec5d4548d93932e2ac3b57577beb5db408798c4892a905cf5ef8ecf5f2a91ed8d3d9bd832fd9a08889d3ec1ad786378a3ba3a8af22b6d471&X-Goog-SignedHeaders=host&X-User=2931823730 (Caused by NewConnectionError('<urllib3.connection.HTTPSConnection object at 0x7f78a9fcb340>: Failed to establish a new connection: [Errno 101] Network is unreachable'))
2025-04-11 13:46:37,830 ERROR   wandb-upload_5:5729 [internal_api.py:upload_file():2558] upload_file request headers: {'User-Agent': 'python-requests/2.32.3', 'Accept-Encoding': 'gzip, deflate, br', 'Accept': '*/*', 'Connection': 'keep-alive', 'Content-Length': '27'}
2025-04-11 13:46:37,830 ERROR   wandb-upload_5:5729 [internal_api.py:upload_file():2560] upload_file response body: 
2025-04-11 13:46:41,895 DEBUG   HandlerThread:5729 [handler.py:handle_request():146] handle_request: status_report
2025-04-11 13:46:42,187 ERROR   wandb-upload_5:5729 [internal_api.py:upload_file():2556] upload_file exception https://storage.googleapis.com/wandb-production.appspot.com/2931823730-harbin-institute-of-technology/ltu-as/e1rp2dmj/wandb-summary.json?X-Goog-Algorithm=GOOG4-RSA-SHA256&X-Goog-Credential=gorilla-files-url-signer-man%40wandb-production.iam.gserviceaccount.com%2F20250411%2Fauto%2Fstorage%2Fgoog4_request&X-Goog-Date=20250411T134634Z&X-Goog-Expires=86399&X-Goog-Signature=ac5e445aae328ee3ae9946dd2ab55fbf6f673f45f548df81577386d8397df42b9cec8bc5e03d7769bcf073b2b1aaf22a28439cb78c2913d462a812b518f0c77dc74ea5b3ff300544c40e4e06f62e863a922a5fd4736bb164c2a3dbed5d8ac771e3d73c275377bf6d644b25e54e374105fae21c754a7d00451e6f4b9bdb8eef6d007da49a984adb31101ff795c71ff81bfae958b73af8919398e18a58f6835c41d1d8b808f4dcfb20fa53b90aed702ce33dd3a843c72139afeadd14489fd191a910b1f046a684e2d5ec5d4548d93932e2ac3b57577beb5db408798c4892a905cf5ef8ecf5f2a91ed8d3d9bd832fd9a08889d3ec1ad786378a3ba3a8af22b6d471&X-Goog-SignedHeaders=host&X-User=2931823730: HTTPSConnectionPool(host='storage.googleapis.com', port=443): Max retries exceeded with url: /wandb-production.appspot.com/2931823730-harbin-institute-of-technology/ltu-as/e1rp2dmj/wandb-summary.json?X-Goog-Algorithm=GOOG4-RSA-SHA256&X-Goog-Credential=gorilla-files-url-signer-man%40wandb-production.iam.gserviceaccount.com%2F20250411%2Fauto%2Fstorage%2Fgoog4_request&X-Goog-Date=20250411T134634Z&X-Goog-Expires=86399&X-Goog-Signature=ac5e445aae328ee3ae9946dd2ab55fbf6f673f45f548df81577386d8397df42b9cec8bc5e03d7769bcf073b2b1aaf22a28439cb78c2913d462a812b518f0c77dc74ea5b3ff300544c40e4e06f62e863a922a5fd4736bb164c2a3dbed5d8ac771e3d73c275377bf6d644b25e54e374105fae21c754a7d00451e6f4b9bdb8eef6d007da49a984adb31101ff795c71ff81bfae958b73af8919398e18a58f6835c41d1d8b808f4dcfb20fa53b90aed702ce33dd3a843c72139afeadd14489fd191a910b1f046a684e2d5ec5d4548d93932e2ac3b57577beb5db408798c4892a905cf5ef8ecf5f2a91ed8d3d9bd832fd9a08889d3ec1ad786378a3ba3a8af22b6d471&X-Goog-SignedHeaders=host&X-User=2931823730 (Caused by NewConnectionError('<urllib3.connection.HTTPSConnection object at 0x7f78a9fc8580>: Failed to establish a new connection: [Errno 101] Network is unreachable'))
2025-04-11 13:46:42,188 ERROR   wandb-upload_5:5729 [internal_api.py:upload_file():2558] upload_file request headers: {'User-Agent': 'python-requests/2.32.3', 'Accept-Encoding': 'gzip, deflate, br', 'Accept': '*/*', 'Connection': 'keep-alive', 'Content-Length': '27'}
2025-04-11 13:46:42,189 ERROR   wandb-upload_5:5729 [internal_api.py:upload_file():2560] upload_file response body: 
2025-04-11 13:46:42,205 DEBUG   HandlerThread:5729 [handler.py:handle_request():146] handle_request: keepalive
2025-04-11 13:46:42,289 ERROR   wandb-upload_2:5729 [internal_api.py:upload_file():2556] upload_file exception https://storage.googleapis.com/wandb-production.appspot.com/2931823730-harbin-institute-of-technology/ltu-as/e1rp2dmj/requirements.txt?X-Goog-Algorithm=GOOG4-RSA-SHA256&X-Goog-Credential=gorilla-files-url-signer-man%40wandb-production.iam.gserviceaccount.com%2F20250411%2Fauto%2Fstorage%2Fgoog4_request&X-Goog-Date=20250411T134634Z&X-Goog-Expires=86399&X-Goog-Signature=3dfde56506a5eb961db089deed7db6aa48f193bc474ae614780e50f5da53dcad1ceb7b36dacc62c9ba2f21a8b3906e3591e27a1bd626d9c92a37b52c1a3a887ec2cc1e37639eb16971e4ed5e87ad2f243861a2fd54b4baab595fa20f3083675b58d7cba3143227443b1fdd03afbf5a03e6931eba414d96f4dbb387b685789045ce2ef0aadfb6f24c2b11b9e2ddba77726489ca36828d76c037fd3115c31241f3da27efd940eb562db1ac7affe47bc6cc8db3526bcefb0f030f2407394d1964bca766bbd1314ea5301db1ec85783aa70e6fe219f7c078906511102594baca5f8df23782c0692dd52f41467d465590ca5b32b230ff1554c23fd76e79fdadc28df4&X-Goog-SignedHeaders=host&X-User=2931823730: HTTPSConnectionPool(host='storage.googleapis.com', port=443): Max retries exceeded with url: /wandb-production.appspot.com/2931823730-harbin-institute-of-technology/ltu-as/e1rp2dmj/requirements.txt?X-Goog-Algorithm=GOOG4-RSA-SHA256&X-Goog-Credential=gorilla-files-url-signer-man%40wandb-production.iam.gserviceaccount.com%2F20250411%2Fauto%2Fstorage%2Fgoog4_request&X-Goog-Date=20250411T134634Z&X-Goog-Expires=86399&X-Goog-Signature=3dfde56506a5eb961db089deed7db6aa48f193bc474ae614780e50f5da53dcad1ceb7b36dacc62c9ba2f21a8b3906e3591e27a1bd626d9c92a37b52c1a3a887ec2cc1e37639eb16971e4ed5e87ad2f243861a2fd54b4baab595fa20f3083675b58d7cba3143227443b1fdd03afbf5a03e6931eba414d96f4dbb387b685789045ce2ef0aadfb6f24c2b11b9e2ddba77726489ca36828d76c037fd3115c31241f3da27efd940eb562db1ac7affe47bc6cc8db3526bcefb0f030f2407394d1964bca766bbd1314ea5301db1ec85783aa70e6fe219f7c078906511102594baca5f8df23782c0692dd52f41467d465590ca5b32b230ff1554c23fd76e79fdadc28df4&X-Goog-SignedHeaders=host&X-User=2931823730 (Caused by NewConnectionError('<urllib3.connection.HTTPSConnection object at 0x7f78a9fcbc70>: Failed to establish a new connection: [Errno 101] Network is unreachable'))
2025-04-11 13:46:42,289 ERROR   wandb-upload_2:5729 [internal_api.py:upload_file():2558] upload_file request headers: {'User-Agent': 'python-requests/2.32.3', 'Accept-Encoding': 'gzip, deflate, br', 'Accept': '*/*', 'Connection': 'keep-alive', 'Content-Length': '4212'}
2025-04-11 13:46:42,289 ERROR   wandb-upload_3:5729 [internal_api.py:upload_file():2556] upload_file exception https://storage.googleapis.com/wandb-production.appspot.com/2931823730-harbin-institute-of-technology/ltu-as/e1rp2dmj/conda-environment.yaml?X-Goog-Algorithm=GOOG4-RSA-SHA256&X-Goog-Credential=gorilla-files-url-signer-man%40wandb-production.iam.gserviceaccount.com%2F20250411%2Fauto%2Fstorage%2Fgoog4_request&X-Goog-Date=20250411T134634Z&X-Goog-Expires=86399&X-Goog-Signature=265e438ee1e70b800d8a7fecfc5ad7df5c6466d860f091f7203140cddce9cf7c92daef52f7ce3e701a0c43e1f92589bbf32fcf34e3491bd34b94e81bf4d369c1acaad089236cab81b7188596c894dc002373a96c6f456f16feb1cf4fc97ba6c918c66221de710c322f624fc3beafa22a0e6267b0d3e03a930092368d7bd298205cfb04835e4b98073b7419be36903de0a53256ad826c162ab35548a4b743df5a7f158aa3ba83515129d2bc120a7668d5f6ba72729786d61f070b892b4caae0f489a444d306207d8845ddfaf36cb07c97e8491db8a6cd464df6b44b458fd31bfb7aec6900e7bce07aa5d7d06f66942850410ced96674f6d13dbde8735c065b758&X-Goog-SignedHeaders=host&X-User=2931823730: HTTPSConnectionPool(host='storage.googleapis.com', port=443): Max retries exceeded with url: /wandb-production.appspot.com/2931823730-harbin-institute-of-technology/ltu-as/e1rp2dmj/conda-environment.yaml?X-Goog-Algorithm=GOOG4-RSA-SHA256&X-Goog-Credential=gorilla-files-url-signer-man%40wandb-production.iam.gserviceaccount.com%2F20250411%2Fauto%2Fstorage%2Fgoog4_request&X-Goog-Date=20250411T134634Z&X-Goog-Expires=86399&X-Goog-Signature=265e438ee1e70b800d8a7fecfc5ad7df5c6466d860f091f7203140cddce9cf7c92daef52f7ce3e701a0c43e1f92589bbf32fcf34e3491bd34b94e81bf4d369c1acaad089236cab81b7188596c894dc002373a96c6f456f16feb1cf4fc97ba6c918c66221de710c322f624fc3beafa22a0e6267b0d3e03a930092368d7bd298205cfb04835e4b98073b7419be36903de0a53256ad826c162ab35548a4b743df5a7f158aa3ba83515129d2bc120a7668d5f6ba72729786d61f070b892b4caae0f489a444d306207d8845ddfaf36cb07c97e8491db8a6cd464df6b44b458fd31bfb7aec6900e7bce07aa5d7d06f66942850410ced96674f6d13dbde8735c065b758&X-Goog-SignedHeaders=host&X-User=2931823730 (Caused by NewConnectionError('<urllib3.connection.HTTPSConnection object at 0x7f78a9fcba90>: Failed to establish a new connection: [Errno 101] Network is unreachable'))
2025-04-11 13:46:42,290 ERROR   wandb-upload_3:5729 [internal_api.py:upload_file():2558] upload_file request headers: {'User-Agent': 'python-requests/2.32.3', 'Accept-Encoding': 'gzip, deflate, br', 'Accept': '*/*', 'Connection': 'keep-alive', 'Content-Length': '8281'}
2025-04-11 13:46:42,290 ERROR   wandb-upload_3:5729 [internal_api.py:upload_file():2560] upload_file response body: 
2025-04-11 13:46:42,289 ERROR   wandb-upload_2:5729 [internal_api.py:upload_file():2560] upload_file response body: 
2025-04-11 13:46:42,551 ERROR   wandb-upload_4:5729 [internal_api.py:upload_file():2556] upload_file exception https://storage.googleapis.com/wandb-production.appspot.com/2931823730-harbin-institute-of-technology/ltu-as/e1rp2dmj/output.log?X-Goog-Algorithm=GOOG4-RSA-SHA256&X-Goog-Credential=gorilla-files-url-signer-man%40wandb-production.iam.gserviceaccount.com%2F20250411%2Fauto%2Fstorage%2Fgoog4_request&X-Goog-Date=20250411T134634Z&X-Goog-Expires=86399&X-Goog-Signature=1128654687b0bf6a676feb1b3994c67f90d4d5ad203efb1db55a64de90d2e137a92e4605a00647015e03b194032e4403003e9fa8121264c1d3fec46eff90feac3c3cffb282d22451c5c6acb440a025e6ed761bf74b5259a8e5e079edcfa55a2cb62cae67f6be3e484d87677dfd925fed1422544e6d25665d96085dab9beb1aba7f0074d9632139baf8e19153ba1bd3f3833ab064bcdd45f81fc55148a4ea0e4c3b3e9d308644abc1ba92aee0756638463b58ca487c63f3ef2b21a51c344d3e9827d9c479edcffa4422015eebc1612fe497273ae11d9a40dc95b6ecf080a596c4206a01011244acfe3450e296dc68077ded4fb723f67f357914c5c7890a257fef&X-Goog-SignedHeaders=host&X-User=2931823730: HTTPSConnectionPool(host='storage.googleapis.com', port=443): Max retries exceeded with url: /wandb-production.appspot.com/2931823730-harbin-institute-of-technology/ltu-as/e1rp2dmj/output.log?X-Goog-Algorithm=GOOG4-RSA-SHA256&X-Goog-Credential=gorilla-files-url-signer-man%40wandb-production.iam.gserviceaccount.com%2F20250411%2Fauto%2Fstorage%2Fgoog4_request&X-Goog-Date=20250411T134634Z&X-Goog-Expires=86399&X-Goog-Signature=1128654687b0bf6a676feb1b3994c67f90d4d5ad203efb1db55a64de90d2e137a92e4605a00647015e03b194032e4403003e9fa8121264c1d3fec46eff90feac3c3cffb282d22451c5c6acb440a025e6ed761bf74b5259a8e5e079edcfa55a2cb62cae67f6be3e484d87677dfd925fed1422544e6d25665d96085dab9beb1aba7f0074d9632139baf8e19153ba1bd3f3833ab064bcdd45f81fc55148a4ea0e4c3b3e9d308644abc1ba92aee0756638463b58ca487c63f3ef2b21a51c344d3e9827d9c479edcffa4422015eebc1612fe497273ae11d9a40dc95b6ecf080a596c4206a01011244acfe3450e296dc68077ded4fb723f67f357914c5c7890a257fef&X-Goog-SignedHeaders=host&X-User=2931823730 (Caused by NewConnectionError('<urllib3.connection.HTTPSConnection object at 0x7f78a860c040>: Failed to establish a new connection: [Errno 101] Network is unreachable'))
2025-04-11 13:46:42,551 ERROR   wandb-upload_4:5729 [internal_api.py:upload_file():2558] upload_file request headers: {'User-Agent': 'python-requests/2.32.3', 'Accept-Encoding': 'gzip, deflate, br', 'Accept': '*/*', 'Connection': 'keep-alive', 'Content-Length': '5068'}
2025-04-11 13:46:42,551 ERROR   wandb-upload_4:5729 [internal_api.py:upload_file():2560] upload_file response body: 
2025-04-11 13:46:42,691 ERROR   wandb-upload_1:5729 [internal_api.py:upload_file():2556] upload_file exception https://storage.googleapis.com/wandb-production.appspot.com/2931823730-harbin-institute-of-technology/ltu-as/e1rp2dmj/config.yaml?X-Goog-Algorithm=GOOG4-RSA-SHA256&X-Goog-Credential=gorilla-files-url-signer-man%40wandb-production.iam.gserviceaccount.com%2F20250411%2Fauto%2Fstorage%2Fgoog4_request&X-Goog-Date=20250411T134634Z&X-Goog-Expires=86399&X-Goog-Signature=4cd10bd589b82e59e27f62a38c7bb859f6315c8a3069f8c95f2b591b6d3a6f96f6cd958040991552a4208cd0e515ea04482dcb1ca32f1ee8f112a9b042da67ef144cb108a105d48d05bdbb86727c5c582615c7931ca7875be77f1e227f3cfbbbabc8417731c4b82ab6769881ee62e375155669ebec4934959856d4a8a2e6fdeaeab1cb06373c7866934a72235500ff61608d04e6a4e6447283f4046d87760e7658444706049c275c8f2fc043498682ac8fbdca5f494b43bd9838f8d8cb8009ffb7896ffb5c219b1f6a8fc992a9df4b59754e5d93a80dafdecf9a6b991c4defa8dc75553a784dcdc6ae3d13b2b7dd71a715a1f70a81feac5341924b175293b18a&X-Goog-SignedHeaders=host&X-User=2931823730: HTTPSConnectionPool(host='storage.googleapis.com', port=443): Max retries exceeded with url: /wandb-production.appspot.com/2931823730-harbin-institute-of-technology/ltu-as/e1rp2dmj/config.yaml?X-Goog-Algorithm=GOOG4-RSA-SHA256&X-Goog-Credential=gorilla-files-url-signer-man%40wandb-production.iam.gserviceaccount.com%2F20250411%2Fauto%2Fstorage%2Fgoog4_request&X-Goog-Date=20250411T134634Z&X-Goog-Expires=86399&X-Goog-Signature=4cd10bd589b82e59e27f62a38c7bb859f6315c8a3069f8c95f2b591b6d3a6f96f6cd958040991552a4208cd0e515ea04482dcb1ca32f1ee8f112a9b042da67ef144cb108a105d48d05bdbb86727c5c582615c7931ca7875be77f1e227f3cfbbbabc8417731c4b82ab6769881ee62e375155669ebec4934959856d4a8a2e6fdeaeab1cb06373c7866934a72235500ff61608d04e6a4e6447283f4046d87760e7658444706049c275c8f2fc043498682ac8fbdca5f494b43bd9838f8d8cb8009ffb7896ffb5c219b1f6a8fc992a9df4b59754e5d93a80dafdecf9a6b991c4defa8dc75553a784dcdc6ae3d13b2b7dd71a715a1f70a81feac5341924b175293b18a&X-Goog-SignedHeaders=host&X-User=2931823730 (Caused by NewConnectionError('<urllib3.connection.HTTPSConnection object at 0x7f78a860cc70>: Failed to establish a new connection: [Errno 101] Network is unreachable'))
2025-04-11 13:46:42,692 ERROR   wandb-upload_1:5729 [internal_api.py:upload_file():2558] upload_file request headers: {'User-Agent': 'python-requests/2.32.3', 'Accept-Encoding': 'gzip, deflate, br', 'Accept': '*/*', 'Connection': 'keep-alive', 'Content-Length': '8684'}
2025-04-11 13:46:42,692 ERROR   wandb-upload_1:5729 [internal_api.py:upload_file():2560] upload_file response body: 
2025-04-11 13:46:46,896 DEBUG   HandlerThread:5729 [handler.py:handle_request():146] handle_request: status_report
2025-04-11 13:46:47,207 DEBUG   HandlerThread:5729 [handler.py:handle_request():146] handle_request: keepalive
2025-04-11 13:46:50,241 ERROR   wandb-upload_5:5729 [internal_api.py:upload_file():2556] upload_file exception https://storage.googleapis.com/wandb-production.appspot.com/2931823730-harbin-institute-of-technology/ltu-as/e1rp2dmj/wandb-summary.json?X-Goog-Algorithm=GOOG4-RSA-SHA256&X-Goog-Credential=gorilla-files-url-signer-man%40wandb-production.iam.gserviceaccount.com%2F20250411%2Fauto%2Fstorage%2Fgoog4_request&X-Goog-Date=20250411T134634Z&X-Goog-Expires=86399&X-Goog-Signature=ac5e445aae328ee3ae9946dd2ab55fbf6f673f45f548df81577386d8397df42b9cec8bc5e03d7769bcf073b2b1aaf22a28439cb78c2913d462a812b518f0c77dc74ea5b3ff300544c40e4e06f62e863a922a5fd4736bb164c2a3dbed5d8ac771e3d73c275377bf6d644b25e54e374105fae21c754a7d00451e6f4b9bdb8eef6d007da49a984adb31101ff795c71ff81bfae958b73af8919398e18a58f6835c41d1d8b808f4dcfb20fa53b90aed702ce33dd3a843c72139afeadd14489fd191a910b1f046a684e2d5ec5d4548d93932e2ac3b57577beb5db408798c4892a905cf5ef8ecf5f2a91ed8d3d9bd832fd9a08889d3ec1ad786378a3ba3a8af22b6d471&X-Goog-SignedHeaders=host&X-User=2931823730: HTTPSConnectionPool(host='storage.googleapis.com', port=443): Max retries exceeded with url: /wandb-production.appspot.com/2931823730-harbin-institute-of-technology/ltu-as/e1rp2dmj/wandb-summary.json?X-Goog-Algorithm=GOOG4-RSA-SHA256&X-Goog-Credential=gorilla-files-url-signer-man%40wandb-production.iam.gserviceaccount.com%2F20250411%2Fauto%2Fstorage%2Fgoog4_request&X-Goog-Date=20250411T134634Z&X-Goog-Expires=86399&X-Goog-Signature=ac5e445aae328ee3ae9946dd2ab55fbf6f673f45f548df81577386d8397df42b9cec8bc5e03d7769bcf073b2b1aaf22a28439cb78c2913d462a812b518f0c77dc74ea5b3ff300544c40e4e06f62e863a922a5fd4736bb164c2a3dbed5d8ac771e3d73c275377bf6d644b25e54e374105fae21c754a7d00451e6f4b9bdb8eef6d007da49a984adb31101ff795c71ff81bfae958b73af8919398e18a58f6835c41d1d8b808f4dcfb20fa53b90aed702ce33dd3a843c72139afeadd14489fd191a910b1f046a684e2d5ec5d4548d93932e2ac3b57577beb5db408798c4892a905cf5ef8ecf5f2a91ed8d3d9bd832fd9a08889d3ec1ad786378a3ba3a8af22b6d471&X-Goog-SignedHeaders=host&X-User=2931823730 (Caused by NewConnectionError('<urllib3.connection.HTTPSConnection object at 0x7f78a860d1b0>: Failed to establish a new connection: [Errno 101] Network is unreachable'))
2025-04-11 13:46:50,241 ERROR   wandb-upload_5:5729 [internal_api.py:upload_file():2558] upload_file request headers: {'User-Agent': 'python-requests/2.32.3', 'Accept-Encoding': 'gzip, deflate, br', 'Accept': '*/*', 'Connection': 'keep-alive', 'Content-Length': '27'}
2025-04-11 13:46:50,241 ERROR   wandb-upload_5:5729 [internal_api.py:upload_file():2560] upload_file response body: 
2025-04-11 13:46:51,877 ERROR   wandb-upload_4:5729 [internal_api.py:upload_file():2556] upload_file exception https://storage.googleapis.com/wandb-production.appspot.com/2931823730-harbin-institute-of-technology/ltu-as/e1rp2dmj/output.log?X-Goog-Algorithm=GOOG4-RSA-SHA256&X-Goog-Credential=gorilla-files-url-signer-man%40wandb-production.iam.gserviceaccount.com%2F20250411%2Fauto%2Fstorage%2Fgoog4_request&X-Goog-Date=20250411T134634Z&X-Goog-Expires=86399&X-Goog-Signature=1128654687b0bf6a676feb1b3994c67f90d4d5ad203efb1db55a64de90d2e137a92e4605a00647015e03b194032e4403003e9fa8121264c1d3fec46eff90feac3c3cffb282d22451c5c6acb440a025e6ed761bf74b5259a8e5e079edcfa55a2cb62cae67f6be3e484d87677dfd925fed1422544e6d25665d96085dab9beb1aba7f0074d9632139baf8e19153ba1bd3f3833ab064bcdd45f81fc55148a4ea0e4c3b3e9d308644abc1ba92aee0756638463b58ca487c63f3ef2b21a51c344d3e9827d9c479edcffa4422015eebc1612fe497273ae11d9a40dc95b6ecf080a596c4206a01011244acfe3450e296dc68077ded4fb723f67f357914c5c7890a257fef&X-Goog-SignedHeaders=host&X-User=2931823730: HTTPSConnectionPool(host='storage.googleapis.com', port=443): Max retries exceeded with url: /wandb-production.appspot.com/2931823730-harbin-institute-of-technology/ltu-as/e1rp2dmj/output.log?X-Goog-Algorithm=GOOG4-RSA-SHA256&X-Goog-Credential=gorilla-files-url-signer-man%40wandb-production.iam.gserviceaccount.com%2F20250411%2Fauto%2Fstorage%2Fgoog4_request&X-Goog-Date=20250411T134634Z&X-Goog-Expires=86399&X-Goog-Signature=1128654687b0bf6a676feb1b3994c67f90d4d5ad203efb1db55a64de90d2e137a92e4605a00647015e03b194032e4403003e9fa8121264c1d3fec46eff90feac3c3cffb282d22451c5c6acb440a025e6ed761bf74b5259a8e5e079edcfa55a2cb62cae67f6be3e484d87677dfd925fed1422544e6d25665d96085dab9beb1aba7f0074d9632139baf8e19153ba1bd3f3833ab064bcdd45f81fc55148a4ea0e4c3b3e9d308644abc1ba92aee0756638463b58ca487c63f3ef2b21a51c344d3e9827d9c479edcffa4422015eebc1612fe497273ae11d9a40dc95b6ecf080a596c4206a01011244acfe3450e296dc68077ded4fb723f67f357914c5c7890a257fef&X-Goog-SignedHeaders=host&X-User=2931823730 (Caused by NewConnectionError('<urllib3.connection.HTTPSConnection object at 0x7f78a9fca860>: Failed to establish a new connection: [Errno 101] Network is unreachable'))
2025-04-11 13:46:51,877 ERROR   wandb-upload_4:5729 [internal_api.py:upload_file():2558] upload_file request headers: {'User-Agent': 'python-requests/2.32.3', 'Accept-Encoding': 'gzip, deflate, br', 'Accept': '*/*', 'Connection': 'keep-alive', 'Content-Length': '5068'}
2025-04-11 13:46:51,877 ERROR   wandb-upload_4:5729 [internal_api.py:upload_file():2560] upload_file response body: 
2025-04-11 13:46:51,897 DEBUG   HandlerThread:5729 [handler.py:handle_request():146] handle_request: status_report
2025-04-11 13:46:51,976 ERROR   wandb-upload_2:5729 [internal_api.py:upload_file():2556] upload_file exception https://storage.googleapis.com/wandb-production.appspot.com/2931823730-harbin-institute-of-technology/ltu-as/e1rp2dmj/requirements.txt?X-Goog-Algorithm=GOOG4-RSA-SHA256&X-Goog-Credential=gorilla-files-url-signer-man%40wandb-production.iam.gserviceaccount.com%2F20250411%2Fauto%2Fstorage%2Fgoog4_request&X-Goog-Date=20250411T134634Z&X-Goog-Expires=86399&X-Goog-Signature=3dfde56506a5eb961db089deed7db6aa48f193bc474ae614780e50f5da53dcad1ceb7b36dacc62c9ba2f21a8b3906e3591e27a1bd626d9c92a37b52c1a3a887ec2cc1e37639eb16971e4ed5e87ad2f243861a2fd54b4baab595fa20f3083675b58d7cba3143227443b1fdd03afbf5a03e6931eba414d96f4dbb387b685789045ce2ef0aadfb6f24c2b11b9e2ddba77726489ca36828d76c037fd3115c31241f3da27efd940eb562db1ac7affe47bc6cc8db3526bcefb0f030f2407394d1964bca766bbd1314ea5301db1ec85783aa70e6fe219f7c078906511102594baca5f8df23782c0692dd52f41467d465590ca5b32b230ff1554c23fd76e79fdadc28df4&X-Goog-SignedHeaders=host&X-User=2931823730: HTTPSConnectionPool(host='storage.googleapis.com', port=443): Max retries exceeded with url: /wandb-production.appspot.com/2931823730-harbin-institute-of-technology/ltu-as/e1rp2dmj/requirements.txt?X-Goog-Algorithm=GOOG4-RSA-SHA256&X-Goog-Credential=gorilla-files-url-signer-man%40wandb-production.iam.gserviceaccount.com%2F20250411%2Fauto%2Fstorage%2Fgoog4_request&X-Goog-Date=20250411T134634Z&X-Goog-Expires=86399&X-Goog-Signature=3dfde56506a5eb961db089deed7db6aa48f193bc474ae614780e50f5da53dcad1ceb7b36dacc62c9ba2f21a8b3906e3591e27a1bd626d9c92a37b52c1a3a887ec2cc1e37639eb16971e4ed5e87ad2f243861a2fd54b4baab595fa20f3083675b58d7cba3143227443b1fdd03afbf5a03e6931eba414d96f4dbb387b685789045ce2ef0aadfb6f24c2b11b9e2ddba77726489ca36828d76c037fd3115c31241f3da27efd940eb562db1ac7affe47bc6cc8db3526bcefb0f030f2407394d1964bca766bbd1314ea5301db1ec85783aa70e6fe219f7c078906511102594baca5f8df23782c0692dd52f41467d465590ca5b32b230ff1554c23fd76e79fdadc28df4&X-Goog-SignedHeaders=host&X-User=2931823730 (Caused by NewConnectionError('<urllib3.connection.HTTPSConnection object at 0x7f78a9fcbfa0>: Failed to establish a new connection: [Errno 101] Network is unreachable'))
2025-04-11 13:46:51,976 ERROR   wandb-upload_2:5729 [internal_api.py:upload_file():2558] upload_file request headers: {'User-Agent': 'python-requests/2.32.3', 'Accept-Encoding': 'gzip, deflate, br', 'Accept': '*/*', 'Connection': 'keep-alive', 'Content-Length': '4212'}
2025-04-11 13:46:51,976 ERROR   wandb-upload_2:5729 [internal_api.py:upload_file():2560] upload_file response body: 
2025-04-11 13:46:52,148 ERROR   wandb-upload_3:5729 [internal_api.py:upload_file():2556] upload_file exception https://storage.googleapis.com/wandb-production.appspot.com/2931823730-harbin-institute-of-technology/ltu-as/e1rp2dmj/conda-environment.yaml?X-Goog-Algorithm=GOOG4-RSA-SHA256&X-Goog-Credential=gorilla-files-url-signer-man%40wandb-production.iam.gserviceaccount.com%2F20250411%2Fauto%2Fstorage%2Fgoog4_request&X-Goog-Date=20250411T134634Z&X-Goog-Expires=86399&X-Goog-Signature=265e438ee1e70b800d8a7fecfc5ad7df5c6466d860f091f7203140cddce9cf7c92daef52f7ce3e701a0c43e1f92589bbf32fcf34e3491bd34b94e81bf4d369c1acaad089236cab81b7188596c894dc002373a96c6f456f16feb1cf4fc97ba6c918c66221de710c322f624fc3beafa22a0e6267b0d3e03a930092368d7bd298205cfb04835e4b98073b7419be36903de0a53256ad826c162ab35548a4b743df5a7f158aa3ba83515129d2bc120a7668d5f6ba72729786d61f070b892b4caae0f489a444d306207d8845ddfaf36cb07c97e8491db8a6cd464df6b44b458fd31bfb7aec6900e7bce07aa5d7d06f66942850410ced96674f6d13dbde8735c065b758&X-Goog-SignedHeaders=host&X-User=2931823730: HTTPSConnectionPool(host='storage.googleapis.com', port=443): Max retries exceeded with url: /wandb-production.appspot.com/2931823730-harbin-institute-of-technology/ltu-as/e1rp2dmj/conda-environment.yaml?X-Goog-Algorithm=GOOG4-RSA-SHA256&X-Goog-Credential=gorilla-files-url-signer-man%40wandb-production.iam.gserviceaccount.com%2F20250411%2Fauto%2Fstorage%2Fgoog4_request&X-Goog-Date=20250411T134634Z&X-Goog-Expires=86399&X-Goog-Signature=265e438ee1e70b800d8a7fecfc5ad7df5c6466d860f091f7203140cddce9cf7c92daef52f7ce3e701a0c43e1f92589bbf32fcf34e3491bd34b94e81bf4d369c1acaad089236cab81b7188596c894dc002373a96c6f456f16feb1cf4fc97ba6c918c66221de710c322f624fc3beafa22a0e6267b0d3e03a930092368d7bd298205cfb04835e4b98073b7419be36903de0a53256ad826c162ab35548a4b743df5a7f158aa3ba83515129d2bc120a7668d5f6ba72729786d61f070b892b4caae0f489a444d306207d8845ddfaf36cb07c97e8491db8a6cd464df6b44b458fd31bfb7aec6900e7bce07aa5d7d06f66942850410ced96674f6d13dbde8735c065b758&X-Goog-SignedHeaders=host&X-User=2931823730 (Caused by NewConnectionError('<urllib3.connection.HTTPSConnection object at 0x7f78a9fca890>: Failed to establish a new connection: [Errno 101] Network is unreachable'))
2025-04-11 13:46:52,148 ERROR   wandb-upload_3:5729 [internal_api.py:upload_file():2558] upload_file request headers: {'User-Agent': 'python-requests/2.32.3', 'Accept-Encoding': 'gzip, deflate, br', 'Accept': '*/*', 'Connection': 'keep-alive', 'Content-Length': '8281'}
2025-04-11 13:46:52,148 ERROR   wandb-upload_3:5729 [internal_api.py:upload_file():2560] upload_file response body: 
2025-04-11 13:46:52,200 ERROR   wandb-upload_0:5729 [internal_api.py:upload_file():2556] upload_file exception https://storage.googleapis.com/wandb-production.appspot.com/2931823730-harbin-institute-of-technology/ltu-as/e1rp2dmj/wandb-metadata.json?X-Goog-Algorithm=GOOG4-RSA-SHA256&X-Goog-Credential=gorilla-files-url-signer-man%40wandb-production.iam.gserviceaccount.com%2F20250411%2Fauto%2Fstorage%2Fgoog4_request&X-Goog-Date=20250411T134619Z&X-Goog-Expires=86399&X-Goog-Signature=af0857f67295574884cf2db9abaaccdaaa96b9ef6a6a5bf495355e0bb2cca3709042f1692f52e7c08335e841d771aa914c48aa2d4228797d3d3e27acc636f79795f401e523ff4840008fc280c934439fd7c669288912ffab1d06e6ea6d7178eef4a61385fb1b24d3b9ac99da5340314e08ce8c06f8ab6fc2b7722cd8b0bc6a8f980aa88ef5ab732b624d921cbc59f22107f1b87637d0b0d91a19dde3c63e2ec50bc1158b56888eaa60741932e5fe7f1c0a48b3a5054cb708ce8ca292f7be8005701d9db2893045106437f669bf301dc965b7f38a319f96b5ca65834a568cba009c6f0e70bec1637f97f4c2ffddca24309dbe47014f789317908c2e7990427d8d&X-Goog-SignedHeaders=host&X-User=2931823730: HTTPSConnectionPool(host='storage.googleapis.com', port=443): Max retries exceeded with url: /wandb-production.appspot.com/2931823730-harbin-institute-of-technology/ltu-as/e1rp2dmj/wandb-metadata.json?X-Goog-Algorithm=GOOG4-RSA-SHA256&X-Goog-Credential=gorilla-files-url-signer-man%40wandb-production.iam.gserviceaccount.com%2F20250411%2Fauto%2Fstorage%2Fgoog4_request&X-Goog-Date=20250411T134619Z&X-Goog-Expires=86399&X-Goog-Signature=af0857f67295574884cf2db9abaaccdaaa96b9ef6a6a5bf495355e0bb2cca3709042f1692f52e7c08335e841d771aa914c48aa2d4228797d3d3e27acc636f79795f401e523ff4840008fc280c934439fd7c669288912ffab1d06e6ea6d7178eef4a61385fb1b24d3b9ac99da5340314e08ce8c06f8ab6fc2b7722cd8b0bc6a8f980aa88ef5ab732b624d921cbc59f22107f1b87637d0b0d91a19dde3c63e2ec50bc1158b56888eaa60741932e5fe7f1c0a48b3a5054cb708ce8ca292f7be8005701d9db2893045106437f669bf301dc965b7f38a319f96b5ca65834a568cba009c6f0e70bec1637f97f4c2ffddca24309dbe47014f789317908c2e7990427d8d&X-Goog-SignedHeaders=host&X-User=2931823730 (Caused by NewConnectionError('<urllib3.connection.HTTPSConnection object at 0x7f78a9fcb280>: Failed to establish a new connection: [Errno 101] Network is unreachable'))
2025-04-11 13:46:52,200 ERROR   wandb-upload_0:5729 [internal_api.py:upload_file():2558] upload_file request headers: {'User-Agent': 'python-requests/2.32.3', 'Accept-Encoding': 'gzip, deflate, br', 'Accept': '*/*', 'Connection': 'keep-alive', 'Content-Length': '2257'}
2025-04-11 13:46:52,200 ERROR   wandb-upload_0:5729 [internal_api.py:upload_file():2560] upload_file response body: 
2025-04-11 13:46:52,209 DEBUG   HandlerThread:5729 [handler.py:handle_request():146] handle_request: keepalive
2025-04-11 13:46:52,616 ERROR   wandb-upload_1:5729 [internal_api.py:upload_file():2556] upload_file exception https://storage.googleapis.com/wandb-production.appspot.com/2931823730-harbin-institute-of-technology/ltu-as/e1rp2dmj/config.yaml?X-Goog-Algorithm=GOOG4-RSA-SHA256&X-Goog-Credential=gorilla-files-url-signer-man%40wandb-production.iam.gserviceaccount.com%2F20250411%2Fauto%2Fstorage%2Fgoog4_request&X-Goog-Date=20250411T134634Z&X-Goog-Expires=86399&X-Goog-Signature=4cd10bd589b82e59e27f62a38c7bb859f6315c8a3069f8c95f2b591b6d3a6f96f6cd958040991552a4208cd0e515ea04482dcb1ca32f1ee8f112a9b042da67ef144cb108a105d48d05bdbb86727c5c582615c7931ca7875be77f1e227f3cfbbbabc8417731c4b82ab6769881ee62e375155669ebec4934959856d4a8a2e6fdeaeab1cb06373c7866934a72235500ff61608d04e6a4e6447283f4046d87760e7658444706049c275c8f2fc043498682ac8fbdca5f494b43bd9838f8d8cb8009ffb7896ffb5c219b1f6a8fc992a9df4b59754e5d93a80dafdecf9a6b991c4defa8dc75553a784dcdc6ae3d13b2b7dd71a715a1f70a81feac5341924b175293b18a&X-Goog-SignedHeaders=host&X-User=2931823730: HTTPSConnectionPool(host='storage.googleapis.com', port=443): Max retries exceeded with url: /wandb-production.appspot.com/2931823730-harbin-institute-of-technology/ltu-as/e1rp2dmj/config.yaml?X-Goog-Algorithm=GOOG4-RSA-SHA256&X-Goog-Credential=gorilla-files-url-signer-man%40wandb-production.iam.gserviceaccount.com%2F20250411%2Fauto%2Fstorage%2Fgoog4_request&X-Goog-Date=20250411T134634Z&X-Goog-Expires=86399&X-Goog-Signature=4cd10bd589b82e59e27f62a38c7bb859f6315c8a3069f8c95f2b591b6d3a6f96f6cd958040991552a4208cd0e515ea04482dcb1ca32f1ee8f112a9b042da67ef144cb108a105d48d05bdbb86727c5c582615c7931ca7875be77f1e227f3cfbbbabc8417731c4b82ab6769881ee62e375155669ebec4934959856d4a8a2e6fdeaeab1cb06373c7866934a72235500ff61608d04e6a4e6447283f4046d87760e7658444706049c275c8f2fc043498682ac8fbdca5f494b43bd9838f8d8cb8009ffb7896ffb5c219b1f6a8fc992a9df4b59754e5d93a80dafdecf9a6b991c4defa8dc75553a784dcdc6ae3d13b2b7dd71a715a1f70a81feac5341924b175293b18a&X-Goog-SignedHeaders=host&X-User=2931823730 (Caused by NewConnectionError('<urllib3.connection.HTTPSConnection object at 0x7f78a9fcada0>: Failed to establish a new connection: [Errno 101] Network is unreachable'))
2025-04-11 13:46:52,616 ERROR   wandb-upload_1:5729 [internal_api.py:upload_file():2558] upload_file request headers: {'User-Agent': 'python-requests/2.32.3', 'Accept-Encoding': 'gzip, deflate, br', 'Accept': '*/*', 'Connection': 'keep-alive', 'Content-Length': '8684'}
2025-04-11 13:46:52,616 ERROR   wandb-upload_1:5729 [internal_api.py:upload_file():2560] upload_file response body: 
2025-04-11 13:46:56,898 DEBUG   HandlerThread:5729 [handler.py:handle_request():146] handle_request: status_report
2025-04-11 13:46:57,212 DEBUG   HandlerThread:5729 [handler.py:handle_request():146] handle_request: keepalive
2025-04-11 13:47:01,899 DEBUG   HandlerThread:5729 [handler.py:handle_request():146] handle_request: status_report
2025-04-11 13:47:02,214 DEBUG   HandlerThread:5729 [handler.py:handle_request():146] handle_request: keepalive
2025-04-11 13:47:06,900 DEBUG   HandlerThread:5729 [handler.py:handle_request():146] handle_request: status_report
2025-04-11 13:47:07,216 DEBUG   HandlerThread:5729 [handler.py:handle_request():146] handle_request: keepalive
2025-04-11 13:47:07,543 ERROR   wandb-upload_5:5729 [internal_api.py:upload_file():2556] upload_file exception https://storage.googleapis.com/wandb-production.appspot.com/2931823730-harbin-institute-of-technology/ltu-as/e1rp2dmj/wandb-summary.json?X-Goog-Algorithm=GOOG4-RSA-SHA256&X-Goog-Credential=gorilla-files-url-signer-man%40wandb-production.iam.gserviceaccount.com%2F20250411%2Fauto%2Fstorage%2Fgoog4_request&X-Goog-Date=20250411T134634Z&X-Goog-Expires=86399&X-Goog-Signature=ac5e445aae328ee3ae9946dd2ab55fbf6f673f45f548df81577386d8397df42b9cec8bc5e03d7769bcf073b2b1aaf22a28439cb78c2913d462a812b518f0c77dc74ea5b3ff300544c40e4e06f62e863a922a5fd4736bb164c2a3dbed5d8ac771e3d73c275377bf6d644b25e54e374105fae21c754a7d00451e6f4b9bdb8eef6d007da49a984adb31101ff795c71ff81bfae958b73af8919398e18a58f6835c41d1d8b808f4dcfb20fa53b90aed702ce33dd3a843c72139afeadd14489fd191a910b1f046a684e2d5ec5d4548d93932e2ac3b57577beb5db408798c4892a905cf5ef8ecf5f2a91ed8d3d9bd832fd9a08889d3ec1ad786378a3ba3a8af22b6d471&X-Goog-SignedHeaders=host&X-User=2931823730: HTTPSConnectionPool(host='storage.googleapis.com', port=443): Max retries exceeded with url: /wandb-production.appspot.com/2931823730-harbin-institute-of-technology/ltu-as/e1rp2dmj/wandb-summary.json?X-Goog-Algorithm=GOOG4-RSA-SHA256&X-Goog-Credential=gorilla-files-url-signer-man%40wandb-production.iam.gserviceaccount.com%2F20250411%2Fauto%2Fstorage%2Fgoog4_request&X-Goog-Date=20250411T134634Z&X-Goog-Expires=86399&X-Goog-Signature=ac5e445aae328ee3ae9946dd2ab55fbf6f673f45f548df81577386d8397df42b9cec8bc5e03d7769bcf073b2b1aaf22a28439cb78c2913d462a812b518f0c77dc74ea5b3ff300544c40e4e06f62e863a922a5fd4736bb164c2a3dbed5d8ac771e3d73c275377bf6d644b25e54e374105fae21c754a7d00451e6f4b9bdb8eef6d007da49a984adb31101ff795c71ff81bfae958b73af8919398e18a58f6835c41d1d8b808f4dcfb20fa53b90aed702ce33dd3a843c72139afeadd14489fd191a910b1f046a684e2d5ec5d4548d93932e2ac3b57577beb5db408798c4892a905cf5ef8ecf5f2a91ed8d3d9bd832fd9a08889d3ec1ad786378a3ba3a8af22b6d471&X-Goog-SignedHeaders=host&X-User=2931823730 (Caused by NewConnectionError('<urllib3.connection.HTTPSConnection object at 0x7f78ba74bbe0>: Failed to establish a new connection: [Errno 101] Network is unreachable'))
2025-04-11 13:47:07,543 ERROR   wandb-upload_5:5729 [internal_api.py:upload_file():2558] upload_file request headers: {'User-Agent': 'python-requests/2.32.3', 'Accept-Encoding': 'gzip, deflate, br', 'Accept': '*/*', 'Connection': 'keep-alive', 'Content-Length': '27'}
2025-04-11 13:47:07,543 ERROR   wandb-upload_5:5729 [internal_api.py:upload_file():2560] upload_file response body: 
2025-04-11 13:47:09,078 ERROR   wandb-upload_4:5729 [internal_api.py:upload_file():2556] upload_file exception https://storage.googleapis.com/wandb-production.appspot.com/2931823730-harbin-institute-of-technology/ltu-as/e1rp2dmj/output.log?X-Goog-Algorithm=GOOG4-RSA-SHA256&X-Goog-Credential=gorilla-files-url-signer-man%40wandb-production.iam.gserviceaccount.com%2F20250411%2Fauto%2Fstorage%2Fgoog4_request&X-Goog-Date=20250411T134634Z&X-Goog-Expires=86399&X-Goog-Signature=1128654687b0bf6a676feb1b3994c67f90d4d5ad203efb1db55a64de90d2e137a92e4605a00647015e03b194032e4403003e9fa8121264c1d3fec46eff90feac3c3cffb282d22451c5c6acb440a025e6ed761bf74b5259a8e5e079edcfa55a2cb62cae67f6be3e484d87677dfd925fed1422544e6d25665d96085dab9beb1aba7f0074d9632139baf8e19153ba1bd3f3833ab064bcdd45f81fc55148a4ea0e4c3b3e9d308644abc1ba92aee0756638463b58ca487c63f3ef2b21a51c344d3e9827d9c479edcffa4422015eebc1612fe497273ae11d9a40dc95b6ecf080a596c4206a01011244acfe3450e296dc68077ded4fb723f67f357914c5c7890a257fef&X-Goog-SignedHeaders=host&X-User=2931823730: HTTPSConnectionPool(host='storage.googleapis.com', port=443): Max retries exceeded with url: /wandb-production.appspot.com/2931823730-harbin-institute-of-technology/ltu-as/e1rp2dmj/output.log?X-Goog-Algorithm=GOOG4-RSA-SHA256&X-Goog-Credential=gorilla-files-url-signer-man%40wandb-production.iam.gserviceaccount.com%2F20250411%2Fauto%2Fstorage%2Fgoog4_request&X-Goog-Date=20250411T134634Z&X-Goog-Expires=86399&X-Goog-Signature=1128654687b0bf6a676feb1b3994c67f90d4d5ad203efb1db55a64de90d2e137a92e4605a00647015e03b194032e4403003e9fa8121264c1d3fec46eff90feac3c3cffb282d22451c5c6acb440a025e6ed761bf74b5259a8e5e079edcfa55a2cb62cae67f6be3e484d87677dfd925fed1422544e6d25665d96085dab9beb1aba7f0074d9632139baf8e19153ba1bd3f3833ab064bcdd45f81fc55148a4ea0e4c3b3e9d308644abc1ba92aee0756638463b58ca487c63f3ef2b21a51c344d3e9827d9c479edcffa4422015eebc1612fe497273ae11d9a40dc95b6ecf080a596c4206a01011244acfe3450e296dc68077ded4fb723f67f357914c5c7890a257fef&X-Goog-SignedHeaders=host&X-User=2931823730 (Caused by NewConnectionError('<urllib3.connection.HTTPSConnection object at 0x7f78ba74b940>: Failed to establish a new connection: [Errno 101] Network is unreachable'))
2025-04-11 13:47:09,078 ERROR   wandb-upload_4:5729 [internal_api.py:upload_file():2558] upload_file request headers: {'User-Agent': 'python-requests/2.32.3', 'Accept-Encoding': 'gzip, deflate, br', 'Accept': '*/*', 'Connection': 'keep-alive', 'Content-Length': '5068'}
2025-04-11 13:47:09,078 ERROR   wandb-upload_4:5729 [internal_api.py:upload_file():2560] upload_file response body: 
2025-04-11 13:47:09,836 ERROR   wandb-upload_2:5729 [internal_api.py:upload_file():2556] upload_file exception https://storage.googleapis.com/wandb-production.appspot.com/2931823730-harbin-institute-of-technology/ltu-as/e1rp2dmj/requirements.txt?X-Goog-Algorithm=GOOG4-RSA-SHA256&X-Goog-Credential=gorilla-files-url-signer-man%40wandb-production.iam.gserviceaccount.com%2F20250411%2Fauto%2Fstorage%2Fgoog4_request&X-Goog-Date=20250411T134634Z&X-Goog-Expires=86399&X-Goog-Signature=3dfde56506a5eb961db089deed7db6aa48f193bc474ae614780e50f5da53dcad1ceb7b36dacc62c9ba2f21a8b3906e3591e27a1bd626d9c92a37b52c1a3a887ec2cc1e37639eb16971e4ed5e87ad2f243861a2fd54b4baab595fa20f3083675b58d7cba3143227443b1fdd03afbf5a03e6931eba414d96f4dbb387b685789045ce2ef0aadfb6f24c2b11b9e2ddba77726489ca36828d76c037fd3115c31241f3da27efd940eb562db1ac7affe47bc6cc8db3526bcefb0f030f2407394d1964bca766bbd1314ea5301db1ec85783aa70e6fe219f7c078906511102594baca5f8df23782c0692dd52f41467d465590ca5b32b230ff1554c23fd76e79fdadc28df4&X-Goog-SignedHeaders=host&X-User=2931823730: HTTPSConnectionPool(host='storage.googleapis.com', port=443): Max retries exceeded with url: /wandb-production.appspot.com/2931823730-harbin-institute-of-technology/ltu-as/e1rp2dmj/requirements.txt?X-Goog-Algorithm=GOOG4-RSA-SHA256&X-Goog-Credential=gorilla-files-url-signer-man%40wandb-production.iam.gserviceaccount.com%2F20250411%2Fauto%2Fstorage%2Fgoog4_request&X-Goog-Date=20250411T134634Z&X-Goog-Expires=86399&X-Goog-Signature=3dfde56506a5eb961db089deed7db6aa48f193bc474ae614780e50f5da53dcad1ceb7b36dacc62c9ba2f21a8b3906e3591e27a1bd626d9c92a37b52c1a3a887ec2cc1e37639eb16971e4ed5e87ad2f243861a2fd54b4baab595fa20f3083675b58d7cba3143227443b1fdd03afbf5a03e6931eba414d96f4dbb387b685789045ce2ef0aadfb6f24c2b11b9e2ddba77726489ca36828d76c037fd3115c31241f3da27efd940eb562db1ac7affe47bc6cc8db3526bcefb0f030f2407394d1964bca766bbd1314ea5301db1ec85783aa70e6fe219f7c078906511102594baca5f8df23782c0692dd52f41467d465590ca5b32b230ff1554c23fd76e79fdadc28df4&X-Goog-SignedHeaders=host&X-User=2931823730 (Caused by NewConnectionError('<urllib3.connection.HTTPSConnection object at 0x7f78a860c280>: Failed to establish a new connection: [Errno 101] Network is unreachable'))
2025-04-11 13:47:09,836 ERROR   wandb-upload_2:5729 [internal_api.py:upload_file():2558] upload_file request headers: {'User-Agent': 'python-requests/2.32.3', 'Accept-Encoding': 'gzip, deflate, br', 'Accept': '*/*', 'Connection': 'keep-alive', 'Content-Length': '4212'}
2025-04-11 13:47:09,836 ERROR   wandb-upload_2:5729 [internal_api.py:upload_file():2560] upload_file response body: 
2025-04-11 13:47:10,872 ERROR   wandb-upload_3:5729 [internal_api.py:upload_file():2556] upload_file exception https://storage.googleapis.com/wandb-production.appspot.com/2931823730-harbin-institute-of-technology/ltu-as/e1rp2dmj/conda-environment.yaml?X-Goog-Algorithm=GOOG4-RSA-SHA256&X-Goog-Credential=gorilla-files-url-signer-man%40wandb-production.iam.gserviceaccount.com%2F20250411%2Fauto%2Fstorage%2Fgoog4_request&X-Goog-Date=20250411T134634Z&X-Goog-Expires=86399&X-Goog-Signature=265e438ee1e70b800d8a7fecfc5ad7df5c6466d860f091f7203140cddce9cf7c92daef52f7ce3e701a0c43e1f92589bbf32fcf34e3491bd34b94e81bf4d369c1acaad089236cab81b7188596c894dc002373a96c6f456f16feb1cf4fc97ba6c918c66221de710c322f624fc3beafa22a0e6267b0d3e03a930092368d7bd298205cfb04835e4b98073b7419be36903de0a53256ad826c162ab35548a4b743df5a7f158aa3ba83515129d2bc120a7668d5f6ba72729786d61f070b892b4caae0f489a444d306207d8845ddfaf36cb07c97e8491db8a6cd464df6b44b458fd31bfb7aec6900e7bce07aa5d7d06f66942850410ced96674f6d13dbde8735c065b758&X-Goog-SignedHeaders=host&X-User=2931823730: HTTPSConnectionPool(host='storage.googleapis.com', port=443): Max retries exceeded with url: /wandb-production.appspot.com/2931823730-harbin-institute-of-technology/ltu-as/e1rp2dmj/conda-environment.yaml?X-Goog-Algorithm=GOOG4-RSA-SHA256&X-Goog-Credential=gorilla-files-url-signer-man%40wandb-production.iam.gserviceaccount.com%2F20250411%2Fauto%2Fstorage%2Fgoog4_request&X-Goog-Date=20250411T134634Z&X-Goog-Expires=86399&X-Goog-Signature=265e438ee1e70b800d8a7fecfc5ad7df5c6466d860f091f7203140cddce9cf7c92daef52f7ce3e701a0c43e1f92589bbf32fcf34e3491bd34b94e81bf4d369c1acaad089236cab81b7188596c894dc002373a96c6f456f16feb1cf4fc97ba6c918c66221de710c322f624fc3beafa22a0e6267b0d3e03a930092368d7bd298205cfb04835e4b98073b7419be36903de0a53256ad826c162ab35548a4b743df5a7f158aa3ba83515129d2bc120a7668d5f6ba72729786d61f070b892b4caae0f489a444d306207d8845ddfaf36cb07c97e8491db8a6cd464df6b44b458fd31bfb7aec6900e7bce07aa5d7d06f66942850410ced96674f6d13dbde8735c065b758&X-Goog-SignedHeaders=host&X-User=2931823730 (Caused by NewConnectionError('<urllib3.connection.HTTPSConnection object at 0x7f78a860cc40>: Failed to establish a new connection: [Errno 101] Network is unreachable'))
2025-04-11 13:47:10,872 ERROR   wandb-upload_3:5729 [internal_api.py:upload_file():2558] upload_file request headers: {'User-Agent': 'python-requests/2.32.3', 'Accept-Encoding': 'gzip, deflate, br', 'Accept': '*/*', 'Connection': 'keep-alive', 'Content-Length': '8281'}
2025-04-11 13:47:10,872 ERROR   wandb-upload_3:5729 [internal_api.py:upload_file():2560] upload_file response body: 
2025-04-11 13:47:11,439 ERROR   wandb-upload_1:5729 [internal_api.py:upload_file():2556] upload_file exception https://storage.googleapis.com/wandb-production.appspot.com/2931823730-harbin-institute-of-technology/ltu-as/e1rp2dmj/config.yaml?X-Goog-Algorithm=GOOG4-RSA-SHA256&X-Goog-Credential=gorilla-files-url-signer-man%40wandb-production.iam.gserviceaccount.com%2F20250411%2Fauto%2Fstorage%2Fgoog4_request&X-Goog-Date=20250411T134634Z&X-Goog-Expires=86399&X-Goog-Signature=4cd10bd589b82e59e27f62a38c7bb859f6315c8a3069f8c95f2b591b6d3a6f96f6cd958040991552a4208cd0e515ea04482dcb1ca32f1ee8f112a9b042da67ef144cb108a105d48d05bdbb86727c5c582615c7931ca7875be77f1e227f3cfbbbabc8417731c4b82ab6769881ee62e375155669ebec4934959856d4a8a2e6fdeaeab1cb06373c7866934a72235500ff61608d04e6a4e6447283f4046d87760e7658444706049c275c8f2fc043498682ac8fbdca5f494b43bd9838f8d8cb8009ffb7896ffb5c219b1f6a8fc992a9df4b59754e5d93a80dafdecf9a6b991c4defa8dc75553a784dcdc6ae3d13b2b7dd71a715a1f70a81feac5341924b175293b18a&X-Goog-SignedHeaders=host&X-User=2931823730: HTTPSConnectionPool(host='storage.googleapis.com', port=443): Max retries exceeded with url: /wandb-production.appspot.com/2931823730-harbin-institute-of-technology/ltu-as/e1rp2dmj/config.yaml?X-Goog-Algorithm=GOOG4-RSA-SHA256&X-Goog-Credential=gorilla-files-url-signer-man%40wandb-production.iam.gserviceaccount.com%2F20250411%2Fauto%2Fstorage%2Fgoog4_request&X-Goog-Date=20250411T134634Z&X-Goog-Expires=86399&X-Goog-Signature=4cd10bd589b82e59e27f62a38c7bb859f6315c8a3069f8c95f2b591b6d3a6f96f6cd958040991552a4208cd0e515ea04482dcb1ca32f1ee8f112a9b042da67ef144cb108a105d48d05bdbb86727c5c582615c7931ca7875be77f1e227f3cfbbbabc8417731c4b82ab6769881ee62e375155669ebec4934959856d4a8a2e6fdeaeab1cb06373c7866934a72235500ff61608d04e6a4e6447283f4046d87760e7658444706049c275c8f2fc043498682ac8fbdca5f494b43bd9838f8d8cb8009ffb7896ffb5c219b1f6a8fc992a9df4b59754e5d93a80dafdecf9a6b991c4defa8dc75553a784dcdc6ae3d13b2b7dd71a715a1f70a81feac5341924b175293b18a&X-Goog-SignedHeaders=host&X-User=2931823730 (Caused by NewConnectionError('<urllib3.connection.HTTPSConnection object at 0x7f78a860d630>: Failed to establish a new connection: [Errno 101] Network is unreachable'))
2025-04-11 13:47:11,439 ERROR   wandb-upload_1:5729 [internal_api.py:upload_file():2558] upload_file request headers: {'User-Agent': 'python-requests/2.32.3', 'Accept-Encoding': 'gzip, deflate, br', 'Accept': '*/*', 'Connection': 'keep-alive', 'Content-Length': '8684'}
2025-04-11 13:47:11,439 ERROR   wandb-upload_1:5729 [internal_api.py:upload_file():2560] upload_file response body: 
2025-04-11 13:47:11,901 DEBUG   HandlerThread:5729 [handler.py:handle_request():146] handle_request: status_report
2025-04-11 13:47:12,218 DEBUG   HandlerThread:5729 [handler.py:handle_request():146] handle_request: keepalive
2025-04-11 13:47:16,902 DEBUG   HandlerThread:5729 [handler.py:handle_request():146] handle_request: status_report
2025-04-11 13:47:17,220 DEBUG   HandlerThread:5729 [handler.py:handle_request():146] handle_request: keepalive
2025-04-11 13:47:21,903 DEBUG   HandlerThread:5729 [handler.py:handle_request():146] handle_request: status_report
2025-04-11 13:47:22,222 DEBUG   HandlerThread:5729 [handler.py:handle_request():146] handle_request: keepalive
2025-04-11 13:47:26,904 DEBUG   HandlerThread:5729 [handler.py:handle_request():146] handle_request: status_report
2025-04-11 13:47:27,224 DEBUG   HandlerThread:5729 [handler.py:handle_request():146] handle_request: keepalive
2025-04-11 13:47:28,144 ERROR   wandb-upload_0:5729 [internal_api.py:upload_file():2556] upload_file exception https://storage.googleapis.com/wandb-production.appspot.com/2931823730-harbin-institute-of-technology/ltu-as/e1rp2dmj/wandb-metadata.json?X-Goog-Algorithm=GOOG4-RSA-SHA256&X-Goog-Credential=gorilla-files-url-signer-man%40wandb-production.iam.gserviceaccount.com%2F20250411%2Fauto%2Fstorage%2Fgoog4_request&X-Goog-Date=20250411T134619Z&X-Goog-Expires=86399&X-Goog-Signature=af0857f67295574884cf2db9abaaccdaaa96b9ef6a6a5bf495355e0bb2cca3709042f1692f52e7c08335e841d771aa914c48aa2d4228797d3d3e27acc636f79795f401e523ff4840008fc280c934439fd7c669288912ffab1d06e6ea6d7178eef4a61385fb1b24d3b9ac99da5340314e08ce8c06f8ab6fc2b7722cd8b0bc6a8f980aa88ef5ab732b624d921cbc59f22107f1b87637d0b0d91a19dde3c63e2ec50bc1158b56888eaa60741932e5fe7f1c0a48b3a5054cb708ce8ca292f7be8005701d9db2893045106437f669bf301dc965b7f38a319f96b5ca65834a568cba009c6f0e70bec1637f97f4c2ffddca24309dbe47014f789317908c2e7990427d8d&X-Goog-SignedHeaders=host&X-User=2931823730: HTTPSConnectionPool(host='storage.googleapis.com', port=443): Max retries exceeded with url: /wandb-production.appspot.com/2931823730-harbin-institute-of-technology/ltu-as/e1rp2dmj/wandb-metadata.json?X-Goog-Algorithm=GOOG4-RSA-SHA256&X-Goog-Credential=gorilla-files-url-signer-man%40wandb-production.iam.gserviceaccount.com%2F20250411%2Fauto%2Fstorage%2Fgoog4_request&X-Goog-Date=20250411T134619Z&X-Goog-Expires=86399&X-Goog-Signature=af0857f67295574884cf2db9abaaccdaaa96b9ef6a6a5bf495355e0bb2cca3709042f1692f52e7c08335e841d771aa914c48aa2d4228797d3d3e27acc636f79795f401e523ff4840008fc280c934439fd7c669288912ffab1d06e6ea6d7178eef4a61385fb1b24d3b9ac99da5340314e08ce8c06f8ab6fc2b7722cd8b0bc6a8f980aa88ef5ab732b624d921cbc59f22107f1b87637d0b0d91a19dde3c63e2ec50bc1158b56888eaa60741932e5fe7f1c0a48b3a5054cb708ce8ca292f7be8005701d9db2893045106437f669bf301dc965b7f38a319f96b5ca65834a568cba009c6f0e70bec1637f97f4c2ffddca24309dbe47014f789317908c2e7990427d8d&X-Goog-SignedHeaders=host&X-User=2931823730 (Caused by NewConnectionError('<urllib3.connection.HTTPSConnection object at 0x7f78ba74beb0>: Failed to establish a new connection: [Errno 101] Network is unreachable'))
2025-04-11 13:47:28,145 ERROR   wandb-upload_0:5729 [internal_api.py:upload_file():2558] upload_file request headers: {'User-Agent': 'python-requests/2.32.3', 'Accept-Encoding': 'gzip, deflate, br', 'Accept': '*/*', 'Connection': 'keep-alive', 'Content-Length': '2257'}
2025-04-11 13:47:28,145 ERROR   wandb-upload_0:5729 [internal_api.py:upload_file():2560] upload_file response body: 
2025-04-11 13:47:31,905 DEBUG   HandlerThread:5729 [handler.py:handle_request():146] handle_request: status_report
2025-04-11 13:47:32,226 DEBUG   HandlerThread:5729 [handler.py:handle_request():146] handle_request: keepalive
2025-04-11 13:47:36,906 DEBUG   HandlerThread:5729 [handler.py:handle_request():146] handle_request: status_report
2025-04-11 13:47:37,228 DEBUG   HandlerThread:5729 [handler.py:handle_request():146] handle_request: keepalive
2025-04-11 13:47:41,907 DEBUG   HandlerThread:5729 [handler.py:handle_request():146] handle_request: status_report
2025-04-11 13:47:41,926 ERROR   wandb-upload_2:5729 [internal_api.py:upload_file():2556] upload_file exception https://storage.googleapis.com/wandb-production.appspot.com/2931823730-harbin-institute-of-technology/ltu-as/e1rp2dmj/requirements.txt?X-Goog-Algorithm=GOOG4-RSA-SHA256&X-Goog-Credential=gorilla-files-url-signer-man%40wandb-production.iam.gserviceaccount.com%2F20250411%2Fauto%2Fstorage%2Fgoog4_request&X-Goog-Date=20250411T134634Z&X-Goog-Expires=86399&X-Goog-Signature=3dfde56506a5eb961db089deed7db6aa48f193bc474ae614780e50f5da53dcad1ceb7b36dacc62c9ba2f21a8b3906e3591e27a1bd626d9c92a37b52c1a3a887ec2cc1e37639eb16971e4ed5e87ad2f243861a2fd54b4baab595fa20f3083675b58d7cba3143227443b1fdd03afbf5a03e6931eba414d96f4dbb387b685789045ce2ef0aadfb6f24c2b11b9e2ddba77726489ca36828d76c037fd3115c31241f3da27efd940eb562db1ac7affe47bc6cc8db3526bcefb0f030f2407394d1964bca766bbd1314ea5301db1ec85783aa70e6fe219f7c078906511102594baca5f8df23782c0692dd52f41467d465590ca5b32b230ff1554c23fd76e79fdadc28df4&X-Goog-SignedHeaders=host&X-User=2931823730: HTTPSConnectionPool(host='storage.googleapis.com', port=443): Max retries exceeded with url: /wandb-production.appspot.com/2931823730-harbin-institute-of-technology/ltu-as/e1rp2dmj/requirements.txt?X-Goog-Algorithm=GOOG4-RSA-SHA256&X-Goog-Credential=gorilla-files-url-signer-man%40wandb-production.iam.gserviceaccount.com%2F20250411%2Fauto%2Fstorage%2Fgoog4_request&X-Goog-Date=20250411T134634Z&X-Goog-Expires=86399&X-Goog-Signature=3dfde56506a5eb961db089deed7db6aa48f193bc474ae614780e50f5da53dcad1ceb7b36dacc62c9ba2f21a8b3906e3591e27a1bd626d9c92a37b52c1a3a887ec2cc1e37639eb16971e4ed5e87ad2f243861a2fd54b4baab595fa20f3083675b58d7cba3143227443b1fdd03afbf5a03e6931eba414d96f4dbb387b685789045ce2ef0aadfb6f24c2b11b9e2ddba77726489ca36828d76c037fd3115c31241f3da27efd940eb562db1ac7affe47bc6cc8db3526bcefb0f030f2407394d1964bca766bbd1314ea5301db1ec85783aa70e6fe219f7c078906511102594baca5f8df23782c0692dd52f41467d465590ca5b32b230ff1554c23fd76e79fdadc28df4&X-Goog-SignedHeaders=host&X-User=2931823730 (Caused by NewConnectionError('<urllib3.connection.HTTPSConnection object at 0x7f78ba74af80>: Failed to establish a new connection: [Errno 101] Network is unreachable'))
2025-04-11 13:47:41,926 ERROR   wandb-upload_2:5729 [internal_api.py:upload_file():2558] upload_file request headers: {'User-Agent': 'python-requests/2.32.3', 'Accept-Encoding': 'gzip, deflate, br', 'Accept': '*/*', 'Connection': 'keep-alive', 'Content-Length': '4212'}
2025-04-11 13:47:41,926 ERROR   wandb-upload_2:5729 [internal_api.py:upload_file():2560] upload_file response body: 
2025-04-11 13:47:42,230 DEBUG   HandlerThread:5729 [handler.py:handle_request():146] handle_request: keepalive
2025-04-11 13:47:42,419 ERROR   wandb-upload_4:5729 [internal_api.py:upload_file():2556] upload_file exception https://storage.googleapis.com/wandb-production.appspot.com/2931823730-harbin-institute-of-technology/ltu-as/e1rp2dmj/output.log?X-Goog-Algorithm=GOOG4-RSA-SHA256&X-Goog-Credential=gorilla-files-url-signer-man%40wandb-production.iam.gserviceaccount.com%2F20250411%2Fauto%2Fstorage%2Fgoog4_request&X-Goog-Date=20250411T134634Z&X-Goog-Expires=86399&X-Goog-Signature=1128654687b0bf6a676feb1b3994c67f90d4d5ad203efb1db55a64de90d2e137a92e4605a00647015e03b194032e4403003e9fa8121264c1d3fec46eff90feac3c3cffb282d22451c5c6acb440a025e6ed761bf74b5259a8e5e079edcfa55a2cb62cae67f6be3e484d87677dfd925fed1422544e6d25665d96085dab9beb1aba7f0074d9632139baf8e19153ba1bd3f3833ab064bcdd45f81fc55148a4ea0e4c3b3e9d308644abc1ba92aee0756638463b58ca487c63f3ef2b21a51c344d3e9827d9c479edcffa4422015eebc1612fe497273ae11d9a40dc95b6ecf080a596c4206a01011244acfe3450e296dc68077ded4fb723f67f357914c5c7890a257fef&X-Goog-SignedHeaders=host&X-User=2931823730: HTTPSConnectionPool(host='storage.googleapis.com', port=443): Max retries exceeded with url: /wandb-production.appspot.com/2931823730-harbin-institute-of-technology/ltu-as/e1rp2dmj/output.log?X-Goog-Algorithm=GOOG4-RSA-SHA256&X-Goog-Credential=gorilla-files-url-signer-man%40wandb-production.iam.gserviceaccount.com%2F20250411%2Fauto%2Fstorage%2Fgoog4_request&X-Goog-Date=20250411T134634Z&X-Goog-Expires=86399&X-Goog-Signature=1128654687b0bf6a676feb1b3994c67f90d4d5ad203efb1db55a64de90d2e137a92e4605a00647015e03b194032e4403003e9fa8121264c1d3fec46eff90feac3c3cffb282d22451c5c6acb440a025e6ed761bf74b5259a8e5e079edcfa55a2cb62cae67f6be3e484d87677dfd925fed1422544e6d25665d96085dab9beb1aba7f0074d9632139baf8e19153ba1bd3f3833ab064bcdd45f81fc55148a4ea0e4c3b3e9d308644abc1ba92aee0756638463b58ca487c63f3ef2b21a51c344d3e9827d9c479edcffa4422015eebc1612fe497273ae11d9a40dc95b6ecf080a596c4206a01011244acfe3450e296dc68077ded4fb723f67f357914c5c7890a257fef&X-Goog-SignedHeaders=host&X-User=2931823730 (Caused by NewConnectionError('<urllib3.connection.HTTPSConnection object at 0x7f78a9fc9fc0>: Failed to establish a new connection: [Errno 101] Network is unreachable'))
2025-04-11 13:47:42,420 ERROR   wandb-upload_4:5729 [internal_api.py:upload_file():2558] upload_file request headers: {'User-Agent': 'python-requests/2.32.3', 'Accept-Encoding': 'gzip, deflate, br', 'Accept': '*/*', 'Connection': 'keep-alive', 'Content-Length': '5068'}
2025-04-11 13:47:42,420 ERROR   wandb-upload_4:5729 [internal_api.py:upload_file():2560] upload_file response body: 
2025-04-11 13:47:43,780 ERROR   wandb-upload_5:5729 [internal_api.py:upload_file():2556] upload_file exception https://storage.googleapis.com/wandb-production.appspot.com/2931823730-harbin-institute-of-technology/ltu-as/e1rp2dmj/wandb-summary.json?X-Goog-Algorithm=GOOG4-RSA-SHA256&X-Goog-Credential=gorilla-files-url-signer-man%40wandb-production.iam.gserviceaccount.com%2F20250411%2Fauto%2Fstorage%2Fgoog4_request&X-Goog-Date=20250411T134634Z&X-Goog-Expires=86399&X-Goog-Signature=ac5e445aae328ee3ae9946dd2ab55fbf6f673f45f548df81577386d8397df42b9cec8bc5e03d7769bcf073b2b1aaf22a28439cb78c2913d462a812b518f0c77dc74ea5b3ff300544c40e4e06f62e863a922a5fd4736bb164c2a3dbed5d8ac771e3d73c275377bf6d644b25e54e374105fae21c754a7d00451e6f4b9bdb8eef6d007da49a984adb31101ff795c71ff81bfae958b73af8919398e18a58f6835c41d1d8b808f4dcfb20fa53b90aed702ce33dd3a843c72139afeadd14489fd191a910b1f046a684e2d5ec5d4548d93932e2ac3b57577beb5db408798c4892a905cf5ef8ecf5f2a91ed8d3d9bd832fd9a08889d3ec1ad786378a3ba3a8af22b6d471&X-Goog-SignedHeaders=host&X-User=2931823730: HTTPSConnectionPool(host='storage.googleapis.com', port=443): Max retries exceeded with url: /wandb-production.appspot.com/2931823730-harbin-institute-of-technology/ltu-as/e1rp2dmj/wandb-summary.json?X-Goog-Algorithm=GOOG4-RSA-SHA256&X-Goog-Credential=gorilla-files-url-signer-man%40wandb-production.iam.gserviceaccount.com%2F20250411%2Fauto%2Fstorage%2Fgoog4_request&X-Goog-Date=20250411T134634Z&X-Goog-Expires=86399&X-Goog-Signature=ac5e445aae328ee3ae9946dd2ab55fbf6f673f45f548df81577386d8397df42b9cec8bc5e03d7769bcf073b2b1aaf22a28439cb78c2913d462a812b518f0c77dc74ea5b3ff300544c40e4e06f62e863a922a5fd4736bb164c2a3dbed5d8ac771e3d73c275377bf6d644b25e54e374105fae21c754a7d00451e6f4b9bdb8eef6d007da49a984adb31101ff795c71ff81bfae958b73af8919398e18a58f6835c41d1d8b808f4dcfb20fa53b90aed702ce33dd3a843c72139afeadd14489fd191a910b1f046a684e2d5ec5d4548d93932e2ac3b57577beb5db408798c4892a905cf5ef8ecf5f2a91ed8d3d9bd832fd9a08889d3ec1ad786378a3ba3a8af22b6d471&X-Goog-SignedHeaders=host&X-User=2931823730 (Caused by NewConnectionError('<urllib3.connection.HTTPSConnection object at 0x7f78a9fc86a0>: Failed to establish a new connection: [Errno 101] Network is unreachable'))
2025-04-11 13:47:43,780 ERROR   wandb-upload_5:5729 [internal_api.py:upload_file():2558] upload_file request headers: {'User-Agent': 'python-requests/2.32.3', 'Accept-Encoding': 'gzip, deflate, br', 'Accept': '*/*', 'Connection': 'keep-alive', 'Content-Length': '27'}
2025-04-11 13:47:43,780 ERROR   wandb-upload_5:5729 [internal_api.py:upload_file():2560] upload_file response body: 
2025-04-11 13:47:44,846 ERROR   wandb-upload_1:5729 [internal_api.py:upload_file():2556] upload_file exception https://storage.googleapis.com/wandb-production.appspot.com/2931823730-harbin-institute-of-technology/ltu-as/e1rp2dmj/config.yaml?X-Goog-Algorithm=GOOG4-RSA-SHA256&X-Goog-Credential=gorilla-files-url-signer-man%40wandb-production.iam.gserviceaccount.com%2F20250411%2Fauto%2Fstorage%2Fgoog4_request&X-Goog-Date=20250411T134634Z&X-Goog-Expires=86399&X-Goog-Signature=4cd10bd589b82e59e27f62a38c7bb859f6315c8a3069f8c95f2b591b6d3a6f96f6cd958040991552a4208cd0e515ea04482dcb1ca32f1ee8f112a9b042da67ef144cb108a105d48d05bdbb86727c5c582615c7931ca7875be77f1e227f3cfbbbabc8417731c4b82ab6769881ee62e375155669ebec4934959856d4a8a2e6fdeaeab1cb06373c7866934a72235500ff61608d04e6a4e6447283f4046d87760e7658444706049c275c8f2fc043498682ac8fbdca5f494b43bd9838f8d8cb8009ffb7896ffb5c219b1f6a8fc992a9df4b59754e5d93a80dafdecf9a6b991c4defa8dc75553a784dcdc6ae3d13b2b7dd71a715a1f70a81feac5341924b175293b18a&X-Goog-SignedHeaders=host&X-User=2931823730: HTTPSConnectionPool(host='storage.googleapis.com', port=443): Max retries exceeded with url: /wandb-production.appspot.com/2931823730-harbin-institute-of-technology/ltu-as/e1rp2dmj/config.yaml?X-Goog-Algorithm=GOOG4-RSA-SHA256&X-Goog-Credential=gorilla-files-url-signer-man%40wandb-production.iam.gserviceaccount.com%2F20250411%2Fauto%2Fstorage%2Fgoog4_request&X-Goog-Date=20250411T134634Z&X-Goog-Expires=86399&X-Goog-Signature=4cd10bd589b82e59e27f62a38c7bb859f6315c8a3069f8c95f2b591b6d3a6f96f6cd958040991552a4208cd0e515ea04482dcb1ca32f1ee8f112a9b042da67ef144cb108a105d48d05bdbb86727c5c582615c7931ca7875be77f1e227f3cfbbbabc8417731c4b82ab6769881ee62e375155669ebec4934959856d4a8a2e6fdeaeab1cb06373c7866934a72235500ff61608d04e6a4e6447283f4046d87760e7658444706049c275c8f2fc043498682ac8fbdca5f494b43bd9838f8d8cb8009ffb7896ffb5c219b1f6a8fc992a9df4b59754e5d93a80dafdecf9a6b991c4defa8dc75553a784dcdc6ae3d13b2b7dd71a715a1f70a81feac5341924b175293b18a&X-Goog-SignedHeaders=host&X-User=2931823730 (Caused by NewConnectionError('<urllib3.connection.HTTPSConnection object at 0x7f78a9fcace0>: Failed to establish a new connection: [Errno 101] Network is unreachable'))
2025-04-11 13:47:44,846 ERROR   wandb-upload_1:5729 [internal_api.py:upload_file():2558] upload_file request headers: {'User-Agent': 'python-requests/2.32.3', 'Accept-Encoding': 'gzip, deflate, br', 'Accept': '*/*', 'Connection': 'keep-alive', 'Content-Length': '8684'}
2025-04-11 13:47:44,846 ERROR   wandb-upload_1:5729 [internal_api.py:upload_file():2560] upload_file response body: 
2025-04-11 13:47:45,106 ERROR   wandb-upload_3:5729 [internal_api.py:upload_file():2556] upload_file exception https://storage.googleapis.com/wandb-production.appspot.com/2931823730-harbin-institute-of-technology/ltu-as/e1rp2dmj/conda-environment.yaml?X-Goog-Algorithm=GOOG4-RSA-SHA256&X-Goog-Credential=gorilla-files-url-signer-man%40wandb-production.iam.gserviceaccount.com%2F20250411%2Fauto%2Fstorage%2Fgoog4_request&X-Goog-Date=20250411T134634Z&X-Goog-Expires=86399&X-Goog-Signature=265e438ee1e70b800d8a7fecfc5ad7df5c6466d860f091f7203140cddce9cf7c92daef52f7ce3e701a0c43e1f92589bbf32fcf34e3491bd34b94e81bf4d369c1acaad089236cab81b7188596c894dc002373a96c6f456f16feb1cf4fc97ba6c918c66221de710c322f624fc3beafa22a0e6267b0d3e03a930092368d7bd298205cfb04835e4b98073b7419be36903de0a53256ad826c162ab35548a4b743df5a7f158aa3ba83515129d2bc120a7668d5f6ba72729786d61f070b892b4caae0f489a444d306207d8845ddfaf36cb07c97e8491db8a6cd464df6b44b458fd31bfb7aec6900e7bce07aa5d7d06f66942850410ced96674f6d13dbde8735c065b758&X-Goog-SignedHeaders=host&X-User=2931823730: HTTPSConnectionPool(host='storage.googleapis.com', port=443): Max retries exceeded with url: /wandb-production.appspot.com/2931823730-harbin-institute-of-technology/ltu-as/e1rp2dmj/conda-environment.yaml?X-Goog-Algorithm=GOOG4-RSA-SHA256&X-Goog-Credential=gorilla-files-url-signer-man%40wandb-production.iam.gserviceaccount.com%2F20250411%2Fauto%2Fstorage%2Fgoog4_request&X-Goog-Date=20250411T134634Z&X-Goog-Expires=86399&X-Goog-Signature=265e438ee1e70b800d8a7fecfc5ad7df5c6466d860f091f7203140cddce9cf7c92daef52f7ce3e701a0c43e1f92589bbf32fcf34e3491bd34b94e81bf4d369c1acaad089236cab81b7188596c894dc002373a96c6f456f16feb1cf4fc97ba6c918c66221de710c322f624fc3beafa22a0e6267b0d3e03a930092368d7bd298205cfb04835e4b98073b7419be36903de0a53256ad826c162ab35548a4b743df5a7f158aa3ba83515129d2bc120a7668d5f6ba72729786d61f070b892b4caae0f489a444d306207d8845ddfaf36cb07c97e8491db8a6cd464df6b44b458fd31bfb7aec6900e7bce07aa5d7d06f66942850410ced96674f6d13dbde8735c065b758&X-Goog-SignedHeaders=host&X-User=2931823730 (Caused by NewConnectionError('<urllib3.connection.HTTPSConnection object at 0x7f78a9fcad70>: Failed to establish a new connection: [Errno 101] Network is unreachable'))
2025-04-11 13:47:45,107 ERROR   wandb-upload_3:5729 [internal_api.py:upload_file():2558] upload_file request headers: {'User-Agent': 'python-requests/2.32.3', 'Accept-Encoding': 'gzip, deflate, br', 'Accept': '*/*', 'Connection': 'keep-alive', 'Content-Length': '8281'}
2025-04-11 13:47:45,107 ERROR   wandb-upload_3:5729 [internal_api.py:upload_file():2560] upload_file response body: 
2025-04-11 13:47:46,908 DEBUG   HandlerThread:5729 [handler.py:handle_request():146] handle_request: status_report
2025-04-11 13:47:47,232 DEBUG   HandlerThread:5729 [handler.py:handle_request():146] handle_request: keepalive
2025-04-11 13:47:51,909 DEBUG   HandlerThread:5729 [handler.py:handle_request():146] handle_request: status_report
2025-04-11 13:47:52,234 DEBUG   HandlerThread:5729 [handler.py:handle_request():146] handle_request: keepalive
2025-04-11 13:47:56,910 DEBUG   HandlerThread:5729 [handler.py:handle_request():146] handle_request: status_report
2025-04-11 13:47:57,236 DEBUG   HandlerThread:5729 [handler.py:handle_request():146] handle_request: keepalive
2025-04-11 13:48:01,911 DEBUG   HandlerThread:5729 [handler.py:handle_request():146] handle_request: status_report
2025-04-11 13:48:02,238 DEBUG   HandlerThread:5729 [handler.py:handle_request():146] handle_request: keepalive
2025-04-11 13:48:06,920 DEBUG   HandlerThread:5729 [handler.py:handle_request():146] handle_request: status_report
2025-04-11 13:48:07,240 DEBUG   HandlerThread:5729 [handler.py:handle_request():146] handle_request: keepalive
2025-04-11 13:48:11,921 DEBUG   HandlerThread:5729 [handler.py:handle_request():146] handle_request: status_report
2025-04-11 13:48:12,242 DEBUG   HandlerThread:5729 [handler.py:handle_request():146] handle_request: keepalive
2025-04-11 13:48:16,922 DEBUG   HandlerThread:5729 [handler.py:handle_request():146] handle_request: status_report
2025-04-11 13:48:17,244 DEBUG   HandlerThread:5729 [handler.py:handle_request():146] handle_request: keepalive
2025-04-11 13:48:21,923 DEBUG   HandlerThread:5729 [handler.py:handle_request():146] handle_request: status_report
2025-04-11 13:48:22,246 DEBUG   HandlerThread:5729 [handler.py:handle_request():146] handle_request: keepalive
2025-04-11 13:48:26,924 DEBUG   HandlerThread:5729 [handler.py:handle_request():146] handle_request: status_report
2025-04-11 13:48:27,248 DEBUG   HandlerThread:5729 [handler.py:handle_request():146] handle_request: keepalive
2025-04-11 13:48:31,925 DEBUG   HandlerThread:5729 [handler.py:handle_request():146] handle_request: status_report
2025-04-11 13:48:32,250 DEBUG   HandlerThread:5729 [handler.py:handle_request():146] handle_request: keepalive
2025-04-11 13:48:36,926 DEBUG   HandlerThread:5729 [handler.py:handle_request():146] handle_request: status_report
2025-04-11 13:48:37,252 DEBUG   HandlerThread:5729 [handler.py:handle_request():146] handle_request: keepalive
2025-04-11 13:48:39,914 INFO    wandb-upload_0:5729 [upload_job.py:push():131] Uploaded file /tmp/tmpidk01ry9wandb/6tzxnkl0-wandb-metadata.json
2025-04-11 13:48:41,927 DEBUG   HandlerThread:5729 [handler.py:handle_request():146] handle_request: status_report
2025-04-11 13:48:42,254 DEBUG   HandlerThread:5729 [handler.py:handle_request():146] handle_request: keepalive
2025-04-11 13:48:46,929 DEBUG   HandlerThread:5729 [handler.py:handle_request():146] handle_request: status_report
2025-04-11 13:48:47,256 DEBUG   HandlerThread:5729 [handler.py:handle_request():146] handle_request: keepalive
2025-04-11 13:48:49,553 INFO    wandb-upload_2:5729 [upload_job.py:push():131] Uploaded file /root/ltu-main/ltu-main/src/ltu_as/train_scripts/wandb/run-20250411_134558-e1rp2dmj/files/requirements.txt
2025-04-11 13:48:51,930 DEBUG   HandlerThread:5729 [handler.py:handle_request():146] handle_request: status_report
2025-04-11 13:48:52,259 DEBUG   HandlerThread:5729 [handler.py:handle_request():146] handle_request: keepalive
2025-04-11 13:48:54,646 INFO    wandb-upload_5:5729 [upload_job.py:push():131] Uploaded file /root/ltu-main/ltu-main/src/ltu_as/train_scripts/wandb/run-20250411_134558-e1rp2dmj/files/wandb-summary.json
2025-04-11 13:48:56,931 DEBUG   HandlerThread:5729 [handler.py:handle_request():146] handle_request: status_report
2025-04-11 13:48:57,260 DEBUG   HandlerThread:5729 [handler.py:handle_request():146] handle_request: keepalive
2025-04-11 13:48:57,775 INFO    wandb-upload_4:5729 [upload_job.py:push():131] Uploaded file /root/ltu-main/ltu-main/src/ltu_as/train_scripts/wandb/run-20250411_134558-e1rp2dmj/files/output.log
2025-04-11 13:48:58,328 INFO    wandb-upload_1:5729 [upload_job.py:push():131] Uploaded file /root/ltu-main/ltu-main/src/ltu_as/train_scripts/wandb/run-20250411_134558-e1rp2dmj/files/config.yaml
2025-04-11 13:49:01,932 DEBUG   HandlerThread:5729 [handler.py:handle_request():146] handle_request: status_report
2025-04-11 13:49:02,262 DEBUG   HandlerThread:5729 [handler.py:handle_request():146] handle_request: keepalive
2025-04-11 13:49:04,220 INFO    wandb-upload_3:5729 [upload_job.py:push():131] Uploaded file /root/ltu-main/ltu-main/src/ltu_as/train_scripts/wandb/run-20250411_134558-e1rp2dmj/files/conda-environment.yaml
2025-04-11 13:49:04,420 INFO    Thread-11 (_thread_body):5729 [sender.py:transition_state():613] send defer: 11
2025-04-11 13:49:04,421 DEBUG   HandlerThread:5729 [handler.py:handle_request():146] handle_request: defer
2025-04-11 13:49:04,422 INFO    HandlerThread:5729 [handler.py:handle_request_defer():172] handle defer: 11
2025-04-11 13:49:04,422 DEBUG   SenderThread:5729 [sender.py:send_request():407] send_request: defer
2025-04-11 13:49:04,423 INFO    SenderThread:5729 [sender.py:send_request_defer():609] handle sender defer: 11
2025-04-11 13:49:04,423 INFO    SenderThread:5729 [file_pusher.py:join():181] waiting for file pusher
2025-04-11 13:49:04,423 INFO    SenderThread:5729 [sender.py:transition_state():613] send defer: 12
2025-04-11 13:49:04,423 DEBUG   HandlerThread:5729 [handler.py:handle_request():146] handle_request: defer
2025-04-11 13:49:04,424 INFO    HandlerThread:5729 [handler.py:handle_request_defer():172] handle defer: 12
2025-04-11 13:49:04,424 DEBUG   SenderThread:5729 [sender.py:send_request():407] send_request: defer
2025-04-11 13:49:04,424 INFO    SenderThread:5729 [sender.py:send_request_defer():609] handle sender defer: 12
2025-04-11 13:49:04,424 INFO    SenderThread:5729 [file_stream.py:finish():595] file stream finish called
2025-04-11 13:49:04,725 INFO    SenderThread:5729 [file_stream.py:finish():599] file stream finish is done
2025-04-11 13:49:04,725 INFO    SenderThread:5729 [sender.py:transition_state():613] send defer: 13
2025-04-11 13:49:04,725 DEBUG   HandlerThread:5729 [handler.py:handle_request():146] handle_request: defer
2025-04-11 13:49:04,725 INFO    HandlerThread:5729 [handler.py:handle_request_defer():172] handle defer: 13
2025-04-11 13:49:04,726 DEBUG   SenderThread:5729 [sender.py:send_request():407] send_request: defer
2025-04-11 13:49:04,726 INFO    SenderThread:5729 [sender.py:send_request_defer():609] handle sender defer: 13
2025-04-11 13:49:04,726 INFO    SenderThread:5729 [sender.py:transition_state():613] send defer: 14
2025-04-11 13:49:04,726 DEBUG   HandlerThread:5729 [handler.py:handle_request():146] handle_request: defer
2025-04-11 13:49:04,726 INFO    HandlerThread:5729 [handler.py:handle_request_defer():172] handle defer: 14
2025-04-11 13:49:04,727 DEBUG   SenderThread:5729 [sender.py:send():380] send: final
2025-04-11 13:49:04,727 DEBUG   SenderThread:5729 [sender.py:send():380] send: footer
2025-04-11 13:49:04,727 DEBUG   SenderThread:5729 [sender.py:send_request():407] send_request: defer
2025-04-11 13:49:04,727 INFO    SenderThread:5729 [sender.py:send_request_defer():609] handle sender defer: 14
2025-04-11 13:49:04,728 DEBUG   HandlerThread:5729 [handler.py:handle_request():146] handle_request: poll_exit
2025-04-11 13:49:04,729 DEBUG   HandlerThread:5729 [handler.py:handle_request():146] handle_request: server_info
2025-04-11 13:49:04,729 DEBUG   SenderThread:5729 [sender.py:send_request():407] send_request: poll_exit
2025-04-11 13:49:04,730 DEBUG   SenderThread:5729 [sender.py:send_request():407] send_request: server_info
2025-04-11 13:49:04,733 DEBUG   HandlerThread:5729 [handler.py:handle_request():146] handle_request: get_summary
2025-04-11 13:49:04,734 DEBUG   HandlerThread:5729 [handler.py:handle_request():146] handle_request: sampled_history
2025-04-11 13:49:04,734 DEBUG   HandlerThread:5729 [handler.py:handle_request():146] handle_request: internal_messages
2025-04-11 13:49:04,734 DEBUG   HandlerThread:5729 [handler.py:handle_request():146] handle_request: job_info
2025-04-11 13:49:05,014 DEBUG   SenderThread:5729 [sender.py:send_request():407] send_request: job_info
2025-04-11 13:49:05,015 INFO    MainThread:5729 [wandb_run.py:_footer_history_summary_info():3599] rendering history
2025-04-11 13:49:05,015 INFO    MainThread:5729 [wandb_run.py:_footer_history_summary_info():3631] rendering summary
2025-04-11 13:49:05,015 INFO    MainThread:5729 [wandb_run.py:_footer_sync_info():3558] logging synced files
2025-04-11 13:49:05,015 DEBUG   HandlerThread:5729 [handler.py:handle_request():146] handle_request: shutdown
2025-04-11 13:49:05,015 INFO    HandlerThread:5729 [handler.py:finish():866] shutting down handler
2025-04-11 13:49:05,734 INFO    WriterThread:5729 [datastore.py:close():294] close: /root/ltu-main/ltu-main/src/ltu_as/train_scripts/wandb/run-20250411_134558-e1rp2dmj/run-e1rp2dmj.wandb
2025-04-11 13:49:06,015 INFO    SenderThread:5729 [sender.py:finish():1534] shutting down sender
2025-04-11 13:49:06,015 INFO    SenderThread:5729 [file_pusher.py:finish():175] shutting down file pusher
2025-04-11 13:49:06,015 INFO    SenderThread:5729 [file_pusher.py:join():181] waiting for file pusher
