2025-04-11 13:34:57,551 INFO    StreamThr :5057 [internal.py:wandb_internal():86] W&B internal server running at pid: 5057, started at: 2025-04-11 13:34:57.550740
2025-04-11 13:34:57,554 DEBUG   HandlerThread:5057 [handler.py:handle_request():146] handle_request: status
2025-04-11 13:34:57,561 INFO    WriterThread:5057 [datastore.py:open_for_write():85] open: /root/ltu-main/ltu-main/src/ltu_as/train_scripts/wandb/run-20250411_133457-ayrd945g/run-ayrd945g.wandb
2025-04-11 13:34:57,562 DEBUG   SenderThread:5057 [sender.py:send():380] send: header
2025-04-11 13:34:57,562 DEBUG   SenderThread:5057 [sender.py:send():380] send: run
2025-04-11 13:34:58,359 INFO    SenderThread:5057 [dir_watcher.py:__init__():211] watching files in: /root/ltu-main/ltu-main/src/ltu_as/train_scripts/wandb/run-20250411_133457-ayrd945g/files
2025-04-11 13:34:58,359 INFO    SenderThread:5057 [sender.py:_start_run_threads():1122] run started: ayrd945g with start time 1744378497.551331
2025-04-11 13:34:58,363 DEBUG   HandlerThread:5057 [handler.py:handle_request():146] handle_request: check_version
2025-04-11 13:34:58,363 DEBUG   SenderThread:5057 [sender.py:send_request():407] send_request: check_version
2025-04-11 13:34:58,989 DEBUG   HandlerThread:5057 [handler.py:handle_request():146] handle_request: run_start
2025-04-11 13:34:59,004 DEBUG   HandlerThread:5057 [system_info.py:__init__():32] System info init
2025-04-11 13:34:59,004 DEBUG   HandlerThread:5057 [system_info.py:__init__():47] System info init done
2025-04-11 13:34:59,004 INFO    HandlerThread:5057 [system_monitor.py:start():194] Starting system monitor
2025-04-11 13:34:59,004 INFO    SystemMonitor:5057 [system_monitor.py:_start():158] Starting system asset monitoring threads
2025-04-11 13:34:59,004 INFO    HandlerThread:5057 [system_monitor.py:probe():214] Collecting system info
2025-04-11 13:34:59,005 INFO    SystemMonitor:5057 [interfaces.py:start():190] Started cpu monitoring
2025-04-11 13:34:59,007 INFO    SystemMonitor:5057 [interfaces.py:start():190] Started disk monitoring
2025-04-11 13:34:59,008 INFO    SystemMonitor:5057 [interfaces.py:start():190] Started gpu monitoring
2025-04-11 13:34:59,009 INFO    SystemMonitor:5057 [interfaces.py:start():190] Started memory monitoring
2025-04-11 13:34:59,011 INFO    SystemMonitor:5057 [interfaces.py:start():190] Started network monitoring
2025-04-11 13:34:59,020 DEBUG   HandlerThread:5057 [system_info.py:probe():196] Probing system
2025-04-11 13:34:59,022 DEBUG   HandlerThread:5057 [gitlib.py:_init_repo():53] git repository is invalid
2025-04-11 13:34:59,022 DEBUG   HandlerThread:5057 [system_info.py:probe():244] Probing system done
2025-04-11 13:34:59,022 DEBUG   HandlerThread:5057 [system_monitor.py:probe():223] {'os': 'Linux-4.15.0-213-generic-x86_64-with-glibc2.27', 'python': '3.10.15', 'heartbeatAt': '2025-04-11T13:34:59.021099', 'startedAt': '2025-04-11T13:34:57.535361', 'docker': None, 'cuda': None, 'args': ('--base_model', '../../../pretrained_mdls/ltuas_long_noqa_a6.bin', '--data_path', '/root/ltu-main/ltu-main/openasqa/data/meld_data.json', '--output_dir', '../exp/ltuas_ft_meld/', '--batch_size', '256', '--micro_batch_size', '1', '--num_epochs', '1', '--learning_rate', '2e-4', '--cutoff_len', '100', '--val_set_size', '0', '--lora_r', '8', '--lora_alpha', '16', '--lora_dropout', '0.05', '--lora_target_modules', '[q_proj,v_proj]', '--group_by_length', '--wandb_run_name', '../exp/ltuas_ft_meld/', '--save_steps', '30', '--trainable_params', 'all'), 'state': 'running', 'program': '/root/ltu-main/ltu-main/src/ltu_as/train_scripts/../finetune_low_resource.py', 'codePathLocal': None, 'host': 'ubuntu', 'username': 'root', 'executable': '/root/anaconda3/envs/venv_ltu/bin/python', 'cpu_count': 4, 'cpu_count_logical': 4, 'cpu_freq': {'current': 2294.598, 'min': 0.0, 'max': 0.0}, 'cpu_freq_per_core': [{'current': 2294.598, 'min': 0.0, 'max': 0.0}, {'current': 2294.598, 'min': 0.0, 'max': 0.0}, {'current': 2294.598, 'min': 0.0, 'max': 0.0}, {'current': 2294.598, 'min': 0.0, 'max': 0.0}], 'disk': {'/': {'total': 499.9882621765137, 'used': 333.22413635253906}}, 'gpu': 'NVIDIA A100-PCIE-40GB', 'gpu_count': 1, 'gpu_devices': [{'name': 'NVIDIA A100-PCIE-40GB', 'memory_total': 42949672960}], 'memory': {'total': 19.60204315185547}}
2025-04-11 13:34:59,022 INFO    HandlerThread:5057 [system_monitor.py:probe():224] Finished collecting system info
2025-04-11 13:34:59,022 INFO    HandlerThread:5057 [system_monitor.py:probe():227] Publishing system info
2025-04-11 13:34:59,022 DEBUG   HandlerThread:5057 [system_info.py:_save_pip():52] Saving list of pip packages installed into the current environment
2025-04-11 13:34:59,023 DEBUG   HandlerThread:5057 [system_info.py:_save_pip():68] Saving pip packages done
2025-04-11 13:34:59,023 DEBUG   HandlerThread:5057 [system_info.py:_save_conda():75] Saving list of conda packages installed into the current environment
2025-04-11 13:34:59,357 INFO    Thread-12 :5057 [dir_watcher.py:_on_file_created():271] file/dir created: /root/ltu-main/ltu-main/src/ltu_as/train_scripts/wandb/run-20250411_133457-ayrd945g/files/conda-environment.yaml
2025-04-11 13:34:59,357 INFO    Thread-12 :5057 [dir_watcher.py:_on_file_created():271] file/dir created: /root/ltu-main/ltu-main/src/ltu_as/train_scripts/wandb/run-20250411_133457-ayrd945g/files/requirements.txt
2025-04-11 13:35:30,761 DEBUG   HandlerThread:5057 [system_info.py:_save_conda():87] Saving conda packages done
2025-04-11 13:35:30,762 INFO    HandlerThread:5057 [system_monitor.py:probe():229] Finished publishing system info
2025-04-11 13:35:30,898 DEBUG   HandlerThread:5057 [handler.py:handle_request():146] handle_request: status_report
2025-04-11 13:35:30,899 DEBUG   HandlerThread:5057 [handler.py:handle_request():146] handle_request: keepalive
2025-04-11 13:35:30,900 DEBUG   HandlerThread:5057 [handler.py:handle_request():146] handle_request: status_report
2025-04-11 13:35:30,900 DEBUG   HandlerThread:5057 [handler.py:handle_request():146] handle_request: keepalive
2025-04-11 13:35:30,900 DEBUG   HandlerThread:5057 [handler.py:handle_request():146] handle_request: status_report
2025-04-11 13:35:30,900 DEBUG   HandlerThread:5057 [handler.py:handle_request():146] handle_request: keepalive
2025-04-11 13:35:30,900 DEBUG   HandlerThread:5057 [handler.py:handle_request():146] handle_request: status_report
2025-04-11 13:35:30,901 DEBUG   HandlerThread:5057 [handler.py:handle_request():146] handle_request: keepalive
2025-04-11 13:35:30,901 DEBUG   HandlerThread:5057 [handler.py:handle_request():146] handle_request: status_report
2025-04-11 13:35:30,901 DEBUG   HandlerThread:5057 [handler.py:handle_request():146] handle_request: keepalive
2025-04-11 13:35:30,901 DEBUG   HandlerThread:5057 [handler.py:handle_request():146] handle_request: status_report
2025-04-11 13:35:30,901 DEBUG   HandlerThread:5057 [handler.py:handle_request():146] handle_request: stop_status
2025-04-11 13:35:30,902 DEBUG   HandlerThread:5057 [handler.py:handle_request():146] handle_request: internal_messages
2025-04-11 13:35:30,903 DEBUG   SenderThread:5057 [sender.py:send():380] send: telemetry
2025-04-11 13:35:30,903 DEBUG   SenderThread:5057 [sender.py:send_request():407] send_request: stop_status
2025-04-11 13:35:31,170 DEBUG   SenderThread:5057 [sender.py:send():380] send: config
2025-04-11 13:35:31,172 DEBUG   SenderThread:5057 [sender.py:send():380] send: metric
2025-04-11 13:35:31,172 DEBUG   SenderThread:5057 [sender.py:send():380] send: telemetry
2025-04-11 13:35:31,173 DEBUG   SenderThread:5057 [sender.py:send():380] send: metric
2025-04-11 13:35:31,173 WARNING SenderThread:5057 [sender.py:send_metric():1329] Seen metric with glob (shouldn't happen)
2025-04-11 13:35:31,174 DEBUG   SenderThread:5057 [sender.py:send():380] send: files
2025-04-11 13:35:31,174 INFO    SenderThread:5057 [sender.py:_save_file():1378] saving file wandb-metadata.json with policy now
2025-04-11 13:35:31,367 INFO    Thread-12 :5057 [dir_watcher.py:_on_file_modified():288] file/dir modified: /root/ltu-main/ltu-main/src/ltu_as/train_scripts/wandb/run-20250411_133457-ayrd945g/files/conda-environment.yaml
2025-04-11 13:35:31,368 INFO    Thread-12 :5057 [dir_watcher.py:_on_file_created():271] file/dir created: /root/ltu-main/ltu-main/src/ltu_as/train_scripts/wandb/run-20250411_133457-ayrd945g/files/output.log
2025-04-11 13:35:31,368 INFO    Thread-12 :5057 [dir_watcher.py:_on_file_created():271] file/dir created: /root/ltu-main/ltu-main/src/ltu_as/train_scripts/wandb/run-20250411_133457-ayrd945g/files/wandb-metadata.json
2025-04-11 13:35:31,699 ERROR   wandb-upload_0:5057 [internal_api.py:upload_file():2556] upload_file exception https://storage.googleapis.com/wandb-production.appspot.com/2931823730-harbin-institute-of-technology/ltu-as/ayrd945g/wandb-metadata.json?X-Goog-Algorithm=GOOG4-RSA-SHA256&X-Goog-Credential=gorilla-files-url-signer-man%40wandb-production.iam.gserviceaccount.com%2F20250411%2Fauto%2Fstorage%2Fgoog4_request&X-Goog-Date=20250411T133531Z&X-Goog-Expires=86399&X-Goog-Signature=3f5aee34cfa797b7aa73f667422a4aee946d1072dcec6b4021fa16645cebbf9a6738f93929154478c65a583fe2e5451e23e58739b96fa5355a823d0848191cccf627be8a9b51eee5861c7ed65eeead014bbceb2dcaeeef78dcdb79f5d1c045f21707476081794fb0708d6ec543c2f328439ef45907a15b52a6f64bbdbbf40ac08a2e90802e63ba340ae771978232c617a39b97d3caff9929e0c70b5a278c509f73435a1bac9fdee8a302d4e14c9e0a1f951e09f2537482c5c835c4eeb93f0efc7b988c8cfecc28c793061d2726f554ddc64313056228b705299a06a992a33bc9e5d77e2dd03adbb5b76f7b20314f6bb3c131cf504b3a39390ed6e8b4e6d7ba46&X-Goog-SignedHeaders=host&X-User=2931823730: HTTPSConnectionPool(host='storage.googleapis.com', port=443): Max retries exceeded with url: /wandb-production.appspot.com/2931823730-harbin-institute-of-technology/ltu-as/ayrd945g/wandb-metadata.json?X-Goog-Algorithm=GOOG4-RSA-SHA256&X-Goog-Credential=gorilla-files-url-signer-man%40wandb-production.iam.gserviceaccount.com%2F20250411%2Fauto%2Fstorage%2Fgoog4_request&X-Goog-Date=20250411T133531Z&X-Goog-Expires=86399&X-Goog-Signature=3f5aee34cfa797b7aa73f667422a4aee946d1072dcec6b4021fa16645cebbf9a6738f93929154478c65a583fe2e5451e23e58739b96fa5355a823d0848191cccf627be8a9b51eee5861c7ed65eeead014bbceb2dcaeeef78dcdb79f5d1c045f21707476081794fb0708d6ec543c2f328439ef45907a15b52a6f64bbdbbf40ac08a2e90802e63ba340ae771978232c617a39b97d3caff9929e0c70b5a278c509f73435a1bac9fdee8a302d4e14c9e0a1f951e09f2537482c5c835c4eeb93f0efc7b988c8cfecc28c793061d2726f554ddc64313056228b705299a06a992a33bc9e5d77e2dd03adbb5b76f7b20314f6bb3c131cf504b3a39390ed6e8b4e6d7ba46&X-Goog-SignedHeaders=host&X-User=2931823730 (Caused by NewConnectionError('<urllib3.connection.HTTPSConnection object at 0x7fcdd01c1210>: Failed to establish a new connection: [Errno 101] Network is unreachable'))
2025-04-11 13:35:31,699 ERROR   wandb-upload_0:5057 [internal_api.py:upload_file():2558] upload_file request headers: {'User-Agent': 'python-requests/2.32.3', 'Accept-Encoding': 'gzip, deflate, br', 'Accept': '*/*', 'Connection': 'keep-alive', 'Content-Length': '2259'}
2025-04-11 13:35:31,699 ERROR   wandb-upload_0:5057 [internal_api.py:upload_file():2560] upload_file response body: 
2025-04-11 13:35:32,901 ERROR   wandb-upload_0:5057 [internal_api.py:upload_file():2556] upload_file exception https://storage.googleapis.com/wandb-production.appspot.com/2931823730-harbin-institute-of-technology/ltu-as/ayrd945g/wandb-metadata.json?X-Goog-Algorithm=GOOG4-RSA-SHA256&X-Goog-Credential=gorilla-files-url-signer-man%40wandb-production.iam.gserviceaccount.com%2F20250411%2Fauto%2Fstorage%2Fgoog4_request&X-Goog-Date=20250411T133531Z&X-Goog-Expires=86399&X-Goog-Signature=3f5aee34cfa797b7aa73f667422a4aee946d1072dcec6b4021fa16645cebbf9a6738f93929154478c65a583fe2e5451e23e58739b96fa5355a823d0848191cccf627be8a9b51eee5861c7ed65eeead014bbceb2dcaeeef78dcdb79f5d1c045f21707476081794fb0708d6ec543c2f328439ef45907a15b52a6f64bbdbbf40ac08a2e90802e63ba340ae771978232c617a39b97d3caff9929e0c70b5a278c509f73435a1bac9fdee8a302d4e14c9e0a1f951e09f2537482c5c835c4eeb93f0efc7b988c8cfecc28c793061d2726f554ddc64313056228b705299a06a992a33bc9e5d77e2dd03adbb5b76f7b20314f6bb3c131cf504b3a39390ed6e8b4e6d7ba46&X-Goog-SignedHeaders=host&X-User=2931823730: HTTPSConnectionPool(host='storage.googleapis.com', port=443): Max retries exceeded with url: /wandb-production.appspot.com/2931823730-harbin-institute-of-technology/ltu-as/ayrd945g/wandb-metadata.json?X-Goog-Algorithm=GOOG4-RSA-SHA256&X-Goog-Credential=gorilla-files-url-signer-man%40wandb-production.iam.gserviceaccount.com%2F20250411%2Fauto%2Fstorage%2Fgoog4_request&X-Goog-Date=20250411T133531Z&X-Goog-Expires=86399&X-Goog-Signature=3f5aee34cfa797b7aa73f667422a4aee946d1072dcec6b4021fa16645cebbf9a6738f93929154478c65a583fe2e5451e23e58739b96fa5355a823d0848191cccf627be8a9b51eee5861c7ed65eeead014bbceb2dcaeeef78dcdb79f5d1c045f21707476081794fb0708d6ec543c2f328439ef45907a15b52a6f64bbdbbf40ac08a2e90802e63ba340ae771978232c617a39b97d3caff9929e0c70b5a278c509f73435a1bac9fdee8a302d4e14c9e0a1f951e09f2537482c5c835c4eeb93f0efc7b988c8cfecc28c793061d2726f554ddc64313056228b705299a06a992a33bc9e5d77e2dd03adbb5b76f7b20314f6bb3c131cf504b3a39390ed6e8b4e6d7ba46&X-Goog-SignedHeaders=host&X-User=2931823730 (Caused by NewConnectionError('<urllib3.connection.HTTPSConnection object at 0x7fcdd01c22f0>: Failed to establish a new connection: [Errno 101] Network is unreachable'))
2025-04-11 13:35:32,901 ERROR   wandb-upload_0:5057 [internal_api.py:upload_file():2558] upload_file request headers: {'User-Agent': 'python-requests/2.32.3', 'Accept-Encoding': 'gzip, deflate, br', 'Accept': '*/*', 'Connection': 'keep-alive', 'Content-Length': '2259'}
2025-04-11 13:35:32,901 ERROR   wandb-upload_0:5057 [internal_api.py:upload_file():2560] upload_file response body: 
2025-04-11 13:35:33,175 DEBUG   HandlerThread:5057 [handler.py:handle_request():146] handle_request: status_report
2025-04-11 13:35:33,368 INFO    Thread-12 :5057 [dir_watcher.py:_on_file_modified():288] file/dir modified: /root/ltu-main/ltu-main/src/ltu_as/train_scripts/wandb/run-20250411_133457-ayrd945g/files/output.log
2025-04-11 13:35:35,050 ERROR   wandb-upload_0:5057 [internal_api.py:upload_file():2556] upload_file exception https://storage.googleapis.com/wandb-production.appspot.com/2931823730-harbin-institute-of-technology/ltu-as/ayrd945g/wandb-metadata.json?X-Goog-Algorithm=GOOG4-RSA-SHA256&X-Goog-Credential=gorilla-files-url-signer-man%40wandb-production.iam.gserviceaccount.com%2F20250411%2Fauto%2Fstorage%2Fgoog4_request&X-Goog-Date=20250411T133531Z&X-Goog-Expires=86399&X-Goog-Signature=3f5aee34cfa797b7aa73f667422a4aee946d1072dcec6b4021fa16645cebbf9a6738f93929154478c65a583fe2e5451e23e58739b96fa5355a823d0848191cccf627be8a9b51eee5861c7ed65eeead014bbceb2dcaeeef78dcdb79f5d1c045f21707476081794fb0708d6ec543c2f328439ef45907a15b52a6f64bbdbbf40ac08a2e90802e63ba340ae771978232c617a39b97d3caff9929e0c70b5a278c509f73435a1bac9fdee8a302d4e14c9e0a1f951e09f2537482c5c835c4eeb93f0efc7b988c8cfecc28c793061d2726f554ddc64313056228b705299a06a992a33bc9e5d77e2dd03adbb5b76f7b20314f6bb3c131cf504b3a39390ed6e8b4e6d7ba46&X-Goog-SignedHeaders=host&X-User=2931823730: HTTPSConnectionPool(host='storage.googleapis.com', port=443): Max retries exceeded with url: /wandb-production.appspot.com/2931823730-harbin-institute-of-technology/ltu-as/ayrd945g/wandb-metadata.json?X-Goog-Algorithm=GOOG4-RSA-SHA256&X-Goog-Credential=gorilla-files-url-signer-man%40wandb-production.iam.gserviceaccount.com%2F20250411%2Fauto%2Fstorage%2Fgoog4_request&X-Goog-Date=20250411T133531Z&X-Goog-Expires=86399&X-Goog-Signature=3f5aee34cfa797b7aa73f667422a4aee946d1072dcec6b4021fa16645cebbf9a6738f93929154478c65a583fe2e5451e23e58739b96fa5355a823d0848191cccf627be8a9b51eee5861c7ed65eeead014bbceb2dcaeeef78dcdb79f5d1c045f21707476081794fb0708d6ec543c2f328439ef45907a15b52a6f64bbdbbf40ac08a2e90802e63ba340ae771978232c617a39b97d3caff9929e0c70b5a278c509f73435a1bac9fdee8a302d4e14c9e0a1f951e09f2537482c5c835c4eeb93f0efc7b988c8cfecc28c793061d2726f554ddc64313056228b705299a06a992a33bc9e5d77e2dd03adbb5b76f7b20314f6bb3c131cf504b3a39390ed6e8b4e6d7ba46&X-Goog-SignedHeaders=host&X-User=2931823730 (Caused by NewConnectionError('<urllib3.connection.HTTPSConnection object at 0x7fcdd01c2a70>: Failed to establish a new connection: [Errno 101] Network is unreachable'))
2025-04-11 13:35:35,050 ERROR   wandb-upload_0:5057 [internal_api.py:upload_file():2558] upload_file request headers: {'User-Agent': 'python-requests/2.32.3', 'Accept-Encoding': 'gzip, deflate, br', 'Accept': '*/*', 'Connection': 'keep-alive', 'Content-Length': '2259'}
2025-04-11 13:35:35,050 ERROR   wandb-upload_0:5057 [internal_api.py:upload_file():2560] upload_file response body: 
2025-04-11 13:35:35,050 INFO    wandb-upload_0:5057 [retry.py:__call__():172] Retry attempt failed:
Traceback (most recent call last):
  File "/root/anaconda3/envs/venv_ltu/lib/python3.10/site-packages/urllib3/connection.py", line 198, in _new_conn
    sock = connection.create_connection(
  File "/root/anaconda3/envs/venv_ltu/lib/python3.10/site-packages/urllib3/util/connection.py", line 85, in create_connection
    raise err
  File "/root/anaconda3/envs/venv_ltu/lib/python3.10/site-packages/urllib3/util/connection.py", line 73, in create_connection
    sock.connect(sa)
OSError: [Errno 101] Network is unreachable

The above exception was the direct cause of the following exception:

Traceback (most recent call last):
  File "/root/anaconda3/envs/venv_ltu/lib/python3.10/site-packages/urllib3/connectionpool.py", line 793, in urlopen
    response = self._make_request(
  File "/root/anaconda3/envs/venv_ltu/lib/python3.10/site-packages/urllib3/connectionpool.py", line 491, in _make_request
    raise new_e
  File "/root/anaconda3/envs/venv_ltu/lib/python3.10/site-packages/urllib3/connectionpool.py", line 467, in _make_request
    self._validate_conn(conn)
  File "/root/anaconda3/envs/venv_ltu/lib/python3.10/site-packages/urllib3/connectionpool.py", line 1099, in _validate_conn
    conn.connect()
  File "/root/anaconda3/envs/venv_ltu/lib/python3.10/site-packages/urllib3/connection.py", line 616, in connect
    self.sock = sock = self._new_conn()
  File "/root/anaconda3/envs/venv_ltu/lib/python3.10/site-packages/urllib3/connection.py", line 213, in _new_conn
    raise NewConnectionError(
urllib3.exceptions.NewConnectionError: <urllib3.connection.HTTPSConnection object at 0x7fcdd01c2a70>: Failed to establish a new connection: [Errno 101] Network is unreachable

The above exception was the direct cause of the following exception:

Traceback (most recent call last):
  File "/root/anaconda3/envs/venv_ltu/lib/python3.10/site-packages/requests/adapters.py", line 667, in send
    resp = conn.urlopen(
  File "/root/anaconda3/envs/venv_ltu/lib/python3.10/site-packages/urllib3/connectionpool.py", line 847, in urlopen
    retries = retries.increment(
  File "/root/anaconda3/envs/venv_ltu/lib/python3.10/site-packages/urllib3/util/retry.py", line 515, in increment
    raise MaxRetryError(_pool, url, reason) from reason  # type: ignore[arg-type]
urllib3.exceptions.MaxRetryError: HTTPSConnectionPool(host='storage.googleapis.com', port=443): Max retries exceeded with url: /wandb-production.appspot.com/2931823730-harbin-institute-of-technology/ltu-as/ayrd945g/wandb-metadata.json?X-Goog-Algorithm=GOOG4-RSA-SHA256&X-Goog-Credential=gorilla-files-url-signer-man%40wandb-production.iam.gserviceaccount.com%2F20250411%2Fauto%2Fstorage%2Fgoog4_request&X-Goog-Date=20250411T133531Z&X-Goog-Expires=86399&X-Goog-Signature=3f5aee34cfa797b7aa73f667422a4aee946d1072dcec6b4021fa16645cebbf9a6738f93929154478c65a583fe2e5451e23e58739b96fa5355a823d0848191cccf627be8a9b51eee5861c7ed65eeead014bbceb2dcaeeef78dcdb79f5d1c045f21707476081794fb0708d6ec543c2f328439ef45907a15b52a6f64bbdbbf40ac08a2e90802e63ba340ae771978232c617a39b97d3caff9929e0c70b5a278c509f73435a1bac9fdee8a302d4e14c9e0a1f951e09f2537482c5c835c4eeb93f0efc7b988c8cfecc28c793061d2726f554ddc64313056228b705299a06a992a33bc9e5d77e2dd03adbb5b76f7b20314f6bb3c131cf504b3a39390ed6e8b4e6d7ba46&X-Goog-SignedHeaders=host&X-User=2931823730 (Caused by NewConnectionError('<urllib3.connection.HTTPSConnection object at 0x7fcdd01c2a70>: Failed to establish a new connection: [Errno 101] Network is unreachable'))

During handling of the above exception, another exception occurred:

Traceback (most recent call last):
  File "/root/anaconda3/envs/venv_ltu/lib/python3.10/site-packages/wandb/sdk/internal/internal_api.py", line 2549, in upload_file
    response = self._upload_file_session.put(
  File "/root/anaconda3/envs/venv_ltu/lib/python3.10/site-packages/requests/sessions.py", line 649, in put
    return self.request("PUT", url, data=data, **kwargs)
  File "/root/anaconda3/envs/venv_ltu/lib/python3.10/site-packages/requests/sessions.py", line 589, in request
    resp = self.send(prep, **send_kwargs)
  File "/root/anaconda3/envs/venv_ltu/lib/python3.10/site-packages/requests/sessions.py", line 703, in send
    r = adapter.send(request, **kwargs)
  File "/root/anaconda3/envs/venv_ltu/lib/python3.10/site-packages/requests/adapters.py", line 700, in send
    raise ConnectionError(e, request=request)
requests.exceptions.ConnectionError: HTTPSConnectionPool(host='storage.googleapis.com', port=443): Max retries exceeded with url: /wandb-production.appspot.com/2931823730-harbin-institute-of-technology/ltu-as/ayrd945g/wandb-metadata.json?X-Goog-Algorithm=GOOG4-RSA-SHA256&X-Goog-Credential=gorilla-files-url-signer-man%40wandb-production.iam.gserviceaccount.com%2F20250411%2Fauto%2Fstorage%2Fgoog4_request&X-Goog-Date=20250411T133531Z&X-Goog-Expires=86399&X-Goog-Signature=3f5aee34cfa797b7aa73f667422a4aee946d1072dcec6b4021fa16645cebbf9a6738f93929154478c65a583fe2e5451e23e58739b96fa5355a823d0848191cccf627be8a9b51eee5861c7ed65eeead014bbceb2dcaeeef78dcdb79f5d1c045f21707476081794fb0708d6ec543c2f328439ef45907a15b52a6f64bbdbbf40ac08a2e90802e63ba340ae771978232c617a39b97d3caff9929e0c70b5a278c509f73435a1bac9fdee8a302d4e14c9e0a1f951e09f2537482c5c835c4eeb93f0efc7b988c8cfecc28c793061d2726f554ddc64313056228b705299a06a992a33bc9e5d77e2dd03adbb5b76f7b20314f6bb3c131cf504b3a39390ed6e8b4e6d7ba46&X-Goog-SignedHeaders=host&X-User=2931823730 (Caused by NewConnectionError('<urllib3.connection.HTTPSConnection object at 0x7fcdd01c2a70>: Failed to establish a new connection: [Errno 101] Network is unreachable'))

During handling of the above exception, another exception occurred:

Traceback (most recent call last):
  File "/root/anaconda3/envs/venv_ltu/lib/python3.10/site-packages/wandb/sdk/lib/retry.py", line 131, in __call__
    result = self._call_fn(*args, **kwargs)
  File "/root/anaconda3/envs/venv_ltu/lib/python3.10/site-packages/wandb/sdk/internal/internal_api.py", line 2580, in upload_file
    raise _e.with_traceback(sys.exc_info()[2])
  File "/root/anaconda3/envs/venv_ltu/lib/python3.10/site-packages/wandb/sdk/internal/internal_api.py", line 2549, in upload_file
    response = self._upload_file_session.put(
  File "/root/anaconda3/envs/venv_ltu/lib/python3.10/site-packages/requests/sessions.py", line 649, in put
    return self.request("PUT", url, data=data, **kwargs)
  File "/root/anaconda3/envs/venv_ltu/lib/python3.10/site-packages/requests/sessions.py", line 589, in request
    resp = self.send(prep, **send_kwargs)
  File "/root/anaconda3/envs/venv_ltu/lib/python3.10/site-packages/requests/sessions.py", line 703, in send
    r = adapter.send(request, **kwargs)
  File "/root/anaconda3/envs/venv_ltu/lib/python3.10/site-packages/requests/adapters.py", line 700, in send
    raise ConnectionError(e, request=request)
wandb.sdk.lib.retry.TransientError: None
2025-04-11 13:35:38,176 DEBUG   HandlerThread:5057 [handler.py:handle_request():146] handle_request: status_report
2025-04-11 13:35:40,260 ERROR   wandb-upload_0:5057 [internal_api.py:upload_file():2556] upload_file exception https://storage.googleapis.com/wandb-production.appspot.com/2931823730-harbin-institute-of-technology/ltu-as/ayrd945g/wandb-metadata.json?X-Goog-Algorithm=GOOG4-RSA-SHA256&X-Goog-Credential=gorilla-files-url-signer-man%40wandb-production.iam.gserviceaccount.com%2F20250411%2Fauto%2Fstorage%2Fgoog4_request&X-Goog-Date=20250411T133531Z&X-Goog-Expires=86399&X-Goog-Signature=3f5aee34cfa797b7aa73f667422a4aee946d1072dcec6b4021fa16645cebbf9a6738f93929154478c65a583fe2e5451e23e58739b96fa5355a823d0848191cccf627be8a9b51eee5861c7ed65eeead014bbceb2dcaeeef78dcdb79f5d1c045f21707476081794fb0708d6ec543c2f328439ef45907a15b52a6f64bbdbbf40ac08a2e90802e63ba340ae771978232c617a39b97d3caff9929e0c70b5a278c509f73435a1bac9fdee8a302d4e14c9e0a1f951e09f2537482c5c835c4eeb93f0efc7b988c8cfecc28c793061d2726f554ddc64313056228b705299a06a992a33bc9e5d77e2dd03adbb5b76f7b20314f6bb3c131cf504b3a39390ed6e8b4e6d7ba46&X-Goog-SignedHeaders=host&X-User=2931823730: HTTPSConnectionPool(host='storage.googleapis.com', port=443): Max retries exceeded with url: /wandb-production.appspot.com/2931823730-harbin-institute-of-technology/ltu-as/ayrd945g/wandb-metadata.json?X-Goog-Algorithm=GOOG4-RSA-SHA256&X-Goog-Credential=gorilla-files-url-signer-man%40wandb-production.iam.gserviceaccount.com%2F20250411%2Fauto%2Fstorage%2Fgoog4_request&X-Goog-Date=20250411T133531Z&X-Goog-Expires=86399&X-Goog-Signature=3f5aee34cfa797b7aa73f667422a4aee946d1072dcec6b4021fa16645cebbf9a6738f93929154478c65a583fe2e5451e23e58739b96fa5355a823d0848191cccf627be8a9b51eee5861c7ed65eeead014bbceb2dcaeeef78dcdb79f5d1c045f21707476081794fb0708d6ec543c2f328439ef45907a15b52a6f64bbdbbf40ac08a2e90802e63ba340ae771978232c617a39b97d3caff9929e0c70b5a278c509f73435a1bac9fdee8a302d4e14c9e0a1f951e09f2537482c5c835c4eeb93f0efc7b988c8cfecc28c793061d2726f554ddc64313056228b705299a06a992a33bc9e5d77e2dd03adbb5b76f7b20314f6bb3c131cf504b3a39390ed6e8b4e6d7ba46&X-Goog-SignedHeaders=host&X-User=2931823730 (Caused by NewConnectionError('<urllib3.connection.HTTPSConnection object at 0x7fcdd01c0250>: Failed to establish a new connection: [Errno 101] Network is unreachable'))
2025-04-11 13:35:40,260 ERROR   wandb-upload_0:5057 [internal_api.py:upload_file():2558] upload_file request headers: {'User-Agent': 'python-requests/2.32.3', 'Accept-Encoding': 'gzip, deflate, br', 'Accept': '*/*', 'Connection': 'keep-alive', 'Content-Length': '2259'}
2025-04-11 13:35:40,260 ERROR   wandb-upload_0:5057 [internal_api.py:upload_file():2560] upload_file response body: 
2025-04-11 13:35:43,177 DEBUG   HandlerThread:5057 [handler.py:handle_request():146] handle_request: status_report
2025-04-11 13:35:44,005 DEBUG   HandlerThread:5057 [handler.py:handle_request():146] handle_request: keepalive
2025-04-11 13:35:44,006 DEBUG   HandlerThread:5057 [handler.py:handle_request():146] handle_request: stop_status
2025-04-11 13:35:44,007 DEBUG   SenderThread:5057 [sender.py:send_request():407] send_request: stop_status
2025-04-11 13:35:44,968 DEBUG   SenderThread:5057 [sender.py:send():380] send: exit
2025-04-11 13:35:44,968 INFO    SenderThread:5057 [sender.py:send_exit():585] handling exit code: 1
2025-04-11 13:35:44,969 INFO    SenderThread:5057 [sender.py:send_exit():587] handling runtime: 45
2025-04-11 13:35:44,970 INFO    SenderThread:5057 [sender.py:_save_file():1378] saving file wandb-summary.json with policy end
2025-04-11 13:35:44,971 INFO    SenderThread:5057 [sender.py:send_exit():593] send defer
2025-04-11 13:35:44,971 DEBUG   HandlerThread:5057 [handler.py:handle_request():146] handle_request: defer
2025-04-11 13:35:44,971 INFO    HandlerThread:5057 [handler.py:handle_request_defer():172] handle defer: 0
2025-04-11 13:35:44,971 DEBUG   SenderThread:5057 [sender.py:send_request():407] send_request: defer
2025-04-11 13:35:44,971 INFO    SenderThread:5057 [sender.py:send_request_defer():609] handle sender defer: 0
2025-04-11 13:35:44,971 INFO    SenderThread:5057 [sender.py:transition_state():613] send defer: 1
2025-04-11 13:35:44,971 DEBUG   HandlerThread:5057 [handler.py:handle_request():146] handle_request: defer
2025-04-11 13:35:44,971 INFO    HandlerThread:5057 [handler.py:handle_request_defer():172] handle defer: 1
2025-04-11 13:35:44,972 DEBUG   SenderThread:5057 [sender.py:send_request():407] send_request: defer
2025-04-11 13:35:44,972 INFO    SenderThread:5057 [sender.py:send_request_defer():609] handle sender defer: 1
2025-04-11 13:35:44,972 INFO    SenderThread:5057 [sender.py:transition_state():613] send defer: 2
2025-04-11 13:35:44,972 DEBUG   HandlerThread:5057 [handler.py:handle_request():146] handle_request: defer
2025-04-11 13:35:44,972 INFO    HandlerThread:5057 [handler.py:handle_request_defer():172] handle defer: 2
2025-04-11 13:35:44,972 INFO    HandlerThread:5057 [system_monitor.py:finish():203] Stopping system monitor
2025-04-11 13:35:44,972 DEBUG   SystemMonitor:5057 [system_monitor.py:_start():172] Starting system metrics aggregation loop
2025-04-11 13:35:44,973 DEBUG   SystemMonitor:5057 [system_monitor.py:_start():179] Finished system metrics aggregation loop
2025-04-11 13:35:44,973 INFO    HandlerThread:5057 [interfaces.py:finish():202] Joined cpu monitor
2025-04-11 13:35:44,973 DEBUG   SystemMonitor:5057 [system_monitor.py:_start():183] Publishing last batch of metrics
2025-04-11 13:35:44,973 INFO    HandlerThread:5057 [interfaces.py:finish():202] Joined disk monitor
2025-04-11 13:35:44,995 INFO    HandlerThread:5057 [interfaces.py:finish():202] Joined gpu monitor
2025-04-11 13:35:44,995 INFO    HandlerThread:5057 [interfaces.py:finish():202] Joined memory monitor
2025-04-11 13:35:44,995 INFO    HandlerThread:5057 [interfaces.py:finish():202] Joined network monitor
2025-04-11 13:35:44,996 DEBUG   SenderThread:5057 [sender.py:send_request():407] send_request: defer
2025-04-11 13:35:44,996 INFO    SenderThread:5057 [sender.py:send_request_defer():609] handle sender defer: 2
2025-04-11 13:35:44,996 INFO    SenderThread:5057 [sender.py:transition_state():613] send defer: 3
2025-04-11 13:35:44,996 DEBUG   SenderThread:5057 [sender.py:send():380] send: stats
2025-04-11 13:35:44,996 DEBUG   HandlerThread:5057 [handler.py:handle_request():146] handle_request: defer
2025-04-11 13:35:44,996 INFO    HandlerThread:5057 [handler.py:handle_request_defer():172] handle defer: 3
2025-04-11 13:35:44,997 DEBUG   SenderThread:5057 [sender.py:send_request():407] send_request: defer
2025-04-11 13:35:44,997 INFO    SenderThread:5057 [sender.py:send_request_defer():609] handle sender defer: 3
2025-04-11 13:35:44,997 INFO    SenderThread:5057 [sender.py:transition_state():613] send defer: 4
2025-04-11 13:35:44,997 DEBUG   HandlerThread:5057 [handler.py:handle_request():146] handle_request: defer
2025-04-11 13:35:44,997 INFO    HandlerThread:5057 [handler.py:handle_request_defer():172] handle defer: 4
2025-04-11 13:35:44,997 DEBUG   SenderThread:5057 [sender.py:send_request():407] send_request: defer
2025-04-11 13:35:44,998 INFO    SenderThread:5057 [sender.py:send_request_defer():609] handle sender defer: 4
2025-04-11 13:35:44,998 INFO    SenderThread:5057 [sender.py:transition_state():613] send defer: 5
2025-04-11 13:35:44,998 DEBUG   HandlerThread:5057 [handler.py:handle_request():146] handle_request: defer
2025-04-11 13:35:44,998 INFO    HandlerThread:5057 [handler.py:handle_request_defer():172] handle defer: 5
2025-04-11 13:35:44,998 DEBUG   SenderThread:5057 [sender.py:send():380] send: summary
2025-04-11 13:35:45,001 INFO    SenderThread:5057 [sender.py:_save_file():1378] saving file wandb-summary.json with policy end
2025-04-11 13:35:45,001 DEBUG   SenderThread:5057 [sender.py:send_request():407] send_request: defer
2025-04-11 13:35:45,001 INFO    SenderThread:5057 [sender.py:send_request_defer():609] handle sender defer: 5
2025-04-11 13:35:45,001 INFO    SenderThread:5057 [sender.py:transition_state():613] send defer: 6
2025-04-11 13:35:45,002 DEBUG   HandlerThread:5057 [handler.py:handle_request():146] handle_request: defer
2025-04-11 13:35:45,002 INFO    HandlerThread:5057 [handler.py:handle_request_defer():172] handle defer: 6
2025-04-11 13:35:45,002 DEBUG   SenderThread:5057 [sender.py:send_request():407] send_request: defer
2025-04-11 13:35:45,002 INFO    SenderThread:5057 [sender.py:send_request_defer():609] handle sender defer: 6
2025-04-11 13:35:45,008 DEBUG   HandlerThread:5057 [handler.py:handle_request():146] handle_request: status_report
2025-04-11 13:35:45,347 INFO    SenderThread:5057 [sender.py:transition_state():613] send defer: 7
2025-04-11 13:35:45,347 DEBUG   HandlerThread:5057 [handler.py:handle_request():146] handle_request: defer
2025-04-11 13:35:45,347 INFO    HandlerThread:5057 [handler.py:handle_request_defer():172] handle defer: 7
2025-04-11 13:35:45,348 DEBUG   SenderThread:5057 [sender.py:send_request():407] send_request: defer
2025-04-11 13:35:45,348 INFO    SenderThread:5057 [sender.py:send_request_defer():609] handle sender defer: 7
2025-04-11 13:35:45,374 INFO    Thread-12 :5057 [dir_watcher.py:_on_file_modified():288] file/dir modified: /root/ltu-main/ltu-main/src/ltu_as/train_scripts/wandb/run-20250411_133457-ayrd945g/files/config.yaml
2025-04-11 13:35:45,374 INFO    Thread-12 :5057 [dir_watcher.py:_on_file_created():271] file/dir created: /root/ltu-main/ltu-main/src/ltu_as/train_scripts/wandb/run-20250411_133457-ayrd945g/files/wandb-summary.json
2025-04-11 13:35:45,967 DEBUG   HandlerThread:5057 [handler.py:handle_request():146] handle_request: poll_exit
2025-04-11 13:35:47,218 INFO    SenderThread:5057 [sender.py:transition_state():613] send defer: 8
2025-04-11 13:35:47,219 DEBUG   SenderThread:5057 [sender.py:send_request():407] send_request: poll_exit
2025-04-11 13:35:47,219 DEBUG   HandlerThread:5057 [handler.py:handle_request():146] handle_request: defer
2025-04-11 13:35:47,219 INFO    HandlerThread:5057 [handler.py:handle_request_defer():172] handle defer: 8
2025-04-11 13:35:47,219 DEBUG   SenderThread:5057 [sender.py:send_request():407] send_request: defer
2025-04-11 13:35:47,220 INFO    SenderThread:5057 [sender.py:send_request_defer():609] handle sender defer: 8
2025-04-11 13:35:47,220 INFO    SenderThread:5057 [job_builder.py:build():281] Attempting to build job artifact
2025-04-11 13:35:47,221 INFO    SenderThread:5057 [job_builder.py:_get_source_type():404] no source found
2025-04-11 13:35:47,221 INFO    SenderThread:5057 [sender.py:transition_state():613] send defer: 9
2025-04-11 13:35:47,222 DEBUG   HandlerThread:5057 [handler.py:handle_request():146] handle_request: defer
2025-04-11 13:35:47,222 INFO    HandlerThread:5057 [handler.py:handle_request_defer():172] handle defer: 9
2025-04-11 13:35:47,222 DEBUG   SenderThread:5057 [sender.py:send_request():407] send_request: defer
2025-04-11 13:35:47,222 INFO    SenderThread:5057 [sender.py:send_request_defer():609] handle sender defer: 9
2025-04-11 13:35:47,222 INFO    SenderThread:5057 [dir_watcher.py:finish():358] shutting down directory watcher
2025-04-11 13:35:47,374 INFO    Thread-12 :5057 [dir_watcher.py:_on_file_modified():288] file/dir modified: /root/ltu-main/ltu-main/src/ltu_as/train_scripts/wandb/run-20250411_133457-ayrd945g/files/output.log
2025-04-11 13:35:47,376 INFO    SenderThread:5057 [dir_watcher.py:finish():388] scan: /root/ltu-main/ltu-main/src/ltu_as/train_scripts/wandb/run-20250411_133457-ayrd945g/files
2025-04-11 13:35:47,376 INFO    SenderThread:5057 [dir_watcher.py:finish():402] scan save: /root/ltu-main/ltu-main/src/ltu_as/train_scripts/wandb/run-20250411_133457-ayrd945g/files/config.yaml config.yaml
2025-04-11 13:35:47,376 INFO    SenderThread:5057 [dir_watcher.py:finish():402] scan save: /root/ltu-main/ltu-main/src/ltu_as/train_scripts/wandb/run-20250411_133457-ayrd945g/files/requirements.txt requirements.txt
2025-04-11 13:35:47,382 INFO    SenderThread:5057 [dir_watcher.py:finish():402] scan save: /root/ltu-main/ltu-main/src/ltu_as/train_scripts/wandb/run-20250411_133457-ayrd945g/files/conda-environment.yaml conda-environment.yaml
2025-04-11 13:35:47,382 INFO    SenderThread:5057 [dir_watcher.py:finish():402] scan save: /root/ltu-main/ltu-main/src/ltu_as/train_scripts/wandb/run-20250411_133457-ayrd945g/files/wandb-metadata.json wandb-metadata.json
2025-04-11 13:35:47,386 INFO    SenderThread:5057 [dir_watcher.py:finish():402] scan save: /root/ltu-main/ltu-main/src/ltu_as/train_scripts/wandb/run-20250411_133457-ayrd945g/files/output.log output.log
2025-04-11 13:35:47,392 INFO    SenderThread:5057 [dir_watcher.py:finish():402] scan save: /root/ltu-main/ltu-main/src/ltu_as/train_scripts/wandb/run-20250411_133457-ayrd945g/files/wandb-summary.json wandb-summary.json
2025-04-11 13:35:47,393 INFO    SenderThread:5057 [sender.py:transition_state():613] send defer: 10
2025-04-11 13:35:47,395 DEBUG   HandlerThread:5057 [handler.py:handle_request():146] handle_request: defer
2025-04-11 13:35:47,398 INFO    HandlerThread:5057 [handler.py:handle_request_defer():172] handle defer: 10
2025-04-11 13:35:47,399 DEBUG   SenderThread:5057 [sender.py:send_request():407] send_request: defer
2025-04-11 13:35:47,399 INFO    SenderThread:5057 [sender.py:send_request_defer():609] handle sender defer: 10
2025-04-11 13:35:47,399 INFO    SenderThread:5057 [file_pusher.py:finish():175] shutting down file pusher
2025-04-11 13:35:47,665 ERROR   wandb-upload_1:5057 [internal_api.py:upload_file():2556] upload_file exception https://storage.googleapis.com/wandb-production.appspot.com/2931823730-harbin-institute-of-technology/ltu-as/ayrd945g/config.yaml?X-Goog-Algorithm=GOOG4-RSA-SHA256&X-Goog-Credential=gorilla-files-url-signer-man%40wandb-production.iam.gserviceaccount.com%2F20250411%2Fauto%2Fstorage%2Fgoog4_request&X-Goog-Date=20250411T133547Z&X-Goog-Expires=86399&X-Goog-Signature=59229da32108dabf2e0b22f3378d7c4eff52c92055ad5d5b992f76e4df1c8015b756cf03412a752e587a2ea6bc2f30001b205d9ef095c5a14ab645fe71a22b821da600c1196db4191aef6cd423a67f5cfc13d398e023ee472db63d91e6f84db94368a9e61522d891c6c41b7eeb918e96b41062c0135485092d85801d941c7eb761567114df29f3b71030380dfe24d3e94c0e9810f87f3eb1f65bf4625252ec95591d290b470be81abb48ba16966c05db2893b493bab6f93bdd5325ee55c3ce817c57cadd71e627b02871d0c646f4dba235a7310afdefe60e03add6e16f1ebcee16c2bf969543124fb60ebc8bf3cee02e75fd183babe4d68e010a4c410a360fd7&X-Goog-SignedHeaders=host&X-User=2931823730: HTTPSConnectionPool(host='storage.googleapis.com', port=443): Max retries exceeded with url: /wandb-production.appspot.com/2931823730-harbin-institute-of-technology/ltu-as/ayrd945g/config.yaml?X-Goog-Algorithm=GOOG4-RSA-SHA256&X-Goog-Credential=gorilla-files-url-signer-man%40wandb-production.iam.gserviceaccount.com%2F20250411%2Fauto%2Fstorage%2Fgoog4_request&X-Goog-Date=20250411T133547Z&X-Goog-Expires=86399&X-Goog-Signature=59229da32108dabf2e0b22f3378d7c4eff52c92055ad5d5b992f76e4df1c8015b756cf03412a752e587a2ea6bc2f30001b205d9ef095c5a14ab645fe71a22b821da600c1196db4191aef6cd423a67f5cfc13d398e023ee472db63d91e6f84db94368a9e61522d891c6c41b7eeb918e96b41062c0135485092d85801d941c7eb761567114df29f3b71030380dfe24d3e94c0e9810f87f3eb1f65bf4625252ec95591d290b470be81abb48ba16966c05db2893b493bab6f93bdd5325ee55c3ce817c57cadd71e627b02871d0c646f4dba235a7310afdefe60e03add6e16f1ebcee16c2bf969543124fb60ebc8bf3cee02e75fd183babe4d68e010a4c410a360fd7&X-Goog-SignedHeaders=host&X-User=2931823730 (Caused by NewConnectionError('<urllib3.connection.HTTPSConnection object at 0x7fcdd01c3940>: Failed to establish a new connection: [Errno 101] Network is unreachable'))
2025-04-11 13:35:47,666 ERROR   wandb-upload_1:5057 [internal_api.py:upload_file():2558] upload_file request headers: {'User-Agent': 'python-requests/2.32.3', 'Accept-Encoding': 'gzip, deflate, br', 'Accept': '*/*', 'Connection': 'keep-alive', 'Content-Length': '8685'}
2025-04-11 13:35:47,666 ERROR   wandb-upload_1:5057 [internal_api.py:upload_file():2560] upload_file response body: 
2025-04-11 13:35:47,846 ERROR   wandb-upload_5:5057 [internal_api.py:upload_file():2556] upload_file exception https://storage.googleapis.com/wandb-production.appspot.com/2931823730-harbin-institute-of-technology/ltu-as/ayrd945g/wandb-summary.json?X-Goog-Algorithm=GOOG4-RSA-SHA256&X-Goog-Credential=gorilla-files-url-signer-man%40wandb-production.iam.gserviceaccount.com%2F20250411%2Fauto%2Fstorage%2Fgoog4_request&X-Goog-Date=20250411T133547Z&X-Goog-Expires=86399&X-Goog-Signature=88d8a33a4942edfdf46386d8d3684fa7b9d5a442bb037f8cda46c414fe422ca150fb4f2e5f776cc41bf710997e8d99494d56986c0251407a93dff567d301deee84d6a9d3c20c4876734beeebe93fc2170c90439950e62f7d895e7dfc8cff58ae05a6debe4386cf769ab635fbfecc6b9311f012934afbb8e9bfc6c652fb999d4b61c9c6dd3511d8a321c3bac43987e7d9891f0c31f9d35ca79f5a1ef87bcfa3ef26a7e363d6207536f2b71b07a4b55c4e341c9e6178a3a7bf0e2c835d2471597f60ccc6925d495148fc1623f5b3160f75ff84cd47fadcd8cd769536b21457ea5f60c8ba539b75f81d476509ef340009289b14c43e1a28cc2e27df0d6e9eb44275&X-Goog-SignedHeaders=host&X-User=2931823730: HTTPSConnectionPool(host='storage.googleapis.com', port=443): Max retries exceeded with url: /wandb-production.appspot.com/2931823730-harbin-institute-of-technology/ltu-as/ayrd945g/wandb-summary.json?X-Goog-Algorithm=GOOG4-RSA-SHA256&X-Goog-Credential=gorilla-files-url-signer-man%40wandb-production.iam.gserviceaccount.com%2F20250411%2Fauto%2Fstorage%2Fgoog4_request&X-Goog-Date=20250411T133547Z&X-Goog-Expires=86399&X-Goog-Signature=88d8a33a4942edfdf46386d8d3684fa7b9d5a442bb037f8cda46c414fe422ca150fb4f2e5f776cc41bf710997e8d99494d56986c0251407a93dff567d301deee84d6a9d3c20c4876734beeebe93fc2170c90439950e62f7d895e7dfc8cff58ae05a6debe4386cf769ab635fbfecc6b9311f012934afbb8e9bfc6c652fb999d4b61c9c6dd3511d8a321c3bac43987e7d9891f0c31f9d35ca79f5a1ef87bcfa3ef26a7e363d6207536f2b71b07a4b55c4e341c9e6178a3a7bf0e2c835d2471597f60ccc6925d495148fc1623f5b3160f75ff84cd47fadcd8cd769536b21457ea5f60c8ba539b75f81d476509ef340009289b14c43e1a28cc2e27df0d6e9eb44275&X-Goog-SignedHeaders=host&X-User=2931823730 (Caused by NewConnectionError('<urllib3.connection.HTTPSConnection object at 0x7fcdd01c0910>: Failed to establish a new connection: [Errno 101] Network is unreachable'))
2025-04-11 13:35:47,846 ERROR   wandb-upload_2:5057 [internal_api.py:upload_file():2556] upload_file exception https://storage.googleapis.com/wandb-production.appspot.com/2931823730-harbin-institute-of-technology/ltu-as/ayrd945g/requirements.txt?X-Goog-Algorithm=GOOG4-RSA-SHA256&X-Goog-Credential=gorilla-files-url-signer-man%40wandb-production.iam.gserviceaccount.com%2F20250411%2Fauto%2Fstorage%2Fgoog4_request&X-Goog-Date=20250411T133547Z&X-Goog-Expires=86399&X-Goog-Signature=8f7985a4ebf492647396ccbeb8281c95f40ce48ca6ebfe7230b06e3e08a640b4892e9fbe8f14f084f14e5d3841d2ed4769d71f5dcc53a827130556bbab907612d4a6c07d1c4b3f38ce4fc656dabf01e58238b7603961296e52ef293121e1ab2eb7c0f40e653fe066ef2a8502bf31d63a12f60e5498b0ebdae66cee400aa1a42598345e000ebb6d22ea01ec55dcf62810cace5cacbb3cef4cc37ca34ae61cfaf15fa634731635ca6ad7b243b89a565ecd2dfae6fdcfdaf084938d1afa790a313af20f904fe253f7e9c5fbe3595321a68018379642acab4619f2715b3e42cea1e7f430dada2242a15e4fdaaa50c317aa219a978a754411899f051b8136a1fa5a4d&X-Goog-SignedHeaders=host&X-User=2931823730: HTTPSConnectionPool(host='storage.googleapis.com', port=443): Max retries exceeded with url: /wandb-production.appspot.com/2931823730-harbin-institute-of-technology/ltu-as/ayrd945g/requirements.txt?X-Goog-Algorithm=GOOG4-RSA-SHA256&X-Goog-Credential=gorilla-files-url-signer-man%40wandb-production.iam.gserviceaccount.com%2F20250411%2Fauto%2Fstorage%2Fgoog4_request&X-Goog-Date=20250411T133547Z&X-Goog-Expires=86399&X-Goog-Signature=8f7985a4ebf492647396ccbeb8281c95f40ce48ca6ebfe7230b06e3e08a640b4892e9fbe8f14f084f14e5d3841d2ed4769d71f5dcc53a827130556bbab907612d4a6c07d1c4b3f38ce4fc656dabf01e58238b7603961296e52ef293121e1ab2eb7c0f40e653fe066ef2a8502bf31d63a12f60e5498b0ebdae66cee400aa1a42598345e000ebb6d22ea01ec55dcf62810cace5cacbb3cef4cc37ca34ae61cfaf15fa634731635ca6ad7b243b89a565ecd2dfae6fdcfdaf084938d1afa790a313af20f904fe253f7e9c5fbe3595321a68018379642acab4619f2715b3e42cea1e7f430dada2242a15e4fdaaa50c317aa219a978a754411899f051b8136a1fa5a4d&X-Goog-SignedHeaders=host&X-User=2931823730 (Caused by NewConnectionError('<urllib3.connection.HTTPSConnection object at 0x7fcdd01c0310>: Failed to establish a new connection: [Errno 101] Network is unreachable'))
2025-04-11 13:35:47,846 ERROR   wandb-upload_5:5057 [internal_api.py:upload_file():2558] upload_file request headers: {'User-Agent': 'python-requests/2.32.3', 'Accept-Encoding': 'gzip, deflate, br', 'Accept': '*/*', 'Connection': 'keep-alive', 'Content-Length': '27'}
2025-04-11 13:35:47,846 ERROR   wandb-upload_2:5057 [internal_api.py:upload_file():2558] upload_file request headers: {'User-Agent': 'python-requests/2.32.3', 'Accept-Encoding': 'gzip, deflate, br', 'Accept': '*/*', 'Connection': 'keep-alive', 'Content-Length': '4212'}
2025-04-11 13:35:47,847 ERROR   wandb-upload_5:5057 [internal_api.py:upload_file():2560] upload_file response body: 
2025-04-11 13:35:47,847 ERROR   wandb-upload_2:5057 [internal_api.py:upload_file():2560] upload_file response body: 
2025-04-11 13:35:47,847 ERROR   wandb-upload_4:5057 [internal_api.py:upload_file():2556] upload_file exception https://storage.googleapis.com/wandb-production.appspot.com/2931823730-harbin-institute-of-technology/ltu-as/ayrd945g/output.log?X-Goog-Algorithm=GOOG4-RSA-SHA256&X-Goog-Credential=gorilla-files-url-signer-man%40wandb-production.iam.gserviceaccount.com%2F20250411%2Fauto%2Fstorage%2Fgoog4_request&X-Goog-Date=20250411T133547Z&X-Goog-Expires=86399&X-Goog-Signature=60a14c64c75b7213832de3f51a8cee68b48766ce9fef4ac66308dcfbe021d98db23ab7a4e8e5a5840ad99fe69b3425e1ecaa5e7cecda0e89061d438052a78b725028def9cc631a332a1e2c99ebd6d1172adc8172fdae0d62bec226a3e99cdb144f8e7a221e0ec08c94a76dc888412fde2d9f87d0b484866e6db161d92750595d0c526c395230151ab2e6574b130439e80c58f6c8fb6187dfedd000237d5c6c32116bebe722b0f4815fa4b433c2c01eac2e6d1d439d109c547bd416ef777f07467da9090b12efc4e78dfb53e81482b7f08de5e21dbddcb7102335ee3f4fc94d9b946d104c6c430ee9e397a2c1ef3c9eaaae349d83697a271010de87b863593b32&X-Goog-SignedHeaders=host&X-User=2931823730: HTTPSConnectionPool(host='storage.googleapis.com', port=443): Max retries exceeded with url: /wandb-production.appspot.com/2931823730-harbin-institute-of-technology/ltu-as/ayrd945g/output.log?X-Goog-Algorithm=GOOG4-RSA-SHA256&X-Goog-Credential=gorilla-files-url-signer-man%40wandb-production.iam.gserviceaccount.com%2F20250411%2Fauto%2Fstorage%2Fgoog4_request&X-Goog-Date=20250411T133547Z&X-Goog-Expires=86399&X-Goog-Signature=60a14c64c75b7213832de3f51a8cee68b48766ce9fef4ac66308dcfbe021d98db23ab7a4e8e5a5840ad99fe69b3425e1ecaa5e7cecda0e89061d438052a78b725028def9cc631a332a1e2c99ebd6d1172adc8172fdae0d62bec226a3e99cdb144f8e7a221e0ec08c94a76dc888412fde2d9f87d0b484866e6db161d92750595d0c526c395230151ab2e6574b130439e80c58f6c8fb6187dfedd000237d5c6c32116bebe722b0f4815fa4b433c2c01eac2e6d1d439d109c547bd416ef777f07467da9090b12efc4e78dfb53e81482b7f08de5e21dbddcb7102335ee3f4fc94d9b946d104c6c430ee9e397a2c1ef3c9eaaae349d83697a271010de87b863593b32&X-Goog-SignedHeaders=host&X-User=2931823730 (Caused by NewConnectionError('<urllib3.connection.HTTPSConnection object at 0x7fcdd01c1570>: Failed to establish a new connection: [Errno 101] Network is unreachable'))
2025-04-11 13:35:47,848 ERROR   wandb-upload_4:5057 [internal_api.py:upload_file():2558] upload_file request headers: {'User-Agent': 'python-requests/2.32.3', 'Accept-Encoding': 'gzip, deflate, br', 'Accept': '*/*', 'Connection': 'keep-alive', 'Content-Length': '5135'}
2025-04-11 13:35:47,848 ERROR   wandb-upload_4:5057 [internal_api.py:upload_file():2560] upload_file response body: 
2025-04-11 13:35:47,859 ERROR   wandb-upload_3:5057 [internal_api.py:upload_file():2556] upload_file exception https://storage.googleapis.com/wandb-production.appspot.com/2931823730-harbin-institute-of-technology/ltu-as/ayrd945g/conda-environment.yaml?X-Goog-Algorithm=GOOG4-RSA-SHA256&X-Goog-Credential=gorilla-files-url-signer-man%40wandb-production.iam.gserviceaccount.com%2F20250411%2Fauto%2Fstorage%2Fgoog4_request&X-Goog-Date=20250411T133547Z&X-Goog-Expires=86399&X-Goog-Signature=4c9126604080912880ede91838f5a7390665008083d7e44309734daddd80b9cf8cf7a4c5c6fa5de745ba75d664cb7469ed45bccd6a8d0f8328f5b819c87f52209a817e2cecb6b43dd002266b64a58a46125cf94eecc520b1b7a33aba86a8651778a4fc020b1e58b91094758a9f0bdf70c1b1709c39a4aa8e5b9998524293e3f95252e6a81cbabe349b8e96481c3fdb99ef3ed87c033bd482bc27e2900be02b6f7a10cc37e178de535da73792986f0057d36c512c3142823ec07dde39234d436ecef04f3b634ff435b7df21a6d1fbd1b616a7aafd7a5bc2d0a15eacb48d1f828c4e7e505ad7f7585a5624f5d9716d95b4b15bdc9c2151e47d7698d62f76621622&X-Goog-SignedHeaders=host&X-User=2931823730: HTTPSConnectionPool(host='storage.googleapis.com', port=443): Max retries exceeded with url: /wandb-production.appspot.com/2931823730-harbin-institute-of-technology/ltu-as/ayrd945g/conda-environment.yaml?X-Goog-Algorithm=GOOG4-RSA-SHA256&X-Goog-Credential=gorilla-files-url-signer-man%40wandb-production.iam.gserviceaccount.com%2F20250411%2Fauto%2Fstorage%2Fgoog4_request&X-Goog-Date=20250411T133547Z&X-Goog-Expires=86399&X-Goog-Signature=4c9126604080912880ede91838f5a7390665008083d7e44309734daddd80b9cf8cf7a4c5c6fa5de745ba75d664cb7469ed45bccd6a8d0f8328f5b819c87f52209a817e2cecb6b43dd002266b64a58a46125cf94eecc520b1b7a33aba86a8651778a4fc020b1e58b91094758a9f0bdf70c1b1709c39a4aa8e5b9998524293e3f95252e6a81cbabe349b8e96481c3fdb99ef3ed87c033bd482bc27e2900be02b6f7a10cc37e178de535da73792986f0057d36c512c3142823ec07dde39234d436ecef04f3b634ff435b7df21a6d1fbd1b616a7aafd7a5bc2d0a15eacb48d1f828c4e7e505ad7f7585a5624f5d9716d95b4b15bdc9c2151e47d7698d62f76621622&X-Goog-SignedHeaders=host&X-User=2931823730 (Caused by NewConnectionError('<urllib3.connection.HTTPSConnection object at 0x7fcdd01c3280>: Failed to establish a new connection: [Errno 101] Network is unreachable'))
2025-04-11 13:35:47,859 ERROR   wandb-upload_3:5057 [internal_api.py:upload_file():2558] upload_file request headers: {'User-Agent': 'python-requests/2.32.3', 'Accept-Encoding': 'gzip, deflate, br', 'Accept': '*/*', 'Connection': 'keep-alive', 'Content-Length': '8281'}
2025-04-11 13:35:47,859 ERROR   wandb-upload_3:5057 [internal_api.py:upload_file():2560] upload_file response body: 
2025-04-11 13:35:48,537 ERROR   wandb-upload_0:5057 [internal_api.py:upload_file():2556] upload_file exception https://storage.googleapis.com/wandb-production.appspot.com/2931823730-harbin-institute-of-technology/ltu-as/ayrd945g/wandb-metadata.json?X-Goog-Algorithm=GOOG4-RSA-SHA256&X-Goog-Credential=gorilla-files-url-signer-man%40wandb-production.iam.gserviceaccount.com%2F20250411%2Fauto%2Fstorage%2Fgoog4_request&X-Goog-Date=20250411T133531Z&X-Goog-Expires=86399&X-Goog-Signature=3f5aee34cfa797b7aa73f667422a4aee946d1072dcec6b4021fa16645cebbf9a6738f93929154478c65a583fe2e5451e23e58739b96fa5355a823d0848191cccf627be8a9b51eee5861c7ed65eeead014bbceb2dcaeeef78dcdb79f5d1c045f21707476081794fb0708d6ec543c2f328439ef45907a15b52a6f64bbdbbf40ac08a2e90802e63ba340ae771978232c617a39b97d3caff9929e0c70b5a278c509f73435a1bac9fdee8a302d4e14c9e0a1f951e09f2537482c5c835c4eeb93f0efc7b988c8cfecc28c793061d2726f554ddc64313056228b705299a06a992a33bc9e5d77e2dd03adbb5b76f7b20314f6bb3c131cf504b3a39390ed6e8b4e6d7ba46&X-Goog-SignedHeaders=host&X-User=2931823730: HTTPSConnectionPool(host='storage.googleapis.com', port=443): Max retries exceeded with url: /wandb-production.appspot.com/2931823730-harbin-institute-of-technology/ltu-as/ayrd945g/wandb-metadata.json?X-Goog-Algorithm=GOOG4-RSA-SHA256&X-Goog-Credential=gorilla-files-url-signer-man%40wandb-production.iam.gserviceaccount.com%2F20250411%2Fauto%2Fstorage%2Fgoog4_request&X-Goog-Date=20250411T133531Z&X-Goog-Expires=86399&X-Goog-Signature=3f5aee34cfa797b7aa73f667422a4aee946d1072dcec6b4021fa16645cebbf9a6738f93929154478c65a583fe2e5451e23e58739b96fa5355a823d0848191cccf627be8a9b51eee5861c7ed65eeead014bbceb2dcaeeef78dcdb79f5d1c045f21707476081794fb0708d6ec543c2f328439ef45907a15b52a6f64bbdbbf40ac08a2e90802e63ba340ae771978232c617a39b97d3caff9929e0c70b5a278c509f73435a1bac9fdee8a302d4e14c9e0a1f951e09f2537482c5c835c4eeb93f0efc7b988c8cfecc28c793061d2726f554ddc64313056228b705299a06a992a33bc9e5d77e2dd03adbb5b76f7b20314f6bb3c131cf504b3a39390ed6e8b4e6d7ba46&X-Goog-SignedHeaders=host&X-User=2931823730 (Caused by NewConnectionError('<urllib3.connection.HTTPSConnection object at 0x7fcd927aa170>: Failed to establish a new connection: [Errno 101] Network is unreachable'))
2025-04-11 13:35:48,537 ERROR   wandb-upload_0:5057 [internal_api.py:upload_file():2558] upload_file request headers: {'User-Agent': 'python-requests/2.32.3', 'Accept-Encoding': 'gzip, deflate, br', 'Accept': '*/*', 'Connection': 'keep-alive', 'Content-Length': '2259'}
2025-04-11 13:35:48,537 ERROR   wandb-upload_0:5057 [internal_api.py:upload_file():2560] upload_file response body: 
2025-04-11 13:35:48,801 ERROR   wandb-upload_1:5057 [internal_api.py:upload_file():2556] upload_file exception https://storage.googleapis.com/wandb-production.appspot.com/2931823730-harbin-institute-of-technology/ltu-as/ayrd945g/config.yaml?X-Goog-Algorithm=GOOG4-RSA-SHA256&X-Goog-Credential=gorilla-files-url-signer-man%40wandb-production.iam.gserviceaccount.com%2F20250411%2Fauto%2Fstorage%2Fgoog4_request&X-Goog-Date=20250411T133547Z&X-Goog-Expires=86399&X-Goog-Signature=59229da32108dabf2e0b22f3378d7c4eff52c92055ad5d5b992f76e4df1c8015b756cf03412a752e587a2ea6bc2f30001b205d9ef095c5a14ab645fe71a22b821da600c1196db4191aef6cd423a67f5cfc13d398e023ee472db63d91e6f84db94368a9e61522d891c6c41b7eeb918e96b41062c0135485092d85801d941c7eb761567114df29f3b71030380dfe24d3e94c0e9810f87f3eb1f65bf4625252ec95591d290b470be81abb48ba16966c05db2893b493bab6f93bdd5325ee55c3ce817c57cadd71e627b02871d0c646f4dba235a7310afdefe60e03add6e16f1ebcee16c2bf969543124fb60ebc8bf3cee02e75fd183babe4d68e010a4c410a360fd7&X-Goog-SignedHeaders=host&X-User=2931823730: HTTPSConnectionPool(host='storage.googleapis.com', port=443): Max retries exceeded with url: /wandb-production.appspot.com/2931823730-harbin-institute-of-technology/ltu-as/ayrd945g/config.yaml?X-Goog-Algorithm=GOOG4-RSA-SHA256&X-Goog-Credential=gorilla-files-url-signer-man%40wandb-production.iam.gserviceaccount.com%2F20250411%2Fauto%2Fstorage%2Fgoog4_request&X-Goog-Date=20250411T133547Z&X-Goog-Expires=86399&X-Goog-Signature=59229da32108dabf2e0b22f3378d7c4eff52c92055ad5d5b992f76e4df1c8015b756cf03412a752e587a2ea6bc2f30001b205d9ef095c5a14ab645fe71a22b821da600c1196db4191aef6cd423a67f5cfc13d398e023ee472db63d91e6f84db94368a9e61522d891c6c41b7eeb918e96b41062c0135485092d85801d941c7eb761567114df29f3b71030380dfe24d3e94c0e9810f87f3eb1f65bf4625252ec95591d290b470be81abb48ba16966c05db2893b493bab6f93bdd5325ee55c3ce817c57cadd71e627b02871d0c646f4dba235a7310afdefe60e03add6e16f1ebcee16c2bf969543124fb60ebc8bf3cee02e75fd183babe4d68e010a4c410a360fd7&X-Goog-SignedHeaders=host&X-User=2931823730 (Caused by NewConnectionError('<urllib3.connection.HTTPSConnection object at 0x7fcd927a9fc0>: Failed to establish a new connection: [Errno 101] Network is unreachable'))
2025-04-11 13:35:48,801 ERROR   wandb-upload_1:5057 [internal_api.py:upload_file():2558] upload_file request headers: {'User-Agent': 'python-requests/2.32.3', 'Accept-Encoding': 'gzip, deflate, br', 'Accept': '*/*', 'Connection': 'keep-alive', 'Content-Length': '8685'}
2025-04-11 13:35:48,801 ERROR   wandb-upload_1:5057 [internal_api.py:upload_file():2560] upload_file response body: 
2025-04-11 13:35:48,801 INFO    wandb-upload_1:5057 [retry.py:__call__():172] Retry attempt failed:
Traceback (most recent call last):
  File "/root/anaconda3/envs/venv_ltu/lib/python3.10/site-packages/urllib3/connection.py", line 198, in _new_conn
    sock = connection.create_connection(
  File "/root/anaconda3/envs/venv_ltu/lib/python3.10/site-packages/urllib3/util/connection.py", line 85, in create_connection
    raise err
  File "/root/anaconda3/envs/venv_ltu/lib/python3.10/site-packages/urllib3/util/connection.py", line 73, in create_connection
    sock.connect(sa)
OSError: [Errno 101] Network is unreachable

The above exception was the direct cause of the following exception:

Traceback (most recent call last):
  File "/root/anaconda3/envs/venv_ltu/lib/python3.10/site-packages/urllib3/connectionpool.py", line 793, in urlopen
    response = self._make_request(
  File "/root/anaconda3/envs/venv_ltu/lib/python3.10/site-packages/urllib3/connectionpool.py", line 491, in _make_request
    raise new_e
  File "/root/anaconda3/envs/venv_ltu/lib/python3.10/site-packages/urllib3/connectionpool.py", line 467, in _make_request
    self._validate_conn(conn)
  File "/root/anaconda3/envs/venv_ltu/lib/python3.10/site-packages/urllib3/connectionpool.py", line 1099, in _validate_conn
    conn.connect()
  File "/root/anaconda3/envs/venv_ltu/lib/python3.10/site-packages/urllib3/connection.py", line 616, in connect
    self.sock = sock = self._new_conn()
  File "/root/anaconda3/envs/venv_ltu/lib/python3.10/site-packages/urllib3/connection.py", line 213, in _new_conn
    raise NewConnectionError(
urllib3.exceptions.NewConnectionError: <urllib3.connection.HTTPSConnection object at 0x7fcd927a9fc0>: Failed to establish a new connection: [Errno 101] Network is unreachable

The above exception was the direct cause of the following exception:

Traceback (most recent call last):
  File "/root/anaconda3/envs/venv_ltu/lib/python3.10/site-packages/requests/adapters.py", line 667, in send
    resp = conn.urlopen(
  File "/root/anaconda3/envs/venv_ltu/lib/python3.10/site-packages/urllib3/connectionpool.py", line 847, in urlopen
    retries = retries.increment(
  File "/root/anaconda3/envs/venv_ltu/lib/python3.10/site-packages/urllib3/util/retry.py", line 515, in increment
    raise MaxRetryError(_pool, url, reason) from reason  # type: ignore[arg-type]
urllib3.exceptions.MaxRetryError: HTTPSConnectionPool(host='storage.googleapis.com', port=443): Max retries exceeded with url: /wandb-production.appspot.com/2931823730-harbin-institute-of-technology/ltu-as/ayrd945g/config.yaml?X-Goog-Algorithm=GOOG4-RSA-SHA256&X-Goog-Credential=gorilla-files-url-signer-man%40wandb-production.iam.gserviceaccount.com%2F20250411%2Fauto%2Fstorage%2Fgoog4_request&X-Goog-Date=20250411T133547Z&X-Goog-Expires=86399&X-Goog-Signature=59229da32108dabf2e0b22f3378d7c4eff52c92055ad5d5b992f76e4df1c8015b756cf03412a752e587a2ea6bc2f30001b205d9ef095c5a14ab645fe71a22b821da600c1196db4191aef6cd423a67f5cfc13d398e023ee472db63d91e6f84db94368a9e61522d891c6c41b7eeb918e96b41062c0135485092d85801d941c7eb761567114df29f3b71030380dfe24d3e94c0e9810f87f3eb1f65bf4625252ec95591d290b470be81abb48ba16966c05db2893b493bab6f93bdd5325ee55c3ce817c57cadd71e627b02871d0c646f4dba235a7310afdefe60e03add6e16f1ebcee16c2bf969543124fb60ebc8bf3cee02e75fd183babe4d68e010a4c410a360fd7&X-Goog-SignedHeaders=host&X-User=2931823730 (Caused by NewConnectionError('<urllib3.connection.HTTPSConnection object at 0x7fcd927a9fc0>: Failed to establish a new connection: [Errno 101] Network is unreachable'))

During handling of the above exception, another exception occurred:

Traceback (most recent call last):
  File "/root/anaconda3/envs/venv_ltu/lib/python3.10/site-packages/wandb/sdk/internal/internal_api.py", line 2549, in upload_file
    response = self._upload_file_session.put(
  File "/root/anaconda3/envs/venv_ltu/lib/python3.10/site-packages/requests/sessions.py", line 649, in put
    return self.request("PUT", url, data=data, **kwargs)
  File "/root/anaconda3/envs/venv_ltu/lib/python3.10/site-packages/requests/sessions.py", line 589, in request
    resp = self.send(prep, **send_kwargs)
  File "/root/anaconda3/envs/venv_ltu/lib/python3.10/site-packages/requests/sessions.py", line 703, in send
    r = adapter.send(request, **kwargs)
  File "/root/anaconda3/envs/venv_ltu/lib/python3.10/site-packages/requests/adapters.py", line 700, in send
    raise ConnectionError(e, request=request)
requests.exceptions.ConnectionError: HTTPSConnectionPool(host='storage.googleapis.com', port=443): Max retries exceeded with url: /wandb-production.appspot.com/2931823730-harbin-institute-of-technology/ltu-as/ayrd945g/config.yaml?X-Goog-Algorithm=GOOG4-RSA-SHA256&X-Goog-Credential=gorilla-files-url-signer-man%40wandb-production.iam.gserviceaccount.com%2F20250411%2Fauto%2Fstorage%2Fgoog4_request&X-Goog-Date=20250411T133547Z&X-Goog-Expires=86399&X-Goog-Signature=59229da32108dabf2e0b22f3378d7c4eff52c92055ad5d5b992f76e4df1c8015b756cf03412a752e587a2ea6bc2f30001b205d9ef095c5a14ab645fe71a22b821da600c1196db4191aef6cd423a67f5cfc13d398e023ee472db63d91e6f84db94368a9e61522d891c6c41b7eeb918e96b41062c0135485092d85801d941c7eb761567114df29f3b71030380dfe24d3e94c0e9810f87f3eb1f65bf4625252ec95591d290b470be81abb48ba16966c05db2893b493bab6f93bdd5325ee55c3ce817c57cadd71e627b02871d0c646f4dba235a7310afdefe60e03add6e16f1ebcee16c2bf969543124fb60ebc8bf3cee02e75fd183babe4d68e010a4c410a360fd7&X-Goog-SignedHeaders=host&X-User=2931823730 (Caused by NewConnectionError('<urllib3.connection.HTTPSConnection object at 0x7fcd927a9fc0>: Failed to establish a new connection: [Errno 101] Network is unreachable'))

During handling of the above exception, another exception occurred:

Traceback (most recent call last):
  File "/root/anaconda3/envs/venv_ltu/lib/python3.10/site-packages/wandb/sdk/lib/retry.py", line 131, in __call__
    result = self._call_fn(*args, **kwargs)
  File "/root/anaconda3/envs/venv_ltu/lib/python3.10/site-packages/wandb/sdk/internal/internal_api.py", line 2580, in upload_file
    raise _e.with_traceback(sys.exc_info()[2])
  File "/root/anaconda3/envs/venv_ltu/lib/python3.10/site-packages/wandb/sdk/internal/internal_api.py", line 2549, in upload_file
    response = self._upload_file_session.put(
  File "/root/anaconda3/envs/venv_ltu/lib/python3.10/site-packages/requests/sessions.py", line 649, in put
    return self.request("PUT", url, data=data, **kwargs)
  File "/root/anaconda3/envs/venv_ltu/lib/python3.10/site-packages/requests/sessions.py", line 589, in request
    resp = self.send(prep, **send_kwargs)
  File "/root/anaconda3/envs/venv_ltu/lib/python3.10/site-packages/requests/sessions.py", line 703, in send
    r = adapter.send(request, **kwargs)
  File "/root/anaconda3/envs/venv_ltu/lib/python3.10/site-packages/requests/adapters.py", line 700, in send
    raise ConnectionError(e, request=request)
wandb.sdk.lib.retry.TransientError: None
2025-04-11 13:35:48,917 ERROR   wandb-upload_5:5057 [internal_api.py:upload_file():2556] upload_file exception https://storage.googleapis.com/wandb-production.appspot.com/2931823730-harbin-institute-of-technology/ltu-as/ayrd945g/wandb-summary.json?X-Goog-Algorithm=GOOG4-RSA-SHA256&X-Goog-Credential=gorilla-files-url-signer-man%40wandb-production.iam.gserviceaccount.com%2F20250411%2Fauto%2Fstorage%2Fgoog4_request&X-Goog-Date=20250411T133547Z&X-Goog-Expires=86399&X-Goog-Signature=88d8a33a4942edfdf46386d8d3684fa7b9d5a442bb037f8cda46c414fe422ca150fb4f2e5f776cc41bf710997e8d99494d56986c0251407a93dff567d301deee84d6a9d3c20c4876734beeebe93fc2170c90439950e62f7d895e7dfc8cff58ae05a6debe4386cf769ab635fbfecc6b9311f012934afbb8e9bfc6c652fb999d4b61c9c6dd3511d8a321c3bac43987e7d9891f0c31f9d35ca79f5a1ef87bcfa3ef26a7e363d6207536f2b71b07a4b55c4e341c9e6178a3a7bf0e2c835d2471597f60ccc6925d495148fc1623f5b3160f75ff84cd47fadcd8cd769536b21457ea5f60c8ba539b75f81d476509ef340009289b14c43e1a28cc2e27df0d6e9eb44275&X-Goog-SignedHeaders=host&X-User=2931823730: HTTPSConnectionPool(host='storage.googleapis.com', port=443): Max retries exceeded with url: /wandb-production.appspot.com/2931823730-harbin-institute-of-technology/ltu-as/ayrd945g/wandb-summary.json?X-Goog-Algorithm=GOOG4-RSA-SHA256&X-Goog-Credential=gorilla-files-url-signer-man%40wandb-production.iam.gserviceaccount.com%2F20250411%2Fauto%2Fstorage%2Fgoog4_request&X-Goog-Date=20250411T133547Z&X-Goog-Expires=86399&X-Goog-Signature=88d8a33a4942edfdf46386d8d3684fa7b9d5a442bb037f8cda46c414fe422ca150fb4f2e5f776cc41bf710997e8d99494d56986c0251407a93dff567d301deee84d6a9d3c20c4876734beeebe93fc2170c90439950e62f7d895e7dfc8cff58ae05a6debe4386cf769ab635fbfecc6b9311f012934afbb8e9bfc6c652fb999d4b61c9c6dd3511d8a321c3bac43987e7d9891f0c31f9d35ca79f5a1ef87bcfa3ef26a7e363d6207536f2b71b07a4b55c4e341c9e6178a3a7bf0e2c835d2471597f60ccc6925d495148fc1623f5b3160f75ff84cd47fadcd8cd769536b21457ea5f60c8ba539b75f81d476509ef340009289b14c43e1a28cc2e27df0d6e9eb44275&X-Goog-SignedHeaders=host&X-User=2931823730 (Caused by NewConnectionError('<urllib3.connection.HTTPSConnection object at 0x7fcd927a9900>: Failed to establish a new connection: [Errno 101] Network is unreachable'))
2025-04-11 13:35:48,918 ERROR   wandb-upload_5:5057 [internal_api.py:upload_file():2558] upload_file request headers: {'User-Agent': 'python-requests/2.32.3', 'Accept-Encoding': 'gzip, deflate, br', 'Accept': '*/*', 'Connection': 'keep-alive', 'Content-Length': '27'}
2025-04-11 13:35:48,918 ERROR   wandb-upload_5:5057 [internal_api.py:upload_file():2560] upload_file response body: 
2025-04-11 13:35:49,001 ERROR   wandb-upload_3:5057 [internal_api.py:upload_file():2556] upload_file exception https://storage.googleapis.com/wandb-production.appspot.com/2931823730-harbin-institute-of-technology/ltu-as/ayrd945g/conda-environment.yaml?X-Goog-Algorithm=GOOG4-RSA-SHA256&X-Goog-Credential=gorilla-files-url-signer-man%40wandb-production.iam.gserviceaccount.com%2F20250411%2Fauto%2Fstorage%2Fgoog4_request&X-Goog-Date=20250411T133547Z&X-Goog-Expires=86399&X-Goog-Signature=4c9126604080912880ede91838f5a7390665008083d7e44309734daddd80b9cf8cf7a4c5c6fa5de745ba75d664cb7469ed45bccd6a8d0f8328f5b819c87f52209a817e2cecb6b43dd002266b64a58a46125cf94eecc520b1b7a33aba86a8651778a4fc020b1e58b91094758a9f0bdf70c1b1709c39a4aa8e5b9998524293e3f95252e6a81cbabe349b8e96481c3fdb99ef3ed87c033bd482bc27e2900be02b6f7a10cc37e178de535da73792986f0057d36c512c3142823ec07dde39234d436ecef04f3b634ff435b7df21a6d1fbd1b616a7aafd7a5bc2d0a15eacb48d1f828c4e7e505ad7f7585a5624f5d9716d95b4b15bdc9c2151e47d7698d62f76621622&X-Goog-SignedHeaders=host&X-User=2931823730: HTTPSConnectionPool(host='storage.googleapis.com', port=443): Max retries exceeded with url: /wandb-production.appspot.com/2931823730-harbin-institute-of-technology/ltu-as/ayrd945g/conda-environment.yaml?X-Goog-Algorithm=GOOG4-RSA-SHA256&X-Goog-Credential=gorilla-files-url-signer-man%40wandb-production.iam.gserviceaccount.com%2F20250411%2Fauto%2Fstorage%2Fgoog4_request&X-Goog-Date=20250411T133547Z&X-Goog-Expires=86399&X-Goog-Signature=4c9126604080912880ede91838f5a7390665008083d7e44309734daddd80b9cf8cf7a4c5c6fa5de745ba75d664cb7469ed45bccd6a8d0f8328f5b819c87f52209a817e2cecb6b43dd002266b64a58a46125cf94eecc520b1b7a33aba86a8651778a4fc020b1e58b91094758a9f0bdf70c1b1709c39a4aa8e5b9998524293e3f95252e6a81cbabe349b8e96481c3fdb99ef3ed87c033bd482bc27e2900be02b6f7a10cc37e178de535da73792986f0057d36c512c3142823ec07dde39234d436ecef04f3b634ff435b7df21a6d1fbd1b616a7aafd7a5bc2d0a15eacb48d1f828c4e7e505ad7f7585a5624f5d9716d95b4b15bdc9c2151e47d7698d62f76621622&X-Goog-SignedHeaders=host&X-User=2931823730 (Caused by NewConnectionError('<urllib3.connection.HTTPSConnection object at 0x7fcd927a8ee0>: Failed to establish a new connection: [Errno 101] Network is unreachable'))
2025-04-11 13:35:49,001 ERROR   wandb-upload_3:5057 [internal_api.py:upload_file():2558] upload_file request headers: {'User-Agent': 'python-requests/2.32.3', 'Accept-Encoding': 'gzip, deflate, br', 'Accept': '*/*', 'Connection': 'keep-alive', 'Content-Length': '8281'}
2025-04-11 13:35:49,001 ERROR   wandb-upload_3:5057 [internal_api.py:upload_file():2560] upload_file response body: 
2025-04-11 13:35:49,035 ERROR   wandb-upload_4:5057 [internal_api.py:upload_file():2556] upload_file exception https://storage.googleapis.com/wandb-production.appspot.com/2931823730-harbin-institute-of-technology/ltu-as/ayrd945g/output.log?X-Goog-Algorithm=GOOG4-RSA-SHA256&X-Goog-Credential=gorilla-files-url-signer-man%40wandb-production.iam.gserviceaccount.com%2F20250411%2Fauto%2Fstorage%2Fgoog4_request&X-Goog-Date=20250411T133547Z&X-Goog-Expires=86399&X-Goog-Signature=60a14c64c75b7213832de3f51a8cee68b48766ce9fef4ac66308dcfbe021d98db23ab7a4e8e5a5840ad99fe69b3425e1ecaa5e7cecda0e89061d438052a78b725028def9cc631a332a1e2c99ebd6d1172adc8172fdae0d62bec226a3e99cdb144f8e7a221e0ec08c94a76dc888412fde2d9f87d0b484866e6db161d92750595d0c526c395230151ab2e6574b130439e80c58f6c8fb6187dfedd000237d5c6c32116bebe722b0f4815fa4b433c2c01eac2e6d1d439d109c547bd416ef777f07467da9090b12efc4e78dfb53e81482b7f08de5e21dbddcb7102335ee3f4fc94d9b946d104c6c430ee9e397a2c1ef3c9eaaae349d83697a271010de87b863593b32&X-Goog-SignedHeaders=host&X-User=2931823730: HTTPSConnectionPool(host='storage.googleapis.com', port=443): Max retries exceeded with url: /wandb-production.appspot.com/2931823730-harbin-institute-of-technology/ltu-as/ayrd945g/output.log?X-Goog-Algorithm=GOOG4-RSA-SHA256&X-Goog-Credential=gorilla-files-url-signer-man%40wandb-production.iam.gserviceaccount.com%2F20250411%2Fauto%2Fstorage%2Fgoog4_request&X-Goog-Date=20250411T133547Z&X-Goog-Expires=86399&X-Goog-Signature=60a14c64c75b7213832de3f51a8cee68b48766ce9fef4ac66308dcfbe021d98db23ab7a4e8e5a5840ad99fe69b3425e1ecaa5e7cecda0e89061d438052a78b725028def9cc631a332a1e2c99ebd6d1172adc8172fdae0d62bec226a3e99cdb144f8e7a221e0ec08c94a76dc888412fde2d9f87d0b484866e6db161d92750595d0c526c395230151ab2e6574b130439e80c58f6c8fb6187dfedd000237d5c6c32116bebe722b0f4815fa4b433c2c01eac2e6d1d439d109c547bd416ef777f07467da9090b12efc4e78dfb53e81482b7f08de5e21dbddcb7102335ee3f4fc94d9b946d104c6c430ee9e397a2c1ef3c9eaaae349d83697a271010de87b863593b32&X-Goog-SignedHeaders=host&X-User=2931823730 (Caused by NewConnectionError('<urllib3.connection.HTTPSConnection object at 0x7fcd927a8a60>: Failed to establish a new connection: [Errno 101] Network is unreachable'))
2025-04-11 13:35:49,035 ERROR   wandb-upload_4:5057 [internal_api.py:upload_file():2558] upload_file request headers: {'User-Agent': 'python-requests/2.32.3', 'Accept-Encoding': 'gzip, deflate, br', 'Accept': '*/*', 'Connection': 'keep-alive', 'Content-Length': '5135'}
2025-04-11 13:35:49,035 ERROR   wandb-upload_4:5057 [internal_api.py:upload_file():2560] upload_file response body: 
2025-04-11 13:35:49,063 ERROR   wandb-upload_2:5057 [internal_api.py:upload_file():2556] upload_file exception https://storage.googleapis.com/wandb-production.appspot.com/2931823730-harbin-institute-of-technology/ltu-as/ayrd945g/requirements.txt?X-Goog-Algorithm=GOOG4-RSA-SHA256&X-Goog-Credential=gorilla-files-url-signer-man%40wandb-production.iam.gserviceaccount.com%2F20250411%2Fauto%2Fstorage%2Fgoog4_request&X-Goog-Date=20250411T133547Z&X-Goog-Expires=86399&X-Goog-Signature=8f7985a4ebf492647396ccbeb8281c95f40ce48ca6ebfe7230b06e3e08a640b4892e9fbe8f14f084f14e5d3841d2ed4769d71f5dcc53a827130556bbab907612d4a6c07d1c4b3f38ce4fc656dabf01e58238b7603961296e52ef293121e1ab2eb7c0f40e653fe066ef2a8502bf31d63a12f60e5498b0ebdae66cee400aa1a42598345e000ebb6d22ea01ec55dcf62810cace5cacbb3cef4cc37ca34ae61cfaf15fa634731635ca6ad7b243b89a565ecd2dfae6fdcfdaf084938d1afa790a313af20f904fe253f7e9c5fbe3595321a68018379642acab4619f2715b3e42cea1e7f430dada2242a15e4fdaaa50c317aa219a978a754411899f051b8136a1fa5a4d&X-Goog-SignedHeaders=host&X-User=2931823730: HTTPSConnectionPool(host='storage.googleapis.com', port=443): Max retries exceeded with url: /wandb-production.appspot.com/2931823730-harbin-institute-of-technology/ltu-as/ayrd945g/requirements.txt?X-Goog-Algorithm=GOOG4-RSA-SHA256&X-Goog-Credential=gorilla-files-url-signer-man%40wandb-production.iam.gserviceaccount.com%2F20250411%2Fauto%2Fstorage%2Fgoog4_request&X-Goog-Date=20250411T133547Z&X-Goog-Expires=86399&X-Goog-Signature=8f7985a4ebf492647396ccbeb8281c95f40ce48ca6ebfe7230b06e3e08a640b4892e9fbe8f14f084f14e5d3841d2ed4769d71f5dcc53a827130556bbab907612d4a6c07d1c4b3f38ce4fc656dabf01e58238b7603961296e52ef293121e1ab2eb7c0f40e653fe066ef2a8502bf31d63a12f60e5498b0ebdae66cee400aa1a42598345e000ebb6d22ea01ec55dcf62810cace5cacbb3cef4cc37ca34ae61cfaf15fa634731635ca6ad7b243b89a565ecd2dfae6fdcfdaf084938d1afa790a313af20f904fe253f7e9c5fbe3595321a68018379642acab4619f2715b3e42cea1e7f430dada2242a15e4fdaaa50c317aa219a978a754411899f051b8136a1fa5a4d&X-Goog-SignedHeaders=host&X-User=2931823730 (Caused by NewConnectionError('<urllib3.connection.HTTPSConnection object at 0x7fcd927aa650>: Failed to establish a new connection: [Errno 101] Network is unreachable'))
2025-04-11 13:35:49,063 ERROR   wandb-upload_2:5057 [internal_api.py:upload_file():2558] upload_file request headers: {'User-Agent': 'python-requests/2.32.3', 'Accept-Encoding': 'gzip, deflate, br', 'Accept': '*/*', 'Connection': 'keep-alive', 'Content-Length': '4212'}
2025-04-11 13:35:49,063 ERROR   wandb-upload_2:5057 [internal_api.py:upload_file():2560] upload_file response body: 
2025-04-11 13:35:50,942 ERROR   wandb-upload_1:5057 [internal_api.py:upload_file():2556] upload_file exception https://storage.googleapis.com/wandb-production.appspot.com/2931823730-harbin-institute-of-technology/ltu-as/ayrd945g/config.yaml?X-Goog-Algorithm=GOOG4-RSA-SHA256&X-Goog-Credential=gorilla-files-url-signer-man%40wandb-production.iam.gserviceaccount.com%2F20250411%2Fauto%2Fstorage%2Fgoog4_request&X-Goog-Date=20250411T133547Z&X-Goog-Expires=86399&X-Goog-Signature=59229da32108dabf2e0b22f3378d7c4eff52c92055ad5d5b992f76e4df1c8015b756cf03412a752e587a2ea6bc2f30001b205d9ef095c5a14ab645fe71a22b821da600c1196db4191aef6cd423a67f5cfc13d398e023ee472db63d91e6f84db94368a9e61522d891c6c41b7eeb918e96b41062c0135485092d85801d941c7eb761567114df29f3b71030380dfe24d3e94c0e9810f87f3eb1f65bf4625252ec95591d290b470be81abb48ba16966c05db2893b493bab6f93bdd5325ee55c3ce817c57cadd71e627b02871d0c646f4dba235a7310afdefe60e03add6e16f1ebcee16c2bf969543124fb60ebc8bf3cee02e75fd183babe4d68e010a4c410a360fd7&X-Goog-SignedHeaders=host&X-User=2931823730: HTTPSConnectionPool(host='storage.googleapis.com', port=443): Max retries exceeded with url: /wandb-production.appspot.com/2931823730-harbin-institute-of-technology/ltu-as/ayrd945g/config.yaml?X-Goog-Algorithm=GOOG4-RSA-SHA256&X-Goog-Credential=gorilla-files-url-signer-man%40wandb-production.iam.gserviceaccount.com%2F20250411%2Fauto%2Fstorage%2Fgoog4_request&X-Goog-Date=20250411T133547Z&X-Goog-Expires=86399&X-Goog-Signature=59229da32108dabf2e0b22f3378d7c4eff52c92055ad5d5b992f76e4df1c8015b756cf03412a752e587a2ea6bc2f30001b205d9ef095c5a14ab645fe71a22b821da600c1196db4191aef6cd423a67f5cfc13d398e023ee472db63d91e6f84db94368a9e61522d891c6c41b7eeb918e96b41062c0135485092d85801d941c7eb761567114df29f3b71030380dfe24d3e94c0e9810f87f3eb1f65bf4625252ec95591d290b470be81abb48ba16966c05db2893b493bab6f93bdd5325ee55c3ce817c57cadd71e627b02871d0c646f4dba235a7310afdefe60e03add6e16f1ebcee16c2bf969543124fb60ebc8bf3cee02e75fd183babe4d68e010a4c410a360fd7&X-Goog-SignedHeaders=host&X-User=2931823730 (Caused by NewConnectionError('<urllib3.connection.HTTPSConnection object at 0x7fcdd3a5f370>: Failed to establish a new connection: [Errno 101] Network is unreachable'))
2025-04-11 13:35:50,943 ERROR   wandb-upload_1:5057 [internal_api.py:upload_file():2558] upload_file request headers: {'User-Agent': 'python-requests/2.32.3', 'Accept-Encoding': 'gzip, deflate, br', 'Accept': '*/*', 'Connection': 'keep-alive', 'Content-Length': '8685'}
2025-04-11 13:35:50,943 ERROR   wandb-upload_1:5057 [internal_api.py:upload_file():2560] upload_file response body: 
2025-04-11 13:35:50,970 DEBUG   HandlerThread:5057 [handler.py:handle_request():146] handle_request: keepalive
2025-04-11 13:35:51,160 ERROR   wandb-upload_5:5057 [internal_api.py:upload_file():2556] upload_file exception https://storage.googleapis.com/wandb-production.appspot.com/2931823730-harbin-institute-of-technology/ltu-as/ayrd945g/wandb-summary.json?X-Goog-Algorithm=GOOG4-RSA-SHA256&X-Goog-Credential=gorilla-files-url-signer-man%40wandb-production.iam.gserviceaccount.com%2F20250411%2Fauto%2Fstorage%2Fgoog4_request&X-Goog-Date=20250411T133547Z&X-Goog-Expires=86399&X-Goog-Signature=88d8a33a4942edfdf46386d8d3684fa7b9d5a442bb037f8cda46c414fe422ca150fb4f2e5f776cc41bf710997e8d99494d56986c0251407a93dff567d301deee84d6a9d3c20c4876734beeebe93fc2170c90439950e62f7d895e7dfc8cff58ae05a6debe4386cf769ab635fbfecc6b9311f012934afbb8e9bfc6c652fb999d4b61c9c6dd3511d8a321c3bac43987e7d9891f0c31f9d35ca79f5a1ef87bcfa3ef26a7e363d6207536f2b71b07a4b55c4e341c9e6178a3a7bf0e2c835d2471597f60ccc6925d495148fc1623f5b3160f75ff84cd47fadcd8cd769536b21457ea5f60c8ba539b75f81d476509ef340009289b14c43e1a28cc2e27df0d6e9eb44275&X-Goog-SignedHeaders=host&X-User=2931823730: HTTPSConnectionPool(host='storage.googleapis.com', port=443): Max retries exceeded with url: /wandb-production.appspot.com/2931823730-harbin-institute-of-technology/ltu-as/ayrd945g/wandb-summary.json?X-Goog-Algorithm=GOOG4-RSA-SHA256&X-Goog-Credential=gorilla-files-url-signer-man%40wandb-production.iam.gserviceaccount.com%2F20250411%2Fauto%2Fstorage%2Fgoog4_request&X-Goog-Date=20250411T133547Z&X-Goog-Expires=86399&X-Goog-Signature=88d8a33a4942edfdf46386d8d3684fa7b9d5a442bb037f8cda46c414fe422ca150fb4f2e5f776cc41bf710997e8d99494d56986c0251407a93dff567d301deee84d6a9d3c20c4876734beeebe93fc2170c90439950e62f7d895e7dfc8cff58ae05a6debe4386cf769ab635fbfecc6b9311f012934afbb8e9bfc6c652fb999d4b61c9c6dd3511d8a321c3bac43987e7d9891f0c31f9d35ca79f5a1ef87bcfa3ef26a7e363d6207536f2b71b07a4b55c4e341c9e6178a3a7bf0e2c835d2471597f60ccc6925d495148fc1623f5b3160f75ff84cd47fadcd8cd769536b21457ea5f60c8ba539b75f81d476509ef340009289b14c43e1a28cc2e27df0d6e9eb44275&X-Goog-SignedHeaders=host&X-User=2931823730 (Caused by NewConnectionError('<urllib3.connection.HTTPSConnection object at 0x7fcdd01c2c20>: Failed to establish a new connection: [Errno 101] Network is unreachable'))
2025-04-11 13:35:51,161 ERROR   wandb-upload_5:5057 [internal_api.py:upload_file():2558] upload_file request headers: {'User-Agent': 'python-requests/2.32.3', 'Accept-Encoding': 'gzip, deflate, br', 'Accept': '*/*', 'Connection': 'keep-alive', 'Content-Length': '27'}
2025-04-11 13:35:51,161 ERROR   wandb-upload_5:5057 [internal_api.py:upload_file():2560] upload_file response body: 
2025-04-11 13:35:51,210 ERROR   wandb-upload_4:5057 [internal_api.py:upload_file():2556] upload_file exception https://storage.googleapis.com/wandb-production.appspot.com/2931823730-harbin-institute-of-technology/ltu-as/ayrd945g/output.log?X-Goog-Algorithm=GOOG4-RSA-SHA256&X-Goog-Credential=gorilla-files-url-signer-man%40wandb-production.iam.gserviceaccount.com%2F20250411%2Fauto%2Fstorage%2Fgoog4_request&X-Goog-Date=20250411T133547Z&X-Goog-Expires=86399&X-Goog-Signature=60a14c64c75b7213832de3f51a8cee68b48766ce9fef4ac66308dcfbe021d98db23ab7a4e8e5a5840ad99fe69b3425e1ecaa5e7cecda0e89061d438052a78b725028def9cc631a332a1e2c99ebd6d1172adc8172fdae0d62bec226a3e99cdb144f8e7a221e0ec08c94a76dc888412fde2d9f87d0b484866e6db161d92750595d0c526c395230151ab2e6574b130439e80c58f6c8fb6187dfedd000237d5c6c32116bebe722b0f4815fa4b433c2c01eac2e6d1d439d109c547bd416ef777f07467da9090b12efc4e78dfb53e81482b7f08de5e21dbddcb7102335ee3f4fc94d9b946d104c6c430ee9e397a2c1ef3c9eaaae349d83697a271010de87b863593b32&X-Goog-SignedHeaders=host&X-User=2931823730: HTTPSConnectionPool(host='storage.googleapis.com', port=443): Max retries exceeded with url: /wandb-production.appspot.com/2931823730-harbin-institute-of-technology/ltu-as/ayrd945g/output.log?X-Goog-Algorithm=GOOG4-RSA-SHA256&X-Goog-Credential=gorilla-files-url-signer-man%40wandb-production.iam.gserviceaccount.com%2F20250411%2Fauto%2Fstorage%2Fgoog4_request&X-Goog-Date=20250411T133547Z&X-Goog-Expires=86399&X-Goog-Signature=60a14c64c75b7213832de3f51a8cee68b48766ce9fef4ac66308dcfbe021d98db23ab7a4e8e5a5840ad99fe69b3425e1ecaa5e7cecda0e89061d438052a78b725028def9cc631a332a1e2c99ebd6d1172adc8172fdae0d62bec226a3e99cdb144f8e7a221e0ec08c94a76dc888412fde2d9f87d0b484866e6db161d92750595d0c526c395230151ab2e6574b130439e80c58f6c8fb6187dfedd000237d5c6c32116bebe722b0f4815fa4b433c2c01eac2e6d1d439d109c547bd416ef777f07467da9090b12efc4e78dfb53e81482b7f08de5e21dbddcb7102335ee3f4fc94d9b946d104c6c430ee9e397a2c1ef3c9eaaae349d83697a271010de87b863593b32&X-Goog-SignedHeaders=host&X-User=2931823730 (Caused by NewConnectionError('<urllib3.connection.HTTPSConnection object at 0x7fcdd01c1270>: Failed to establish a new connection: [Errno 101] Network is unreachable'))
2025-04-11 13:35:51,210 ERROR   wandb-upload_4:5057 [internal_api.py:upload_file():2558] upload_file request headers: {'User-Agent': 'python-requests/2.32.3', 'Accept-Encoding': 'gzip, deflate, br', 'Accept': '*/*', 'Connection': 'keep-alive', 'Content-Length': '5135'}
2025-04-11 13:35:51,210 ERROR   wandb-upload_4:5057 [internal_api.py:upload_file():2560] upload_file response body: 
2025-04-11 13:35:51,220 ERROR   wandb-upload_2:5057 [internal_api.py:upload_file():2556] upload_file exception https://storage.googleapis.com/wandb-production.appspot.com/2931823730-harbin-institute-of-technology/ltu-as/ayrd945g/requirements.txt?X-Goog-Algorithm=GOOG4-RSA-SHA256&X-Goog-Credential=gorilla-files-url-signer-man%40wandb-production.iam.gserviceaccount.com%2F20250411%2Fauto%2Fstorage%2Fgoog4_request&X-Goog-Date=20250411T133547Z&X-Goog-Expires=86399&X-Goog-Signature=8f7985a4ebf492647396ccbeb8281c95f40ce48ca6ebfe7230b06e3e08a640b4892e9fbe8f14f084f14e5d3841d2ed4769d71f5dcc53a827130556bbab907612d4a6c07d1c4b3f38ce4fc656dabf01e58238b7603961296e52ef293121e1ab2eb7c0f40e653fe066ef2a8502bf31d63a12f60e5498b0ebdae66cee400aa1a42598345e000ebb6d22ea01ec55dcf62810cace5cacbb3cef4cc37ca34ae61cfaf15fa634731635ca6ad7b243b89a565ecd2dfae6fdcfdaf084938d1afa790a313af20f904fe253f7e9c5fbe3595321a68018379642acab4619f2715b3e42cea1e7f430dada2242a15e4fdaaa50c317aa219a978a754411899f051b8136a1fa5a4d&X-Goog-SignedHeaders=host&X-User=2931823730: HTTPSConnectionPool(host='storage.googleapis.com', port=443): Max retries exceeded with url: /wandb-production.appspot.com/2931823730-harbin-institute-of-technology/ltu-as/ayrd945g/requirements.txt?X-Goog-Algorithm=GOOG4-RSA-SHA256&X-Goog-Credential=gorilla-files-url-signer-man%40wandb-production.iam.gserviceaccount.com%2F20250411%2Fauto%2Fstorage%2Fgoog4_request&X-Goog-Date=20250411T133547Z&X-Goog-Expires=86399&X-Goog-Signature=8f7985a4ebf492647396ccbeb8281c95f40ce48ca6ebfe7230b06e3e08a640b4892e9fbe8f14f084f14e5d3841d2ed4769d71f5dcc53a827130556bbab907612d4a6c07d1c4b3f38ce4fc656dabf01e58238b7603961296e52ef293121e1ab2eb7c0f40e653fe066ef2a8502bf31d63a12f60e5498b0ebdae66cee400aa1a42598345e000ebb6d22ea01ec55dcf62810cace5cacbb3cef4cc37ca34ae61cfaf15fa634731635ca6ad7b243b89a565ecd2dfae6fdcfdaf084938d1afa790a313af20f904fe253f7e9c5fbe3595321a68018379642acab4619f2715b3e42cea1e7f430dada2242a15e4fdaaa50c317aa219a978a754411899f051b8136a1fa5a4d&X-Goog-SignedHeaders=host&X-User=2931823730 (Caused by NewConnectionError('<urllib3.connection.HTTPSConnection object at 0x7fcdd01c0520>: Failed to establish a new connection: [Errno 101] Network is unreachable'))
2025-04-11 13:35:51,220 ERROR   wandb-upload_2:5057 [internal_api.py:upload_file():2558] upload_file request headers: {'User-Agent': 'python-requests/2.32.3', 'Accept-Encoding': 'gzip, deflate, br', 'Accept': '*/*', 'Connection': 'keep-alive', 'Content-Length': '4212'}
2025-04-11 13:35:51,220 ERROR   wandb-upload_2:5057 [internal_api.py:upload_file():2560] upload_file response body: 
2025-04-11 13:35:51,315 ERROR   wandb-upload_3:5057 [internal_api.py:upload_file():2556] upload_file exception https://storage.googleapis.com/wandb-production.appspot.com/2931823730-harbin-institute-of-technology/ltu-as/ayrd945g/conda-environment.yaml?X-Goog-Algorithm=GOOG4-RSA-SHA256&X-Goog-Credential=gorilla-files-url-signer-man%40wandb-production.iam.gserviceaccount.com%2F20250411%2Fauto%2Fstorage%2Fgoog4_request&X-Goog-Date=20250411T133547Z&X-Goog-Expires=86399&X-Goog-Signature=4c9126604080912880ede91838f5a7390665008083d7e44309734daddd80b9cf8cf7a4c5c6fa5de745ba75d664cb7469ed45bccd6a8d0f8328f5b819c87f52209a817e2cecb6b43dd002266b64a58a46125cf94eecc520b1b7a33aba86a8651778a4fc020b1e58b91094758a9f0bdf70c1b1709c39a4aa8e5b9998524293e3f95252e6a81cbabe349b8e96481c3fdb99ef3ed87c033bd482bc27e2900be02b6f7a10cc37e178de535da73792986f0057d36c512c3142823ec07dde39234d436ecef04f3b634ff435b7df21a6d1fbd1b616a7aafd7a5bc2d0a15eacb48d1f828c4e7e505ad7f7585a5624f5d9716d95b4b15bdc9c2151e47d7698d62f76621622&X-Goog-SignedHeaders=host&X-User=2931823730: HTTPSConnectionPool(host='storage.googleapis.com', port=443): Max retries exceeded with url: /wandb-production.appspot.com/2931823730-harbin-institute-of-technology/ltu-as/ayrd945g/conda-environment.yaml?X-Goog-Algorithm=GOOG4-RSA-SHA256&X-Goog-Credential=gorilla-files-url-signer-man%40wandb-production.iam.gserviceaccount.com%2F20250411%2Fauto%2Fstorage%2Fgoog4_request&X-Goog-Date=20250411T133547Z&X-Goog-Expires=86399&X-Goog-Signature=4c9126604080912880ede91838f5a7390665008083d7e44309734daddd80b9cf8cf7a4c5c6fa5de745ba75d664cb7469ed45bccd6a8d0f8328f5b819c87f52209a817e2cecb6b43dd002266b64a58a46125cf94eecc520b1b7a33aba86a8651778a4fc020b1e58b91094758a9f0bdf70c1b1709c39a4aa8e5b9998524293e3f95252e6a81cbabe349b8e96481c3fdb99ef3ed87c033bd482bc27e2900be02b6f7a10cc37e178de535da73792986f0057d36c512c3142823ec07dde39234d436ecef04f3b634ff435b7df21a6d1fbd1b616a7aafd7a5bc2d0a15eacb48d1f828c4e7e505ad7f7585a5624f5d9716d95b4b15bdc9c2151e47d7698d62f76621622&X-Goog-SignedHeaders=host&X-User=2931823730 (Caused by NewConnectionError('<urllib3.connection.HTTPSConnection object at 0x7fcdd01c11b0>: Failed to establish a new connection: [Errno 101] Network is unreachable'))
2025-04-11 13:35:51,316 ERROR   wandb-upload_3:5057 [internal_api.py:upload_file():2558] upload_file request headers: {'User-Agent': 'python-requests/2.32.3', 'Accept-Encoding': 'gzip, deflate, br', 'Accept': '*/*', 'Connection': 'keep-alive', 'Content-Length': '8281'}
2025-04-11 13:35:51,316 ERROR   wandb-upload_3:5057 [internal_api.py:upload_file():2560] upload_file response body: 
2025-04-11 13:35:53,400 DEBUG   HandlerThread:5057 [handler.py:handle_request():146] handle_request: status_report
2025-04-11 13:35:55,167 ERROR   wandb-upload_1:5057 [internal_api.py:upload_file():2556] upload_file exception https://storage.googleapis.com/wandb-production.appspot.com/2931823730-harbin-institute-of-technology/ltu-as/ayrd945g/config.yaml?X-Goog-Algorithm=GOOG4-RSA-SHA256&X-Goog-Credential=gorilla-files-url-signer-man%40wandb-production.iam.gserviceaccount.com%2F20250411%2Fauto%2Fstorage%2Fgoog4_request&X-Goog-Date=20250411T133547Z&X-Goog-Expires=86399&X-Goog-Signature=59229da32108dabf2e0b22f3378d7c4eff52c92055ad5d5b992f76e4df1c8015b756cf03412a752e587a2ea6bc2f30001b205d9ef095c5a14ab645fe71a22b821da600c1196db4191aef6cd423a67f5cfc13d398e023ee472db63d91e6f84db94368a9e61522d891c6c41b7eeb918e96b41062c0135485092d85801d941c7eb761567114df29f3b71030380dfe24d3e94c0e9810f87f3eb1f65bf4625252ec95591d290b470be81abb48ba16966c05db2893b493bab6f93bdd5325ee55c3ce817c57cadd71e627b02871d0c646f4dba235a7310afdefe60e03add6e16f1ebcee16c2bf969543124fb60ebc8bf3cee02e75fd183babe4d68e010a4c410a360fd7&X-Goog-SignedHeaders=host&X-User=2931823730: HTTPSConnectionPool(host='storage.googleapis.com', port=443): Max retries exceeded with url: /wandb-production.appspot.com/2931823730-harbin-institute-of-technology/ltu-as/ayrd945g/config.yaml?X-Goog-Algorithm=GOOG4-RSA-SHA256&X-Goog-Credential=gorilla-files-url-signer-man%40wandb-production.iam.gserviceaccount.com%2F20250411%2Fauto%2Fstorage%2Fgoog4_request&X-Goog-Date=20250411T133547Z&X-Goog-Expires=86399&X-Goog-Signature=59229da32108dabf2e0b22f3378d7c4eff52c92055ad5d5b992f76e4df1c8015b756cf03412a752e587a2ea6bc2f30001b205d9ef095c5a14ab645fe71a22b821da600c1196db4191aef6cd423a67f5cfc13d398e023ee472db63d91e6f84db94368a9e61522d891c6c41b7eeb918e96b41062c0135485092d85801d941c7eb761567114df29f3b71030380dfe24d3e94c0e9810f87f3eb1f65bf4625252ec95591d290b470be81abb48ba16966c05db2893b493bab6f93bdd5325ee55c3ce817c57cadd71e627b02871d0c646f4dba235a7310afdefe60e03add6e16f1ebcee16c2bf969543124fb60ebc8bf3cee02e75fd183babe4d68e010a4c410a360fd7&X-Goog-SignedHeaders=host&X-User=2931823730 (Caused by NewConnectionError('<urllib3.connection.HTTPSConnection object at 0x7fcdd01c2020>: Failed to establish a new connection: [Errno 101] Network is unreachable'))
2025-04-11 13:35:55,168 ERROR   wandb-upload_1:5057 [internal_api.py:upload_file():2558] upload_file request headers: {'User-Agent': 'python-requests/2.32.3', 'Accept-Encoding': 'gzip, deflate, br', 'Accept': '*/*', 'Connection': 'keep-alive', 'Content-Length': '8685'}
2025-04-11 13:35:55,168 ERROR   wandb-upload_1:5057 [internal_api.py:upload_file():2560] upload_file response body: 
2025-04-11 13:35:55,266 ERROR   wandb-upload_5:5057 [internal_api.py:upload_file():2556] upload_file exception https://storage.googleapis.com/wandb-production.appspot.com/2931823730-harbin-institute-of-technology/ltu-as/ayrd945g/wandb-summary.json?X-Goog-Algorithm=GOOG4-RSA-SHA256&X-Goog-Credential=gorilla-files-url-signer-man%40wandb-production.iam.gserviceaccount.com%2F20250411%2Fauto%2Fstorage%2Fgoog4_request&X-Goog-Date=20250411T133547Z&X-Goog-Expires=86399&X-Goog-Signature=88d8a33a4942edfdf46386d8d3684fa7b9d5a442bb037f8cda46c414fe422ca150fb4f2e5f776cc41bf710997e8d99494d56986c0251407a93dff567d301deee84d6a9d3c20c4876734beeebe93fc2170c90439950e62f7d895e7dfc8cff58ae05a6debe4386cf769ab635fbfecc6b9311f012934afbb8e9bfc6c652fb999d4b61c9c6dd3511d8a321c3bac43987e7d9891f0c31f9d35ca79f5a1ef87bcfa3ef26a7e363d6207536f2b71b07a4b55c4e341c9e6178a3a7bf0e2c835d2471597f60ccc6925d495148fc1623f5b3160f75ff84cd47fadcd8cd769536b21457ea5f60c8ba539b75f81d476509ef340009289b14c43e1a28cc2e27df0d6e9eb44275&X-Goog-SignedHeaders=host&X-User=2931823730: HTTPSConnectionPool(host='storage.googleapis.com', port=443): Max retries exceeded with url: /wandb-production.appspot.com/2931823730-harbin-institute-of-technology/ltu-as/ayrd945g/wandb-summary.json?X-Goog-Algorithm=GOOG4-RSA-SHA256&X-Goog-Credential=gorilla-files-url-signer-man%40wandb-production.iam.gserviceaccount.com%2F20250411%2Fauto%2Fstorage%2Fgoog4_request&X-Goog-Date=20250411T133547Z&X-Goog-Expires=86399&X-Goog-Signature=88d8a33a4942edfdf46386d8d3684fa7b9d5a442bb037f8cda46c414fe422ca150fb4f2e5f776cc41bf710997e8d99494d56986c0251407a93dff567d301deee84d6a9d3c20c4876734beeebe93fc2170c90439950e62f7d895e7dfc8cff58ae05a6debe4386cf769ab635fbfecc6b9311f012934afbb8e9bfc6c652fb999d4b61c9c6dd3511d8a321c3bac43987e7d9891f0c31f9d35ca79f5a1ef87bcfa3ef26a7e363d6207536f2b71b07a4b55c4e341c9e6178a3a7bf0e2c835d2471597f60ccc6925d495148fc1623f5b3160f75ff84cd47fadcd8cd769536b21457ea5f60c8ba539b75f81d476509ef340009289b14c43e1a28cc2e27df0d6e9eb44275&X-Goog-SignedHeaders=host&X-User=2931823730 (Caused by NewConnectionError('<urllib3.connection.HTTPSConnection object at 0x7fcd927aa740>: Failed to establish a new connection: [Errno 101] Network is unreachable'))
2025-04-11 13:35:55,266 ERROR   wandb-upload_5:5057 [internal_api.py:upload_file():2558] upload_file request headers: {'User-Agent': 'python-requests/2.32.3', 'Accept-Encoding': 'gzip, deflate, br', 'Accept': '*/*', 'Connection': 'keep-alive', 'Content-Length': '27'}
2025-04-11 13:35:55,267 ERROR   wandb-upload_5:5057 [internal_api.py:upload_file():2560] upload_file response body: 
2025-04-11 13:35:55,620 ERROR   wandb-upload_4:5057 [internal_api.py:upload_file():2556] upload_file exception https://storage.googleapis.com/wandb-production.appspot.com/2931823730-harbin-institute-of-technology/ltu-as/ayrd945g/output.log?X-Goog-Algorithm=GOOG4-RSA-SHA256&X-Goog-Credential=gorilla-files-url-signer-man%40wandb-production.iam.gserviceaccount.com%2F20250411%2Fauto%2Fstorage%2Fgoog4_request&X-Goog-Date=20250411T133547Z&X-Goog-Expires=86399&X-Goog-Signature=60a14c64c75b7213832de3f51a8cee68b48766ce9fef4ac66308dcfbe021d98db23ab7a4e8e5a5840ad99fe69b3425e1ecaa5e7cecda0e89061d438052a78b725028def9cc631a332a1e2c99ebd6d1172adc8172fdae0d62bec226a3e99cdb144f8e7a221e0ec08c94a76dc888412fde2d9f87d0b484866e6db161d92750595d0c526c395230151ab2e6574b130439e80c58f6c8fb6187dfedd000237d5c6c32116bebe722b0f4815fa4b433c2c01eac2e6d1d439d109c547bd416ef777f07467da9090b12efc4e78dfb53e81482b7f08de5e21dbddcb7102335ee3f4fc94d9b946d104c6c430ee9e397a2c1ef3c9eaaae349d83697a271010de87b863593b32&X-Goog-SignedHeaders=host&X-User=2931823730: HTTPSConnectionPool(host='storage.googleapis.com', port=443): Max retries exceeded with url: /wandb-production.appspot.com/2931823730-harbin-institute-of-technology/ltu-as/ayrd945g/output.log?X-Goog-Algorithm=GOOG4-RSA-SHA256&X-Goog-Credential=gorilla-files-url-signer-man%40wandb-production.iam.gserviceaccount.com%2F20250411%2Fauto%2Fstorage%2Fgoog4_request&X-Goog-Date=20250411T133547Z&X-Goog-Expires=86399&X-Goog-Signature=60a14c64c75b7213832de3f51a8cee68b48766ce9fef4ac66308dcfbe021d98db23ab7a4e8e5a5840ad99fe69b3425e1ecaa5e7cecda0e89061d438052a78b725028def9cc631a332a1e2c99ebd6d1172adc8172fdae0d62bec226a3e99cdb144f8e7a221e0ec08c94a76dc888412fde2d9f87d0b484866e6db161d92750595d0c526c395230151ab2e6574b130439e80c58f6c8fb6187dfedd000237d5c6c32116bebe722b0f4815fa4b433c2c01eac2e6d1d439d109c547bd416ef777f07467da9090b12efc4e78dfb53e81482b7f08de5e21dbddcb7102335ee3f4fc94d9b946d104c6c430ee9e397a2c1ef3c9eaaae349d83697a271010de87b863593b32&X-Goog-SignedHeaders=host&X-User=2931823730 (Caused by NewConnectionError('<urllib3.connection.HTTPSConnection object at 0x7fcd927a8dc0>: Failed to establish a new connection: [Errno 101] Network is unreachable'))
2025-04-11 13:35:55,620 ERROR   wandb-upload_4:5057 [internal_api.py:upload_file():2558] upload_file request headers: {'User-Agent': 'python-requests/2.32.3', 'Accept-Encoding': 'gzip, deflate, br', 'Accept': '*/*', 'Connection': 'keep-alive', 'Content-Length': '5135'}
2025-04-11 13:35:55,620 ERROR   wandb-upload_4:5057 [internal_api.py:upload_file():2560] upload_file response body: 
2025-04-11 13:35:55,680 ERROR   wandb-upload_3:5057 [internal_api.py:upload_file():2556] upload_file exception https://storage.googleapis.com/wandb-production.appspot.com/2931823730-harbin-institute-of-technology/ltu-as/ayrd945g/conda-environment.yaml?X-Goog-Algorithm=GOOG4-RSA-SHA256&X-Goog-Credential=gorilla-files-url-signer-man%40wandb-production.iam.gserviceaccount.com%2F20250411%2Fauto%2Fstorage%2Fgoog4_request&X-Goog-Date=20250411T133547Z&X-Goog-Expires=86399&X-Goog-Signature=4c9126604080912880ede91838f5a7390665008083d7e44309734daddd80b9cf8cf7a4c5c6fa5de745ba75d664cb7469ed45bccd6a8d0f8328f5b819c87f52209a817e2cecb6b43dd002266b64a58a46125cf94eecc520b1b7a33aba86a8651778a4fc020b1e58b91094758a9f0bdf70c1b1709c39a4aa8e5b9998524293e3f95252e6a81cbabe349b8e96481c3fdb99ef3ed87c033bd482bc27e2900be02b6f7a10cc37e178de535da73792986f0057d36c512c3142823ec07dde39234d436ecef04f3b634ff435b7df21a6d1fbd1b616a7aafd7a5bc2d0a15eacb48d1f828c4e7e505ad7f7585a5624f5d9716d95b4b15bdc9c2151e47d7698d62f76621622&X-Goog-SignedHeaders=host&X-User=2931823730: HTTPSConnectionPool(host='storage.googleapis.com', port=443): Max retries exceeded with url: /wandb-production.appspot.com/2931823730-harbin-institute-of-technology/ltu-as/ayrd945g/conda-environment.yaml?X-Goog-Algorithm=GOOG4-RSA-SHA256&X-Goog-Credential=gorilla-files-url-signer-man%40wandb-production.iam.gserviceaccount.com%2F20250411%2Fauto%2Fstorage%2Fgoog4_request&X-Goog-Date=20250411T133547Z&X-Goog-Expires=86399&X-Goog-Signature=4c9126604080912880ede91838f5a7390665008083d7e44309734daddd80b9cf8cf7a4c5c6fa5de745ba75d664cb7469ed45bccd6a8d0f8328f5b819c87f52209a817e2cecb6b43dd002266b64a58a46125cf94eecc520b1b7a33aba86a8651778a4fc020b1e58b91094758a9f0bdf70c1b1709c39a4aa8e5b9998524293e3f95252e6a81cbabe349b8e96481c3fdb99ef3ed87c033bd482bc27e2900be02b6f7a10cc37e178de535da73792986f0057d36c512c3142823ec07dde39234d436ecef04f3b634ff435b7df21a6d1fbd1b616a7aafd7a5bc2d0a15eacb48d1f828c4e7e505ad7f7585a5624f5d9716d95b4b15bdc9c2151e47d7698d62f76621622&X-Goog-SignedHeaders=host&X-User=2931823730 (Caused by NewConnectionError('<urllib3.connection.HTTPSConnection object at 0x7fcd927a8e20>: Failed to establish a new connection: [Errno 101] Network is unreachable'))
2025-04-11 13:35:55,680 ERROR   wandb-upload_3:5057 [internal_api.py:upload_file():2558] upload_file request headers: {'User-Agent': 'python-requests/2.32.3', 'Accept-Encoding': 'gzip, deflate, br', 'Accept': '*/*', 'Connection': 'keep-alive', 'Content-Length': '8281'}
2025-04-11 13:35:55,680 ERROR   wandb-upload_3:5057 [internal_api.py:upload_file():2560] upload_file response body: 
2025-04-11 13:35:55,723 ERROR   wandb-upload_2:5057 [internal_api.py:upload_file():2556] upload_file exception https://storage.googleapis.com/wandb-production.appspot.com/2931823730-harbin-institute-of-technology/ltu-as/ayrd945g/requirements.txt?X-Goog-Algorithm=GOOG4-RSA-SHA256&X-Goog-Credential=gorilla-files-url-signer-man%40wandb-production.iam.gserviceaccount.com%2F20250411%2Fauto%2Fstorage%2Fgoog4_request&X-Goog-Date=20250411T133547Z&X-Goog-Expires=86399&X-Goog-Signature=8f7985a4ebf492647396ccbeb8281c95f40ce48ca6ebfe7230b06e3e08a640b4892e9fbe8f14f084f14e5d3841d2ed4769d71f5dcc53a827130556bbab907612d4a6c07d1c4b3f38ce4fc656dabf01e58238b7603961296e52ef293121e1ab2eb7c0f40e653fe066ef2a8502bf31d63a12f60e5498b0ebdae66cee400aa1a42598345e000ebb6d22ea01ec55dcf62810cace5cacbb3cef4cc37ca34ae61cfaf15fa634731635ca6ad7b243b89a565ecd2dfae6fdcfdaf084938d1afa790a313af20f904fe253f7e9c5fbe3595321a68018379642acab4619f2715b3e42cea1e7f430dada2242a15e4fdaaa50c317aa219a978a754411899f051b8136a1fa5a4d&X-Goog-SignedHeaders=host&X-User=2931823730: HTTPSConnectionPool(host='storage.googleapis.com', port=443): Max retries exceeded with url: /wandb-production.appspot.com/2931823730-harbin-institute-of-technology/ltu-as/ayrd945g/requirements.txt?X-Goog-Algorithm=GOOG4-RSA-SHA256&X-Goog-Credential=gorilla-files-url-signer-man%40wandb-production.iam.gserviceaccount.com%2F20250411%2Fauto%2Fstorage%2Fgoog4_request&X-Goog-Date=20250411T133547Z&X-Goog-Expires=86399&X-Goog-Signature=8f7985a4ebf492647396ccbeb8281c95f40ce48ca6ebfe7230b06e3e08a640b4892e9fbe8f14f084f14e5d3841d2ed4769d71f5dcc53a827130556bbab907612d4a6c07d1c4b3f38ce4fc656dabf01e58238b7603961296e52ef293121e1ab2eb7c0f40e653fe066ef2a8502bf31d63a12f60e5498b0ebdae66cee400aa1a42598345e000ebb6d22ea01ec55dcf62810cace5cacbb3cef4cc37ca34ae61cfaf15fa634731635ca6ad7b243b89a565ecd2dfae6fdcfdaf084938d1afa790a313af20f904fe253f7e9c5fbe3595321a68018379642acab4619f2715b3e42cea1e7f430dada2242a15e4fdaaa50c317aa219a978a754411899f051b8136a1fa5a4d&X-Goog-SignedHeaders=host&X-User=2931823730 (Caused by NewConnectionError('<urllib3.connection.HTTPSConnection object at 0x7fcd927a9b10>: Failed to establish a new connection: [Errno 101] Network is unreachable'))
2025-04-11 13:35:55,723 ERROR   wandb-upload_2:5057 [internal_api.py:upload_file():2558] upload_file request headers: {'User-Agent': 'python-requests/2.32.3', 'Accept-Encoding': 'gzip, deflate, br', 'Accept': '*/*', 'Connection': 'keep-alive', 'Content-Length': '4212'}
2025-04-11 13:35:55,723 ERROR   wandb-upload_2:5057 [internal_api.py:upload_file():2560] upload_file response body: 
2025-04-11 13:35:55,971 DEBUG   HandlerThread:5057 [handler.py:handle_request():146] handle_request: keepalive
2025-04-11 13:35:58,401 DEBUG   HandlerThread:5057 [handler.py:handle_request():146] handle_request: status_report
2025-04-11 13:36:00,974 DEBUG   HandlerThread:5057 [handler.py:handle_request():146] handle_request: keepalive
2025-04-11 13:36:03,402 DEBUG   HandlerThread:5057 [handler.py:handle_request():146] handle_request: status_report
2025-04-11 13:36:03,747 ERROR   wandb-upload_1:5057 [internal_api.py:upload_file():2556] upload_file exception https://storage.googleapis.com/wandb-production.appspot.com/2931823730-harbin-institute-of-technology/ltu-as/ayrd945g/config.yaml?X-Goog-Algorithm=GOOG4-RSA-SHA256&X-Goog-Credential=gorilla-files-url-signer-man%40wandb-production.iam.gserviceaccount.com%2F20250411%2Fauto%2Fstorage%2Fgoog4_request&X-Goog-Date=20250411T133547Z&X-Goog-Expires=86399&X-Goog-Signature=59229da32108dabf2e0b22f3378d7c4eff52c92055ad5d5b992f76e4df1c8015b756cf03412a752e587a2ea6bc2f30001b205d9ef095c5a14ab645fe71a22b821da600c1196db4191aef6cd423a67f5cfc13d398e023ee472db63d91e6f84db94368a9e61522d891c6c41b7eeb918e96b41062c0135485092d85801d941c7eb761567114df29f3b71030380dfe24d3e94c0e9810f87f3eb1f65bf4625252ec95591d290b470be81abb48ba16966c05db2893b493bab6f93bdd5325ee55c3ce817c57cadd71e627b02871d0c646f4dba235a7310afdefe60e03add6e16f1ebcee16c2bf969543124fb60ebc8bf3cee02e75fd183babe4d68e010a4c410a360fd7&X-Goog-SignedHeaders=host&X-User=2931823730: HTTPSConnectionPool(host='storage.googleapis.com', port=443): Max retries exceeded with url: /wandb-production.appspot.com/2931823730-harbin-institute-of-technology/ltu-as/ayrd945g/config.yaml?X-Goog-Algorithm=GOOG4-RSA-SHA256&X-Goog-Credential=gorilla-files-url-signer-man%40wandb-production.iam.gserviceaccount.com%2F20250411%2Fauto%2Fstorage%2Fgoog4_request&X-Goog-Date=20250411T133547Z&X-Goog-Expires=86399&X-Goog-Signature=59229da32108dabf2e0b22f3378d7c4eff52c92055ad5d5b992f76e4df1c8015b756cf03412a752e587a2ea6bc2f30001b205d9ef095c5a14ab645fe71a22b821da600c1196db4191aef6cd423a67f5cfc13d398e023ee472db63d91e6f84db94368a9e61522d891c6c41b7eeb918e96b41062c0135485092d85801d941c7eb761567114df29f3b71030380dfe24d3e94c0e9810f87f3eb1f65bf4625252ec95591d290b470be81abb48ba16966c05db2893b493bab6f93bdd5325ee55c3ce817c57cadd71e627b02871d0c646f4dba235a7310afdefe60e03add6e16f1ebcee16c2bf969543124fb60ebc8bf3cee02e75fd183babe4d68e010a4c410a360fd7&X-Goog-SignedHeaders=host&X-User=2931823730 (Caused by NewConnectionError('<urllib3.connection.HTTPSConnection object at 0x7fcdd01c2d70>: Failed to establish a new connection: [Errno 101] Network is unreachable'))
2025-04-11 13:36:03,747 ERROR   wandb-upload_1:5057 [internal_api.py:upload_file():2558] upload_file request headers: {'User-Agent': 'python-requests/2.32.3', 'Accept-Encoding': 'gzip, deflate, br', 'Accept': '*/*', 'Connection': 'keep-alive', 'Content-Length': '8685'}
2025-04-11 13:36:03,747 ERROR   wandb-upload_1:5057 [internal_api.py:upload_file():2560] upload_file response body: 
2025-04-11 13:36:03,940 ERROR   wandb-upload_2:5057 [internal_api.py:upload_file():2556] upload_file exception https://storage.googleapis.com/wandb-production.appspot.com/2931823730-harbin-institute-of-technology/ltu-as/ayrd945g/requirements.txt?X-Goog-Algorithm=GOOG4-RSA-SHA256&X-Goog-Credential=gorilla-files-url-signer-man%40wandb-production.iam.gserviceaccount.com%2F20250411%2Fauto%2Fstorage%2Fgoog4_request&X-Goog-Date=20250411T133547Z&X-Goog-Expires=86399&X-Goog-Signature=8f7985a4ebf492647396ccbeb8281c95f40ce48ca6ebfe7230b06e3e08a640b4892e9fbe8f14f084f14e5d3841d2ed4769d71f5dcc53a827130556bbab907612d4a6c07d1c4b3f38ce4fc656dabf01e58238b7603961296e52ef293121e1ab2eb7c0f40e653fe066ef2a8502bf31d63a12f60e5498b0ebdae66cee400aa1a42598345e000ebb6d22ea01ec55dcf62810cace5cacbb3cef4cc37ca34ae61cfaf15fa634731635ca6ad7b243b89a565ecd2dfae6fdcfdaf084938d1afa790a313af20f904fe253f7e9c5fbe3595321a68018379642acab4619f2715b3e42cea1e7f430dada2242a15e4fdaaa50c317aa219a978a754411899f051b8136a1fa5a4d&X-Goog-SignedHeaders=host&X-User=2931823730: HTTPSConnectionPool(host='storage.googleapis.com', port=443): Max retries exceeded with url: /wandb-production.appspot.com/2931823730-harbin-institute-of-technology/ltu-as/ayrd945g/requirements.txt?X-Goog-Algorithm=GOOG4-RSA-SHA256&X-Goog-Credential=gorilla-files-url-signer-man%40wandb-production.iam.gserviceaccount.com%2F20250411%2Fauto%2Fstorage%2Fgoog4_request&X-Goog-Date=20250411T133547Z&X-Goog-Expires=86399&X-Goog-Signature=8f7985a4ebf492647396ccbeb8281c95f40ce48ca6ebfe7230b06e3e08a640b4892e9fbe8f14f084f14e5d3841d2ed4769d71f5dcc53a827130556bbab907612d4a6c07d1c4b3f38ce4fc656dabf01e58238b7603961296e52ef293121e1ab2eb7c0f40e653fe066ef2a8502bf31d63a12f60e5498b0ebdae66cee400aa1a42598345e000ebb6d22ea01ec55dcf62810cace5cacbb3cef4cc37ca34ae61cfaf15fa634731635ca6ad7b243b89a565ecd2dfae6fdcfdaf084938d1afa790a313af20f904fe253f7e9c5fbe3595321a68018379642acab4619f2715b3e42cea1e7f430dada2242a15e4fdaaa50c317aa219a978a754411899f051b8136a1fa5a4d&X-Goog-SignedHeaders=host&X-User=2931823730 (Caused by NewConnectionError('<urllib3.connection.HTTPSConnection object at 0x7fcdd01c2ec0>: Failed to establish a new connection: [Errno 101] Network is unreachable'))
2025-04-11 13:36:03,941 ERROR   wandb-upload_2:5057 [internal_api.py:upload_file():2558] upload_file request headers: {'User-Agent': 'python-requests/2.32.3', 'Accept-Encoding': 'gzip, deflate, br', 'Accept': '*/*', 'Connection': 'keep-alive', 'Content-Length': '4212'}
2025-04-11 13:36:03,941 ERROR   wandb-upload_2:5057 [internal_api.py:upload_file():2560] upload_file response body: 
2025-04-11 13:36:04,110 ERROR   wandb-upload_4:5057 [internal_api.py:upload_file():2556] upload_file exception https://storage.googleapis.com/wandb-production.appspot.com/2931823730-harbin-institute-of-technology/ltu-as/ayrd945g/output.log?X-Goog-Algorithm=GOOG4-RSA-SHA256&X-Goog-Credential=gorilla-files-url-signer-man%40wandb-production.iam.gserviceaccount.com%2F20250411%2Fauto%2Fstorage%2Fgoog4_request&X-Goog-Date=20250411T133547Z&X-Goog-Expires=86399&X-Goog-Signature=60a14c64c75b7213832de3f51a8cee68b48766ce9fef4ac66308dcfbe021d98db23ab7a4e8e5a5840ad99fe69b3425e1ecaa5e7cecda0e89061d438052a78b725028def9cc631a332a1e2c99ebd6d1172adc8172fdae0d62bec226a3e99cdb144f8e7a221e0ec08c94a76dc888412fde2d9f87d0b484866e6db161d92750595d0c526c395230151ab2e6574b130439e80c58f6c8fb6187dfedd000237d5c6c32116bebe722b0f4815fa4b433c2c01eac2e6d1d439d109c547bd416ef777f07467da9090b12efc4e78dfb53e81482b7f08de5e21dbddcb7102335ee3f4fc94d9b946d104c6c430ee9e397a2c1ef3c9eaaae349d83697a271010de87b863593b32&X-Goog-SignedHeaders=host&X-User=2931823730: HTTPSConnectionPool(host='storage.googleapis.com', port=443): Max retries exceeded with url: /wandb-production.appspot.com/2931823730-harbin-institute-of-technology/ltu-as/ayrd945g/output.log?X-Goog-Algorithm=GOOG4-RSA-SHA256&X-Goog-Credential=gorilla-files-url-signer-man%40wandb-production.iam.gserviceaccount.com%2F20250411%2Fauto%2Fstorage%2Fgoog4_request&X-Goog-Date=20250411T133547Z&X-Goog-Expires=86399&X-Goog-Signature=60a14c64c75b7213832de3f51a8cee68b48766ce9fef4ac66308dcfbe021d98db23ab7a4e8e5a5840ad99fe69b3425e1ecaa5e7cecda0e89061d438052a78b725028def9cc631a332a1e2c99ebd6d1172adc8172fdae0d62bec226a3e99cdb144f8e7a221e0ec08c94a76dc888412fde2d9f87d0b484866e6db161d92750595d0c526c395230151ab2e6574b130439e80c58f6c8fb6187dfedd000237d5c6c32116bebe722b0f4815fa4b433c2c01eac2e6d1d439d109c547bd416ef777f07467da9090b12efc4e78dfb53e81482b7f08de5e21dbddcb7102335ee3f4fc94d9b946d104c6c430ee9e397a2c1ef3c9eaaae349d83697a271010de87b863593b32&X-Goog-SignedHeaders=host&X-User=2931823730 (Caused by NewConnectionError('<urllib3.connection.HTTPSConnection object at 0x7fcdd01c27d0>: Failed to establish a new connection: [Errno 101] Network is unreachable'))
2025-04-11 13:36:04,110 ERROR   wandb-upload_4:5057 [internal_api.py:upload_file():2558] upload_file request headers: {'User-Agent': 'python-requests/2.32.3', 'Accept-Encoding': 'gzip, deflate, br', 'Accept': '*/*', 'Connection': 'keep-alive', 'Content-Length': '5135'}
2025-04-11 13:36:04,110 ERROR   wandb-upload_4:5057 [internal_api.py:upload_file():2560] upload_file response body: 
2025-04-11 13:36:04,511 ERROR   wandb-upload_5:5057 [internal_api.py:upload_file():2556] upload_file exception https://storage.googleapis.com/wandb-production.appspot.com/2931823730-harbin-institute-of-technology/ltu-as/ayrd945g/wandb-summary.json?X-Goog-Algorithm=GOOG4-RSA-SHA256&X-Goog-Credential=gorilla-files-url-signer-man%40wandb-production.iam.gserviceaccount.com%2F20250411%2Fauto%2Fstorage%2Fgoog4_request&X-Goog-Date=20250411T133547Z&X-Goog-Expires=86399&X-Goog-Signature=88d8a33a4942edfdf46386d8d3684fa7b9d5a442bb037f8cda46c414fe422ca150fb4f2e5f776cc41bf710997e8d99494d56986c0251407a93dff567d301deee84d6a9d3c20c4876734beeebe93fc2170c90439950e62f7d895e7dfc8cff58ae05a6debe4386cf769ab635fbfecc6b9311f012934afbb8e9bfc6c652fb999d4b61c9c6dd3511d8a321c3bac43987e7d9891f0c31f9d35ca79f5a1ef87bcfa3ef26a7e363d6207536f2b71b07a4b55c4e341c9e6178a3a7bf0e2c835d2471597f60ccc6925d495148fc1623f5b3160f75ff84cd47fadcd8cd769536b21457ea5f60c8ba539b75f81d476509ef340009289b14c43e1a28cc2e27df0d6e9eb44275&X-Goog-SignedHeaders=host&X-User=2931823730: HTTPSConnectionPool(host='storage.googleapis.com', port=443): Max retries exceeded with url: /wandb-production.appspot.com/2931823730-harbin-institute-of-technology/ltu-as/ayrd945g/wandb-summary.json?X-Goog-Algorithm=GOOG4-RSA-SHA256&X-Goog-Credential=gorilla-files-url-signer-man%40wandb-production.iam.gserviceaccount.com%2F20250411%2Fauto%2Fstorage%2Fgoog4_request&X-Goog-Date=20250411T133547Z&X-Goog-Expires=86399&X-Goog-Signature=88d8a33a4942edfdf46386d8d3684fa7b9d5a442bb037f8cda46c414fe422ca150fb4f2e5f776cc41bf710997e8d99494d56986c0251407a93dff567d301deee84d6a9d3c20c4876734beeebe93fc2170c90439950e62f7d895e7dfc8cff58ae05a6debe4386cf769ab635fbfecc6b9311f012934afbb8e9bfc6c652fb999d4b61c9c6dd3511d8a321c3bac43987e7d9891f0c31f9d35ca79f5a1ef87bcfa3ef26a7e363d6207536f2b71b07a4b55c4e341c9e6178a3a7bf0e2c835d2471597f60ccc6925d495148fc1623f5b3160f75ff84cd47fadcd8cd769536b21457ea5f60c8ba539b75f81d476509ef340009289b14c43e1a28cc2e27df0d6e9eb44275&X-Goog-SignedHeaders=host&X-User=2931823730 (Caused by NewConnectionError('<urllib3.connection.HTTPSConnection object at 0x7fcdd01c2fb0>: Failed to establish a new connection: [Errno 101] Network is unreachable'))
2025-04-11 13:36:04,511 ERROR   wandb-upload_5:5057 [internal_api.py:upload_file():2558] upload_file request headers: {'User-Agent': 'python-requests/2.32.3', 'Accept-Encoding': 'gzip, deflate, br', 'Accept': '*/*', 'Connection': 'keep-alive', 'Content-Length': '27'}
2025-04-11 13:36:04,511 ERROR   wandb-upload_5:5057 [internal_api.py:upload_file():2560] upload_file response body: 
2025-04-11 13:36:04,573 ERROR   wandb-upload_3:5057 [internal_api.py:upload_file():2556] upload_file exception https://storage.googleapis.com/wandb-production.appspot.com/2931823730-harbin-institute-of-technology/ltu-as/ayrd945g/conda-environment.yaml?X-Goog-Algorithm=GOOG4-RSA-SHA256&X-Goog-Credential=gorilla-files-url-signer-man%40wandb-production.iam.gserviceaccount.com%2F20250411%2Fauto%2Fstorage%2Fgoog4_request&X-Goog-Date=20250411T133547Z&X-Goog-Expires=86399&X-Goog-Signature=4c9126604080912880ede91838f5a7390665008083d7e44309734daddd80b9cf8cf7a4c5c6fa5de745ba75d664cb7469ed45bccd6a8d0f8328f5b819c87f52209a817e2cecb6b43dd002266b64a58a46125cf94eecc520b1b7a33aba86a8651778a4fc020b1e58b91094758a9f0bdf70c1b1709c39a4aa8e5b9998524293e3f95252e6a81cbabe349b8e96481c3fdb99ef3ed87c033bd482bc27e2900be02b6f7a10cc37e178de535da73792986f0057d36c512c3142823ec07dde39234d436ecef04f3b634ff435b7df21a6d1fbd1b616a7aafd7a5bc2d0a15eacb48d1f828c4e7e505ad7f7585a5624f5d9716d95b4b15bdc9c2151e47d7698d62f76621622&X-Goog-SignedHeaders=host&X-User=2931823730: HTTPSConnectionPool(host='storage.googleapis.com', port=443): Max retries exceeded with url: /wandb-production.appspot.com/2931823730-harbin-institute-of-technology/ltu-as/ayrd945g/conda-environment.yaml?X-Goog-Algorithm=GOOG4-RSA-SHA256&X-Goog-Credential=gorilla-files-url-signer-man%40wandb-production.iam.gserviceaccount.com%2F20250411%2Fauto%2Fstorage%2Fgoog4_request&X-Goog-Date=20250411T133547Z&X-Goog-Expires=86399&X-Goog-Signature=4c9126604080912880ede91838f5a7390665008083d7e44309734daddd80b9cf8cf7a4c5c6fa5de745ba75d664cb7469ed45bccd6a8d0f8328f5b819c87f52209a817e2cecb6b43dd002266b64a58a46125cf94eecc520b1b7a33aba86a8651778a4fc020b1e58b91094758a9f0bdf70c1b1709c39a4aa8e5b9998524293e3f95252e6a81cbabe349b8e96481c3fdb99ef3ed87c033bd482bc27e2900be02b6f7a10cc37e178de535da73792986f0057d36c512c3142823ec07dde39234d436ecef04f3b634ff435b7df21a6d1fbd1b616a7aafd7a5bc2d0a15eacb48d1f828c4e7e505ad7f7585a5624f5d9716d95b4b15bdc9c2151e47d7698d62f76621622&X-Goog-SignedHeaders=host&X-User=2931823730 (Caused by NewConnectionError('<urllib3.connection.HTTPSConnection object at 0x7fcdd01c1e70>: Failed to establish a new connection: [Errno 101] Network is unreachable'))
2025-04-11 13:36:04,573 ERROR   wandb-upload_3:5057 [internal_api.py:upload_file():2558] upload_file request headers: {'User-Agent': 'python-requests/2.32.3', 'Accept-Encoding': 'gzip, deflate, br', 'Accept': '*/*', 'Connection': 'keep-alive', 'Content-Length': '8281'}
2025-04-11 13:36:04,573 ERROR   wandb-upload_3:5057 [internal_api.py:upload_file():2560] upload_file response body: 
2025-04-11 13:36:04,872 ERROR   wandb-upload_0:5057 [internal_api.py:upload_file():2556] upload_file exception https://storage.googleapis.com/wandb-production.appspot.com/2931823730-harbin-institute-of-technology/ltu-as/ayrd945g/wandb-metadata.json?X-Goog-Algorithm=GOOG4-RSA-SHA256&X-Goog-Credential=gorilla-files-url-signer-man%40wandb-production.iam.gserviceaccount.com%2F20250411%2Fauto%2Fstorage%2Fgoog4_request&X-Goog-Date=20250411T133531Z&X-Goog-Expires=86399&X-Goog-Signature=3f5aee34cfa797b7aa73f667422a4aee946d1072dcec6b4021fa16645cebbf9a6738f93929154478c65a583fe2e5451e23e58739b96fa5355a823d0848191cccf627be8a9b51eee5861c7ed65eeead014bbceb2dcaeeef78dcdb79f5d1c045f21707476081794fb0708d6ec543c2f328439ef45907a15b52a6f64bbdbbf40ac08a2e90802e63ba340ae771978232c617a39b97d3caff9929e0c70b5a278c509f73435a1bac9fdee8a302d4e14c9e0a1f951e09f2537482c5c835c4eeb93f0efc7b988c8cfecc28c793061d2726f554ddc64313056228b705299a06a992a33bc9e5d77e2dd03adbb5b76f7b20314f6bb3c131cf504b3a39390ed6e8b4e6d7ba46&X-Goog-SignedHeaders=host&X-User=2931823730: HTTPSConnectionPool(host='storage.googleapis.com', port=443): Max retries exceeded with url: /wandb-production.appspot.com/2931823730-harbin-institute-of-technology/ltu-as/ayrd945g/wandb-metadata.json?X-Goog-Algorithm=GOOG4-RSA-SHA256&X-Goog-Credential=gorilla-files-url-signer-man%40wandb-production.iam.gserviceaccount.com%2F20250411%2Fauto%2Fstorage%2Fgoog4_request&X-Goog-Date=20250411T133531Z&X-Goog-Expires=86399&X-Goog-Signature=3f5aee34cfa797b7aa73f667422a4aee946d1072dcec6b4021fa16645cebbf9a6738f93929154478c65a583fe2e5451e23e58739b96fa5355a823d0848191cccf627be8a9b51eee5861c7ed65eeead014bbceb2dcaeeef78dcdb79f5d1c045f21707476081794fb0708d6ec543c2f328439ef45907a15b52a6f64bbdbbf40ac08a2e90802e63ba340ae771978232c617a39b97d3caff9929e0c70b5a278c509f73435a1bac9fdee8a302d4e14c9e0a1f951e09f2537482c5c835c4eeb93f0efc7b988c8cfecc28c793061d2726f554ddc64313056228b705299a06a992a33bc9e5d77e2dd03adbb5b76f7b20314f6bb3c131cf504b3a39390ed6e8b4e6d7ba46&X-Goog-SignedHeaders=host&X-User=2931823730 (Caused by NewConnectionError('<urllib3.connection.HTTPSConnection object at 0x7fcd927aa0e0>: Failed to establish a new connection: [Errno 101] Network is unreachable'))
2025-04-11 13:36:04,872 ERROR   wandb-upload_0:5057 [internal_api.py:upload_file():2558] upload_file request headers: {'User-Agent': 'python-requests/2.32.3', 'Accept-Encoding': 'gzip, deflate, br', 'Accept': '*/*', 'Connection': 'keep-alive', 'Content-Length': '2259'}
2025-04-11 13:36:04,872 ERROR   wandb-upload_0:5057 [internal_api.py:upload_file():2560] upload_file response body: 
2025-04-11 13:36:05,976 DEBUG   HandlerThread:5057 [handler.py:handle_request():146] handle_request: keepalive
2025-04-11 13:36:08,403 DEBUG   HandlerThread:5057 [handler.py:handle_request():146] handle_request: status_report
2025-04-11 13:36:10,978 DEBUG   HandlerThread:5057 [handler.py:handle_request():146] handle_request: keepalive
2025-04-11 13:36:13,404 DEBUG   HandlerThread:5057 [handler.py:handle_request():146] handle_request: status_report
2025-04-11 13:36:15,980 DEBUG   HandlerThread:5057 [handler.py:handle_request():146] handle_request: keepalive
2025-04-11 13:36:18,405 DEBUG   HandlerThread:5057 [handler.py:handle_request():146] handle_request: status_report
2025-04-11 13:36:20,983 DEBUG   HandlerThread:5057 [handler.py:handle_request():146] handle_request: keepalive
2025-04-11 13:36:21,113 ERROR   wandb-upload_3:5057 [internal_api.py:upload_file():2556] upload_file exception https://storage.googleapis.com/wandb-production.appspot.com/2931823730-harbin-institute-of-technology/ltu-as/ayrd945g/conda-environment.yaml?X-Goog-Algorithm=GOOG4-RSA-SHA256&X-Goog-Credential=gorilla-files-url-signer-man%40wandb-production.iam.gserviceaccount.com%2F20250411%2Fauto%2Fstorage%2Fgoog4_request&X-Goog-Date=20250411T133547Z&X-Goog-Expires=86399&X-Goog-Signature=4c9126604080912880ede91838f5a7390665008083d7e44309734daddd80b9cf8cf7a4c5c6fa5de745ba75d664cb7469ed45bccd6a8d0f8328f5b819c87f52209a817e2cecb6b43dd002266b64a58a46125cf94eecc520b1b7a33aba86a8651778a4fc020b1e58b91094758a9f0bdf70c1b1709c39a4aa8e5b9998524293e3f95252e6a81cbabe349b8e96481c3fdb99ef3ed87c033bd482bc27e2900be02b6f7a10cc37e178de535da73792986f0057d36c512c3142823ec07dde39234d436ecef04f3b634ff435b7df21a6d1fbd1b616a7aafd7a5bc2d0a15eacb48d1f828c4e7e505ad7f7585a5624f5d9716d95b4b15bdc9c2151e47d7698d62f76621622&X-Goog-SignedHeaders=host&X-User=2931823730: HTTPSConnectionPool(host='storage.googleapis.com', port=443): Max retries exceeded with url: /wandb-production.appspot.com/2931823730-harbin-institute-of-technology/ltu-as/ayrd945g/conda-environment.yaml?X-Goog-Algorithm=GOOG4-RSA-SHA256&X-Goog-Credential=gorilla-files-url-signer-man%40wandb-production.iam.gserviceaccount.com%2F20250411%2Fauto%2Fstorage%2Fgoog4_request&X-Goog-Date=20250411T133547Z&X-Goog-Expires=86399&X-Goog-Signature=4c9126604080912880ede91838f5a7390665008083d7e44309734daddd80b9cf8cf7a4c5c6fa5de745ba75d664cb7469ed45bccd6a8d0f8328f5b819c87f52209a817e2cecb6b43dd002266b64a58a46125cf94eecc520b1b7a33aba86a8651778a4fc020b1e58b91094758a9f0bdf70c1b1709c39a4aa8e5b9998524293e3f95252e6a81cbabe349b8e96481c3fdb99ef3ed87c033bd482bc27e2900be02b6f7a10cc37e178de535da73792986f0057d36c512c3142823ec07dde39234d436ecef04f3b634ff435b7df21a6d1fbd1b616a7aafd7a5bc2d0a15eacb48d1f828c4e7e505ad7f7585a5624f5d9716d95b4b15bdc9c2151e47d7698d62f76621622&X-Goog-SignedHeaders=host&X-User=2931823730 (Caused by NewConnectionError('<urllib3.connection.HTTPSConnection object at 0x7fcd927aba60>: Failed to establish a new connection: [Errno 101] Network is unreachable'))
2025-04-11 13:36:21,113 ERROR   wandb-upload_3:5057 [internal_api.py:upload_file():2558] upload_file request headers: {'User-Agent': 'python-requests/2.32.3', 'Accept-Encoding': 'gzip, deflate, br', 'Accept': '*/*', 'Connection': 'keep-alive', 'Content-Length': '8281'}
2025-04-11 13:36:21,113 ERROR   wandb-upload_3:5057 [internal_api.py:upload_file():2560] upload_file response body: 
2025-04-11 13:36:21,291 ERROR   wandb-upload_5:5057 [internal_api.py:upload_file():2556] upload_file exception https://storage.googleapis.com/wandb-production.appspot.com/2931823730-harbin-institute-of-technology/ltu-as/ayrd945g/wandb-summary.json?X-Goog-Algorithm=GOOG4-RSA-SHA256&X-Goog-Credential=gorilla-files-url-signer-man%40wandb-production.iam.gserviceaccount.com%2F20250411%2Fauto%2Fstorage%2Fgoog4_request&X-Goog-Date=20250411T133547Z&X-Goog-Expires=86399&X-Goog-Signature=88d8a33a4942edfdf46386d8d3684fa7b9d5a442bb037f8cda46c414fe422ca150fb4f2e5f776cc41bf710997e8d99494d56986c0251407a93dff567d301deee84d6a9d3c20c4876734beeebe93fc2170c90439950e62f7d895e7dfc8cff58ae05a6debe4386cf769ab635fbfecc6b9311f012934afbb8e9bfc6c652fb999d4b61c9c6dd3511d8a321c3bac43987e7d9891f0c31f9d35ca79f5a1ef87bcfa3ef26a7e363d6207536f2b71b07a4b55c4e341c9e6178a3a7bf0e2c835d2471597f60ccc6925d495148fc1623f5b3160f75ff84cd47fadcd8cd769536b21457ea5f60c8ba539b75f81d476509ef340009289b14c43e1a28cc2e27df0d6e9eb44275&X-Goog-SignedHeaders=host&X-User=2931823730: HTTPSConnectionPool(host='storage.googleapis.com', port=443): Max retries exceeded with url: /wandb-production.appspot.com/2931823730-harbin-institute-of-technology/ltu-as/ayrd945g/wandb-summary.json?X-Goog-Algorithm=GOOG4-RSA-SHA256&X-Goog-Credential=gorilla-files-url-signer-man%40wandb-production.iam.gserviceaccount.com%2F20250411%2Fauto%2Fstorage%2Fgoog4_request&X-Goog-Date=20250411T133547Z&X-Goog-Expires=86399&X-Goog-Signature=88d8a33a4942edfdf46386d8d3684fa7b9d5a442bb037f8cda46c414fe422ca150fb4f2e5f776cc41bf710997e8d99494d56986c0251407a93dff567d301deee84d6a9d3c20c4876734beeebe93fc2170c90439950e62f7d895e7dfc8cff58ae05a6debe4386cf769ab635fbfecc6b9311f012934afbb8e9bfc6c652fb999d4b61c9c6dd3511d8a321c3bac43987e7d9891f0c31f9d35ca79f5a1ef87bcfa3ef26a7e363d6207536f2b71b07a4b55c4e341c9e6178a3a7bf0e2c835d2471597f60ccc6925d495148fc1623f5b3160f75ff84cd47fadcd8cd769536b21457ea5f60c8ba539b75f81d476509ef340009289b14c43e1a28cc2e27df0d6e9eb44275&X-Goog-SignedHeaders=host&X-User=2931823730 (Caused by NewConnectionError('<urllib3.connection.HTTPSConnection object at 0x7fcd927a9480>: Failed to establish a new connection: [Errno 101] Network is unreachable'))
2025-04-11 13:36:21,291 ERROR   wandb-upload_5:5057 [internal_api.py:upload_file():2558] upload_file request headers: {'User-Agent': 'python-requests/2.32.3', 'Accept-Encoding': 'gzip, deflate, br', 'Accept': '*/*', 'Connection': 'keep-alive', 'Content-Length': '27'}
2025-04-11 13:36:21,291 ERROR   wandb-upload_5:5057 [internal_api.py:upload_file():2560] upload_file response body: 
2025-04-11 13:36:22,279 ERROR   wandb-upload_4:5057 [internal_api.py:upload_file():2556] upload_file exception https://storage.googleapis.com/wandb-production.appspot.com/2931823730-harbin-institute-of-technology/ltu-as/ayrd945g/output.log?X-Goog-Algorithm=GOOG4-RSA-SHA256&X-Goog-Credential=gorilla-files-url-signer-man%40wandb-production.iam.gserviceaccount.com%2F20250411%2Fauto%2Fstorage%2Fgoog4_request&X-Goog-Date=20250411T133547Z&X-Goog-Expires=86399&X-Goog-Signature=60a14c64c75b7213832de3f51a8cee68b48766ce9fef4ac66308dcfbe021d98db23ab7a4e8e5a5840ad99fe69b3425e1ecaa5e7cecda0e89061d438052a78b725028def9cc631a332a1e2c99ebd6d1172adc8172fdae0d62bec226a3e99cdb144f8e7a221e0ec08c94a76dc888412fde2d9f87d0b484866e6db161d92750595d0c526c395230151ab2e6574b130439e80c58f6c8fb6187dfedd000237d5c6c32116bebe722b0f4815fa4b433c2c01eac2e6d1d439d109c547bd416ef777f07467da9090b12efc4e78dfb53e81482b7f08de5e21dbddcb7102335ee3f4fc94d9b946d104c6c430ee9e397a2c1ef3c9eaaae349d83697a271010de87b863593b32&X-Goog-SignedHeaders=host&X-User=2931823730: HTTPSConnectionPool(host='storage.googleapis.com', port=443): Max retries exceeded with url: /wandb-production.appspot.com/2931823730-harbin-institute-of-technology/ltu-as/ayrd945g/output.log?X-Goog-Algorithm=GOOG4-RSA-SHA256&X-Goog-Credential=gorilla-files-url-signer-man%40wandb-production.iam.gserviceaccount.com%2F20250411%2Fauto%2Fstorage%2Fgoog4_request&X-Goog-Date=20250411T133547Z&X-Goog-Expires=86399&X-Goog-Signature=60a14c64c75b7213832de3f51a8cee68b48766ce9fef4ac66308dcfbe021d98db23ab7a4e8e5a5840ad99fe69b3425e1ecaa5e7cecda0e89061d438052a78b725028def9cc631a332a1e2c99ebd6d1172adc8172fdae0d62bec226a3e99cdb144f8e7a221e0ec08c94a76dc888412fde2d9f87d0b484866e6db161d92750595d0c526c395230151ab2e6574b130439e80c58f6c8fb6187dfedd000237d5c6c32116bebe722b0f4815fa4b433c2c01eac2e6d1d439d109c547bd416ef777f07467da9090b12efc4e78dfb53e81482b7f08de5e21dbddcb7102335ee3f4fc94d9b946d104c6c430ee9e397a2c1ef3c9eaaae349d83697a271010de87b863593b32&X-Goog-SignedHeaders=host&X-User=2931823730 (Caused by NewConnectionError('<urllib3.connection.HTTPSConnection object at 0x7fcd927a90c0>: Failed to establish a new connection: [Errno 101] Network is unreachable'))
2025-04-11 13:36:22,279 ERROR   wandb-upload_4:5057 [internal_api.py:upload_file():2558] upload_file request headers: {'User-Agent': 'python-requests/2.32.3', 'Accept-Encoding': 'gzip, deflate, br', 'Accept': '*/*', 'Connection': 'keep-alive', 'Content-Length': '5135'}
2025-04-11 13:36:22,279 ERROR   wandb-upload_4:5057 [internal_api.py:upload_file():2560] upload_file response body: 
2025-04-11 13:36:22,820 ERROR   wandb-upload_1:5057 [internal_api.py:upload_file():2556] upload_file exception https://storage.googleapis.com/wandb-production.appspot.com/2931823730-harbin-institute-of-technology/ltu-as/ayrd945g/config.yaml?X-Goog-Algorithm=GOOG4-RSA-SHA256&X-Goog-Credential=gorilla-files-url-signer-man%40wandb-production.iam.gserviceaccount.com%2F20250411%2Fauto%2Fstorage%2Fgoog4_request&X-Goog-Date=20250411T133547Z&X-Goog-Expires=86399&X-Goog-Signature=59229da32108dabf2e0b22f3378d7c4eff52c92055ad5d5b992f76e4df1c8015b756cf03412a752e587a2ea6bc2f30001b205d9ef095c5a14ab645fe71a22b821da600c1196db4191aef6cd423a67f5cfc13d398e023ee472db63d91e6f84db94368a9e61522d891c6c41b7eeb918e96b41062c0135485092d85801d941c7eb761567114df29f3b71030380dfe24d3e94c0e9810f87f3eb1f65bf4625252ec95591d290b470be81abb48ba16966c05db2893b493bab6f93bdd5325ee55c3ce817c57cadd71e627b02871d0c646f4dba235a7310afdefe60e03add6e16f1ebcee16c2bf969543124fb60ebc8bf3cee02e75fd183babe4d68e010a4c410a360fd7&X-Goog-SignedHeaders=host&X-User=2931823730: HTTPSConnectionPool(host='storage.googleapis.com', port=443): Max retries exceeded with url: /wandb-production.appspot.com/2931823730-harbin-institute-of-technology/ltu-as/ayrd945g/config.yaml?X-Goog-Algorithm=GOOG4-RSA-SHA256&X-Goog-Credential=gorilla-files-url-signer-man%40wandb-production.iam.gserviceaccount.com%2F20250411%2Fauto%2Fstorage%2Fgoog4_request&X-Goog-Date=20250411T133547Z&X-Goog-Expires=86399&X-Goog-Signature=59229da32108dabf2e0b22f3378d7c4eff52c92055ad5d5b992f76e4df1c8015b756cf03412a752e587a2ea6bc2f30001b205d9ef095c5a14ab645fe71a22b821da600c1196db4191aef6cd423a67f5cfc13d398e023ee472db63d91e6f84db94368a9e61522d891c6c41b7eeb918e96b41062c0135485092d85801d941c7eb761567114df29f3b71030380dfe24d3e94c0e9810f87f3eb1f65bf4625252ec95591d290b470be81abb48ba16966c05db2893b493bab6f93bdd5325ee55c3ce817c57cadd71e627b02871d0c646f4dba235a7310afdefe60e03add6e16f1ebcee16c2bf969543124fb60ebc8bf3cee02e75fd183babe4d68e010a4c410a360fd7&X-Goog-SignedHeaders=host&X-User=2931823730 (Caused by NewConnectionError('<urllib3.connection.HTTPSConnection object at 0x7fcd927aaad0>: Failed to establish a new connection: [Errno 101] Network is unreachable'))
2025-04-11 13:36:22,820 ERROR   wandb-upload_1:5057 [internal_api.py:upload_file():2558] upload_file request headers: {'User-Agent': 'python-requests/2.32.3', 'Accept-Encoding': 'gzip, deflate, br', 'Accept': '*/*', 'Connection': 'keep-alive', 'Content-Length': '8685'}
2025-04-11 13:36:22,820 ERROR   wandb-upload_1:5057 [internal_api.py:upload_file():2560] upload_file response body: 
2025-04-11 13:36:23,406 DEBUG   HandlerThread:5057 [handler.py:handle_request():146] handle_request: status_report
2025-04-11 13:36:23,925 ERROR   wandb-upload_2:5057 [internal_api.py:upload_file():2556] upload_file exception https://storage.googleapis.com/wandb-production.appspot.com/2931823730-harbin-institute-of-technology/ltu-as/ayrd945g/requirements.txt?X-Goog-Algorithm=GOOG4-RSA-SHA256&X-Goog-Credential=gorilla-files-url-signer-man%40wandb-production.iam.gserviceaccount.com%2F20250411%2Fauto%2Fstorage%2Fgoog4_request&X-Goog-Date=20250411T133547Z&X-Goog-Expires=86399&X-Goog-Signature=8f7985a4ebf492647396ccbeb8281c95f40ce48ca6ebfe7230b06e3e08a640b4892e9fbe8f14f084f14e5d3841d2ed4769d71f5dcc53a827130556bbab907612d4a6c07d1c4b3f38ce4fc656dabf01e58238b7603961296e52ef293121e1ab2eb7c0f40e653fe066ef2a8502bf31d63a12f60e5498b0ebdae66cee400aa1a42598345e000ebb6d22ea01ec55dcf62810cace5cacbb3cef4cc37ca34ae61cfaf15fa634731635ca6ad7b243b89a565ecd2dfae6fdcfdaf084938d1afa790a313af20f904fe253f7e9c5fbe3595321a68018379642acab4619f2715b3e42cea1e7f430dada2242a15e4fdaaa50c317aa219a978a754411899f051b8136a1fa5a4d&X-Goog-SignedHeaders=host&X-User=2931823730: HTTPSConnectionPool(host='storage.googleapis.com', port=443): Max retries exceeded with url: /wandb-production.appspot.com/2931823730-harbin-institute-of-technology/ltu-as/ayrd945g/requirements.txt?X-Goog-Algorithm=GOOG4-RSA-SHA256&X-Goog-Credential=gorilla-files-url-signer-man%40wandb-production.iam.gserviceaccount.com%2F20250411%2Fauto%2Fstorage%2Fgoog4_request&X-Goog-Date=20250411T133547Z&X-Goog-Expires=86399&X-Goog-Signature=8f7985a4ebf492647396ccbeb8281c95f40ce48ca6ebfe7230b06e3e08a640b4892e9fbe8f14f084f14e5d3841d2ed4769d71f5dcc53a827130556bbab907612d4a6c07d1c4b3f38ce4fc656dabf01e58238b7603961296e52ef293121e1ab2eb7c0f40e653fe066ef2a8502bf31d63a12f60e5498b0ebdae66cee400aa1a42598345e000ebb6d22ea01ec55dcf62810cace5cacbb3cef4cc37ca34ae61cfaf15fa634731635ca6ad7b243b89a565ecd2dfae6fdcfdaf084938d1afa790a313af20f904fe253f7e9c5fbe3595321a68018379642acab4619f2715b3e42cea1e7f430dada2242a15e4fdaaa50c317aa219a978a754411899f051b8136a1fa5a4d&X-Goog-SignedHeaders=host&X-User=2931823730 (Caused by NewConnectionError('<urllib3.connection.HTTPSConnection object at 0x7fcdd01c2860>: Failed to establish a new connection: [Errno 101] Network is unreachable'))
2025-04-11 13:36:23,925 ERROR   wandb-upload_2:5057 [internal_api.py:upload_file():2558] upload_file request headers: {'User-Agent': 'python-requests/2.32.3', 'Accept-Encoding': 'gzip, deflate, br', 'Accept': '*/*', 'Connection': 'keep-alive', 'Content-Length': '4212'}
2025-04-11 13:36:23,925 ERROR   wandb-upload_2:5057 [internal_api.py:upload_file():2560] upload_file response body: 
2025-04-11 13:36:25,985 DEBUG   HandlerThread:5057 [handler.py:handle_request():146] handle_request: keepalive
2025-04-11 13:36:28,407 DEBUG   HandlerThread:5057 [handler.py:handle_request():146] handle_request: status_report
2025-04-11 13:36:30,987 DEBUG   HandlerThread:5057 [handler.py:handle_request():146] handle_request: keepalive
2025-04-11 13:36:33,408 DEBUG   HandlerThread:5057 [handler.py:handle_request():146] handle_request: status_report
2025-04-11 13:36:35,989 DEBUG   HandlerThread:5057 [handler.py:handle_request():146] handle_request: keepalive
2025-04-11 13:36:38,409 DEBUG   HandlerThread:5057 [handler.py:handle_request():146] handle_request: status_report
2025-04-11 13:36:40,992 DEBUG   HandlerThread:5057 [handler.py:handle_request():146] handle_request: keepalive
2025-04-11 13:36:41,533 ERROR   wandb-upload_0:5057 [internal_api.py:upload_file():2556] upload_file exception https://storage.googleapis.com/wandb-production.appspot.com/2931823730-harbin-institute-of-technology/ltu-as/ayrd945g/wandb-metadata.json?X-Goog-Algorithm=GOOG4-RSA-SHA256&X-Goog-Credential=gorilla-files-url-signer-man%40wandb-production.iam.gserviceaccount.com%2F20250411%2Fauto%2Fstorage%2Fgoog4_request&X-Goog-Date=20250411T133531Z&X-Goog-Expires=86399&X-Goog-Signature=3f5aee34cfa797b7aa73f667422a4aee946d1072dcec6b4021fa16645cebbf9a6738f93929154478c65a583fe2e5451e23e58739b96fa5355a823d0848191cccf627be8a9b51eee5861c7ed65eeead014bbceb2dcaeeef78dcdb79f5d1c045f21707476081794fb0708d6ec543c2f328439ef45907a15b52a6f64bbdbbf40ac08a2e90802e63ba340ae771978232c617a39b97d3caff9929e0c70b5a278c509f73435a1bac9fdee8a302d4e14c9e0a1f951e09f2537482c5c835c4eeb93f0efc7b988c8cfecc28c793061d2726f554ddc64313056228b705299a06a992a33bc9e5d77e2dd03adbb5b76f7b20314f6bb3c131cf504b3a39390ed6e8b4e6d7ba46&X-Goog-SignedHeaders=host&X-User=2931823730: HTTPSConnectionPool(host='storage.googleapis.com', port=443): Max retries exceeded with url: /wandb-production.appspot.com/2931823730-harbin-institute-of-technology/ltu-as/ayrd945g/wandb-metadata.json?X-Goog-Algorithm=GOOG4-RSA-SHA256&X-Goog-Credential=gorilla-files-url-signer-man%40wandb-production.iam.gserviceaccount.com%2F20250411%2Fauto%2Fstorage%2Fgoog4_request&X-Goog-Date=20250411T133531Z&X-Goog-Expires=86399&X-Goog-Signature=3f5aee34cfa797b7aa73f667422a4aee946d1072dcec6b4021fa16645cebbf9a6738f93929154478c65a583fe2e5451e23e58739b96fa5355a823d0848191cccf627be8a9b51eee5861c7ed65eeead014bbceb2dcaeeef78dcdb79f5d1c045f21707476081794fb0708d6ec543c2f328439ef45907a15b52a6f64bbdbbf40ac08a2e90802e63ba340ae771978232c617a39b97d3caff9929e0c70b5a278c509f73435a1bac9fdee8a302d4e14c9e0a1f951e09f2537482c5c835c4eeb93f0efc7b988c8cfecc28c793061d2726f554ddc64313056228b705299a06a992a33bc9e5d77e2dd03adbb5b76f7b20314f6bb3c131cf504b3a39390ed6e8b4e6d7ba46&X-Goog-SignedHeaders=host&X-User=2931823730 (Caused by NewConnectionError('<urllib3.connection.HTTPSConnection object at 0x7fcdd01c3280>: Failed to establish a new connection: [Errno 101] Network is unreachable'))
2025-04-11 13:36:41,533 ERROR   wandb-upload_0:5057 [internal_api.py:upload_file():2558] upload_file request headers: {'User-Agent': 'python-requests/2.32.3', 'Accept-Encoding': 'gzip, deflate, br', 'Accept': '*/*', 'Connection': 'keep-alive', 'Content-Length': '2259'}
2025-04-11 13:36:41,533 ERROR   wandb-upload_0:5057 [internal_api.py:upload_file():2560] upload_file response body: 
2025-04-11 13:36:43,410 DEBUG   HandlerThread:5057 [handler.py:handle_request():146] handle_request: status_report
2025-04-11 13:36:45,993 DEBUG   HandlerThread:5057 [handler.py:handle_request():146] handle_request: keepalive
2025-04-11 13:36:48,412 DEBUG   HandlerThread:5057 [handler.py:handle_request():146] handle_request: status_report
2025-04-11 13:36:50,996 DEBUG   HandlerThread:5057 [handler.py:handle_request():146] handle_request: keepalive
2025-04-11 13:36:53,413 DEBUG   HandlerThread:5057 [handler.py:handle_request():146] handle_request: status_report
2025-04-11 13:36:54,052 ERROR   wandb-upload_3:5057 [internal_api.py:upload_file():2556] upload_file exception https://storage.googleapis.com/wandb-production.appspot.com/2931823730-harbin-institute-of-technology/ltu-as/ayrd945g/conda-environment.yaml?X-Goog-Algorithm=GOOG4-RSA-SHA256&X-Goog-Credential=gorilla-files-url-signer-man%40wandb-production.iam.gserviceaccount.com%2F20250411%2Fauto%2Fstorage%2Fgoog4_request&X-Goog-Date=20250411T133547Z&X-Goog-Expires=86399&X-Goog-Signature=4c9126604080912880ede91838f5a7390665008083d7e44309734daddd80b9cf8cf7a4c5c6fa5de745ba75d664cb7469ed45bccd6a8d0f8328f5b819c87f52209a817e2cecb6b43dd002266b64a58a46125cf94eecc520b1b7a33aba86a8651778a4fc020b1e58b91094758a9f0bdf70c1b1709c39a4aa8e5b9998524293e3f95252e6a81cbabe349b8e96481c3fdb99ef3ed87c033bd482bc27e2900be02b6f7a10cc37e178de535da73792986f0057d36c512c3142823ec07dde39234d436ecef04f3b634ff435b7df21a6d1fbd1b616a7aafd7a5bc2d0a15eacb48d1f828c4e7e505ad7f7585a5624f5d9716d95b4b15bdc9c2151e47d7698d62f76621622&X-Goog-SignedHeaders=host&X-User=2931823730: HTTPSConnectionPool(host='storage.googleapis.com', port=443): Max retries exceeded with url: /wandb-production.appspot.com/2931823730-harbin-institute-of-technology/ltu-as/ayrd945g/conda-environment.yaml?X-Goog-Algorithm=GOOG4-RSA-SHA256&X-Goog-Credential=gorilla-files-url-signer-man%40wandb-production.iam.gserviceaccount.com%2F20250411%2Fauto%2Fstorage%2Fgoog4_request&X-Goog-Date=20250411T133547Z&X-Goog-Expires=86399&X-Goog-Signature=4c9126604080912880ede91838f5a7390665008083d7e44309734daddd80b9cf8cf7a4c5c6fa5de745ba75d664cb7469ed45bccd6a8d0f8328f5b819c87f52209a817e2cecb6b43dd002266b64a58a46125cf94eecc520b1b7a33aba86a8651778a4fc020b1e58b91094758a9f0bdf70c1b1709c39a4aa8e5b9998524293e3f95252e6a81cbabe349b8e96481c3fdb99ef3ed87c033bd482bc27e2900be02b6f7a10cc37e178de535da73792986f0057d36c512c3142823ec07dde39234d436ecef04f3b634ff435b7df21a6d1fbd1b616a7aafd7a5bc2d0a15eacb48d1f828c4e7e505ad7f7585a5624f5d9716d95b4b15bdc9c2151e47d7698d62f76621622&X-Goog-SignedHeaders=host&X-User=2931823730 (Caused by NewConnectionError('<urllib3.connection.HTTPSConnection object at 0x7fcdd01c1330>: Failed to establish a new connection: [Errno 101] Network is unreachable'))
2025-04-11 13:36:54,053 ERROR   wandb-upload_3:5057 [internal_api.py:upload_file():2558] upload_file request headers: {'User-Agent': 'python-requests/2.32.3', 'Accept-Encoding': 'gzip, deflate, br', 'Accept': '*/*', 'Connection': 'keep-alive', 'Content-Length': '8281'}
2025-04-11 13:36:54,053 ERROR   wandb-upload_3:5057 [internal_api.py:upload_file():2560] upload_file response body: 
2025-04-11 13:36:55,188 ERROR   wandb-upload_1:5057 [internal_api.py:upload_file():2556] upload_file exception https://storage.googleapis.com/wandb-production.appspot.com/2931823730-harbin-institute-of-technology/ltu-as/ayrd945g/config.yaml?X-Goog-Algorithm=GOOG4-RSA-SHA256&X-Goog-Credential=gorilla-files-url-signer-man%40wandb-production.iam.gserviceaccount.com%2F20250411%2Fauto%2Fstorage%2Fgoog4_request&X-Goog-Date=20250411T133547Z&X-Goog-Expires=86399&X-Goog-Signature=59229da32108dabf2e0b22f3378d7c4eff52c92055ad5d5b992f76e4df1c8015b756cf03412a752e587a2ea6bc2f30001b205d9ef095c5a14ab645fe71a22b821da600c1196db4191aef6cd423a67f5cfc13d398e023ee472db63d91e6f84db94368a9e61522d891c6c41b7eeb918e96b41062c0135485092d85801d941c7eb761567114df29f3b71030380dfe24d3e94c0e9810f87f3eb1f65bf4625252ec95591d290b470be81abb48ba16966c05db2893b493bab6f93bdd5325ee55c3ce817c57cadd71e627b02871d0c646f4dba235a7310afdefe60e03add6e16f1ebcee16c2bf969543124fb60ebc8bf3cee02e75fd183babe4d68e010a4c410a360fd7&X-Goog-SignedHeaders=host&X-User=2931823730: HTTPSConnectionPool(host='storage.googleapis.com', port=443): Max retries exceeded with url: /wandb-production.appspot.com/2931823730-harbin-institute-of-technology/ltu-as/ayrd945g/config.yaml?X-Goog-Algorithm=GOOG4-RSA-SHA256&X-Goog-Credential=gorilla-files-url-signer-man%40wandb-production.iam.gserviceaccount.com%2F20250411%2Fauto%2Fstorage%2Fgoog4_request&X-Goog-Date=20250411T133547Z&X-Goog-Expires=86399&X-Goog-Signature=59229da32108dabf2e0b22f3378d7c4eff52c92055ad5d5b992f76e4df1c8015b756cf03412a752e587a2ea6bc2f30001b205d9ef095c5a14ab645fe71a22b821da600c1196db4191aef6cd423a67f5cfc13d398e023ee472db63d91e6f84db94368a9e61522d891c6c41b7eeb918e96b41062c0135485092d85801d941c7eb761567114df29f3b71030380dfe24d3e94c0e9810f87f3eb1f65bf4625252ec95591d290b470be81abb48ba16966c05db2893b493bab6f93bdd5325ee55c3ce817c57cadd71e627b02871d0c646f4dba235a7310afdefe60e03add6e16f1ebcee16c2bf969543124fb60ebc8bf3cee02e75fd183babe4d68e010a4c410a360fd7&X-Goog-SignedHeaders=host&X-User=2931823730 (Caused by NewConnectionError('<urllib3.connection.HTTPSConnection object at 0x7fcdd01c2c80>: Failed to establish a new connection: [Errno 101] Network is unreachable'))
2025-04-11 13:36:55,188 ERROR   wandb-upload_1:5057 [internal_api.py:upload_file():2558] upload_file request headers: {'User-Agent': 'python-requests/2.32.3', 'Accept-Encoding': 'gzip, deflate, br', 'Accept': '*/*', 'Connection': 'keep-alive', 'Content-Length': '8685'}
2025-04-11 13:36:55,188 ERROR   wandb-upload_1:5057 [internal_api.py:upload_file():2560] upload_file response body: 
2025-04-11 13:36:55,491 ERROR   wandb-upload_5:5057 [internal_api.py:upload_file():2556] upload_file exception https://storage.googleapis.com/wandb-production.appspot.com/2931823730-harbin-institute-of-technology/ltu-as/ayrd945g/wandb-summary.json?X-Goog-Algorithm=GOOG4-RSA-SHA256&X-Goog-Credential=gorilla-files-url-signer-man%40wandb-production.iam.gserviceaccount.com%2F20250411%2Fauto%2Fstorage%2Fgoog4_request&X-Goog-Date=20250411T133547Z&X-Goog-Expires=86399&X-Goog-Signature=88d8a33a4942edfdf46386d8d3684fa7b9d5a442bb037f8cda46c414fe422ca150fb4f2e5f776cc41bf710997e8d99494d56986c0251407a93dff567d301deee84d6a9d3c20c4876734beeebe93fc2170c90439950e62f7d895e7dfc8cff58ae05a6debe4386cf769ab635fbfecc6b9311f012934afbb8e9bfc6c652fb999d4b61c9c6dd3511d8a321c3bac43987e7d9891f0c31f9d35ca79f5a1ef87bcfa3ef26a7e363d6207536f2b71b07a4b55c4e341c9e6178a3a7bf0e2c835d2471597f60ccc6925d495148fc1623f5b3160f75ff84cd47fadcd8cd769536b21457ea5f60c8ba539b75f81d476509ef340009289b14c43e1a28cc2e27df0d6e9eb44275&X-Goog-SignedHeaders=host&X-User=2931823730: HTTPSConnectionPool(host='storage.googleapis.com', port=443): Max retries exceeded with url: /wandb-production.appspot.com/2931823730-harbin-institute-of-technology/ltu-as/ayrd945g/wandb-summary.json?X-Goog-Algorithm=GOOG4-RSA-SHA256&X-Goog-Credential=gorilla-files-url-signer-man%40wandb-production.iam.gserviceaccount.com%2F20250411%2Fauto%2Fstorage%2Fgoog4_request&X-Goog-Date=20250411T133547Z&X-Goog-Expires=86399&X-Goog-Signature=88d8a33a4942edfdf46386d8d3684fa7b9d5a442bb037f8cda46c414fe422ca150fb4f2e5f776cc41bf710997e8d99494d56986c0251407a93dff567d301deee84d6a9d3c20c4876734beeebe93fc2170c90439950e62f7d895e7dfc8cff58ae05a6debe4386cf769ab635fbfecc6b9311f012934afbb8e9bfc6c652fb999d4b61c9c6dd3511d8a321c3bac43987e7d9891f0c31f9d35ca79f5a1ef87bcfa3ef26a7e363d6207536f2b71b07a4b55c4e341c9e6178a3a7bf0e2c835d2471597f60ccc6925d495148fc1623f5b3160f75ff84cd47fadcd8cd769536b21457ea5f60c8ba539b75f81d476509ef340009289b14c43e1a28cc2e27df0d6e9eb44275&X-Goog-SignedHeaders=host&X-User=2931823730 (Caused by NewConnectionError('<urllib3.connection.HTTPSConnection object at 0x7fcdd01c37f0>: Failed to establish a new connection: [Errno 101] Network is unreachable'))
2025-04-11 13:36:55,491 ERROR   wandb-upload_5:5057 [internal_api.py:upload_file():2558] upload_file request headers: {'User-Agent': 'python-requests/2.32.3', 'Accept-Encoding': 'gzip, deflate, br', 'Accept': '*/*', 'Connection': 'keep-alive', 'Content-Length': '27'}
2025-04-11 13:36:55,491 ERROR   wandb-upload_5:5057 [internal_api.py:upload_file():2560] upload_file response body: 
2025-04-11 13:36:55,998 DEBUG   HandlerThread:5057 [handler.py:handle_request():146] handle_request: keepalive
2025-04-11 13:36:57,915 ERROR   wandb-upload_4:5057 [internal_api.py:upload_file():2556] upload_file exception https://storage.googleapis.com/wandb-production.appspot.com/2931823730-harbin-institute-of-technology/ltu-as/ayrd945g/output.log?X-Goog-Algorithm=GOOG4-RSA-SHA256&X-Goog-Credential=gorilla-files-url-signer-man%40wandb-production.iam.gserviceaccount.com%2F20250411%2Fauto%2Fstorage%2Fgoog4_request&X-Goog-Date=20250411T133547Z&X-Goog-Expires=86399&X-Goog-Signature=60a14c64c75b7213832de3f51a8cee68b48766ce9fef4ac66308dcfbe021d98db23ab7a4e8e5a5840ad99fe69b3425e1ecaa5e7cecda0e89061d438052a78b725028def9cc631a332a1e2c99ebd6d1172adc8172fdae0d62bec226a3e99cdb144f8e7a221e0ec08c94a76dc888412fde2d9f87d0b484866e6db161d92750595d0c526c395230151ab2e6574b130439e80c58f6c8fb6187dfedd000237d5c6c32116bebe722b0f4815fa4b433c2c01eac2e6d1d439d109c547bd416ef777f07467da9090b12efc4e78dfb53e81482b7f08de5e21dbddcb7102335ee3f4fc94d9b946d104c6c430ee9e397a2c1ef3c9eaaae349d83697a271010de87b863593b32&X-Goog-SignedHeaders=host&X-User=2931823730: HTTPSConnectionPool(host='storage.googleapis.com', port=443): Max retries exceeded with url: /wandb-production.appspot.com/2931823730-harbin-institute-of-technology/ltu-as/ayrd945g/output.log?X-Goog-Algorithm=GOOG4-RSA-SHA256&X-Goog-Credential=gorilla-files-url-signer-man%40wandb-production.iam.gserviceaccount.com%2F20250411%2Fauto%2Fstorage%2Fgoog4_request&X-Goog-Date=20250411T133547Z&X-Goog-Expires=86399&X-Goog-Signature=60a14c64c75b7213832de3f51a8cee68b48766ce9fef4ac66308dcfbe021d98db23ab7a4e8e5a5840ad99fe69b3425e1ecaa5e7cecda0e89061d438052a78b725028def9cc631a332a1e2c99ebd6d1172adc8172fdae0d62bec226a3e99cdb144f8e7a221e0ec08c94a76dc888412fde2d9f87d0b484866e6db161d92750595d0c526c395230151ab2e6574b130439e80c58f6c8fb6187dfedd000237d5c6c32116bebe722b0f4815fa4b433c2c01eac2e6d1d439d109c547bd416ef777f07467da9090b12efc4e78dfb53e81482b7f08de5e21dbddcb7102335ee3f4fc94d9b946d104c6c430ee9e397a2c1ef3c9eaaae349d83697a271010de87b863593b32&X-Goog-SignedHeaders=host&X-User=2931823730 (Caused by NewConnectionError('<urllib3.connection.HTTPSConnection object at 0x7fcd927a9c30>: Failed to establish a new connection: [Errno 101] Network is unreachable'))
2025-04-11 13:36:57,915 ERROR   wandb-upload_4:5057 [internal_api.py:upload_file():2558] upload_file request headers: {'User-Agent': 'python-requests/2.32.3', 'Accept-Encoding': 'gzip, deflate, br', 'Accept': '*/*', 'Connection': 'keep-alive', 'Content-Length': '5135'}
2025-04-11 13:36:57,915 ERROR   wandb-upload_4:5057 [internal_api.py:upload_file():2560] upload_file response body: 
2025-04-11 13:36:58,414 DEBUG   HandlerThread:5057 [handler.py:handle_request():146] handle_request: status_report
2025-04-11 13:37:01,000 DEBUG   HandlerThread:5057 [handler.py:handle_request():146] handle_request: keepalive
2025-04-11 13:37:02,481 ERROR   wandb-upload_2:5057 [internal_api.py:upload_file():2556] upload_file exception https://storage.googleapis.com/wandb-production.appspot.com/2931823730-harbin-institute-of-technology/ltu-as/ayrd945g/requirements.txt?X-Goog-Algorithm=GOOG4-RSA-SHA256&X-Goog-Credential=gorilla-files-url-signer-man%40wandb-production.iam.gserviceaccount.com%2F20250411%2Fauto%2Fstorage%2Fgoog4_request&X-Goog-Date=20250411T133547Z&X-Goog-Expires=86399&X-Goog-Signature=8f7985a4ebf492647396ccbeb8281c95f40ce48ca6ebfe7230b06e3e08a640b4892e9fbe8f14f084f14e5d3841d2ed4769d71f5dcc53a827130556bbab907612d4a6c07d1c4b3f38ce4fc656dabf01e58238b7603961296e52ef293121e1ab2eb7c0f40e653fe066ef2a8502bf31d63a12f60e5498b0ebdae66cee400aa1a42598345e000ebb6d22ea01ec55dcf62810cace5cacbb3cef4cc37ca34ae61cfaf15fa634731635ca6ad7b243b89a565ecd2dfae6fdcfdaf084938d1afa790a313af20f904fe253f7e9c5fbe3595321a68018379642acab4619f2715b3e42cea1e7f430dada2242a15e4fdaaa50c317aa219a978a754411899f051b8136a1fa5a4d&X-Goog-SignedHeaders=host&X-User=2931823730: HTTPSConnectionPool(host='storage.googleapis.com', port=443): Max retries exceeded with url: /wandb-production.appspot.com/2931823730-harbin-institute-of-technology/ltu-as/ayrd945g/requirements.txt?X-Goog-Algorithm=GOOG4-RSA-SHA256&X-Goog-Credential=gorilla-files-url-signer-man%40wandb-production.iam.gserviceaccount.com%2F20250411%2Fauto%2Fstorage%2Fgoog4_request&X-Goog-Date=20250411T133547Z&X-Goog-Expires=86399&X-Goog-Signature=8f7985a4ebf492647396ccbeb8281c95f40ce48ca6ebfe7230b06e3e08a640b4892e9fbe8f14f084f14e5d3841d2ed4769d71f5dcc53a827130556bbab907612d4a6c07d1c4b3f38ce4fc656dabf01e58238b7603961296e52ef293121e1ab2eb7c0f40e653fe066ef2a8502bf31d63a12f60e5498b0ebdae66cee400aa1a42598345e000ebb6d22ea01ec55dcf62810cace5cacbb3cef4cc37ca34ae61cfaf15fa634731635ca6ad7b243b89a565ecd2dfae6fdcfdaf084938d1afa790a313af20f904fe253f7e9c5fbe3595321a68018379642acab4619f2715b3e42cea1e7f430dada2242a15e4fdaaa50c317aa219a978a754411899f051b8136a1fa5a4d&X-Goog-SignedHeaders=host&X-User=2931823730 (Caused by NewConnectionError('<urllib3.connection.HTTPSConnection object at 0x7fcd927aa650>: Failed to establish a new connection: [Errno 101] Network is unreachable'))
2025-04-11 13:37:02,481 ERROR   wandb-upload_2:5057 [internal_api.py:upload_file():2558] upload_file request headers: {'User-Agent': 'python-requests/2.32.3', 'Accept-Encoding': 'gzip, deflate, br', 'Accept': '*/*', 'Connection': 'keep-alive', 'Content-Length': '4212'}
2025-04-11 13:37:02,481 ERROR   wandb-upload_2:5057 [internal_api.py:upload_file():2560] upload_file response body: 
2025-04-11 13:37:03,415 DEBUG   HandlerThread:5057 [handler.py:handle_request():146] handle_request: status_report
2025-04-11 13:37:06,002 DEBUG   HandlerThread:5057 [handler.py:handle_request():146] handle_request: keepalive
2025-04-11 13:37:08,416 DEBUG   HandlerThread:5057 [handler.py:handle_request():146] handle_request: status_report
2025-04-11 13:37:11,004 DEBUG   HandlerThread:5057 [handler.py:handle_request():146] handle_request: keepalive
2025-04-11 13:37:13,417 DEBUG   HandlerThread:5057 [handler.py:handle_request():146] handle_request: status_report
2025-04-11 13:37:16,006 DEBUG   HandlerThread:5057 [handler.py:handle_request():146] handle_request: keepalive
2025-04-11 13:37:18,418 DEBUG   HandlerThread:5057 [handler.py:handle_request():146] handle_request: status_report
2025-04-11 13:37:21,009 DEBUG   HandlerThread:5057 [handler.py:handle_request():146] handle_request: keepalive
2025-04-11 13:37:23,419 DEBUG   HandlerThread:5057 [handler.py:handle_request():146] handle_request: status_report
2025-04-11 13:37:26,011 DEBUG   HandlerThread:5057 [handler.py:handle_request():146] handle_request: keepalive
2025-04-11 13:37:28,420 DEBUG   HandlerThread:5057 [handler.py:handle_request():146] handle_request: status_report
2025-04-11 13:37:31,013 DEBUG   HandlerThread:5057 [handler.py:handle_request():146] handle_request: keepalive
2025-04-11 13:37:33,421 DEBUG   HandlerThread:5057 [handler.py:handle_request():146] handle_request: status_report
2025-04-11 13:37:36,016 DEBUG   HandlerThread:5057 [handler.py:handle_request():146] handle_request: keepalive
2025-04-11 13:37:38,422 DEBUG   HandlerThread:5057 [handler.py:handle_request():146] handle_request: status_report
2025-04-11 13:37:41,018 DEBUG   HandlerThread:5057 [handler.py:handle_request():146] handle_request: keepalive
2025-04-11 13:37:43,423 DEBUG   HandlerThread:5057 [handler.py:handle_request():146] handle_request: status_report
2025-04-11 13:37:46,020 DEBUG   HandlerThread:5057 [handler.py:handle_request():146] handle_request: keepalive
2025-04-11 13:37:48,424 DEBUG   HandlerThread:5057 [handler.py:handle_request():146] handle_request: status_report
2025-04-11 13:37:48,822 ERROR   wandb-upload_0:5057 [internal_api.py:upload_file():2556] upload_file exception https://storage.googleapis.com/wandb-production.appspot.com/2931823730-harbin-institute-of-technology/ltu-as/ayrd945g/wandb-metadata.json?X-Goog-Algorithm=GOOG4-RSA-SHA256&X-Goog-Credential=gorilla-files-url-signer-man%40wandb-production.iam.gserviceaccount.com%2F20250411%2Fauto%2Fstorage%2Fgoog4_request&X-Goog-Date=20250411T133531Z&X-Goog-Expires=86399&X-Goog-Signature=3f5aee34cfa797b7aa73f667422a4aee946d1072dcec6b4021fa16645cebbf9a6738f93929154478c65a583fe2e5451e23e58739b96fa5355a823d0848191cccf627be8a9b51eee5861c7ed65eeead014bbceb2dcaeeef78dcdb79f5d1c045f21707476081794fb0708d6ec543c2f328439ef45907a15b52a6f64bbdbbf40ac08a2e90802e63ba340ae771978232c617a39b97d3caff9929e0c70b5a278c509f73435a1bac9fdee8a302d4e14c9e0a1f951e09f2537482c5c835c4eeb93f0efc7b988c8cfecc28c793061d2726f554ddc64313056228b705299a06a992a33bc9e5d77e2dd03adbb5b76f7b20314f6bb3c131cf504b3a39390ed6e8b4e6d7ba46&X-Goog-SignedHeaders=host&X-User=2931823730: HTTPSConnectionPool(host='storage.googleapis.com', port=443): Max retries exceeded with url: /wandb-production.appspot.com/2931823730-harbin-institute-of-technology/ltu-as/ayrd945g/wandb-metadata.json?X-Goog-Algorithm=GOOG4-RSA-SHA256&X-Goog-Credential=gorilla-files-url-signer-man%40wandb-production.iam.gserviceaccount.com%2F20250411%2Fauto%2Fstorage%2Fgoog4_request&X-Goog-Date=20250411T133531Z&X-Goog-Expires=86399&X-Goog-Signature=3f5aee34cfa797b7aa73f667422a4aee946d1072dcec6b4021fa16645cebbf9a6738f93929154478c65a583fe2e5451e23e58739b96fa5355a823d0848191cccf627be8a9b51eee5861c7ed65eeead014bbceb2dcaeeef78dcdb79f5d1c045f21707476081794fb0708d6ec543c2f328439ef45907a15b52a6f64bbdbbf40ac08a2e90802e63ba340ae771978232c617a39b97d3caff9929e0c70b5a278c509f73435a1bac9fdee8a302d4e14c9e0a1f951e09f2537482c5c835c4eeb93f0efc7b988c8cfecc28c793061d2726f554ddc64313056228b705299a06a992a33bc9e5d77e2dd03adbb5b76f7b20314f6bb3c131cf504b3a39390ed6e8b4e6d7ba46&X-Goog-SignedHeaders=host&X-User=2931823730 (Caused by NewConnectionError('<urllib3.connection.HTTPSConnection object at 0x7fcd927a8b20>: Failed to establish a new connection: [Errno 101] Network is unreachable'))
2025-04-11 13:37:48,822 ERROR   wandb-upload_0:5057 [internal_api.py:upload_file():2558] upload_file request headers: {'User-Agent': 'python-requests/2.32.3', 'Accept-Encoding': 'gzip, deflate, br', 'Accept': '*/*', 'Connection': 'keep-alive', 'Content-Length': '2259'}
2025-04-11 13:37:48,822 ERROR   wandb-upload_0:5057 [internal_api.py:upload_file():2560] upload_file response body: 
2025-04-11 13:37:51,022 DEBUG   HandlerThread:5057 [handler.py:handle_request():146] handle_request: keepalive
2025-04-11 13:37:53,425 DEBUG   HandlerThread:5057 [handler.py:handle_request():146] handle_request: status_report
2025-04-11 13:37:56,024 DEBUG   HandlerThread:5057 [handler.py:handle_request():146] handle_request: keepalive
2025-04-11 13:37:58,426 DEBUG   HandlerThread:5057 [handler.py:handle_request():146] handle_request: status_report
2025-04-11 13:38:00,584 ERROR   wandb-upload_3:5057 [internal_api.py:upload_file():2556] upload_file exception https://storage.googleapis.com/wandb-production.appspot.com/2931823730-harbin-institute-of-technology/ltu-as/ayrd945g/conda-environment.yaml?X-Goog-Algorithm=GOOG4-RSA-SHA256&X-Goog-Credential=gorilla-files-url-signer-man%40wandb-production.iam.gserviceaccount.com%2F20250411%2Fauto%2Fstorage%2Fgoog4_request&X-Goog-Date=20250411T133547Z&X-Goog-Expires=86399&X-Goog-Signature=4c9126604080912880ede91838f5a7390665008083d7e44309734daddd80b9cf8cf7a4c5c6fa5de745ba75d664cb7469ed45bccd6a8d0f8328f5b819c87f52209a817e2cecb6b43dd002266b64a58a46125cf94eecc520b1b7a33aba86a8651778a4fc020b1e58b91094758a9f0bdf70c1b1709c39a4aa8e5b9998524293e3f95252e6a81cbabe349b8e96481c3fdb99ef3ed87c033bd482bc27e2900be02b6f7a10cc37e178de535da73792986f0057d36c512c3142823ec07dde39234d436ecef04f3b634ff435b7df21a6d1fbd1b616a7aafd7a5bc2d0a15eacb48d1f828c4e7e505ad7f7585a5624f5d9716d95b4b15bdc9c2151e47d7698d62f76621622&X-Goog-SignedHeaders=host&X-User=2931823730: HTTPSConnectionPool(host='storage.googleapis.com', port=443): Max retries exceeded with url: /wandb-production.appspot.com/2931823730-harbin-institute-of-technology/ltu-as/ayrd945g/conda-environment.yaml?X-Goog-Algorithm=GOOG4-RSA-SHA256&X-Goog-Credential=gorilla-files-url-signer-man%40wandb-production.iam.gserviceaccount.com%2F20250411%2Fauto%2Fstorage%2Fgoog4_request&X-Goog-Date=20250411T133547Z&X-Goog-Expires=86399&X-Goog-Signature=4c9126604080912880ede91838f5a7390665008083d7e44309734daddd80b9cf8cf7a4c5c6fa5de745ba75d664cb7469ed45bccd6a8d0f8328f5b819c87f52209a817e2cecb6b43dd002266b64a58a46125cf94eecc520b1b7a33aba86a8651778a4fc020b1e58b91094758a9f0bdf70c1b1709c39a4aa8e5b9998524293e3f95252e6a81cbabe349b8e96481c3fdb99ef3ed87c033bd482bc27e2900be02b6f7a10cc37e178de535da73792986f0057d36c512c3142823ec07dde39234d436ecef04f3b634ff435b7df21a6d1fbd1b616a7aafd7a5bc2d0a15eacb48d1f828c4e7e505ad7f7585a5624f5d9716d95b4b15bdc9c2151e47d7698d62f76621622&X-Goog-SignedHeaders=host&X-User=2931823730 (Caused by NewConnectionError('<urllib3.connection.HTTPSConnection object at 0x7fcd927a8eb0>: Failed to establish a new connection: [Errno 101] Network is unreachable'))
2025-04-11 13:38:00,584 ERROR   wandb-upload_3:5057 [internal_api.py:upload_file():2558] upload_file request headers: {'User-Agent': 'python-requests/2.32.3', 'Accept-Encoding': 'gzip, deflate, br', 'Accept': '*/*', 'Connection': 'keep-alive', 'Content-Length': '8281'}
2025-04-11 13:38:00,585 ERROR   wandb-upload_3:5057 [internal_api.py:upload_file():2560] upload_file response body: 
2025-04-11 13:38:01,027 DEBUG   HandlerThread:5057 [handler.py:handle_request():146] handle_request: keepalive
2025-04-11 13:38:03,427 DEBUG   HandlerThread:5057 [handler.py:handle_request():146] handle_request: status_report
2025-04-11 13:38:06,029 DEBUG   HandlerThread:5057 [handler.py:handle_request():146] handle_request: keepalive
2025-04-11 13:38:08,010 ERROR   wandb-upload_1:5057 [internal_api.py:upload_file():2556] upload_file exception https://storage.googleapis.com/wandb-production.appspot.com/2931823730-harbin-institute-of-technology/ltu-as/ayrd945g/config.yaml?X-Goog-Algorithm=GOOG4-RSA-SHA256&X-Goog-Credential=gorilla-files-url-signer-man%40wandb-production.iam.gserviceaccount.com%2F20250411%2Fauto%2Fstorage%2Fgoog4_request&X-Goog-Date=20250411T133547Z&X-Goog-Expires=86399&X-Goog-Signature=59229da32108dabf2e0b22f3378d7c4eff52c92055ad5d5b992f76e4df1c8015b756cf03412a752e587a2ea6bc2f30001b205d9ef095c5a14ab645fe71a22b821da600c1196db4191aef6cd423a67f5cfc13d398e023ee472db63d91e6f84db94368a9e61522d891c6c41b7eeb918e96b41062c0135485092d85801d941c7eb761567114df29f3b71030380dfe24d3e94c0e9810f87f3eb1f65bf4625252ec95591d290b470be81abb48ba16966c05db2893b493bab6f93bdd5325ee55c3ce817c57cadd71e627b02871d0c646f4dba235a7310afdefe60e03add6e16f1ebcee16c2bf969543124fb60ebc8bf3cee02e75fd183babe4d68e010a4c410a360fd7&X-Goog-SignedHeaders=host&X-User=2931823730: HTTPSConnectionPool(host='storage.googleapis.com', port=443): Max retries exceeded with url: /wandb-production.appspot.com/2931823730-harbin-institute-of-technology/ltu-as/ayrd945g/config.yaml?X-Goog-Algorithm=GOOG4-RSA-SHA256&X-Goog-Credential=gorilla-files-url-signer-man%40wandb-production.iam.gserviceaccount.com%2F20250411%2Fauto%2Fstorage%2Fgoog4_request&X-Goog-Date=20250411T133547Z&X-Goog-Expires=86399&X-Goog-Signature=59229da32108dabf2e0b22f3378d7c4eff52c92055ad5d5b992f76e4df1c8015b756cf03412a752e587a2ea6bc2f30001b205d9ef095c5a14ab645fe71a22b821da600c1196db4191aef6cd423a67f5cfc13d398e023ee472db63d91e6f84db94368a9e61522d891c6c41b7eeb918e96b41062c0135485092d85801d941c7eb761567114df29f3b71030380dfe24d3e94c0e9810f87f3eb1f65bf4625252ec95591d290b470be81abb48ba16966c05db2893b493bab6f93bdd5325ee55c3ce817c57cadd71e627b02871d0c646f4dba235a7310afdefe60e03add6e16f1ebcee16c2bf969543124fb60ebc8bf3cee02e75fd183babe4d68e010a4c410a360fd7&X-Goog-SignedHeaders=host&X-User=2931823730 (Caused by NewConnectionError('<urllib3.connection.HTTPSConnection object at 0x7fcd927a8e50>: Failed to establish a new connection: [Errno 101] Network is unreachable'))
2025-04-11 13:38:08,010 ERROR   wandb-upload_1:5057 [internal_api.py:upload_file():2558] upload_file request headers: {'User-Agent': 'python-requests/2.32.3', 'Accept-Encoding': 'gzip, deflate, br', 'Accept': '*/*', 'Connection': 'keep-alive', 'Content-Length': '8685'}
2025-04-11 13:38:08,010 ERROR   wandb-upload_1:5057 [internal_api.py:upload_file():2560] upload_file response body: 
2025-04-11 13:38:08,428 DEBUG   HandlerThread:5057 [handler.py:handle_request():146] handle_request: status_report
2025-04-11 13:38:09,236 ERROR   wandb-upload_4:5057 [internal_api.py:upload_file():2556] upload_file exception https://storage.googleapis.com/wandb-production.appspot.com/2931823730-harbin-institute-of-technology/ltu-as/ayrd945g/output.log?X-Goog-Algorithm=GOOG4-RSA-SHA256&X-Goog-Credential=gorilla-files-url-signer-man%40wandb-production.iam.gserviceaccount.com%2F20250411%2Fauto%2Fstorage%2Fgoog4_request&X-Goog-Date=20250411T133547Z&X-Goog-Expires=86399&X-Goog-Signature=60a14c64c75b7213832de3f51a8cee68b48766ce9fef4ac66308dcfbe021d98db23ab7a4e8e5a5840ad99fe69b3425e1ecaa5e7cecda0e89061d438052a78b725028def9cc631a332a1e2c99ebd6d1172adc8172fdae0d62bec226a3e99cdb144f8e7a221e0ec08c94a76dc888412fde2d9f87d0b484866e6db161d92750595d0c526c395230151ab2e6574b130439e80c58f6c8fb6187dfedd000237d5c6c32116bebe722b0f4815fa4b433c2c01eac2e6d1d439d109c547bd416ef777f07467da9090b12efc4e78dfb53e81482b7f08de5e21dbddcb7102335ee3f4fc94d9b946d104c6c430ee9e397a2c1ef3c9eaaae349d83697a271010de87b863593b32&X-Goog-SignedHeaders=host&X-User=2931823730: HTTPSConnectionPool(host='storage.googleapis.com', port=443): Max retries exceeded with url: /wandb-production.appspot.com/2931823730-harbin-institute-of-technology/ltu-as/ayrd945g/output.log?X-Goog-Algorithm=GOOG4-RSA-SHA256&X-Goog-Credential=gorilla-files-url-signer-man%40wandb-production.iam.gserviceaccount.com%2F20250411%2Fauto%2Fstorage%2Fgoog4_request&X-Goog-Date=20250411T133547Z&X-Goog-Expires=86399&X-Goog-Signature=60a14c64c75b7213832de3f51a8cee68b48766ce9fef4ac66308dcfbe021d98db23ab7a4e8e5a5840ad99fe69b3425e1ecaa5e7cecda0e89061d438052a78b725028def9cc631a332a1e2c99ebd6d1172adc8172fdae0d62bec226a3e99cdb144f8e7a221e0ec08c94a76dc888412fde2d9f87d0b484866e6db161d92750595d0c526c395230151ab2e6574b130439e80c58f6c8fb6187dfedd000237d5c6c32116bebe722b0f4815fa4b433c2c01eac2e6d1d439d109c547bd416ef777f07467da9090b12efc4e78dfb53e81482b7f08de5e21dbddcb7102335ee3f4fc94d9b946d104c6c430ee9e397a2c1ef3c9eaaae349d83697a271010de87b863593b32&X-Goog-SignedHeaders=host&X-User=2931823730 (Caused by NewConnectionError('<urllib3.connection.HTTPSConnection object at 0x7fcdd01c2050>: Failed to establish a new connection: [Errno 101] Network is unreachable'))
2025-04-11 13:38:09,236 ERROR   wandb-upload_4:5057 [internal_api.py:upload_file():2558] upload_file request headers: {'User-Agent': 'python-requests/2.32.3', 'Accept-Encoding': 'gzip, deflate, br', 'Accept': '*/*', 'Connection': 'keep-alive', 'Content-Length': '5135'}
2025-04-11 13:38:09,236 ERROR   wandb-upload_4:5057 [internal_api.py:upload_file():2560] upload_file response body: 
2025-04-11 13:38:11,031 DEBUG   HandlerThread:5057 [handler.py:handle_request():146] handle_request: keepalive
2025-04-11 13:38:12,832 ERROR   wandb-upload_2:5057 [internal_api.py:upload_file():2556] upload_file exception https://storage.googleapis.com/wandb-production.appspot.com/2931823730-harbin-institute-of-technology/ltu-as/ayrd945g/requirements.txt?X-Goog-Algorithm=GOOG4-RSA-SHA256&X-Goog-Credential=gorilla-files-url-signer-man%40wandb-production.iam.gserviceaccount.com%2F20250411%2Fauto%2Fstorage%2Fgoog4_request&X-Goog-Date=20250411T133547Z&X-Goog-Expires=86399&X-Goog-Signature=8f7985a4ebf492647396ccbeb8281c95f40ce48ca6ebfe7230b06e3e08a640b4892e9fbe8f14f084f14e5d3841d2ed4769d71f5dcc53a827130556bbab907612d4a6c07d1c4b3f38ce4fc656dabf01e58238b7603961296e52ef293121e1ab2eb7c0f40e653fe066ef2a8502bf31d63a12f60e5498b0ebdae66cee400aa1a42598345e000ebb6d22ea01ec55dcf62810cace5cacbb3cef4cc37ca34ae61cfaf15fa634731635ca6ad7b243b89a565ecd2dfae6fdcfdaf084938d1afa790a313af20f904fe253f7e9c5fbe3595321a68018379642acab4619f2715b3e42cea1e7f430dada2242a15e4fdaaa50c317aa219a978a754411899f051b8136a1fa5a4d&X-Goog-SignedHeaders=host&X-User=2931823730: HTTPSConnectionPool(host='storage.googleapis.com', port=443): Max retries exceeded with url: /wandb-production.appspot.com/2931823730-harbin-institute-of-technology/ltu-as/ayrd945g/requirements.txt?X-Goog-Algorithm=GOOG4-RSA-SHA256&X-Goog-Credential=gorilla-files-url-signer-man%40wandb-production.iam.gserviceaccount.com%2F20250411%2Fauto%2Fstorage%2Fgoog4_request&X-Goog-Date=20250411T133547Z&X-Goog-Expires=86399&X-Goog-Signature=8f7985a4ebf492647396ccbeb8281c95f40ce48ca6ebfe7230b06e3e08a640b4892e9fbe8f14f084f14e5d3841d2ed4769d71f5dcc53a827130556bbab907612d4a6c07d1c4b3f38ce4fc656dabf01e58238b7603961296e52ef293121e1ab2eb7c0f40e653fe066ef2a8502bf31d63a12f60e5498b0ebdae66cee400aa1a42598345e000ebb6d22ea01ec55dcf62810cace5cacbb3cef4cc37ca34ae61cfaf15fa634731635ca6ad7b243b89a565ecd2dfae6fdcfdaf084938d1afa790a313af20f904fe253f7e9c5fbe3595321a68018379642acab4619f2715b3e42cea1e7f430dada2242a15e4fdaaa50c317aa219a978a754411899f051b8136a1fa5a4d&X-Goog-SignedHeaders=host&X-User=2931823730 (Caused by NewConnectionError('<urllib3.connection.HTTPSConnection object at 0x7fcdd01c2170>: Failed to establish a new connection: [Errno 101] Network is unreachable'))
2025-04-11 13:38:12,832 ERROR   wandb-upload_2:5057 [internal_api.py:upload_file():2558] upload_file request headers: {'User-Agent': 'python-requests/2.32.3', 'Accept-Encoding': 'gzip, deflate, br', 'Accept': '*/*', 'Connection': 'keep-alive', 'Content-Length': '4212'}
2025-04-11 13:38:12,832 ERROR   wandb-upload_2:5057 [internal_api.py:upload_file():2560] upload_file response body: 
2025-04-11 13:38:13,429 DEBUG   HandlerThread:5057 [handler.py:handle_request():146] handle_request: status_report
2025-04-11 13:38:14,700 ERROR   wandb-upload_5:5057 [internal_api.py:upload_file():2556] upload_file exception https://storage.googleapis.com/wandb-production.appspot.com/2931823730-harbin-institute-of-technology/ltu-as/ayrd945g/wandb-summary.json?X-Goog-Algorithm=GOOG4-RSA-SHA256&X-Goog-Credential=gorilla-files-url-signer-man%40wandb-production.iam.gserviceaccount.com%2F20250411%2Fauto%2Fstorage%2Fgoog4_request&X-Goog-Date=20250411T133547Z&X-Goog-Expires=86399&X-Goog-Signature=88d8a33a4942edfdf46386d8d3684fa7b9d5a442bb037f8cda46c414fe422ca150fb4f2e5f776cc41bf710997e8d99494d56986c0251407a93dff567d301deee84d6a9d3c20c4876734beeebe93fc2170c90439950e62f7d895e7dfc8cff58ae05a6debe4386cf769ab635fbfecc6b9311f012934afbb8e9bfc6c652fb999d4b61c9c6dd3511d8a321c3bac43987e7d9891f0c31f9d35ca79f5a1ef87bcfa3ef26a7e363d6207536f2b71b07a4b55c4e341c9e6178a3a7bf0e2c835d2471597f60ccc6925d495148fc1623f5b3160f75ff84cd47fadcd8cd769536b21457ea5f60c8ba539b75f81d476509ef340009289b14c43e1a28cc2e27df0d6e9eb44275&X-Goog-SignedHeaders=host&X-User=2931823730: HTTPSConnectionPool(host='storage.googleapis.com', port=443): Max retries exceeded with url: /wandb-production.appspot.com/2931823730-harbin-institute-of-technology/ltu-as/ayrd945g/wandb-summary.json?X-Goog-Algorithm=GOOG4-RSA-SHA256&X-Goog-Credential=gorilla-files-url-signer-man%40wandb-production.iam.gserviceaccount.com%2F20250411%2Fauto%2Fstorage%2Fgoog4_request&X-Goog-Date=20250411T133547Z&X-Goog-Expires=86399&X-Goog-Signature=88d8a33a4942edfdf46386d8d3684fa7b9d5a442bb037f8cda46c414fe422ca150fb4f2e5f776cc41bf710997e8d99494d56986c0251407a93dff567d301deee84d6a9d3c20c4876734beeebe93fc2170c90439950e62f7d895e7dfc8cff58ae05a6debe4386cf769ab635fbfecc6b9311f012934afbb8e9bfc6c652fb999d4b61c9c6dd3511d8a321c3bac43987e7d9891f0c31f9d35ca79f5a1ef87bcfa3ef26a7e363d6207536f2b71b07a4b55c4e341c9e6178a3a7bf0e2c835d2471597f60ccc6925d495148fc1623f5b3160f75ff84cd47fadcd8cd769536b21457ea5f60c8ba539b75f81d476509ef340009289b14c43e1a28cc2e27df0d6e9eb44275&X-Goog-SignedHeaders=host&X-User=2931823730 (Caused by NewConnectionError('<urllib3.connection.HTTPSConnection object at 0x7fcdd01c2980>: Failed to establish a new connection: [Errno 101] Network is unreachable'))
2025-04-11 13:38:14,700 ERROR   wandb-upload_5:5057 [internal_api.py:upload_file():2558] upload_file request headers: {'User-Agent': 'python-requests/2.32.3', 'Accept-Encoding': 'gzip, deflate, br', 'Accept': '*/*', 'Connection': 'keep-alive', 'Content-Length': '27'}
2025-04-11 13:38:14,700 ERROR   wandb-upload_5:5057 [internal_api.py:upload_file():2560] upload_file response body: 
2025-04-11 13:38:16,033 DEBUG   HandlerThread:5057 [handler.py:handle_request():146] handle_request: keepalive
2025-04-11 13:38:18,430 DEBUG   HandlerThread:5057 [handler.py:handle_request():146] handle_request: status_report
2025-04-11 13:38:21,035 DEBUG   HandlerThread:5057 [handler.py:handle_request():146] handle_request: keepalive
2025-04-11 13:38:23,431 DEBUG   HandlerThread:5057 [handler.py:handle_request():146] handle_request: status_report
2025-04-11 13:38:26,037 DEBUG   HandlerThread:5057 [handler.py:handle_request():146] handle_request: keepalive
2025-04-11 13:38:28,432 DEBUG   HandlerThread:5057 [handler.py:handle_request():146] handle_request: status_report
2025-04-11 13:38:31,039 DEBUG   HandlerThread:5057 [handler.py:handle_request():146] handle_request: keepalive
2025-04-11 13:38:33,433 DEBUG   HandlerThread:5057 [handler.py:handle_request():146] handle_request: status_report
2025-04-11 13:38:36,041 DEBUG   HandlerThread:5057 [handler.py:handle_request():146] handle_request: keepalive
2025-04-11 13:38:38,434 DEBUG   HandlerThread:5057 [handler.py:handle_request():146] handle_request: status_report
2025-04-11 13:38:41,044 DEBUG   HandlerThread:5057 [handler.py:handle_request():146] handle_request: keepalive
2025-04-11 13:38:43,435 DEBUG   HandlerThread:5057 [handler.py:handle_request():146] handle_request: status_report
2025-04-11 13:38:46,046 DEBUG   HandlerThread:5057 [handler.py:handle_request():146] handle_request: keepalive
2025-04-11 13:38:48,436 DEBUG   HandlerThread:5057 [handler.py:handle_request():146] handle_request: status_report
2025-04-11 13:38:51,048 DEBUG   HandlerThread:5057 [handler.py:handle_request():146] handle_request: keepalive
2025-04-11 13:38:53,437 DEBUG   HandlerThread:5057 [handler.py:handle_request():146] handle_request: status_report
2025-04-11 13:38:56,050 DEBUG   HandlerThread:5057 [handler.py:handle_request():146] handle_request: keepalive
2025-04-11 13:38:58,438 DEBUG   HandlerThread:5057 [handler.py:handle_request():146] handle_request: status_report
2025-04-11 13:39:01,052 DEBUG   HandlerThread:5057 [handler.py:handle_request():146] handle_request: keepalive
2025-04-11 13:39:03,439 DEBUG   HandlerThread:5057 [handler.py:handle_request():146] handle_request: status_report
2025-04-11 13:39:06,054 DEBUG   HandlerThread:5057 [handler.py:handle_request():146] handle_request: keepalive
2025-04-11 13:39:08,440 DEBUG   HandlerThread:5057 [handler.py:handle_request():146] handle_request: status_report
2025-04-11 13:39:11,057 DEBUG   HandlerThread:5057 [handler.py:handle_request():146] handle_request: keepalive
2025-04-11 13:39:13,441 DEBUG   HandlerThread:5057 [handler.py:handle_request():146] handle_request: status_report
2025-04-11 13:39:16,058 DEBUG   HandlerThread:5057 [handler.py:handle_request():146] handle_request: keepalive
2025-04-11 13:39:18,442 DEBUG   HandlerThread:5057 [handler.py:handle_request():146] handle_request: status_report
2025-04-11 13:39:21,061 DEBUG   HandlerThread:5057 [handler.py:handle_request():146] handle_request: keepalive
2025-04-11 13:39:23,443 DEBUG   HandlerThread:5057 [handler.py:handle_request():146] handle_request: status_report
2025-04-11 13:39:26,062 DEBUG   HandlerThread:5057 [handler.py:handle_request():146] handle_request: keepalive
2025-04-11 13:39:28,444 DEBUG   HandlerThread:5057 [handler.py:handle_request():146] handle_request: status_report
2025-04-11 13:39:31,065 DEBUG   HandlerThread:5057 [handler.py:handle_request():146] handle_request: keepalive
2025-04-11 13:39:33,445 DEBUG   HandlerThread:5057 [handler.py:handle_request():146] handle_request: status_report
2025-04-11 13:39:36,067 DEBUG   HandlerThread:5057 [handler.py:handle_request():146] handle_request: keepalive
2025-04-11 13:39:38,446 DEBUG   HandlerThread:5057 [handler.py:handle_request():146] handle_request: status_report
2025-04-11 13:39:41,069 DEBUG   HandlerThread:5057 [handler.py:handle_request():146] handle_request: keepalive
2025-04-11 13:39:43,447 DEBUG   HandlerThread:5057 [handler.py:handle_request():146] handle_request: status_report
2025-04-11 13:39:46,071 DEBUG   HandlerThread:5057 [handler.py:handle_request():146] handle_request: keepalive
2025-04-11 13:39:48,448 DEBUG   HandlerThread:5057 [handler.py:handle_request():146] handle_request: status_report
2025-04-11 13:39:51,073 DEBUG   HandlerThread:5057 [handler.py:handle_request():146] handle_request: keepalive
2025-04-11 13:39:53,449 DEBUG   HandlerThread:5057 [handler.py:handle_request():146] handle_request: status_report
2025-04-11 13:39:56,075 DEBUG   HandlerThread:5057 [handler.py:handle_request():146] handle_request: keepalive
2025-04-11 13:39:58,450 DEBUG   HandlerThread:5057 [handler.py:handle_request():146] handle_request: status_report
2025-04-11 13:40:01,077 DEBUG   HandlerThread:5057 [handler.py:handle_request():146] handle_request: keepalive
2025-04-11 13:40:03,451 DEBUG   HandlerThread:5057 [handler.py:handle_request():146] handle_request: status_report
2025-04-11 13:40:06,079 DEBUG   HandlerThread:5057 [handler.py:handle_request():146] handle_request: keepalive
2025-04-11 13:40:08,452 DEBUG   HandlerThread:5057 [handler.py:handle_request():146] handle_request: status_report
2025-04-11 13:40:11,081 DEBUG   HandlerThread:5057 [handler.py:handle_request():146] handle_request: keepalive
2025-04-11 13:40:13,453 DEBUG   HandlerThread:5057 [handler.py:handle_request():146] handle_request: status_report
2025-04-11 13:40:13,617 ERROR   wandb-upload_0:5057 [internal_api.py:upload_file():2556] upload_file exception https://storage.googleapis.com/wandb-production.appspot.com/2931823730-harbin-institute-of-technology/ltu-as/ayrd945g/wandb-metadata.json?X-Goog-Algorithm=GOOG4-RSA-SHA256&X-Goog-Credential=gorilla-files-url-signer-man%40wandb-production.iam.gserviceaccount.com%2F20250411%2Fauto%2Fstorage%2Fgoog4_request&X-Goog-Date=20250411T133531Z&X-Goog-Expires=86399&X-Goog-Signature=3f5aee34cfa797b7aa73f667422a4aee946d1072dcec6b4021fa16645cebbf9a6738f93929154478c65a583fe2e5451e23e58739b96fa5355a823d0848191cccf627be8a9b51eee5861c7ed65eeead014bbceb2dcaeeef78dcdb79f5d1c045f21707476081794fb0708d6ec543c2f328439ef45907a15b52a6f64bbdbbf40ac08a2e90802e63ba340ae771978232c617a39b97d3caff9929e0c70b5a278c509f73435a1bac9fdee8a302d4e14c9e0a1f951e09f2537482c5c835c4eeb93f0efc7b988c8cfecc28c793061d2726f554ddc64313056228b705299a06a992a33bc9e5d77e2dd03adbb5b76f7b20314f6bb3c131cf504b3a39390ed6e8b4e6d7ba46&X-Goog-SignedHeaders=host&X-User=2931823730: HTTPSConnectionPool(host='storage.googleapis.com', port=443): Max retries exceeded with url: /wandb-production.appspot.com/2931823730-harbin-institute-of-technology/ltu-as/ayrd945g/wandb-metadata.json?X-Goog-Algorithm=GOOG4-RSA-SHA256&X-Goog-Credential=gorilla-files-url-signer-man%40wandb-production.iam.gserviceaccount.com%2F20250411%2Fauto%2Fstorage%2Fgoog4_request&X-Goog-Date=20250411T133531Z&X-Goog-Expires=86399&X-Goog-Signature=3f5aee34cfa797b7aa73f667422a4aee946d1072dcec6b4021fa16645cebbf9a6738f93929154478c65a583fe2e5451e23e58739b96fa5355a823d0848191cccf627be8a9b51eee5861c7ed65eeead014bbceb2dcaeeef78dcdb79f5d1c045f21707476081794fb0708d6ec543c2f328439ef45907a15b52a6f64bbdbbf40ac08a2e90802e63ba340ae771978232c617a39b97d3caff9929e0c70b5a278c509f73435a1bac9fdee8a302d4e14c9e0a1f951e09f2537482c5c835c4eeb93f0efc7b988c8cfecc28c793061d2726f554ddc64313056228b705299a06a992a33bc9e5d77e2dd03adbb5b76f7b20314f6bb3c131cf504b3a39390ed6e8b4e6d7ba46&X-Goog-SignedHeaders=host&X-User=2931823730 (Caused by NewConnectionError('<urllib3.connection.HTTPSConnection object at 0x7fcdd01c1e70>: Failed to establish a new connection: [Errno 101] Network is unreachable'))
2025-04-11 13:40:13,618 ERROR   wandb-upload_0:5057 [internal_api.py:upload_file():2558] upload_file request headers: {'User-Agent': 'python-requests/2.32.3', 'Accept-Encoding': 'gzip, deflate, br', 'Accept': '*/*', 'Connection': 'keep-alive', 'Content-Length': '2259'}
2025-04-11 13:40:13,618 ERROR   wandb-upload_0:5057 [internal_api.py:upload_file():2560] upload_file response body: 
2025-04-11 13:40:16,082 DEBUG   HandlerThread:5057 [handler.py:handle_request():146] handle_request: keepalive
2025-04-11 13:40:18,454 DEBUG   HandlerThread:5057 [handler.py:handle_request():146] handle_request: status_report
2025-04-11 13:40:21,085 DEBUG   HandlerThread:5057 [handler.py:handle_request():146] handle_request: keepalive
2025-04-11 13:40:23,455 DEBUG   HandlerThread:5057 [handler.py:handle_request():146] handle_request: status_report
2025-04-11 13:40:26,087 DEBUG   HandlerThread:5057 [handler.py:handle_request():146] handle_request: keepalive
2025-04-11 13:40:28,191 ERROR   wandb-upload_4:5057 [internal_api.py:upload_file():2556] upload_file exception https://storage.googleapis.com/wandb-production.appspot.com/2931823730-harbin-institute-of-technology/ltu-as/ayrd945g/output.log?X-Goog-Algorithm=GOOG4-RSA-SHA256&X-Goog-Credential=gorilla-files-url-signer-man%40wandb-production.iam.gserviceaccount.com%2F20250411%2Fauto%2Fstorage%2Fgoog4_request&X-Goog-Date=20250411T133547Z&X-Goog-Expires=86399&X-Goog-Signature=60a14c64c75b7213832de3f51a8cee68b48766ce9fef4ac66308dcfbe021d98db23ab7a4e8e5a5840ad99fe69b3425e1ecaa5e7cecda0e89061d438052a78b725028def9cc631a332a1e2c99ebd6d1172adc8172fdae0d62bec226a3e99cdb144f8e7a221e0ec08c94a76dc888412fde2d9f87d0b484866e6db161d92750595d0c526c395230151ab2e6574b130439e80c58f6c8fb6187dfedd000237d5c6c32116bebe722b0f4815fa4b433c2c01eac2e6d1d439d109c547bd416ef777f07467da9090b12efc4e78dfb53e81482b7f08de5e21dbddcb7102335ee3f4fc94d9b946d104c6c430ee9e397a2c1ef3c9eaaae349d83697a271010de87b863593b32&X-Goog-SignedHeaders=host&X-User=2931823730: HTTPSConnectionPool(host='storage.googleapis.com', port=443): Max retries exceeded with url: /wandb-production.appspot.com/2931823730-harbin-institute-of-technology/ltu-as/ayrd945g/output.log?X-Goog-Algorithm=GOOG4-RSA-SHA256&X-Goog-Credential=gorilla-files-url-signer-man%40wandb-production.iam.gserviceaccount.com%2F20250411%2Fauto%2Fstorage%2Fgoog4_request&X-Goog-Date=20250411T133547Z&X-Goog-Expires=86399&X-Goog-Signature=60a14c64c75b7213832de3f51a8cee68b48766ce9fef4ac66308dcfbe021d98db23ab7a4e8e5a5840ad99fe69b3425e1ecaa5e7cecda0e89061d438052a78b725028def9cc631a332a1e2c99ebd6d1172adc8172fdae0d62bec226a3e99cdb144f8e7a221e0ec08c94a76dc888412fde2d9f87d0b484866e6db161d92750595d0c526c395230151ab2e6574b130439e80c58f6c8fb6187dfedd000237d5c6c32116bebe722b0f4815fa4b433c2c01eac2e6d1d439d109c547bd416ef777f07467da9090b12efc4e78dfb53e81482b7f08de5e21dbddcb7102335ee3f4fc94d9b946d104c6c430ee9e397a2c1ef3c9eaaae349d83697a271010de87b863593b32&X-Goog-SignedHeaders=host&X-User=2931823730 (Caused by NewConnectionError('<urllib3.connection.HTTPSConnection object at 0x7fcdd01c2830>: Failed to establish a new connection: [Errno 101] Network is unreachable'))
2025-04-11 13:40:28,191 ERROR   wandb-upload_4:5057 [internal_api.py:upload_file():2558] upload_file request headers: {'User-Agent': 'python-requests/2.32.3', 'Accept-Encoding': 'gzip, deflate, br', 'Accept': '*/*', 'Connection': 'keep-alive', 'Content-Length': '5135'}
2025-04-11 13:40:28,192 ERROR   wandb-upload_4:5057 [internal_api.py:upload_file():2560] upload_file response body: 
2025-04-11 13:40:28,455 DEBUG   HandlerThread:5057 [handler.py:handle_request():146] handle_request: status_report
2025-04-11 13:40:30,789 ERROR   wandb-upload_1:5057 [internal_api.py:upload_file():2556] upload_file exception https://storage.googleapis.com/wandb-production.appspot.com/2931823730-harbin-institute-of-technology/ltu-as/ayrd945g/config.yaml?X-Goog-Algorithm=GOOG4-RSA-SHA256&X-Goog-Credential=gorilla-files-url-signer-man%40wandb-production.iam.gserviceaccount.com%2F20250411%2Fauto%2Fstorage%2Fgoog4_request&X-Goog-Date=20250411T133547Z&X-Goog-Expires=86399&X-Goog-Signature=59229da32108dabf2e0b22f3378d7c4eff52c92055ad5d5b992f76e4df1c8015b756cf03412a752e587a2ea6bc2f30001b205d9ef095c5a14ab645fe71a22b821da600c1196db4191aef6cd423a67f5cfc13d398e023ee472db63d91e6f84db94368a9e61522d891c6c41b7eeb918e96b41062c0135485092d85801d941c7eb761567114df29f3b71030380dfe24d3e94c0e9810f87f3eb1f65bf4625252ec95591d290b470be81abb48ba16966c05db2893b493bab6f93bdd5325ee55c3ce817c57cadd71e627b02871d0c646f4dba235a7310afdefe60e03add6e16f1ebcee16c2bf969543124fb60ebc8bf3cee02e75fd183babe4d68e010a4c410a360fd7&X-Goog-SignedHeaders=host&X-User=2931823730: HTTPSConnectionPool(host='storage.googleapis.com', port=443): Max retries exceeded with url: /wandb-production.appspot.com/2931823730-harbin-institute-of-technology/ltu-as/ayrd945g/config.yaml?X-Goog-Algorithm=GOOG4-RSA-SHA256&X-Goog-Credential=gorilla-files-url-signer-man%40wandb-production.iam.gserviceaccount.com%2F20250411%2Fauto%2Fstorage%2Fgoog4_request&X-Goog-Date=20250411T133547Z&X-Goog-Expires=86399&X-Goog-Signature=59229da32108dabf2e0b22f3378d7c4eff52c92055ad5d5b992f76e4df1c8015b756cf03412a752e587a2ea6bc2f30001b205d9ef095c5a14ab645fe71a22b821da600c1196db4191aef6cd423a67f5cfc13d398e023ee472db63d91e6f84db94368a9e61522d891c6c41b7eeb918e96b41062c0135485092d85801d941c7eb761567114df29f3b71030380dfe24d3e94c0e9810f87f3eb1f65bf4625252ec95591d290b470be81abb48ba16966c05db2893b493bab6f93bdd5325ee55c3ce817c57cadd71e627b02871d0c646f4dba235a7310afdefe60e03add6e16f1ebcee16c2bf969543124fb60ebc8bf3cee02e75fd183babe4d68e010a4c410a360fd7&X-Goog-SignedHeaders=host&X-User=2931823730 (Caused by NewConnectionError('<urllib3.connection.HTTPSConnection object at 0x7fcd927aa050>: Failed to establish a new connection: [Errno 101] Network is unreachable'))
2025-04-11 13:40:30,789 ERROR   wandb-upload_1:5057 [internal_api.py:upload_file():2558] upload_file request headers: {'User-Agent': 'python-requests/2.32.3', 'Accept-Encoding': 'gzip, deflate, br', 'Accept': '*/*', 'Connection': 'keep-alive', 'Content-Length': '8685'}
2025-04-11 13:40:30,789 ERROR   wandb-upload_1:5057 [internal_api.py:upload_file():2560] upload_file response body: 
2025-04-11 13:40:31,089 DEBUG   HandlerThread:5057 [handler.py:handle_request():146] handle_request: keepalive
2025-04-11 13:40:33,160 ERROR   wandb-upload_3:5057 [internal_api.py:upload_file():2556] upload_file exception https://storage.googleapis.com/wandb-production.appspot.com/2931823730-harbin-institute-of-technology/ltu-as/ayrd945g/conda-environment.yaml?X-Goog-Algorithm=GOOG4-RSA-SHA256&X-Goog-Credential=gorilla-files-url-signer-man%40wandb-production.iam.gserviceaccount.com%2F20250411%2Fauto%2Fstorage%2Fgoog4_request&X-Goog-Date=20250411T133547Z&X-Goog-Expires=86399&X-Goog-Signature=4c9126604080912880ede91838f5a7390665008083d7e44309734daddd80b9cf8cf7a4c5c6fa5de745ba75d664cb7469ed45bccd6a8d0f8328f5b819c87f52209a817e2cecb6b43dd002266b64a58a46125cf94eecc520b1b7a33aba86a8651778a4fc020b1e58b91094758a9f0bdf70c1b1709c39a4aa8e5b9998524293e3f95252e6a81cbabe349b8e96481c3fdb99ef3ed87c033bd482bc27e2900be02b6f7a10cc37e178de535da73792986f0057d36c512c3142823ec07dde39234d436ecef04f3b634ff435b7df21a6d1fbd1b616a7aafd7a5bc2d0a15eacb48d1f828c4e7e505ad7f7585a5624f5d9716d95b4b15bdc9c2151e47d7698d62f76621622&X-Goog-SignedHeaders=host&X-User=2931823730: HTTPSConnectionPool(host='storage.googleapis.com', port=443): Max retries exceeded with url: /wandb-production.appspot.com/2931823730-harbin-institute-of-technology/ltu-as/ayrd945g/conda-environment.yaml?X-Goog-Algorithm=GOOG4-RSA-SHA256&X-Goog-Credential=gorilla-files-url-signer-man%40wandb-production.iam.gserviceaccount.com%2F20250411%2Fauto%2Fstorage%2Fgoog4_request&X-Goog-Date=20250411T133547Z&X-Goog-Expires=86399&X-Goog-Signature=4c9126604080912880ede91838f5a7390665008083d7e44309734daddd80b9cf8cf7a4c5c6fa5de745ba75d664cb7469ed45bccd6a8d0f8328f5b819c87f52209a817e2cecb6b43dd002266b64a58a46125cf94eecc520b1b7a33aba86a8651778a4fc020b1e58b91094758a9f0bdf70c1b1709c39a4aa8e5b9998524293e3f95252e6a81cbabe349b8e96481c3fdb99ef3ed87c033bd482bc27e2900be02b6f7a10cc37e178de535da73792986f0057d36c512c3142823ec07dde39234d436ecef04f3b634ff435b7df21a6d1fbd1b616a7aafd7a5bc2d0a15eacb48d1f828c4e7e505ad7f7585a5624f5d9716d95b4b15bdc9c2151e47d7698d62f76621622&X-Goog-SignedHeaders=host&X-User=2931823730 (Caused by NewConnectionError('<urllib3.connection.HTTPSConnection object at 0x7fcd927a9ab0>: Failed to establish a new connection: [Errno 101] Network is unreachable'))
2025-04-11 13:40:33,160 ERROR   wandb-upload_3:5057 [internal_api.py:upload_file():2558] upload_file request headers: {'User-Agent': 'python-requests/2.32.3', 'Accept-Encoding': 'gzip, deflate, br', 'Accept': '*/*', 'Connection': 'keep-alive', 'Content-Length': '8281'}
2025-04-11 13:40:33,160 ERROR   wandb-upload_3:5057 [internal_api.py:upload_file():2560] upload_file response body: 
2025-04-11 13:40:33,456 DEBUG   HandlerThread:5057 [handler.py:handle_request():146] handle_request: status_report
2025-04-11 13:40:34,427 ERROR   wandb-upload_2:5057 [internal_api.py:upload_file():2556] upload_file exception https://storage.googleapis.com/wandb-production.appspot.com/2931823730-harbin-institute-of-technology/ltu-as/ayrd945g/requirements.txt?X-Goog-Algorithm=GOOG4-RSA-SHA256&X-Goog-Credential=gorilla-files-url-signer-man%40wandb-production.iam.gserviceaccount.com%2F20250411%2Fauto%2Fstorage%2Fgoog4_request&X-Goog-Date=20250411T133547Z&X-Goog-Expires=86399&X-Goog-Signature=8f7985a4ebf492647396ccbeb8281c95f40ce48ca6ebfe7230b06e3e08a640b4892e9fbe8f14f084f14e5d3841d2ed4769d71f5dcc53a827130556bbab907612d4a6c07d1c4b3f38ce4fc656dabf01e58238b7603961296e52ef293121e1ab2eb7c0f40e653fe066ef2a8502bf31d63a12f60e5498b0ebdae66cee400aa1a42598345e000ebb6d22ea01ec55dcf62810cace5cacbb3cef4cc37ca34ae61cfaf15fa634731635ca6ad7b243b89a565ecd2dfae6fdcfdaf084938d1afa790a313af20f904fe253f7e9c5fbe3595321a68018379642acab4619f2715b3e42cea1e7f430dada2242a15e4fdaaa50c317aa219a978a754411899f051b8136a1fa5a4d&X-Goog-SignedHeaders=host&X-User=2931823730: HTTPSConnectionPool(host='storage.googleapis.com', port=443): Max retries exceeded with url: /wandb-production.appspot.com/2931823730-harbin-institute-of-technology/ltu-as/ayrd945g/requirements.txt?X-Goog-Algorithm=GOOG4-RSA-SHA256&X-Goog-Credential=gorilla-files-url-signer-man%40wandb-production.iam.gserviceaccount.com%2F20250411%2Fauto%2Fstorage%2Fgoog4_request&X-Goog-Date=20250411T133547Z&X-Goog-Expires=86399&X-Goog-Signature=8f7985a4ebf492647396ccbeb8281c95f40ce48ca6ebfe7230b06e3e08a640b4892e9fbe8f14f084f14e5d3841d2ed4769d71f5dcc53a827130556bbab907612d4a6c07d1c4b3f38ce4fc656dabf01e58238b7603961296e52ef293121e1ab2eb7c0f40e653fe066ef2a8502bf31d63a12f60e5498b0ebdae66cee400aa1a42598345e000ebb6d22ea01ec55dcf62810cace5cacbb3cef4cc37ca34ae61cfaf15fa634731635ca6ad7b243b89a565ecd2dfae6fdcfdaf084938d1afa790a313af20f904fe253f7e9c5fbe3595321a68018379642acab4619f2715b3e42cea1e7f430dada2242a15e4fdaaa50c317aa219a978a754411899f051b8136a1fa5a4d&X-Goog-SignedHeaders=host&X-User=2931823730 (Caused by NewConnectionError('<urllib3.connection.HTTPSConnection object at 0x7fcd927a92a0>: Failed to establish a new connection: [Errno 101] Network is unreachable'))
2025-04-11 13:40:34,428 ERROR   wandb-upload_2:5057 [internal_api.py:upload_file():2558] upload_file request headers: {'User-Agent': 'python-requests/2.32.3', 'Accept-Encoding': 'gzip, deflate, br', 'Accept': '*/*', 'Connection': 'keep-alive', 'Content-Length': '4212'}
2025-04-11 13:40:34,428 ERROR   wandb-upload_2:5057 [internal_api.py:upload_file():2560] upload_file response body: 
2025-04-11 13:40:36,091 DEBUG   HandlerThread:5057 [handler.py:handle_request():146] handle_request: keepalive
2025-04-11 13:40:37,657 ERROR   wandb-upload_5:5057 [internal_api.py:upload_file():2556] upload_file exception https://storage.googleapis.com/wandb-production.appspot.com/2931823730-harbin-institute-of-technology/ltu-as/ayrd945g/wandb-summary.json?X-Goog-Algorithm=GOOG4-RSA-SHA256&X-Goog-Credential=gorilla-files-url-signer-man%40wandb-production.iam.gserviceaccount.com%2F20250411%2Fauto%2Fstorage%2Fgoog4_request&X-Goog-Date=20250411T133547Z&X-Goog-Expires=86399&X-Goog-Signature=88d8a33a4942edfdf46386d8d3684fa7b9d5a442bb037f8cda46c414fe422ca150fb4f2e5f776cc41bf710997e8d99494d56986c0251407a93dff567d301deee84d6a9d3c20c4876734beeebe93fc2170c90439950e62f7d895e7dfc8cff58ae05a6debe4386cf769ab635fbfecc6b9311f012934afbb8e9bfc6c652fb999d4b61c9c6dd3511d8a321c3bac43987e7d9891f0c31f9d35ca79f5a1ef87bcfa3ef26a7e363d6207536f2b71b07a4b55c4e341c9e6178a3a7bf0e2c835d2471597f60ccc6925d495148fc1623f5b3160f75ff84cd47fadcd8cd769536b21457ea5f60c8ba539b75f81d476509ef340009289b14c43e1a28cc2e27df0d6e9eb44275&X-Goog-SignedHeaders=host&X-User=2931823730: HTTPSConnectionPool(host='storage.googleapis.com', port=443): Max retries exceeded with url: /wandb-production.appspot.com/2931823730-harbin-institute-of-technology/ltu-as/ayrd945g/wandb-summary.json?X-Goog-Algorithm=GOOG4-RSA-SHA256&X-Goog-Credential=gorilla-files-url-signer-man%40wandb-production.iam.gserviceaccount.com%2F20250411%2Fauto%2Fstorage%2Fgoog4_request&X-Goog-Date=20250411T133547Z&X-Goog-Expires=86399&X-Goog-Signature=88d8a33a4942edfdf46386d8d3684fa7b9d5a442bb037f8cda46c414fe422ca150fb4f2e5f776cc41bf710997e8d99494d56986c0251407a93dff567d301deee84d6a9d3c20c4876734beeebe93fc2170c90439950e62f7d895e7dfc8cff58ae05a6debe4386cf769ab635fbfecc6b9311f012934afbb8e9bfc6c652fb999d4b61c9c6dd3511d8a321c3bac43987e7d9891f0c31f9d35ca79f5a1ef87bcfa3ef26a7e363d6207536f2b71b07a4b55c4e341c9e6178a3a7bf0e2c835d2471597f60ccc6925d495148fc1623f5b3160f75ff84cd47fadcd8cd769536b21457ea5f60c8ba539b75f81d476509ef340009289b14c43e1a28cc2e27df0d6e9eb44275&X-Goog-SignedHeaders=host&X-User=2931823730 (Caused by NewConnectionError('<urllib3.connection.HTTPSConnection object at 0x7fcd927a8a90>: Failed to establish a new connection: [Errno 101] Network is unreachable'))
2025-04-11 13:40:37,657 ERROR   wandb-upload_5:5057 [internal_api.py:upload_file():2558] upload_file request headers: {'User-Agent': 'python-requests/2.32.3', 'Accept-Encoding': 'gzip, deflate, br', 'Accept': '*/*', 'Connection': 'keep-alive', 'Content-Length': '27'}
2025-04-11 13:40:37,657 ERROR   wandb-upload_5:5057 [internal_api.py:upload_file():2560] upload_file response body: 
2025-04-11 13:40:38,457 DEBUG   HandlerThread:5057 [handler.py:handle_request():146] handle_request: status_report
2025-04-11 13:40:41,094 DEBUG   HandlerThread:5057 [handler.py:handle_request():146] handle_request: keepalive
2025-04-11 13:40:43,458 DEBUG   HandlerThread:5057 [handler.py:handle_request():146] handle_request: status_report
2025-04-11 13:40:46,095 DEBUG   HandlerThread:5057 [handler.py:handle_request():146] handle_request: keepalive
2025-04-11 13:40:48,459 DEBUG   HandlerThread:5057 [handler.py:handle_request():146] handle_request: status_report
2025-04-11 13:40:51,098 DEBUG   HandlerThread:5057 [handler.py:handle_request():146] handle_request: keepalive
2025-04-11 13:40:53,460 DEBUG   HandlerThread:5057 [handler.py:handle_request():146] handle_request: status_report
2025-04-11 13:40:56,100 DEBUG   HandlerThread:5057 [handler.py:handle_request():146] handle_request: keepalive
2025-04-11 13:40:58,461 DEBUG   HandlerThread:5057 [handler.py:handle_request():146] handle_request: status_report
2025-04-11 13:41:01,102 DEBUG   HandlerThread:5057 [handler.py:handle_request():146] handle_request: keepalive
2025-04-11 13:41:03,462 DEBUG   HandlerThread:5057 [handler.py:handle_request():146] handle_request: status_report
2025-04-11 13:41:06,104 DEBUG   HandlerThread:5057 [handler.py:handle_request():146] handle_request: keepalive
2025-04-11 13:41:08,464 DEBUG   HandlerThread:5057 [handler.py:handle_request():146] handle_request: status_report
2025-04-11 13:41:11,107 DEBUG   HandlerThread:5057 [handler.py:handle_request():146] handle_request: keepalive
